Workbook

Sheet Свод_250-270_диз
C2: Технико-экономическая оценка стоимости владения
C4: Ранжирование общих аннуитетов - по возрастанию | G4: Ранжирование по стоимости самосвала - по возрастанию
C5: № | D5: Марка станка | E5: Аннуитет, руб/ткм | G5: =C5 -> № | H5: =D5 -> Марка станка | K5: Цена за ед., тыс. руб.
C6: 1 | D6: =IFERROR(HLOOKUP(E6,$F$58:$O$60,3,FALSE),"-") -> YANGZI DR75 | E6: =IFERROR(SMALL($F$58:$O$58,C6),"-") -> 11.045801 | G6: =C6 -> 1 | H6: =IFERROR(HLOOKUP(K6,$F$59:$O$60,2,FALSE),"-") -> - | K6: =IFERROR(SMALL($F$59:$O$59,C6),"-") -> -
C7: =C6+1 -> 2 | D7: =IFERROR(HLOOKUP(E7,$F$58:$O$60,3,FALSE),"-") -> Sunward SWDRT270SM | E7: =IFERROR(SMALL($F$58:$O$58,C7),"-") -> 12.086588 | G7: =C7 -> 2 | H7: =IFERROR(HLOOKUP(K7,$F$59:$O$60,2,FALSE),"-") -> - | K7: =IFERROR(SMALL($F$59:$O$59,C7),"-") -> -
C8: =C7+1 -> 3 | D8: =IFERROR(HLOOKUP(E8,$F$58:$O$60,3,FALSE),"-") -> Sunward SWDRT270B | E8: =IFERROR(SMALL($F$58:$O$58,C8),"-") -> 13.62781 | G8: =C8 -> 3 | H8: =IFERROR(HLOOKUP(K8,$F$59:$O$60,2,FALSE),"-") -> - | K8: =IFERROR(SMALL($F$59:$O$59,C8),"-") -> -
C9: =C8+1 -> 4 | D9: =IFERROR(HLOOKUP(E9,$F$58:$O$60,3,FALSE),"-") -> Sunward SWDRT250SM | E9: =IFERROR(SMALL($F$58:$O$58,C9),"-") -> 13.768153 | G9: =C9 -> 4 | H9: =IFERROR(HLOOKUP(K9,$F$59:$O$60,2,FALSE),"-") -> - | K9: =IFERROR(SMALL($F$59:$O$59,C9),"-") -> -
C10: =C9+1 -> 5 | D10: =IFERROR(HLOOKUP(E10,$F$58:$O$60,3,FALSE),"-") -> HIFO 75D | E10: =IFERROR(SMALL($F$58:$O$58,C10),"-") -> 14.68475 | G10: =C10 -> 5 | H10: =IFERROR(HLOOKUP(K10,$F$59:$O$60,2,FALSE),"-") -> - | K10: =IFERROR(SMALL($F$59:$O$59,C10),"-") -> -
C11: =C10+1 -> 6 | D11: =IFERROR(HLOOKUP(E11,$F$58:$O$60,3,FALSE),"-") -> - | E11: =IFERROR(SMALL($F$58:$O$58,C11),"-") -> - | G11: =C11 -> 6 | H11: =IFERROR(HLOOKUP(K11,$F$59:$O$60,2,FALSE),"-") -> - | K11: =IFERROR(SMALL($F$59:$O$59,C11),"-") -> -
C12: =C11+1 -> 7 | D12: =IFERROR(HLOOKUP(E12,$F$58:$O$60,3,FALSE),"-") -> - | E12: =IFERROR(SMALL($F$58:$O$58,C12),"-") -> - | G12: =C12 -> 7 | H12: =IFERROR(HLOOKUP(K12,$F$59:$O$60,2,FALSE),"-") -> - | K12: =IFERROR(SMALL($F$59:$O$59,C12),"-") -> -
C13: =C12+1 -> 8 | D13: =IFERROR(HLOOKUP(E13,$F$58:$O$60,3,FALSE),"-") -> - | E13: =IFERROR(SMALL($F$58:$O$58,C13),"-") -> - | G13: =C13 -> 8 | H13: =IFERROR(HLOOKUP(K13,$F$59:$O$60,2,FALSE),"-") -> - | K13: =IFERROR(SMALL($F$59:$O$59,C13),"-") -> -
C14: =C13+1 -> 9 | D14: =IFERROR(HLOOKUP(E14,$F$58:$O$60,3,FALSE),"-") -> - | E14: =IFERROR(SMALL($F$58:$O$58,C14),"-") -> - | G14: =C14 -> 9 | H14: =IFERROR(HLOOKUP(K14,$F$59:$O$60,2,FALSE),"-") -> - | K14: =IFERROR(SMALL($F$59:$O$59,C14),"-") -> -
C15: =C14+1 -> 10 | D15: =IFERROR(HLOOKUP(E15,$F$58:$O$60,3,FALSE),"-") -> - | E15: =IFERROR(SMALL($F$58:$O$58,C15),"-") -> - | G15: =C15 -> 10 | H15: =IFERROR(HLOOKUP(K15,$F$59:$O$60,2,FALSE),"-") -> - | K15: =IFERROR(SMALL($F$59:$O$59,C15),"-") -> -
F18: =VLOOKUP(F19,Производительность!$C$7:$AB$33,26,FALSE) -> Майнинг Солюшнс | G18: =VLOOKUP(G19,Производительность!$C$7:$AB$33,26,FALSE) -> Стройкомпозит-Н | H18: =VLOOKUP(H19,Производительность!$C$7:$AB$33,26,FALSE) -> Стройкомпозит-Н | I18: =VLOOKUP(I19,Производительность!$C$7:$AB$33,26,FALSE) -> Огунвей | J18: =VLOOKUP(J19,Производительность!$C$7:$AB$33,26,FALSE) -> Огунвей | K18: =VLOOKUP(K19,Производительность!$C$7:$AB$33,26,FALSE) -> #N/A | L18: =VLOOKUP(L19,Производительность!$C$7:$AB$33,26,FALSE) -> #N/A | M18: =VLOOKUP(M19,Производительность!$C$7:$AB$33,26,FALSE) -> #N/A | ... O18: =VLOOKUP(O19,Производительность!$C$7:$AB$33,26,FALSE) -> #N/A
C19: № | D19: Показатель | E19: Ед. изм. | F19: =Производительность!C12 -> HIFO 75D | G19: =Производительность!C10 -> Sunward SWDRT270SM | H19: =Производительность!C9 -> Sunward SWDRT250SM | I19: =Производительность!C8 -> YANGZI DR75 | J19: =Производительность!C11 -> Sunward SWDRT270B | P19: Комментарий
C20: 1 | D20: Диаметр бурения (в расчете) | E20: мм | F20: =SUMIFS('W час'!$E$19:$AF$19,'W час'!$E$4:$AF$4,F$19)*1000 -> 266.96421 | G20: =SUMIFS('W час'!$E$19:$AF$19,'W час'!$E$4:$AF$4,G$19)*1000 -> 266.96421 | H20: =SUMIFS('W час'!$E$19:$AF$19,'W час'!$E$4:$AF$4,H$19)*1000 -> 266.96421 | I20: =SUMIFS('W час'!$E$19:$AF$19,'W час'!$E$4:$AF$4,I$19)*1000 -> 266.96421 | J20: =SUMIFS('W час'!$E$19:$AF$19,'W час'!$E$4:$AF$4,J$19)*1000 -> 266.96421 | K20: =SUMIFS('W час'!$E$19:$AF$19,'W час'!$E$4:$AF$4,K$19)*1000 -> 0 | L20: =SUMIFS('W час'!$E$19:$AF$19,'W час'!$E$4:$AF$4,L$19)*1000 -> 0 | M20: =SUMIFS('W час'!$E$19:$AF$19,'W час'!$E$4:$AF$4,M$19)*1000 -> 0 | ... O20: =SUMIFS('W час'!$E$19:$AF$19,'W час'!$E$4:$AF$4,O$19)*1000 -> 0
C21: =MAX(C$20:C20)+1 -> 2 | D21: Вес станка | E21: т | F21: =HLOOKUP(F$19,'W час'!$E$4:$AF$5,2,FALSE) -> 68-85 | G21: =HLOOKUP(G$19,'W час'!$E$4:$AF$5,2,FALSE) -> 65-70 | H21: =HLOOKUP(H$19,'W час'!$E$4:$AF$5,2,FALSE) -> 65-70 | I21: =HLOOKUP(I$19,'W час'!$E$4:$AF$5,2,FALSE) -> не более 85 | J21: =HLOOKUP(J$19,'W час'!$E$4:$AF$5,2,FALSE) -> 65-70 | K21: =HLOOKUP(K$19,'W час'!$E$4:$AF$5,2,FALSE) -> #N/A | L21: =HLOOKUP(L$19,'W час'!$E$4:$AF$5,2,FALSE) -> #N/A | M21: =HLOOKUP(M$19,'W час'!$E$4:$AF$5,2,FALSE) -> #N/A | ... O21: =HLOOKUP(O$19,'W час'!$E$4:$AF$5,2,FALSE) -> #N/A
C22: =MAX(C$20:C21)+1 -> 3 | D22: Мощность привода вращателя (в расчете) | E22: кВт | F22: =SUMIFS('W час'!$E$22:$AF$22,'W час'!$E$4:$AF$4,F$19) -> 136 | G22: =SUMIFS('W час'!$E$22:$AF$22,'W час'!$E$4:$AF$4,G$19) -> 173.4 | H22: =SUMIFS('W час'!$E$22:$AF$22,'W час'!$E$4:$AF$4,H$19) -> 148.3 | I22: =SUMIFS('W час'!$E$22:$AF$22,'W час'!$E$4:$AF$4,I$19) -> 136 | J22: =SUMIFS('W час'!$E$22:$AF$22,'W час'!$E$4:$AF$4,J$19) -> 173.4 | K22: =SUMIFS('W час'!$E$22:$AF$22,'W час'!$E$4:$AF$4,K$19) -> 0 | L22: =SUMIFS('W час'!$E$22:$AF$22,'W час'!$E$4:$AF$4,L$19) -> 0 | M22: =SUMIFS('W час'!$E$22:$AF$22,'W час'!$E$4:$AF$4,M$19) -> 0 | ... O22: =SUMIFS('W час'!$E$22:$AF$22,'W час'!$E$4:$AF$4,O$19) -> 0
C23: =MAX(C$20:C22)+1 -> 4 | D23: Срок эксплуатации | E23: лет | F23: =SUMIFS(Производительность!$Y$7:$Y$34,Производительность!$C$7:$C$34,F$19) -> 10 | G23: =SUMIFS(Производительность!$Y$7:$Y$34,Производительность!$C$7:$C$34,G$19) -> 12 | H23: =SUMIFS(Производительность!$Y$7:$Y$34,Производительность!$C$7:$C$34,H$19) -> 12 | I23: =SUMIFS(Производительность!$Y$7:$Y$34,Производительность!$C$7:$C$34,I$19) -> 12 | J23: =SUMIFS(Производительность!$Y$7:$Y$34,Производительность!$C$7:$C$34,J$19) -> 12 | K23: =SUMIFS(Производительность!$Y$7:$Y$34,Производительность!$C$7:$C$34,K$19) -> 0 | L23: =SUMIFS(Производительность!$Y$7:$Y$34,Производительность!$C$7:$C$34,L$19) -> 0 | M23: =SUMIFS(Производительность!$Y$7:$Y$34,Производительность!$C$7:$C$34,M$19) -> 0 | ... O23: =SUMIFS(Производительность!$Y$7:$Y$34,Производительность!$C$7:$C$34,O$19) -> 0
C24: =MAX(C$20:C23)+1 -> 5 | D24: КТГ (средний за эксплуатацию) | E24: коэфф. | F24: =SUMIFS(Производительность!$Z$7:$Z$34,Производительность!$C$7:$C$34,F$19) -> 0.86279872 | G24: =SUMIFS(Производительность!$Z$7:$Z$34,Производительность!$C$7:$C$34,G$19) -> 0.86075942 | H24: =SUMIFS(Производительность!$Z$7:$Z$34,Производительность!$C$7:$C$34,H$19) -> 0.86075942 | I24: =SUMIFS(Производительность!$Z$7:$Z$34,Производительность!$C$7:$C$34,I$19) -> 0.90811031 | J24: =SUMIFS(Производительность!$Z$7:$Z$34,Производительность!$C$7:$C$34,J$19) -> 0.89583333 | K24: =SUMIFS(Производительность!$Z$7:$Z$34,Производительность!$C$7:$C$34,K$19) -> 0 | L24: =SUMIFS(Производительность!$Z$7:$Z$34,Производительность!$C$7:$C$34,L$19) -> 0 | M24: =SUMIFS(Производительность!$Z$7:$Z$34,Производительность!$C$7:$C$34,M$19) -> 0 | ... O24: =SUMIFS(Производительность!$Z$7:$Z$34,Производительность!$C$7:$C$34,O$19) -> 0
C25: =MAX(C$20:C24)+1 -> 6 | D25: КТГ (1-й год) | E25: =E24 -> коэфф. | F25: =SUMIFS(Производительность!$E$7:$E$34,Производительность!$C$7:$C$34,F$19) -> 0.89322362 | G25: =SUMIFS(Производительность!$E$7:$E$34,Производительность!$C$7:$C$34,G$19) -> 0.8947946 | H25: =SUMIFS(Производительность!$E$7:$E$34,Производительность!$C$7:$C$34,H$19) -> 0.8947946 | I25: =SUMIFS(Производительность!$E$7:$E$34,Производительность!$C$7:$C$34,I$19) -> 0.93093607 | J25: =SUMIFS(Производительность!$E$7:$E$34,Производительность!$C$7:$C$34,J$19) -> 0.93 | K25: =SUMIFS(Производительность!$E$7:$E$34,Производительность!$C$7:$C$34,K$19) -> 0 | L25: =SUMIFS(Производительность!$E$7:$E$34,Производительность!$C$7:$C$34,L$19) -> 0 | M25: =SUMIFS(Производительность!$E$7:$E$34,Производительность!$C$7:$C$34,M$19) -> 0 | ... O25: =SUMIFS(Производительность!$E$7:$E$34,Производительность!$C$7:$C$34,O$19) -> 0
C26: =MAX(C$20:C25)+1 -> 7 | D26: КИО (средний за эксплуатацию) | E26: =E24 -> коэфф. | F26: =SUMIFS(Производительность!$Z$115:$Z$142,Производительность!$C$115:$C$142,F$19) -> 0.69752392 | G26: =SUMIFS(Производительность!$Z$115:$Z$142,Производительность!$C$115:$C$142,G$19) -> 0.69587526 | H26: =SUMIFS(Производительность!$Z$115:$Z$142,Производительность!$C$115:$C$142,H$19) -> 0.69587526 | I26: =SUMIFS(Производительность!$Z$115:$Z$142,Производительность!$C$115:$C$142,I$19) -> 0.73415577 | J26: =SUMIFS(Производительность!$Z$115:$Z$142,Производительность!$C$115:$C$142,J$19) -> 0.72423053 | K26: =SUMIFS(Производительность!$Z$115:$Z$142,Производительность!$C$115:$C$142,K$19) -> 0 | L26: =SUMIFS(Производительность!$Z$115:$Z$142,Производительность!$C$115:$C$142,L$19) -> 0 | M26: =SUMIFS(Производительность!$Z$115:$Z$142,Производительность!$C$115:$C$142,M$19) -> 0 | ... O26: =SUMIFS(Производительность!$Z$115:$Z$142,Производительность!$C$115:$C$142,O$19) -> 0
C27: =MAX(C$20:C26)+1 -> 8 | D27: Часовая производительность | E27: п. м/час | F27: =SUMIFS(Производительность!$E$169:$E$196,Производительность!$C$169:$C$196,F$19) -> 16.310776 | G27: =SUMIFS(Производительность!$E$169:$E$196,Производительность!$C$169:$C$196,G$19) -> 20.040244 | H27: =SUMIFS(Производительность!$E$169:$E$196,Производительность!$C$169:$C$196,H$19) -> 17.592641 | I27: =SUMIFS(Производительность!$E$169:$E$196,Производительность!$C$169:$C$196,I$19) -> 16.310776 | J27: =SUMIFS(Производительность!$E$169:$E$196,Производительность!$C$169:$C$196,J$19) -> 20.040244 | K27: =SUMIFS(Производительность!$E$169:$E$196,Производительность!$C$169:$C$196,K$19) -> 0 | L27: =SUMIFS(Производительность!$E$169:$E$196,Производительность!$C$169:$C$196,L$19) -> 0 | M27: =SUMIFS(Производительность!$E$169:$E$196,Производительность!$C$169:$C$196,M$19) -> 0 | ... O27: =SUMIFS(Производительность!$E$169:$E$196,Производительность!$C$169:$C$196,O$19) -> 0
C28: =MAX(C$20:C27)+1 -> 9 | D28: Производительность (средняя за эксплуатацию) | E28: тыс. п. м | F28: =SUMIFS(Производительность!$Z$196:$Z$223,Производительность!$C$196:$C$223,F$19) -> 99.663889 | G28: =SUMIFS(Производительность!$Z$196:$Z$223,Производительность!$C$196:$C$223,G$19) -> 122.16267 | H28: =SUMIFS(Производительность!$Z$196:$Z$223,Производительность!$C$196:$C$223,H$19) -> 107.2424 | I28: =SUMIFS(Производительность!$Z$196:$Z$223,Производительность!$C$196:$C$223,I$19) -> 104.89794 | J28: =SUMIFS(Производительность!$Z$196:$Z$223,Производительность!$C$196:$C$223,J$19) -> 127.14051 | K28: =SUMIFS(Производительность!$Z$196:$Z$223,Производительность!$C$196:$C$223,K$19) -> 0 | L28: =SUMIFS(Производительность!$Z$196:$Z$223,Производительность!$C$196:$C$223,L$19) -> 0 | M28: =SUMIFS(Производительность!$Z$196:$Z$223,Производительность!$C$196:$C$223,M$19) -> 0 | ... O28: =SUMIFS(Производительность!$Z$196:$Z$223,Производительность!$C$196:$C$223,O$19) -> 0
C29: =MAX(C$20:C28)+1 -> 10 | E29: тыс. м3 | F29: =SUMIFS(Производительность!$Z$250:$Z$277,Производительность!$C$250:$C$277,F$19) -> 4724.592 | G29: =SUMIFS(Производительность!$Z$250:$Z$277,Производительность!$C$250:$C$277,G$19) -> 5871.7519 | H29: =SUMIFS(Производительность!$Z$250:$Z$277,Производительность!$C$250:$C$277,H$19) -> 5154.6091 | I29: =SUMIFS(Производительность!$Z$250:$Z$277,Производительность!$C$250:$C$277,I$19) -> 5043.4471 | J29: =SUMIFS(Производительность!$Z$250:$Z$277,Производительность!$C$250:$C$277,J$19) -> 6111.3813 | K29: =SUMIFS(Производительность!$Z$250:$Z$277,Производительность!$C$250:$C$277,K$19) -> 0 | L29: =SUMIFS(Производительность!$Z$250:$Z$277,Производительность!$C$250:$C$277,L$19) -> 0 | M29: =SUMIFS(Производительность!$Z$250:$Z$277,Производительность!$C$250:$C$277,M$19) -> 0 | ... O29: =SUMIFS(Производительность!$Z$250:$Z$277,Производительность!$C$250:$C$277,O$19) -> 0
C30: =MAX(C$20:C29)+1 -> 11 | D30: Производительность (1-й год) | E30: =E28 -> тыс. п. м | F30: =SUMIFS(Производительность!$E$196:$E$223,Производительность!$C$196:$C$223,F$19) -> 103.17834 | G30: =SUMIFS(Производительность!$E$196:$E$223,Производительность!$C$196:$C$223,G$19) -> 126.99308 | H30: =SUMIFS(Производительность!$E$196:$E$223,Производительность!$C$196:$C$223,H$19) -> 111.48286 | I30: =SUMIFS(Производительность!$E$196:$E$223,Производительность!$C$196:$C$223,I$19) -> 107.53459 | J30: =SUMIFS(Производительность!$E$196:$E$223,Производительность!$C$196:$C$223,J$19) -> 131.98959 | K30: =SUMIFS(Производительность!$E$196:$E$223,Производительность!$C$196:$C$223,K$19) -> 0 | L30: =SUMIFS(Производительность!$E$196:$E$223,Производительность!$C$196:$C$223,L$19) -> 0 | M30: =SUMIFS(Производительность!$E$196:$E$223,Производительность!$C$196:$C$223,M$19) -> 0 | ... O30: =SUMIFS(Производительность!$E$196:$E$223,Производительность!$C$196:$C$223,O$19) -> 0
C31: =MAX(C$20:C30)+1 -> 12 | E31: =E29 -> тыс. м3 | F31: =SUMIFS(Производительность!$E$250:$E$277,Производительность!$C$250:$C$277,F$19) -> 5103.7424 | G31: =SUMIFS(Производительность!$E$250:$E$277,Производительность!$C$250:$C$277,G$19) -> 6281.7447 | H31: =SUMIFS(Производительность!$E$250:$E$277,Производительность!$C$250:$C$277,H$19) -> 5514.5277 | I31: =SUMIFS(Производительность!$E$250:$E$277,Производительность!$C$250:$C$277,I$19) -> 5319.2255 | J31: =SUMIFS(Производительность!$E$250:$E$277,Производительность!$C$250:$C$277,J$19) -> 6528.8979 | K31: =SUMIFS(Производительность!$E$250:$E$277,Производительность!$C$250:$C$277,K$19) -> 0 | L31: =SUMIFS(Производительность!$E$250:$E$277,Производительность!$C$250:$C$277,L$19) -> 0 | M31: =SUMIFS(Производительность!$E$250:$E$277,Производительность!$C$250:$C$277,M$19) -> 0 | ... O31: =SUMIFS(Производительность!$E$250:$E$277,Производительность!$C$250:$C$277,O$19) -> 0
C33: =MAX(C$20:C32)+1 -> 13 | D33: Стоимость станка | E33: тыс. руб. | F33: =F37+F38 -> 0 | G33: =G37+G38 -> 0 | H33: =H37+H38 -> 0 | I33: =I37+I38 -> 0 | J33: =J37+J38 -> 0 | K33: =K37+K38 -> 0 | L33: =L37+L38 -> 0 | M33: =M37+M38 -> 0 | ... O33: =O37+O38 -> 0 | R33: курс ЦБ на хх.07.2026
A34: заполнить | C34: =MAX(C$20:C33)+1 -> 14 | D34: Цена в долларах | E34: тыс. долл. | R34: 80
A35: заполнить | C35: =MAX(C$20:C34)+1 -> 15 | D35: Цена в евро | E35: тыс. евро | R35: 90
A36: заполнить | C36: =MAX(C$20:C35)+1 -> 16 | D36: Цена в юанях | E36: тыс. юаней | R36: 11
A37: заполнить | C37: =MAX(C$20:C36)+1 -> 17 | D37: Цена в рублях | E37: =E33 -> тыс. руб.
A38: заполнить | C38: =MAX(C$20:C37)+1 -> 18 | D38: Сборка | E38: =E33 -> тыс. руб.
A40: заполнить | C40: =MAX(C$20:C39)+1 -> 19 | D40: Потребность | E40: ед.
C41: =MAX(C$20:C40)+1 -> 20 | D41: CAPEX на потребность | E41: =E33 -> тыс. руб. | F41: =F40*F33 -> 0 | G41: =G40*G33 -> 0 | H41: =H40*H33 -> 0 | I41: =I40*I33 -> 0 | J41: =J40*J33 -> 0 | K41: =K40*K33 -> 0 | L41: =L40*L33 -> 0 | M41: =M40*M33 -> 0 | ... O41: =O40*O33 -> 0
C43: =MAX(C$20:C42)+1 -> 21 | D43: Среднегодовые затраты на ТО (включая смазочные) и ремонты | E43: тыс. руб. | F43: =SUMIFS('ТСО_250-270_диз'!$AB:$AB,'ТСО_250-270_диз'!$A:$A,F$19) -> 50139.665 | G43: =SUMIFS('ТСО_250-270_диз'!$AB:$AB,'ТСО_250-270_диз'!$A:$A,G$19) -> 49385.811 | H43: =SUMIFS('ТСО_250-270_диз'!$AB:$AB,'ТСО_250-270_диз'!$A:$A,H$19) -> 49385.811 | I43: =SUMIFS('ТСО_250-270_диз'!$AB:$AB,'ТСО_250-270_диз'!$A:$A,I$19) -> 28597.333 | J43: =SUMIFS('ТСО_250-270_диз'!$AB:$AB,'ТСО_250-270_диз'!$A:$A,J$19) -> 66898.704 | K43: =SUMIFS('ТСО_250-270_диз'!$AB:$AB,'ТСО_250-270_диз'!$A:$A,K$19) -> 0 | L43: =SUMIFS('ТСО_250-270_диз'!$AB:$AB,'ТСО_250-270_диз'!$A:$A,L$19) -> 0 | M43: =SUMIFS('ТСО_250-270_диз'!$AB:$AB,'ТСО_250-270_диз'!$A:$A,M$19) -> 0 | ... O43: =SUMIFS('ТСО_250-270_диз'!$AB:$AB,'ТСО_250-270_диз'!$A:$A,O$19) -> 0
A45: ='ТСО_250-270_диз'!B87 -> Аннуитет операционный | C45: =MAX(C$20:C44)+1 -> 22 | D45: ='ТСО_250-270_диз'!D87 -> Аннуитет операционный | E45: ='ТСО_250-270_диз'!E87 -> руб/м3 | F45: =SUMIFS('ТСО_250-270_диз'!$AC:$AC,'ТСО_250-270_диз'!$A:$A,F$19,'ТСО_250-270_диз'!$B:$B,$A45) -> 14.68475 | G45: =SUMIFS('ТСО_250-270_диз'!$AC:$AC,'ТСО_250-270_диз'!$A:$A,G$19,'ТСО_250-270_диз'!$B:$B,$A45) -> 12.086588 | H45: =SUMIFS('ТСО_250-270_диз'!$AC:$AC,'ТСО_250-270_диз'!$A:$A,H$19,'ТСО_250-270_диз'!$B:$B,$A45) -> 13.768153 | I45: =SUMIFS('ТСО_250-270_диз'!$AC:$AC,'ТСО_250-270_диз'!$A:$A,I$19,'ТСО_250-270_диз'!$B:$B,$A45) -> 11.045801 | J45: =SUMIFS('ТСО_250-270_диз'!$AC:$AC,'ТСО_250-270_диз'!$A:$A,J$19,'ТСО_250-270_диз'!$B:$B,$A45) -> 13.62781 | K45: =SUMIFS('ТСО_250-270_диз'!$AC:$AC,'ТСО_250-270_диз'!$A:$A,K$19,'ТСО_250-270_диз'!$B:$B,$A45) -> 0 | L45: =SUMIFS('ТСО_250-270_диз'!$AC:$AC,'ТСО_250-270_диз'!$A:$A,L$19,'ТСО_250-270_диз'!$B:$B,$A45) -> 0 | M45: =SUMIFS('ТСО_250-270_диз'!$AC:$AC,'ТСО_250-270_диз'!$A:$A,M$19,'ТСО_250-270_диз'!$B:$B,$A45) -> 0 | ... O45: =SUMIFS('ТСО_250-270_диз'!$AC:$AC,'ТСО_250-270_диз'!$A:$A,O$19,'ТСО_250-270_диз'!$B:$B,$A45) -> 0
A46: ='ТСО_250-270_диз'!B88 -> ТО, ТР, ППР | C46: =MAX(C$20:C45)+1 -> 23 | D46: ='ТСО_250-270_диз'!D88 -> ТО, ТР, ППР | E46: ='ТСО_250-270_диз'!E88 -> руб/м3 | F46: =SUMIFS('ТСО_250-270_диз'!$AC:$AC,'ТСО_250-270_диз'!$A:$A,F$19,'ТСО_250-270_диз'!$B:$B,$A46) -> 10.019176 | G46: =SUMIFS('ТСО_250-270_диз'!$AC:$AC,'ТСО_250-270_диз'!$A:$A,G$19,'ТСО_250-270_диз'!$B:$B,$A46) -> 8.432075 | H46: =SUMIFS('ТСО_250-270_диз'!$AC:$AC,'ТСО_250-270_диз'!$A:$A,H$19,'ТСО_250-270_диз'!$B:$B,$A46) -> 9.6052002 | I46: =SUMIFS('ТСО_250-270_диз'!$AC:$AC,'ТСО_250-270_диз'!$A:$A,I$19,'ТСО_250-270_диз'!$B:$B,$A46) -> 5.4633445 | J46: =SUMIFS('ТСО_250-270_диз'!$AC:$AC,'ТСО_250-270_диз'!$A:$A,J$19,'ТСО_250-270_диз'!$B:$B,$A46) -> 10.571834 | K46: =SUMIFS('ТСО_250-270_диз'!$AC:$AC,'ТСО_250-270_диз'!$A:$A,K$19,'ТСО_250-270_диз'!$B:$B,$A46) -> 0 | L46: =SUMIFS('ТСО_250-270_диз'!$AC:$AC,'ТСО_250-270_диз'!$A:$A,L$19,'ТСО_250-270_диз'!$B:$B,$A46) -> 0 | M46: =SUMIFS('ТСО_250-270_диз'!$AC:$AC,'ТСО_250-270_диз'!$A:$A,M$19,'ТСО_250-270_диз'!$B:$B,$A46) -> 0 | ... O46: =SUMIFS('ТСО_250-270_диз'!$AC:$AC,'ТСО_250-270_диз'!$A:$A,O$19,'ТСО_250-270_диз'!$B:$B,$A46) -> 0
A47: ='ТСО_250-270_диз'!B89 -> Смазочные | C47: =MAX(C$20:C46)+1 -> 24 | D47: ='ТСО_250-270_диз'!D89 -> Смазочные | E47: ='ТСО_250-270_диз'!E89 -> руб/м3 | F47: =SUMIFS('ТСО_250-270_диз'!$AC:$AC,'ТСО_250-270_диз'!$A:$A,F$19,'ТСО_250-270_диз'!$B:$B,$A47) -> 0 | G47: =SUMIFS('ТСО_250-270_диз'!$AC:$AC,'ТСО_250-270_диз'!$A:$A,G$19,'ТСО_250-270_диз'!$B:$B,$A47) -> 0 | H47: =SUMIFS('ТСО_250-270_диз'!$AC:$AC,'ТСО_250-270_диз'!$A:$A,H$19,'ТСО_250-270_диз'!$B:$B,$A47) -> 0 | I47: =SUMIFS('ТСО_250-270_диз'!$AC:$AC,'ТСО_250-270_диз'!$A:$A,I$19,'ТСО_250-270_диз'!$B:$B,$A47) -> 0 | J47: =SUMIFS('ТСО_250-270_диз'!$AC:$AC,'ТСО_250-270_диз'!$A:$A,J$19,'ТСО_250-270_диз'!$B:$B,$A47) -> 0 | K47: =SUMIFS('ТСО_250-270_диз'!$AC:$AC,'ТСО_250-270_диз'!$A:$A,K$19,'ТСО_250-270_диз'!$B:$B,$A47) -> 0 | L47: =SUMIFS('ТСО_250-270_диз'!$AC:$AC,'ТСО_250-270_диз'!$A:$A,L$19,'ТСО_250-270_диз'!$B:$B,$A47) -> 0 | M47: =SUMIFS('ТСО_250-270_диз'!$AC:$AC,'ТСО_250-270_диз'!$A:$A,M$19,'ТСО_250-270_диз'!$B:$B,$A47) -> 0 | ... O47: =SUMIFS('ТСО_250-270_диз'!$AC:$AC,'ТСО_250-270_диз'!$A:$A,O$19,'ТСО_250-270_диз'!$B:$B,$A47) -> 0
A48: ='ТСО_250-270_диз'!B90 -> Долота | C48: =MAX(C$20:C47)+1 -> 25 | D48: ='ТСО_250-270_диз'!D90 -> Долота | E48: ='ТСО_250-270_диз'!E90 -> руб/м3 | F48: =SUMIFS('ТСО_250-270_диз'!$AC:$AC,'ТСО_250-270_диз'!$A:$A,F$19,'ТСО_250-270_диз'!$B:$B,$A48) -> 0 | G48: =SUMIFS('ТСО_250-270_диз'!$AC:$AC,'ТСО_250-270_диз'!$A:$A,G$19,'ТСО_250-270_диз'!$B:$B,$A48) -> 0 | H48: =SUMIFS('ТСО_250-270_диз'!$AC:$AC,'ТСО_250-270_диз'!$A:$A,H$19,'ТСО_250-270_диз'!$B:$B,$A48) -> 0 | I48: =SUMIFS('ТСО_250-270_диз'!$AC:$AC,'ТСО_250-270_диз'!$A:$A,I$19,'ТСО_250-270_диз'!$B:$B,$A48) -> 0 | J48: =SUMIFS('ТСО_250-270_диз'!$AC:$AC,'ТСО_250-270_диз'!$A:$A,J$19,'ТСО_250-270_диз'!$B:$B,$A48) -> 0 | K48: =SUMIFS('ТСО_250-270_диз'!$AC:$AC,'ТСО_250-270_диз'!$A:$A,K$19,'ТСО_250-270_диз'!$B:$B,$A48) -> 0 | L48: =SUMIFS('ТСО_250-270_диз'!$AC:$AC,'ТСО_250-270_диз'!$A:$A,L$19,'ТСО_250-270_диз'!$B:$B,$A48) -> 0 | M48: =SUMIFS('ТСО_250-270_диз'!$AC:$AC,'ТСО_250-270_диз'!$A:$A,M$19,'ТСО_250-270_диз'!$B:$B,$A48) -> 0 | ... O48: =SUMIFS('ТСО_250-270_диз'!$AC:$AC,'ТСО_250-270_диз'!$A:$A,O$19,'ТСО_250-270_диз'!$B:$B,$A48) -> 0
...

Sheet ТСО_250-270_диз
A1: не удалять | B1: не удалять | C1: не удалять | D1: Показатель | E1: Ед. изм. | F1: =G1-1 -> 0 | G1: 1 | H1: =G1+1 -> 2 | I1: =H1+1 -> 3 | J1: =I1+1 -> 4 | K1: =J1+1 -> 5 | L1: =K1+1 -> 6 | M1: =L1+1 -> 7 | N1: =M1+1 -> 8 | O1: =N1+1 -> 9 | ... Z1: =Y1+1 -> 20 | AA1: не удалять | AB1: не удалять | AC1: не удалять
A2: * | F2: лет | G2: 2027 | H2: =G2+1 -> 2028 | I2: =H2+1 -> 2029 | J2: =I2+1 -> 2030 | K2: =J2+1 -> 2031 | L2: =K2+1 -> 2032 | M2: =L2+1 -> 2033 | N2: =M2+1 -> 2034 | O2: =N2+1 -> 2035 | ... Z2: =Y2+1 -> 2046 | AA2: проверки | AB2: средние на ТО, ТР, ППР | AC2: аннуитет
A3: * | G3: =Производительность!E6 -> 8760 | H3: =Производительность!F6 -> 8760 | I3: =Производительность!G6 -> 8760 | J3: =Производительность!H6 -> 8760 | K3: =Производительность!I6 -> 8760 | L3: =Производительность!J6 -> 8760 | M3: =Производительность!K6 -> 8760 | N3: =Производительность!L6 -> 8760 | ... Z3: =Производительность!X6 -> 8760
A4: * | D4: Расчет аннуитета
A5: *
A6: * | C6: =SUM(F66:Z66,F80:Z80,F101:Z101,AA48) -> #DIV/0! | D6: ='Свод_250-270_диз'!F19 -> HIFO 75D | E6: =SUMIFS(Производительность!$Y$7:$Y$34,Производительность!$C$7:$C$34,$D6) -> 10 | F6: =$F$2 -> лет
A7: *
A8: =D6 -> HIFO 75D | D8: =D$1 -> Показатель | E8: =E$1 -> Ед. изм. | F8: =F$1 -> 0 | G8: =G$1 -> 1 | H8: =H$1 -> 2 | I8: =I$1 -> 3 | J8: =J$1 -> 4 | K8: =K$1 -> 5 | ... Z8: =Z$1 -> 20
A9: =A8 -> HIFO 75D | D9: КТГ | E9: % | G9: =SUMIFS(Производительность!E$7:E$34,Производительность!$C$7:$C$34,$A9) -> 0.89322362 | H9: =SUMIFS(Производительность!F$7:F$34,Производительность!$C$7:$C$34,$A9) -> 0.8669947 | I9: =SUMIFS(Производительность!G$7:G$34,Производительность!$C$7:$C$34,$A9) -> 0.85358337 | J9: =SUMIFS(Производительность!H$7:H$34,Производительность!$C$7:$C$34,$A9) -> 0.86506358 | K9: =SUMIFS(Производительность!I$7:I$34,Производительность!$C$7:$C$34,$A9) -> 0.87024876 | L9: =SUMIFS(Производительность!J$7:J$34,Производительность!$C$7:$C$34,$A9) -> 0.84426956 | M9: =SUMIFS(Производительность!K$7:K$34,Производительность!$C$7:$C$34,$A9) -> 0.85844004 | N9: =SUMIFS(Производительность!L$7:L$34,Производительность!$C$7:$C$34,$A9) -> 0.8705795 | ... Z9: =SUMIFS(Производительность!X$7:X$34,Производительность!$C$7:$C$34,$A9) -> 0
A10: =A9 -> HIFO 75D | D10: КИО | E10: =E9 -> % | G10: =SUMIFS(Производительность!E$115:E$142,Производительность!$C$115:$C$142,$A10) -> 0.72212072 | H10: =SUMIFS(Производительность!F$115:F$142,Производительность!$C$115:$C$142,$A10) -> 0.70091613 | I10: =SUMIFS(Производительность!G$115:G$142,Производительность!$C$115:$C$142,$A10) -> 0.69007382 | J10: =SUMIFS(Производительность!H$115:H$142,Производительность!$C$115:$C$142,$A10) -> 0.69935492 | K10: =SUMIFS(Производительность!I$115:I$142,Производительность!$C$115:$C$142,$A10) -> 0.70354685 | L10: =SUMIFS(Производительность!J$115:J$142,Производительность!$C$115:$C$142,$A10) -> 0.68254414 | M10: =SUMIFS(Производительность!K$115:K$142,Производительность!$C$115:$C$142,$A10) -> 0.69400017 | N10: =SUMIFS(Производительность!L$115:L$142,Производительность!$C$115:$C$142,$A10) -> 0.70381423 | ... Z10: =SUMIFS(Производительность!X$115:X$142,Производительность!$C$115:$C$142,$A10) -> 0
A11: =A10 -> HIFO 75D | D11: Производительность_бурение | E11: тыс. п. м | G11: =SUMIFS(Производительность!E$196:E$223,Производительность!$C$196:$C$223,$A11) -> 103.17834 | H11: =SUMIFS(Производительность!F$196:F$223,Производительность!$C$196:$C$223,$A11) -> 100.14858 | I11: =SUMIFS(Производительность!G$196:G$223,Производительность!$C$196:$C$223,$A11) -> 98.599402 | J11: =SUMIFS(Производительность!H$196:H$223,Производительность!$C$196:$C$223,$A11) -> 99.925508 | K11: =SUMIFS(Производительность!I$196:I$223,Производительность!$C$196:$C$223,$A11) -> 100.52446 | L11: =SUMIFS(Производительность!J$196:J$223,Производительность!$C$196:$C$223,$A11) -> 97.523543 | M11: =SUMIFS(Производительность!K$196:K$223,Производительность!$C$196:$C$223,$A11) -> 99.160407 | N11: =SUMIFS(Производительность!L$196:L$223,Производительность!$C$196:$C$223,$A11) -> 100.56266 | ... Z11: =SUMIFS(Производительность!X$196:X$223,Производительность!$C$196:$C$223,$A11) -> 0
A12: =A11 -> HIFO 75D | D12: Производительность_взрывание | E12: тыс. м3 | G12: =SUMIFS(Производительность!E$250:E$277,Производительность!$C$250:$C$277,$A12) -> 5103.7424 | H12: =SUMIFS(Производительность!F$250:F$277,Производительность!$C$250:$C$277,$A12) -> 4863.4854 | I12: =SUMIFS(Производительность!G$250:G$277,Производительность!$C$250:$C$277,$A12) -> 4506.8915 | J12: =SUMIFS(Производительность!H$250:H$277,Производительность!$C$250:$C$277,$A12) -> 4873.1427 | K12: =SUMIFS(Производительность!I$250:I$277,Производительность!$C$250:$C$277,$A12) -> 4960.8765 | L12: =SUMIFS(Производительность!J$250:J$277,Производительность!$C$250:$C$277,$A12) -> 4351.3171 | M12: =SUMIFS(Производительность!K$250:K$277,Производительность!$C$250:$C$277,$A12) -> 4474.4237 | N12: =SUMIFS(Производительность!L$250:L$277,Производительность!$C$250:$C$277,$A12) -> 5046.2503 | ... Z12: =SUMIFS(Производительность!X$250:X$277,Производительность!$C$250:$C$277,$A12) -> 0
A13: =A12 -> HIFO 75D | D13: Производительность кумулятивная | E13: =E12 -> тыс. м3 | G13: =G12 -> 5103.7424 | H13: =IF(H12=0,0,G13+H12) -> 9967.2278 | I13: =IF(I12=0,0,H13+I12) -> 14474.119 | J13: =IF(J12=0,0,I13+J12) -> 19347.262 | K13: =IF(K12=0,0,J13+K12) -> 24308.138 | L13: =IF(L12=0,0,K13+L12) -> 28659.456 | M13: =IF(M12=0,0,L13+M12) -> 33133.879 | N13: =IF(N12=0,0,M13+N12) -> 38180.13 | O13: =IF(O12=0,0,N13+O12) -> 42770.024 | ... Z13: =IF(Z12=0,0,Y13+Z12) -> 0
A14: =A13 -> HIFO 75D
A15: =A14 -> HIFO 75D | D15: Операционный денежный поток | E15: тыс. руб. | F15: =F49+F50-F48 -> 0 | G15: =G49+G50-G48 -> 43231.297 | H15: =H49+H50-H48 -> 60466.293 | I15: =I49+I50-I48 -> 81883.568 | J15: =J49+J50-J48 -> 73213.857 | K15: =K49+K50-K48 -> 85328.553 | L15: =L49+L50-L48 -> 70939.222 | M15: =M49+M50-M48 -> 75775.388 | ... Z15: =Z49+Z50-Z48 -> 0
A16: =A15 -> HIFO 75D | D16: ТО, ТР, ППР | E16: =E15 -> тыс. руб. | G16: =(G17+G18+G19)*'ФОТ, МТР, макро'!AJ$8 -> 11524.785 | H16: =(H17+H18+H19)*'ФОТ, МТР, макро'!AK$8 -> 35397.298 | I16: =(I17+I18+I19)*'ФОТ, МТР, макро'!AL$8 -> 64410.026 | J16: =(J17+J18+J19)*'ФОТ, МТР, макро'!AM$8 -> 52459.763 | K16: =(K17+K18+K19)*'ФОТ, МТР, макро'!AN$8 -> 68436.249 | L16: =(L17+L18+L19)*'ФОТ, МТР, макро'!AO$8 -> 50134.496 | M16: =(M17+M18+M19)*'ФОТ, МТР, макро'!AP$8 -> 56100.524 | N16: =(N17+N18+N19)*'ФОТ, МТР, макро'!AQ$8 -> 55898.672 | ... P16: =(P17+P18+P19)*'ФОТ, МТР, макро'!AS$8 -> 26275.082 | AB16: =SUM(F16:Z16,F21:Z21)/E6 -> 50139.665
A17: =A16 -> HIFO 75D | D17: ТО (включая смазочные) | E17: тыс. евро | G17: ='HIFO 75D'!E22 -> 74.95522 | H17: ='HIFO 75D'!F22 -> 78.685549 | I17: ='HIFO 75D'!G22 -> 101.7663 | J17: ='HIFO 75D'!H22 -> 78.685549 | K17: ='HIFO 75D'!I22 -> 100.97287 | L17: ='HIFO 75D'!J22 -> 79.478976 | M17: ='HIFO 75D'!K22 -> 74.95522 | N17: ='HIFO 75D'!L22 -> 104.7032 | ... P17: ='HIFO 75D'!N22 -> 104.7032
A18: =A17 -> HIFO 75D | D18: ТР, ППР | E18: тыс. евро | G18: ='HIFO 75D'!E23+'HIFO 75D'!E24 -> 11.889202 | H18: ='HIFO 75D'!F23+'HIFO 75D'!F24 -> 259.727 | I18: ='HIFO 75D'!G23+'HIFO 75D'!G24 -> 552.01401 | J18: ='HIFO 75D'!H23+'HIFO 75D'!H24 -> 448.30258 | K18: ='HIFO 75D'!I23+'HIFO 75D'!I24 -> 606.23657 | L18: ='HIFO 75D'!J23+'HIFO 75D'!J24 -> 410.82589 | M18: ='HIFO 75D'!K23+'HIFO 75D'!K24 -> 489.03072 | N18: ='HIFO 75D'!L23+'HIFO 75D'!L24 -> 463.37235 | ... P18: ='HIFO 75D'!N23+'HIFO 75D'!N24 -> 124.8831
A19: =A18 -> HIFO 75D | D19: трудозатраты | E19: тыс. евро | G19: ='HIFO 75D'!E25+'HIFO 75D'!E26 -> 41.208749 | H19: ='HIFO 75D'!F25+'HIFO 75D'!F26 -> 54.890771 | I19: ='HIFO 75D'!G25+'HIFO 75D'!G26 -> 61.886648 | J19: ='HIFO 75D'!H25+'HIFO 75D'!H26 -> 55.898122 | K19: ='HIFO 75D'!I25+'HIFO 75D'!I26 -> 53.193327 | L19: ='HIFO 75D'!J25+'HIFO 75D'!J26 -> 66.745089 | M19: ='HIFO 75D'!K25+'HIFO 75D'!K26 -> 59.353219 | N19: ='HIFO 75D'!L25+'HIFO 75D'!L26 -> 53.020804 | ... P19: ='HIFO 75D'!N25+'HIFO 75D'!N26 -> 62.359061
A20: =A19 -> HIFO 75D | D20: % стоимости справочно | G20: =G16/$F53 -> #DIV/0! | H20: =H16/$F53 -> #DIV/0! | I20: =I16/$F53 -> #DIV/0! | J20: =J16/$F53 -> #DIV/0! | K20: =K16/$F53 -> #DIV/0! | L20: =L16/$F53 -> #DIV/0! | M20: =M16/$F53 -> #DIV/0! | N20: =N16/$F53 -> #DIV/0! | ... Z20: =Z16/$F53 -> #DIV/0! | AA20: =SUM(F16:Z16)/$F53 -> #DIV/0!
A21: =A20 -> HIFO 75D | D21: Смазочные | E21: =E15 -> тыс. руб.
A22: =A21 -> HIFO 75D
A23: =A22 -> HIFO 75D | D23: Долота | E23: =E15 -> тыс. руб. | G23: =G25*G26 -> 0 | H23: =H25*H26 -> 0 | I23: =I25*I26 -> 0 | J23: =J25*J26 -> 0 | K23: =K25*K26 -> 0 | L23: =L25*L26 -> 0 | M23: =M25*M26 -> 0 | N23: =N25*N26 -> 0 | ... Z23: =Z25*Z26 -> 0
A24: =A23 -> HIFO 75D | D24: удельный расход | E24: шт./тыс. п. м | F24: =SUMIFS('ФОТ, МТР, макро'!$B$4:$B$31,'ФОТ, МТР, макро'!$A$4:$A$31,$A24) -> 0 | G24: =F24 -> 0 | H24: =G24 -> 0 | I24: =H24 -> 0 | J24: =I24 -> 0 | K24: =J24 -> 0 | L24: =K24 -> 0 | M24: =L24 -> 0 | N24: =M24 -> 0 | ... Z24: =Y24 -> 0
A25: =A24 -> HIFO 75D | D25: расход за период | E25: шт. | G25: =G11*G24 -> 0 | H25: =H11*H24 -> 0 | I25: =I11*I24 -> 0 | J25: =J11*J24 -> 0 | K25: =K11*K24 -> 0 | L25: =L11*L24 -> 0 | M25: =M11*M24 -> 0 | N25: =N11*N24 -> 0 | ... Z25: =Z11*Z24 -> 0
A26: =A25 -> HIFO 75D | D26: цена | E26: тыс. руб./шт. | F26: =SUMIFS('ФОТ, МТР, макро'!$C$4:$C$31,'ФОТ, МТР, макро'!$A$4:$A$31,$A26) -> 0 | G26: =F26 -> 0 | H26: =G26 -> 0 | I26: =H26 -> 0 | J26: =I26 -> 0 | K26: =J26 -> 0 | L26: =K26 -> 0 | M26: =L26 -> 0 | N26: =M26 -> 0 | ... Z26: =Y26 -> 0
A27: =A26 -> HIFO 75D | D27: Штанги буровые | E27: =E15 -> тыс. руб. | G27: =G29*G30 -> 0 | H27: =H29*H30 -> 0 | I27: =I29*I30 -> 0 | J27: =J29*J30 -> 0 | K27: =K29*K30 -> 0 | L27: =L29*L30 -> 0 | M27: =M29*M30 -> 0 | N27: =N29*N30 -> 0 | ... Z27: =Z29*Z30 -> 0
A28: =A27 -> HIFO 75D | D28: удельный расход | E28: шт./тыс. п. м | F28: =SUMIFS('ФОТ, МТР, макро'!$E$4:$E$31,'ФОТ, МТР, макро'!$A$4:$A$31,$A28) -> 0 | G28: =F28 -> 0 | H28: =G28 -> 0 | I28: =H28 -> 0 | J28: =I28 -> 0 | K28: =J28 -> 0 | L28: =K28 -> 0 | M28: =L28 -> 0 | N28: =M28 -> 0 | ... Z28: =Y28 -> 0
A29: =A28 -> HIFO 75D | D29: расход за период | E29: шт. | G29: =G11*G28 -> 0 | H29: =H11*H28 -> 0 | I29: =I11*I28 -> 0 | J29: =J11*J28 -> 0 | K29: =K11*K28 -> 0 | L29: =L11*L28 -> 0 | M29: =M11*M28 -> 0 | N29: =N11*N28 -> 0 | ... Z29: =Z11*Z28 -> 0
A30: =A29 -> HIFO 75D | D30: цена | E30: тыс. руб./шт. | F30: =SUMIFS('ФОТ, МТР, макро'!$F$4:$F$31,'ФОТ, МТР, макро'!$A$4:$A$31,$A30) -> 0 | G30: =F30 -> 0 | H30: =G30 -> 0 | I30: =H30 -> 0 | J30: =I30 -> 0 | K30: =J30 -> 0 | L30: =K30 -> 0 | M30: =L30 -> 0 | N30: =M30 -> 0 | ... Z30: =Y30 -> 0
A31: =A30 -> HIFO 75D | D31: Расходники | E31: =E15 -> тыс. руб. | G31: =G11*G32 -> 0 | H31: =H11*H32 -> 0 | I31: =I11*I32 -> 0 | J31: =J11*J32 -> 0 | K31: =K11*K32 -> 0 | L31: =L11*L32 -> 0 | M31: =M11*M32 -> 0 | N31: =N11*N32 -> 0 | ... Z31: =Z11*Z32 -> 0
A32: =A31 -> HIFO 75D | D32: удельный расход | E32: руб./п. м | F32: =SUMIFS('ФОТ, МТР, макро'!$H$4:$H$31,'ФОТ, МТР, макро'!$A$4:$A$31,$A32) -> 0 | G32: =F32 -> 0 | H32: =G32 -> 0 | I32: =H32 -> 0 | J32: =I32 -> 0 | K32: =J32 -> 0 | L32: =K32 -> 0 | M32: =L32 -> 0 | N32: =M32 -> 0 | ... Z32: =Y32 -> 0
A33: =A32 -> HIFO 75D | C33: =SUMIFS('ФОТ, МТР, макро'!$N$4:$N$31,'ФОТ, МТР, макро'!$J$4:$J$31,$A33) -> 1 | D33: Топливо/Электроэнергия | E33: =E15 -> тыс. руб. | G33: =IF($C33=1,G34,G38) -> 30394.646 | H33: =IF($C33=1,H34,H38) -> 29502.128 | I33: =IF($C33=1,I34,I38) -> 29045.766 | J33: =IF($C33=1,J34,J38) -> 29436.416 | K33: =IF($C33=1,K34,K38) -> 29612.857 | L33: =IF($C33=1,L34,L38) -> 28728.836 | M33: =IF($C33=1,M34,M38) -> 29211.029 | N33: =IF($C33=1,N34,N38) -> 29624.111 | ... Z33: =IF($C33=1,Z34,Z38) -> 0
A34: =A33 -> HIFO 75D | D34: - расчет (1) | E34: =E33 -> тыс. руб. | G34: =G36*G37 -> 30394.646 | H34: =H36*H37 -> 29502.128 | I34: =I36*I37 -> 29045.766 | J34: =J36*J37 -> 29436.416 | K34: =K36*K37 -> 29612.857 | L34: =L36*L37 -> 28728.836 | M34: =M36*M37 -> 29211.029 | N34: =N36*N37 -> 29624.111 | ... Z34: =Z36*Z37 -> 0
A35: =A34 -> HIFO 75D | D35: удельный расход | E35: =VLOOKUP($A35,'ФОТ, МТР, макро'!$J$4:$N$31,2,FALSE) -> кг/час | F35: =SUMIFS('ФОТ, МТР, макро'!$L$4:$L$31,'ФОТ, МТР, макро'!$J$4:$J$31,$A35) -> 72.780455 | G35: =F35 -> 72.780455 | H35: =G35 -> 72.780455 | I35: =H35 -> 72.780455 | J35: =I35 -> 72.780455 | K35: =J35 -> 72.780455 | L35: =K35 -> 72.780455 | M35: =L35 -> 72.780455 | N35: =M35 -> 72.780455 | ... Z35: =Y35 -> 72.780455
A36: =A35 -> HIFO 75D | D36: расход за период | E36: =IF(E35="кг/час","т","тыс. кВт*ч") -> т | G36: =G$3*G10*G35/1000 -> 460.39297 | H36: =H$3*H10*H35/1000 -> 446.87384 | I36: =I$3*I10*I35/1000 -> 439.96125 | J36: =J$3*J10*J35/1000 -> 445.87848 | K36: =K$3*K10*K35/1000 -> 448.55107 | L36: =L$3*L10*L35/1000 -> 435.16065 | M36: =M$3*M10*M35/1000 -> 442.46452 | N36: =N$3*N10*N35/1000 -> 448.72154 | ... Z36: =Z$3*Z10*Z35/1000 -> 0
A37: =A36 -> HIFO 75D | D37: цена | E37: =IF(E36="т","тыс. руб./т","руб./кВт*ч") -> тыс. руб./т | F37: =IF(E36="т",'ФОТ, МТР, макро'!$Q$2,'ФОТ, МТР, макро'!$Q$15) -> 66.018919 | G37: =F37 -> 66.018919 | H37: =G37 -> 66.018919 | I37: =H37 -> 66.018919 | J37: =I37 -> 66.018919 | K37: =J37 -> 66.018919 | L37: =K37 -> 66.018919 | M37: =L37 -> 66.018919 | N37: =M37 -> 66.018919 | ... Z37: =Y37 -> 66.018919
A38: =A37 -> HIFO 75D | D38: - поставщик (2) | E38: =E34 -> тыс. руб. | G38: =G40*G41 -> 39047.563 | H38: =H40*H41 -> 37900.958 | I38: =I40*I41 -> 37314.677 | J38: =J40*J41 -> 37816.538 | K38: =K40*K41 -> 38043.21 | L38: =L40*L41 -> 36907.521 | M38: =M40*M41 -> 37526.988 | N38: =N40*N41 -> 38057.668 | ... Z38: =Z40*Z41 -> 0
A39: =A38 -> HIFO 75D | D39: удельный расход | E39: =E35 -> кг/час | F39: =SUMIFS('ФОТ, МТР, макро'!$M$4:$M$31,'ФОТ, МТР, макро'!$J$4:$J$31,$A39) -> 93.5 | G39: =F39 -> 93.5 | H39: =G39 -> 93.5 | I39: =H39 -> 93.5 | J39: =I39 -> 93.5 | K39: =J39 -> 93.5 | L39: =K39 -> 93.5 | M39: =L39 -> 93.5 | N39: =M39 -> 93.5 | ... Z39: =Y39 -> 93.5
A40: =A39 -> HIFO 75D | D40: расход за период | E40: =E36 -> т | G40: =G$3*G10*G39/1000 -> 591.4602 | H40: =H$3*H10*H39/1000 -> 574.09237 | I40: =I$3*I10*I39/1000 -> 565.21186 | J40: =J$3*J10*J39/1000 -> 572.81364 | K40: =K$3*K10*K39/1000 -> 576.24709 | L40: =L$3*L10*L39/1000 -> 559.04461 | M40: =M$3*M10*M39/1000 -> 568.42778 | N40: =N$3*N10*N39/1000 -> 576.46609 | ... Z40: =Z$3*Z10*Z39/1000 -> 0
...

Sheet Свод_250-270_эл
C2: Технико-экономическая оценка стоимости владения
C4: Ранжирование общих аннуитетов - по возрастанию | G4: Ранжирование по стоимости самосвала - по возрастанию
C5: № | D5: Марка станка | E5: Аннуитет, руб/ткм | G5: =C5 -> № | H5: =D5 -> Марка станка | K5: Цена за ед., тыс. руб.
C6: 1 | D6: =IFERROR(HLOOKUP(E6,$F$58:$O$60,3,FALSE),"-") -> - | E6: =IFERROR(SMALL($F$58:$O$58,C6),"-") -> - | G6: =C6 -> 1 | H6: =IFERROR(HLOOKUP(K6,$F$59:$O$60,2,FALSE),"-") -> - | K6: =IFERROR(SMALL($F$59:$O$59,C6),"-") -> -
C7: =C6+1 -> 2 | D7: =IFERROR(HLOOKUP(E7,$F$58:$O$60,3,FALSE),"-") -> - | E7: =IFERROR(SMALL($F$58:$O$58,C7),"-") -> - | G7: =C7 -> 2 | H7: =IFERROR(HLOOKUP(K7,$F$59:$O$60,2,FALSE),"-") -> - | K7: =IFERROR(SMALL($F$59:$O$59,C7),"-") -> -
C8: =C7+1 -> 3 | D8: =IFERROR(HLOOKUP(E8,$F$58:$O$60,3,FALSE),"-") -> - | E8: =IFERROR(SMALL($F$58:$O$58,C8),"-") -> - | G8: =C8 -> 3 | H8: =IFERROR(HLOOKUP(K8,$F$59:$O$60,2,FALSE),"-") -> - | K8: =IFERROR(SMALL($F$59:$O$59,C8),"-") -> -
C9: =C8+1 -> 4 | D9: =IFERROR(HLOOKUP(E9,$F$58:$O$60,3,FALSE),"-") -> - | E9: =IFERROR(SMALL($F$58:$O$58,C9),"-") -> - | G9: =C9 -> 4 | H9: =IFERROR(HLOOKUP(K9,$F$59:$O$60,2,FALSE),"-") -> - | K9: =IFERROR(SMALL($F$59:$O$59,C9),"-") -> -
C10: =C9+1 -> 5 | D10: =IFERROR(HLOOKUP(E10,$F$58:$O$60,3,FALSE),"-") -> - | E10: =IFERROR(SMALL($F$58:$O$58,C10),"-") -> - | G10: =C10 -> 5 | H10: =IFERROR(HLOOKUP(K10,$F$59:$O$60,2,FALSE),"-") -> - | K10: =IFERROR(SMALL($F$59:$O$59,C10),"-") -> -
C11: =C10+1 -> 6 | D11: =IFERROR(HLOOKUP(E11,$F$58:$O$60,3,FALSE),"-") -> - | E11: =IFERROR(SMALL($F$58:$O$58,C11),"-") -> - | G11: =C11 -> 6 | H11: =IFERROR(HLOOKUP(K11,$F$59:$O$60,2,FALSE),"-") -> - | K11: =IFERROR(SMALL($F$59:$O$59,C11),"-") -> -
C12: =C11+1 -> 7 | D12: =IFERROR(HLOOKUP(E12,$F$58:$O$60,3,FALSE),"-") -> - | E12: =IFERROR(SMALL($F$58:$O$58,C12),"-") -> - | G12: =C12 -> 7 | H12: =IFERROR(HLOOKUP(K12,$F$59:$O$60,2,FALSE),"-") -> - | K12: =IFERROR(SMALL($F$59:$O$59,C12),"-") -> -
C13: =C12+1 -> 8 | D13: =IFERROR(HLOOKUP(E13,$F$58:$O$60,3,FALSE),"-") -> - | E13: =IFERROR(SMALL($F$58:$O$58,C13),"-") -> - | G13: =C13 -> 8 | H13: =IFERROR(HLOOKUP(K13,$F$59:$O$60,2,FALSE),"-") -> - | K13: =IFERROR(SMALL($F$59:$O$59,C13),"-") -> -
C14: =C13+1 -> 9 | D14: =IFERROR(HLOOKUP(E14,$F$58:$O$60,3,FALSE),"-") -> - | E14: =IFERROR(SMALL($F$58:$O$58,C14),"-") -> - | G14: =C14 -> 9 | H14: =IFERROR(HLOOKUP(K14,$F$59:$O$60,2,FALSE),"-") -> - | K14: =IFERROR(SMALL($F$59:$O$59,C14),"-") -> -
C15: =C14+1 -> 10 | D15: =IFERROR(HLOOKUP(E15,$F$58:$O$60,3,FALSE),"-") -> - | E15: =IFERROR(SMALL($F$58:$O$58,C15),"-") -> - | G15: =C15 -> 10 | H15: =IFERROR(HLOOKUP(K15,$F$59:$O$60,2,FALSE),"-") -> - | K15: =IFERROR(SMALL($F$59:$O$59,C15),"-") -> -
F18: =VLOOKUP(F19,Производительность!$C$7:$AB$33,26,FALSE) -> рудгормаш | G18: =VLOOKUP(G19,Производительность!$C$7:$AB$33,26,FALSE) -> #N/A | H18: =VLOOKUP(H19,Производительность!$C$7:$AB$33,26,FALSE) -> #N/A | I18: =VLOOKUP(I19,Производительность!$C$7:$AB$33,26,FALSE) -> #N/A | J18: =VLOOKUP(J19,Производительность!$C$7:$AB$33,26,FALSE) -> #N/A | K18: =VLOOKUP(K19,Производительность!$C$7:$AB$33,26,FALSE) -> #N/A | L18: =VLOOKUP(L19,Производительность!$C$7:$AB$33,26,FALSE) -> #N/A | M18: =VLOOKUP(M19,Производительность!$C$7:$AB$33,26,FALSE) -> #N/A | ... O18: =VLOOKUP(O19,Производительность!$C$7:$AB$33,26,FALSE) -> #N/A
C19: № | D19: Показатель | E19: Ед. изм. | F19: =Производительность!C16 -> СБШ-250/270КП | P19: Комментарий
C20: 1 | D20: Диаметр бурения (в расчете) | E20: мм | F20: =SUMIFS('W час'!$E$19:$AF$19,'W час'!$E$4:$AF$4,F$19)*1000 -> 266.96421 | G20: =SUMIFS('W час'!$E$19:$AF$19,'W час'!$E$4:$AF$4,G$19)*1000 -> 0 | H20: =SUMIFS('W час'!$E$19:$AF$19,'W час'!$E$4:$AF$4,H$19)*1000 -> 0 | I20: =SUMIFS('W час'!$E$19:$AF$19,'W час'!$E$4:$AF$4,I$19)*1000 -> 0 | J20: =SUMIFS('W час'!$E$19:$AF$19,'W час'!$E$4:$AF$4,J$19)*1000 -> 0 | K20: =SUMIFS('W час'!$E$19:$AF$19,'W час'!$E$4:$AF$4,K$19)*1000 -> 0 | L20: =SUMIFS('W час'!$E$19:$AF$19,'W час'!$E$4:$AF$4,L$19)*1000 -> 0 | M20: =SUMIFS('W час'!$E$19:$AF$19,'W час'!$E$4:$AF$4,M$19)*1000 -> 0 | ... O20: =SUMIFS('W час'!$E$19:$AF$19,'W час'!$E$4:$AF$4,O$19)*1000 -> 0
C21: =MAX(C$20:C20)+1 -> 2 | D21: Вес станка | E21: т | F21: =HLOOKUP(F$19,'W час'!$E$4:$AF$5,2,FALSE) -> 130 | G21: =HLOOKUP(G$19,'W час'!$E$4:$AF$5,2,FALSE) -> #N/A | H21: =HLOOKUP(H$19,'W час'!$E$4:$AF$5,2,FALSE) -> #N/A | I21: =HLOOKUP(I$19,'W час'!$E$4:$AF$5,2,FALSE) -> #N/A | J21: =HLOOKUP(J$19,'W час'!$E$4:$AF$5,2,FALSE) -> #N/A | K21: =HLOOKUP(K$19,'W час'!$E$4:$AF$5,2,FALSE) -> #N/A | L21: =HLOOKUP(L$19,'W час'!$E$4:$AF$5,2,FALSE) -> #N/A | M21: =HLOOKUP(M$19,'W час'!$E$4:$AF$5,2,FALSE) -> #N/A | ... O21: =HLOOKUP(O$19,'W час'!$E$4:$AF$5,2,FALSE) -> #N/A
C22: =MAX(C$20:C21)+1 -> 3 | D22: Мощность привода вращателя (в расчете) | E22: кВт | F22: =SUMIFS('W час'!$E$22:$AF$22,'W час'!$E$4:$AF$4,F$19) -> 120 | G22: =SUMIFS('W час'!$E$22:$AF$22,'W час'!$E$4:$AF$4,G$19) -> 0 | H22: =SUMIFS('W час'!$E$22:$AF$22,'W час'!$E$4:$AF$4,H$19) -> 0 | I22: =SUMIFS('W час'!$E$22:$AF$22,'W час'!$E$4:$AF$4,I$19) -> 0 | J22: =SUMIFS('W час'!$E$22:$AF$22,'W час'!$E$4:$AF$4,J$19) -> 0 | K22: =SUMIFS('W час'!$E$22:$AF$22,'W час'!$E$4:$AF$4,K$19) -> 0 | L22: =SUMIFS('W час'!$E$22:$AF$22,'W час'!$E$4:$AF$4,L$19) -> 0 | M22: =SUMIFS('W час'!$E$22:$AF$22,'W час'!$E$4:$AF$4,M$19) -> 0 | ... O22: =SUMIFS('W час'!$E$22:$AF$22,'W час'!$E$4:$AF$4,O$19) -> 0
C23: =MAX(C$20:C22)+1 -> 4 | D23: Срок эксплуатации | E23: лет | F23: =SUMIFS(Производительность!$Y$7:$Y$34,Производительность!$C$7:$C$34,F$19) -> 0 | G23: =SUMIFS(Производительность!$Y$7:$Y$34,Производительность!$C$7:$C$34,G$19) -> 0 | H23: =SUMIFS(Производительность!$Y$7:$Y$34,Производительность!$C$7:$C$34,H$19) -> 0 | I23: =SUMIFS(Производительность!$Y$7:$Y$34,Производительность!$C$7:$C$34,I$19) -> 0 | J23: =SUMIFS(Производительность!$Y$7:$Y$34,Производительность!$C$7:$C$34,J$19) -> 0 | K23: =SUMIFS(Производительность!$Y$7:$Y$34,Производительность!$C$7:$C$34,K$19) -> 0 | L23: =SUMIFS(Производительность!$Y$7:$Y$34,Производительность!$C$7:$C$34,L$19) -> 0 | M23: =SUMIFS(Производительность!$Y$7:$Y$34,Производительность!$C$7:$C$34,M$19) -> 0 | ... O23: =SUMIFS(Производительность!$Y$7:$Y$34,Производительность!$C$7:$C$34,O$19) -> 0
C24: =MAX(C$20:C23)+1 -> 5 | D24: КТГ (средний за эксплуатацию) | E24: коэфф. | F24: =SUMIFS(Производительность!$Z$7:$Z$34,Производительность!$C$7:$C$34,F$19) -> #DIV/0! | G24: =SUMIFS(Производительность!$Z$7:$Z$34,Производительность!$C$7:$C$34,G$19) -> 0 | H24: =SUMIFS(Производительность!$Z$7:$Z$34,Производительность!$C$7:$C$34,H$19) -> 0 | I24: =SUMIFS(Производительность!$Z$7:$Z$34,Производительность!$C$7:$C$34,I$19) -> 0 | J24: =SUMIFS(Производительность!$Z$7:$Z$34,Производительность!$C$7:$C$34,J$19) -> 0 | K24: =SUMIFS(Производительность!$Z$7:$Z$34,Производительность!$C$7:$C$34,K$19) -> 0 | L24: =SUMIFS(Производительность!$Z$7:$Z$34,Производительность!$C$7:$C$34,L$19) -> 0 | M24: =SUMIFS(Производительность!$Z$7:$Z$34,Производительность!$C$7:$C$34,M$19) -> 0 | ... O24: =SUMIFS(Производительность!$Z$7:$Z$34,Производительность!$C$7:$C$34,O$19) -> 0
C25: =MAX(C$20:C24)+1 -> 6 | D25: КТГ (1-й год) | E25: =E24 -> коэфф. | F25: =SUMIFS(Производительность!$E$7:$E$34,Производительность!$C$7:$C$34,F$19) -> 0 | G25: =SUMIFS(Производительность!$E$7:$E$34,Производительность!$C$7:$C$34,G$19) -> 0 | H25: =SUMIFS(Производительность!$E$7:$E$34,Производительность!$C$7:$C$34,H$19) -> 0 | I25: =SUMIFS(Производительность!$E$7:$E$34,Производительность!$C$7:$C$34,I$19) -> 0 | J25: =SUMIFS(Производительность!$E$7:$E$34,Производительность!$C$7:$C$34,J$19) -> 0 | K25: =SUMIFS(Производительность!$E$7:$E$34,Производительность!$C$7:$C$34,K$19) -> 0 | L25: =SUMIFS(Производительность!$E$7:$E$34,Производительность!$C$7:$C$34,L$19) -> 0 | M25: =SUMIFS(Производительность!$E$7:$E$34,Производительность!$C$7:$C$34,M$19) -> 0 | ... O25: =SUMIFS(Производительность!$E$7:$E$34,Производительность!$C$7:$C$34,O$19) -> 0
C26: =MAX(C$20:C25)+1 -> 7 | D26: КИО (средний за эксплуатацию) | E26: =E24 -> коэфф. | F26: =SUMIFS(Производительность!$Z$115:$Z$142,Производительность!$C$115:$C$142,F$19) -> #DIV/0! | G26: =SUMIFS(Производительность!$Z$115:$Z$142,Производительность!$C$115:$C$142,G$19) -> 0 | H26: =SUMIFS(Производительность!$Z$115:$Z$142,Производительность!$C$115:$C$142,H$19) -> 0 | I26: =SUMIFS(Производительность!$Z$115:$Z$142,Производительность!$C$115:$C$142,I$19) -> 0 | J26: =SUMIFS(Производительность!$Z$115:$Z$142,Производительность!$C$115:$C$142,J$19) -> 0 | K26: =SUMIFS(Производительность!$Z$115:$Z$142,Производительность!$C$115:$C$142,K$19) -> 0 | L26: =SUMIFS(Производительность!$Z$115:$Z$142,Производительность!$C$115:$C$142,L$19) -> 0 | M26: =SUMIFS(Производительность!$Z$115:$Z$142,Производительность!$C$115:$C$142,M$19) -> 0 | ... O26: =SUMIFS(Производительность!$Z$115:$Z$142,Производительность!$C$115:$C$142,O$19) -> 0
C27: =MAX(C$20:C26)+1 -> 8 | D27: Часовая производительность | E27: п. м/час | F27: =SUMIFS(Производительность!$E$169:$E$196,Производительность!$C$169:$C$196,F$19) -> 14.098448 | G27: =SUMIFS(Производительность!$E$169:$E$196,Производительность!$C$169:$C$196,G$19) -> 0 | H27: =SUMIFS(Производительность!$E$169:$E$196,Производительность!$C$169:$C$196,H$19) -> 0 | I27: =SUMIFS(Производительность!$E$169:$E$196,Производительность!$C$169:$C$196,I$19) -> 0 | J27: =SUMIFS(Производительность!$E$169:$E$196,Производительность!$C$169:$C$196,J$19) -> 0 | K27: =SUMIFS(Производительность!$E$169:$E$196,Производительность!$C$169:$C$196,K$19) -> 0 | L27: =SUMIFS(Производительность!$E$169:$E$196,Производительность!$C$169:$C$196,L$19) -> 0 | M27: =SUMIFS(Производительность!$E$169:$E$196,Производительность!$C$169:$C$196,M$19) -> 0 | ... O27: =SUMIFS(Производительность!$E$169:$E$196,Производительность!$C$169:$C$196,O$19) -> 0
C28: =MAX(C$20:C27)+1 -> 9 | D28: Производительность (средняя за эксплуатацию) | E28: тыс. п. м | F28: =SUMIFS(Производительность!$Z$196:$Z$223,Производительность!$C$196:$C$223,F$19) -> #DIV/0! | G28: =SUMIFS(Производительность!$Z$196:$Z$223,Производительность!$C$196:$C$223,G$19) -> 0 | H28: =SUMIFS(Производительность!$Z$196:$Z$223,Производительность!$C$196:$C$223,H$19) -> 0 | I28: =SUMIFS(Производительность!$Z$196:$Z$223,Производительность!$C$196:$C$223,I$19) -> 0 | J28: =SUMIFS(Производительность!$Z$196:$Z$223,Производительность!$C$196:$C$223,J$19) -> 0 | K28: =SUMIFS(Производительность!$Z$196:$Z$223,Производительность!$C$196:$C$223,K$19) -> 0 | L28: =SUMIFS(Производительность!$Z$196:$Z$223,Производительность!$C$196:$C$223,L$19) -> 0 | M28: =SUMIFS(Производительность!$Z$196:$Z$223,Производительность!$C$196:$C$223,M$19) -> 0 | ... O28: =SUMIFS(Производительность!$Z$196:$Z$223,Производительность!$C$196:$C$223,O$19) -> 0
C29: =MAX(C$20:C28)+1 -> 10 | E29: тыс. м3 | F29: =SUMIFS(Производительность!$Z$250:$Z$277,Производительность!$C$250:$C$277,F$19) -> #DIV/0! | G29: =SUMIFS(Производительность!$Z$250:$Z$277,Производительность!$C$250:$C$277,G$19) -> 0 | H29: =SUMIFS(Производительность!$Z$250:$Z$277,Производительность!$C$250:$C$277,H$19) -> 0 | I29: =SUMIFS(Производительность!$Z$250:$Z$277,Производительность!$C$250:$C$277,I$19) -> 0 | J29: =SUMIFS(Производительность!$Z$250:$Z$277,Производительность!$C$250:$C$277,J$19) -> 0 | K29: =SUMIFS(Производительность!$Z$250:$Z$277,Производительность!$C$250:$C$277,K$19) -> 0 | L29: =SUMIFS(Производительность!$Z$250:$Z$277,Производительность!$C$250:$C$277,L$19) -> 0 | M29: =SUMIFS(Производительность!$Z$250:$Z$277,Производительность!$C$250:$C$277,M$19) -> 0 | ... O29: =SUMIFS(Производительность!$Z$250:$Z$277,Производительность!$C$250:$C$277,O$19) -> 0
C30: =MAX(C$20:C29)+1 -> 11 | D30: Производительность (1-й год) | E30: =E28 -> тыс. п. м | F30: =SUMIFS(Производительность!$E$196:$E$223,Производительность!$C$196:$C$223,F$19) -> 0 | G30: =SUMIFS(Производительность!$E$196:$E$223,Производительность!$C$196:$C$223,G$19) -> 0 | H30: =SUMIFS(Производительность!$E$196:$E$223,Производительность!$C$196:$C$223,H$19) -> 0 | I30: =SUMIFS(Производительность!$E$196:$E$223,Производительность!$C$196:$C$223,I$19) -> 0 | J30: =SUMIFS(Производительность!$E$196:$E$223,Производительность!$C$196:$C$223,J$19) -> 0 | K30: =SUMIFS(Производительность!$E$196:$E$223,Производительность!$C$196:$C$223,K$19) -> 0 | L30: =SUMIFS(Производительность!$E$196:$E$223,Производительность!$C$196:$C$223,L$19) -> 0 | M30: =SUMIFS(Производительность!$E$196:$E$223,Производительность!$C$196:$C$223,M$19) -> 0 | ... O30: =SUMIFS(Производительность!$E$196:$E$223,Производительность!$C$196:$C$223,O$19) -> 0
C31: =MAX(C$20:C30)+1 -> 12 | E31: =E29 -> тыс. м3 | F31: =SUMIFS(Производительность!$E$250:$E$277,Производительность!$C$250:$C$277,F$19) -> 0 | G31: =SUMIFS(Производительность!$E$250:$E$277,Производительность!$C$250:$C$277,G$19) -> 0 | H31: =SUMIFS(Производительность!$E$250:$E$277,Производительность!$C$250:$C$277,H$19) -> 0 | I31: =SUMIFS(Производительность!$E$250:$E$277,Производительность!$C$250:$C$277,I$19) -> 0 | J31: =SUMIFS(Производительность!$E$250:$E$277,Производительность!$C$250:$C$277,J$19) -> 0 | K31: =SUMIFS(Производительность!$E$250:$E$277,Производительность!$C$250:$C$277,K$19) -> 0 | L31: =SUMIFS(Производительность!$E$250:$E$277,Производительность!$C$250:$C$277,L$19) -> 0 | M31: =SUMIFS(Производительность!$E$250:$E$277,Производительность!$C$250:$C$277,M$19) -> 0 | ... O31: =SUMIFS(Производительность!$E$250:$E$277,Производительность!$C$250:$C$277,O$19) -> 0
C33: =MAX(C$20:C32)+1 -> 13 | D33: Стоимость станка | E33: тыс. руб. | F33: =F37+F38 -> 0 | G33: =G37+G38 -> 0 | H33: =H37+H38 -> 0 | I33: =I37+I38 -> 0 | J33: =J37+J38 -> 0 | K33: =K37+K38 -> 0 | L33: =L37+L38 -> 0 | M33: =M37+M38 -> 0 | ... O33: =O37+O38 -> 0 | R33: ='Свод_250-270_диз'!R33 -> курс ЦБ на хх.07.2026
A34: заполнить | C34: =MAX(C$20:C33)+1 -> 14 | D34: Цена в долларах | E34: тыс. долл. | R34: ='Свод_250-270_диз'!R34 -> 80
A35: заполнить | C35: =MAX(C$20:C34)+1 -> 15 | D35: Цена в евро | E35: тыс. евро | R35: ='Свод_250-270_диз'!R35 -> 90
A36: заполнить | C36: =MAX(C$20:C35)+1 -> 16 | D36: Цена в юанях | E36: тыс. юаней | R36: ='Свод_250-270_диз'!R36 -> 11
A37: заполнить | C37: =MAX(C$20:C36)+1 -> 17 | D37: Цена в рублях | E37: =E33 -> тыс. руб.
A38: заполнить | C38: =MAX(C$20:C37)+1 -> 18 | D38: Сборка | E38: =E33 -> тыс. руб.
A40: заполнить | C40: =MAX(C$20:C39)+1 -> 19 | D40: Потребность | E40: ед.
C41: =MAX(C$20:C40)+1 -> 20 | D41: CAPEX на потребность | E41: =E33 -> тыс. руб. | F41: =F40*F33 -> 0 | G41: =G40*G33 -> 0 | H41: =H40*H33 -> 0 | I41: =I40*I33 -> 0 | J41: =J40*J33 -> 0 | K41: =K40*K33 -> 0 | L41: =L40*L33 -> 0 | M41: =M40*M33 -> 0 | ... O41: =O40*O33 -> 0
C43: =MAX(C$20:C42)+1 -> 21 | D43: Среднегодовые затраты на ТО (включая смазочные) и ремонты | E43: тыс. руб. | F43: =SUMIFS('ТСО_250-270_эл'!$AB:$AB,'ТСО_250-270_эл'!$A:$A,F$19) -> #DIV/0! | G43: =SUMIFS('ТСО_250-270_эл'!$AB:$AB,'ТСО_250-270_эл'!$A:$A,G$19) -> 0 | H43: =SUMIFS('ТСО_250-270_эл'!$AB:$AB,'ТСО_250-270_эл'!$A:$A,H$19) -> 0 | I43: =SUMIFS('ТСО_250-270_эл'!$AB:$AB,'ТСО_250-270_эл'!$A:$A,I$19) -> 0 | J43: =SUMIFS('ТСО_250-270_эл'!$AB:$AB,'ТСО_250-270_эл'!$A:$A,J$19) -> 0 | K43: =SUMIFS('ТСО_250-270_эл'!$AB:$AB,'ТСО_250-270_эл'!$A:$A,K$19) -> 0 | L43: =SUMIFS('ТСО_250-270_эл'!$AB:$AB,'ТСО_250-270_эл'!$A:$A,L$19) -> 0 | M43: =SUMIFS('ТСО_250-270_эл'!$AB:$AB,'ТСО_250-270_эл'!$A:$A,M$19) -> 0 | ... O43: =SUMIFS('ТСО_250-270_эл'!$AB:$AB,'ТСО_250-270_эл'!$A:$A,O$19) -> 0
A45: ='ТСО_250-270_эл'!B87 -> Аннуитет операционный | C45: =MAX(C$20:C44)+1 -> 22 | D45: ='ТСО_250-270_эл'!D87 -> Аннуитет операционный | E45: ='ТСО_250-270_эл'!E87 -> руб/м3 | F45: =SUMIFS('ТСО_250-270_эл'!$AC:$AC,'ТСО_250-270_эл'!$A:$A,F$19,'ТСО_250-270_эл'!$B:$B,$A45) -> #DIV/0! | G45: =SUMIFS('ТСО_250-270_эл'!$AC:$AC,'ТСО_250-270_эл'!$A:$A,G$19,'ТСО_250-270_эл'!$B:$B,$A45) -> 0 | H45: =SUMIFS('ТСО_250-270_эл'!$AC:$AC,'ТСО_250-270_эл'!$A:$A,H$19,'ТСО_250-270_эл'!$B:$B,$A45) -> 0 | I45: =SUMIFS('ТСО_250-270_эл'!$AC:$AC,'ТСО_250-270_эл'!$A:$A,I$19,'ТСО_250-270_эл'!$B:$B,$A45) -> 0 | J45: =SUMIFS('ТСО_250-270_эл'!$AC:$AC,'ТСО_250-270_эл'!$A:$A,J$19,'ТСО_250-270_эл'!$B:$B,$A45) -> 0 | K45: =SUMIFS('ТСО_250-270_эл'!$AC:$AC,'ТСО_250-270_эл'!$A:$A,K$19,'ТСО_250-270_эл'!$B:$B,$A45) -> 0 | L45: =SUMIFS('ТСО_250-270_эл'!$AC:$AC,'ТСО_250-270_эл'!$A:$A,L$19,'ТСО_250-270_эл'!$B:$B,$A45) -> 0 | M45: =SUMIFS('ТСО_250-270_эл'!$AC:$AC,'ТСО_250-270_эл'!$A:$A,M$19,'ТСО_250-270_эл'!$B:$B,$A45) -> 0 | ... O45: =SUMIFS('ТСО_250-270_эл'!$AC:$AC,'ТСО_250-270_эл'!$A:$A,O$19,'ТСО_250-270_эл'!$B:$B,$A45) -> 0
A46: ='ТСО_250-270_эл'!B88 -> ТО, ТР, ППР | C46: =MAX(C$20:C45)+1 -> 23 | D46: ='ТСО_250-270_эл'!D88 -> ТО, ТР, ППР | E46: ='ТСО_250-270_эл'!E88 -> руб/м3 | F46: =SUMIFS('ТСО_250-270_эл'!$AC:$AC,'ТСО_250-270_эл'!$A:$A,F$19,'ТСО_250-270_эл'!$B:$B,$A46) -> #DIV/0! | G46: =SUMIFS('ТСО_250-270_эл'!$AC:$AC,'ТСО_250-270_эл'!$A:$A,G$19,'ТСО_250-270_эл'!$B:$B,$A46) -> 0 | H46: =SUMIFS('ТСО_250-270_эл'!$AC:$AC,'ТСО_250-270_эл'!$A:$A,H$19,'ТСО_250-270_эл'!$B:$B,$A46) -> 0 | I46: =SUMIFS('ТСО_250-270_эл'!$AC:$AC,'ТСО_250-270_эл'!$A:$A,I$19,'ТСО_250-270_эл'!$B:$B,$A46) -> 0 | J46: =SUMIFS('ТСО_250-270_эл'!$AC:$AC,'ТСО_250-270_эл'!$A:$A,J$19,'ТСО_250-270_эл'!$B:$B,$A46) -> 0 | K46: =SUMIFS('ТСО_250-270_эл'!$AC:$AC,'ТСО_250-270_эл'!$A:$A,K$19,'ТСО_250-270_эл'!$B:$B,$A46) -> 0 | L46: =SUMIFS('ТСО_250-270_эл'!$AC:$AC,'ТСО_250-270_эл'!$A:$A,L$19,'ТСО_250-270_эл'!$B:$B,$A46) -> 0 | M46: =SUMIFS('ТСО_250-270_эл'!$AC:$AC,'ТСО_250-270_эл'!$A:$A,M$19,'ТСО_250-270_эл'!$B:$B,$A46) -> 0 | ... O46: =SUMIFS('ТСО_250-270_эл'!$AC:$AC,'ТСО_250-270_эл'!$A:$A,O$19,'ТСО_250-270_эл'!$B:$B,$A46) -> 0
A47: ='ТСО_250-270_эл'!B89 -> Смазочные | C47: =MAX(C$20:C46)+1 -> 24 | D47: ='ТСО_250-270_эл'!D89 -> Смазочные | E47: ='ТСО_250-270_эл'!E89 -> руб/м3 | F47: =SUMIFS('ТСО_250-270_эл'!$AC:$AC,'ТСО_250-270_эл'!$A:$A,F$19,'ТСО_250-270_эл'!$B:$B,$A47) -> #DIV/0! | G47: =SUMIFS('ТСО_250-270_эл'!$AC:$AC,'ТСО_250-270_эл'!$A:$A,G$19,'ТСО_250-270_эл'!$B:$B,$A47) -> 0 | H47: =SUMIFS('ТСО_250-270_эл'!$AC:$AC,'ТСО_250-270_эл'!$A:$A,H$19,'ТСО_250-270_эл'!$B:$B,$A47) -> 0 | I47: =SUMIFS('ТСО_250-270_эл'!$AC:$AC,'ТСО_250-270_эл'!$A:$A,I$19,'ТСО_250-270_эл'!$B:$B,$A47) -> 0 | J47: =SUMIFS('ТСО_250-270_эл'!$AC:$AC,'ТСО_250-270_эл'!$A:$A,J$19,'ТСО_250-270_эл'!$B:$B,$A47) -> 0 | K47: =SUMIFS('ТСО_250-270_эл'!$AC:$AC,'ТСО_250-270_эл'!$A:$A,K$19,'ТСО_250-270_эл'!$B:$B,$A47) -> 0 | L47: =SUMIFS('ТСО_250-270_эл'!$AC:$AC,'ТСО_250-270_эл'!$A:$A,L$19,'ТСО_250-270_эл'!$B:$B,$A47) -> 0 | M47: =SUMIFS('ТСО_250-270_эл'!$AC:$AC,'ТСО_250-270_эл'!$A:$A,M$19,'ТСО_250-270_эл'!$B:$B,$A47) -> 0 | ... O47: =SUMIFS('ТСО_250-270_эл'!$AC:$AC,'ТСО_250-270_эл'!$A:$A,O$19,'ТСО_250-270_эл'!$B:$B,$A47) -> 0
A48: ='ТСО_250-270_эл'!B90 -> Долота | C48: =MAX(C$20:C47)+1 -> 25 | D48: ='ТСО_250-270_эл'!D90 -> Долота | E48: ='ТСО_250-270_эл'!E90 -> руб/м3 | F48: =SUMIFS('ТСО_250-270_эл'!$AC:$AC,'ТСО_250-270_эл'!$A:$A,F$19,'ТСО_250-270_эл'!$B:$B,$A48) -> #DIV/0! | G48: =SUMIFS('ТСО_250-270_эл'!$AC:$AC,'ТСО_250-270_эл'!$A:$A,G$19,'ТСО_250-270_эл'!$B:$B,$A48) -> 0 | H48: =SUMIFS('ТСО_250-270_эл'!$AC:$AC,'ТСО_250-270_эл'!$A:$A,H$19,'ТСО_250-270_эл'!$B:$B,$A48) -> 0 | I48: =SUMIFS('ТСО_250-270_эл'!$AC:$AC,'ТСО_250-270_эл'!$A:$A,I$19,'ТСО_250-270_эл'!$B:$B,$A48) -> 0 | J48: =SUMIFS('ТСО_250-270_эл'!$AC:$AC,'ТСО_250-270_эл'!$A:$A,J$19,'ТСО_250-270_эл'!$B:$B,$A48) -> 0 | K48: =SUMIFS('ТСО_250-270_эл'!$AC:$AC,'ТСО_250-270_эл'!$A:$A,K$19,'ТСО_250-270_эл'!$B:$B,$A48) -> 0 | L48: =SUMIFS('ТСО_250-270_эл'!$AC:$AC,'ТСО_250-270_эл'!$A:$A,L$19,'ТСО_250-270_эл'!$B:$B,$A48) -> 0 | M48: =SUMIFS('ТСО_250-270_эл'!$AC:$AC,'ТСО_250-270_эл'!$A:$A,M$19,'ТСО_250-270_эл'!$B:$B,$A48) -> 0 | ... O48: =SUMIFS('ТСО_250-270_эл'!$AC:$AC,'ТСО_250-270_эл'!$A:$A,O$19,'ТСО_250-270_эл'!$B:$B,$A48) -> 0
...

Sheet ТСО_250-270_эл
A1: не удалять | B1: не удалять | C1: не удалять | D1: Показатель | E1: Ед. изм. | F1: =G1-1 -> 0 | G1: 1 | H1: =G1+1 -> 2 | I1: =H1+1 -> 3 | J1: =I1+1 -> 4 | K1: =J1+1 -> 5 | L1: =K1+1 -> 6 | M1: =L1+1 -> 7 | N1: =M1+1 -> 8 | O1: =N1+1 -> 9 | ... Z1: =Y1+1 -> 20 | AA1: не удалять | AB1: не удалять | AC1: не удалять
A2: * | F2: лет | G2: 2027 | H2: =G2+1 -> 2028 | I2: =H2+1 -> 2029 | J2: =I2+1 -> 2030 | K2: =J2+1 -> 2031 | L2: =K2+1 -> 2032 | M2: =L2+1 -> 2033 | N2: =M2+1 -> 2034 | O2: =N2+1 -> 2035 | ... Z2: =Y2+1 -> 2046 | AA2: проверки | AB2: средние на ТО, ТР, ППР | AC2: аннуитет
A3: * | G3: =Производительность!E6 -> 8760 | H3: =Производительность!F6 -> 8760 | I3: =Производительность!G6 -> 8760 | J3: =Производительность!H6 -> 8760 | K3: =Производительность!I6 -> 8760 | L3: =Производительность!J6 -> 8760 | M3: =Производительность!K6 -> 8760 | N3: =Производительность!L6 -> 8760 | ... Z3: =Производительность!X6 -> 8760
A4: * | D4: Расчет аннуитета
A5: *
A6: * | C6: =SUM(F66:Z66,F80:Z80,F101:Z101,AA48) -> #DIV/0! | D6: ='Свод_250-270_эл'!F19 -> СБШ-250/270КП | E6: =SUMIFS(Производительность!$Y$7:$Y$34,Производительность!$C$7:$C$34,$D6) -> 0 | F6: =$F$2 -> лет
A7: *
A8: =D6 -> СБШ-250/270КП | D8: =D$1 -> Показатель | E8: =E$1 -> Ед. изм. | F8: =F$1 -> 0 | G8: =G$1 -> 1 | H8: =H$1 -> 2 | I8: =I$1 -> 3 | J8: =J$1 -> 4 | K8: =K$1 -> 5 | ... Z8: =Z$1 -> 20
A9: =A8 -> СБШ-250/270КП | D9: КТГ | E9: % | G9: =SUMIFS(Производительность!E$7:E$34,Производительность!$C$7:$C$34,$A9) -> 0 | H9: =SUMIFS(Производительность!F$7:F$34,Производительность!$C$7:$C$34,$A9) -> 0 | I9: =SUMIFS(Производительность!G$7:G$34,Производительность!$C$7:$C$34,$A9) -> 0 | J9: =SUMIFS(Производительность!H$7:H$34,Производительность!$C$7:$C$34,$A9) -> 0 | K9: =SUMIFS(Производительность!I$7:I$34,Производительность!$C$7:$C$34,$A9) -> 0 | L9: =SUMIFS(Производительность!J$7:J$34,Производительность!$C$7:$C$34,$A9) -> 0 | M9: =SUMIFS(Производительность!K$7:K$34,Производительность!$C$7:$C$34,$A9) -> 0 | N9: =SUMIFS(Производительность!L$7:L$34,Производительность!$C$7:$C$34,$A9) -> 0 | ... Z9: =SUMIFS(Производительность!X$7:X$34,Производительность!$C$7:$C$34,$A9) -> 0
A10: =A9 -> СБШ-250/270КП | D10: КИО | E10: =E9 -> % | G10: =SUMIFS(Производительность!E$115:E$142,Производительность!$C$115:$C$142,$A10) -> 0 | H10: =SUMIFS(Производительность!F$115:F$142,Производительность!$C$115:$C$142,$A10) -> 0 | I10: =SUMIFS(Производительность!G$115:G$142,Производительность!$C$115:$C$142,$A10) -> 0 | J10: =SUMIFS(Производительность!H$115:H$142,Производительность!$C$115:$C$142,$A10) -> 0 | K10: =SUMIFS(Производительность!I$115:I$142,Производительность!$C$115:$C$142,$A10) -> 0 | L10: =SUMIFS(Производительность!J$115:J$142,Производительность!$C$115:$C$142,$A10) -> 0 | M10: =SUMIFS(Производительность!K$115:K$142,Производительность!$C$115:$C$142,$A10) -> 0 | N10: =SUMIFS(Производительность!L$115:L$142,Производительность!$C$115:$C$142,$A10) -> 0 | ... Z10: =SUMIFS(Производительность!X$115:X$142,Производительность!$C$115:$C$142,$A10) -> 0
A11: =A10 -> СБШ-250/270КП | D11: Производительность_бурение | E11: тыс. п. м | G11: =SUMIFS(Производительность!E$196:E$223,Производительность!$C$196:$C$223,$A11) -> 0 | H11: =SUMIFS(Производительность!F$196:F$223,Производительность!$C$196:$C$223,$A11) -> 0 | I11: =SUMIFS(Производительность!G$196:G$223,Производительность!$C$196:$C$223,$A11) -> 0 | J11: =SUMIFS(Производительность!H$196:H$223,Производительность!$C$196:$C$223,$A11) -> 0 | K11: =SUMIFS(Производительность!I$196:I$223,Производительность!$C$196:$C$223,$A11) -> 0 | L11: =SUMIFS(Производительность!J$196:J$223,Производительность!$C$196:$C$223,$A11) -> 0 | M11: =SUMIFS(Производительность!K$196:K$223,Производительность!$C$196:$C$223,$A11) -> 0 | N11: =SUMIFS(Производительность!L$196:L$223,Производительность!$C$196:$C$223,$A11) -> 0 | ... Z11: =SUMIFS(Производительность!X$196:X$223,Производительность!$C$196:$C$223,$A11) -> 0
A12: =A11 -> СБШ-250/270КП | D12: Производительность_взрывание | E12: тыс. м3 | G12: =SUMIFS(Производительность!E$250:E$277,Производительность!$C$250:$C$277,$A12) -> 0 | H12: =SUMIFS(Производительность!F$250:F$277,Производительность!$C$250:$C$277,$A12) -> 0 | I12: =SUMIFS(Производительность!G$250:G$277,Производительность!$C$250:$C$277,$A12) -> 0 | J12: =SUMIFS(Производительность!H$250:H$277,Производительность!$C$250:$C$277,$A12) -> 0 | K12: =SUMIFS(Производительность!I$250:I$277,Производительность!$C$250:$C$277,$A12) -> 0 | L12: =SUMIFS(Производительность!J$250:J$277,Производительность!$C$250:$C$277,$A12) -> 0 | M12: =SUMIFS(Производительность!K$250:K$277,Производительность!$C$250:$C$277,$A12) -> 0 | N12: =SUMIFS(Производительность!L$250:L$277,Производительность!$C$250:$C$277,$A12) -> 0 | ... Z12: =SUMIFS(Производительность!X$250:X$277,Производительность!$C$250:$C$277,$A12) -> 0
