Workbook

Sheet 1
A2: Гончарова Марина Алексеевна | B2: Группа отчетности по заработной плате | C2: Руководитель группы
A3: Макаенко Анастасия Леонидовна | B3: Отдел специальной оценки условий труда и оценки профессиональных | C3: Начальник отдела
A5: 0.3 | B5: основной единый тариф страховых взносов
A6: 0.037 | B6: НС, без скидки
B7: страховые взносы по дополнительному тарифу:
A8: 0.04 | B8: оценка труда, 3.2
A9: 0.02 | B9: оценка труда, 3.1
A12: Власенко Светлана Леонидовна | B12: Дирекция по экономике и финансам | C12: Старший бизнес-партнер
A14: Давыденко Сергей Александрович | B14: Дирекция по персоналу | C14: Бизнес-партнер по управлению персоналом

Sheet Версии
B1: 1
B2: 1 | C2: Данные для расчета по варианту "Производство"
B3: 1
B4: 1 | C4: Модель | D4: г/п, т | E4: КИГ | F4: Вес, т | G4: Погрузка, мин | H4: Разгрузка, мин | I4: Норма топлива, г/ткм | J4: Пробег шин, тыс. км | K4: Эксплуатация, лет | L4: Техн скорость, км/час
B5: =IF(C5=0,0,1) -> 1 | C5: =Производительность_1!C24 -> NHL NTE 240 | D5: =Производительность_1!E24 -> 227.8 | E5: =Производительность_1!E40 -> 0.98371378 | F5: =Производительность_1!E24 -> 227.8 | G5: =Простои!AA9 -> 3.5 | H5: =Простои!AC9 -> 0.8 | I5: ='ФОТ, МТР, макро'!O5 -> 90 | J5: ='ФОТ, МТР, макро'!Y5 -> 80 | K5: =Производительность_1!Y56 -> 20 | L5: =Производительность_1!E152 -> 22.46
B6: =IF(C6=0,0,1) -> 1 | C6: =Производительность_1!C25 -> Estar ESDE240 (ГПБ К) | D6: =Производительность_1!E25 -> 211.392 | E6: =Производительность_1!E41 -> 0.98371378 | F6: =Производительность_1!E25 -> 211.392 | G6: =Простои!AA10 -> 3.5 | H6: =Простои!AC10 -> 0.8 | I6: ='ФОТ, МТР, макро'!O6 -> 90 | J6: ='ФОТ, МТР, макро'!Y6 -> 80 | K6: =Производительность_1!Y57 -> 10 | L6: =Производительность_1!E153 -> 22.46
B7: =IF(C7=0,0,1) -> 1 | C7: =Производительность_1!C26 -> SANY SET240S | D7: =Производительность_1!E26 -> 216.362 | E7: =Производительность_1!E42 -> 0.98371378 | F7: =Производительность_1!E26 -> 216.362 | G7: =Простои!AA11 -> 3.5 | H7: =Простои!AC11 -> 0.8 | I7: ='ФОТ, МТР, макро'!O7 -> 90 | J7: ='ФОТ, МТР, макро'!Y7 -> 80 | K7: =Производительность_1!Y58 -> 12 | L7: =Производительность_1!E154 -> 22.46
B8: =IF(C8=0,0,1) -> 1 | C8: =Производительность_1!C27 -> TZCO TZE240 | D8: =Производительность_1!E27 -> 222 | E8: =Производительность_1!E43 -> 0.98371378 | F8: =Производительность_1!E27 -> 222 | G8: =Простои!AA12 -> 3.5 | H8: =Простои!AC12 -> 0.8 | I8: ='ФОТ, МТР, макро'!O8 -> 90 | J8: ='ФОТ, МТР, макро'!Y8 -> 80 | K8: =Производительность_1!Y59 -> 8 | L8: =Производительность_1!E155 -> 22.46
B9: =IF(C9=0,0,1) -> 1 | C9: =Производительность_1!C28 -> БелАЗ 7531 (ГПФК) | D9: =Производительность_1!E28 -> 231 | E9: =Производительность_1!E44 -> 0.98371378 | F9: =Производительность_1!E28 -> 231 | G9: =Простои!AA13 -> 3.5 | H9: =Простои!AC13 -> 0.8 | I9: ='ФОТ, МТР, макро'!O9 -> 90 | J9: ='ФОТ, МТР, макро'!Y9 -> 90 | K9: =Производительность_1!Y60 -> 10 | L9: =Производительность_1!E156 -> 22.46
B10: =IF(C10=0,0,1) -> 1 | C10: =Производительность_1!C29 -> XCMG 240 | D10: =Производительность_1!E29 -> 211.392 | E10: =Производительность_1!E45 -> 0.98371378 | F10: =Производительность_1!E29 -> 211.392 | G10: =Простои!AA14 -> 3.5 | H10: =Простои!AC14 -> 0.8 | I10: ='ФОТ, МТР, макро'!O10 -> 90 | J10: ='ФОТ, МТР, макро'!Y10 -> 80 | K10: =Производительность_1!Y61 -> 0 | L10: =Производительность_1!E157 -> 22.46
B11: =IF(C11=0,0,1) -> 1 | C11: =Производительность_1!C30 -> БелАЗ 7531 (БТЛ) | D11: =Производительность_1!E30 -> 231 | E11: =Производительность_1!E46 -> 0.98371378 | F11: =Производительность_1!E30 -> 231 | G11: =Простои!AA15 -> 3.5 | H11: =Простои!AC15 -> 0.8 | I11: ='ФОТ, МТР, макро'!O11 -> 90 | J11: ='ФОТ, МТР, макро'!Y11 -> 80 | K11: =Производительность_1!Y62 -> 10 | L11: =Производительность_1!E158 -> 22.46
B12: =IF(C12=0,0,1) -> 0 | C12: =Производительность_1!C31 -> 0 | D12: =Производительность_1!E31 -> 0 | E12: =Производительность_1!E47 -> 0 | F12: =Производительность_1!E31 -> 0 | G12: =Простои!AA16 -> 0 | H12: =Простои!AC16 -> 0 | I12: ='ФОТ, МТР, макро'!O12 -> 0 | J12: ='ФОТ, МТР, макро'!Y12 -> 0 | K12: =Производительность_1!Y63 -> 0 | L12: =Производительность_1!E159 -> 0
B13: =IF(C13=0,0,1) -> 0 | C13: =Производительность_1!C32 -> 0 | D13: =Производительность_1!E32 -> 0 | E13: =Производительность_1!E48 -> 0 | F13: =Производительность_1!E32 -> 0 | G13: =Простои!AA17 -> 0 | H13: =Простои!AC17 -> 0 | I13: ='ФОТ, МТР, макро'!O13 -> 0 | J13: ='ФОТ, МТР, макро'!Y13 -> 0 | K13: =Производительность_1!Y64 -> 0 | L13: =Производительность_1!E160 -> 0
B14: =IF(C14=0,0,1) -> 0 | C14: =Производительность_1!C33 -> 0 | D14: =Производительность_1!E33 -> 0 | E14: =Производительность_1!E49 -> 0 | F14: =Производительность_1!E33 -> 0 | G14: =Простои!AA18 -> 0 | H14: =Простои!AC18 -> 0 | I14: ='ФОТ, МТР, макро'!O14 -> 0 | J14: ='ФОТ, МТР, макро'!Y14 -> 0 | K14: =Производительность_1!Y65 -> 0 | L14: =Производительность_1!E161 -> 0
B15: =IF(C15=0,0,1) -> 0 | C15: =Производительность_1!C34 -> 0 | D15: =Производительность_1!E34 -> 0 | E15: =Производительность_1!E50 -> 0 | F15: =Производительность_1!E34 -> 0 | G15: =Простои!AA19 -> 0 | H15: =Простои!AC19 -> 0 | I15: ='ФОТ, МТР, макро'!O15 -> 0 | J15: ='ФОТ, МТР, макро'!Y15 -> 0 | K15: =Производительность_1!Y66 -> 0 | L15: =Производительность_1!E162 -> 0
B16: =IF(C16=0,0,1) -> 0 | C16: =Производительность_1!C35 -> 0 | D16: =Производительность_1!E35 -> 0 | E16: =Производительность_1!E51 -> 0 | F16: =Производительность_1!E35 -> 0 | G16: =Простои!AA20 -> 0 | H16: =Простои!AC20 -> 0 | I16: ='ФОТ, МТР, макро'!O16 -> 0 | J16: ='ФОТ, МТР, макро'!Y16 -> 0 | K16: =Производительность_1!Y67 -> 0 | L16: =Производительность_1!E163 -> 0
... B19: =IF(C19=0,0,1) -> 0 | C19: =Производительность_1!C38 -> 0 | D19: =Производительность_1!E38 -> 0 | E19: =Производительность_1!E54 -> 0 | F19: =Производительность_1!E38 -> 0 | G19: =Простои!AA23 -> 0 | H19: =Простои!AC23 -> 0 | I19: ='ФОТ, МТР, макро'!O19 -> 0 | J19: ='ФОТ, МТР, макро'!Y19 -> 0 | K19: =Производительность_1!Y70 -> 0 | L19: =Производительность_1!E166 -> 0
B20: 1
B21: 1
B22: 1
B23: 1 | C23: КТГ
B24: 1
B25: 1 | C25: КТГ по годам старения в расчете | D25: =Производительность_1!D4 -> Ед. изм. | E25: =Производительность_1!E4 -> 1 | F25: =Производительность_1!F4 -> 2 | G25: =Производительность_1!G4 -> 3 | H25: =Производительность_1!H4 -> 4 | I25: =Производительность_1!I4 -> 5 | J25: =Производительность_1!J4 -> 6 | K25: =Производительность_1!K4 -> 7 | ... X25: =Производительность_1!X4 -> 20 | Y25: Средний
B26: =B5 -> 1 | C26: =C5 -> NHL NTE 240 | D26: =Производительность_1!D56 -> коэфф. | E26: =Производительность_1!E56 -> 0.93755029 | F26: =Производительность_1!F56 -> 0.93038071 | G26: =Производительность_1!G56 -> 0.92090265 | H26: =Производительность_1!H56 -> 0.90840582 | I26: =Производительность_1!I56 -> 0.93333289 | J26: =Производительность_1!J56 -> 0.92172393 | K26: =Производительность_1!K56 -> 0.93126858 | ... X26: =Производительность_1!X56 -> 0.92201249 | Y26: =Производительность_1!Z56 -> 0.92288816 | Z26: =Производительность_1!AA56 -> 0
B27: =B6 -> 1 | C27: =C6 -> Estar ESDE240 (ГПБ К) | D27: =Производительность_1!D57 -> коэфф. | E27: =Производительность_1!E57 -> 0.91162481 | F27: =Производительность_1!F57 -> 0.89608701 | G27: =Производительность_1!G57 -> 0.84869673 | H27: =Производительность_1!H57 -> 0.80563483 | I27: =Производительность_1!I57 -> 0.89852867 | J27: =Производительность_1!J57 -> 0.8220605 | K27: =Производительность_1!K57 -> 0.88942796 | ... X27: =Производительность_1!X57 -> 0 | Y27: =Производительность_1!Z57 -> 0.8573313 | Z27: =Производительность_1!AA57 -> 0
B28: =B7 -> 1 | C28: =C7 -> SANY SET240S | D28: =Производительность_1!D58 -> коэфф. | E28: =Производительность_1!E58 -> 0.9357084 | F28: =Производительность_1!F58 -> 0.90263508 | G28: =Производительность_1!G58 -> 0.86578831 | H28: =Производительность_1!H58 -> 0.90352296 | I28: =Производительность_1!I58 -> 0.85025051 | J28: =Производительность_1!J58 -> 0.90352296 | K28: =Производительность_1!K58 -> 0.86578831 | ... X28: =Производительность_1!X58 -> 0 | Y28: =Производительность_1!Z58 -> 0.88337931 | Z28: =Производительность_1!AA58 -> 0
B29: =B8 -> 1 | C29: =C8 -> TZCO TZE240 | D29: =Производительность_1!D59 -> коэфф. | E29: =Производительность_1!E59 -> 0.90962709 | F29: =Производительность_1!F59 -> 0.88376776 | G29: =Производительность_1!G59 -> 0.77400431 | H29: =Производительность_1!H59 -> 0.88376776 | I29: =Производительность_1!I59 -> 0.90962709 | J29: =Производительность_1!J59 -> 0.74814498 | K29: =Производительность_1!K59 -> 0.90962709 | ... X29: =Производительность_1!X59 -> 0 | Y29: =Производительность_1!Z59 -> 0.86279173 | Z29: =Производительность_1!AA59 -> 0
B30: =B9 -> 1 | C30: =C9 -> БелАЗ 7531 (ГПФК) | D30: =Производительность_1!D60 -> коэфф. | E30: =Производительность_1!E60 -> 0.90830416 | F30: =Производительность_1!F60 -> 0.88577435 | G30: =Производительность_1!G60 -> 0.86468734 | H30: =Производительность_1!H60 -> 0.87460194 | I30: =Производительность_1!I60 -> 0.88129799 | J30: =Производительность_1!J60 -> 0.84567204 | K30: =Производительность_1!K60 -> 0.89713174 | ... X30: =Производительность_1!X60 -> 0 | Y30: =Производительность_1!Z60 -> 0.87156467 | Z30: =Производительность_1!AA60 -> 0
B31: =B10 -> 1 | C31: =C10 -> XCMG 240 | D31: =Производительность_1!D61 -> коэфф. | E31: =Производительность_1!E61 -> 0 | F31: =Производительность_1!F61 -> 0 | G31: =Производительность_1!G61 -> 0 | H31: =Производительность_1!H61 -> 0 | I31: =Производительность_1!I61 -> 0 | J31: =Производительность_1!J61 -> 0 | K31: =Производительность_1!K61 -> 0 | ... X31: =Производительность_1!X61 -> 0 | Y31: =Производительность_1!Z61 -> #DIV/0! | Z31: =Производительность_1!AA61 -> 0
B32: =B11 -> 1 | C32: =C11 -> БелАЗ 7531 (БТЛ) | D32: =Производительность_1!D62 -> коэфф. | E32: =Производительность_1!E62 -> 0.92956037 | F32: =Производительность_1!F62 -> 0.90792065 | G32: =Производительность_1!G62 -> 0.89941186 | H32: =Производительность_1!H62 -> 0.88050754 | I32: =Производительность_1!I62 -> 0.90115061 | J32: =Производительность_1!J62 -> 0.87025999 | K32: =Производительность_1!K62 -> 0.85058935 | ... X32: =Производительность_1!X62 -> 0 | Y32: =Производительность_1!Z62 -> 0.88411536 | Z32: =Производительность_1!AA62 -> 0
B33: =B12 -> 0 | C33: =C12 -> 0 | D33: =Производительность_1!D63 -> коэфф. | E33: =Производительность_1!E63 -> 0 | F33: =Производительность_1!F63 -> 0 | G33: =Производительность_1!G63 -> 0 | H33: =Производительность_1!H63 -> 0 | I33: =Производительность_1!I63 -> 0 | J33: =Производительность_1!J63 -> 0 | K33: =Производительность_1!K63 -> 0 | ... X33: =Производительность_1!X63 -> 0 | Y33: =Производительность_1!Z63 -> #DIV/0! | Z33: =Производительность_1!AA63 -> 0
B34: =B13 -> 0 | C34: =C13 -> 0 | D34: =Производительность_1!D64 -> коэфф. | E34: =Производительность_1!E64 -> 0 | F34: =Производительность_1!F64 -> 0 | G34: =Производительность_1!G64 -> 0 | H34: =Производительность_1!H64 -> 0 | I34: =Производительность_1!I64 -> 0 | J34: =Производительность_1!J64 -> 0 | K34: =Производительность_1!K64 -> 0 | ... X34: =Производительность_1!X64 -> 0 | Y34: =Производительность_1!Z64 -> #DIV/0! | Z34: =Производительность_1!AA64 -> 0
B35: =B14 -> 0 | C35: =C14 -> 0 | D35: =Производительность_1!D65 -> коэфф. | E35: =Производительность_1!E65 -> 0 | F35: =Производительность_1!F65 -> 0 | G35: =Производительность_1!G65 -> 0 | H35: =Производительность_1!H65 -> 0 | I35: =Производительность_1!I65 -> 0 | J35: =Производительность_1!J65 -> 0 | K35: =Производительность_1!K65 -> 0 | ... X35: =Производительность_1!X65 -> 0 | Y35: =Производительность_1!Z65 -> #DIV/0! | Z35: =Производительность_1!AA65 -> 0
B36: =B15 -> 0 | C36: =C15 -> 0 | D36: =Производительность_1!D66 -> коэфф. | E36: =Производительность_1!E66 -> 0 | F36: =Производительность_1!F66 -> 0 | G36: =Производительность_1!G66 -> 0 | H36: =Производительность_1!H66 -> 0 | I36: =Производительность_1!I66 -> 0 | J36: =Производительность_1!J66 -> 0 | K36: =Производительность_1!K66 -> 0 | ... X36: =Производительность_1!X66 -> 0 | Y36: =Производительность_1!Z66 -> #DIV/0! | Z36: =Производительность_1!AA66 -> 0
B37: =B16 -> 0 | C37: =C16 -> 0 | D37: =Производительность_1!D67 -> коэфф. | E37: =Производительность_1!E67 -> 0 | F37: =Производительность_1!F67 -> 0 | G37: =Производительность_1!G67 -> 0 | H37: =Производительность_1!H67 -> 0 | I37: =Производительность_1!I67 -> 0 | J37: =Производительность_1!J67 -> 0 | K37: =Производительность_1!K67 -> 0 | ... X37: =Производительность_1!X67 -> 0 | Y37: =Производительность_1!Z67 -> #DIV/0! | Z37: =Производительность_1!AA67 -> 0
... B40: =B19 -> 0 | C40: =C19 -> 0 | D40: =Производительность_1!D70 -> коэфф. | E40: =Производительность_1!E70 -> 0 | F40: =Производительность_1!F70 -> 0 | G40: =Производительность_1!G70 -> 0 | H40: =Производительность_1!H70 -> 0 | I40: =Производительность_1!I70 -> 0 | J40: =Производительность_1!J70 -> 0 | K40: =Производительность_1!K70 -> 0 | ... X40: =Производительность_1!X70 -> 0 | Y40: =Производительность_1!Z70 -> #DIV/0! | Z40: =Производительность_1!AA70 -> 0
B41: =B20 -> 1
B42: 1
B43: 1 | C43: КТГ поставщиков (текущий тендер) | D43: =D25 -> Ед. изм. | E43: =E25 -> 1 | F43: =F25 -> 2 | G43: =G25 -> 3 | H43: =H25 -> 4 | I43: =I25 -> 5 | J43: =J25 -> 6 | K43: =K25 -> 7 | ... Y43: =Y25 -> Средний
B44: =B26 -> 1 | C44: =C26 -> NHL NTE 240 | D44: =D26 -> коэфф. | E44: =Производительность!E56 -> 0.93755029 | F44: =Производительность!F56 -> 0.93038071 | G44: =Производительность!G56 -> 0.92090265 | H44: =Производительность!H56 -> 0.90840582 | I44: =Производительность!I56 -> 0.93333289 | J44: =Производительность!J56 -> 0.92172393 | K44: =Производительность!K56 -> 0.93126858 | L44: =Производительность!L56 -> 0.91113604 | ... X44: =Производительность!X56 -> 0.92201249 | Y44: =Производительность!Z56 -> 0.92288816 | Z44: =Производительность!AA56 -> данные поставщика от 27.07.2026
...

Sheet Статус
C2: Все | D2: =Свод!F23 -> NHL NTE 240 | E2: =Свод!G23 -> Estar ESDE240 (ГПБ К) | F2: =Свод!H23 -> SANY SET240S | G2: =Свод!I23 -> TZCO TZE240 | H2: =Свод!J23 -> БелАЗ 7531 (ГПФК) | I2: =Свод!K23 -> XCMG 240 | J2: =Свод!L23 -> БелАЗ 7531 (БТЛ)
B3: Загрузка | C3: 07.07 - запросили политику загрузки с расчетом номинальной грузоподъемности, вес футеровки | D3: 09.07 - прислали политику; заданы вопросы (путаница в цифрах 220/240, 228/334) 10.07 - беру в расчет 227,8 (236 - 8,2 футеровка) пока нет иных данных | E3: 20.07 - прислали политику и схему футеровки | F3: 07.07 - прислали политику и вес стандартной футеровки 07.07 - запросили вес кузова с футеровкой под скальную спецификацию (с раскладкой листов в кузове, толщиной, весом и т.д.), отправили ТЗ на самосвал (по запросу) | G3: 15.07 - прислали политику, не прислали расчет номинальной; повторно запрошен | H3: 10.07 - ждут ответ от завода | J3: 22.07 - запросили расчет, политику
F4: 21.07 - прислали вес скального кузова; замечание Кузнецова В.Е. | G4: 16.07 - прислали расчет полезной нагрузки с учетом футеровки
F5: 22.07 - получен ответ
C6: долги | D6: Кузнецов В.Е., Михайлов А.С. - уточняют с поставщиком/заводом | H6: нет ответа от завода | J6: нет ответа
B7: Срок эксплуатации | C7: 07.07 - запрос (с ТСО) указать срок службы, установленный заводом-изготовителем (подтвердить документом) | D7: 29.07 - прислали письмо от завода (15-20 лет) | F7: 13.07 - прислали письмо о сроке службы (12 лет) | G7: 13.07 - по тексту письма: 8 лет | H7: 08.07 - прислали руководство; на встрече договорились, что запросят у завода 10.07 - ждут ответ от завода | J7: 22.07 - запросили
F8: 29.07 - еще раз прислали письмо, по запросу | G8: 29.07 - прислали письмо, 8 лет
C9: долги | E9: нет ответа, ТСО на 10 лет | H9: нет ответа от завода, ТСО на 10 лет | J9: нет ответа
B10: ТСО | C10: 25-26.06 - отправка шаблона для заполнения поставщикам | J10: 22.07 - прислали ТСО
C11: 03.07 - получены заполненные файлы от Михайлова А.С. (21:02) 06.07 - направлены в Развитие для оценки, Лысенко Д.В, Кузнецов В.Е. (09:11) | J11: 23.07 - принято (Кузнецов В.Е.)
C12: 07.07 - получены замечания от Развития, направлены поставщикам | D12: 1. КТГ завышен 2. Указать срок службы, установленный заводом-изготовителем (подтвердить документом) 3. Некорректная цикличность ТО – проверить и исправить 4. Текущие ремонты не заполнены 5. Реальные трудозатраты и текущие ремонты не оценены 6. Капитальные ремонты не досчитаны и не заполнены полностью 7. Стоимостные расчеты занижены | E12: 1. Текущие ремонты отсутствуют 2. Указать срок службы, установленный заводом-изготовителем (подтвердить документом) | F12: 1. Шины включены – исключить (указать стоимость дополнительно отдельно) 2. Неполное предоставление данных по затратам на КР | G12: 1. Цикличность – ок 2. Занижена станка н-часа 3. 5000H PERIODIC SERVICE(PM LABOR) - затраты в ТО не представлены 4. Автошины убрать (выделить стоимость) 5. Указать срок службы, установленный заводом-изготовителем (подтвердить документом) | H12: 1. Некорректная цикличность ТО (ТО-2 и ТО-3) – проверить и исправить 2. Исходя из цикличности проверить правильность расходников в ТО 3. Перепроверить периодичность КР узлов 4. Указать срок службы, установленный заводом-изготовителем (подтвердить документом) 5. КТГ завышен
D13: 08.07 - встреча с поставщиком (наши вопросы, как заполнять шаблон) | E13: 24.07 - прислали ТСО, берем в работу (Кузнецов В.Е.) | F13: 13.07 - прислали обновленный файл для обсуждения (встреча 13.07); на встрече обсудили вопросы, ждем данные для расчета с учетом замечаний (наработка узлов, завышен КТГ, не заполнены полностью часы простоя и трудоемкость) | G13: 13.07 - прислали ТСО; запрос: скорректировать на срок службы (8 лет)+замечания (трудозатраты и простои на КР, динамика КТГ с учетом КР) | H13: 08.07 - прислали руководство по эксплуатации БЕЛАЗ-7531; "Руководство во вложении, вы можете все перепроверить" 08.07 - встреча с поставщиком (наши вопросы, как заполнять шаблон)
D14: 14.07 - прислали ТСО с затратами на 35% меньше первой версии; замечания не исправлены, КТГ 0,94 на 20 лет; назначена встреча, еще раз обсудили замечания | F14: 16.07 - прислали ТСО, берем в работу (Кузнецов В.Е.) | G14: 15.07 - прислали ТСО, берем в работу (Кузнецов В.Е.) | H14: 09.07 - прислали данные, направлены вопросы (занижение ремонтов 7-й год (как результат, высокий КТГ), ремонты – не скорректирован ресурс до замены (обсуждали на встрече))
D15: 27.07 - прислали ТСО | H15: 10.07 - ответ, что данные корректны; берем в работу (Кузнецов В.Е.)
D16: 28.07 - отправили замечания, не правят; берем в работу что есть
C17: долги

Sheet Свод
C2: Технико-экономическая оценка стоимости владения
C4: Ранжирование общих аннуитетов - по возрастанию | G4: Ранжирование по стоимости самосвала - по возрастанию
C5: № | D5: Марка автосамосвала | E5: Аннуитет, руб/ткм | G5: =C5 -> № | H5: =D5 -> Марка автосамосвала | K5: Цена за ед., тыс. руб.
C6: 1 | D6: =IFERROR(HLOOKUP(E6,$F$64:$T$66,3,FALSE),"-") -> - | E6: =IFERROR(SMALL($F$64:$T$64,C6),"-") -> - | G6: =C6 -> 1 | H6: =IFERROR(HLOOKUP(K6,$F$65:$T$66,2,FALSE),"-") -> - | K6: =IFERROR(SMALL($F$65:$T$65,C6),"-") -> -
C7: =C6+1 -> 2 | D7: =IFERROR(HLOOKUP(E7,$F$64:$T$66,3,FALSE),"-") -> - | E7: =IFERROR(SMALL($F$64:$T$64,C7),"-") -> - | G7: =C7 -> 2 | H7: =IFERROR(HLOOKUP(K7,$F$65:$T$66,2,FALSE),"-") -> - | K7: =IFERROR(SMALL($F$65:$T$65,C7),"-") -> -
C8: =C7+1 -> 3 | D8: =IFERROR(HLOOKUP(E8,$F$64:$T$66,3,FALSE),"-") -> - | E8: =IFERROR(SMALL($F$64:$T$64,C8),"-") -> - | G8: =C8 -> 3 | H8: =IFERROR(HLOOKUP(K8,$F$65:$T$66,2,FALSE),"-") -> - | K8: =IFERROR(SMALL($F$65:$T$65,C8),"-") -> -
C9: =C8+1 -> 4 | D9: =IFERROR(HLOOKUP(E9,$F$64:$T$66,3,FALSE),"-") -> - | E9: =IFERROR(SMALL($F$64:$T$64,C9),"-") -> - | G9: =C9 -> 4 | H9: =IFERROR(HLOOKUP(K9,$F$65:$T$66,2,FALSE),"-") -> - | K9: =IFERROR(SMALL($F$65:$T$65,C9),"-") -> -
C10: =C9+1 -> 5 | D10: =IFERROR(HLOOKUP(E10,$F$64:$T$66,3,FALSE),"-") -> - | E10: =IFERROR(SMALL($F$64:$T$64,C10),"-") -> - | G10: =C10 -> 5 | H10: =IFERROR(HLOOKUP(K10,$F$65:$T$66,2,FALSE),"-") -> - | K10: =IFERROR(SMALL($F$65:$T$65,C10),"-") -> -
C11: =C10+1 -> 6 | D11: =IFERROR(HLOOKUP(E11,$F$64:$T$66,3,FALSE),"-") -> - | E11: =IFERROR(SMALL($F$64:$T$64,C11),"-") -> - | G11: =C11 -> 6 | H11: =IFERROR(HLOOKUP(K11,$F$65:$T$66,2,FALSE),"-") -> - | K11: =IFERROR(SMALL($F$65:$T$65,C11),"-") -> -
C12: =C11+1 -> 7 | D12: =IFERROR(HLOOKUP(E12,$F$64:$T$66,3,FALSE),"-") -> - | E12: =IFERROR(SMALL($F$64:$T$64,C12),"-") -> - | G12: =C12 -> 7 | H12: =IFERROR(HLOOKUP(K12,$F$65:$T$66,2,FALSE),"-") -> - | K12: =IFERROR(SMALL($F$65:$T$65,C12),"-") -> -
C13: =C12+1 -> 8 | D13: =IFERROR(HLOOKUP(E13,$F$64:$T$66,3,FALSE),"-") -> - | E13: =IFERROR(SMALL($F$64:$T$64,C13),"-") -> - | G13: =C13 -> 8 | H13: =IFERROR(HLOOKUP(K13,$F$65:$T$66,2,FALSE),"-") -> - | K13: =IFERROR(SMALL($F$65:$T$65,C13),"-") -> -
C14: =C13+1 -> 9 | D14: =IFERROR(HLOOKUP(E14,$F$64:$T$66,3,FALSE),"-") -> - | E14: =IFERROR(SMALL($F$64:$T$64,C14),"-") -> - | G14: =C14 -> 9 | H14: =IFERROR(HLOOKUP(K14,$F$65:$T$66,2,FALSE),"-") -> - | K14: =IFERROR(SMALL($F$65:$T$65,C14),"-") -> -
C15: =C14+1 -> 10 | D15: =IFERROR(HLOOKUP(E15,$F$64:$T$66,3,FALSE),"-") -> - | E15: =IFERROR(SMALL($F$64:$T$64,C15),"-") -> - | G15: =C15 -> 10 | H15: =IFERROR(HLOOKUP(K15,$F$65:$T$66,2,FALSE),"-") -> - | K15: =IFERROR(SMALL($F$65:$T$65,C15),"-") -> -
C16: =C15+1 -> 11 | D16: =IFERROR(HLOOKUP(E16,$F$64:$T$66,3,FALSE),"-") -> - | E16: =IFERROR(SMALL($F$64:$T$64,C16),"-") -> - | G16: =C16 -> 11 | H16: =IFERROR(HLOOKUP(K16,$F$65:$T$66,2,FALSE),"-") -> - | K16: =IFERROR(SMALL($F$65:$T$65,C16),"-") -> -
C17: =C16+1 -> 12 | D17: =IFERROR(HLOOKUP(E17,$F$64:$T$66,3,FALSE),"-") -> - | E17: =IFERROR(SMALL($F$64:$T$64,C17),"-") -> - | G17: =C17 -> 12 | H17: =IFERROR(HLOOKUP(K17,$F$65:$T$66,2,FALSE),"-") -> - | K17: =IFERROR(SMALL($F$65:$T$65,C17),"-") -> -
C18: =C17+1 -> 13 | D18: =IFERROR(HLOOKUP(E18,$F$64:$T$66,3,FALSE),"-") -> - | E18: =IFERROR(SMALL($F$64:$T$64,C18),"-") -> - | G18: =C18 -> 13 | H18: =IFERROR(HLOOKUP(K18,$F$65:$T$66,2,FALSE),"-") -> - | K18: =IFERROR(SMALL($F$65:$T$65,C18),"-") -> -
... C20: =C19+1 -> 15 | D20: =IFERROR(HLOOKUP(E20,$F$64:$T$66,3,FALSE),"-") -> - | E20: =IFERROR(SMALL($F$64:$T$64,C20),"-") -> - | G20: =C20 -> 15 | H20: =IFERROR(HLOOKUP(K20,$F$65:$T$66,2,FALSE),"-") -> - | K20: =IFERROR(SMALL($F$65:$T$65,C20),"-") -> -
C23: № | D23: Показатель | E23: Ед. изм. | F23: NHL NTE 240 | G23: Estar ESDE240 (ГПБ К) | H23: SANY SET240S | I23: TZCO TZE240 | J23: БелАЗ 7531 (ГПФК) | K23: XCMG 240 | L23: БелАЗ 7531 (БТЛ) | U23: Комментарий
C24: 1 | D24: Грузоподъемность | E24: т | F24: =SUMIFS(Производительность!$E$23:$E$39,Производительность!$C$23:$C$39,F$23) -> 227.8 | G24: =SUMIFS(Производительность!$E$23:$E$39,Производительность!$C$23:$C$39,G$23) -> 211.392 | H24: =SUMIFS(Производительность!$E$23:$E$39,Производительность!$C$23:$C$39,H$23) -> 216.362 | I24: =SUMIFS(Производительность!$E$23:$E$39,Производительность!$C$23:$C$39,I$23) -> 222 | J24: =SUMIFS(Производительность!$E$23:$E$39,Производительность!$C$23:$C$39,J$23) -> 231 | K24: =SUMIFS(Производительность!$E$23:$E$39,Производительность!$C$23:$C$39,K$23) -> 211.392 | L24: =SUMIFS(Производительность!$E$23:$E$39,Производительность!$C$23:$C$39,L$23) -> 231 | M24: =SUMIFS(Производительность!$E$23:$E$39,Производительность!$C$23:$C$39,M$23) -> 0 | ... T24: =SUMIFS(Производительность!$E$23:$E$39,Производительность!$C$23:$C$39,T$23) -> 0
C25: =MAX(C$24:C24)+1 -> 2 | D25: Мощность двигателя | E25: л.с. | F25: =SUMIFS('ФОТ, МТР, макро'!$AC$4:$AC$20,'ФОТ, МТР, макро'!$W$4:$W$20,F$23) -> 2500 | G25: =SUMIFS('ФОТ, МТР, макро'!$AC$4:$AC$20,'ФОТ, МТР, макро'!$W$4:$W$20,G$23) -> 1864 | H25: =SUMIFS('ФОТ, МТР, макро'!$AC$4:$AC$20,'ФОТ, МТР, макро'!$W$4:$W$20,H$23) -> 2843 | I25: =SUMIFS('ФОТ, МТР, макро'!$AC$4:$AC$20,'ФОТ, МТР, макро'!$W$4:$W$20,I$23) -> 2500 | J25: =SUMIFS('ФОТ, МТР, макро'!$AC$4:$AC$20,'ФОТ, МТР, макро'!$W$4:$W$20,J$23) -> 2535 | K25: =SUMIFS('ФОТ, МТР, макро'!$AC$4:$AC$20,'ФОТ, МТР, макро'!$W$4:$W$20,K$23) -> 0 | L25: =SUMIFS('ФОТ, МТР, макро'!$AC$4:$AC$20,'ФОТ, МТР, макро'!$W$4:$W$20,L$23) -> 2535 | M25: =SUMIFS('ФОТ, МТР, макро'!$AC$4:$AC$20,'ФОТ, МТР, макро'!$W$4:$W$20,M$23) -> 0 | ... T25: =SUMIFS('ФОТ, МТР, макро'!$AC$4:$AC$20,'ФОТ, МТР, макро'!$W$4:$W$20,T$23) -> 0
C26: =MAX(C$24:C25)+1 -> 3 | D26: Срок эксплуатации | E26: лет | F26: =SUMIFS(Производительность!$Y$55:$Y$71,Производительность!$C$55:$C$71,F$23) -> 20 | G26: =SUMIFS(Производительность!$Y$55:$Y$71,Производительность!$C$55:$C$71,G$23) -> 10 | H26: =SUMIFS(Производительность!$Y$55:$Y$71,Производительность!$C$55:$C$71,H$23) -> 12 | I26: =SUMIFS(Производительность!$Y$55:$Y$71,Производительность!$C$55:$C$71,I$23) -> 8 | J26: =SUMIFS(Производительность!$Y$55:$Y$71,Производительность!$C$55:$C$71,J$23) -> 10 | K26: =SUMIFS(Производительность!$Y$55:$Y$71,Производительность!$C$55:$C$71,K$23) -> 0 | L26: =SUMIFS(Производительность!$Y$55:$Y$71,Производительность!$C$55:$C$71,L$23) -> 10 | M26: =SUMIFS(Производительность!$Y$55:$Y$71,Производительность!$C$55:$C$71,M$23) -> 0 | ... T26: =SUMIFS(Производительность!$Y$55:$Y$71,Производительность!$C$55:$C$71,T$23) -> 0
C27: =MAX(C$24:C26)+1 -> 4 | D27: КТГ (средний за эксплуатацию) | E27: коэфф. | F27: =SUMIFS(Производительность!$Z$55:$Z$71,Производительность!$C$55:$C$71,F$23) -> 0.92288816 | G27: =SUMIFS(Производительность!$Z$55:$Z$71,Производительность!$C$55:$C$71,G$23) -> 0.8573313 | H27: =SUMIFS(Производительность!$Z$55:$Z$71,Производительность!$C$55:$C$71,H$23) -> 0.88337931 | I27: =SUMIFS(Производительность!$Z$55:$Z$71,Производительность!$C$55:$C$71,I$23) -> 0.86279173 | J27: =SUMIFS(Производительность!$Z$55:$Z$71,Производительность!$C$55:$C$71,J$23) -> 0.87156467 | K27: =SUMIFS(Производительность!$Z$55:$Z$71,Производительность!$C$55:$C$71,K$23) -> #DIV/0! | L27: =SUMIFS(Производительность!$Z$55:$Z$71,Производительность!$C$55:$C$71,L$23) -> 0.88411536 | M27: =SUMIFS(Производительность!$Z$55:$Z$71,Производительность!$C$55:$C$71,M$23) -> #DIV/0! | ... T27: =SUMIFS(Производительность!$Z$55:$Z$71,Производительность!$C$55:$C$71,T$23) -> #DIV/0!
C28: =MAX(C$24:C27)+1 -> 5 | D28: КТГ (1-й год) | E28: =E27 -> коэфф. | F28: =SUMIFS(Производительность!$E$55:$E$71,Производительность!$C$55:$C$71,F$23) -> 0.93755029 | G28: =SUMIFS(Производительность!$E$55:$E$71,Производительность!$C$55:$C$71,G$23) -> 0.91162481 | H28: =SUMIFS(Производительность!$E$55:$E$71,Производительность!$C$55:$C$71,H$23) -> 0.9357084 | I28: =SUMIFS(Производительность!$E$55:$E$71,Производительность!$C$55:$C$71,I$23) -> 0.90962709 | J28: =SUMIFS(Производительность!$E$55:$E$71,Производительность!$C$55:$C$71,J$23) -> 0.90830416 | K28: =SUMIFS(Производительность!$E$55:$E$71,Производительность!$C$55:$C$71,K$23) -> 0 | L28: =SUMIFS(Производительность!$E$55:$E$71,Производительность!$C$55:$C$71,L$23) -> 0.92956037 | M28: =SUMIFS(Производительность!$E$55:$E$71,Производительность!$C$55:$C$71,M$23) -> 0 | ... T28: =SUMIFS(Производительность!$E$55:$E$71,Производительность!$C$55:$C$71,T$23) -> 0
C29: =MAX(C$24:C28)+1 -> 6 | D29: КИО (средний за эксплуатацию) | E29: =E27 -> коэфф. | F29: =SUMIFS(Производительность!$Z$119:$Z$135,Производительность!$C$119:$C$135,F$23) -> 0.79732431 | G29: =SUMIFS(Производительность!$Z$119:$Z$135,Производительность!$C$119:$C$135,G$23) -> 0.74004467 | H29: =SUMIFS(Производительность!$Z$119:$Z$135,Производительность!$C$119:$C$135,H$23) -> 0.76275508 | I29: =SUMIFS(Производительность!$Z$119:$Z$135,Производительность!$C$119:$C$135,I$23) -> 0.74446948 | J29: =SUMIFS(Производительность!$Z$119:$Z$135,Производительность!$C$119:$C$135,J$23) -> 0.75236066 | K29: =SUMIFS(Производительность!$Z$119:$Z$135,Производительность!$C$119:$C$135,K$23) -> #DIV/0! | L29: =SUMIFS(Производительность!$Z$119:$Z$135,Производительность!$C$119:$C$135,L$23) -> 0.7631828 | M29: =SUMIFS(Производительность!$Z$119:$Z$135,Производительность!$C$119:$C$135,M$23) -> #DIV/0! | ... T29: =SUMIFS(Производительность!$Z$119:$Z$135,Производительность!$C$119:$C$135,T$23) -> #DIV/0!
C30: =MAX(C$24:C29)+1 -> 7 | D30: Среднетехническая скорость (1-й год) | E30: км/час | F30: =SUMIFS(Производительность!$E$151:$E$167,Производительность!$C$151:$C$167,F$23) -> 22.46 | G30: =SUMIFS(Производительность!$E$151:$E$167,Производительность!$C$151:$C$167,G$23) -> 22.46 | H30: =SUMIFS(Производительность!$E$151:$E$167,Производительность!$C$151:$C$167,H$23) -> 22.46 | I30: =SUMIFS(Производительность!$E$151:$E$167,Производительность!$C$151:$C$167,I$23) -> 22.46 | J30: =SUMIFS(Производительность!$E$151:$E$167,Производительность!$C$151:$C$167,J$23) -> 22.46 | K30: =SUMIFS(Производительность!$E$151:$E$167,Производительность!$C$151:$C$167,K$23) -> 22.46 | L30: =SUMIFS(Производительность!$E$151:$E$167,Производительность!$C$151:$C$167,L$23) -> 22.46 | M30: =SUMIFS(Производительность!$E$151:$E$167,Производительность!$C$151:$C$167,M$23) -> 0 | ... T30: =SUMIFS(Производительность!$E$151:$E$167,Производительность!$C$151:$C$167,T$23) -> 0
C31: =MAX(C$24:C30)+1 -> 8 | D31: Производительность (средняя за эксплуатацию) | E31: тыс. т | F31: =SUMIFS(Производительность!$Z$247:$Z$263,Производительность!$C$247:$C$263,F$23) -> 2756.3657 | G31: =SUMIFS(Производительность!$Z$247:$Z$263,Производительность!$C$247:$C$263,G$23) -> 2598.1276 | H31: =SUMIFS(Производительность!$Z$247:$Z$263,Производительность!$C$247:$C$263,H$23) -> 2677.4963 | I31: =SUMIFS(Производительность!$Z$247:$Z$263,Производительность!$C$247:$C$263,I$23) -> 2832.1807 | J31: =SUMIFS(Производительность!$Z$247:$Z$263,Производительность!$C$247:$C$263,J$23) -> 2885.6027 | K31: =SUMIFS(Производительность!$Z$247:$Z$263,Производительность!$C$247:$C$263,K$23) -> #DIV/0! | L31: =SUMIFS(Производительность!$Z$247:$Z$263,Производительность!$C$247:$C$263,L$23) -> 2928.2687 | M31: =SUMIFS(Производительность!$Z$247:$Z$263,Производительность!$C$247:$C$263,M$23) -> #DIV/0! | ... T31: =SUMIFS(Производительность!$Z$247:$Z$263,Производительность!$C$247:$C$263,T$23) -> #DIV/0!
C32: =MAX(C$24:C31)+1 -> 9 | E32: тыс. ткм | F32: =SUMIFS(Производительность!$Z$263:$Z$279,Производительность!$C$263:$C$279,F$23) -> 13243.304 | G32: =SUMIFS(Производительность!$Z$263:$Z$279,Производительность!$C$263:$C$279,G$23) -> 11054.29 | H32: =SUMIFS(Производительность!$Z$263:$Z$279,Производительность!$C$263:$C$279,H$23) -> 11760.948 | I32: =SUMIFS(Производительность!$Z$263:$Z$279,Производительность!$C$263:$C$279,I$23) -> 11541.076 | J32: =SUMIFS(Производительность!$Z$263:$Z$279,Производительность!$C$263:$C$279,J$23) -> 12281.888 | K32: =SUMIFS(Производительность!$Z$263:$Z$279,Производительность!$C$263:$C$279,K$23) -> #DIV/0! | L32: =SUMIFS(Производительность!$Z$263:$Z$279,Производительность!$C$263:$C$279,L$23) -> 12456.732 | M32: =SUMIFS(Производительность!$Z$263:$Z$279,Производительность!$C$263:$C$279,M$23) -> #DIV/0! | ... T32: =SUMIFS(Производительность!$Z$263:$Z$279,Производительность!$C$263:$C$279,T$23) -> #DIV/0!
C33: =MAX(C$24:C32)+1 -> 10 | D33: Производительность (1-й год) | E33: =E31 -> тыс. т | F33: =SUMIFS(Производительность!$E$247:$E$263,Производительность!$C$247:$C$263,F$23) -> 3844.3302 | G33: =SUMIFS(Производительность!$E$247:$E$263,Производительность!$C$247:$C$263,G$23) -> 3468.7825 | H33: =SUMIFS(Производительность!$E$247:$E$263,Производительность!$C$247:$C$263,H$23) -> 3644.1304 | I33: =SUMIFS(Производительность!$E$247:$E$263,Производительность!$C$247:$C$263,I$23) -> 3634.8689 | J33: =SUMIFS(Производительность!$E$247:$E$263,Производительность!$C$247:$C$263,J$23) -> 3776.7277 | K33: =SUMIFS(Производительность!$E$247:$E$263,Производительность!$C$247:$C$263,K$23) -> 0 | L33: =SUMIFS(Производительность!$E$247:$E$263,Производительность!$C$247:$C$263,L$23) -> 3865.111 | M33: =SUMIFS(Производительность!$E$247:$E$263,Производительность!$C$247:$C$263,M$23) -> 0 | ... T33: =SUMIFS(Производительность!$E$247:$E$263,Производительность!$C$247:$C$263,T$23) -> 0
C34: =MAX(C$24:C33)+1 -> 11 | E34: =E32 -> тыс. ткм | F34: =SUMIFS(Производительность!$E$263:$E$279,Производительность!$C$263:$C$279,F$23) -> 11685.165 | G34: =SUMIFS(Производительность!$E$263:$E$279,Производительность!$C$263:$C$279,G$23) -> 10543.656 | H34: =SUMIFS(Производительность!$E$263:$E$279,Производительность!$C$263:$C$279,H$23) -> 11076.641 | I34: =SUMIFS(Производительность!$E$263:$E$279,Производительность!$C$263:$C$279,I$23) -> 11048.49 | J34: =SUMIFS(Производительность!$E$263:$E$279,Производительность!$C$263:$C$279,J$23) -> 11479.681 | K34: =SUMIFS(Производительность!$E$263:$E$279,Производительность!$C$263:$C$279,K$23) -> 0 | L34: =SUMIFS(Производительность!$E$263:$E$279,Производительность!$C$263:$C$279,L$23) -> 11748.33 | M34: =SUMIFS(Производительность!$E$263:$E$279,Производительность!$C$263:$C$279,M$23) -> 0 | ... T34: =SUMIFS(Производительность!$E$263:$E$279,Производительность!$C$263:$C$279,T$23) -> 0
C36: =MAX(C$24:C35)+1 -> 12 | D36: Габариты:
A37: заполнить | C37: =MAX(C$24:C36)+1 -> 13 | D37: эксплуатационная ширина | E37: мм | F37: ='NHL NTE240'!D6 -> 8500 | G37: =ESDE240!D6 -> 9104 | H37: =SANY!D6 -> 8970 | I37: =TZCO!D6 -> 7822 | J37: =БелАЗ!E6 -> 8800 | L37: =БелАЗ_Б!E6 -> 8400
A38: заполнить | C38: =MAX(C$24:C37)+1 -> 14 | D38: высота по переднему козырьку | E38: =E37 -> мм | F38: ='NHL NTE240'!D7 -> 7300 | G38: =ESDE240!D7 -> 7205 | H38: =SANY!D7 -> 7050 | I38: =TZCO!D7 -> 7427 | J38: =БелАЗ!E7 -> 6720 | L38: =БелАЗ_Б!E7 -> 6720
A39: заполнить | C39: =MAX(C$24:C38)+1 -> 15 | D39: габаритная длина | E39: =E38 -> мм | F39: ='NHL NTE240'!D8 -> 15600 | G39: =ESDE240!D8 -> 14595 | H39: =SANY!D8 -> 14900 | I39: =TZCO!D8 -> 14380 | J39: =БелАЗ!E8 -> 13390 | L39: =БелАЗ_Б!E8 -> 13390
C41: =MAX(C$24:C40)+1 -> 16 | D41: Стоимость самосвала | E41: тыс. руб. | F41: =F44+F45+F46 -> 0 | G41: =G44+G45+G46 -> 0 | H41: =H44+H45+H46 -> 0 | I41: =I44+I45+I46 -> 0 | J41: =J44+J45+J46 -> 0 | K41: =K44+K45+K46 -> 0 | L41: =L44+L45+L46 -> 0 | M41: =M44+M45+M46 -> 0 | ... T41: =T44+T45+T46 -> 0 | W41: курс ЦБ на хх.07.2026
A42: заполнить | C42: =MAX(C$24:C41)+1 -> 17 | D42: Цена в долларах | E42: тыс. долл. | W42: 94.0485
A43: заполнить | C43: =MAX(C$24:C42)+1 -> 18 | D43: Цена в юанях | E43: тыс. юаней | W43: 12.7702
A44: заполнить | C44: =MAX(C$24:C43)+1 -> 19 | D44: Цена в рублях | E44: =E41 -> тыс. руб.
A45: заполнить | C45: =MAX(C$24:C44)+1 -> 20 | D45: Шины | E45: =E41 -> тыс. руб.
A46: заполнить | C46: =MAX(C$24:C45)+1 -> 21 | D46: Сборка | E46: =E41 -> тыс. руб.
A48: заполнить | C48: =MAX(C$24:C47)+1 -> 22 | D48: Потребность | E48: ед.
...

Sheet ТСО
A1: не удалять | B1: не удалять | C1: не удалять | D1: Показатель | E1: Ед. изм. | F1: =G1-1 -> 0 | G1: 1 | H1: =G1+1 -> 2 | I1: =H1+1 -> 3 | J1: =I1+1 -> 4 | K1: =J1+1 -> 5 | L1: =K1+1 -> 6 | M1: =L1+1 -> 7 | N1: =M1+1 -> 8 | O1: =N1+1 -> 9 | ... Z1: =Y1+1 -> 20 | AA1: не удалять | AB1: не удалять | AC1: не удалять
A2: * | F2: лет | G2: 2027 | H2: =G2+1 -> 2028 | I2: =H2+1 -> 2029 | J2: =I2+1 -> 2030 | K2: =J2+1 -> 2031 | L2: =K2+1 -> 2032 | M2: =L2+1 -> 2033 | N2: =M2+1 -> 2034 | O2: =N2+1 -> 2035 | ... Z2: =Y2+1 -> 2046 | AA2: проверки | AB2: средние на ТО, ТР, ППР | AC2: аннуитет
A3: * | D3: Расчет аннуитета
A4: *
A5: * | C5: =SUM(F55:Z55,F67:Z67,F86:Z86,AA39) -> -8.8817842e-16 | D5: =Свод!F23 -> NHL NTE 240 | E5: =SUMIFS(Производительность!$Y$55:$Y$71,Производительность!$C$55:$C$71,$D5) -> 20 | F5: =$F$2 -> лет
A6: *
A7: =D5 -> NHL NTE 240 | D7: =D$1 -> Показатель | E7: =E$1 -> Ед. изм. | F7: =F$1 -> 0 | G7: =G$1 -> 1 | H7: =H$1 -> 2 | I7: =I$1 -> 3 | J7: =J$1 -> 4 | K7: =K$1 -> 5 | ... Z7: =Z$1 -> 20
A8: =A7 -> NHL NTE 240 | D8: КТГ | E8: % | G8: =SUMIFS(Производительность!E$55:E$71,Производительность!$C$55:$C$71,$A8) -> 0.93755029 | H8: =SUMIFS(Производительность!F$55:F$71,Производительность!$C$55:$C$71,$A8) -> 0.93038071 | I8: =SUMIFS(Производительность!G$55:G$71,Производительность!$C$55:$C$71,$A8) -> 0.92090265 | J8: =SUMIFS(Производительность!H$55:H$71,Производительность!$C$55:$C$71,$A8) -> 0.90840582 | K8: =SUMIFS(Производительность!I$55:I$71,Производительность!$C$55:$C$71,$A8) -> 0.93333289 | L8: =SUMIFS(Производительность!J$55:J$71,Производительность!$C$55:$C$71,$A8) -> 0.92172393 | M8: =SUMIFS(Производительность!K$55:K$71,Производительность!$C$55:$C$71,$A8) -> 0.93126858 | N8: =SUMIFS(Производительность!L$55:L$71,Производительность!$C$55:$C$71,$A8) -> 0.91113604 | ... Z8: =SUMIFS(Производительность!X$55:X$71,Производительность!$C$55:$C$71,$A8) -> 0.92201249
A9: =A8 -> NHL NTE 240 | D9: КИО | E9: =E8 -> % | G9: =SUMIFS(Производительность!E$119:E$135,Производительность!$C$119:$C$135,$A9) -> 0.80423564 | H9: =SUMIFS(Производительность!F$119:F$135,Производительность!$C$119:$C$135,$A9) -> 0.79808553 | I9: =SUMIFS(Производительность!G$119:G$135,Производительность!$C$119:$C$135,$A9) -> 0.79624552 | J9: =SUMIFS(Производительность!H$119:H$135,Производительность!$C$119:$C$135,$A9) -> 0.78544031 | K9: =SUMIFS(Производительность!I$119:I$135,Производительность!$C$119:$C$135,$A9) -> 0.80699315 | L9: =SUMIFS(Производительность!J$119:J$135,Производительность!$C$119:$C$135,$A9) -> 0.79695563 | M9: =SUMIFS(Производительность!K$119:K$135,Производительность!$C$119:$C$135,$A9) -> 0.80520828 | N9: =SUMIFS(Производительность!L$119:L$135,Производительность!$C$119:$C$135,$A9) -> 0.78780095 | ... Z9: =SUMIFS(Производительность!X$119:X$135,Производительность!$C$119:$C$135,$A9) -> 0.79720513
A10: =A9 -> NHL NTE 240 | D10: Производительность: масса | E10: тыс. т | G10: =SUMIFS(Производительность!E$247:E$263,Производительность!$C$247:$C$263,$A10) -> 3844.3302 | H10: =SUMIFS(Производительность!F$247:F$263,Производительность!$C$247:$C$263,$A10) -> 3560.0083 | I10: =SUMIFS(Производительность!G$247:G$263,Производительность!$C$247:$C$263,$A10) -> 3123.9324 | J10: =SUMIFS(Производительность!H$247:H$263,Производительность!$C$247:$C$263,$A10) -> 3160.7422 | K10: =SUMIFS(Производительность!I$247:I$263,Производительность!$C$247:$C$263,$A10) -> 2793.918 | L10: =SUMIFS(Производительность!J$247:J$263,Производительность!$C$247:$C$263,$A10) -> 2535.7903 | M10: =SUMIFS(Производительность!K$247:K$263,Производительность!$C$247:$C$263,$A10) -> 2962.7003 | N10: =SUMIFS(Производительность!L$247:L$263,Производительность!$C$247:$C$263,$A10) -> 2847.7655 | ... Z10: =SUMIFS(Производительность!X$247:X$263,Производительность!$C$247:$C$263,$A10) -> 2103.0359
A11: =A10 -> NHL NTE 240 | D11: Производительность: грузооборот | E11: тыс. ткм | G11: =SUMIFS(Производительность!E$263:E$279,Производительность!$C$263:$C$279,$A11) -> 11685.165 | H11: =SUMIFS(Производительность!F$263:F$279,Производительность!$C$263:$C$279,$A11) -> 11996.598 | I11: =SUMIFS(Производительность!G$263:G$279,Производительность!$C$263:$C$279,$A11) -> 12641.634 | J11: =SUMIFS(Производительность!H$263:H$279,Производительность!$C$263:$C$279,$A11) -> 12345.563 | K11: =SUMIFS(Производительность!I$263:I$279,Производительность!$C$263:$C$279,$A11) -> 13397.412 | L11: =SUMIFS(Производительность!J$263:J$279,Производительность!$C$263:$C$279,$A11) -> 13581.965 | M11: =SUMIFS(Производительность!K$263:K$279,Производительность!$C$263:$C$279,$A11) -> 13092.705 | N11: =SUMIFS(Производительность!L$263:L$279,Производительность!$C$263:$C$279,$A11) -> 12889.665 | ... Z11: =SUMIFS(Производительность!X$263:X$279,Производительность!$C$263:$C$279,$A11) -> 14267.842
A12: =A11 -> NHL NTE 240 | D12: Грузооборот кумулятивный | E12: =E11 -> тыс. ткм | G12: =G11 -> 11685.165 | H12: =IF(H7>$E5,0,G12+H11) -> 23681.763 | I12: =IF(I7>$E5,0,H12+I11) -> 36323.397 | J12: =IF(J7>$E5,0,I12+J11) -> 48668.96 | K12: =IF(K7>$E5,0,J12+K11) -> 62066.371 | L12: =IF(L7>$E5,0,K12+L11) -> 75648.337 | M12: =IF(M7>$E5,0,L12+M11) -> 88741.042 | N12: =IF(N7>$E5,0,M12+N11) -> 101630.71 | O12: =IF(O7>$E5,0,N12+O11) -> 115159.92 | ... Z12: =IF(Z7>$E5,0,Y12+Z11) -> 264866.08
A13: =A12 -> NHL NTE 240 | D13: Пробег | E13: тыс. км | G13: =SUMIFS(Производительность!E$279:E$295,Производительность!$C$279:$C$295,$A13)/1000 -> 104.28993 | H13: =SUMIFS(Производительность!F$279:F$295,Производительность!$C$279:$C$295,$A13)/1000 -> 107.06946 | I13: =SUMIFS(Производительность!G$279:G$295,Производительность!$C$279:$C$295,$A13)/1000 -> 112.8264 | J13: =SUMIFS(Производительность!H$279:H$295,Производительность!$C$279:$C$295,$A13)/1000 -> 110.18397 | K13: =SUMIFS(Производительность!I$279:I$295,Производительность!$C$279:$C$295,$A13)/1000 -> 119.57171 | L13: =SUMIFS(Производительность!J$279:J$295,Производительность!$C$279:$C$295,$A13)/1000 -> 121.21884 | M13: =SUMIFS(Производительность!K$279:K$295,Производительность!$C$279:$C$295,$A13)/1000 -> 116.8522 | N13: =SUMIFS(Производительность!L$279:L$295,Производительность!$C$279:$C$295,$A13)/1000 -> 115.04007 | ... Z13: =SUMIFS(Производительность!X$279:X$295,Производительность!$C$279:$C$295,$A13)/1000 -> 127.34028
A14: =A13 -> NHL NTE 240
A15: =A14 -> NHL NTE 240 | D15: Операционный денежный поток | E15: тыс. руб. | F15: =F40+F41-F39 -> 0 | G15: =G40+G41-G39 -> 88109.824 | H15: =H40+H41-H39 -> 91720.889 | I15: =I40+I41-I39 -> 126414.68 | J15: =J40+J41-J39 -> 107273.38 | K15: =K40+K41-K39 -> 100380.94 | L15: =L40+L41-L39 -> 131144.41 | M15: =M40+M41-M39 -> 98086.046 | ... Z15: =Z40+Z41-Z39 -> 106136.2
A16: =A15 -> NHL NTE 240 | C16: =D16 -> ТО, ТР, ППР | D16: ТО, ТР, ППР | E16: =E15 -> тыс. руб. | G16: =(G17+G18+G19)*'ФОТ, МТР, макро'!AK$8 -> 6011.0008 | H16: =(H17+H18+H19)*'ФОТ, МТР, макро'!AL$8 -> 8352.9635 | I16: =(I17+I18+I19)*'ФОТ, МТР, макро'!AM$8 -> 49489.736 | J16: =(J17+J18+J19)*'ФОТ, МТР, макро'!AN$8 -> 26318.824 | K16: =(K17+K18+K19)*'ФОТ, МТР, макро'!AO$8 -> 8777.1811 | L16: =(L17+L18+L19)*'ФОТ, МТР, макро'!AP$8 -> 48329.776 | M16: =(M17+M18+M19)*'ФОТ, МТР, макро'!AQ$8 -> 8136.7045 | N16: =(N17+N18+N19)*'ФОТ, МТР, макро'!AR$8 -> 27892.956 | ... Z16: =(Z17+Z18+Z19)*'ФОТ, МТР, макро'!BD$8 -> 9539.6148 | AB16: =SUM(F16:Z16,F30:Z30)/E5 -> 37724.114
A17: =A16 -> NHL NTE 240 | D17: ТО (включая смазочные) | E17: тыс. юаней | G17: ='NHL NTE240'!E19 -> 297.27424 | H17: ='NHL NTE240'!F19 -> 297.27424 | I17: ='NHL NTE240'!G19 -> 297.27424 | J17: ='NHL NTE240'!H19 -> 297.27424 | K17: ='NHL NTE240'!I19 -> 297.27424 | L17: ='NHL NTE240'!J19 -> 297.27424 | M17: ='NHL NTE240'!K19 -> 297.27424 | N17: ='NHL NTE240'!L19 -> 297.27424 | ... Z17: ='NHL NTE240'!X19 -> 297.27424
A18: =A17 -> NHL NTE 240 | D18: ТР, ППР | E18: тыс. юаней | G18: ='NHL NTE240'!E20 -> 0 | H18: ='NHL NTE240'!F20 -> 151.6104 | I18: ='NHL NTE240'!G20 -> 3293.5408 | J18: ='NHL NTE240'!H20 -> 1329.6506 | K18: ='NHL NTE240'!I20 -> 207.44414 | L18: ='NHL NTE240'!J20 -> 3259.167 | M18: ='NHL NTE240'!K20 -> 47.96174 | N18: ='NHL NTE240'!L20 -> 1481.261 | ... Z18: ='NHL NTE240'!X20 -> 237.35227
A19: =A18 -> NHL NTE 240 | D19: трудозатраты | E19: тыс. юаней | G19: ='NHL NTE240'!E21+'NHL NTE240'!E22 -> 173.43106 | H19: ='NHL NTE240'!F21+'NHL NTE240'!F22 -> 205.21346 | I19: ='NHL NTE240'!G21+'NHL NTE240'!G22 -> 284.59306 | J19: ='NHL NTE240'!H21+'NHL NTE240'!H22 -> 434.03146 | K19: ='NHL NTE240'!I21+'NHL NTE240'!I22 -> 182.59906 | L19: ='NHL NTE240'!J21+'NHL NTE240'!J22 -> 228.13346 | M19: ='NHL NTE240'!K21+'NHL NTE240'!K22 -> 291.92746 | N19: ='NHL NTE240'!L21+'NHL NTE240'!L22 -> 405.68706 | ... Z19: ='NHL NTE240'!X21+'NHL NTE240'!X22 -> 212.39506
A20: =A19 -> NHL NTE 240 | D20: % стоимости справочно | G20: =G16/$F44 -> #DIV/0! | H20: =H16/$F44 -> #DIV/0! | I20: =I16/$F44 -> #DIV/0! | J20: =J16/$F44 -> #DIV/0! | K20: =K16/$F44 -> #DIV/0! | L20: =L16/$F44 -> #DIV/0! | M20: =M16/$F44 -> #DIV/0! | N20: =N16/$F44 -> #DIV/0! | ... Z20: =Z16/$F44 -> #DIV/0! | AA20: =SUM(F16:Z16)/$F44 -> #DIV/0!
A21: =A20 -> NHL NTE 240 | D21: Шины | E21: =E15 -> тыс. руб. | G21: =G23*G24 -> 23350.892 | H21: =H23*H24 -> 23973.24 | I21: =I23*I24 -> 25262.239 | J21: =J23*J24 -> 24670.589 | K21: =K23*K24 -> 26772.537 | L21: =L23*L24 -> 27141.337 | M21: =M23*M24 -> 26163.631 | N21: =N23*N24 -> 25757.887 | ... Z21: =Z23*Z24 -> 28511.949
A22: =A21 -> NHL NTE 240 | D22: удельный расход | E22: шт./тыс. км | F22: =SUMIFS('ФОТ, МТР, макро'!$Z$4:$Z$20,'ФОТ, МТР, макро'!$W$4:$W$20,$A22) -> 0.075 | G22: =F22 -> 0.075 | H22: =G22 -> 0.075 | I22: =H22 -> 0.075 | J22: =I22 -> 0.075 | K22: =J22 -> 0.075 | L22: =K22 -> 0.075 | M22: =L22 -> 0.075 | N22: =M22 -> 0.075 | ... Z22: =Y22 -> 0.075
A23: =A22 -> NHL NTE 240 | D23: расход за период | E23: шт. | G23: =G13*G22 -> 7.8217446 | H23: =H13*H22 -> 8.0302097 | I23: =I13*I22 -> 8.4619799 | J23: =J13*J22 -> 8.2637977 | K23: =K13*K22 -> 8.967878 | L23: =L13*L22 -> 9.0914131 | M23: =M13*M22 -> 8.7639153 | N23: =N13*N22 -> 8.6280052 | ... Z23: =Z13*Z22 -> 9.550521 | AA23: =SUM(F13:Z13)*F22-SUM(F23:Z23) -> 0
A24: =A23 -> NHL NTE 240 | D24: цена | E24: тыс. руб./шт. | F24: =SUMIFS('ФОТ, МТР, макро'!$AA$4:$AA$20,'ФОТ, МТР, макро'!$W$4:$W$20,$A24) -> 2985.3815 | G24: =F24 -> 2985.3815 | H24: =G24 -> 2985.3815 | I24: =H24 -> 2985.3815 | J24: =I24 -> 2985.3815 | K24: =J24 -> 2985.3815 | L24: =K24 -> 2985.3815 | M24: =L24 -> 2985.3815 | N24: =M24 -> 2985.3815 | ... Z24: =Y24 -> 2985.3815
A25: =A24 -> NHL NTE 240 | D25: Топливо | E25: =E15 -> тыс. руб. | G25: =G28*G29 -> 69429.777 | H25: =H28*H29 -> 71280.219 | I25: =I28*I29 -> 75112.831 | J25: =J28*J29 -> 73353.664 | K25: =K28*K29 -> 79603.439 | L25: =L28*L29 -> 80699.999 | M25: =M28*M29 -> 77792.962 | N25: =N28*N29 -> 76586.555 | ... Z25: =Z28*Z29 -> 84775.274
A26: =A25 -> NHL NTE 240 | D26: удельный расход | E26: =VLOOKUP($A26,'ФОТ, МТР, макро'!$N$4:$Q$20,4,FALSE) -> г/ткм | F26: =IF($E26="г/ткм",SUMIFS('ФОТ, МТР, макро'!$O$4:$O$20,'ФОТ, МТР, макро'!$N$4:$N$20,$A26),SUMIFS('ФОТ, МТР, макро'!$P$4:$P$20,'ФОТ, МТР, макро'!$N$4:$N$20,$A26)) -> 90 | G26: =F26 -> 90 | H26: =G26 -> 90 | I26: =H26 -> 90 | J26: =I26 -> 90 | K26: =J26 -> 90 | L26: =K26 -> 90 | M26: =L26 -> 90 | N26: =M26 -> 90 | ... Z26: =Y26 -> 90
A27: =A26 -> NHL NTE 240 | D27: справочно | E27: =IF(E26='ФОТ, МТР, макро'!$O$4,'ФОТ, МТР, макро'!$P$4,'ФОТ, МТР, макро'!$O$4) -> л/час | G27: =IF($E26="г/ткм",G28*1000/(365*24*G9),G28/G11*1000) -> 149.27598 | H27: =IF($E26="г/ткм",H28*1000/(365*24*H9),H28/H11*1000) -> 154.43548 | I27: =IF($E26="г/ткм",I28*1000/(365*24*I9),I28/I11*1000) -> 163.11527 | J27: =IF($E26="г/ткм",J28*1000/(365*24*J9),J28/J11*1000) -> 161.48646 | K27: =IF($E26="г/ткм",K28*1000/(365*24*K9),K28/K11*1000) -> 170.56482 | L27: =IF($E26="г/ткм",L28*1000/(365*24*L9),L28/L11*1000) -> 175.09223 | M27: =IF($E26="г/ткм",M28*1000/(365*24*M9),M28/M11*1000) -> 167.05503 | N27: =IF($E26="г/ткм",N28*1000/(365*24*N9),N28/N11*1000) -> 168.09838 | ... Z27: =IF($E26="г/ткм",Z28*1000/(365*24*Z9),Z28/Z11*1000) -> 183.87666
A28: =A27 -> NHL NTE 240 | D28: расход за период | E28: т | G28: =IF($E26="г/ткм",G11*G26/1000,365*24*G9*G26*0.85/1000) -> 1051.6648 | H28: =IF($E26="г/ткм",H11*H26/1000,365*24*H9*H26*0.85/1000) -> 1079.6938 | I28: =IF($E26="г/ткм",I11*I26/1000,365*24*I9*I26*0.85/1000) -> 1137.747 | J28: =IF($E26="г/ткм",J11*J26/1000,365*24*J9*J26*0.85/1000) -> 1111.1007 | K28: =IF($E26="г/ткм",K11*K26/1000,365*24*K9*K26*0.85/1000) -> 1205.7671 | L28: =IF($E26="г/ткм",L11*L26/1000,365*24*L9*L26*0.85/1000) -> 1222.3769 | M28: =IF($E26="г/ткм",M11*M26/1000,365*24*M9*M26*0.85/1000) -> 1178.3435 | N28: =IF($E26="г/ткм",N11*N26/1000,365*24*N9*N26*0.85/1000) -> 1160.0698 | ... Z28: =IF($E26="г/ткм",Z11*Z26/1000,365*24*Z9*Z26*0.85/1000) -> 1284.1058
A29: =A28 -> NHL NTE 240 | D29: цена | E29: тыс. руб./т | F29: ='ФОТ, МТР, макро'!$G$2 -> 66.018919 | G29: =F29 -> 66.018919 | H29: =G29 -> 66.018919 | I29: =H29 -> 66.018919 | J29: =I29 -> 66.018919 | K29: =J29 -> 66.018919 | L29: =K29 -> 66.018919 | M29: =L29 -> 66.018919 | N29: =M29 -> 66.018919 | ... Z29: =Y29 -> 66.018919
A30: =A29 -> NHL NTE 240 | C30: =C16 -> ТО, ТР, ППР | D30: Смазочные | E30: =E15 -> тыс. руб.
A31: =A30 -> NHL NTE 240
A32: =A31 -> NHL NTE 240 | D32: Затраты на персонал | E32: =E15 -> тыс. руб. | G32: =G33+G34+G35 -> 18475.596 | H32: =H33+H34+H35 -> 18475.596 | I32: =I33+I34+I35 -> 18475.596 | J32: =J33+J34+J35 -> 18475.596 | K32: =K33+K34+K35 -> 18475.596 | L32: =L33+L34+L35 -> 18475.596 | M32: =M33+M34+M35 -> 18475.596 | N32: =N33+N34+N35 -> 18475.596 | ... Z32: =Z33+Z34+Z35 -> 18475.596
A33: =A32 -> NHL NTE 240 | D33: ФОТ | E33: =E32 -> тыс. руб. | F33: ='ФОТ, МТР, макро'!$B$4*'ФОТ, МТР, макро'!$B$7 -> 11107.5 | G33: =IF(G10=0,0,$F33) -> 11107.5 | H33: =IF(H10=0,0,$F33) -> 11107.5 | I33: =IF(I10=0,0,$F33) -> 11107.5 | J33: =IF(J10=0,0,$F33) -> 11107.5 | K33: =IF(K10=0,0,$F33) -> 11107.5 | L33: =IF(L10=0,0,$F33) -> 11107.5 | M33: =IF(M10=0,0,$F33) -> 11107.5 | N33: =IF(N10=0,0,$F33) -> 11107.5 | ... Z33: =IF(Z10=0,0,$F33) -> 11107.5
A34: =A33 -> NHL NTE 240 | D34: отчисления | E34: =E32 -> тыс. руб. | F34: ='ФОТ, МТР, макро'!$B$5 -> 0.377 | G34: =G33*$F34 -> 4187.5275 | H34: =H33*$F34 -> 4187.5275 | I34: =I33*$F34 -> 4187.5275 | J34: =J33*$F34 -> 4187.5275 | K34: =K33*$F34 -> 4187.5275 | L34: =L33*$F34 -> 4187.5275 | M34: =M33*$F34 -> 4187.5275 | N34: =N33*$F34 -> 4187.5275 | ... Z34: =Z33*$F34 -> 4187.5275
A35: =A34 -> NHL NTE 240 | D35: прочее | F35: ='ФОТ, МТР, макро'!$C$13*'ФОТ, МТР, макро'!$B$7 -> 3180.5687 | G35: =IF(G10=0,0,$F35) -> 3180.5687 | H35: =IF(H10=0,0,$F35) -> 3180.5687 | I35: =IF(I10=0,0,$F35) -> 3180.5687 | J35: =IF(J10=0,0,$F35) -> 3180.5687 | K35: =IF(K10=0,0,$F35) -> 3180.5687 | L35: =IF(L10=0,0,$F35) -> 3180.5687 | M35: =IF(M10=0,0,$F35) -> 3180.5687 | N35: =IF(N10=0,0,$F35) -> 3180.5687 | ... Z35: =IF(Z10=0,0,$F35) -> 3180.5687
A36: =A35 -> NHL NTE 240 | D36: Транспортный налог | E36: =E15 -> тыс. руб. | G36: =IF(G10=0,0,G37*G38/1000) -> 212.5 | H36: =IF(H10=0,0,H37*H38/1000) -> 212.5 | I36: =IF(I10=0,0,I37*I38/1000) -> 212.5 | J36: =IF(J10=0,0,J37*J38/1000) -> 212.5 | K36: =IF(K10=0,0,K37*K38/1000) -> 212.5 | L36: =IF(L10=0,0,L37*L38/1000) -> 212.5 | M36: =IF(M10=0,0,M37*M38/1000) -> 212.5 | N36: =IF(N10=0,0,N37*N38/1000) -> 212.5 | ... Z36: =IF(Z10=0,0,Z37*Z38/1000) -> 212.5
A37: =A36 -> NHL NTE 240 | D37: мощность двигателя | E37: л.с. | F37: =SUMIFS('ФОТ, МТР, макро'!$AC$4:$AC$20,'ФОТ, МТР, макро'!$W$4:$W$20,$A37) -> 2500 | G37: =F37 -> 2500 | H37: =G37 -> 2500 | I37: =H37 -> 2500 | J37: =I37 -> 2500 | K37: =J37 -> 2500 | L37: =K37 -> 2500 | M37: =L37 -> 2500 | N37: =M37 -> 2500 | ... Z37: =Y37 -> 2500
A38: =A37 -> NHL NTE 240 | D38: налоговая ставка | E38: руб./л.с. | F38: =SUMIFS('ФОТ, МТР, макро'!$AD$4:$AD$20,'ФОТ, МТР, макро'!$W$4:$W$20,$A38) -> 85 | G38: =F38 -> 85 | H38: =G38 -> 85 | I38: =H38 -> 85 | J38: =I38 -> 85 | K38: =J38 -> 85 | L38: =K38 -> 85 | M38: =L38 -> 85 | N38: =M38 -> 85 | ... Z38: =Y38 -> 85
A39: =A38 -> NHL NTE 240 | C39: =SUMIFS('ФОТ, МТР, макро'!$AG$4:$AG$20,'ФОТ, МТР, макро'!$W$4:$W$20,$A39) -> 14.117647 | D39: Амортизация НУ | E39: =E15 -> тыс. руб. | G39: =IF(G7<=$C40,$F44*$C39%,"ОШИБКА") -> 0 | H39: =IF(H7<=$C40,$F44*$C39%,$F44-SUM($G39:G39)) -> 0 | I39: =IF(I7<=$C40,$F44*$C39%,$F44-SUM($G39:H39)) -> 0 | J39: =IF(J7<=$C40,$F44*$C39%,$F44-SUM($G39:I39)) -> 0 | K39: =IF(K7<=$C40,$F44*$C39%,$F44-SUM($G39:J39)) -> 0 | L39: =IF(L7<=$C40,$F44*$C39%,$F44-SUM($G39:K39)) -> 0 | M39: =IF(M7<=$C40,$F44*$C39%,$F44-SUM($G39:L39)) -> 0 | N39: =IF(N7<=$C40,$F44*$C39%,$F44-SUM($G39:M39)) -> 0 | O39: =IF(O7<=$C40,$F44*$C39%,$F44-SUM($G39:N39)) -> 0 | ... Z39: =IF(Z7<=$C40,$F44*$C39%,$F44-SUM($G39:Y39)) -> 0 | AA39: =F44-SUM(G39:Z39) -> 0
A40: =A39 -> NHL NTE 240 | C40: =SUMIFS('ФОТ, МТР, макро'!$AF$4:$AF$20,'ФОТ, МТР, макро'!$W$4:$W$20,$A40)/12 -> 7.0833333 | D40: Налогооблагаемая база (по налогу на прибыль) | E40: =E15 -> тыс. руб. | G40: =SUM(G16,G21,G25,G30,G32,G36,G39) -> 117479.77 | H40: =SUM(H16,H21,H25,H30,H32,H36,H39) -> 122294.52 | I40: =SUM(I16,I21,I25,I30,I32,I36,I39) -> 168552.9 | J40: =SUM(J16,J21,J25,J30,J32,J36,J39) -> 143031.17 | K40: =SUM(K16,K21,K25,K30,K32,K36,K39) -> 133841.25 | L40: =SUM(L16,L21,L25,L30,L32,L36,L39) -> 174859.21 | M40: =SUM(M16,M21,M25,M30,M32,M36,M39) -> 130781.39 | N40: =SUM(N16,N21,N25,N30,N32,N36,N39) -> 148925.49 | ... Z40: =SUM(Z16,Z21,Z25,Z30,Z32,Z36,Z39) -> 141514.93
...

Sheet Производительность
E1: =ТСО!G2 -> 2027 | F1: =ТСО!H2 -> 2028 | G1: =ТСО!I2 -> 2029 | H1: =ТСО!J2 -> 2030 | I1: =ТСО!K2 -> 2031 | J1: =ТСО!L2 -> 2032 | K1: =ТСО!M2 -> 2033 | L1: =ТСО!N2 -> 2034 | ... X1: =ТСО!Z2 -> 2046
B2: Производительность по годам эксплуатации
Y3: не удалять | Z3: не удалять | AA3: не удалять | AB3: не удалять | AC3: не удалять
A4: 1 | B4: № | C4: Наименование показателя | D4: Ед. изм. | E4: =ТСО!G1 -> 1 | F4: =ТСО!H1 -> 2 | G4: =ТСО!I1 -> 3 | H4: =ТСО!J1 -> 4 | I4: =ТСО!K1 -> 5 | J4: =ТСО!L1 -> 6 | K4: =ТСО!M1 -> 7 | L4: =ТСО!N1 -> 8 | ... X4: =ТСО!Z1 -> 20 | Z4: средняя
A5: 0 | B5: * | C5: Количество дней в периоде | D5: дней | E5: 365 | F5: =E5 -> 365 | G5: =F5 -> 365 | H5: =G5 -> 365 | I5: =H5 -> 365 | J5: =I5 -> 365 | K5: =J5 -> 365 | L5: =K5 -> 365 | M5: =L5 -> 365 | ... X5: =W5 -> 365
A6: 0 | B6: * | C6: Календарный фонд времени | D6: час. | E6: =E5*24 -> 8760 | F6: =F5*24 -> 8760 | G6: =G5*24 -> 8760 | H6: =H5*24 -> 8760 | I6: =I5*24 -> 8760 | J6: =J5*24 -> 8760 | K6: =K5*24 -> 8760 | L6: =L5*24 -> 8760 | ... X6: =X5*24 -> 8760
A7: =A23 -> 1 | B7: 1 | C7: Расстояние транспортировки | D7: км | E7: 3.0395841 | F7: 3.369823 | G7: 4.0467054 | H7: 3.9059063 | I7: 4.7952058 | J7: 5.3561073 | K7: 4.4191798 | L7: 4.526238 | M7: 5.3840572 | N7: 4.8197555 | O7: 4.7397683 | P7: 5.7368198 | Q7: 5.8316077 | R7: 6.0469833 | S7: 5.9999465 | T7: 5.6103506 | U7: 4.0567755 | V7: 4.6317429 | W7: 5.9728866 | X7: 6.7844023 | Y7: карьер, КП 1.0.1
A8: =A24 -> 1 | C8: =Свод!F23 -> NHL NTE 240 | D8: =D7 -> км | E8: =IF($A8=1,E$7,0) -> 3.0395841 | F8: =IF($A8=1,F$7,0) -> 3.369823 | G8: =IF($A8=1,G$7,0) -> 4.0467054 | H8: =IF($A8=1,H$7,0) -> 3.9059063 | I8: =IF($A8=1,I$7,0) -> 4.7952058 | J8: =IF($A8=1,J$7,0) -> 5.3561073 | K8: =IF($A8=1,K$7,0) -> 4.4191798 | L8: =IF($A8=1,L$7,0) -> 4.526238 | ... X8: =IF($A8=1,X$7,0) -> 6.7844023
A9: =A25 -> 1 | C9: =Свод!G23 -> Estar ESDE240 (ГПБ К) | D9: =D8 -> км | E9: =IF($A9=1,E$7,0) -> 3.0395841 | F9: =IF($A9=1,F$7,0) -> 3.369823 | G9: =IF($A9=1,G$7,0) -> 4.0467054 | H9: =IF($A9=1,H$7,0) -> 3.9059063 | I9: =IF($A9=1,I$7,0) -> 4.7952058 | J9: =IF($A9=1,J$7,0) -> 5.3561073 | K9: =IF($A9=1,K$7,0) -> 4.4191798 | L9: =IF($A9=1,L$7,0) -> 4.526238 | ... X9: =IF($A9=1,X$7,0) -> 6.7844023
A10: =A26 -> 1 | C10: =Свод!H23 -> SANY SET240S | D10: =D9 -> км | E10: =IF($A10=1,E$7,0) -> 3.0395841 | F10: =IF($A10=1,F$7,0) -> 3.369823 | G10: =IF($A10=1,G$7,0) -> 4.0467054 | H10: =IF($A10=1,H$7,0) -> 3.9059063 | I10: =IF($A10=1,I$7,0) -> 4.7952058 | J10: =IF($A10=1,J$7,0) -> 5.3561073 | K10: =IF($A10=1,K$7,0) -> 4.4191798 | L10: =IF($A10=1,L$7,0) -> 4.526238 | ... X10: =IF($A10=1,X$7,0) -> 6.7844023
A11: =A27 -> 1 | C11: =Свод!I23 -> TZCO TZE240 | D11: =D10 -> км | E11: =IF($A11=1,E$7,0) -> 3.0395841 | F11: =IF($A11=1,F$7,0) -> 3.369823 | G11: =IF($A11=1,G$7,0) -> 4.0467054 | H11: =IF($A11=1,H$7,0) -> 3.9059063 | I11: =IF($A11=1,I$7,0) -> 4.7952058 | J11: =IF($A11=1,J$7,0) -> 5.3561073 | K11: =IF($A11=1,K$7,0) -> 4.4191798 | L11: =IF($A11=1,L$7,0) -> 4.526238 | ... X11: =IF($A11=1,X$7,0) -> 6.7844023
A12: =A28 -> 1 | C12: =Свод!J23 -> БелАЗ 7531 (ГПФК) | D12: =D11 -> км | E12: =IF($A12=1,E$7,0) -> 3.0395841 | F12: =IF($A12=1,F$7,0) -> 3.369823 | G12: =IF($A12=1,G$7,0) -> 4.0467054 | H12: =IF($A12=1,H$7,0) -> 3.9059063 | I12: =IF($A12=1,I$7,0) -> 4.7952058 | J12: =IF($A12=1,J$7,0) -> 5.3561073 | K12: =IF($A12=1,K$7,0) -> 4.4191798 | L12: =IF($A12=1,L$7,0) -> 4.526238 | ... X12: =IF($A12=1,X$7,0) -> 6.7844023
A13: =A29 -> 1 | C13: =Свод!K23 -> XCMG 240 | D13: =D12 -> км | E13: =IF($A13=1,E$7,0) -> 3.0395841 | F13: =IF($A13=1,F$7,0) -> 3.369823 | G13: =IF($A13=1,G$7,0) -> 4.0467054 | H13: =IF($A13=1,H$7,0) -> 3.9059063 | I13: =IF($A13=1,I$7,0) -> 4.7952058 | J13: =IF($A13=1,J$7,0) -> 5.3561073 | K13: =IF($A13=1,K$7,0) -> 4.4191798 | L13: =IF($A13=1,L$7,0) -> 4.526238 | ... X13: =IF($A13=1,X$7,0) -> 6.7844023
A14: =A30 -> 1 | C14: =Свод!L23 -> БелАЗ 7531 (БТЛ) | D14: =D13 -> км | E14: =IF($A14=1,E$7,0) -> 3.0395841 | F14: =IF($A14=1,F$7,0) -> 3.369823 | G14: =IF($A14=1,G$7,0) -> 4.0467054 | H14: =IF($A14=1,H$7,0) -> 3.9059063 | I14: =IF($A14=1,I$7,0) -> 4.7952058 | J14: =IF($A14=1,J$7,0) -> 5.3561073 | K14: =IF($A14=1,K$7,0) -> 4.4191798 | L14: =IF($A14=1,L$7,0) -> 4.526238 | ... X14: =IF($A14=1,X$7,0) -> 6.7844023
A15: =A31 -> 0 | C15: =Свод!M23 -> 0 | D15: =D14 -> км | E15: =IF($A15=1,E$7,0) -> 0 | F15: =IF($A15=1,F$7,0) -> 0 | G15: =IF($A15=1,G$7,0) -> 0 | H15: =IF($A15=1,H$7,0) -> 0 | I15: =IF($A15=1,I$7,0) -> 0 | J15: =IF($A15=1,J$7,0) -> 0 | K15: =IF($A15=1,K$7,0) -> 0 | L15: =IF($A15=1,L$7,0) -> 0 | ... X15: =IF($A15=1,X$7,0) -> 0
A16: =A32 -> 0 | C16: =Свод!N23 -> 0 | D16: =D15 -> км | E16: =IF($A16=1,E$7,0) -> 0 | F16: =IF($A16=1,F$7,0) -> 0 | G16: =IF($A16=1,G$7,0) -> 0 | H16: =IF($A16=1,H$7,0) -> 0 | I16: =IF($A16=1,I$7,0) -> 0 | J16: =IF($A16=1,J$7,0) -> 0 | K16: =IF($A16=1,K$7,0) -> 0 | L16: =IF($A16=1,L$7,0) -> 0 | ... X16: =IF($A16=1,X$7,0) -> 0
A17: =A33 -> 0 | C17: =Свод!O23 -> 0 | D17: =D16 -> км | E17: =IF($A17=1,E$7,0) -> 0 | F17: =IF($A17=1,F$7,0) -> 0 | G17: =IF($A17=1,G$7,0) -> 0 | H17: =IF($A17=1,H$7,0) -> 0 | I17: =IF($A17=1,I$7,0) -> 0 | J17: =IF($A17=1,J$7,0) -> 0 | K17: =IF($A17=1,K$7,0) -> 0 | L17: =IF($A17=1,L$7,0) -> 0 | ... X17: =IF($A17=1,X$7,0) -> 0
A18: =A34 -> 0 | C18: =Свод!P23 -> 0 | D18: =D17 -> км | E18: =IF($A18=1,E$7,0) -> 0 | F18: =IF($A18=1,F$7,0) -> 0 | G18: =IF($A18=1,G$7,0) -> 0 | H18: =IF($A18=1,H$7,0) -> 0 | I18: =IF($A18=1,I$7,0) -> 0 | J18: =IF($A18=1,J$7,0) -> 0 | K18: =IF($A18=1,K$7,0) -> 0 | L18: =IF($A18=1,L$7,0) -> 0 | ... X18: =IF($A18=1,X$7,0) -> 0
A19: =A35 -> 0 | C19: =Свод!Q23 -> 0 | D19: =D18 -> км | E19: =IF($A19=1,E$7,0) -> 0 | F19: =IF($A19=1,F$7,0) -> 0 | G19: =IF($A19=1,G$7,0) -> 0 | H19: =IF($A19=1,H$7,0) -> 0 | I19: =IF($A19=1,I$7,0) -> 0 | J19: =IF($A19=1,J$7,0) -> 0 | K19: =IF($A19=1,K$7,0) -> 0 | L19: =IF($A19=1,L$7,0) -> 0 | ... X19: =IF($A19=1,X$7,0) -> 0
A20: =A36 -> 0 | C20: =Свод!R23 -> 0 | D20: =D19 -> км | E20: =IF($A20=1,E$7,0) -> 0 | F20: =IF($A20=1,F$7,0) -> 0 | G20: =IF($A20=1,G$7,0) -> 0 | H20: =IF($A20=1,H$7,0) -> 0 | I20: =IF($A20=1,I$7,0) -> 0 | J20: =IF($A20=1,J$7,0) -> 0 | K20: =IF($A20=1,K$7,0) -> 0 | L20: =IF($A20=1,L$7,0) -> 0 | ... X20: =IF($A20=1,X$7,0) -> 0
A21: =A37 -> 0 | C21: =Свод!S23 -> 0 | D21: =D20 -> км | E21: =IF($A21=1,E$7,0) -> 0 | F21: =IF($A21=1,F$7,0) -> 0 | G21: =IF($A21=1,G$7,0) -> 0 | H21: =IF($A21=1,H$7,0) -> 0 | I21: =IF($A21=1,I$7,0) -> 0 | J21: =IF($A21=1,J$7,0) -> 0 | K21: =IF($A21=1,K$7,0) -> 0 | L21: =IF($A21=1,L$7,0) -> 0 | ... X21: =IF($A21=1,X$7,0) -> 0
A22: =A38 -> 0 | C22: =Свод!T23 -> 0 | D22: =D21 -> км | E22: =IF($A22=1,E$7,0) -> 0 | F22: =IF($A22=1,F$7,0) -> 0 | G22: =IF($A22=1,G$7,0) -> 0 | H22: =IF($A22=1,H$7,0) -> 0 | I22: =IF($A22=1,I$7,0) -> 0 | J22: =IF($A22=1,J$7,0) -> 0 | K22: =IF($A22=1,K$7,0) -> 0 | L22: =IF($A22=1,L$7,0) -> 0 | ... X22: =IF($A22=1,X$7,0) -> 0
A23: 1 | B23: =B7+1 -> 2 | C23: Грузоподъемность | Z23: груженый | AA23: порожний | AB23: футеровка | AC23: номинал
A24: =IF(MAX(E24:P24)=0,0,1) -> 1 | C24: =C8 -> NHL NTE 240 | D24: т | E24: =AC24 -> 227.8 | F24: =E24 -> 227.8 | G24: =F24 -> 227.8 | H24: =G24 -> 227.8 | I24: =H24 -> 227.8 | J24: =I24 -> 227.8 | K24: =J24 -> 227.8 | L24: =K24 -> 227.8 | M24: =L24 -> 227.8 | ... X24: =W24 -> 227.8 | Y24: см. Загрузка | Z24: 236 | AB24: 8.2 | AC24: =Z24-AA24-AB24 -> 227.8
A25: =IF(MAX(E25:P25)=0,0,1) -> 1 | C25: =C9 -> Estar ESDE240 (ГПБ К) | D25: =D24 -> т | E25: =AC25 -> 211.392 | F25: =E25 -> 211.392 | G25: =F25 -> 211.392 | H25: =G25 -> 211.392 | I25: =H25 -> 211.392 | J25: =I25 -> 211.392 | K25: =J25 -> 211.392 | L25: =K25 -> 211.392 | M25: =L25 -> 211.392 | ... X25: =W25 -> 211.392 | Y25: см. Загрузка | Z25: =ESDE240!D9 -> 220 | AB25: 8.608 | AC25: =Z25-AA25-AB25 -> 211.392
