Workbook
Name _____NAY14: #REF!
Name _____PDR11: #REF!
Name _____PDR13: '[1]#ССЫЛКА'!$I$5
Name _____PDR14: #REF!
Name _____PDR20: #REF!
Name _____PDR9: #REF!
Name ____NAU11: #REF!
Name ____NAU13: #REF!
Name ____NAU14: #REF!
Name ____NAU20: #REF!
Name ____NAY14: #REF!
Name ____PDR11: #REF!
Name ____PDR13: '[2]#ССЫЛКА'!$I$5
Name ____PDR14: #REF!
Name ____PDR20: #REF!
Name ____PDR9: #REF!
Name ___NAU11: #REF!
Name ___NAU13: #REF!
Name ___NAU14: #REF!
Name ___NAU20: #REF!
Name ___NAY14: #REF!
Name ___PDR11: #REF!
Name ___PDR13: '[1]#ССЫЛКА'!$I$5
Name ___PDR14: #REF!
Name ___PDR20: #REF!
Name ___PDR9: #REF!
Name __bas186: [6]Stocks!#REF!
Name __bas187: [6]Stocks!#REF!
Name __bas188: [6]Stocks!#REF!
Name __bas189: [6]Stocks!#REF!
Name __bas190: [6]Stocks!#REF!
Name __bas286: [6]Stocks!#REF!
Name __bas287: [6]Stocks!#REF!
Name __bas288: [6]Stocks!#REF!
Name __bas289: [6]Stocks!#REF!
Name __bas290: [6]Stocks!#REF!
Name __bas386: [6]Stocks!#REF!
Name __bas387: [6]Stocks!#REF!
Name __bas388: [6]Stocks!#REF!
Name __bas389: [6]Stocks!#REF!
Name __bas486: [6]Stocks!#REF!
Name __bas487: [6]Stocks!#REF!
Name __bas488: [6]Stocks!#REF!
Name __bas489: [6]Stocks!#REF!
Name __cap01: '[6]Mine Capacity'!#REF!
Name __cap02: '[6]Mine Capacity'!#REF!
Name __cap03: '[6]Mine Capacity'!#REF!
Name __cap04: '[6]Mine Capacity'!#REF!
Name __cap05: '[6]Mine Capacity'!#REF!
Name __cap06: '[6]Mine Capacity'!#REF!
Name __cap07: '[6]Mine Capacity'!#REF!
Name __cap20: '[6]Mine Capacity'!#REF!
Name __cap90: '[6]Mine Capacity'!#REF!
Name __cap91: '[6]Mine Capacity'!#REF!
Name __cap92: '[6]Mine Capacity'!#REF!
Name __cap93: '[6]Mine Capacity'!#REF!
Name __cap94: '[6]Mine Capacity'!#REF!
Name __cap95: '[6]Mine Capacity'!#REF!
Name __cap96: '[6]Mine Capacity'!#REF!
Name __cap97: '[6]Mine Capacity'!#REF!

Sheet 1. Сводная_аннуитеты
B2: версия "производство"
A4: Ранжирование общих аннуитетов экскаваторов | E4: Ранжирование по стоимости оборудования
A5: № | B5: Экскаватор | C5: Аннуитет, руб/м3 | E5: № | F5: Экскаватор | H5: Цена за ед., тыс.руб.
A6: 1 | B6: =VLOOKUP(C6,$B$54:$D$63,3,FALSE) -> Komatsu PC2000-11R Огунвэй | C6: =SMALL($D$49:$M$49,A6) -> 46.005042 | E6: 1 | F6: =VLOOKUP(H6,$C$54:$D$63,2,FALSE) -> TZCO TZ2000 Дзикай | H6: =SMALL($D$31:$M$31,E6) -> 172584.72
A7: =A6+1 -> 2 | B7: =VLOOKUP(C7,$B$54:$D$63,3,FALSE) -> Komatsu PC2000-11R ИСТК | C7: =SMALL($D$49:$M$49,A7) -> 48.838068 | E7: =E6+1 -> 2 | F7: =VLOOKUP(H7,$C$54:$D$63,2,FALSE) -> Shantui SE2000LCW Строймпорттехника | H7: =SMALL($D$31:$M$31,E7) -> 187624.79
A8: =A7+1 -> 3 | B8: =VLOOKUP(C8,$B$54:$D$63,3,FALSE) -> Zoomlion ZE2000G ОРИКС | C8: =SMALL($D$49:$M$49,A8) -> 49.38578 | E8: =E7+1 -> 3 | F8: =VLOOKUP(H8,$C$54:$D$63,2,FALSE) -> Estar ESE2000 ГПБ Комплект | H8: =SMALL($D$31:$M$31,E8) -> 193158.57
A9: =A8+1 -> 4 | B9: =VLOOKUP(C9,$B$54:$D$63,3,FALSE) -> Komatsu PC2000-11R Mining Solutions | C9: =SMALL($D$49:$M$49,A9) -> 51.164872 | E9: =E8+1 -> 4 | F9: =VLOOKUP(H9,$C$54:$D$63,2,FALSE) -> Sany SY2000 АСТ | H9: =SMALL($D$31:$M$31,E9) -> 219895.6
A10: =A9+1 -> 5 | B10: =VLOOKUP(C10,$B$54:$D$63,3,FALSE) -> Shantui SE2000LCW Строймпорттехника | C10: =SMALL($D$49:$M$49,A10) -> 52.357275 | E10: =E9+1 -> 5 | F10: =VLOOKUP(H10,$C$54:$D$63,2,FALSE) -> Komatsu PC2000-11R Огунвэй | H10: =SMALL($D$31:$M$31,E10) -> 222029.35
A11: =A10+1 -> 6 | B11: =VLOOKUP(C11,$B$54:$D$63,3,FALSE) -> Hitachi EX2000 Майнтек | C11: =SMALL($D$49:$M$49,A11) -> 53.489754 | E11: =E10+1 -> 6 | F11: =VLOOKUP(H11,$C$54:$D$63,2,FALSE) -> Zoomlion ZE2000G ОРИКС | H11: =SMALL($D$31:$M$31,E11) -> 225581.68
A12: =A11+1 -> 7 | B12: =VLOOKUP(C12,$B$54:$D$63,3,FALSE) -> Estar ESE2000 ГПБ Комплект | C12: =SMALL($D$49:$M$49,A12) -> 55.110917 | E12: =E11+1 -> 7 | F12: =VLOOKUP(H12,$C$54:$D$63,2,FALSE) -> XCMG LYR 2000 Огунвэй | H12: =SMALL($D$31:$M$31,E12) -> 231366.47
A13: =A12+1 -> 8 | B13: =VLOOKUP(C13,$B$54:$D$63,3,FALSE) -> Sany SY2000 АСТ | C13: =SMALL($D$49:$M$49,A13) -> 58.703686 | E13: =E12+1 -> 8 | F13: =VLOOKUP(H13,$C$54:$D$63,2,FALSE) -> Hitachi EX2000 Майнтек | H13: =SMALL($D$31:$M$31,E13) -> 243602.56
A14: =A13+1 -> 9 | B14: =VLOOKUP(C14,$B$54:$D$63,3,FALSE) -> #NUM! | C14: =SMALL($D$49:$M$49,A14) -> #NUM! | E14: =E13+1 -> 9 | F14: =VLOOKUP(H14,$C$54:$D$63,2,FALSE) -> Komatsu PC2000-11R ИСТК | H14: =SMALL($D$31:$M$31,E14) -> 258952.52
A15: =A14+1 -> 10 | B15: =VLOOKUP(C15,$B$54:$D$63,3,FALSE) -> #NUM! | C15: =SMALL($D$49:$M$49,A15) -> #NUM! | E15: =E14+1 -> 10 | F15: =VLOOKUP(H15,$C$54:$D$63,2,FALSE) -> Komatsu PC2000-11R Mining Solutions | H15: =SMALL($D$31:$M$31,E15) -> 289278.04
F17: в верхней части только из-за ковша | I17: не дали данные по ремонтам, только ТО. В мире - 3 ед., 2 - из них на ОПИ | J17: не предоставили данные для расчета, приравнены к PC2000 ИСТК. Поставка из Китая - 15 мес!!! | K17: не предоставили данные для расчета
A18: № п/п | B18: Параметры | C18: Ед.изм. | D18: Komatsu PC2000-11R Mining Solutions | E18: Komatsu PC2000-11R ИСТК | F18: Zoomlion ZE2000G ОРИКС | G18: Sany SY2000 АСТ | H18: Shantui SE2000LCW Строймпорттехника | I18: TZCO TZ2000 Дзикай | J18: Komatsu PC2000-11R Огунвэй | K18: XCMG LYR 2000 Огунвэй | L18: Hitachi EX2000 Майнтек | M18: Estar ESE2000 ГПБ Комплект | N18: Примечания
A19: 1 | B19: Производственные показатели
A20: =A19+1 -> 2 | B20: Геометрическая емкость ковша | C20: м3 | D20: ='3. Час.произв.'!D6 -> 10 | E20: ='3. Час.произв.'!E6 -> 10 | F20: ='3. Час.произв.'!F6 -> 12 | G20: ='3. Час.произв.'!G6 -> 10 | H20: ='3. Час.произв.'!H6 -> 9.6 | I20: ='3. Час.произв.'!I6 -> 12 | J20: ='3. Час.произв.'!J6 -> 10 | L20: ='3. Час.произв.'!L6 -> 9.5 | M20: ='3. Час.произв.'!M6 -> 10
A21: =A20+1 -> 3 | B21: Емкость ковша с шапкой | C21: м3 | D21: ='3. Час.произв.'!D7 -> 12 | E21: ='3. Час.произв.'!E7 -> 12 | F21: ='3. Час.произв.'!F7 -> 13 | G21: ='3. Час.произв.'!G7 -> 12 | H21: ='3. Час.произв.'!H7 -> 12 | I21: ='3. Час.произв.'!I7 -> 13.5 | J21: ='3. Час.произв.'!J7 -> 12 | L21: ='3. Час.произв.'!L7 -> 12 | M21: ='3. Час.произв.'!M7 -> 12
A22: =A21+1 -> 4 | B22: Время цикла | C22: сек | D22: ='3. Час.произв.'!D19 -> 37.3 | E22: ='3. Час.произв.'!E19 -> 37.3 | F22: ='3. Час.произв.'!F19 -> 37.3 | G22: ='3. Час.произв.'!G19 -> 37.3 | H22: ='3. Час.произв.'!H19 -> 37.3 | I22: ='3. Час.произв.'!I19 -> 37.3 | J22: ='3. Час.произв.'!J19 -> 37.3 | L22: ='3. Час.произв.'!L19 -> 37.3 | M22: ='3. Час.произв.'!M19 -> 37.3
A23: =A22+1 -> 5 | B23: КТГ экскаватора (средний за период эксплуатации) | C23: коэфф. | D23: ='2. Произв-сть экскаваторов'!N18 -> 0.79038201 | E23: ='2. Произв-сть экскаваторов'!N19 -> 0.79038201 | F23: ='2. Произв-сть экскаваторов'!N20 -> 0.72097116 | G23: ='2. Произв-сть экскаваторов'!N21 -> 0.72097116 | H23: ='2. Произв-сть экскаваторов'!N22 -> 0.72097116 | I23: ='2. Произв-сть экскаваторов'!N23 -> 0.72097116 | J23: ='2. Произв-сть экскаваторов'!N24 -> 0.79038201 | L23: ='2. Произв-сть экскаваторов'!N26 -> 0.72245288 | M23: ='2. Произв-сть экскаваторов'!N27 -> 0.72097116
A24: =A23+1 -> 6 | B24: Производительность нового экск. (средняя за период экспл.) | C24: тыс.м3 | D24: ='2. Произв-сть экскаваторов'!N83 -> 1894.8939 | E24: ='2. Произв-сть экскаваторов'!N84 -> 1894.8939 | F24: ='2. Произв-сть экскаваторов'!N85 -> 2118.7596 | G24: ='2. Произв-сть экскаваторов'!N86 -> 1728.4893 | H24: ='2. Произв-сть экскаваторов'!N87 -> 1728.4893 | I24: ='2. Произв-сть экскаваторов'!N88 -> 2118.7596 | J24: ='2. Произв-сть экскаваторов'!N89 -> 1894.8939 | L24: ='2. Произв-сть экскаваторов'!N91 -> 1732.114 | M24: ='2. Произв-сть экскаваторов'!N92 -> 1728.4893
A25: =A24+1 -> 7 | B25: Двигатель | C25: марка | D25: Кomatsu SAA12V140E[1]3 12 - 140 x 165 30.48 | E25: Komatsu SAA12V140E-7 12 - 140 x 165 30.48 | F25: Cummins QST30 | G25: Cummins QSK38 | H25: Weichai 12M33 | I25: Weichai 12M33 | L25: Cummins QST30-C | M25: Cummins QSK38
A26: =A25+1 -> 8 | B26: Расход ДТ - от поставщика | D26: ='PC2000-8 MS'!D50 -> 80 литров в час | E26: 105 литров в час | F26: 0,286 кг/м3 | G26: ='Sany АСТ'!$D$38 -> 0,19 гр/м3 | H26: 120 л/час = 102 кг/час | I26: 60 кг/час | L26: 129 кг/ч | M26: 110-140 л/час. Среднее - 125 л/час = 106 кг/час
A27: =A26+1 -> 9 | B27: Расход ДТ - в расчете | C27: значение | D27: ='4. Аннуитеты'!D42 -> 88.464215 | E27: ='4. Аннуитеты'!D183 -> 88.464215 | F27: ='4. Аннуитеты'!D330 -> 0.286 | G27: ='4. Аннуитеты'!D471 -> 0.19 | H27: ='4. Аннуитеты'!D606 -> 102 | J27: ='4. Аннуитеты'!$D$888 -> 88.464215 | L27: ='4. Аннуитеты'!D1170 -> 129.2425 | M27: ='4. Аннуитеты'!D1311 -> 106.25
A28: =A27+1 -> 10 | C28: ед.изм. | D28: ='4. Аннуитеты'!C42 -> кг/час | E28: ='4. Аннуитеты'!C183 -> кг/час | F28: ='4. Аннуитеты'!C330 -> кг/м3 | G28: ='4. Аннуитеты'!C471 -> кг/м3 | H28: ='4. Аннуитеты'!C606 -> кг/час | J28: ='4. Аннуитеты'!C888 -> кг/час | L28: ='4. Аннуитеты'!C1170 -> кг/час | M28: ='4. Аннуитеты'!C1311 -> кг/час
A29: =A28+1 -> 11 | C29: комментарий | D29: факт КБЕ по PC2000 | E29: факт КБЕ по PC2000 | F29: от поставщика | G29: от поставщика | H29: от поставщика | J29: факт КБЕ по PC2000 | L29: от поставщика | M29: поставщик
A30: =A29+1 -> 12 | B30: Срок эксплуатации | C30: лет | D30: 10 | E30: 10 | F30: 10 | G30: 10 | H30: 10 | I30: 10 | J30: 10 | L30: 10 | M30: 10
A31: =A30+1 -> 13 | B31: Стоимость экскаватора | C31: тыс.руб | D31: =SUM(D34:D35) -> 289278.04 | E31: =SUM(E34:E35) -> 258952.52 | F31: =SUM(F34:F35) -> 225581.68 | G31: =SUM(G34:G35) -> 219895.6 | H31: =SUM(H34:H35) -> 187624.79 | I31: =SUM(I34:I35) -> 172584.72 | J31: =SUM(J34:J35) -> 222029.35 | K31: =SUM(K34:K35) -> 231366.47 | ... M31: =SUM(M34:M35) -> 193158.57 | Q31: Курс ЦБ с 08.07.2026
A32: =A31+1 -> 14 | B32: Цена за 1 ед., тыс.юаней | C32: 0 | F32: =20129 -> 20129 | G32: =19621.62259 -> 19621.623 | H32: =16742.0489 -> 16742.049 | I32: 15400 | J32: =19812.02 -> 19812.02 | K32: =20645.186 -> 20645.186 | M32: =17235.836 -> 17235.836 | Q32: 11.2068 | R32: юань
A33: =A32+1 -> 15 | B33: Цена за 1 ед., тыс.долларов | C33: 0 | D33: =3800 -> 3800 | E33: 3401.6393 | L33: 3200 | Q33: 76.1258 | R33: доллар
A34: =A33+1 -> 16 | B34: Цена за 1 ед., тыс.руб | C34: тыс.руб | D34: =D33*$Q$33 -> 289278.04 | E34: =E33*$Q$33 -> 258952.52 | F34: =F32*$Q32 -> 225581.68 | G34: =G32*$Q32 -> 219895.6 | H34: =H32*$Q32 -> 187624.79 | I34: =I32*$Q32 -> 172584.72 | J34: =J32*$Q32 -> 222029.35 | K34: =K32*$Q32 -> 231366.47 | L34: =L33*$Q$33 -> 243602.56 | M34: =M32*$Q32 -> 193158.57 | Q34: 86.8976 | R34: евро
A35: =A34+1 -> 17 | B35: Стоимость монтажных работ | C35: тыс.руб
A36: =A35+1 -> 18 | B36: Срок поставки | C36: мес. | D36: =120/30 -> 4 | E36: =310/30 -> 10.333333 | F36: =30/30 -> 1 | G36: =90/30 -> 3 | H36: =70/30 -> 2.3333333 | I36: =210/30 -> 7 | J36: =450/30 -> 15 | K36: =100/30 -> 3.3333333 | L36: 4 мес - но уточни у Леши Михайлова | N36: Потребность - апр.2027 | Q36: =(U36-S36)/30 -> 8.1333333 | R36: месяцев до ввода с | S36: 46234 | U36: 46478
A37: =A36+1 -> 19 | B37: Референс | F37: 3 ед. - в РФ | G37: 5 ед. в РФ 2025-2025 гг | H37: 1 ед. - в Китае, на угле; 5 ед. Shantui1500 (3 - Красноярский кр., по 1 - Индонезия и Китай) | I37: 3 ед. (в т.ч. 1 - электр.), введены в 2026 году. Из 3 ед. - 2 ед.на ОПИ в Китае | L37: 50 ед в РФ, всего произведено 113 ед с 2019 года | M37: 7 ед. - введены в РФ в 2024-2025 гг
A39: =A37+1 -> 20 | B39: Аннуитеты
A40: =A39+1 -> 21 | B40: операционный аннуитет | C40: руб./м3 | D40: ='4. Аннуитеты'!N116 -> 24.14614 | E40: ='4. Аннуитеты'!N257 -> 24.651757 | F40: ='4. Аннуитеты'!N398 -> 30.542498 | G40: ='4. Аннуитеты'!N539 -> 36.188048 | H40: ='4. Аннуитеты'!N680 -> 33.145923 | J40: ='4. Аннуитеты'!N962 -> 25.267376 | L40: ='4. Аннуитеты'!N1244 -> 28.598901 | M40: ='4. Аннуитеты'!N1385 -> 35.332948
A41: =A40+1 -> 22 | B41: ='4. Аннуитеты'!B117 -> ТО, ТР, ППР, вкл смазочные | C41: руб./м3 | D41: ='4. Аннуитеты'!N117 -> 19.817928 | E41: ='4. Аннуитеты'!N258 -> 19.817928 | F41: ='4. Аннуитеты'!N399 -> 22.24111 | G41: ='4. Аннуитеты'!N540 -> 32.88677 | H41: ='4. Аннуитеты'!N681 -> 27.262861 | J41: ='4. Аннуитеты'!N963 -> 19.817928 | L41: ='4. Аннуитеты'!N1245 -> 19.528463 | M41: ='4. Аннуитеты'!N1386 -> 28.045203
A42: =A41+1 -> 23 | B42: ='4. Аннуитеты'!B118 -> затраты на сервис: ремонты и ТО | C42: руб./м3 | D42: ='4. Аннуитеты'!N118 -> 1.2600942 | E42: ='4. Аннуитеты'!N259 -> 1.2600942 | F42: ='4. Аннуитеты'!N400 -> 1.3742268 | G42: ='4. Аннуитеты'!N541 -> 3.4256417 | H42: ='4. Аннуитеты'!N682 -> 1.6845093 | J42: ='4. Аннуитеты'!N964 -> 1.2600942 | L42: ='4. Аннуитеты'!N1246 -> 1.5291124 | M42: ='4. Аннуитеты'!N1387 -> 3.4057112
A43: =A42+1 -> 24 | B43: ='4. Аннуитеты'!B119 -> расходники на ковш | C43: руб./м3 | D43: ='4. Аннуитеты'!N119 -> 0.88762507 | E43: ='4. Аннуитеты'!N260 -> 0.88762507 | F43: ='4. Аннуитеты'!N401 -> 0.88907324 | G43: ='4. Аннуитеты'!N542 -> 0.88907324 | H43: ='4. Аннуитеты'!N683 -> 0.88907324 | J43: ='4. Аннуитеты'!N965 -> 0.88762507 | L43: ='4. Аннуитеты'!N1247 -> 0.87297406 | M43: ='4. Аннуитеты'!N1388 -> 0.88907324
A44: =A43+1 -> 25 | B44: ='4. Аннуитеты'!B120 -> Дизтопливо | C44: руб./м3 | D44: ='4. Аннуитеты'!N120 -> 11.374639 | E44: ='4. Аннуитеты'!N261 -> 11.374639 | F44: ='4. Аннуитеты'!N402 -> 15.976934 | G44: ='4. Аннуитеты'!N543 -> 10.614047 | H44: ='4. Аннуитеты'!N684 -> 13.136454 | J44: ='4. Аннуитеты'!N966 -> 11.374639 | L44: ='4. Аннуитеты'!N1248 -> 16.343578 | M44: ='4. Аннуитеты'!N1389 -> 13.683806
...

Sheet 2. Произв-сть экскаваторов
B2: Производительность новых экскаваторов | D2: 1 | E2: =D2+1 -> 2 | F2: =E2+1 -> 3 | G2: =F2+1 -> 4 | H2: =G2+1 -> 5 | I2: =H2+1 -> 6 | J2: =I2+1 -> 7 | K2: =J2+1 -> 8 | L2: =K2+1 -> 9 | M2: =L2+1 -> 10
B3: Наименование показателя | C3: Ед. изм. | D3: 2027 | E3: =D3+1 -> 2028 | F3: =E3+1 -> 2029 | G3: =F3+1 -> 2030 | H3: =G3+1 -> 2031 | I3: =H3+1 -> 2032 | J3: =I3+1 -> 2033 | K3: =J3+1 -> 2034 | L3: =K3+1 -> 2035 | M3: =L3+1 -> 2036 | N3: среднее
B4: Дней | C4: дн | D4: 365 | E4: 366 | F4: 365 | G4: 365 | H4: 365 | I4: 366 | J4: 365 | K4: 365 | L4: 365 | M4: 366
B5: КФВ | C5: час | D5: =D4*24 -> 8760 | E5: =E4*24 -> 8784 | F5: =F4*24 -> 8760 | G5: =G4*24 -> 8760 | H5: =H4*24 -> 8760 | I5: =I4*24 -> 8784 | J5: =J4*24 -> 8760 | K5: =K4*24 -> 8760 | ... M5: =M4*24 -> 8784
B6: Объем ковша с шапкой
B7: ='1. Сводная_аннуитеты'!D18 -> Komatsu PC2000-11R Mining Solutions | C7: м3 | D7: ='PC2000-8 MS'!$D$6 -> 12 | E7: =D7 -> 12 | F7: =E7 -> 12 | G7: =F7 -> 12 | H7: =G7 -> 12 | I7: =H7 -> 12 | J7: =I7 -> 12 | K7: =J7 -> 12 | L7: =K7 -> 12 | M7: =L7 -> 12
B8: ='1. Сводная_аннуитеты'!E18 -> Komatsu PC2000-11R ИСТК | C8: м3 | D8: ='PC2000-11R ИСТК'!D6 -> 12 | E8: =D8 -> 12 | F8: =E8 -> 12 | G8: =F8 -> 12 | H8: =G8 -> 12 | I8: =H8 -> 12 | J8: =I8 -> 12 | K8: =J8 -> 12 | L8: =K8 -> 12 | M8: =L8 -> 12
B9: ='1. Сводная_аннуитеты'!F18 -> Zoomlion ZE2000G ОРИКС | C9: м3 | D9: =Zooml_Орикс!D6 -> 13 | E9: =D9 -> 13 | F9: =E9 -> 13 | G9: =F9 -> 13 | H9: =G9 -> 13 | I9: =H9 -> 13 | J9: =I9 -> 13 | K9: =J9 -> 13 | L9: =K9 -> 13 | M9: =L9 -> 13
B10: ='1. Сводная_аннуитеты'!G18 -> Sany SY2000 АСТ | C10: м3 | D10: ='Sany АСТ'!D6 -> 12 | E10: =D10 -> 12 | F10: =E10 -> 12 | G10: =F10 -> 12 | H10: =G10 -> 12 | I10: =H10 -> 12 | J10: =I10 -> 12 | K10: =J10 -> 12 | L10: =K10 -> 12 | M10: =L10 -> 12
B11: ='1. Сводная_аннуитеты'!H18 -> Shantui SE2000LCW Строймпорттехника | C11: м3 | D11: ='Shantui Стройимп'!D6 -> 12 | E11: =D11 -> 12 | F11: =E11 -> 12 | G11: =F11 -> 12 | H11: =G11 -> 12 | I11: =H11 -> 12 | J11: =I11 -> 12 | K11: =J11 -> 12 | L11: =K11 -> 12 | M11: =L11 -> 12
B12: ='1. Сводная_аннуитеты'!I18 -> TZCO TZ2000 Дзикай | C12: м3 | D12: ='TZCO Дзикай'!D6 -> 13.5 | E12: =D12 -> 13.5 | F12: =E12 -> 13.5 | G12: =F12 -> 13.5 | H12: =G12 -> 13.5 | I12: =H12 -> 13.5 | J12: =I12 -> 13.5 | K12: =J12 -> 13.5 | L12: =K12 -> 13.5 | M12: =L12 -> 13.5
B13: ='1. Сводная_аннуитеты'!J18 -> Komatsu PC2000-11R Огунвэй | C13: м3 | D13: 12 | E13: =D13 -> 12 | F13: =E13 -> 12 | G13: =F13 -> 12 | H13: =G13 -> 12 | I13: =H13 -> 12 | J13: =I13 -> 12 | K13: =J13 -> 12 | L13: =K13 -> 12 | M13: =L13 -> 12
B14: ='1. Сводная_аннуитеты'!K18 -> XCMG LYR 2000 Огунвэй | C14: м3 | D14: 12 | E14: =D14 -> 12 | F14: =E14 -> 12 | G14: =F14 -> 12 | H14: =G14 -> 12 | I14: =H14 -> 12 | J14: =I14 -> 12 | K14: =J14 -> 12 | L14: =K14 -> 12 | M14: =L14 -> 12
B15: ='1. Сводная_аннуитеты'!L18 -> Hitachi EX2000 Майнтек | C15: м3 | D15: 12 | E15: =D15 -> 12 | F15: =E15 -> 12 | G15: =F15 -> 12 | H15: =G15 -> 12 | I15: =H15 -> 12 | J15: =I15 -> 12 | K15: =J15 -> 12 | L15: =K15 -> 12 | M15: =L15 -> 12
B16: ='1. Сводная_аннуитеты'!M18 -> Estar ESE2000 ГПБ Комплект | C16: м3 | D16: 12 | E16: =D16 -> 12 | F16: =E16 -> 12 | G16: =F16 -> 12 | H16: =G16 -> 12 | I16: =H16 -> 12 | J16: =I16 -> 12 | K16: =J16 -> 12 | L16: =K16 -> 12 | M16: =L16 -> 12
B17: КТГ
B18: =B7 -> Komatsu PC2000-11R Mining Solutions | C18: коэф. | D18: ='PC2000-8 MS'!E7 -> 0.92406268 | E18: ='PC2000-8 MS'!F7 -> 0.79773755 | F18: ='PC2000-8 MS'!G7 -> 0.82453381 | G18: ='PC2000-8 MS'!H7 -> 0.76394441 | H18: ='PC2000-8 MS'!I7 -> 0.76281505 | I18: ='PC2000-8 MS'!J7 -> 0.81214813 | J18: ='PC2000-8 MS'!K7 -> 0.78656324 | K18: ='PC2000-8 MS'!L7 -> 0.84263903 | ... M18: ='PC2000-8 MS'!N7 -> 0.82670539 | N18: =AVERAGE(D18:M18) -> 0.79038201 | O18: ='PC2000-8 MS'!O7 -> факт по Группе
B19: =B8 -> Komatsu PC2000-11R ИСТК | C19: коэф. | D19: ='PC2000-11R ИСТК'!E7 -> 0.92406268 | E19: ='PC2000-11R ИСТК'!F7 -> 0.79773755 | F19: ='PC2000-11R ИСТК'!G7 -> 0.82453381 | G19: ='PC2000-11R ИСТК'!H7 -> 0.76394441 | H19: ='PC2000-11R ИСТК'!I7 -> 0.76281505 | I19: ='PC2000-11R ИСТК'!J7 -> 0.81214813 | J19: ='PC2000-11R ИСТК'!K7 -> 0.78656324 | K19: ='PC2000-11R ИСТК'!L7 -> 0.84263903 | ... M19: ='PC2000-11R ИСТК'!N7 -> 0.82670539 | N19: =AVERAGE(D19:M19) -> 0.79038201 | O19: ='PC2000-11R ИСТК'!Y7 -> равно PC2000 - факт по Группе
B20: =B9 -> Zoomlion ZE2000G ОРИКС | C20: коэф. | D20: =Zooml_Орикс!E7 -> 0.85465183 | E20: =Zooml_Орикс!F7 -> 0.7283267 | F20: =Zooml_Орикс!G7 -> 0.75512296 | G20: =Zooml_Орикс!H7 -> 0.69453356 | H20: =Zooml_Орикс!I7 -> 0.6934042 | I20: =Zooml_Орикс!J7 -> 0.74273728 | J20: =Zooml_Орикс!K7 -> 0.71715238 | K20: =Zooml_Орикс!L7 -> 0.77322818 | ... M20: =Zooml_Орикс!N7 -> 0.75729454 | N20: =AVERAGE(D20:M20) -> 0.72097116 | O20: =Zooml_Орикс!Y7 -> первый год - факт Люгонга по Группе, далее динамика от факта PC2000
B21: =B10 -> Sany SY2000 АСТ | C21: коэф. | D21: ='Sany АСТ'!E7 -> 0.85465183 | E21: ='Sany АСТ'!F7 -> 0.7283267 | F21: ='Sany АСТ'!G7 -> 0.75512296 | G21: ='Sany АСТ'!H7 -> 0.69453356 | H21: ='Sany АСТ'!I7 -> 0.6934042 | I21: ='Sany АСТ'!J7 -> 0.74273728 | J21: ='Sany АСТ'!K7 -> 0.71715238 | K21: ='Sany АСТ'!L7 -> 0.77322818 | ... M21: ='Sany АСТ'!N7 -> 0.75729454 | N21: =AVERAGE(D21:M21) -> 0.72097116 | O21: ='Sany АСТ'!O7 -> первый год - факт Люгонга по Группе, далее динамика от факта PC2000
B22: =B11 -> Shantui SE2000LCW Строймпорттехника | C22: коэф. | D22: ='Shantui Стройимп'!E7 -> 0.85465183 | E22: ='Shantui Стройимп'!F7 -> 0.7283267 | F22: ='Shantui Стройимп'!G7 -> 0.75512296 | G22: ='Shantui Стройимп'!H7 -> 0.69453356 | H22: ='Shantui Стройимп'!I7 -> 0.6934042 | I22: ='Shantui Стройимп'!J7 -> 0.74273728 | J22: ='Shantui Стройимп'!K7 -> 0.71715238 | K22: ='Shantui Стройимп'!L7 -> 0.77322818 | ... M22: ='Shantui Стройимп'!N7 -> 0.75729454 | N22: =AVERAGE(D22:M22) -> 0.72097116 | O22: ='Shantui Стройимп'!Y7 -> первый год - факт Люгонга по Группе, далее динамика от факта PC2000
B23: =B12 -> TZCO TZ2000 Дзикай | C23: коэф. | D23: ='TZCO Дзикай'!E7 -> 0.85465183 | E23: ='TZCO Дзикай'!F7 -> 0.7283267 | F23: ='TZCO Дзикай'!G7 -> 0.75512296 | G23: ='TZCO Дзикай'!H7 -> 0.69453356 | H23: ='TZCO Дзикай'!I7 -> 0.6934042 | I23: ='TZCO Дзикай'!J7 -> 0.74273728 | J23: ='TZCO Дзикай'!K7 -> 0.71715238 | K23: ='TZCO Дзикай'!L7 -> 0.77322818 | ... M23: ='TZCO Дзикай'!N7 -> 0.75729454 | N23: =AVERAGE(D23:M23) -> 0.72097116 | O23: ='TZCO Дзикай'!Y7 -> первый год - факт Люгонга по Группе, далее динамика от факта PC2000
B24: =B13 -> Komatsu PC2000-11R Огунвэй | C24: коэф. | D24: =D19 -> 0.92406268 | E24: =E19 -> 0.79773755 | F24: =F19 -> 0.82453381 | G24: =G19 -> 0.76394441 | H24: =H19 -> 0.76281505 | I24: =I19 -> 0.81214813 | J24: =J19 -> 0.78656324 | K24: =K19 -> 0.84263903 | ... M24: =M19 -> 0.82670539 | N24: =AVERAGE(D24:M24) -> 0.79038201 | O24: =O19 -> равно PC2000 - факт по Группе
B25: =B14 -> XCMG LYR 2000 Огунвэй | C25: коэф. | D25: =Факт.КТГ!D23 -> 0.85465183 | E25: =Факт.КТГ!E23 -> 0.7283267 | F25: =Факт.КТГ!F23 -> 0.75512296 | G25: =Факт.КТГ!G23 -> 0.69453356 | H25: =Факт.КТГ!H23 -> 0.6934042 | I25: =Факт.КТГ!I23 -> 0.74273728 | J25: =Факт.КТГ!J23 -> 0.71715238 | K25: =Факт.КТГ!K23 -> 0.77322818 | ... M25: =Факт.КТГ!M23 -> 0.75729454 | N25: =AVERAGE(D25:M25) -> 0.72097116 | O25: =O20 -> первый год - факт Люгонга по Группе, далее динамика от факта PC2000
B26: =B15 -> Hitachi EX2000 Майнтек | C26: коэф. | D26: ='Факт.КТГ Алдан Hitachi'!I33 -> 0.74 | E26: ='Факт.КТГ Алдан Hitachi'!J33 -> 0.73 | F26: ='Факт.КТГ Алдан Hitachi'!K33 -> 0.79 | G26: ='Факт.КТГ Алдан Hitachi'!L33 -> 0.63 | H26: ='Факт.КТГ Алдан Hitachi'!M33 -> 0.68812671 | I26: ='Факт.КТГ Алдан Hitachi'!N33 -> 0.82178051 | J26: ='Факт.КТГ Алдан Hitachi'!O33 -> 0.57808219 | K26: ='Факт.КТГ Алдан Hitachi'!P33 -> 0.70980826 | ... M26: ='Факт.КТГ Алдан Hitachi'!R33 -> 0.79134985 | N26: =AVERAGE(D26:M26) -> 0.72245288 | O26: факт Алдана по Hitachi EX1200 (обратная лопата)
B27: =B16 -> Estar ESE2000 ГПБ Комплект | C27: коэф. | D27: =D25 -> 0.85465183 | E27: =E25 -> 0.7283267 | F27: =F25 -> 0.75512296 | G27: =G25 -> 0.69453356 | H27: =H25 -> 0.6934042 | I27: =I25 -> 0.74273728 | J27: =J25 -> 0.71715238 | K27: =K25 -> 0.77322818 | ... M27: =M25 -> 0.75729454 | N27: =AVERAGE(D27:M27) -> 0.72097116 | O27: =O25 -> первый год - факт Люгонга по Группе, далее динамика от факта PC2000
B28: Техническая готовность
B29: =B7 -> Komatsu PC2000-11R Mining Solutions | C29: час. | D29: =D$5*D18 -> 8094.7891 | E29: =E$5*E18 -> 7007.3267 | F29: =F$5*F18 -> 7222.9162 | G29: =G$5*G18 -> 6692.1531 | H29: =H$5*H18 -> 6682.2598 | I29: =I$5*I18 -> 7133.9091 | J29: =J$5*J18 -> 6890.2939 | K29: =K$5*K18 -> 7381.5179 | ... M29: =M$5*M18 -> 7261.7802
B30: =B8 -> Komatsu PC2000-11R ИСТК | C30: час. | D30: =D$5*D19 -> 8094.7891 | E30: =E$5*E19 -> 7007.3267 | F30: =F$5*F19 -> 7222.9162 | G30: =G$5*G19 -> 6692.1531 | H30: =H$5*H19 -> 6682.2598 | I30: =I$5*I19 -> 7133.9091 | J30: =J$5*J19 -> 6890.2939 | K30: =K$5*K19 -> 7381.5179 | ... M30: =M$5*M19 -> 7261.7802
B31: =B9 -> Zoomlion ZE2000G ОРИКС | C31: час. | D31: =D$5*D20 -> 7486.75 | E31: =E$5*E20 -> 6397.6217 | F31: =F$5*F20 -> 6614.8771 | G31: =G$5*G20 -> 6084.114 | H31: =H$5*H20 -> 6074.2208 | I31: =I$5*I20 -> 6524.2042 | J31: =J$5*J20 -> 6282.2549 | K31: =K$5*K20 -> 6773.4789 | ... M31: =M$5*M20 -> 6652.0753
B32: =B10 -> Sany SY2000 АСТ | C32: час. | D32: =D$5*D21 -> 7486.75 | E32: =E$5*E21 -> 6397.6217 | F32: =F$5*F21 -> 6614.8771 | G32: =G$5*G21 -> 6084.114 | H32: =H$5*H21 -> 6074.2208 | I32: =I$5*I21 -> 6524.2042 | J32: =J$5*J21 -> 6282.2549 | K32: =K$5*K21 -> 6773.4789 | ... M32: =M$5*M21 -> 6652.0753
B33: =B11 -> Shantui SE2000LCW Строймпорттехника | C33: час. | D33: =D$5*D22 -> 7486.75 | E33: =E$5*E22 -> 6397.6217 | F33: =F$5*F22 -> 6614.8771 | G33: =G$5*G22 -> 6084.114 | H33: =H$5*H22 -> 6074.2208 | I33: =I$5*I22 -> 6524.2042 | J33: =J$5*J22 -> 6282.2549 | K33: =K$5*K22 -> 6773.4789 | ... M33: =M$5*M22 -> 6652.0753
B34: =B12 -> TZCO TZ2000 Дзикай | C34: час. | D34: =D$5*D23 -> 7486.75 | E34: =E$5*E23 -> 6397.6217 | F34: =F$5*F23 -> 6614.8771 | G34: =G$5*G23 -> 6084.114 | H34: =H$5*H23 -> 6074.2208 | I34: =I$5*I23 -> 6524.2042 | J34: =J$5*J23 -> 6282.2549 | K34: =K$5*K23 -> 6773.4789 | ... M34: =M$5*M23 -> 6652.0753
B35: =B13 -> Komatsu PC2000-11R Огунвэй | C35: час. | D35: =D$5*D24 -> 8094.7891 | E35: =E$5*E24 -> 7007.3267 | F35: =F$5*F24 -> 7222.9162 | G35: =G$5*G24 -> 6692.1531 | H35: =H$5*H24 -> 6682.2598 | I35: =I$5*I24 -> 7133.9091 | J35: =J$5*J24 -> 6890.2939 | K35: =K$5*K24 -> 7381.5179 | ... M35: =M$5*M24 -> 7261.7802
B36: =B14 -> XCMG LYR 2000 Огунвэй | C36: час. | D36: =D$5*D25 -> 7486.75 | E36: =E$5*E25 -> 6397.6217 | F36: =F$5*F25 -> 6614.8771 | G36: =G$5*G25 -> 6084.114 | H36: =H$5*H25 -> 6074.2208 | I36: =I$5*I25 -> 6524.2042 | J36: =J$5*J25 -> 6282.2549 | K36: =K$5*K25 -> 6773.4789 | ... M36: =M$5*M25 -> 6652.0753
B37: =B15 -> Hitachi EX2000 Майнтек | C37: час. | D37: =D$5*D26 -> 6482.4 | E37: =E$5*E26 -> 6412.32 | F37: =F$5*F26 -> 6920.4 | G37: =G$5*G26 -> 5518.8 | H37: =H$5*H26 -> 6027.99 | I37: =I$5*I26 -> 7218.52 | J37: =J$5*J26 -> 5064 | K37: =K$5*K26 -> 6217.9204 | ... M37: =M$5*M26 -> 6951.2171
B38: =B16 -> Estar ESE2000 ГПБ Комплект | C38: час. | D38: =D$5*D27 -> 7486.75 | E38: =E$5*E27 -> 6397.6217 | F38: =F$5*F27 -> 6614.8771 | G38: =G$5*G27 -> 6084.114 | H38: =H$5*H27 -> 6074.2208 | I38: =I$5*I27 -> 6524.2042 | J38: =J$5*J27 -> 6282.2549 | K38: =K$5*K27 -> 6773.4789 | ... M38: =M$5*M27 -> 6652.0753
B39: Ежесменные регламентные простои | C39: мин/см | D39: =SUM(D40:D42) -> 0 | E39: =SUM(E40:E42) -> 0 | F39: =SUM(F40:F42) -> 0 | G39: =SUM(G40:G42) -> 0 | H39: =SUM(H40:H42) -> 0 | I39: =SUM(I40:I42) -> 0 | J39: =SUM(J40:J42) -> 0 | K39: =SUM(K40:K42) -> 0 | ... M39: =SUM(M40:M42) -> 0
C40: мин/см | E40: =D40 -> 0 | F40: =E40 -> 0 | G40: =F40 -> 0 | H40: =G40 -> 0 | I40: =H40 -> 0 | J40: =I40 -> 0 | K40: =J40 -> 0 | L40: =K40 -> 0 | M40: =L40 -> 0 | N40: Балансировка КБЕ - новый PC2000
B41: все регламентные | C41: мин/см | E41: =D41 -> 0 | F41: =E41 -> 0 | G41: =F41 -> 0 | H41: =G41 -> 0 | I41: =H41 -> 0 | J41: =I41 -> 0 | K41: =J41 -> 0 | L41: =K41 -> 0 | M41: =L41 -> 0 | N41: Балансировка КБЕ - новый PC2000
...

Sheet 3. Час.произв.
B1: Часовая производительность погрузочной техники
B4: Модель экскаватора | C4: Ед.изм. | D4: ='1. Сводная_аннуитеты'!D18 -> Komatsu PC2000-11R Mining Solutions | E4: ='1. Сводная_аннуитеты'!E18 -> Komatsu PC2000-11R ИСТК | F4: ='1. Сводная_аннуитеты'!F18 -> Zoomlion ZE2000G ОРИКС | G4: ='1. Сводная_аннуитеты'!G18 -> Sany SY2000 АСТ | H4: ='1. Сводная_аннуитеты'!H18 -> Shantui SE2000LCW Строймпорттехника | I4: ='1. Сводная_аннуитеты'!I18 -> TZCO TZ2000 Дзикай | J4: ='1. Сводная_аннуитеты'!J18 -> Komatsu PC2000-11R Огунвэй | K4: ='1. Сводная_аннуитеты'!K18 -> XCMG LYR 2000 Огунвэй | ... M4: ='1. Сводная_аннуитеты'!M18 -> Estar ESE2000 ГПБ Комплект
B5: Объём ковша - в расчете | C5: м3 | D5: =D6 -> 10 | E5: =E6 -> 10 | F5: =F6 -> 12 | G5: =G6 -> 10 | H5: =H6 -> 9.6 | I5: =I6 -> 12 | J5: =J6 -> 10 | K5: =K6 -> 10 | ... M5: =M6 -> 10
B6: Объём ковша - геометрический | C6: м3 | D6: =E6 -> 10 | E6: ='PC2000-11R ИСТК'!D5 -> 10 | F6: =Zooml_Орикс!D5 -> 12 | G6: ='Sany АСТ'!D5 -> 10 | H6: ='Shantui Стройимп'!D5 -> 9.6 | I6: ='TZCO Дзикай'!D5 -> 12 | J6: =E6 -> 10 | K6: =J6 -> 10 | L6: 9.5 | M6: =K6 -> 10
B7: Объём ковша - с шапкой | C7: м3 | D7: ='PC2000-8 MS'!D6 -> 12 | E7: ='PC2000-11R ИСТК'!D6 -> 12 | F7: =Zooml_Орикс!D6 -> 13 | G7: ='Sany АСТ'!D6 -> 12 | H7: ='Shantui Стройимп'!D6 -> 12 | I7: ='TZCO Дзикай'!D6 -> 13.5 | J7: =E7 -> 12 | K7: =J7 -> 12 | L7: 12 | M7: ='Estar ГПБ'!D6 -> 12
B8: Грузоподъёмность самосвала | C8: тн | D8: 136 | E8: =D8 -> 136 | F8: =E8 -> 136 | G8: =F8 -> 136 | H8: =G8 -> 136 | I8: =H8 -> 136 | J8: =I8 -> 136 | K8: =J8 -> 136 | L8: =K8 -> 136 | M8: =K8 -> 136
B9: Плотность породы | C9: кг/м3 | D9: 2.787 | E9: =D9 -> 2.787 | F9: =E9 -> 2.787 | G9: =F9 -> 2.787 | H9: =G9 -> 2.787 | I9: =H9 -> 2.787 | J9: =I9 -> 2.787 | K9: =J9 -> 2.787 | L9: =K9 -> 2.787 | M9: =K9 -> 2.787 | N9: балансировка КБЕ
B10: Коэффициент разрыхления | C10: коэф. | D10: 1.5 | E10: =D10 -> 1.5 | F10: =E10 -> 1.5 | G10: =F10 -> 1.5 | H10: =G10 -> 1.5 | I10: =H10 -> 1.5 | J10: =I10 -> 1.5 | K10: =J10 -> 1.5 | L10: =K10 -> 1.5 | M10: =K10 -> 1.5 | N10: балансировка КБЕ
B11: Коэффициент наполнения ковша | C11: % | D11: 0.9 | E11: =D11 -> 0.9 | F11: =E11 -> 0.9 | G11: =F11 -> 0.9 | H11: =G11 -> 0.9 | I11: =H11 -> 0.9 | J11: =I11 -> 0.9 | K11: =J11 -> 0.9 | L11: =K11 -> 0.9 | M11: =K11 -> 0.9 | N11: балансировка КБЕ
B12: Коэффициент экскавации | C12: % | D12: =D11/D10 -> 0.6 | E12: =E11/E10 -> 0.6 | F12: =F11/F10 -> 0.6 | G12: =G11/G10 -> 0.6 | H12: =H11/H10 -> 0.6 | I12: =I11/I10 -> 0.6 | J12: =J11/J10 -> 0.6 | K12: =K11/K10 -> 0.6 | ... M12: =M11/M10 -> 0.6
B13: Коэффициент потерь горной массы при экскавации | C13: % | D13: 0.9 | E13: =D13 -> 0.9 | F13: =E13 -> 0.9 | G13: =F13 -> 0.9 | H13: =G13 -> 0.9 | I13: =H13 -> 0.9 | J13: =I13 -> 0.9 | K13: =J13 -> 0.9 | L13: =K13 -> 0.9 | M13: =K13 -> 0.9 | N13: балансировка КБЕ
B14: Порода в ковше | C14: тн | D14: =D5*D9*D12*D13 -> 15.0498 | E14: =E5*E9*E12*E13 -> 15.0498 | F14: =F5*F9*F12*F13 -> 18.05976 | G14: =G5*G9*G12*G13 -> 15.0498 | H14: =H5*H9*H12*H13 -> 14.447808 | I14: =I5*I9*I12*I13 -> 18.05976 | J14: =J5*J9*J12*J13 -> 15.0498 | K14: =K5*K9*K12*K13 -> 15.0498 | ... M14: =M5*M9*M12*M13 -> 15.0498
B15: Коэффициент использования грузоподъемности АС | C15: коэф. | D15: 1 | E15: =D15 -> 1 | F15: =E15 -> 1 | G15: =F15 -> 1 | H15: =G15 -> 1 | I15: =H15 -> 1 | J15: =I15 -> 1 | K15: =J15 -> 1 | L15: =K15 -> 1 | M15: =K15 -> 1 | N15: балансировка КБЕ
B16: Масса породы в самосвале | C16: тн | D16: =D8*D15 -> 136 | E16: =E8*E15 -> 136 | F16: =F8*F15 -> 136 | G16: =G8*G15 -> 136 | H16: =H8*H15 -> 136 | I16: =I8*I15 -> 136 | J16: =J8*J15 -> 136 | K16: =K8*K15 -> 136 | ... M16: =M8*M15 -> 136
B17: Кол-во ковшей, дробное | C17: шт. | D17: =D16/D14 -> 9.0366649 | E17: =E16/E14 -> 9.0366649 | F17: =F16/F14 -> 7.5305541 | G17: =G16/G14 -> 9.0366649 | H17: =H16/H14 -> 9.4131926 | I17: =I16/I14 -> 7.5305541 | J17: =J16/J14 -> 9.0366649 | K17: =K16/K14 -> 9.0366649 | ... M17: =M16/M14 -> 9.0366649
B18: Кол-во ковшей (циклов погрузки), практически | C18: шт. | D18: =ROUNDUP(D17,0) -> 10 | E18: =ROUNDUP(E17,0) -> 10 | F18: =ROUNDUP(F17,0) -> 8 | G18: =ROUNDUP(G17,0) -> 10 | H18: =ROUNDUP(H17,0) -> 10 | I18: =ROUNDUP(I17,0) -> 8 | J18: =ROUNDUP(J17,0) -> 10 | K18: =ROUNDUP(K17,0) -> 10 | ... M18: =ROUNDUP(M17,0) -> 10
B19: Время цикла | C19: сек | D19: 37.3 | E19: =D19 -> 37.3 | F19: =E19 -> 37.3 | G19: =F19 -> 37.3 | H19: =G19 -> 37.3 | I19: =H19 -> 37.3 | J19: =I19 -> 37.3 | K19: =J19 -> 37.3 | L19: =K19 -> 37.3 | M19: =K19 -> 37.3
B20: Время постановки самосвала под загрузку (время оборота а/с) | C20: сек | D20: 32 | E20: =D20 -> 32 | F20: =D20 -> 32 | G20: =E20 -> 32 | H20: =F20 -> 32 | I20: =G20 -> 32 | J20: =H20 -> 32 | K20: =I20 -> 32 | L20: =J20 -> 32 | M20: =J20 -> 32 | N20: балансировка КБЕ
B21: Максимальная теоретическая производительность | C21: а/с за час работы | D21: =3600/(D18*D19+D20) -> 8.8888889 | E21: =3600/(E18*E19+E20) -> 8.8888889 | F21: =3600/(F18*F19+F20) -> 10.895884 | G21: =3600/(G18*G19+G20) -> 8.8888889 | H21: =3600/(H18*H19+H20) -> 8.8888889 | I21: =3600/(I18*I19+I20) -> 10.895884 | J21: =3600/(J18*J19+J20) -> 8.8888889 | K21: =3600/(K18*K19+K20) -> 8.8888889 | ... M21: =3600/(M18*M19+M20) -> 8.8888889
C22: тн/час | D22: =D14*D17*D21 -> 1208.8889 | E22: =E14*E17*E21 -> 1208.8889 | F22: =F14*F17*F21 -> 1481.8402 | G22: =G14*G17*G21 -> 1208.8889 | H22: =H14*H17*H21 -> 1208.8889 | I22: =I14*I17*I21 -> 1481.8402 | J22: =J14*J17*J21 -> 1208.8889 | K22: =K14*K17*K21 -> 1208.8889 | ... M22: =M14*M17*M21 -> 1208.8889
C23: м3/час | D23: =D22/D9 -> 433.75992 | E23: =E22/E9 -> 433.75992 | F23: =F22/F9 -> 531.69723 | G23: =G22/G9 -> 433.75992 | H23: =H22/H9 -> 433.75992 | I23: =I22/I9 -> 531.69723 | J23: =J22/J9 -> 433.75992 | K23: =K22/K9 -> 433.75992 | ... M23: =M22/M9 -> 433.75992
B24: Теоретическая производительность | C24: а/с за час работы | D24: =3600/(D18*D19+D20) -> 8.8888889 | E24: =3600/(E18*E19+E20) -> 8.8888889 | F24: =3600/(F18*F19+F20) -> 10.895884 | G24: =3600/(G18*G19+G20) -> 8.8888889 | H24: =3600/(H18*H19+H20) -> 8.8888889 | I24: =3600/(I18*I19+I20) -> 10.895884 | J24: =3600/(J18*J19+J20) -> 8.8888889 | K24: =3600/(K18*K19+K20) -> 8.8888889 | ... M24: =3600/(M18*M19+M20) -> 8.8888889
C25: тн/час | D25: =D14*D17*D24 -> 1208.8889 | E25: =E14*E17*E24 -> 1208.8889 | F25: =F14*F17*F24 -> 1481.8402 | G25: =G14*G17*G24 -> 1208.8889 | H25: =H14*H17*H24 -> 1208.8889 | I25: =I14*I17*I24 -> 1481.8402 | J25: =J14*J17*J24 -> 1208.8889 | K25: =K14*K17*K24 -> 1208.8889 | ... M25: =M14*M17*M24 -> 1208.8889
C26: м3/час | D26: =D25/D9 -> 433.75992 | E26: =E25/E9 -> 433.75992 | F26: =F25/F9 -> 531.69723 | G26: =G25/G9 -> 433.75992 | H26: =H25/H9 -> 433.75992 | I26: =I25/I9 -> 531.69723 | J26: =J25/J9 -> 433.75992 | K26: =K25/K9 -> 433.75992 | ... M26: =M25/M9 -> 433.75992
B27: Время погрузки самосвала | C27: мин | D27: =D18*D19/60 -> 6.2166667 | E27: =E18*E19/60 -> 6.2166667 | F27: =F18*F19/60 -> 4.9733333 | G27: =G18*G19/60 -> 6.2166667 | H27: =H18*H19/60 -> 6.2166667 | I27: =I18*I19/60 -> 4.9733333 | J27: =J18*J19/60 -> 6.2166667 | K27: =K18*K19/60 -> 6.2166667 | ... M27: =M18*M19/60 -> 6.2166667
B29: Годовая (1-ый год) | C29: тыс.м3 | D29: =VLOOKUP(D$4,'2. Произв-сть экскаваторов'!$B$83:$D$92,3,FALSE) -> 2213.5159 | E29: =VLOOKUP(E$4,'2. Произв-сть экскаваторов'!$B$83:$D$92,3,FALSE) -> 2213.5159 | F29: =VLOOKUP(F$4,'2. Произв-сть экскаваторов'!$B$83:$D$92,3,FALSE) -> 2509.4897 | G29: =VLOOKUP(G$4,'2. Произв-сть экскаваторов'!$B$83:$D$92,3,FALSE) -> 2047.2479 | H29: =VLOOKUP(H$4,'2. Произв-сть экскаваторов'!$B$83:$D$92,3,FALSE) -> 2047.2479 | I29: =VLOOKUP(I$4,'2. Произв-сть экскаваторов'!$B$83:$D$92,3,FALSE) -> 2509.4897 | J29: =VLOOKUP(J$4,'2. Произв-сть экскаваторов'!$B$83:$D$92,3,FALSE) -> 2213.5159 | K29: =VLOOKUP(K$4,'2. Произв-сть экскаваторов'!$B$83:$D$92,3,FALSE) -> 2047.2479 | L29: ='2. Произв-сть экскаваторов'!D91 -> 1772.6089 | M29: =VLOOKUP(M$4,'2. Произв-сть экскаваторов'!$B$83:$D$92,3,FALSE) -> 2047.2479
D32: =D4 -> Komatsu PC2000-11R Mining Solutions | E32: =E4 -> Komatsu PC2000-11R ИСТК | F32: =F4 -> Zoomlion ZE2000G ОРИКС | G32: =G4 -> Sany SY2000 АСТ | H32: =H4 -> Shantui SE2000LCW Строймпорттехника | I32: =I4 -> TZCO TZ2000 Дзикай | J32: =J4 -> Komatsu PC2000-11R Огунвэй | K32: =K4 -> XCMG LYR 2000 Огунвэй | M32: =M4 -> Estar ESE2000 ГПБ Комплект
B33: Время цикла от постащиков | C33: сек | D33: ='PC2000-8 MS'!E13 -> 27 | E33: ='PC2000-11R ИСТК'!D13 -> 29 | F33: =Zooml_Орикс!D13 -> 30 | G33: ='Sany АСТ'!E13 -> 29.25 | H33: ='Shantui Стройимп'!D13 -> 25 | I33: ='TZCO Дзикай'!D13 -> 0 | M33: ='Estar ГПБ'!D11 -> 26
B39: Сухой Лог ОПР, прямая лопата. 2025
D67: =D69*1.5 -> 39.39
D68: 6.5
B69: PC-1250: Красноярск и Верни/СЛ ОПР - обратная лопата. 2025 | D69: 26.26
B121: Часовая PC-2000, факт-2025

Sheet 4. Аннуитеты
D1: 2026 | E1: =D1+1 -> 2027 | F1: =E1+1 -> 2028 | G1: =F1+1 -> 2029 | H1: =G1+1 -> 2030 | I1: =H1+1 -> 2031 | J1: =I1+1 -> 2032 | K1: =J1+1 -> 2033 | L1: =K1+1 -> 2034 | ... N1: =M1+1 -> 2036 | O1: 1.35962
E2: 1 | F2: =E2+1 -> 2 | G2: =F2+1 -> 3 | H2: =G2+1 -> 4 | I2: =H2+1 -> 5 | J2: =I2+1 -> 6 | K2: =J2+1 -> 7 | L2: =K2+1 -> 8 | M2: =L2+1 -> 9 | N2: =M2+1 -> 10
B3: Аннуитет затрат экскаватора
B5: ='1. Сводная_аннуитеты'!D18 -> Komatsu PC2000-11R Mining Solutions
B6: Показатель | C6: Ед. изм. | D6: Период | P6: =B5 -> Komatsu PC2000-11R Mining Solutions
D7: 0 | E7: =D7+1 -> 1 | F7: =E7+1 -> 2 | G7: =F7+1 -> 3 | H7: =G7+1 -> 4 | I7: =H7+1 -> 5 | J7: =I7+1 -> 6 | K7: =J7+1 -> 7 | L7: =K7+1 -> 8 | ... N7: =M7+1 -> 10 | P7: =P6 -> Komatsu PC2000-11R Mining Solutions
B8: Календарный фонд времени | E8: ='2. Произв-сть экскаваторов'!D$5 -> 8760 | F8: ='2. Произв-сть экскаваторов'!E$5 -> 8784 | G8: ='2. Произв-сть экскаваторов'!F$5 -> 8760 | H8: ='2. Произв-сть экскаваторов'!G$5 -> 8760 | I8: ='2. Произв-сть экскаваторов'!H$5 -> 8760 | J8: ='2. Произв-сть экскаваторов'!I$5 -> 8784 | K8: ='2. Произв-сть экскаваторов'!J$5 -> 8760 | L8: ='2. Произв-сть экскаваторов'!K$5 -> 8760 | ... N8: ='2. Произв-сть экскаваторов'!M$5 -> 8784 | P8: =P7 -> Komatsu PC2000-11R Mining Solutions
B9: КТГ | C9: % | E9: ='2. Произв-сть экскаваторов'!D18 -> 0.92406268 | F9: ='2. Произв-сть экскаваторов'!E18 -> 0.79773755 | G9: ='2. Произв-сть экскаваторов'!F18 -> 0.82453381 | H9: ='2. Произв-сть экскаваторов'!G18 -> 0.76394441 | I9: ='2. Произв-сть экскаваторов'!H18 -> 0.76281505 | J9: ='2. Произв-сть экскаваторов'!I18 -> 0.81214813 | K9: ='2. Произв-сть экскаваторов'!J18 -> 0.78656324 | L9: ='2. Произв-сть экскаваторов'!K18 -> 0.84263903 | ... N9: ='2. Произв-сть экскаваторов'!M18 -> 0.82670539 | P9: =P8 -> Komatsu PC2000-11R Mining Solutions
B10: КИО | C10: % | E10: ='2. Произв-сть экскаваторов'!D61 -> 0.58254452 | F10: ='2. Произв-сть экскаваторов'!E61 -> 0.50290705 | G10: ='2. Произв-сть экскаваторов'!F61 -> 0.51979986 | H10: ='2. Произв-сть экскаваторов'!G61 -> 0.48160329 | I10: ='2. Произв-сть экскаваторов'!H61 -> 0.48089132 | J10: ='2. Произв-сть экскаваторов'!I61 -> 0.51199171 | K10: ='2. Произв-сть экскаваторов'!J61 -> 0.49586257 | L10: ='2. Произв-сть экскаваторов'!K61 -> 0.53121369 | ... N10: ='2. Произв-сть экскаваторов'!M61 -> 0.52116886 | P10: =P9 -> Komatsu PC2000-11R Mining Solutions
B11: Производительность | C11: тыс.м3 | E11: ='2. Произв-сть экскаваторов'!D83 -> 2213.5159 | F11: ='2. Произв-сть экскаваторов'!E83 -> 1916.1498 | G11: ='2. Произв-сть экскаваторов'!F83 -> 1975.1027 | H11: ='2. Произв-сть экскаваторов'!G83 -> 1829.9658 | I11: ='2. Произв-сть экскаваторов'!H83 -> 1827.2605 | J11: ='2. Произв-сть экскаваторов'!I83 -> 1950.7638 | K11: ='2. Произв-сть экскаваторов'!J83 -> 1884.1473 | L11: ='2. Произв-сть экскаваторов'!K83 -> 2018.4722 | ... N11: ='2. Произв-сть экскаваторов'!M83 -> 1985.73 | P11: =P10 -> Komatsu PC2000-11R Mining Solutions
B12: Операционный денежный поток | C12: тыс. руб. | E12: =E88+E89-E84 -> 19274.311 | F12: =F88+F89-F84 -> 18894.341 | G12: =G88+G89-G84 -> 47530.209 | H12: =H88+H89-H84 -> 91739.297 | I12: =I88+I89-I84 -> 22119.593 | J12: =J88+J89-J84 -> 61283.154 | K12: =K88+K89-K84 -> 32602.326 | L12: =L88+L89-L84 -> 105132.38 | ... N12: =N88+N89-N84 -> 31212.191 | P12: =P11 -> Komatsu PC2000-11R Mining Solutions
B13: ТО, ТР, ППР, вкл смазочные | C13: тыс. руб. | E13: =E15 -> 5653.5622 | F13: =F15 -> 8598.4209 | G13: =G15 -> 45686.378 | H13: =H15 -> 105913.26 | I13: =I15 -> 14027.4 | J13: =J15 -> 48631.237 | K13: =K15 -> 8598.4209 | L13: =L15 -> 102968.4 | ... N13: =N15 -> 5653.5622 | P13: =P12 -> Komatsu PC2000-11R Mining Solutions
B14: ремонты и ТО | C14: тыс.долл./год | E14: =E155 -> 74.266046 | F14: =F155 -> 112.95016 | G14: =G155 -> 600.14316 | H14: =H155 -> 1391.2926 | I14: =I155 -> 184.26605 | J14: =J155 -> 638.82727 | K14: =K155 -> 112.95016 | L14: =L155 -> 1352.6085 | ... N14: =N155 -> 74.266046 | P14: =P13 -> Komatsu PC2000-11R Mining Solutions
C15: тыс.руб./год | E15: =E14*Макро!D$4 -> 5653.5622 | F15: =F14*Макро!E$4 -> 8598.4209 | G15: =G14*Макро!F$4 -> 45686.378 | H15: =H14*Макро!G$4 -> 105913.26 | I15: =I14*Макро!H$4 -> 14027.4 | J15: =J14*Макро!I$4 -> 48631.237 | K15: =K14*Макро!J$4 -> 8598.4209 | L15: =L14*Макро!K$4 -> 102968.4 | ... N15: =N14*Макро!M$4 -> 5653.5622 | P15: =P14 -> Komatsu PC2000-11R Mining Solutions
B16: затраты на сервис: ремонты и ТО | C16: тыс.руб. | E16: =E18 -> 2009.7211 | F16: =F18 -> 2142.9413 | G16: =G18 -> 2525.4734 | H16: =H18 -> 2993.6471 | I16: =I18 -> 2085.8469 | J16: =J18 -> 2658.6936 | K16: =K18 -> 2142.9413 | L16: =L18 -> 2860.4269 | ... N16: =N18 -> 2009.7211 | P16: =P15 -> Komatsu PC2000-11R Mining Solutions
B17: трудозатраты | C17: тыс.долл./год | E17: =E158 -> 26.4 | F17: =F158 -> 28.15 | G17: =G158 -> 33.175 | H17: =H158 -> 39.325 | I17: =I158 -> 27.4 | J17: =J158 -> 34.925 | K17: =K158 -> 28.15 | L17: =L158 -> 37.575 | ... N17: =N158 -> 26.4 | P17: =P16 -> Komatsu PC2000-11R Mining Solutions
C18: тыс.руб./год | E18: =E17*Макро!D$4 -> 2009.7211 | F18: =F17*Макро!E$4 -> 2142.9413 | G18: =G17*Макро!F$4 -> 2525.4734 | H18: =H17*Макро!G$4 -> 2993.6471 | I18: =I17*Макро!H$4 -> 2085.8469 | J18: =J17*Макро!I$4 -> 2658.6936 | K18: =K17*Макро!J$4 -> 2142.9413 | L18: =L17*Макро!K$4 -> 2860.4269 | ... N18: =N17*Макро!M$4 -> 2009.7211 | P18: =P17 -> Komatsu PC2000-11R Mining Solutions
B19: расходники на ковш | C19: тыс.руб. | E19: =E21+E25 -> 1931.5402 | F19: =F21+F25 -> 1672.0551 | G19: =G21+G25 -> 1723.498 | H19: =H21+H25 -> 1596.8498 | I19: =I21+I25 -> 1594.4892 | J19: =J21+J25 -> 1702.2596 | K19: =K21+K25 -> 1644.1293 | L19: =L21+L25 -> 1761.3428 | ... N19: =N21+N25 -> 1732.7715 | P19: =P18 -> Komatsu PC2000-11R Mining Solutions
P20: =P19 -> Komatsu PC2000-11R Mining Solutions
B21: расходники на ковш (зубья, коронки, фиксаторы…) | C21: тыс.руб. | E21: =E24*E11 -> 1931.5402 | F21: =F24*F11 -> 1672.0551 | G21: =G24*G11 -> 1723.498 | H21: =H24*H11 -> 1596.8498 | I21: =I24*I11 -> 1594.4892 | J21: =J24*J11 -> 1702.2596 | K21: =K24*K11 -> 1644.1293 | L21: =L24*L11 -> 1761.3428 | ... N21: =N24*N11 -> 1732.7715 | P21: =P20 -> Komatsu PC2000-11R Mining Solutions
B22: удельный расход | C22: шт/тыс.м3 | P22: =P21 -> Komatsu PC2000-11R Mining Solutions
B23: расход | C23: шт/год | P23: =P22 -> Komatsu PC2000-11R Mining Solutions
B24: цена за шт. | C24: руб./м3 | D24: ='Зубья ковша, коронки'!$P$57 -> 0.011462761 | E24: =$D24*Макро!D$4 -> 0.87261185 | F24: =$D24*Макро!E$4 -> 0.87261185 | G24: =$D24*Макро!F$4 -> 0.87261185 | H24: =$D24*Макро!G$4 -> 0.87261185 | I24: =$D24*Макро!H$4 -> 0.87261185 | J24: =$D24*Макро!I$4 -> 0.87261185 | K24: =$D24*Макро!J$4 -> 0.87261185 | L24: =$D24*Макро!K$4 -> 0.87261185 | ... N24: =$D24*Макро!M$4 -> 0.87261185 | P24: =P23 -> Komatsu PC2000-11R Mining Solutions
B25: другое | C25: тыс.руб. | E25: =E26*E27/1000 -> 0 | F25: =F26*F27/1000 -> 0 | G25: =G26*G27/1000 -> 0 | H25: =H26*H27/1000 -> 0 | I25: =I26*I27/1000 -> 0 | J25: =J26*J27/1000 -> 0 | K25: =K26*K27/1000 -> 0 | L25: =L26*L27/1000 -> 0 | ... N25: =N26*N27/1000 -> 0 | P25: =P24 -> Komatsu PC2000-11R Mining Solutions
B26: удельный расход | C26: комплект | P26: =P25 -> Komatsu PC2000-11R Mining Solutions
B27: цена за компл. | C27: руб.компл. | P27: =P26 -> Komatsu PC2000-11R Mining Solutions
C28: тыс.руб. | P28: =P27 -> Komatsu PC2000-11R Mining Solutions
B29: удельный расход | C29: мчас/комплект | P29: =P28 -> Komatsu PC2000-11R Mining Solutions
B30: расход | C30: компл./год | P30: =P29 -> Komatsu PC2000-11R Mining Solutions
B31: цена за компл. | C31: руб.компл. | P31: =P30 -> Komatsu PC2000-11R Mining Solutions
C32: тыс.руб. | P32: =P31 -> Komatsu PC2000-11R Mining Solutions
P33: =P32 -> Komatsu PC2000-11R Mining Solutions
B34: расход | C34: компл./год | P34: =P33 -> Komatsu PC2000-11R Mining Solutions
B35: цена за компл. | C35: руб.компл. | P35: =P34 -> Komatsu PC2000-11R Mining Solutions
P36: =P35 -> Komatsu PC2000-11R Mining Solutions
P37: =P36 -> Komatsu PC2000-11R Mining Solutions
P38: =P37 -> Komatsu PC2000-11R Mining Solutions
B39: Дизтопливо | C39: тыс.руб. | E39: =E41 -> 24752.087 | F39: =F41 -> 21426.866 | G39: =G41 -> 22086.091 | H39: =H41 -> 20463.134 | I39: =I41 -> 20432.883 | J39: =J41 -> 21813.927 | K39: =K41 -> 21069.005 | L39: =L41 -> 22571.06 | ... N39: =N41 -> 22204.929 | P39: =P38 -> Komatsu PC2000-11R Mining Solutions
P40: =P39 -> Komatsu PC2000-11R Mining Solutions
B41: расход (факт кг/час) | C41: тыс.руб. | E41: =E43*E44 -> 24752.087 | F41: =F43*F44 -> 21426.866 | G41: =G43*G44 -> 22086.091 | H41: =H43*H44 -> 20463.134 | I41: =I43*I44 -> 20432.883 | J41: =J43*J44 -> 21813.927 | K41: =K43*K44 -> 21069.005 | L41: =L43*L44 -> 22571.06 | ... N41: =N43*N44 -> 22204.929 | P41: =P40 -> Komatsu PC2000-11R Mining Solutions
...

Sheet PC2000-8 MS
B2: ячейки к заполнению поставщиком
B3: Экскаватор | C3: Komatsu PC2000-8 | D3: 16.07.2026: Доронин Ю.: PC2000-11 будет к поставке, не PC2000-8 | O3: Примечания
A4: 1 | B4: Период (год) | C4: Ед. изм. | D4: 0 | E4: =D4+1 -> 1 | F4: =E4+1 -> 2 | G4: =F4+1 -> 3 | H4: =G4+1 -> 4 | I4: =H4+1 -> 5 | J4: =I4+1 -> 6 | K4: =J4+1 -> 7 | L4: =K4+1 -> 8 | ... N4: =M4+1 -> 10
A5: =A4+1 -> 2 | B5: Геометрическая емкость ковша экскаватора | C5: м3 | D5: 8.5
A6: =A5+1 -> 3 | B6: Емкость ковша с шапкой | C6: м3 | D6: 12
B7: КТГ - в расчет | C7: коэф. | E7: =Факт.КТГ!D10 -> 0.92406268 | F7: =Факт.КТГ!E10 -> 0.79773755 | G7: =Факт.КТГ!F10 -> 0.82453381 | H7: =Факт.КТГ!G10 -> 0.76394441 | I7: =Факт.КТГ!H10 -> 0.76281505 | J7: =Факт.КТГ!I10 -> 0.81214813 | K7: =Факт.КТГ!J10 -> 0.78656324 | L7: =Факт.КТГ!K10 -> 0.84263903 | ... N7: =Факт.КТГ!M10 -> 0.82670539 | O7: факт по Группе
A9: =A6+1 -> 4 | B9: КТГ при нормативной эксплуатации | E9: =(8760-E10-E11-E12)/8760 -> 0.94081367 | F9: =(8760-F10-F11-F12)/8760 -> 0.90174721 | G9: =(8760-G10-G11-G12)/8760 -> 0.87999429 | H9: =(8760-H10-H11-H12)/8760 -> 0.90441083 | I9: =(8760-I10-I11-I12)/8760 -> 0.93726218 | J9: =(8760-J10-J11-J12)/8760 -> 0.85513382 | K9: =(8760-K10-K11-K12)/8760 -> 0.9279395 | L9: =(8760-L10-L11-L12)/8760 -> 0.853802 | ... N9: =(8760-N10-N11-N12)/8760 -> 0.91106989 | O9: Расчетный - от поставщика
A10: =A9+1 -> 5 | B10: простои на ТО | C10: час | E10: ='PC2000-8 MS_ТО'!G7 -> 259 | F10: ='PC2000-8 MS_ТО'!H7 -> 259 | G10: ='PC2000-8 MS_ТО'!I7 -> 259 | H10: ='PC2000-8 MS_ТО'!J7 -> 259 | I10: ='PC2000-8 MS_ТО'!K7 -> 259 | J10: ='PC2000-8 MS_ТО'!L7 -> 259 | K10: ='PC2000-8 MS_ТО'!M7 -> 259 | L10: ='PC2000-8 MS_ТО'!N7 -> 259 | ... N10: ='PC2000-8 MS_ТО'!P7 -> 259
A11: =A10+1 -> 6 | B11: простои в ремонтах | C11: час | E11: ='PC2000-8 MS_Ремонты'!F8 -> 24 | F11: ='PC2000-8 MS_Ремонты'!G8 -> 376 | G11: ='PC2000-8 MS_Ремонты'!H8 -> 572 | H11: ='PC2000-8 MS_Ремонты'!I8 -> 352 | I11: ='PC2000-8 MS_Ремонты'!J8 -> 56 | J11: ='PC2000-8 MS_Ремонты'!K8 -> 796 | K11: ='PC2000-8 MS_Ремонты'!L8 -> 140 | L11: ='PC2000-8 MS_Ремонты'!M8 -> 808 | ... N11: ='PC2000-8 MS_Ремонты'!O8 -> 292
A12: =A11+1 -> 7 | B12: ежесменный осмотр (20 минут в смену) | C12: час | E12: =(8760-E10-E11)/12*20/60 -> 235.47222 | F12: =(8760-F10-F11)/12*20/60 -> 225.69444 | G12: =(8760-G10-G11)/12*20/60 -> 220.25 | H12: =(8760-H10-H11)/12*20/60 -> 226.36111 | I12: =(8760-I10-I11)/12*20/60 -> 234.58333 | J12: =(8760-J10-J11)/12*20/60 -> 214.02778 | K12: =(8760-K10-K11)/12*20/60 -> 232.25 | L12: =(8760-L10-L11)/12*20/60 -> 213.69444 | ... N12: =(8760-N10-N11)/12*20/60 -> 228.02778
A13: =A12+1 -> 8 | B13: Время цикла | C13: сек | D13: 26-28 секунд | E13: =AVERAGE(26,28) -> 27
A14: =A13+1 -> 9 | B14: Мощность двигателя | C14: л.с. | D14: 1050
A15: =A14+1 -> 10 | B15: Затраты на ТО и ремонты | C15: тыс.дол./год | E15: =SUM(E16:E20) -> 142.08144 | F15: =SUM(F16:F20) -> 1515.237 | G15: =SUM(G16:G20) -> 1617.9303 | H15: =SUM(H16:H20) -> 1513.4951 | I15: =SUM(I16:I20) -> 150.17068 | J15: =SUM(J16:J20) -> 2932.4804 | K15: =SUM(K16:K20) -> 199.81592 | L15: =SUM(L16:L20) -> 2933.3514 | ... N15: =SUM(N16:N20) -> 1465.5918
A16: =A15+1 -> 11 | B16: ТО, включая смазочные | C16: тыс.дол./год | E16: ='PC2000-8 MS_ТО'!G9/1000 -> 102.74293 | F16: ='PC2000-8 MS_ТО'!H9/1000 -> 102.74293 | G16: ='PC2000-8 MS_ТО'!I9/1000 -> 102.74293 | H16: ='PC2000-8 MS_ТО'!J9/1000 -> 102.74293 | I16: ='PC2000-8 MS_ТО'!K9/1000 -> 102.74293 | J16: ='PC2000-8 MS_ТО'!L9/1000 -> 102.74293 | K16: ='PC2000-8 MS_ТО'!M9/1000 -> 102.74293 | L16: ='PC2000-8 MS_ТО'!N9/1000 -> 102.74293 | ... N16: ='PC2000-8 MS_ТО'!P9/1000 -> 102.74293
A17: =A16+1 -> 12 | B17: текущие ремонты | C17: тыс.дол./год | E17: ='PC2000-8 MS_Ремонты'!F10/1000 -> 1.7419268 | F17: ='PC2000-8 MS_Ремонты'!G10/1000 -> 4.3548171 | G17: ='PC2000-8 MS_Ремонты'!H10/1000 -> 3.4838537 | H17: ='PC2000-8 MS_Ремонты'!I10/1000 -> 2.6128903 | I17: ='PC2000-8 MS_Ремонты'!J10/1000 -> 3.4838537 | J17: ='PC2000-8 MS_Ремонты'!K10/1000 -> 2.6128903 | K17: ='PC2000-8 MS_Ремонты'!L10/1000 -> 4.3548171 | L17: ='PC2000-8 MS_Ремонты'!M10/1000 -> 3.4838537 | ... N17: ='PC2000-8 MS_Ремонты'!O10/1000 -> 3.4838537
A18: =A17+1 -> 13 | B18: планово-предупредительные (капитальные) ремонты | C18: тыс.дол./год | E18: ='PC2000-8 MS_Ремонты'!F11/1000 -> 0 | F18: ='PC2000-8 MS_Ремонты'!G11/1000 -> 1347.6073 | G18: ='PC2000-8 MS_Ремонты'!H11/1000 -> 1436.0748 | H18: ='PC2000-8 MS_Ремонты'!I11/1000 -> 1347.6073 | I18: ='PC2000-8 MS_Ремонты'!J11/1000 -> 5.7666667 | J18: ='PC2000-8 MS_Ремонты'!K11/1000 -> 2734.367 | K18: ='PC2000-8 MS_Ремонты'!L11/1000 -> 49.315167 | L18: ='PC2000-8 MS_Ремонты'!M11/1000 -> 2734.367 | ... N18: ='PC2000-8 MS_Ремонты'!O11/1000 -> 1304.0588
A19: =A18+1 -> 14 | B19: сервис (трудозатраты) - ТО | C19: тыс.дол./год | E19: ='PC2000-8 MS_ТО'!G10/1000 -> 37.596588 | F19: ='PC2000-8 MS_ТО'!H10/1000 -> 37.596588 | G19: ='PC2000-8 MS_ТО'!I10/1000 -> 37.596588 | H19: ='PC2000-8 MS_ТО'!J10/1000 -> 37.596588 | I19: ='PC2000-8 MS_ТО'!K10/1000 -> 37.596588 | J19: ='PC2000-8 MS_ТО'!L10/1000 -> 37.596588 | K19: ='PC2000-8 MS_ТО'!M10/1000 -> 37.596588 | L19: ='PC2000-8 MS_ТО'!N10/1000 -> 37.596588 | ... N19: ='PC2000-8 MS_ТО'!P10/1000 -> 37.596588
A20: =A19+1 -> 15 | B20: сервис (трудозатраты) - ремонты | C20: тыс.дол./год | E20: ='PC2000-8 MS_Ремонты'!F12/1000 -> 0 | F20: ='PC2000-8 MS_Ремонты'!G12/1000 -> 22.93537 | G20: ='PC2000-8 MS_Ремонты'!H12/1000 -> 38.032069 | H20: ='PC2000-8 MS_Ремонты'!I12/1000 -> 22.93537 | I20: ='PC2000-8 MS_Ремонты'!J12/1000 -> 0.58064228 | J20: ='PC2000-8 MS_Ремонты'!K12/1000 -> 55.161017 | K20: ='PC2000-8 MS_Ремонты'!L12/1000 -> 5.8064228 | L20: ='PC2000-8 MS_Ремонты'!M12/1000 -> 55.161017 | ... N20: ='PC2000-8 MS_Ремонты'!O12/1000 -> 17.70959
A21: =A20+1 -> 16 | B21: Расходные материалы:
A22: =A21+1 -> 17 | B22: зубья ковша | C22: 5 шт. | O22: кол-во штук на ковше
A23: =A22+1 -> 18 | B23: удельный расход на 7000 м.ч | C23: 110 | E23: 110 | F23: 110 | G23: 110 | H23: 110 | I23: 110 | J23: 110 | K23: 110 | L23: 110 | M23: 110 | N23: 110
A24: =A23+1 -> 19 | B24: цена за ед. | C24: 444 | E24: =E23*C24 -> 48840 | F24: =F23*C24 -> 48840 | G24: =G23*C24 -> 48840 | H24: =H23*C24 -> 48840 | I24: =I23*C24 -> 48840 | J24: =J23*C24 -> 48840 | K24: =K23*C24 -> 48840 | L24: =L23*C24 -> 48840 | M24: =M23*C24 -> 48840 | N24: =N23*C24 -> 48840
A25: =A24+1 -> 20 | B25: Палец коронки | C25: 5 шт. | O25: кол-во штук на ковше
A26: =A25+1 -> 21 | B26: удельный расход на 7000 м.ч | C26: 110 | E26: 110 | F26: 110 | G26: 110 | H26: 110 | I26: 110 | J26: 110 | K26: 110 | L26: 110 | M26: 110 | N26: 110
A27: =A26+1 -> 22 | B27: цена за ед. | C27: 48 | E27: =E26*C27 -> 5280 | F27: =F26*C27 -> 5280 | G27: =G26*C27 -> 5280 | H27: =H26*C27 -> 5280 | I27: =I26*C27 -> 5280 | J27: =J26*C27 -> 5280 | K27: =K26*C27 -> 5280 | L27: =L26*C27 -> 5280 | M27: =M26*C27 -> 5280 | N27: =N26*C27 -> 5280
A28: =A27+1 -> 23 | B28: Крышка износа центральная | C28: 3 шт. | O28: кол-во штук на ковше
A29: =A28+1 -> 24 | B29: удельный расход на 7000 м.ч | C29: 21 | E29: 21 | F29: 21 | G29: 21 | H29: 21 | I29: 21 | J29: 21 | K29: 21 | L29: 21 | M29: 21 | N29: 21
A30: =A29+1 -> 25 | B30: цена за ед. | C30: 224 | E30: =E29*C30 -> 4704 | F30: =F29*C30 -> 4704 | G30: =G29*C30 -> 4704 | H30: =H29*C30 -> 4704 | I30: =I29*C30 -> 4704 | J30: =J29*C30 -> 4704 | K30: =K29*C30 -> 4704 | L30: =L29*C30 -> 4704 | M30: =M29*C30 -> 4704 | N30: =N29*C30 -> 4704
A31: =A30+1 -> 26 | B31: Крышка износа угловая | C31: 2 шт. | O31: кол-во штук на ковше
A32: =A31+1 -> 27 | B32: удельный расход на 7000 м.ч | C32: 14 | E32: 14 | F32: 14 | G32: 14 | H32: 14 | I32: 14 | J32: 14 | K32: 14 | L32: 14 | M32: 14 | N32: 14
A33: =A32+1 -> 28 | B33: цена за ед. | C33: 560 | E33: =E32*C33 -> 7840 | F33: =F32*C33 -> 7840 | G33: =G32*C33 -> 7840 | H33: =H32*C33 -> 7840 | I33: =I32*C33 -> 7840 | J33: =J32*C33 -> 7840 | K33: =K32*C33 -> 7840 | L33: =L32*C33 -> 7840 | M33: =M32*C33 -> 7840 | N33: =N32*C33 -> 7840
A34: =A33+1 -> 29 | B34: Мезубка. | C34: 4 шт. | O34: кол-во штук на ковше
A35: =A34+1 -> 30 | B35: удельный расход на 7000 м.ч | C35: 28 | E35: 28 | F35: 28 | G35: 28 | H35: 28 | I35: 28 | J35: 28 | K35: 28 | L35: 28 | M35: 28 | N35: 28
A36: =A35+1 -> 31 | B36: цена за ед. | C36: 1634 | E36: =E35*C36 -> 45752 | F36: =F35*C36 -> 45752 | G36: =G35*C36 -> 45752 | H36: =H35*C36 -> 45752 | I36: =I35*C36 -> 45752 | J36: =J35*C36 -> 45752 | K36: =K35*C36 -> 45752 | L36: =L35*C36 -> 45752 | M36: =M35*C36 -> 45752 | N36: =N35*C36 -> 45752
A37: =A36+1 -> 32 | B37: J болт | C37: 4 шт. | O37: кол-во штук на ковше
A38: =A37+1 -> 33 | B38: удельный расход на 7000 м.ч | C38: 28 | E38: 28 | F38: 28 | G38: 28 | H38: 28 | I38: 28 | J38: 28 | K38: 28 | L38: 28 | M38: 28 | N38: 28
A39: =A38+1 -> 34 | B39: цена за ед. | C39: 326 | E39: =E38*C39 -> 9128 | F39: =F38*C39 -> 9128 | G39: =G38*C39 -> 9128 | H39: =H38*C39 -> 9128 | I39: =I38*C39 -> 9128 | J39: =J38*C39 -> 9128 | K39: =K38*C39 -> 9128 | L39: =L38*C39 -> 9128 | M39: =M38*C39 -> 9128 | N39: =N38*C39 -> 9128
A40: =A39+1 -> 35 | B40: угловая защита | C40: 12 шт. | O40: кол-во штук на ковше
A41: =A40+1 -> 36 | B41: удельный расход на 7000 м.ч | C41: 48 | E41: 48 | F41: 48 | G41: 48 | H41: 48 | I41: 48 | J41: 48 | K41: 48 | L41: 48 | M41: 48 | N41: 48
A42: =A41+1 -> 37 | B42: цена за ед. | C42: 294 | E42: =E41*C42 -> 14112 | F42: =F41*C42 -> 14112 | G42: =G41*C42 -> 14112 | H42: =H41*C42 -> 14112 | I42: =I41*C42 -> 14112 | J42: =J41*C42 -> 14112 | K42: =K41*C42 -> 14112 | L42: =L41*C42 -> 14112 | M42: =M41*C42 -> 14112 | N42: =N41*C42 -> 14112
...

Sheet PC2000-8 MS_ТО
B2: ячейки к заполнению поставщиком
B3: Расчетный КТГ | G3: ='PC2000-8 MS'!E9 -> 0.94081367 | H3: ='PC2000-8 MS'!F9 -> 0.90174721 | I3: ='PC2000-8 MS'!G9 -> 0.87999429 | J3: ='PC2000-8 MS'!H9 -> 0.90441083 | K3: ='PC2000-8 MS'!I9 -> 0.93726218 | L3: ='PC2000-8 MS'!J9 -> 0.85513382 | M3: ='PC2000-8 MS'!K9 -> 0.9279395 | N3: ='PC2000-8 MS'!L9 -> 0.853802 | ... P3: ='PC2000-8 MS'!N9 -> 0.91106989
B4: Год службы (год) | C4: Ед. изм. | G4: =E4+1 -> 1 | H4: =G4+1 -> 2 | I4: =H4+1 -> 3 | J4: =I4+1 -> 4 | K4: =J4+1 -> 5 | L4: =K4+1 -> 6 | M4: =L4+1 -> 7 | N4: =M4+1 -> 8 | O4: =N4+1 -> 9 | P4: =O4+1 -> 10
B5: Наработка на начало года | C5: м/час | G5: 0 | H5: =G6+1 -> 7001 | I5: =H6+1 -> 14001 | J5: =I6+1 -> 21001 | K5: =J6+1 -> 28001 | L5: =K6+1 -> 35001 | M5: =L6+1 -> 42001 | N5: =M6+1 -> 49001 | O5: =N6+1 -> 56001 | P5: =O6+1 -> 63001
B6: Наработка на конец года | C6: м/час | F6: 7000 | G6: =F6 -> 7000 | H6: =G6+$F6 -> 14000 | I6: =H6+$F6 -> 21000 | J6: =I6+$F6 -> 28000 | K6: =J6+$F6 -> 35000 | L6: =K6+$F6 -> 42000 | M6: =L6+$F6 -> 49000 | N6: =M6+$F6 -> 56000 | O6: =N6+$F6 -> 63000 | P6: =O6+$F6 -> 70000
B7: длительность простоев на ТО | C7: часов | G7: =G13 -> 259 | H7: =H13 -> 259 | I7: =I13 -> 259 | J7: =J13 -> 259 | K7: =K13 -> 259 | L7: =L13 -> 259 | M7: =M13 -> 259 | N7: =N13 -> 259 | ... P7: =P13 -> 259
B8: Затраты на ТО | C8: долларов/год | G8: =SUM(G9:G10) -> 140339.51 | H8: =SUM(H9:H10) -> 140339.51 | I8: =SUM(I9:I10) -> 140339.51 | J8: =SUM(J9:J10) -> 140339.51 | K8: =SUM(K9:K10) -> 140339.51 | L8: =SUM(L9:L10) -> 140339.51 | M8: =SUM(M9:M10) -> 140339.51 | N8: =SUM(N9:N10) -> 140339.51 | ... P8: =SUM(P9:P10) -> 140339.51
B9: ТО, включая масла и смазки | C9: долларов/год | G9: =G21 -> 102742.93 | H9: =H21 -> 102742.93 | I9: =I21 -> 102742.93 | J9: =J21 -> 102742.93 | K9: =K21 -> 102742.93 | L9: =L21 -> 102742.93 | M9: =M21 -> 102742.93 | N9: =N21 -> 102742.93 | ... P9: =P21 -> 102742.93
B10: сервис (трудозатраты) на ТО | C10: долларов/год | F10: 72.580285 | G10: =SUMPRODUCT(G14:G18,$F$14:$F$18)*$F10 -> 37596.588 | H10: =SUMPRODUCT(H14:H18,$F$14:$F$18)*$F10 -> 37596.588 | I10: =SUMPRODUCT(I14:I18,$F$14:$F$18)*$F10 -> 37596.588 | J10: =SUMPRODUCT(J14:J18,$F$14:$F$18)*$F10 -> 37596.588 | K10: =SUMPRODUCT(K14:K18,$F$14:$F$18)*$F10 -> 37596.588 | L10: =SUMPRODUCT(L14:L18,$F$14:$F$18)*$F10 -> 37596.588 | M10: =SUMPRODUCT(M14:M18,$F$14:$F$18)*$F10 -> 37596.588 | N10: =SUMPRODUCT(N14:N18,$F$14:$F$18)*$F10 -> 37596.588 | ... P10: =SUMPRODUCT(P14:P18,$F$14:$F$18)*$F10 -> 37596.588
B12: Простои оборудования на ТО | C12: Интервал ТО | D12: Длительность простоя на одном ТО, час | E12: Кол-во ТО в год | F12: Занято человек | G12: Простоев в год, час | H12: Простоев в год, час | I12: Простоев в год, час | J12: Простоев в год, час | K12: Простоев в год, час | L12: Простоев в год, час | M12: Простоев в год, час | N12: Простоев в год, час | O12: Простоев в год, час | P12: Простоев в год, час | R12: цена руб без ндс месяц за 1 человека | T12: часов в смене | U12: колличество дней | V12: цена за 1 час руб. без ндс | W12: курс USD | X12: 74.63
B13: всего простоев на ТО, часов | G13: =SUM(G14:G18) -> 259 | H13: =SUM(H14:H18) -> 259 | I13: =SUM(I14:I18) -> 259 | J13: =SUM(J14:J18) -> 259 | K13: =SUM(K14:K18) -> 259 | L13: =SUM(L14:L18) -> 259 | M13: =SUM(M14:M18) -> 259 | N13: =SUM(N14:N18) -> 259 | ... P13: =SUM(P14:P18) -> 259 | R13: 1300000 | T13: 8 | U13: 30 | V13: =R13/(T13*U13) -> 5416.6667 | X13: =V13/X12 -> 72.580285
B14: ТО-1 | C14: 500 | D14: 10.2 | E14: =$F$6/C14 -> 14 | F14: 2 | G14: =$E14*$D14 -> 142.8 | H14: =$E14*$D14 -> 142.8 | I14: =$E14*$D14 -> 142.8 | J14: =$E14*$D14 -> 142.8 | K14: =$E14*$D14 -> 142.8 | L14: =$E14*$D14 -> 142.8 | M14: =$E14*$D14 -> 142.8 | N14: =$E14*$D14 -> 142.8 | ... P14: =$E14*$D14 -> 142.8
B15: ТО-2 | C15: 1000 | D15: 9.4 | E15: =$F$6/C15 -> 7 | F15: 2 | G15: =$E15*$D15 -> 65.8 | H15: =$E15*$D15 -> 65.8 | I15: =$E15*$D15 -> 65.8 | J15: =$E15*$D15 -> 65.8 | K15: =$E15*$D15 -> 65.8 | L15: =$E15*$D15 -> 65.8 | M15: =$E15*$D15 -> 65.8 | N15: =$E15*$D15 -> 65.8 | ... P15: =$E15*$D15 -> 65.8
B16: ТО-3 | C16: 2000 | D16: 12.4 | E16: 3 | F16: 2 | G16: =$E16*$D16 -> 37.2 | H16: =$E16*$D16 -> 37.2 | I16: =$E16*$D16 -> 37.2 | J16: =$E16*$D16 -> 37.2 | K16: =$E16*$D16 -> 37.2 | L16: =$E16*$D16 -> 37.2 | M16: =$E16*$D16 -> 37.2 | N16: =$E16*$D16 -> 37.2 | ... P16: =$E16*$D16 -> 37.2
B17: ТО-4 | C17: 4000 | D17: 7.8 | E17: 1 | F17: 2 | G17: =$E17*$D17 -> 7.8 | H17: =$E17*$D17 -> 7.8 | I17: =$E17*$D17 -> 7.8 | J17: =$E17*$D17 -> 7.8 | K17: =$E17*$D17 -> 7.8 | L17: =$E17*$D17 -> 7.8 | M17: =$E17*$D17 -> 7.8 | N17: =$E17*$D17 -> 7.8 | ... P17: =$E17*$D17 -> 7.8
B18: ТО-5 | C18: 5000 | D18: 5.4 | E18: 1 | F18: 2 | G18: =$E18*$D18 -> 5.4 | H18: =$E18*$D18 -> 5.4 | I18: =$E18*$D18 -> 5.4 | J18: =$E18*$D18 -> 5.4 | K18: =$E18*$D18 -> 5.4 | L18: =$E18*$D18 -> 5.4 | M18: =$E18*$D18 -> 5.4 | N18: =$E18*$D18 -> 5.4 | ... P18: =$E18*$D18 -> 5.4
B20: Затраты на ТО | C20: Каталожный номер | D20: стоимость за ед., $ | E20: Кол-во | F20: Кол-во ТО в год | G20: $ | H20: $ | I20: $ | J20: $ | K20: $ | L20: $ | M20: $ | N20: $ | O20: $ | P20: $
B21: ТО | G21: =SUM(G22:G53) -> 102742.93 | H21: =SUM(H22:H53) -> 102742.93 | I21: =SUM(I22:I53) -> 102742.93 | J21: =SUM(J22:J53) -> 102742.93 | K21: =SUM(K22:K53) -> 102742.93 | L21: =SUM(L22:L53) -> 102742.93 | M21: =SUM(M22:M53) -> 102742.93 | N21: =SUM(N22:N53) -> 102742.93 | ... P21: =SUM(P22:P53) -> 102742.93
B22: ТО-1 | E22: =VLOOKUP($B22,$B$14:$C$18,2,FALSE) -> 500 | F22: =VLOOKUP($B22,$B$14:$E$18,4,FALSE) -> 14
B23: Маслянный фильтр | C23: 600-211-1341 | D23: 114.83333 | E23: 4 | G23: =IF(G$14=0,0,G$14/$D$14*$E23*$D23) -> 6430.6667 | H23: =IF(H$14=0,0,H$14/$D$14*$E23*$D23) -> 6430.6667 | I23: =IF(I$14=0,0,I$14/$D$14*$E23*$D23) -> 6430.6667 | J23: =IF(J$14=0,0,J$14/$D$14*$E23*$D23) -> 6430.6667 | K23: =IF(K$14=0,0,K$14/$D$14*$E23*$D23) -> 6430.6667 | L23: =IF(L$14=0,0,L$14/$D$14*$E23*$D23) -> 6430.6667 | M23: =IF(M$14=0,0,M$14/$D$14*$E23*$D23) -> 6430.6667 | N23: =IF(N$14=0,0,N$14/$D$14*$E23*$D23) -> 6430.6667 | ... P23: =IF(P$14=0,0,P$14/$D$14*$E23*$D23) -> 6430.6667
B24: Топливный фильтр | C24: 600-319-4540 | D24: 141.33333 | E24: 2 | G24: =IF(G$14=0,0,G$14/$D$14*$E24*$D24) -> 3957.3333 | H24: =IF(H$14=0,0,H$14/$D$14*$E24*$D24) -> 3957.3333 | I24: =IF(I$14=0,0,I$14/$D$14*$E24*$D24) -> 3957.3333 | J24: =IF(J$14=0,0,J$14/$D$14*$E24*$D24) -> 3957.3333 | K24: =IF(K$14=0,0,K$14/$D$14*$E24*$D24) -> 3957.3333 | L24: =IF(L$14=0,0,L$14/$D$14*$E24*$D24) -> 3957.3333 | M24: =IF(M$14=0,0,M$14/$D$14*$E24*$D24) -> 3957.3333 | N24: =IF(N$14=0,0,N$14/$D$14*$E24*$D24) -> 3957.3333 | ... P24: =IF(P$14=0,0,P$14/$D$14*$E24*$D24) -> 3957.3333
