Workbook

Sheet Данные_Буровой станок
B2: ячейки к заполнению поставщиком
B3: Буровой станок | C3: Epiroc DM75 | Q3: Данные по Epiroc DM75
A4: 1 | B4: Период | C4: Ед. изм. | D4: 0 | E4: =D4+1 -> 1 | F4: =E4+1 -> 2 | G4: =F4+1 -> 3 | H4: =G4+1 -> 4 | I4: =H4+1 -> 5 | J4: =I4+1 -> 6 | K4: =J4+1 -> 7 | L4: =K4+1 -> 8 | ... P4: =O4+1 -> 12 | Q4: Срок эксплуатации 12 лет
A5: =A4+1 -> 2 | B5: Диаметр долота | C5: мм | D5: 250 | Q5: Источник: Epiroc DM75 Brochure (открытые данные Epiroc)
A6: =A5+1 -> 3 | B6: КТГ при нормативной эксплуатации | C6: коэф. | E6: =(8760-E7-E8-E9)/8760 -> 0.93093607 | F6: =(8760-F7-F8-F9)/8760 -> 0.91717402 | G6: =(8760-G7-G8-G9)/8760 -> 0.93093607 | H6: =(8760-H7-H8-H9)/8760 -> 0.91717402 | I6: =(8760-I7-I8-I9)/8760 -> 0.88654236 | J6: =(8760-J7-J8-J9)/8760 -> 0.91717402 | K6: =(8760-K7-K8-K9)/8760 -> 0.85058346 | L6: =(8760-L7-L8-L9)/8760 -> 0.91983765 | ... P6: =(8760-P7-P8-P9)/8760 -> 0.91717402 | Q6: расчетный
A7: =A6+1 -> 4 | B7: простои на ТО | C7: часов | E7: =ТО!G7 -> 172 | F7: =ТО!H7 -> 196 | G7: =ТО!I7 -> 172 | H7: =ТО!J7 -> 196 | I7: =ТО!K7 -> 172 | J7: =ТО!L7 -> 196 | K7: =ТО!M7 -> 196 | L7: =ТО!N7 -> 172 | ... P7: =ТО!R7 -> 196
A8: =A7+1 -> 5 | B8: простои в ремонтах | C8: часов | E8: =Ремонты!F8 -> 200 | F8: =Ремонты!G8 -> 300 | G8: =Ремонты!H8 -> 200 | H8: =Ремонты!I8 -> 300 | I8: =Ремонты!J8 -> 600 | J8: =Ремонты!K8 -> 300 | K8: =Ремонты!L8 -> 900 | L8: =Ремонты!M8 -> 300 | ... P8: =Ремонты!Q8 -> 300
B9: ежесменный осмотр (20 мин/смену) | C9: часов | E9: =(8760-E7-E8)/12*20/60 -> 233 | F9: =(8760-F7-F8)/12*20/60 -> 229.55556 | G9: =(8760-G7-G8)/12*20/60 -> 233 | H9: =(8760-H7-H8)/12*20/60 -> 229.55556 | I9: =(8760-I7-I8)/12*20/60 -> 221.88889 | J9: =(8760-J7-J8)/12*20/60 -> 229.55556 | K9: =(8760-K7-K8)/12*20/60 -> 212.88889 | L9: =(8760-L7-L8)/12*20/60 -> 230.22222 | ... P9: =(8760-P7-P8)/12*20/60 -> 229.55556
A10: =A8+1 -> 6 | B10: Модель ДВС | D10: Cummins QSK19 | Q10: Источник: Epiroc DM75 Brochure
A11: =A10+1 -> 7 | B11: Мощность двигателя | C11: кВт | D11: 563 | Q11: Источник: Epiroc DM75 Brochure
A12: =A11+1 -> 8 | B12: Длина штанги | C12: м | D12: 10.7 | Q12: Источник: Epiroc DM75 Brochure
A13: =A12+1 -> 9 | B13: Глубина бурения в первый заход | C13: м | D13: 9.3 | Q13: Источник: Epiroc DM75 Brochure
A14: =A13+1 -> 10 | B14: Скорость подъема бур.снаряда, м/мин | C14: м/мин | D14: 51.5 | Q14: Источник: Epiroc DM75 Brochure
B15: Скорость спуска бур.снаряда, м/мин | C15: м/мин | D15: 26.9 | Q15: Источник: Epiroc DM75 Brochure
B16: Для вращательного бурения
A17: =A14+1 -> 11 | B17: Мощность привода вращателя, кВт | C17: кВт / л.с. | D17: 350/476
A18: =A17+1 -> 12 | B18: Крутящий момент вращателя | C18: Нм | D18: 14600 | Q18: Источник: Epiroc DM75 Brochure
A19: =A18+1 -> 13 | B19: Частота вращения | C19: об/мин | D19: 200 | Q19: Источник: Epiroc DM75 Brochure
B20: Для пневмоударного бурения
A21: =A19+1 -> 14 | B21: Производительность компрессора | C21: м3/мин | D21: 53.8 | Q21: Источник: Epiroc DM75 Brochure
A22: =A21+1 -> 15 | B22: Давление компрессора | C22: бар | D22: 7.6 | Q22: Источник: Epiroc DM75 Brochure
A23: =A22+1 -> 16 | B23: Рекомендуемый буровой инструмент
A24: =A23+1 -> 17 | B24: Паспортное потребление воздуха / давление | C24: м3/мин | D24: н/п | Q24: Неприменимо
A25: =A24+1 -> 18 | B25: Число ударов пневмоударника | C25: уд/мин | D25: н/п | Q25: Неприменимо
A26: =A25+1 -> 19 | B26: Энергия единичного удара | C26: Дж | D26: н/п | Q26: Неприменимо
A28: =A26+1 -> 20 | B28: Затраты на ТО и ремонты | C28: тыс./год | E28: =SUM(E29:E33) -> 180.86 | F28: =SUM(F29:F33) -> 331.14 | G28: =SUM(G29:G33) -> 421.46 | H28: =SUM(H29:H33) -> 356.14 | I28: =SUM(I29:I33) -> 292.36 | J28: =SUM(J29:J33) -> 462.64 | K28: =SUM(K29:K33) -> 337.64 | L28: =SUM(L29:L33) -> 408.96 | ... P28: =SUM(P29:P33) -> 388.14
A29: =A28+1 -> 21 | B29: ТО | E29: =ТО!G9/1000 -> 70.12 | F29: =ТО!H9/1000 -> 70.12 | G29: =ТО!I9/1000 -> 70.12 | H29: =ТО!J9/1000 -> 70.12 | I29: =ТО!K9/1000 -> 70.12 | J29: =ТО!L9/1000 -> 70.12 | K29: =ТО!M9/1000 -> 70.12 | L29: =ТО!N9/1000 -> 70.12 | ... P29: =ТО!R9/1000 -> 70.12
A30: =A29+1 -> 22 | B30: текущие ремонты | E30: =Ремонты!F33/1000 -> 8.5 | F30: =Ремонты!G33/1000 -> 8.5 | G30: =Ремонты!H33/1000 -> 8.5 | H30: =Ремонты!I33/1000 -> 8.5 | I30: =Ремонты!J33/1000 -> 8.5 | J30: =Ремонты!K33/1000 -> 8.5 | K30: =Ремонты!L33/1000 -> 8.5 | L30: =Ремонты!M33/1000 -> 8.5 | ... P30: =Ремонты!Q33/1000 -> 8.5
A31: =A30+1 -> 23 | B31: планово-предупредительные (капитальные) ремонты | E31: =Ремонты!F39/1000 -> 76.2 | F31: =Ремонты!G39/1000 -> 217.8 | G31: =Ремонты!H39/1000 -> 316.8 | H31: =Ремонты!I39/1000 -> 242.8 | I31: =Ремонты!J39/1000 -> 145.7 | J31: =Ремонты!K39/1000 -> 349.3 | K31: =Ремонты!L39/1000 -> 182.3 | L31: =Ремонты!M39/1000 -> 297.3 | ... P31: =Ремонты!Q39/1000 -> 274.8
A32: =A31+1 -> 24 | B32: сервис (трудозатраты) - ТО | E32: =ТО!G10/1000 -> 12.04 | F32: =ТО!H10/1000 -> 13.72 | G32: =ТО!I10/1000 -> 12.04 | H32: =ТО!J10/1000 -> 13.72 | I32: =ТО!K10/1000 -> 12.04 | J32: =ТО!L10/1000 -> 13.72 | K32: =ТО!M10/1000 -> 13.72 | L32: =ТО!N10/1000 -> 12.04 | ... P32: =ТО!R10/1000 -> 13.72
A33: =A32+1 -> 25 | B33: сервис (трудозатраты) - ремонты | E33: =Ремонты!F12/1000 -> 14 | F33: =Ремонты!G12/1000 -> 21 | G33: =Ремонты!H12/1000 -> 14 | H33: =Ремонты!I12/1000 -> 21 | I33: =Ремонты!J12/1000 -> 56 | J33: =Ремонты!K12/1000 -> 21 | K33: =Ремонты!L12/1000 -> 63 | L33: =Ремонты!M12/1000 -> 21 | ... P33: =Ремонты!Q12/1000 -> 21
A35: =A33+1 -> 26 | B35: Рекомендуемый буровой инструмент
A36: =A35+1 -> 27 | B36: Для вращательного бурения
A37: =A36+1 -> 28 | B37: долота, USD
A38: =A37+1 -> 29 | B38: удельный расход | C38: =C39/1500 -> 1.0666667
A39: =A38+1 -> 30 | B39: цена за ед. | C39: 1600
A40: =A39+1 -> 31 | B40: Штанги буровые, USD
A41: =A40+1 -> 32 | B41: удельный расход | C41: =C42/4000 -> 1
A42: =A41+1 -> 33 | B42: цена за ед. | C42: 4000
A43: =A42+1 -> 34 | B43: Адаптер долота, USD
...

Sheet ТО
B2: ячейки к заполнению поставщиком
B4: Год службы (год) | C4: Ед. изм. | G4: =E4+1 -> 1 | H4: =G4+1 -> 2 | I4: =H4+1 -> 3 | J4: =I4+1 -> 4 | K4: =J4+1 -> 5 | L4: =K4+1 -> 6 | M4: =L4+1 -> 7 | N4: =M4+1 -> 8 | O4: =N4+1 -> 9 | ... R4: =Q4+1 -> 12
B5: Наработка на начало года | C5: м/час | G5: 0 | H5: =G6+1 -> 7001 | I5: =H6+1 -> 14001 | J5: =I6+1 -> 21001 | K5: =J6+1 -> 28001 | L5: =K6+1 -> 35001 | M5: =L6+1 -> 42001 | N5: =M6+1 -> 49001 | O5: =N6+1 -> 56001 | ... R5: =Q6+1 -> 77001
B6: Наработка на конец года | C6: м/час | F6: 7000 | G6: =F6 -> 7000 | H6: =G6+$F6 -> 14000 | I6: =H6+$F6 -> 21000 | J6: =I6+$F6 -> 28000 | K6: =J6+$F6 -> 35000 | L6: =K6+$F6 -> 42000 | M6: =L6+$F6 -> 49000 | N6: =M6+$F6 -> 56000 | O6: =N6+$F6 -> 63000 | ... R6: =Q6+$F6 -> 84000
B7: длительность простоев на ТО | C7: часов | G7: =G13 -> 172 | H7: =H13 -> 196 | I7: =I13 -> 172 | J7: =J13 -> 196 | K7: =K13 -> 172 | L7: =L13 -> 196 | M7: =M13 -> 196 | N7: =N13 -> 172 | ... R7: =R13 -> 196
B8: Затраты на ТО | C8: долларов/год | G8: =SUM(G9:G10) -> 82160 | H8: =SUM(H9:H10) -> 83840 | I8: =SUM(I9:I10) -> 82160 | J8: =SUM(J9:J10) -> 83840 | K8: =SUM(K9:K10) -> 82160 | L8: =SUM(L9:L10) -> 83840 | M8: =SUM(M9:M10) -> 83840 | N8: =SUM(N9:N10) -> 82160 | ... R8: =SUM(R9:R10) -> 83840
B9: ТО, включая масла и смазки | C9: долларов/год | G9: =G22 -> 70120 | H9: =H22 -> 70120 | I9: =I22 -> 70120 | J9: =J22 -> 70120 | K9: =K22 -> 70120 | L9: =L22 -> 70120 | M9: =M22 -> 70120 | N9: =N22 -> 70120 | ... R9: =R22 -> 70120
B10: сервис (трудозатраты) на ТО | C10: долларов/год | F10: 35 | G10: =SUMPRODUCT(G14:G19,$F$14:$F$19)*$F10 -> 12040 | H10: =SUMPRODUCT(H14:H19,$F$14:$F$19)*$F10 -> 13720 | I10: =SUMPRODUCT(I14:I19,$F$14:$F$19)*$F10 -> 12040 | J10: =SUMPRODUCT(J14:J19,$F$14:$F$19)*$F10 -> 13720 | K10: =SUMPRODUCT(K14:K19,$F$14:$F$19)*$F10 -> 12040 | L10: =SUMPRODUCT(L14:L19,$F$14:$F$19)*$F10 -> 13720 | M10: =SUMPRODUCT(M14:M19,$F$14:$F$19)*$F10 -> 13720 | N10: =SUMPRODUCT(N14:N19,$F$14:$F$19)*$F10 -> 12040 | ... R10: =SUMPRODUCT(R14:R19,$F$14:$F$19)*$F10 -> 13720
B12: Простои оборудования на ТО | C12: Интервал ТО | D12: Длительность простоя на одном ТО, час | E12: Кол-во ТО в год | F12: Занято человек | G12: Простоев в год, час | H12: Простоев в год, час | I12: Простоев в год, час | J12: Простоев в год, час | K12: Простоев в год, час | L12: Простоев в год, час | M12: Простоев в год, час | N12: Простоев в год, час | O12: Простоев в год, час | P12: Простоев в год, час | Q12: Простоев в год, час | R12: Простоев в год, час
B13: всего простоев на ТО, часов | G13: =SUM(G14:G19) -> 172 | H13: =SUM(H14:H19) -> 196 | I13: =SUM(I14:I19) -> 172 | J13: =SUM(J14:J19) -> 196 | K13: =SUM(K14:K19) -> 172 | L13: =SUM(L14:L19) -> 196 | M13: =SUM(M14:M19) -> 196 | N13: =SUM(N14:N19) -> 172 | ... R13: =SUM(R14:R19) -> 196
B14: ТО-1 | C14: 500 | D14: 4 | E14: =$F$6/C14 -> 14 | F14: 2 | G14: =$E14*$D14 -> 56 | H14: =$E14*$D14 -> 56 | I14: =$E14*$D14 -> 56 | J14: =$E14*$D14 -> 56 | K14: =$E14*$D14 -> 56 | L14: =$E14*$D14 -> 56 | M14: =$E14*$D14 -> 56 | N14: =$E14*$D14 -> 56 | ... R14: =$E14*$D14 -> 56 | T14: формулы для примера, можно менять под необходимые параметры
B15: ТО-2 | C15: 1000 | D15: 8 | E15: =$F$6/C15 -> 7 | F15: 2 | G15: =$E15*$D15 -> 56 | H15: =$E15*$D15 -> 56 | I15: =$E15*$D15 -> 56 | J15: =$E15*$D15 -> 56 | K15: =$E15*$D15 -> 56 | L15: =$E15*$D15 -> 56 | M15: =$E15*$D15 -> 56 | N15: =$E15*$D15 -> 56 | ... R15: =$E15*$D15 -> 56 | T15: формулы для примера, можно менять под необходимые параметры
B16: ТО-3 | C16: 2000 | D16: 12 | E16: 3 | F16: 2 | G16: =$E16*$D16 -> 36 | H16: =$E16*$D16 -> 36 | I16: =$E16*$D16 -> 36 | J16: =$E16*$D16 -> 36 | K16: =$E16*$D16 -> 36 | L16: =$E16*$D16 -> 36 | M16: =$E16*$D16 -> 36 | N16: =$E16*$D16 -> 36 | ... R16: =$E16*$D16 -> 36 | T16: формулы для примера, можно менять под необходимые параметры
B17: ТО-4 | C17: 4000 | D17: 12 | E17: 1 | F17: 2 | G17: =$E17*$D17 -> 12 | H17: =$E17*$D17 -> 12 | I17: =$E17*$D17 -> 12 | J17: =$E17*$D17 -> 12 | K17: =$E17*$D17 -> 12 | L17: =$E17*$D17 -> 12 | M17: =$E17*$D17 -> 12 | N17: =$E17*$D17 -> 12 | ... R17: =$E17*$D17 -> 12 | T17: формулы для примера, можно менять под необходимые параметры
B18: ТО-5 | C18: 6000 | D18: 12 | E18: 1 | F18: 2 | G18: =$E18*$D18 -> 12 | H18: =$E18*$D18 -> 12 | I18: =$E18*$D18 -> 12 | J18: =$E18*$D18 -> 12 | K18: =$E18*$D18 -> 12 | L18: =$E18*$D18 -> 12 | M18: =$E18*$D18 -> 12 | N18: =$E18*$D18 -> 12 | ... R18: =$E18*$D18 -> 12 | T18: формулы для примера, можно менять под необходимые параметры
B19: ТО-6 | C19: 12000 | D19: 24 | E19: 0 | F19: 2 | G19: 0 | H19: =$D19 -> 24 | I19: 0 | J19: =$D19 -> 24 | K19: 0 | L19: =$D19 -> 24 | M19: =$D19 -> 24 | N19: 0 | O19: =$D19 -> 24 | P19: 0 | Q19: =$D19 -> 24 | R19: =$D19 -> 24 | T19: формулы для примера, можно менять под необходимые параметры
B21: Затраты на ТО | C21: Каталожный номер | D21: стоимость за ед., $ | E21: Кол-во | F21: Кол-во ТО в год | G21: $ | H21: $ | I21: $ | J21: $ | K21: $ | L21: $ | M21: $ | N21: $ | O21: $ | P21: $ | Q21: $ | R21: $
B22: ТО | G22: =SUM(G23:G58) -> 70120 | H22: =SUM(H23:H58) -> 70120 | I22: =SUM(I23:I58) -> 70120 | J22: =SUM(J23:J58) -> 70120 | K22: =SUM(K23:K58) -> 70120 | L22: =SUM(L23:L58) -> 70120 | M22: =SUM(M23:M58) -> 70120 | N22: =SUM(N23:N58) -> 70120 | ... R22: =SUM(R23:R58) -> 70120
B23: ТО-1 | E23: =VLOOKUP($B23,$B$14:$C$19,2,FALSE()) -> 500 | F23: =VLOOKUP($B23,$B$14:$E$19,4,FALSE()) -> 14
B24: фильтр | C24: EPI-FLT-FUEL-01 | D24: 140 | E24: 2 | G24: =IF(G$14=0,0,G$14/$D$14*$E24*$D24) -> 3920 | H24: =IF(H$14=0,0,H$14/$D$14*$E24*$D24) -> 3920 | I24: =IF(I$14=0,0,I$14/$D$14*$E24*$D24) -> 3920 | J24: =IF(J$14=0,0,J$14/$D$14*$E24*$D24) -> 3920 | K24: =IF(K$14=0,0,K$14/$D$14*$E24*$D24) -> 3920 | L24: =IF(L$14=0,0,L$14/$D$14*$E24*$D24) -> 3920 | M24: =IF(M$14=0,0,M$14/$D$14*$E24*$D24) -> 3920 | N24: =IF(N$14=0,0,N$14/$D$14*$E24*$D24) -> 3920 | ... R24: =IF(R$14=0,0,R$14/$D$14*$E24*$D24) -> 3920
B25: фильтр | C25: EPI-FLT-FUEL-02 | D25: 70 | E25: 2 | G25: =IF(G$14=0,0,G$14/$D$14*$E25*$D25) -> 1960 | H25: =IF(H$14=0,0,H$14/$D$14*$E25*$D25) -> 1960 | I25: =IF(I$14=0,0,I$14/$D$14*$E25*$D25) -> 1960 | J25: =IF(J$14=0,0,J$14/$D$14*$E25*$D25) -> 1960 | K25: =IF(K$14=0,0,K$14/$D$14*$E25*$D25) -> 1960 | L25: =IF(L$14=0,0,L$14/$D$14*$E25*$D25) -> 1960 | M25: =IF(M$14=0,0,M$14/$D$14*$E25*$D25) -> 1960 | N25: =IF(N$14=0,0,N$14/$D$14*$E25*$D25) -> 1960 | ... R25: =IF(R$14=0,0,R$14/$D$14*$E25*$D25) -> 1960
B26: масло | C26: EPI-OIL-ENG-15W40 | D26: 6 | E26: 80 | G26: =IF(G$14=0,0,G$14/$D$14*$E26*$D26) -> 6720 | H26: =IF(H$14=0,0,H$14/$D$14*$E26*$D26) -> 6720 | I26: =IF(I$14=0,0,I$14/$D$14*$E26*$D26) -> 6720 | J26: =IF(J$14=0,0,J$14/$D$14*$E26*$D26) -> 6720 | K26: =IF(K$14=0,0,K$14/$D$14*$E26*$D26) -> 6720 | L26: =IF(L$14=0,0,L$14/$D$14*$E26*$D26) -> 6720 | M26: =IF(M$14=0,0,M$14/$D$14*$E26*$D26) -> 6720 | N26: =IF(N$14=0,0,N$14/$D$14*$E26*$D26) -> 6720 | ... R26: =IF(R$14=0,0,R$14/$D$14*$E26*$D26) -> 6720
B27: масло | C27: EPI-OIL-HYD-46 | D27: 6 | E27: 80 | G27: =IF(G$14=0,0,G$14/$D$14*$E27*$D27) -> 6720 | H27: =IF(H$14=0,0,H$14/$D$14*$E27*$D27) -> 6720 | I27: =IF(I$14=0,0,I$14/$D$14*$E27*$D27) -> 6720 | J27: =IF(J$14=0,0,J$14/$D$14*$E27*$D27) -> 6720 | K27: =IF(K$14=0,0,K$14/$D$14*$E27*$D27) -> 6720 | L27: =IF(L$14=0,0,L$14/$D$14*$E27*$D27) -> 6720 | M27: =IF(M$14=0,0,M$14/$D$14*$E27*$D27) -> 6720 | N27: =IF(N$14=0,0,N$14/$D$14*$E27*$D27) -> 6720 | ... R27: =IF(R$14=0,0,R$14/$D$14*$E27*$D27) -> 6720
B28: смазка | C28: EPI-GRS-EP2-01 | D28: 8 | E28: 80 | G28: =IF(G$14=0,0,G$14/$D$14*$E28*$D28) -> 8960 | H28: =IF(H$14=0,0,H$14/$D$14*$E28*$D28) -> 8960 | I28: =IF(I$14=0,0,I$14/$D$14*$E28*$D28) -> 8960 | J28: =IF(J$14=0,0,J$14/$D$14*$E28*$D28) -> 8960 | K28: =IF(K$14=0,0,K$14/$D$14*$E28*$D28) -> 8960 | L28: =IF(L$14=0,0,L$14/$D$14*$E28*$D28) -> 8960 | M28: =IF(M$14=0,0,M$14/$D$14*$E28*$D28) -> 8960 | N28: =IF(N$14=0,0,N$14/$D$14*$E28*$D28) -> 8960 | ... R28: =IF(R$14=0,0,R$14/$D$14*$E28*$D28) -> 8960
B29: смазка | C29: EPI-GRS-EP2-02 | D29: 8 | E29: 80 | G29: =IF(G$14=0,0,G$14/$D$14*$E29*$D29) -> 8960 | H29: =IF(H$14=0,0,H$14/$D$14*$E29*$D29) -> 8960 | I29: =IF(I$14=0,0,I$14/$D$14*$E29*$D29) -> 8960 | J29: =IF(J$14=0,0,J$14/$D$14*$E29*$D29) -> 8960 | K29: =IF(K$14=0,0,K$14/$D$14*$E29*$D29) -> 8960 | L29: =IF(L$14=0,0,L$14/$D$14*$E29*$D29) -> 8960 | M29: =IF(M$14=0,0,M$14/$D$14*$E29*$D29) -> 8960 | N29: =IF(N$14=0,0,N$14/$D$14*$E29*$D29) -> 8960 | ... R29: =IF(R$14=0,0,R$14/$D$14*$E29*$D29) -> 8960
B30: ТО-2 | E30: =VLOOKUP($B30,$B$14:$C$19,2,FALSE()) -> 1000 | F30: =VLOOKUP($B30,$B$14:$E$19,4,FALSE()) -> 7
B31: фильтр | C31: EPI-FLT-FUEL-01 | D31: 140 | E31: 2 | G31: =IF(G$15=0,0,G$15/$D$15*$E31*$D31) -> 1960 | H31: =IF(H$15=0,0,H$15/$D$15*$E31*$D31) -> 1960 | I31: =IF(I$15=0,0,I$15/$D$15*$E31*$D31) -> 1960 | J31: =IF(J$15=0,0,J$15/$D$15*$E31*$D31) -> 1960 | K31: =IF(K$15=0,0,K$15/$D$15*$E31*$D31) -> 1960 | L31: =IF(L$15=0,0,L$15/$D$15*$E31*$D31) -> 1960 | M31: =IF(M$15=0,0,M$15/$D$15*$E31*$D31) -> 1960 | N31: =IF(N$15=0,0,N$15/$D$15*$E31*$D31) -> 1960 | ... R31: =IF(R$15=0,0,R$15/$D$15*$E31*$D31) -> 1960
B32: фильтр | C32: EPI-FLT-FUEL-02 | D32: 70 | E32: 2 | G32: =IF(G$15=0,0,G$15/$D$15*$E32*$D32) -> 980 | H32: =IF(H$15=0,0,H$15/$D$15*$E32*$D32) -> 980 | I32: =IF(I$15=0,0,I$15/$D$15*$E32*$D32) -> 980 | J32: =IF(J$15=0,0,J$15/$D$15*$E32*$D32) -> 980 | K32: =IF(K$15=0,0,K$15/$D$15*$E32*$D32) -> 980 | L32: =IF(L$15=0,0,L$15/$D$15*$E32*$D32) -> 980 | M32: =IF(M$15=0,0,M$15/$D$15*$E32*$D32) -> 980 | N32: =IF(N$15=0,0,N$15/$D$15*$E32*$D32) -> 980 | ... R32: =IF(R$15=0,0,R$15/$D$15*$E32*$D32) -> 980
B33: масло | C33: EPI-OIL-ENG-15W40 | D33: 6 | E33: 80 | G33: =IF(G$15=0,0,G$15/$D$15*$E33*$D33) -> 3360 | H33: =IF(H$15=0,0,H$15/$D$15*$E33*$D33) -> 3360 | I33: =IF(I$15=0,0,I$15/$D$15*$E33*$D33) -> 3360 | J33: =IF(J$15=0,0,J$15/$D$15*$E33*$D33) -> 3360 | K33: =IF(K$15=0,0,K$15/$D$15*$E33*$D33) -> 3360 | L33: =IF(L$15=0,0,L$15/$D$15*$E33*$D33) -> 3360 | M33: =IF(M$15=0,0,M$15/$D$15*$E33*$D33) -> 3360 | N33: =IF(N$15=0,0,N$15/$D$15*$E33*$D33) -> 3360 | ... R33: =IF(R$15=0,0,R$15/$D$15*$E33*$D33) -> 3360
B34: масло | C34: EPI-OIL-HYD-46 | D34: 6 | E34: 80 | G34: =IF(G$15=0,0,G$15/$D$15*$E34*$D34) -> 3360 | H34: =IF(H$15=0,0,H$15/$D$15*$E34*$D34) -> 3360 | I34: =IF(I$15=0,0,I$15/$D$15*$E34*$D34) -> 3360 | J34: =IF(J$15=0,0,J$15/$D$15*$E34*$D34) -> 3360 | K34: =IF(K$15=0,0,K$15/$D$15*$E34*$D34) -> 3360 | L34: =IF(L$15=0,0,L$15/$D$15*$E34*$D34) -> 3360 | M34: =IF(M$15=0,0,M$15/$D$15*$E34*$D34) -> 3360 | N34: =IF(N$15=0,0,N$15/$D$15*$E34*$D34) -> 3360 | ... R34: =IF(R$15=0,0,R$15/$D$15*$E34*$D34) -> 3360
B35: смазка | C35: EPI-GRS-EP2-01 | D35: 8 | E35: 80 | G35: =IF(G$15=0,0,G$15/$D$15*$E35*$D35) -> 4480 | H35: =IF(H$15=0,0,H$15/$D$15*$E35*$D35) -> 4480 | I35: =IF(I$15=0,0,I$15/$D$15*$E35*$D35) -> 4480 | J35: =IF(J$15=0,0,J$15/$D$15*$E35*$D35) -> 4480 | K35: =IF(K$15=0,0,K$15/$D$15*$E35*$D35) -> 4480 | L35: =IF(L$15=0,0,L$15/$D$15*$E35*$D35) -> 4480 | M35: =IF(M$15=0,0,M$15/$D$15*$E35*$D35) -> 4480 | N35: =IF(N$15=0,0,N$15/$D$15*$E35*$D35) -> 4480 | ... R35: =IF(R$15=0,0,R$15/$D$15*$E35*$D35) -> 4480
B36: смазка | C36: EPI-GRS-EP2-02 | D36: 8 | E36: 80 | G36: =IF(G$15=0,0,G$15/$D$15*$E36*$D36) -> 4480 | H36: =IF(H$15=0,0,H$15/$D$15*$E36*$D36) -> 4480 | I36: =IF(I$15=0,0,I$15/$D$15*$E36*$D36) -> 4480 | J36: =IF(J$15=0,0,J$15/$D$15*$E36*$D36) -> 4480 | K36: =IF(K$15=0,0,K$15/$D$15*$E36*$D36) -> 4480 | L36: =IF(L$15=0,0,L$15/$D$15*$E36*$D36) -> 4480 | M36: =IF(M$15=0,0,M$15/$D$15*$E36*$D36) -> 4480 | N36: =IF(N$15=0,0,N$15/$D$15*$E36*$D36) -> 4480 | ... R36: =IF(R$15=0,0,R$15/$D$15*$E36*$D36) -> 4480
B37: ТО-3 | E37: =VLOOKUP($B37,$B$14:$C$19,2,FALSE()) -> 2000 | F37: =VLOOKUP($B37,$B$14:$E$19,4,FALSE()) -> 3
B38: фильтр | C38: EPI-FLT-FUEL-01 | D38: 140 | E38: 2 | G38: =IF(G$16=0,0,G$16/$D$16*$E38*$D38) -> 840 | H38: =IF(H$16=0,0,H$16/$D$16*$E38*$D38) -> 840 | I38: =IF(I$16=0,0,I$16/$D$16*$E38*$D38) -> 840 | J38: =IF(J$16=0,0,J$16/$D$16*$E38*$D38) -> 840 | K38: =IF(K$16=0,0,K$16/$D$16*$E38*$D38) -> 840 | L38: =IF(L$16=0,0,L$16/$D$16*$E38*$D38) -> 840 | M38: =IF(M$16=0,0,M$16/$D$16*$E38*$D38) -> 840 | N38: =IF(N$16=0,0,N$16/$D$16*$E38*$D38) -> 840 | ... R38: =IF(R$16=0,0,R$16/$D$16*$E38*$D38) -> 840
B39: фильтр | C39: EPI-FLT-FUEL-02 | D39: 70 | E39: 2 | G39: =IF(G$16=0,0,G$16/$D$16*$E39*$D39) -> 420 | H39: =IF(H$16=0,0,H$16/$D$16*$E39*$D39) -> 420 | I39: =IF(I$16=0,0,I$16/$D$16*$E39*$D39) -> 420 | J39: =IF(J$16=0,0,J$16/$D$16*$E39*$D39) -> 420 | K39: =IF(K$16=0,0,K$16/$D$16*$E39*$D39) -> 420 | L39: =IF(L$16=0,0,L$16/$D$16*$E39*$D39) -> 420 | M39: =IF(M$16=0,0,M$16/$D$16*$E39*$D39) -> 420 | N39: =IF(N$16=0,0,N$16/$D$16*$E39*$D39) -> 420 | ... R39: =IF(R$16=0,0,R$16/$D$16*$E39*$D39) -> 420
B40: масло | C40: EPI-OIL-ENG-15W40 | D40: 7 | E40: 80 | G40: =IF(G$16=0,0,G$16/$D$16*$E40*$D40) -> 1680 | H40: =IF(H$16=0,0,H$16/$D$16*$E40*$D40) -> 1680 | I40: =IF(I$16=0,0,I$16/$D$16*$E40*$D40) -> 1680 | J40: =IF(J$16=0,0,J$16/$D$16*$E40*$D40) -> 1680 | K40: =IF(K$16=0,0,K$16/$D$16*$E40*$D40) -> 1680 | L40: =IF(L$16=0,0,L$16/$D$16*$E40*$D40) -> 1680 | M40: =IF(M$16=0,0,M$16/$D$16*$E40*$D40) -> 1680 | N40: =IF(N$16=0,0,N$16/$D$16*$E40*$D40) -> 1680 | ... R40: =IF(R$16=0,0,R$16/$D$16*$E40*$D40) -> 1680
B41: масло | C41: EPI-OIL-HYD-46 | D41: 7 | E41: 80 | G41: =IF(G$16=0,0,G$16/$D$16*$E41*$D41) -> 1680 | H41: =IF(H$16=0,0,H$16/$D$16*$E41*$D41) -> 1680 | I41: =IF(I$16=0,0,I$16/$D$16*$E41*$D41) -> 1680 | J41: =IF(J$16=0,0,J$16/$D$16*$E41*$D41) -> 1680 | K41: =IF(K$16=0,0,K$16/$D$16*$E41*$D41) -> 1680 | L41: =IF(L$16=0,0,L$16/$D$16*$E41*$D41) -> 1680 | M41: =IF(M$16=0,0,M$16/$D$16*$E41*$D41) -> 1680 | N41: =IF(N$16=0,0,N$16/$D$16*$E41*$D41) -> 1680 | ... R41: =IF(R$16=0,0,R$16/$D$16*$E41*$D41) -> 1680
B42: смазка | C42: EPI-GRS-EP2-01 | D42: 9 | E42: 80 | G42: =IF(G$16=0,0,G$16/$D$16*$E42*$D42) -> 2160 | H42: =IF(H$16=0,0,H$16/$D$16*$E42*$D42) -> 2160 | I42: =IF(I$16=0,0,I$16/$D$16*$E42*$D42) -> 2160 | J42: =IF(J$16=0,0,J$16/$D$16*$E42*$D42) -> 2160 | K42: =IF(K$16=0,0,K$16/$D$16*$E42*$D42) -> 2160 | L42: =IF(L$16=0,0,L$16/$D$16*$E42*$D42) -> 2160 | M42: =IF(M$16=0,0,M$16/$D$16*$E42*$D42) -> 2160 | N42: =IF(N$16=0,0,N$16/$D$16*$E42*$D42) -> 2160 | ... R42: =IF(R$16=0,0,R$16/$D$16*$E42*$D42) -> 2160
B43: смазка | C43: EPI-GRS-EP2-02 | D43: 9 | E43: 80 | G43: =IF(G$16=0,0,G$16/$D$16*$E43*$D43) -> 2160 | H43: =IF(H$16=0,0,H$16/$D$16*$E43*$D43) -> 2160 | I43: =IF(I$16=0,0,I$16/$D$16*$E43*$D43) -> 2160 | J43: =IF(J$16=0,0,J$16/$D$16*$E43*$D43) -> 2160 | K43: =IF(K$16=0,0,K$16/$D$16*$E43*$D43) -> 2160 | L43: =IF(L$16=0,0,L$16/$D$16*$E43*$D43) -> 2160 | M43: =IF(M$16=0,0,M$16/$D$16*$E43*$D43) -> 2160 | N43: =IF(N$16=0,0,N$16/$D$16*$E43*$D43) -> 2160 | ... R43: =IF(R$16=0,0,R$16/$D$16*$E43*$D43) -> 2160
B44: ТО-4 | E44: =VLOOKUP($B44,$B$14:$C$19,2,FALSE()) -> 4000 | F44: =VLOOKUP($B44,$B$14:$E$19,4,FALSE()) -> 1
...

Sheet Ремонты
B2: ячейки к заполнению поставщиком
B3: Расчетный КТГ | F3: ='Данные_Буровой станок'!E6 -> 0.93093607 | G3: ='Данные_Буровой станок'!F6 -> 0.91717402 | H3: ='Данные_Буровой станок'!G6 -> 0.93093607 | I3: ='Данные_Буровой станок'!H6 -> 0.91717402 | J3: ='Данные_Буровой станок'!I6 -> 0.88654236 | K3: ='Данные_Буровой станок'!J6 -> 0.91717402 | L3: ='Данные_Буровой станок'!K6 -> 0.85058346 | M3: ='Данные_Буровой станок'!L6 -> 0.91983765 | ... Q3: ='Данные_Буровой станок'!P6 -> 0.91717402
B4: Год службы (год) | C4: Ед.изм. | F4: 1 | G4: =F4+1 -> 2 | H4: =G4+1 -> 3 | I4: =H4+1 -> 4 | J4: =I4+1 -> 5 | K4: =J4+1 -> 6 | L4: =K4+1 -> 7 | M4: =L4+1 -> 8 | N4: =M4+1 -> 9 | ... Q4: =P4+1 -> 12
B5: Наработка на начало года | C5: м/час | F5: 0 | G5: =F6+1 -> 7001 | H5: =G6+1 -> 14001 | I5: =H6+1 -> 21001 | J5: =I6+1 -> 28001 | K5: =J6+1 -> 35001 | L5: =K6+1 -> 42001 | M5: =L6+1 -> 49001 | N5: =M6+1 -> 56001 | ... Q5: =P6+1 -> 77001
B6: Наработка на конец года | C6: м/час | E6: =ТО!F6 -> 7000 | F6: =E6 -> 7000 | G6: =F6+$E6 -> 14000 | H6: =G6+$E6 -> 21000 | I6: =H6+$E6 -> 28000 | J6: =I6+$E6 -> 35000 | K6: =J6+$E6 -> 42000 | L6: =K6+$E6 -> 49000 | M6: =L6+$E6 -> 56000 | N6: =M6+$E6 -> 63000 | ... Q6: =P6+$E6 -> 84000
B8: Простои в ремонтах | C8: часов | F8: =F16 -> 200 | G8: =G16 -> 300 | H8: =H16 -> 200 | I8: =I16 -> 300 | J8: =J16 -> 600 | K8: =K16 -> 300 | L8: =L16 -> 900 | M8: =M16 -> 300 | ... Q8: =Q16 -> 300
B9: Затраты на ТО и ремонты | C9: $/год | F9: =SUM(F10:F12) -> 98700 | G9: =SUM(G10:G12) -> 247300 | H9: =SUM(H10:H12) -> 339300 | I9: =SUM(I10:I12) -> 272300 | J9: =SUM(J10:J12) -> 210200 | K9: =SUM(K10:K12) -> 378800 | L9: =SUM(L10:L12) -> 253800 | M9: =SUM(M10:M12) -> 326800 | ... Q9: =SUM(Q10:Q12) -> 304300
B10: текущие ремонты | C10: $/год | F10: =F33 -> 8500 | G10: =G33 -> 8500 | H10: =H33 -> 8500 | I10: =I33 -> 8500 | J10: =J33 -> 8500 | K10: =K33 -> 8500 | L10: =L33 -> 8500 | M10: =M33 -> 8500 | ... Q10: =Q33 -> 8500
B11: планово-предупредительные (капитальные) ремонты | C11: $/год | F11: =F39 -> 76200 | G11: =G39 -> 217800 | H11: =H39 -> 316800 | I11: =I39 -> 242800 | J11: =J39 -> 145700 | K11: =K39 -> 349300 | L11: =L39 -> 182300 | M11: =M39 -> 297300 | ... Q11: =Q39 -> 274800
B12: сервис (трудозатраты) | C12: $/год | F12: =SUMPRODUCT(F$25:F$29,$D25:$D29) -> 14000 | G12: =SUMPRODUCT(G$25:G$29,$D25:$D29) -> 21000 | H12: =SUMPRODUCT(H$25:H$29,$D25:$D29) -> 14000 | I12: =SUMPRODUCT(I$25:I$29,$D25:$D29) -> 21000 | J12: =SUMPRODUCT(J$25:J$29,$D25:$D29) -> 56000 | K12: =SUMPRODUCT(K$25:K$29,$D25:$D29) -> 21000 | L12: =SUMPRODUCT(L$25:L$29,$D25:$D29) -> 63000 | M12: =SUMPRODUCT(M$25:M$29,$D25:$D29) -> 21000 | ... Q12: =SUMPRODUCT(Q$25:Q$29,$D25:$D29) -> 21000
B14: Простои в ремонте (час)
B15: Вид ремонта | C15: Ед.изм. | F15: часов | G15: часов | H15: часов | I15: часов | J15: часов | K15: часов | L15: часов | M15: часов | N15: часов | O15: часов | P15: часов | Q15: часов
B16: Всего простоев | F16: =SUM(F17:F21) -> 200 | G16: =SUM(G17:G21) -> 300 | H16: =SUM(H17:H21) -> 200 | I16: =SUM(I17:I21) -> 300 | J16: =SUM(J17:J21) -> 600 | K16: =SUM(K17:K21) -> 300 | L16: =SUM(L17:L21) -> 900 | M16: =SUM(M17:M21) -> 300 | ... Q16: =SUM(Q17:Q21) -> 300
B17: ремонт-1 | C17: часов | F17: 200 | G17: 200 | H17: 200 | I17: 200 | J17: 200 | K17: 200 | L17: 200 | M17: 200 | N17: 200 | O17: 200 | P17: 200 | Q17: 200
B18: ремонт-2 | C18: часов | F18: 0 | G18: 0 | H18: 0 | I18: 0 | J18: 200 | K18: 0 | L18: 400 | M18: 0 | N18: 0 | O18: 400 | P18: 0 | Q18: 0
B19: ремонт-3 | C19: часов | F19: 0 | G19: 100 | H19: 0 | I19: 100 | J19: 0 | K19: 100 | L19: 0 | M19: 100 | N19: 0 | O19: 0 | P19: 0 | Q19: 100
B20: ремонт-4 | C20: часов | F20: 0 | G20: 0 | H20: 0 | I20: 0 | J20: 100 | K20: 0 | L20: 200 | M20: 0 | N20: 0 | O20: 200 | P20: 0 | Q20: 0
B21: ремонт-5 | C21: часов | F21: 0 | G21: 0 | H21: 0 | I21: 0 | J21: 100 | K21: 0 | L21: 100 | M21: 0 | N21: 0 | O21: 100 | P21: 0 | Q21: 0
B23: Трудозатраты на ремонты (ч/час) | D23: =ТО!F10 -> 35
B24: Вид ремонта | C24: Ед.изм. | D24: Стоимость чел.часа | F24: ч/часов | G24: ч/часов | H24: ч/часов | I24: ч/часов | J24: ч/часов | K24: ч/часов | L24: ч/часов | M24: ч/часов | N24: ч/часов | O24: ч/часов | P24: ч/часов | Q24: ч/часов
B25: =B17 -> ремонт-1 | C25: ч/часов | D25: =$D$23 -> 35 | F25: 400 | G25: 400 | H25: 400 | I25: 400 | J25: 400 | K25: 400 | L25: 400 | M25: 400 | N25: 400 | O25: 400 | P25: 400 | Q25: 400
B26: =B18 -> ремонт-2 | C26: ч/часов | D26: =$D$23 -> 35 | F26: 0 | G26: 0 | H26: 0 | I26: 0 | J26: 600 | K26: 0 | L26: 800 | M26: 0 | N26: 0 | O26: 800 | P26: 0 | Q26: 0
B27: =B19 -> ремонт-3 | C27: ч/часов | D27: =$D$23 -> 35 | F27: 0 | G27: 200 | H27: 0 | I27: 200 | J27: 0 | K27: 200 | L27: 0 | M27: 200 | N27: 0 | O27: 0 | P27: 0 | Q27: 200
B28: =B20 -> ремонт-4 | C28: ч/часов | D28: =$D$23 -> 35 | F28: 0 | G28: 0 | H28: 0 | I28: 0 | J28: 400 | K28: 0 | L28: 400 | M28: 0 | N28: 0 | O28: 400 | P28: 0 | Q28: 0
B29: =B21 -> ремонт-5 | C29: ч/часов | D29: =$D$23 -> 35 | F29: 0 | G29: 0 | H29: 0 | I29: 0 | J29: 200 | K29: 0 | L29: 200 | M29: 0 | N29: 0 | O29: 200 | P29: 0 | Q29: 0
B31: Затраты на ремонты ($)
B32: Детализация затрат | C32: Стоимость за ед., $ | D32: Ресурс до замены / ремонта, м/ч | E32: Кол-во МТР | F32: $ | G32: $ | H32: $ | I32: $ | J32: $ | K32: $ | L32: $ | M32: $ | N32: $ | O32: $ | P32: $ | Q32: $
B33: Текущие ремонты (если планируются) | F33: =SUM(F34:F38) -> 8500 | G33: =SUM(G34:G38) -> 8500 | H33: =SUM(H34:H38) -> 8500 | I33: =SUM(I34:I38) -> 8500 | J33: =SUM(J34:J38) -> 8500 | K33: =SUM(K34:K38) -> 8500 | L33: =SUM(L34:L38) -> 8500 | M33: =SUM(M34:M38) -> 8500 | ... Q33: =SUM(Q34:Q38) -> 8500
B34: текущий ремонт (ходовая часть) | C34: 500 | D34: 500 | E34: 5 | F34: =$E34*$C34 -> 2500 | G34: =$E34*$C34 -> 2500 | H34: =$E34*$C34 -> 2500 | I34: =$E34*$C34 -> 2500 | J34: =$E34*$C34 -> 2500 | K34: =$E34*$C34 -> 2500 | L34: =$E34*$C34 -> 2500 | M34: =$E34*$C34 -> 2500 | ... Q34: =$E34*$C34 -> 2500
B35: текущий ремонт (рабочее оборудование) | C35: 500 | D35: 1000 | E35: 4 | F35: =$E35*$C35 -> 2000 | G35: =$E35*$C35 -> 2000 | H35: =$E35*$C35 -> 2000 | I35: =$E35*$C35 -> 2000 | J35: =$E35*$C35 -> 2000 | K35: =$E35*$C35 -> 2000 | L35: =$E35*$C35 -> 2000 | M35: =$E35*$C35 -> 2000 | ... Q35: =$E35*$C35 -> 2000
B36: уплотнения и сальники (ходовая/гидравлика) | C36: 500 | D36: 2000 | E36: 3 | F36: =$E36*$C36 -> 1500 | G36: =$E36*$C36 -> 1500 | H36: =$E36*$C36 -> 1500 | I36: =$E36*$C36 -> 1500 | J36: =$E36*$C36 -> 1500 | K36: =$E36*$C36 -> 1500 | L36: =$E36*$C36 -> 1500 | M36: =$E36*$C36 -> 1500 | ... Q36: =$E36*$C36 -> 1500
B37: электрика, датчики, разъёмы (мелкий ремонт) | C37: 500 | D37: 4000 | E37: 3 | F37: =$E37*$C37 -> 1500 | G37: =$E37*$C37 -> 1500 | H37: =$E37*$C37 -> 1500 | I37: =$E37*$C37 -> 1500 | J37: =$E37*$C37 -> 1500 | K37: =$E37*$C37 -> 1500 | L37: =$E37*$C37 -> 1500 | M37: =$E37*$C37 -> 1500 | ... Q37: =$E37*$C37 -> 1500
B38: крепёж, шланги низкого давления, фитинги | C38: 500 | D38: 6000 | E38: 2 | F38: =$E38*$C38 -> 1000 | G38: =$E38*$C38 -> 1000 | H38: =$E38*$C38 -> 1000 | I38: =$E38*$C38 -> 1000 | J38: =$E38*$C38 -> 1000 | K38: =$E38*$C38 -> 1000 | L38: =$E38*$C38 -> 1000 | M38: =$E38*$C38 -> 1000 | ... Q38: =$E38*$C38 -> 1000
B39: планово-предупредительные (капитальные) ремонты | F39: =SUM(F40:F77) -> 76200 | G39: =SUM(G40:G77) -> 217800 | H39: =SUM(H40:H77) -> 316800 | I39: =SUM(I40:I77) -> 242800 | J39: =SUM(J40:J77) -> 145700 | K39: =SUM(K40:K77) -> 349300 | L39: =SUM(L40:L77) -> 182300 | M39: =SUM(M40:M77) -> 297300 | ... Q39: =SUM(Q40:Q77) -> 274800
B40: ДВС
B41: турбокомпрессор (Holset, одноступенчатый) — капитальный ремонт (ремкомплект) | C41: 2500 | D41: 6000 | E41: 1 | F41: =$C41*$E41 -> 2500 | G41: =$C41*$E41 -> 2500 | H41: =$C41*$E41 -> 2500 | I41: =$C41*$E41 -> 2500 | J41: =$C41*$E41 -> 2500 | K41: =$C41*$E41 -> 2500 | L41: =$C41*$E41 -> 2500 | M41: =$C41*$E41 -> 2500 | ... Q41: =$C41*$E41 -> 2500
B42: турбокомпрессор (Holset) — полная замена | C42: 5000 | D42: 12000 | E42: 1 | F42: 0 | G42: =$C42*$E42 -> 5000 | H42: 0 | I42: =$C42*$E42 -> 5000 | J42: 0 | K42: =$C42*$E42 -> 5000 | L42: 0 | M42: =$C42*$E42 -> 5000 | N42: 0 | O42: =$C42*$E42 -> 5000 | P42: 0 | Q42: =$C42*$E42 -> 5000
B43: форсунки топливные MCRS (комплект, 6 шт.) — замена | C43: 12000 | D43: 10000 | E43: 1 | F43: 0 | G43: =$C43*$E43 -> 12000 | H43: 0 | I43: =$C43*$E43 -> 12000 | J43: =$C43*$E43 -> 12000 | K43: 0 | L43: =$C43*$E43 -> 12000 | M43: 0 | N43: =$C43*$E43 -> 12000 | O43: =$C43*$E43 -> 12000 | P43: 0 | Q43: =$C43*$E43 -> 12000
B44: вспомогательное оборудование ДВС (стартер, генератор, водяной насос) — замена | C44: 7500 | D44: 12000 | E44: 1 | F44: 0 | G44: =$C44*$E44 -> 7500 | H44: 0 | I44: =$C44*$E44 -> 7500 | J44: 0 | K44: =$C44*$E44 -> 7500 | L44: 0 | M44: =$C44*$E44 -> 7500 | N44: 0 | O44: =$C44*$E44 -> 7500 | P44: 0 | Q44: =$C44*$E44 -> 7500
B45: капитальный ремонт двигателя (переборка блока: ЦПГ, коленвал, вкладыши и т.п.) | C45: 48000 | D45: 18000 | E45: 1 | F45: 0 | G45: 0 | H45: =$C45*$E45 -> 48000 | I45: 0 | J45: 0 | K45: =C45*1.5 -> 72000 | L45: 0 | M45: 0 | N45: 0 | O45: 0 | P45: 0 | Q45: 0
...
