Workbook

Sheet Методика
B1: МЕТОДИКА ОЦЕНКИ СТОИМОСТИ ВЛАДЕНИЯ ГОРНЫХ МАШИН (TCO / LCC)
B2: Сравнение вариантов оборудования одного класса на основе полного жизненного цикла.
C4: 1. НАЗНАЧЕНИЕ
C5: Модель предназначена для экономического сравнения нескольких моделей горного оборудования одного класса (экскаваторы, самосвалы, погрузчики, бульдозеры, буровые станки) по критерию совокупной стоимости владения за полный жизненный цикл (Total Cost of Ownership / Life Cycle Cost). Результат — обоснованный выбор варианта с минимальными приведёнными затратами на единицу продукции.
C6: 2. СОСТАВ ЗАТРАТ ЖИЗНЕННОГО ЦИКЛА
C7: • Капитальные (CAPEX): цена приобретения, доставка/монтаж/ПНР, стартовый ЗИП, финансирование (кредит/лизинг), за вычетом остаточной стоимости.
C8: • Энергоносители: дизельное топливо или электроэнергия (ключевой драйвер OPEX).
C9: • Смазочные материалы и технические жидкости.
C10: • Расходные части и износ: шины (самосвалы, погрузчики) или ходовая часть/ГЭТ (экскаваторы, бульдозеры).
C11: • ТОиР: плановое техническое обслуживание и капитальные ремонты (rebuild) основных узлов.
C12: • Оплата труда операторов (с учётом сменности и полной стоимости персонала).
C13: • Постоянные затраты: страхование, налоги, сборы.
C14: 3. МЕТОДОЛОГИЯ РАСЧЁТА
C15: Все потоки затрат приводятся к текущей стоимости (NPV) по ставке дисконтирования (WACC). Затраты каждой категории растут с индивидуальной эскалацией (топливо, труд, запчасти, инфляция) и приводятся через коэффициент растущего аннуитета GAF(g, r, N) = (1 − ((1+g)/(1+r))^N) / (r − g).
... C34: зелёные ячейки — итоговые показатели / лучший вариант

Sheet Параметры
B1: ГЛОБАЛЬНЫЕ ПАРАМЕТРЫ И МАКРОДОПУЩЕНИЯ
B2: Единые для всех сравниваемых вариантов. Заполняйте жёлтые ячейки.
B4: Параметр | C4: Значение | D4: Ед. изм. | E4: Комментарий
B5: Валюта расчёта | C5: USD | D5: — | E5: Условная денежная единица (все суммы в ней)
B6: Ставка дисконтирования (WACC) | C6: 0.12 | D6: %/год | E6: Стоимость капитала для приведения к текущей стоимости
B7: Общая инфляция | C7: 0.04 | D7: %/год | E7: Рост постоянных затрат (страхование, налоги)
B8: Эскалация цены топлива/энергии | C8: 0.05 | D8: %/год | E8: Прогнозный рост цен на дизтопливо/электроэнергию
B9: Эскалация оплаты труда | C9: 0.06 | D9: %/год | E9: Прогнозный рост ФОТ операторов
B10: Эскалация запчастей и ремонта | C10: 0.05 | D10: %/год | E10: Рост цен на ЗИП, шины/ГЭТ, услуги ТОиР
B11: Цена дизельного топлива | C11: 0.9 | D11: /л | E11: Средняя цена на площадке эксплуатации
B12: Цена электроэнергии | C12: 0.09 | D12: /кВт·ч | E12: Для электрических/гибридных машин
B13: Оплата труда оператора (полная) | C13: 35 | D13: /ч | E13: С учётом налогов, СИЗ, обучения, накладных
B14: Ценность продукции (выручка), опц. | C14: 0 | D14: /т | E14: Для анализа влияния простоев; 0 = не учитывать
B16: Легенда: | D16: — ячейки для ввода данных пользователем
D17: — расчётные итоговые показатели

Sheet Ввод данных
B1: ВВОД ИСХОДНЫХ ДАННЫХ ПО ВАРИАНТАМ ОБОРУДОВАНИЯ
B2: Сравнение до 4-х моделей одного класса. Пример: гидравлические экскаваторы ~250 т.
B4: Показатель | C4: Вариант 1 | D4: Вариант 2 | E4: Вариант 3 | F4: Вариант 4 | G4: Ед. изм. | H4: Пояснение
B6: A. ИДЕНТИФИКАЦИЯ
B7: Наименование / модель | C7: Экскаватор A | D7: Экскаватор B | E7: Экскаватор C | F7: Экскаватор D | G7: — | H7: Название варианта
B8: Производитель | C8: Поставщик 1 | D8: Поставщик 2 | E8: Поставщик 3 | F8: Поставщик 4 | G8: —
B9: Класс / тип | C9: Гидравл. экскаватор | D9: Гидравл. экскаватор | E9: Гидравл. экскаватор | F9: Гидравл. экскаватор | G9: — | H9: Один класс для корректного сравнения
B10: Тип привода | C10: Дизель | D10: Дизель | E10: Дизель | F10: Дизель | G10: — | H10: Дизель / Электро / Гибрид
B11: B. ТЕХНИЧЕСКИЕ ХАРАКТЕРИСТИКИ
B12: Номинальная мощность | C12: 1500 | D12: 1400 | E12: 1600 | F12: 1520 | G12: кВт | H12: Мощность двигателя/привода
B13: Эксплуатационная масса | C13: 250 | D13: 248 | E13: 255 | F13: 251 | G13: т
B14: Ёмкость ковша / грузоподъём. | C14: 15 | D14: 15 | E14: 16 | F14: 15 | G14: м³/т | H14: Ковш (экскаватор) или г/п (самосвал)
B15: C. РЕЖИМ ЭКСПЛУАТАЦИИ
B16: Срок службы (горизонт анализа) | C16: 10 | D16: 10 | E16: 10 | F16: 10 | G16: лет | H16: Расчётный срок владения
B17: Наработка в год | C17: 5500 | D17: 5500 | E17: 5500 | F17: 5500 | G17: мото-ч/год | H17: Годовой фонд рабочего времени машины
B18: Коэф. технической готовности | C18: 0.85 | D18: 0.85 | E18: 0.85 | F18: 0.85 | G18: % | H18: Справочно (надёжность/ремонтопригодность)
B19: Коэф. использования | C19: 0.85 | D19: 0.85 | E19: 0.85 | F19: 0.85 | G19: % | H19: Доля рабочего времени в готовом времени
B20: Эксплуатац. производительность | C20: 2500 | D20: 2450 | E20: 2550 | F20: 2500 | G20: т/мото-ч | H20: Фактич. производит. за мото-час работы
B21: D. КАПИТАЛЬНЫЕ ЗАТРАТЫ (CAPEX)
B22: Цена приобретения | C22: 4500000 | D22: 4200000 | E22: 5000000 | F22: 4700000 | H22: Стоимость машины (без доставки)
B23: Доставка, монтаж, ПНР | C23: 150000 | D23: 150000 | E23: 160000 | F23: 155000 | H23: Логистика, сборка, пуско-наладка
B24: Стартовый комплект ЗИП | C24: 120000 | D24: 110000 | E24: 140000 | F24: 125000 | H24: Первичный запас запчастей
B25: Остаточная стоимость | C25: 0.14 | D25: 0.11 | E25: 0.16 | F25: 0.13 | G25: % от цены | H25: Стоимость реализации в конце срока
B26: Доля заёмного финансирования | C26: 0.6 | D26: 0.6 | E26: 0.6 | F26: 0.6 | G26: % | H26: Кредит/лизинг; 0 = покупка за свои
B27: Ставка кредита / лизинга | C27: 0.08 | D27: 0.08 | E27: 0.08 | F27: 0.08 | G27: %/год | H27: Годовая ставка финансирования
B28: Срок финансирования | C28: 6 | D28: 6 | E28: 6 | F28: 6 | G28: лет | H28: Период погашения кредита
B29: E. ЭНЕРГОНОСИТЕЛИ
B30: Удельный расход топлива | C30: 300 | D30: 325 | E30: 275 | F30: 290 | G30: л/мото-ч | H30: Ключевой драйвер OPEX
B31: Удельный расход электроэнергии | C31: 0 | D31: 0 | E31: 0 | F31: 0 | G31: кВт·ч/мото-ч | H31: Для электро/гибрид; иначе 0
B32: Смазочные материалы | C32: 0.12 | D32: 0.12 | E32: 0.12 | F32: 0.12 | G32: % от топлива | H32: Масла, смазки, охл. жидкости
B33: F. РАСХОДНЫЕ ЧАСТИ / ИЗНОС
B34: Стоимость комплекта шин/гус./ГЭТ | C34: 350000 | D34: 340000 | E34: 360000 | F34: 350000 | H34: Шины (самосвал) или ходовая (экскаватор)
B35: Ресурс комплекта | C35: 15000 | D35: 14000 | E35: 16000 | F35: 15000 | G35: мото-ч | H35: Наработка до полной замены
B36: G. ТЕХОБСЛУЖИВАНИЕ И РЕМОНТ (ТОиР)
B37: Удельные затраты на ТО (плановое) | C37: 40 | D37: 46 | E37: 34 | F37: 38 | G37: /мото-ч | H37: Плановое ТО, фильтры, работы
B38: Стоимость капитального ремонта | C38: 700000 | D38: 650000 | E38: 800000 | F38: 720000 | H38: Стоимость одного капремонта/rebuild
B39: Периодичность капремонта | C39: 20000 | D39: 18000 | E39: 24000 | F39: 21000 | G39: мото-ч | H39: Наработка между капремонтами
B40: H. ПЕРСОНАЛ
B41: Операторов на машину (сменность) | C41: 1.05 | D41: 1.05 | E41: 1.05 | F41: 1.05 | G41: чел.·смен | H41: Коэф. с учётом подмены; ЗП из 'Параметры'
B42: I. ПРОЧИЕ ГОДОВЫЕ ЗАТРАТЫ
...

Sheet Расчёт TCO
B1: РАСЧЁТ СОВОКУПНОЙ СТОИМОСТИ ВЛАДЕНИЯ (TCO / LCC)
B2: Модель дисконтированного жизненного цикла. Значения рассчитываются автоматически.
B4: Статья | C4: ='Ввод данных'!C7 | D4: ='Ввод данных'!D7 | E4: ='Ввод данных'!E7 | F4: ='Ввод данных'!F7 | G4: Ед. изм.
B5: ПРОИЗВОДСТВЕННЫЕ ПОКАЗАТЕЛИ
B6: Наработка за срок службы | C6: ='Ввод данных'!C17*'Ввод данных'!C16 | D6: ='Ввод данных'!D17*'Ввод данных'!D16 | E6: ='Ввод данных'!E17*'Ввод данных'!E16 | F6: ='Ввод данных'!F17*'Ввод данных'!F16 | G6: мото-ч
B7: Годовой объём производства | C7: ='Ввод данных'!C17*'Ввод данных'!C20 | D7: ='Ввод данных'!D17*'Ввод данных'!D20 | E7: ='Ввод данных'!E17*'Ввод данных'!E20 | F7: ='Ввод данных'!F17*'Ввод данных'!F20 | G7: т/год
B8: Полный объём производства за срок | C8: =C7*'Ввод данных'!C16 | D8: =D7*'Ввод данных'!D16 | E8: =E7*'Ввод данных'!E16 | F8: =F7*'Ввод данных'!F16 | G8: т
B9: ГОДОВЫЕ ЭКСПЛУАТАЦИОННЫЕ ЗАТРАТЫ (в ценах 1-го года)
B10: Топливо | C10: ='Ввод данных'!C17*'Ввод данных'!C30*'Параметры'!C11 | D10: ='Ввод данных'!D17*'Ввод данных'!D30*'Параметры'!C11 | E10: ='Ввод данных'!E17*'Ввод данных'!E30*'Параметры'!C11 | F10: ='Ввод данных'!F17*'Ввод данных'!F30*'Параметры'!C11
B11: Электроэнергия | C11: ='Ввод данных'!C17*'Ввод данных'!C31*'Параметры'!C12 | D11: ='Ввод данных'!D17*'Ввод данных'!D31*'Параметры'!C12 | E11: ='Ввод данных'!E17*'Ввод данных'!E31*'Параметры'!C12 | F11: ='Ввод данных'!F17*'Ввод данных'!F31*'Параметры'!C12
B12: Смазочные материалы | C12: =C10*'Ввод данных'!C32 | D12: =D10*'Ввод данных'!D32 | E12: =E10*'Ввод данных'!E32 | F12: =F10*'Ввод данных'!F32
B13: Шины / гусеницы / ГЭТ | C13: ='Ввод данных'!C34/'Ввод данных'!C35*'Ввод данных'!C17 | D13: ='Ввод данных'!D34/'Ввод данных'!D35*'Ввод данных'!D17 | E13: ='Ввод данных'!E34/'Ввод данных'!E35*'Ввод данных'!E17 | F13: ='Ввод данных'!F34/'Ввод данных'!F35*'Ввод данных'!F17
B14: ТО плановое | C14: ='Ввод данных'!C37*'Ввод данных'!C17 | D14: ='Ввод данных'!D37*'Ввод данных'!D17 | E14: ='Ввод данных'!E37*'Ввод данных'!E17 | F14: ='Ввод данных'!F37*'Ввод данных'!F17
B15: Капитальные ремонты (аннуитизировано) | C15: ='Ввод данных'!C38/'Ввод данных'!C39*'Ввод данных'!C17 | D15: ='Ввод данных'!D38/'Ввод данных'!D39*'Ввод данных'!D17 | E15: ='Ввод данных'!E38/'Ввод данных'!E39*'Ввод данных'!E17 | F15: ='Ввод данных'!F38/'Ввод данных'!F39*'Ввод данных'!F17
B16: Оплата труда операторов | C16: ='Ввод данных'!C17*'Ввод данных'!C41*'Параметры'!C13 | D16: ='Ввод данных'!D17*'Ввод данных'!D41*'Параметры'!C13 | E16: ='Ввод данных'!E17*'Ввод данных'!E41*'Параметры'!C13 | F16: ='Ввод данных'!F17*'Ввод данных'!F41*'Параметры'!C13
B17: Страхование | C17: ='Ввод данных'!C22*'Ввод данных'!C43 | D17: ='Ввод данных'!D22*'Ввод данных'!D43 | E17: ='Ввод данных'!E22*'Ввод данных'!E43 | F17: ='Ввод данных'!F22*'Ввод данных'!F43
B18: Налоги и прочее | C18: ='Ввод данных'!C22*'Ввод данных'!C44 | D18: ='Ввод данных'!D22*'Ввод данных'!D44 | E18: ='Ввод данных'!E22*'Ввод данных'!E44 | F18: ='Ввод данных'!F22*'Ввод данных'!F44
B19: ИТОГО годовые эксплуатационные (год 1) | C19: =C10+C11+C12+C13+C14+C15+C16+C17+C18 | D19: =D10+D11+D12+D13+D14+D15+D16+D17+D18 | E19: =E10+E11+E12+E13+E14+E15+E16+E17+E18 | F19: =F10+F11+F12+F13+F14+F15+F16+F17+F18 | G19: /год
B20: ГРУППЫ ЗАТРАТ ДЛЯ ЭСКАЛАЦИИ (год 1)
B21: Энергия (топливо+электро) | C21: =C10+C11 | D21: =D10+D11 | E21: =E10+E11 | F21: =F10+F11
B22: Труд | C22: =C16 | D22: =D16 | E22: =E16 | F22: =F16
B23: Запчасти и ТОиР (смазка+ГЭТ+ТО+ремонт) | C23: =C12+C13+C14+C15 | D23: =D12+D13+D14+D15 | E23: =E12+E13+E14+E15 | F23: =F12+F13+F14+F15
B24: Постоянные (страхование+налоги) | C24: =C17+C18 | D24: =D17+D18 | E24: =E17+E18 | F24: =F17+F18
B25: КАПИТАЛЬНЫЕ ЗАТРАТЫ И ФИНАНСИРОВАНИЕ
B26: Первоначальные инвестиции (CAPEX) | C26: ='Ввод данных'!C22+'Ввод данных'!C23+'Ввод данных'!C24 | D26: ='Ввод данных'!D22+'Ввод данных'!D23+'Ввод данных'!D24 | E26: ='Ввод данных'!E22+'Ввод данных'!E23+'Ввод данных'!E24 | F26: ='Ввод данных'!F22+'Ввод данных'!F23+'Ввод данных'!F24
B27: Собственные средства (год 0) | C27: ='Ввод данных'!C22*(1-'Ввод данных'!C26)+'Ввод данных'!C23+'Ввод данных'!C24 | D27: ='Ввод данных'!D22*(1-'Ввод данных'!D26)+'Ввод данных'!D23+'Ввод данных'!D24 | E27: ='Ввод данных'!E22*(1-'Ввод данных'!E26)+'Ввод данных'!E23+'Ввод данных'!E24 | F27: ='Ввод данных'!F22*(1-'Ввод данных'!F26)+'Ввод данных'!F23+'Ввод данных'!F24
B28: Заёмные средства (тело кредита) | C28: ='Ввод данных'!C22*'Ввод данных'!C26 | D28: ='Ввод данных'!D22*'Ввод данных'!D26 | E28: ='Ввод данных'!E22*'Ввод данных'!E26 | F28: ='Ввод данных'!F22*'Ввод данных'!F26
B29: Годовой платёж по кредиту | C29: =IF('Ввод данных'!C27=0,C28/'Ввод данных'!C28,C28*'Ввод данных'!C27/(1-(1+'Ввод данных'!C27)^-'Ввод данных'!C28)) | D29: =IF('Ввод данных'!D27=0,D28/'Ввод данных'!D28,D28*'Ввод данных'!D27/(1-(1+'Ввод данных'!D27)^-'Ввод данных'!D28)) | E29: =IF('Ввод данных'!E27=0,E28/'Ввод данных'!E28,E28*'Ввод данных'!E27/(1-(1+'Ввод данных'!E27)^-'Ввод данных'!E28)) | F29: =IF('Ввод данных'!F27=0,F28/'Ввод данных'!F28,F28*'Ввод данных'!F27/(1-(1+'Ввод данных'!F27)^-'Ввод данных'!F28)) | G29: /год
B30: Всего выплат по кредиту (номинал) | C30: =C29*'Ввод данных'!C28 | D30: =D29*'Ввод данных'!D28 | E30: =E29*'Ввод данных'!E28 | F30: =F29*'Ввод данных'!F28
B31: Переплата (проценты) | C31: =C30-C28 | D31: =D30-D28 | E31: =E30-E28 | F31: =F30-F28
B32: Остаточная стоимость (год N) | C32: ='Ввод данных'!C22*'Ввод данных'!C25 | D32: ='Ввод данных'!D22*'Ввод данных'!D25 | E32: ='Ввод данных'!E22*'Ввод данных'!E25 | F32: ='Ввод данных'!F22*'Ввод данных'!F25
B33: ФИНАНСОВЫЕ КОЭФФИЦИЕНТЫ
B34: Коэф. приведения энергии | C34: =IF(ABS('Параметры'!C6-'Параметры'!C8)<1E-9,'Ввод данных'!C16/(1+'Параметры'!C6),(1-((1+'Параметры'!C8)/(1+'Параметры'!C6))^'Ввод данных'!C16)/('Параметры'!C6-'Параметры'!C8)) | D34: =IF(ABS('Параметры'!C6-'Параметры'!C8)<1E-9,'Ввод данных'!D16/(1+'Параметры'!C6),(1-((1+'Параметры'!C8)/(1+'Параметры'!C6))^'Ввод данных'!D16)/('Параметры'!C6-'Параметры'!C8)) | E34: =IF(ABS('Параметры'!C6-'Параметры'!C8)<1E-9,'Ввод данных'!E16/(1+'Параметры'!C6),(1-((1+'Параметры'!C8)/(1+'Параметры'!C6))^'Ввод данных'!E16)/('Параметры'!C6-'Параметры'!C8)) | F34: =IF(ABS('Параметры'!C6-'Параметры'!C8)<1E-9,'Ввод данных'!F16/(1+'Параметры'!C6),(1-((1+'Параметры'!C8)/(1+'Параметры'!C6))^'Ввод данных'!F16)/('Параметры'!C6-'Параметры'!C8))
B35: Коэф. приведения труда | C35: =IF(ABS('Параметры'!C6-'Параметры'!C9)<1E-9,'Ввод данных'!C16/(1+'Параметры'!C6),(1-((1+'Параметры'!C9)/(1+'Параметры'!C6))^'Ввод данных'!C16)/('Параметры'!C6-'Параметры'!C9)) | D35: =IF(ABS('Параметры'!C6-'Параметры'!C9)<1E-9,'Ввод данных'!D16/(1+'Параметры'!C6),(1-((1+'Параметры'!C9)/(1+'Параметры'!C6))^'Ввод данных'!D16)/('Параметры'!C6-'Параметры'!C9)) | E35: =IF(ABS('Параметры'!C6-'Параметры'!C9)<1E-9,'Ввод данных'!E16/(1+'Параметры'!C6),(1-((1+'Параметры'!C9)/(1+'Параметры'!C6))^'Ввод данных'!E16)/('Параметры'!C6-'Параметры'!C9)) | F35: =IF(ABS('Параметры'!C6-'Параметры'!C9)<1E-9,'Ввод данных'!F16/(1+'Параметры'!C6),(1-((1+'Параметры'!C9)/(1+'Параметры'!C6))^'Ввод данных'!F16)/('Параметры'!C6-'Параметры'!C9))
B36: Коэф. приведения запчастей/ТОиР | C36: =IF(ABS('Параметры'!C6-'Параметры'!C10)<1E-9,'Ввод данных'!C16/(1+'Параметры'!C6),(1-((1+'Параметры'!C10)/(1+'Параметры'!C6))^'Ввод данных'!C16)/('Параметры'!C6-'Параметры'!C10)) | D36: =IF(ABS('Параметры'!C6-'Параметры'!C10)<1E-9,'Ввод данных'!D16/(1+'Параметры'!C6),(1-((1+'Параметры'!C10)/(1+'Параметры'!C6))^'Ввод данных'!D16)/('Параметры'!C6-'Параметры'!C10)) | E36: =IF(ABS('Параметры'!C6-'Параметры'!C10)<1E-9,'Ввод данных'!E16/(1+'Параметры'!C6),(1-((1+'Параметры'!C10)/(1+'Параметры'!C6))^'Ввод данных'!E16)/('Параметры'!C6-'Параметры'!C10)) | F36: =IF(ABS('Параметры'!C6-'Параметры'!C10)<1E-9,'Ввод данных'!F16/(1+'Параметры'!C6),(1-((1+'Параметры'!C10)/(1+'Параметры'!C6))^'Ввод данных'!F16)/('Параметры'!C6-'Параметры'!C10))
B37: Коэф. приведения постоянных | C37: =IF(ABS('Параметры'!C6-'Параметры'!C7)<1E-9,'Ввод данных'!C16/(1+'Параметры'!C6),(1-((1+'Параметры'!C7)/(1+'Параметры'!C6))^'Ввод данных'!C16)/('Параметры'!C6-'Параметры'!C7)) | D37: =IF(ABS('Параметры'!C6-'Параметры'!C7)<1E-9,'Ввод данных'!D16/(1+'Параметры'!C6),(1-((1+'Параметры'!C7)/(1+'Параметры'!C6))^'Ввод данных'!D16)/('Параметры'!C6-'Параметры'!C7)) | E37: =IF(ABS('Параметры'!C6-'Параметры'!C7)<1E-9,'Ввод данных'!E16/(1+'Параметры'!C6),(1-((1+'Параметры'!C7)/(1+'Параметры'!C6))^'Ввод данных'!E16)/('Параметры'!C6-'Параметры'!C7)) | F37: =IF(ABS('Параметры'!C6-'Параметры'!C7)<1E-9,'Ввод данных'!F16/(1+'Параметры'!C6),(1-((1+'Параметры'!C7)/(1+'Параметры'!C6))^'Ввод данных'!F16)/('Параметры'!C6-'Параметры'!C7))
B38: Коэф. аннуитета проекта (r, N) | C38: =IF('Параметры'!C6=0,'Ввод данных'!C16,(1-(1+'Параметры'!C6)^-'Ввод данных'!C16)/'Параметры'!C6) | D38: =IF('Параметры'!C6=0,'Ввод данных'!D16,(1-(1+'Параметры'!C6)^-'Ввод данных'!D16)/'Параметры'!C6) | E38: =IF('Параметры'!C6=0,'Ввод данных'!E16,(1-(1+'Параметры'!C6)^-'Ввод данных'!E16)/'Параметры'!C6) | F38: =IF('Параметры'!C6=0,'Ввод данных'!F16,(1-(1+'Параметры'!C6)^-'Ввод данных'!F16)/'Параметры'!C6)
B39: Коэф. аннуитета кредита (r, срок) | C39: =IF('Параметры'!C6=0,'Ввод данных'!C28,(1-(1+'Параметры'!C6)^-'Ввод данных'!C28)/'Параметры'!C6) | D39: =IF('Параметры'!C6=0,'Ввод данных'!D28,(1-(1+'Параметры'!C6)^-'Ввод данных'!D28)/'Параметры'!C6) | E39: =IF('Параметры'!C6=0,'Ввод данных'!E28,(1-(1+'Параметры'!C6)^-'Ввод данных'!E28)/'Параметры'!C6) | F39: =IF('Параметры'!C6=0,'Ввод данных'!F28,(1-(1+'Параметры'!C6)^-'Ввод данных'!F28)/'Параметры'!C6)
B40: Дисконт остаточной стоимости | C40: =1/(1+'Параметры'!C6)^'Ввод данных'!C16 | D40: =1/(1+'Параметры'!C6)^'Ввод данных'!D16 | E40: =1/(1+'Параметры'!C6)^'Ввод данных'!E16 | F40: =1/(1+'Параметры'!C6)^'Ввод данных'!F16
B41: ДИСКОНТИРОВАННЫЕ ЗАТРАТЫ (NPV, текущая стоимость)
...

Sheet Сравнение
B1: СРАВНИТЕЛЬНЫЙ АНАЛИЗ ВАРИАНТОВ ОБОРУДОВАНИЯ
B2: Итоговый дашборд. Зелёным выделен лучший вариант по удельному TCO на тонну.
B4: Показатель | C4: ='Ввод данных'!C7 | D4: ='Ввод данных'!D7 | E4: ='Ввод данных'!E7 | F4: ='Ввод данных'!F7 | G4: Ед.
B5: Цена приобретения | C5: ='Ввод данных'!C22 | D5: ='Ввод данных'!D22 | E5: ='Ввод данных'!E22 | F5: ='Ввод данных'!F22
B6: Первоначальные инвестиции (CAPEX) | C6: ='Расчёт TCO'!C26 | D6: ='Расчёт TCO'!D26 | E6: ='Расчёт TCO'!E26 | F6: ='Расчёт TCO'!F26
B7: Годовые эксплуатац. затраты (год 1) | C7: ='Расчёт TCO'!C19 | D7: ='Расчёт TCO'!D19 | E7: ='Расчёт TCO'!E19 | F7: ='Расчёт TCO'!F19 | G7: /год
B8: Годовой объём производства | C8: ='Расчёт TCO'!C7 | D8: ='Расчёт TCO'!D7 | E8: ='Расчёт TCO'!E7 | F8: ='Расчёт TCO'!F7 | G8: т/год
B9: Полный объём за срок службы | C9: ='Расчёт TCO'!C8 | D9: ='Расчёт TCO'!D8 | E9: ='Расчёт TCO'!E8 | F9: ='Расчёт TCO'!F8 | G9: т
B10: TCO — совокупная стоимость (NPV) | C10: ='Расчёт TCO'!C49 | D10: ='Расчёт TCO'!D49 | E10: ='Расчёт TCO'!E49 | F10: ='Расчёт TCO'!F49
B11: TCO — совокупные затраты (номинал) | C11: ='Расчёт TCO'!C56 | D11: ='Расчёт TCO'!D56 | E11: ='Расчёт TCO'!E56 | F11: ='Расчёт TCO'!F56
B12: EAC — эквивалентная годовая стоим. | C12: ='Расчёт TCO'!C59 | D12: ='Расчёт TCO'!D59 | E12: ='Расчёт TCO'!E59 | F12: ='Расчёт TCO'!F59 | G12: /год
B13: Удельный TCO на мото-час | C13: ='Расчёт TCO'!C60 | D13: ='Расчёт TCO'!D60 | E13: ='Расчёт TCO'!E60 | F13: ='Расчёт TCO'!F60 | G13: /мото-ч
B14: Удельный TCO на тонну | C14: ='Расчёт TCO'!C62 | D14: ='Расчёт TCO'!D62 | E14: ='Расчёт TCO'!E62 | F14: ='Расчёт TCO'!F62 | G14: /т
B15: Доля CAPEX в TCO | C15: ='Расчёт TCO'!C63 | D15: ='Расчёт TCO'!D63 | E15: ='Расчёт TCO'!E63 | F15: ='Расчёт TCO'!F63 | G15: %
B16: Доля эксплуатации в TCO | C16: ='Расчёт TCO'!C64 | D16: ='Расчёт TCO'!D64 | E16: ='Расчёт TCO'!E64 | F16: ='Расчёт TCO'!F64 | G16: %
B17: ИТОГОВАЯ ОЦЕНКА (критерий: минимум удельного TCO на тонну)
B18: Место в рейтинге | C18: =RANK(C14,C14:F14,1) | D18: =RANK(D14,C14:F14,1) | E18: =RANK(E14,C14:F14,1) | F18: =RANK(F14,C14:F14,1)
B19: Отклонение от лучшего, % | C19: =C14/MIN(C14:F14)-1 | D19: =D14/MIN(C14:F14)-1 | E19: =E14/MIN(C14:F14)-1 | F19: =F14/MIN(C14:F14)-1
B21: РЕКОМЕНДУЕМЫЙ ВАРИАНТ: | C21: =INDEX(C4:F4,MATCH(MIN(C14:F14),C14:F14,0))&" ("&TEXT(MIN(C14:F14),"0.00")&" /т)"
B23: СТРУКТУРА ЗАТРАТ TCO (NPV) ПО КАТЕГОРИЯМ
B24: Категория | C24: ='Ввод данных'!C7 | D24: ='Ввод данных'!D7 | E24: ='Ввод данных'!E7 | F24: ='Ввод данных'!F7
B25: Капитальные (за вычетом остат. ст-ти) | C25: ='Расчёт TCO'!C46+'Расчёт TCO'!C47-'Расчёт TCO'!C48 | D25: ='Расчёт TCO'!D46+'Расчёт TCO'!D47-'Расчёт TCO'!D48 | E25: ='Расчёт TCO'!E46+'Расчёт TCO'!E47-'Расчёт TCO'!E48 | F25: ='Расчёт TCO'!F46+'Расчёт TCO'!F47-'Расчёт TCO'!F48
B26: Энергия / топливо | C26: ='Расчёт TCO'!C42 | D26: ='Расчёт TCO'!D42 | E26: ='Расчёт TCO'!E42 | F26: ='Расчёт TCO'!F42
B27: Оплата труда | C27: ='Расчёт TCO'!C43 | D27: ='Расчёт TCO'!D43 | E27: ='Расчёт TCO'!E43 | F27: ='Расчёт TCO'!F43
B28: Запчасти и ТОиР | C28: ='Расчёт TCO'!C44 | D28: ='Расчёт TCO'!D44 | E28: ='Расчёт TCO'!E44 | F28: ='Расчёт TCO'!F44
B29: Постоянные (страхование, налоги) | C29: ='Расчёт TCO'!C45 | D29: ='Расчёт TCO'!D45 | E29: ='Расчёт TCO'!E45 | F29: ='Расчёт TCO'!F45
B30: ИТОГО TCO (NPV) | C30: =SUM(C25:C29) | D30: =SUM(D25:D29) | E30: =SUM(E25:E29) | F30: =SUM(F25:F29)

Sheet Чувствительность
B1: АНАЛИЗ ЧУВСТВИТЕЛЬНОСТИ
B2: Торнадо-анализ ключевых драйверов и чувствительность к утилизации.
B4: Анализируемый вариант (1–4): | C4: 1 | D4: =INDEX('Ввод данных'!C7:F7,$C$4)
B6: БАЗОВЫЕ ПОКАЗАТЕЛИ ВЫБРАННОГО ВАРИАНТА
B7: TCO (NPV) | C7: =INDEX('Расчёт TCO'!C49:F49,$C$4)
B8: EAC — эквивалентная годовая | C8: =INDEX('Расчёт TCO'!C59:F59,$C$4)
B9: Удельный TCO на тонну | C9: =INDEX('Расчёт TCO'!C62:F62,$C$4)
B10: Коэф. аннуитета (r, N) | C10: =INDEX('Расчёт TCO'!C38:F38,$C$4)
B11: Годовой объём производства, т | C11: =INDEX('Расчёт TCO'!C7:F7,$C$4)
B12: NPV энергии | C12: =INDEX('Расчёт TCO'!C42:F42,$C$4)
B13: NPV труда | C13: =INDEX('Расчёт TCO'!C43:F43,$C$4)
B14: NPV запчастей и ТОиР | C14: =INDEX('Расчёт TCO'!C44:F44,$C$4)
B15: NPV капитальных (нетто) | C15: =INDEX('Расчёт TCO'!C46:F46,$C$4)+INDEX('Расчёт TCO'!C47:F47,$C$4)-INDEX('Расчёт TCO'!C48:F48,$C$4)+INDEX('Расчёт TCO'!C45:F45,$C$4)
B16: NPV переменных (энергия+труд+ТОиР) | C16: =INDEX('Расчёт TCO'!C42:F42,$C$4)+INDEX('Расчёт TCO'!C43:F43,$C$4)+INDEX('Расчёт TCO'!C44:F44,$C$4)
B18: ТОРНАДО-АНАЛИЗ: ВЛИЯНИЕ ДРАЙВЕРОВ НА TCO (NPV)
B19: Драйвер | C19: Диапазон | D19: TCO при снижении | E19: TCO при росте | F19: Размах | G19: Влияние, % | I19: низкое, откл. | J19: высокое, откл.
B20: Цена топлива / энергии | C20: ±20% | D20: =$C$7-0.2*$C$12 | E20: =$C$7+0.2*$C$12 | F20: =E20-D20 | G20: =F20/$C$7 | I20: =D20-$C$7 | J20: =E20-$C$7
B21: Оплата труда | C21: ±15% | D21: =$C$7-0.15*$C$13 | E21: =$C$7+0.15*$C$13 | F21: =E21-D21 | G21: =F21/$C$7 | I21: =D21-$C$7 | J21: =E21-$C$7
B22: Затраты на ТОиР | C22: ±25% | D22: =$C$7-0.25*$C$14 | E22: =$C$7+0.25*$C$14 | F22: =E22-D22 | G22: =F22/$C$7 | I22: =D22-$C$7 | J22: =E22-$C$7
B23: Цена приобретения | C23: ±15% | D23: =$C$7-0.15*$C$15 | E23: =$C$7+0.15*$C$15 | F23: =E23-D23 | G23: =F23/$C$7 | I23: =D23-$C$7 | J23: =E23-$C$7
B26: ЧУВСТВИТЕЛЬНОСТЬ К УТИЛИЗАЦИИ (НАРАБОТКЕ)
B27: Изменение наработки | C27: -15% | D27: -10% | E27: 0% | F27: +10% | G27: +15%
B28: TCO (NPV) | C28: =($C$7-$C$16)+$C$16*(1+-0.15) | D28: =($C$7-$C$16)+$C$16*(1+-0.1) | E28: =($C$7-$C$16)+$C$16*(1+0.0) | F28: =($C$7-$C$16)+$C$16*(1+0.1) | G28: =($C$7-$C$16)+$C$16*(1+0.15)
B29: Удельный TCO на тонну | C29: =(C28/$C$10)/($C$11*(1+-0.15)) | D29: =(D28/$C$10)/($C$11*(1+-0.1)) | E29: =(E28/$C$10)/($C$11*(1+0.0)) | F29: =(F28/$C$10)/($C$11*(1+0.1)) | G29: =(G28/$C$10)/($C$11*(1+0.15))
B31: Примечание: рост наработки распределяет постоянные затраты на больший объём — удельный TCO на тонну снижается (эффект масштаба использования).

Sheet Справочник
B1: СПРАВОЧНИК ОРИЕНТИРОВОЧНЫХ ЗНАЧЕНИЙ
B2: Диапазоны для проверки исходных данных. Требуют уточнения по данным поставщика/эксплуатации.
B4: Класс оборудования | C4: Мощность, кВт | D4: Расход топлива, л/мото-ч | E4: Ресурс ходовой/шин, мото-ч | F4: Плановое ТО, /мото-ч | G4: Периодич. капрем., мото-ч | H4: Ресурс до списания, мото-ч | I4: Коэф. готовности | J4: Остат. ст-ть, %
B5: Карьерный самосвал (90–100 т) | C5: 750–900 | D5: 45–75 | E5: 5 000–7 000 (шины) | F5: 12–22 | G5: 18 000–24 000 | H5: 60 000–90 000 | I5: 80–88% | J5: 10–18%
B6: Карьерный самосвал (220 т+) | C6: 1 800–2 700 | D6: 180–280 | E6: 6 000–9 000 (шины) | F6: 22–40 | G6: 18 000–24 000 | H6: 60 000–100 000 | I6: 82–90% | J6: 12–20%
B7: Гидравлический экскаватор ~250 т | C7: 1 300–1 700 | D7: 260–340 | E7: 12 000–18 000 (ход.) | F7: 30–50 | G7: 18 000–24 000 | H7: 60 000–90 000 | I7: 80–88% | J7: 10–16%
B8: Электрический канатный экскав. | C8: 2 000–4 500 | D8: (электро) | E8: 40 000–60 000 (ход.) | F8: 25–45 | G8: 40 000–60 000 | H8: 120 000–200 000 | I8: 85–92% | J8: 8–15%
B9: Колёсный погрузчик (10–15 м³) | C9: 500–900 | D9: 60–110 | E9: 4 000–6 000 (шины) | F9: 18–32 | G9: 16 000–20 000 | H9: 50 000–70 000 | I9: 80–88% | J9: 12–20%
B10: Бульдозер (крупный, 60–100 т) | C10: 400–700 | D10: 40–70 | E10: 8 000–12 000 (ход.) | F10: 20–35 | G10: 15 000–20 000 | H10: 45 000–70 000 | I10: 78–86% | J10: 10–18%
B11: Буровой станок (шарошечный) | C11: 400–900 | D11: 50–90 | E11: — | F11: 20–40 | G11: 18 000–24 000 | H11: 60 000–90 000 | I11: 80–88% | J11: 10–18%
B13: Методические примечания:
B14: • Смазочные материалы: обычно 8–15% от стоимости топлива.
B15: • Оплата труда: закладывается «полная» ставка (налоги, СИЗ, обучение, накладные, подмена).
B16: • Эскалация: цена топлива и ФОТ, как правило, растут быстрее общей инфляции.
B17: • Ставка дисконтирования = WACC компании (обычно 8–15% в реальном или номинальном выражении — согласуйте с эскалацией).
B18: • Капремонты (rebuild) двигателя/гидравлики/трансмиссии учитываются как аннуитизированные затраты по наработке.
B19: • Значения таблицы — ориентир для проверки порядка величин, а не норматив.
