Workbook

Sheet Методика
B1: МЕТОДИКА: АННУИТЕТ ЗАТРАТ (РУБ/ТКМ) НА ВЛАДЕНИЕ АВТОСАМОСВАЛАМИ
B2: Пост-налоговый погодовой дисконтированный аннуитет жизненного цикла.
C4: 1. НАЗНАЧЕНИЕ
C5: Экономическое сравнение карьерных автосамосвалов одного класса по удельному аннуитету затрат (руб/ткм грузооборота, а также руб/т перевезённой массы) за полный срок эксплуатации. Метрика корректно сопоставляет самосвалы с разной ценой, грузоподъёмностью и производительностью. Лучший вариант — минимум руб/ткм.
C6: 2. ПРОИЗВОДИТЕЛЬНОСТЬ (транспортный цикл из файла «Производительность»)
C7: Время рейса = (подход + погрузка + разгрузка + прочее) + время движения; время движения = 2 × плечо / скорость × 60 (гружёный + порожний ход). Рейсов/час = 60 / время рейса. Часовая производительность (т/эфф.час) = рейсов/час × грузоподъёмность × КИГ. КИО = КТГ × (1 − простои_смены/(60 × смена)); эффективное время = КФВ × КИО. Годовой объём (тыс.т) = часовая × эффективное время; грузооборот (тыс.ткм) = объём × плечо; пробег = рейсы × 2 × плечо.
C8: 3. ПОГОДОВОЙ ДЕНЕЖНЫЙ ПОТОК (10 лет)
C9: Для каждого года считаются: топливо (грузооборот × г/ткм × цена), ТОиР и сервис (задаются ПО ГОДАМ на листах «Поставщик N» — ТО, текущие и капитальные ремонты; годы капремонтов дают всплеск затрат), шины (пробег × удельный расход × цена), персонал, транспортный налог. Добавляются амортизация (НУ) и налог на прибыль (щит). Операционный поток = база + налог − амортизация. Инвестиции — в год 0, остаточная стоимость — в конце срока.
C10: 4. АННУИТЕТ (ЯДРО)
C11: Потоки дисконтируются и преобразуются в эквивалентный годовой платёж: Аннуитет = NPV затрат / Σ(дисконт-факторов). Инвестиционный аннуитет = (Цена − дисконт. остаточная стоимость) / Σ(дисконт-факторов). Операционный аннуитет — приведённые эксплуатационные затраты после налога. Общий = инвестиционный + операционный. Удельный аннуитет (руб/ткм) = общий аннуитет / средний годовой грузооборот; руб/т = руб/ткм × плечо.
C12: 5. ПОРЯДОК РАБОТЫ
C13: «Параметры» → «Ввод данных» (цена, грузоподъёмность, мощность двигателя, персонал) → листы «Поставщик 1…6»: по каждой машине задаются КТГ, простои и затраты ТОиР по годам — КТГ и ИТОГО ТОиР считаются автоматически. Сводка «Данные по годам» тянет итоги сама → авторасчёт «Производительность», «Денежный поток», «Расчёт аннуитета» → «Дашборд», «Сравнение», «Аналитика», «Чувствительность». Правки — в листах «Поставщик N» и «Ввод данных».
C14: 6. ДОПУЩЕНИЯ
C15: • Самосвалы сравниваются в одном классе и одной задаче; разница в производительности учтена через руб/ткм и руб/т.
... C22: зелёные ячейки — итоговые показатели / лучший вариант

Sheet Дашборд
B1: ИТОГОВЫЙ ДАШБОРД — СРАВНЕНИЕ АВТОСАМОСВАЛОВ
B2: ВЕРСИЯ «ДАННЫЕ ПРОИЗВОДСТВА» (паспорт завода: срок 8–20 лет, факт. КТГ, дифф. ТОиР). Ключевые показатели и графики; данные обновляются автоматически.
B4: КЛЮЧЕВЫЕ ПОКАЗАТЕЛИ
B5: Лучший вариант | C5: Мин. аннуитет, руб/ткм | D5: Мин. NPV владения, тыс.руб | E5: Разброс аннуитета, руб/ткм
B6: =INDEX('Ввод данных'!D7:I7,MATCH(MIN('Расчёт аннуитета'!D26:I26),'Расчёт аннуитета'!D26:I26,0)) -> NHL NTE 240 | C6: =MIN('Расчёт аннуитета'!D26:I26) -> 10.495818 | D6: =MIN('Расчёт аннуитета'!D14:I14) -> 813813.98 | E6: =MAX('Расчёт аннуитета'!D26:I26)-MIN('Расчёт аннуитета'!D26:I26) -> 4.777154
B8: РЕЙТИНГ ПО УДЕЛЬНОМУ АННУИТЕТУ (руб/ткм)
B9: Место | C9: Автосамосвал | G9: руб/ткм | I9: руб/т
B10: 1 | C10: =INDEX('Ввод данных'!D7:I7,MATCH(SMALL('Расчёт аннуитета'!D26:I26,1),'Расчёт аннуитета'!D26:I26,0)) -> NHL NTE 240 | G10: =SMALL('Расчёт аннуитета'!D26:I26,1) -> 10.495818 | I10: =INDEX('Расчёт аннуитета'!$D$28:$I$28,MATCH(SMALL('Расчёт аннуитета'!D26:I26,1),'Расчёт аннуитета'!D26:I26,0)) -> 50.411413
B11: 2 | C11: =INDEX('Ввод данных'!D7:I7,MATCH(SMALL('Расчёт аннуитета'!D26:I26,2),'Расчёт аннуитета'!D26:I26,0)) -> SANY SET240S | G11: =SMALL('Расчёт аннуитета'!D26:I26,2) -> 11.980934 | I11: =INDEX('Расчёт аннуитета'!$D$28:$I$28,MATCH(SMALL('Расчёт аннуитета'!D26:I26,2),'Расчёт аннуитета'!D26:I26,0)) -> 52.5963
B12: 3 | C12: =INDEX('Ввод данных'!D7:I7,MATCH(SMALL('Расчёт аннуитета'!D26:I26,3),'Расчёт аннуитета'!D26:I26,0)) -> БелАЗ 7531 (ГПФК) | G12: =SMALL('Расчёт аннуитета'!D26:I26,3) -> 12.352308 | I12: =INDEX('Расчёт аннуитета'!$D$28:$I$28,MATCH(SMALL('Расчёт аннуитета'!D26:I26,3),'Расчёт аннуитета'!D26:I26,0)) -> 52.546718
B13: 4 | C13: =INDEX('Ввод данных'!D7:I7,MATCH(SMALL('Расчёт аннуитета'!D26:I26,4),'Расчёт аннуитета'!D26:I26,0)) -> БелАЗ 7531 (БТЛ) | G13: =SMALL('Расчёт аннуитета'!D26:I26,4) -> 12.366911 | I13: =INDEX('Расчёт аннуитета'!$D$28:$I$28,MATCH(SMALL('Расчёт аннуитета'!D26:I26,4),'Расчёт аннуитета'!D26:I26,0)) -> 52.60884
B14: 5 | C14: =INDEX('Ввод данных'!D7:I7,MATCH(SMALL('Расчёт аннуитета'!D26:I26,5),'Расчёт аннуитета'!D26:I26,0)) -> TZCO TZE240 | G14: =SMALL('Расчёт аннуитета'!D26:I26,5) -> 15.220258 | I14: =INDEX('Расчёт аннуитета'!$D$28:$I$28,MATCH(SMALL('Расчёт аннуитета'!D26:I26,5),'Расчёт аннуитета'!D26:I26,0)) -> 61.992109
B15: 6 | C15: =INDEX('Ввод данных'!D7:I7,MATCH(SMALL('Расчёт аннуитета'!D26:I26,6),'Расчёт аннуитета'!D26:I26,0)) -> Estar ESDE240 (ГПБ К) | G15: =SMALL('Расчёт аннуитета'!D26:I26,6) -> 15.272972 | I15: =INDEX('Расчёт аннуитета'!$D$28:$I$28,MATCH(SMALL('Расчёт аннуитета'!D26:I26,6),'Расчёт аннуитета'!D26:I26,0)) -> 64.955949

Sheet Параметры
B1: ГЛОБАЛЬНЫЕ ПАРАМЕТРЫ МОДЕЛИ
B2: Единые допущения для всех вариантов. Жёлтые ячейки — ввод.
B4: Финансовые допущения
B5: Параметр | C5: Значение | D5: Ед. | E5: Комментарий
B6: Ставка дисконтирования (WACC) | C6: 0.12 | D6: %/год | E6: Стоимость капитала для приведения к текущей стоимости
B7: Налог на прибыль | C7: 0.25 | D7: % | E7: Формирует налоговый щит на затраты и амортизацию
B8: Срок эксплуатации (горизонт) | C8: 10 | D8: лет | E8: Фиксирован = 10 лет в погодовом движке
B9: Срок амортизации (налоговый учёт) | C9: 5.083 | D9: лет | E9: Линейная; 61 мес ≈ 5,08 года
B10: Цена дизельного топлива | C10: 66.019 | D10: тыс.руб/т | E10: СЛ 2025: 1 274 749,9 тыс.руб / 19 308,86 т
B12: Эскалация цен (реальный/номинальный рост)
B13: Параметр | C13: Значение | D13: Ед. | E13: Комментарий
B14: Эскалация цены топлива | C14: 0 | D14: %/год | E14: 0 = данные уже с учётом инфляции
B15: Эскалация ЗЧ/шин/расходников | C15: 0 | D15: %/год | E15: ТОиР задаётся по годам напрямую
B16: Эскалация оплаты труда | C16: 0 | D16: %/год | E16: Рост ФОТ экипажей
B18: Курсы валют
B19: Параметр | C19: Значение | D19: Ед. | E19: Комментарий
B20: Курс юаня (CNY) | C20: 12.7702 | D20: руб | E20: Для оборудования из Китая
B21: Курс доллара (USD) | C21: 94.0485 | D21: руб
B22: Курс евро (EUR) | C22: 100 | D22: руб
B24: Параметры производительности (транспортный цикл)
B25: Параметр | C25: Значение | D25: Ед. | E25: Комментарий
B26: Календарный фонд времени | C26: 8760 | D26: час/год | E26: 24 ч × 365 дн
B27: Длительность смены | C27: 12 | D27: час | E27: Для пересчёта простоев
B28: Расстояние транспортировки (плечо) | C28: 3.0396 | D28: км | E28: Среднее плечо откатки (гружёный ход)
B29: Средняя техническая скорость | C29: 22.46 | D29: км/час | E29: С учётом профиля трассы
B30: КИГ (использование грузоподъёмности) | C30: 0.9837 | D30: коэф. | E30: Доля номинальной грузоподъёмности (факт NTE)
B31: Фикс. время рейса (подход+погр+разгр+прочее) | C31: 8.4 | D31: мин | E31: Подход/погрузка/разгрузка 7,9 + прочие 0,5
B32: Удельный расход топлива | C32: 78.4 | D32: г/ткм | E32: На тонно-километр грузооборота
B34: Шины
B35: Параметр | C35: Значение | D35: Ед. | E35: Комментарий
B36: Удельный расход шин | C36: 0.0563 | D36: шт./тыс.км | E36: Комплект/износ на пробег
B37: Цена шины | C37: 2985.38 | D37: тыс.руб/шт | E37: DDP, без НДС (типоразмер 50/80R57 и аналоги)
B39: Транспортный налог и персонал
B40: Параметр | C40: Значение | D40: Ед. | E40: Комментарий
B41: Ставка транспортного налога | C41: 85 | D41: руб/л.с. | E41: Иркутская область
B43: Расчётные финансовые коэффициенты
B44: Параметр | C44: Значение | D44: Ед. | E44: Комментарий
B45: Коэф. аннуитета Σдиск.факторов (r, N) | C45: =IF('Параметры'!C6=0,'Параметры'!C8,(1-(1+'Параметры'!C6)^-'Параметры'!C8)/'Параметры'!C6) -> 5.650223 | D45: коэф. | E45: Сумма дисконт-факторов за срок службы
B46: Коэф. приведённой амортизации | C46: =(1/'Параметры'!C9)*((1-(1+'Параметры'!C6)^-INT('Параметры'!C9))/'Параметры'!C6+('Параметры'!C9-INT('Параметры'!C9))*(1+'Параметры'!C6)^-(INT('Параметры'!C9)+1)) -> 0.71745555 | D46: коэф. | E46: Приведённая амортизация на 1 руб. цены (налог. щит)
B48: Легенда: | D48: — ввод данных
...

Sheet Ввод данных
B1: ВВОД ИСХОДНЫХ ДАННЫХ ПО АВТОСАМОСВАЛАМ
B2: Сравнение до 6 машин одного класса. Пример: самосвалы класса 220–240 т, карьер «Сухой Лог».
B4: Показатель | C4: Ед. | D4: Самосвал 1 | E4: Самосвал 2 | F4: Самосвал 3 | G4: Самосвал 4 | H4: Самосвал 5 | I4: Самосвал 6 | K4: Пояснение
B6: A. ИДЕНТИФИКАЦИЯ
B7: Наименование / модель | C7: — | D7: NHL NTE 240 | E7: Estar ESDE240 (ГПБ К) | F7: SANY SET240S | G7: TZCO TZE240 | H7: БелАЗ 7531 (ГПФК) | I7: БелАЗ 7531 (БТЛ) | K7: Название варианта
B8: Поставщик | C8: — | D8: Горная Евразия | E8: ГПБ | F8: ИСТК | G8: ИСТК | H8: ГПФК | I8: БТЛ
B9: Двигатель / привод | C9: — | D9: электро (2500 л.с.) | E9: 1864 л.с. | F9: 2843 л.с. | G9: 2500 л.с. | H9: 2535 л.с. | I9: 2535 л.с.
B10: B. СТОИМОСТЬ И ОСТАТОЧНАЯ ЦЕНА
B11: Цена за единицу | C11: тыс.вал. | D11: 312568.63 | E11: 319027.49 | F11: 296085.09 | G11: 302883.56 | H11: 287367.57 | I11: 287367.58 | K11: ⚠ В файле поставщика цена не указана — ОЦЕНКА, уточнить
B12: Валюта цены | C12: — | D12: RUB | E12: RUB | F12: RUB | G12: RUB | H12: RUB | I12: RUB | K12: CNY / USD / EUR / RUB
B13: Доставка, ПНР, шеф-монтаж | C13: тыс.руб | D13: 0 | E13: 0 | F13: 0 | G13: 0 | H13: 0 | I13: 0 | K13: Дополнительно к цене
B14: Остаточная стоимость | C14: % от цены | D14: 0 | E14: 0 | F14: 0 | G14: 0 | H14: 0 | I14: 0 | K14: Реализация в конце срока (0 = не учитывать)
B15: Срок службы (завод-изготовитель) | C15: лет | D15: 20 | E15: 10 | F15: 12 | G15: 8 | H15: 10 | I15: 10 | K15: Инвестиц. аннуитет (EAC) считается по этому сроку; влияет на чувствительность
B16: C. ПРОИЗВОДИТЕЛЬНОСТЬ
B17: Грузоподъёмность (в расчёте) | C17: т | D17: 227.8 | E17: 211.392 | F17: 216.362 | G17: 222 | H17: 226.5 | I17: 226.5 | K17: × КИГ (лист «Параметры») = фактическая загрузка
B18: Эффективное плечо откатки (за срок службы) | C18: км | D18: 4.803 | E18: 4.253 | F18: 4.39 | G18: 4.073 | H18: 4.254 | I18: 4.254 | K18: Средневзвешенное по годам плечо за срок службы машины
B19: D. ПРОЧИЕ ГОДОВЫЕ ЗАТРАТЫ И ПАРАМЕТРЫ
B20: Расходы на персонал (экипаж) | C20: тыс.руб/год | D20: 18475.6 | E20: 18475.6 | F20: 18475.6 | G20: 18475.6 | H20: 18475.6 | I20: 18475.6 | K20: ФОТ+отчисления+прочее на 1 машину
B21: Мощность двигателя (транспортный налог) | C21: л.с. | D21: 2500 | E21: 2500 | F21: 2843 | G21: 2500 | H21: 2535 | I21: 2535 | K21: × ставку налога (руб/л.с.)
B22: ℹ КТГ, простои и затраты на ТОиР (ТО/ТР/капремонты/сервис) задаются ПО ГОДАМ на листах «Поставщик 1…6». Расход топлива (г/ткм), шины и КИГ — общие на листе «Параметры». Сводка — на листе «Данные по годам».

Sheet Поставщик 1
B1: ДАННЫЕ ПОСТАВЩИКА — ВАРИАНТ 1 (ТО и Ремонты — модель по узлам)
B2: Жёлтое — ввод. Зелёное — авто (снизу вверх). ИТОГО ТОиР = (ЗЧ ТО + ЗЧ капремонтов + сервис) × коэф.калибровки; тянется в «Данные по годам».
B4: Автосамосвал: | E4: ='Ввод данных'!D7 -> NHL NTE 240
B5: Валюта затрат ТОиР: | D5: CNY
B6: Показатель | C6: Ед. | E6: год 1 | F6: год 2 | G6: год 3 | H6: год 4 | I6: год 5 | J6: год 6 | K6: год 7 | L6: год 8 | M6: год 9 | N6: год 10
B7: СВОДКА ПО ГОДАМ (зелёное — авто снизу вверх; тянется в расчёт)
B8: Простои на ТО (авто из интервалов) | C8: ч/год | E8: =E37 -> 337.148 | F8: =F37 -> 337.148 | G8: =G37 -> 337.148 | H8: =H37 -> 337.148 | I8: =I37 -> 337.148 | J8: =J37 -> 337.148 | K8: =K37 -> 337.148 | L8: =L37 -> 337.148 | ... N8: =N37 -> 337.148
B9: Простои в ремонтах (справочно) | C9: ч/год | E9: 139 | F9: 175 | G9: 289 | H9: 373 | I9: 177 | J9: 253 | K9: 167 | L9: 377 | M9: 295 | N9: 187
B10: Ежесменный осмотр (20 мин/смену), справочно | C10: ч/год | E10: =('Параметры'!C26-E8-E9)/'Параметры'!C27*20/60 -> 230.107 | F10: =('Параметры'!C26-F8-F9)/'Параметры'!C27*20/60 -> 229.107 | G10: =('Параметры'!C26-G8-G9)/'Параметры'!C27*20/60 -> 225.94033 | H10: =('Параметры'!C26-H8-H9)/'Параметры'!C27*20/60 -> 223.607 | I10: =('Параметры'!C26-I8-I9)/'Параметры'!C27*20/60 -> 229.05144 | J10: =('Параметры'!C26-J8-J9)/'Параметры'!C27*20/60 -> 226.94033 | K10: =('Параметры'!C26-K8-K9)/'Параметры'!C27*20/60 -> 229.32922 | L10: =('Параметры'!C26-L8-L9)/'Параметры'!C27*20/60 -> 223.49589 | M10: =('Параметры'!C26-M8-M9)/'Параметры'!C27*20/60 -> 225.77367 | N10: =('Параметры'!C26-N8-N9)/'Параметры'!C27*20/60 -> 228.77367
B11: КТГ (техготовность, ВВОД) → «Данные по годам» | C11: коэф. | E11: 0.9331 | F11: 0.926 | G11: 0.9165 | H11: 0.9041 | I11: 0.9289 | J11: 0.9173 | K11: 0.9269 | L11: 0.9068 | M11: 0.9127 | N11: 0.9278
B12: Затраты на ЗЧ ТО (авто из каталога) | C12: тыс.вал/г | E12: =E73 -> 615.85391 | F12: =F73 -> 615.85391 | G12: =G73 -> 615.85391 | H12: =H73 -> 615.85391 | I12: =I73 -> 615.85391 | J12: =J73 -> 615.85391 | K12: =K73 -> 615.85391 | L12: =L73 -> 615.85391 | ... N12: =N73 -> 615.85391
B13: Затраты на ЗЧ капремонтов (авто по ресурсу) | C13: тыс.вал/г | E13: =E96 -> 0 | F13: =F96 -> 151.6104 | G13: =G96 -> 3293.5408 | H13: =H96 -> 894.48203 | I13: =I96 -> 99.85674 | J13: =J96 -> 3353.1664 | K13: =K96 -> 47.96174 | L13: =L96 -> 938.50503 | ... N13: =N96 -> 151.6104
B14: Трудозатраты ТО (авто) | C14: ч-час/г | E14: =E44 -> 1281.392 | F14: =F44 -> 1281.392 | G14: =G44 -> 1281.392 | H14: =H44 -> 1281.392 | I14: =I44 -> 1281.392 | J14: =J44 -> 1281.392 | K14: =K44 -> 1281.392 | L14: =L44 -> 1281.392 | ... N14: =N44 -> 1281.392
B15: Трудозатраты капремонтов (авто) | C15: ч-час/г | E15: =E119 -> 0 | F15: =F119 -> 472 | G15: =G119 -> 1020 | H15: =H119 -> 1038 | I15: =I119 -> 482 | J15: =J119 -> 1020 | K15: =K119 -> 20 | L15: =L119 -> 1490 | ... N15: =N119 -> 472
B16: Сервис (трудозатраты) ТО+капремонты | C16: тыс.вал/г | E16: =(E14+E15)*$E$21/1000 -> 244.74587 | F16: =(F14+F15)*$E$21/1000 -> 334.89787 | G16: =(G14+G15)*$E$21/1000 -> 439.56587 | H16: =(H14+H15)*$E$21/1000 -> 443.00387 | I16: =(I14+I15)*$E$21/1000 -> 336.80787 | J16: =(J14+J15)*$E$21/1000 -> 439.56587 | K16: =(K14+K15)*$E$21/1000 -> 248.56587 | L16: =(L14+L15)*$E$21/1000 -> 529.33587 | ... N16: =(N14+N15)*$E$21/1000 -> 334.89787
B17: Коэффициент калибровки ИТОГО под ТКП | C17: коэф. | E17: 1.2755
B18: ИТОГО ТОиР → «Данные по годам» | C18: тыс.вал/г | E18: =(E12+E13+E16)*$E$17 -> 1097.695 | F18: =(F12+F13+F16)*$E$17 -> 1406.063 | G18: =(G12+G13+G16)*$E$17 -> 5547.0992 | H18: =(H12+H13+H16)*$E$17 -> 2491.4849 | I18: =(I12+I13+I16)*$E$17 -> 1342.4874 | J18: =(J12+J13+J16)*$E$17 -> 5623.1517 | K18: =(K12+K13+K16)*$E$17 -> 1163.7426 | L18: =(L12+L13+L16)*$E$17 -> 2657.7527 | ... N18: =(N12+N13+N16)*$E$17 -> 1406.063
B20: РАСЧЁТ ТО (по интервалам обслуживания), ПО ГОДАМ
B21: Ставка сервиса | C21: вал/ч·час | E21: 191
B22: Наработка по годам | C22: м/час | E22: 7000 | F22: 7000 | G22: 7000 | H22: 7000 | I22: 7000 | J22: 7000 | K22: 7000 | L22: 7000 | M22: 7000 | N22: 7000
B23: Вид ТО | C23: интервал, м/ч | D23: простой/ТО, ч | E23: персонал
B24: ТО-1 | C24: 250 | D24: 2.4 | E24: 3
B25: ТО-2 | C25: 500 | D25: 8.332 | E25: 4
B26: ТО-3 | C26: 1000 | D26: 9.68 | E26: 4
B27: ТО-4 | C27: 2000 | D27: 11.28 | E27: 4
B28: ТО-5 | C28: 5000 | D28: 18.6 | E28: 4
B29: ТО-6 | C29: 10000 | D29: 28.6 | E29: 4
B31: ТО-1: простои, ч/год | C31: ч | E31: =E$22/$C24*$D24 -> 67.2 | F31: =F$22/$C24*$D24 -> 67.2 | G31: =G$22/$C24*$D24 -> 67.2 | H31: =H$22/$C24*$D24 -> 67.2 | I31: =I$22/$C24*$D24 -> 67.2 | J31: =J$22/$C24*$D24 -> 67.2 | K31: =K$22/$C24*$D24 -> 67.2 | L31: =L$22/$C24*$D24 -> 67.2 | ... N31: =N$22/$C24*$D24 -> 67.2
B32: ТО-2: простои, ч/год | C32: ч | E32: =E$22/$C25*$D25 -> 116.648 | F32: =F$22/$C25*$D25 -> 116.648 | G32: =G$22/$C25*$D25 -> 116.648 | H32: =H$22/$C25*$D25 -> 116.648 | I32: =I$22/$C25*$D25 -> 116.648 | J32: =J$22/$C25*$D25 -> 116.648 | K32: =K$22/$C25*$D25 -> 116.648 | L32: =L$22/$C25*$D25 -> 116.648 | ... N32: =N$22/$C25*$D25 -> 116.648
B33: ТО-3: простои, ч/год | C33: ч | E33: =E$22/$C26*$D26 -> 67.76 | F33: =F$22/$C26*$D26 -> 67.76 | G33: =G$22/$C26*$D26 -> 67.76 | H33: =H$22/$C26*$D26 -> 67.76 | I33: =I$22/$C26*$D26 -> 67.76 | J33: =J$22/$C26*$D26 -> 67.76 | K33: =K$22/$C26*$D26 -> 67.76 | L33: =L$22/$C26*$D26 -> 67.76 | ... N33: =N$22/$C26*$D26 -> 67.76
B34: ТО-4: простои, ч/год | C34: ч | E34: =E$22/$C27*$D27 -> 39.48 | F34: =F$22/$C27*$D27 -> 39.48 | G34: =G$22/$C27*$D27 -> 39.48 | H34: =H$22/$C27*$D27 -> 39.48 | I34: =I$22/$C27*$D27 -> 39.48 | J34: =J$22/$C27*$D27 -> 39.48 | K34: =K$22/$C27*$D27 -> 39.48 | L34: =L$22/$C27*$D27 -> 39.48 | ... N34: =N$22/$C27*$D27 -> 39.48
B35: ТО-5: простои, ч/год | C35: ч | E35: =E$22/$C28*$D28 -> 26.04 | F35: =F$22/$C28*$D28 -> 26.04 | G35: =G$22/$C28*$D28 -> 26.04 | H35: =H$22/$C28*$D28 -> 26.04 | I35: =I$22/$C28*$D28 -> 26.04 | J35: =J$22/$C28*$D28 -> 26.04 | K35: =K$22/$C28*$D28 -> 26.04 | L35: =L$22/$C28*$D28 -> 26.04 | ... N35: =N$22/$C28*$D28 -> 26.04
B36: ТО-6: простои, ч/год | C36: ч | E36: =E$22/$C29*$D29 -> 20.02 | F36: =F$22/$C29*$D29 -> 20.02 | G36: =G$22/$C29*$D29 -> 20.02 | H36: =H$22/$C29*$D29 -> 20.02 | I36: =I$22/$C29*$D29 -> 20.02 | J36: =J$22/$C29*$D29 -> 20.02 | K36: =K$22/$C29*$D29 -> 20.02 | L36: =L$22/$C29*$D29 -> 20.02 | ... N36: =N$22/$C29*$D29 -> 20.02
B37: Итого простои ТО | E37: =SUM(E31:E36) -> 337.148 | F37: =SUM(F31:F36) -> 337.148 | G37: =SUM(G31:G36) -> 337.148 | H37: =SUM(H31:H36) -> 337.148 | I37: =SUM(I31:I36) -> 337.148 | J37: =SUM(J31:J36) -> 337.148 | K37: =SUM(K31:K36) -> 337.148 | L37: =SUM(L31:L36) -> 337.148 | ... N37: =SUM(N31:N36) -> 337.148
B38: ТО-1: чел-часы/год | C38: ч-час | E38: =E31*$E24 -> 201.6 | F38: =F31*$E24 -> 201.6 | G38: =G31*$E24 -> 201.6 | H38: =H31*$E24 -> 201.6 | I38: =I31*$E24 -> 201.6 | J38: =J31*$E24 -> 201.6 | K38: =K31*$E24 -> 201.6 | L38: =L31*$E24 -> 201.6 | ... N38: =N31*$E24 -> 201.6
B39: ТО-2: чел-часы/год | C39: ч-час | E39: =E32*$E25 -> 466.592 | F39: =F32*$E25 -> 466.592 | G39: =G32*$E25 -> 466.592 | H39: =H32*$E25 -> 466.592 | I39: =I32*$E25 -> 466.592 | J39: =J32*$E25 -> 466.592 | K39: =K32*$E25 -> 466.592 | L39: =L32*$E25 -> 466.592 | ... N39: =N32*$E25 -> 466.592
B40: ТО-3: чел-часы/год | C40: ч-час | E40: =E33*$E26 -> 271.04 | F40: =F33*$E26 -> 271.04 | G40: =G33*$E26 -> 271.04 | H40: =H33*$E26 -> 271.04 | I40: =I33*$E26 -> 271.04 | J40: =J33*$E26 -> 271.04 | K40: =K33*$E26 -> 271.04 | L40: =L33*$E26 -> 271.04 | ... N40: =N33*$E26 -> 271.04
B41: ТО-4: чел-часы/год | C41: ч-час | E41: =E34*$E27 -> 157.92 | F41: =F34*$E27 -> 157.92 | G41: =G34*$E27 -> 157.92 | H41: =H34*$E27 -> 157.92 | I41: =I34*$E27 -> 157.92 | J41: =J34*$E27 -> 157.92 | K41: =K34*$E27 -> 157.92 | L41: =L34*$E27 -> 157.92 | ... N41: =N34*$E27 -> 157.92
B42: ТО-5: чел-часы/год | C42: ч-час | E42: =E35*$E28 -> 104.16 | F42: =F35*$E28 -> 104.16 | G42: =G35*$E28 -> 104.16 | H42: =H35*$E28 -> 104.16 | I42: =I35*$E28 -> 104.16 | J42: =J35*$E28 -> 104.16 | K42: =K35*$E28 -> 104.16 | L42: =L35*$E28 -> 104.16 | ... N42: =N35*$E28 -> 104.16
B43: ТО-6: чел-часы/год | C43: ч-час | E43: =E36*$E29 -> 80.08 | F43: =F36*$E29 -> 80.08 | G43: =G36*$E29 -> 80.08 | H43: =H36*$E29 -> 80.08 | I43: =I36*$E29 -> 80.08 | J43: =J36*$E29 -> 80.08 | K43: =K36*$E29 -> 80.08 | L43: =L36*$E29 -> 80.08 | ... N43: =N36*$E29 -> 80.08
...

Sheet Поставщик 2
B1: ДАННЫЕ ПОСТАВЩИКА — ВАРИАНТ 2 (ТО и Ремонты — модель по узлам)
B2: Жёлтое — ввод. Зелёное — авто (снизу вверх). ИТОГО ТОиР = (ЗЧ ТО + ЗЧ капремонтов + сервис) × коэф.калибровки; тянется в «Данные по годам».
B4: Автосамосвал: | E4: ='Ввод данных'!E7 -> Estar ESDE240 (ГПБ К)
B5: Валюта затрат ТОиР: | D5: CNY
B6: Показатель | C6: Ед. | E6: год 1 | F6: год 2 | G6: год 3 | H6: год 4 | I6: год 5 | J6: год 6 | K6: год 7 | L6: год 8 | M6: год 9 | N6: год 10
B7: СВОДКА ПО ГОДАМ (зелёное — авто снизу вверх; тянется в расчёт)
B8: Простои на ТО (авто из интервалов) | C8: ч/год | E8: =E37 -> 337.148 | F8: =F37 -> 337.148 | G8: =G37 -> 337.148 | H8: =H37 -> 337.148 | I8: =I37 -> 337.148 | J8: =J37 -> 337.148 | K8: =K37 -> 337.148 | L8: =L37 -> 337.148 | ... N8: =N37 -> 337.148
B9: Простои в ремонтах (справочно) | C9: ч/год | E9: 420 | F9: 505 | G9: 905 | H9: 1287 | I9: 455 | J9: 1132 | K9: 485 | L9: 1290 | M9: 782 | N9: 1155
B10: Ежесменный осмотр (20 мин/смену), справочно | C10: ч/год | E10: =('Параметры'!C26-E8-E9)/'Параметры'!C27*20/60 -> 222.30144 | F10: =('Параметры'!C26-F8-F9)/'Параметры'!C27*20/60 -> 219.94033 | G10: =('Параметры'!C26-G8-G9)/'Параметры'!C27*20/60 -> 208.82922 | H10: =('Параметры'!C26-H8-H9)/'Параметры'!C27*20/60 -> 198.21811 | I10: =('Параметры'!C26-I8-I9)/'Параметры'!C27*20/60 -> 221.32922 | J10: =('Параметры'!C26-J8-J9)/'Параметры'!C27*20/60 -> 202.52367 | K10: =('Параметры'!C26-K8-K9)/'Параметры'!C27*20/60 -> 220.49589 | L10: =('Параметры'!C26-L8-L9)/'Параметры'!C27*20/60 -> 198.13478 | M10: =('Параметры'!C26-M8-M9)/'Параметры'!C27*20/60 -> 212.24589 | N10: =('Параметры'!C26-N8-N9)/'Параметры'!C27*20/60 -> 201.88478
B11: КТГ (техготовность, ВВОД) → «Данные по годам» | C11: коэф. | E11: 0.9145 | F11: 0.8984 | G11: 0.852 | H11: 0.8085 | I11: 0.9018 | J11: 0.8247 | K11: 0.8914 | L11: 0.8132 | M11: 0.8589 | N11: 0.8366
B12: Затраты на ЗЧ ТО (авто из каталога) | C12: тыс.вал/г | E12: =E73 -> 615.85391 | F12: =F73 -> 615.85391 | G12: =G73 -> 615.85391 | H12: =H73 -> 615.85391 | I12: =I73 -> 615.85391 | J12: =J73 -> 615.85391 | K12: =K73 -> 615.85391 | L12: =L73 -> 615.85391 | ... N12: =N73 -> 615.85391
B13: Затраты на ЗЧ капремонтов (авто по ресурсу) | C13: тыс.вал/г | E13: =E96 -> 0 | F13: =F96 -> 151.6104 | G13: =G96 -> 3293.5408 | H13: =H96 -> 894.48203 | I13: =I96 -> 99.85674 | J13: =J96 -> 3353.1664 | K13: =K96 -> 47.96174 | L13: =L96 -> 938.50503 | ... N13: =N96 -> 151.6104
B14: Трудозатраты ТО (авто) | C14: ч-час/г | E14: =E44 -> 1281.392 | F14: =F44 -> 1281.392 | G14: =G44 -> 1281.392 | H14: =H44 -> 1281.392 | I14: =I44 -> 1281.392 | J14: =J44 -> 1281.392 | K14: =K44 -> 1281.392 | L14: =L44 -> 1281.392 | ... N14: =N44 -> 1281.392
B15: Трудозатраты капремонтов (авто) | C15: ч-час/г | E15: =E119 -> 0 | F15: =F119 -> 472 | G15: =G119 -> 1020 | H15: =H119 -> 1038 | I15: =I119 -> 482 | J15: =J119 -> 1020 | K15: =K119 -> 20 | L15: =L119 -> 1490 | ... N15: =N119 -> 472
B16: Сервис (трудозатраты) ТО+капремонты | C16: тыс.вал/г | E16: =(E14+E15)*$E$21/1000 -> 244.74587 | F16: =(F14+F15)*$E$21/1000 -> 334.89787 | G16: =(G14+G15)*$E$21/1000 -> 439.56587 | H16: =(H14+H15)*$E$21/1000 -> 443.00387 | I16: =(I14+I15)*$E$21/1000 -> 336.80787 | J16: =(J14+J15)*$E$21/1000 -> 439.56587 | K16: =(K14+K15)*$E$21/1000 -> 248.56587 | L16: =(L14+L15)*$E$21/1000 -> 529.33587 | ... N16: =(N14+N15)*$E$21/1000 -> 334.89787
B17: Коэффициент калибровки ИТОГО под ТКП | C17: коэф. | E17: 2.528
B18: ИТОГО ТОиР → «Данные по годам» | C18: тыс.вал/г | E18: =(E12+E13+E16)*$E$17 -> 2175.5962 | F18: =(F12+F13+F16)*$E$17 -> 2786.7716 | G18: =(G12+G13+G16)*$E$17 -> 10994.172 | H18: =(H12+H13+H16)*$E$17 -> 4938.043 | I18: =(I12+I13+I16)*$E$17 -> 2660.7668 | J18: =(J12+J13+J16)*$E$17 -> 11144.906 | K18: =(K12+K13+K16)*$E$17 -> 2306.5005 | L18: =(L12+L13+L16)*$E$17 -> 5267.5805 | ... N18: =(N12+N13+N16)*$E$17 -> 2786.7716
B20: РАСЧЁТ ТО (по интервалам обслуживания), ПО ГОДАМ
B21: Ставка сервиса | C21: вал/ч·час | E21: 191
B22: Наработка по годам | C22: м/час | E22: 7000 | F22: 7000 | G22: 7000 | H22: 7000 | I22: 7000 | J22: 7000 | K22: 7000 | L22: 7000 | M22: 7000 | N22: 7000
B23: Вид ТО | C23: интервал, м/ч | D23: простой/ТО, ч | E23: персонал
B24: ТО-1 | C24: 250 | D24: 2.4 | E24: 3
B25: ТО-2 | C25: 500 | D25: 8.332 | E25: 4
B26: ТО-3 | C26: 1000 | D26: 9.68 | E26: 4
B27: ТО-4 | C27: 2000 | D27: 11.28 | E27: 4
B28: ТО-5 | C28: 5000 | D28: 18.6 | E28: 4
B29: ТО-6 | C29: 10000 | D29: 28.6 | E29: 4
B31: ТО-1: простои, ч/год | C31: ч | E31: =E$22/$C24*$D24 -> 67.2 | F31: =F$22/$C24*$D24 -> 67.2 | G31: =G$22/$C24*$D24 -> 67.2 | H31: =H$22/$C24*$D24 -> 67.2 | I31: =I$22/$C24*$D24 -> 67.2 | J31: =J$22/$C24*$D24 -> 67.2 | K31: =K$22/$C24*$D24 -> 67.2 | L31: =L$22/$C24*$D24 -> 67.2 | ... N31: =N$22/$C24*$D24 -> 67.2
B32: ТО-2: простои, ч/год | C32: ч | E32: =E$22/$C25*$D25 -> 116.648 | F32: =F$22/$C25*$D25 -> 116.648 | G32: =G$22/$C25*$D25 -> 116.648 | H32: =H$22/$C25*$D25 -> 116.648 | I32: =I$22/$C25*$D25 -> 116.648 | J32: =J$22/$C25*$D25 -> 116.648 | K32: =K$22/$C25*$D25 -> 116.648 | L32: =L$22/$C25*$D25 -> 116.648 | ... N32: =N$22/$C25*$D25 -> 116.648
B33: ТО-3: простои, ч/год | C33: ч | E33: =E$22/$C26*$D26 -> 67.76 | F33: =F$22/$C26*$D26 -> 67.76 | G33: =G$22/$C26*$D26 -> 67.76 | H33: =H$22/$C26*$D26 -> 67.76 | I33: =I$22/$C26*$D26 -> 67.76 | J33: =J$22/$C26*$D26 -> 67.76 | K33: =K$22/$C26*$D26 -> 67.76 | L33: =L$22/$C26*$D26 -> 67.76 | ... N33: =N$22/$C26*$D26 -> 67.76
B34: ТО-4: простои, ч/год | C34: ч | E34: =E$22/$C27*$D27 -> 39.48 | F34: =F$22/$C27*$D27 -> 39.48 | G34: =G$22/$C27*$D27 -> 39.48 | H34: =H$22/$C27*$D27 -> 39.48 | I34: =I$22/$C27*$D27 -> 39.48 | J34: =J$22/$C27*$D27 -> 39.48 | K34: =K$22/$C27*$D27 -> 39.48 | L34: =L$22/$C27*$D27 -> 39.48 | ... N34: =N$22/$C27*$D27 -> 39.48
B35: ТО-5: простои, ч/год | C35: ч | E35: =E$22/$C28*$D28 -> 26.04 | F35: =F$22/$C28*$D28 -> 26.04 | G35: =G$22/$C28*$D28 -> 26.04 | H35: =H$22/$C28*$D28 -> 26.04 | I35: =I$22/$C28*$D28 -> 26.04 | J35: =J$22/$C28*$D28 -> 26.04 | K35: =K$22/$C28*$D28 -> 26.04 | L35: =L$22/$C28*$D28 -> 26.04 | ... N35: =N$22/$C28*$D28 -> 26.04
B36: ТО-6: простои, ч/год | C36: ч | E36: =E$22/$C29*$D29 -> 20.02 | F36: =F$22/$C29*$D29 -> 20.02 | G36: =G$22/$C29*$D29 -> 20.02 | H36: =H$22/$C29*$D29 -> 20.02 | I36: =I$22/$C29*$D29 -> 20.02 | J36: =J$22/$C29*$D29 -> 20.02 | K36: =K$22/$C29*$D29 -> 20.02 | L36: =L$22/$C29*$D29 -> 20.02 | ... N36: =N$22/$C29*$D29 -> 20.02
B37: Итого простои ТО | E37: =SUM(E31:E36) -> 337.148 | F37: =SUM(F31:F36) -> 337.148 | G37: =SUM(G31:G36) -> 337.148 | H37: =SUM(H31:H36) -> 337.148 | I37: =SUM(I31:I36) -> 337.148 | J37: =SUM(J31:J36) -> 337.148 | K37: =SUM(K31:K36) -> 337.148 | L37: =SUM(L31:L36) -> 337.148 | ... N37: =SUM(N31:N36) -> 337.148
B38: ТО-1: чел-часы/год | C38: ч-час | E38: =E31*$E24 -> 201.6 | F38: =F31*$E24 -> 201.6 | G38: =G31*$E24 -> 201.6 | H38: =H31*$E24 -> 201.6 | I38: =I31*$E24 -> 201.6 | J38: =J31*$E24 -> 201.6 | K38: =K31*$E24 -> 201.6 | L38: =L31*$E24 -> 201.6 | ... N38: =N31*$E24 -> 201.6
B39: ТО-2: чел-часы/год | C39: ч-час | E39: =E32*$E25 -> 466.592 | F39: =F32*$E25 -> 466.592 | G39: =G32*$E25 -> 466.592 | H39: =H32*$E25 -> 466.592 | I39: =I32*$E25 -> 466.592 | J39: =J32*$E25 -> 466.592 | K39: =K32*$E25 -> 466.592 | L39: =L32*$E25 -> 466.592 | ... N39: =N32*$E25 -> 466.592
B40: ТО-3: чел-часы/год | C40: ч-час | E40: =E33*$E26 -> 271.04 | F40: =F33*$E26 -> 271.04 | G40: =G33*$E26 -> 271.04 | H40: =H33*$E26 -> 271.04 | I40: =I33*$E26 -> 271.04 | J40: =J33*$E26 -> 271.04 | K40: =K33*$E26 -> 271.04 | L40: =L33*$E26 -> 271.04 | ... N40: =N33*$E26 -> 271.04
B41: ТО-4: чел-часы/год | C41: ч-час | E41: =E34*$E27 -> 157.92 | F41: =F34*$E27 -> 157.92 | G41: =G34*$E27 -> 157.92 | H41: =H34*$E27 -> 157.92 | I41: =I34*$E27 -> 157.92 | J41: =J34*$E27 -> 157.92 | K41: =K34*$E27 -> 157.92 | L41: =L34*$E27 -> 157.92 | ... N41: =N34*$E27 -> 157.92
B42: ТО-5: чел-часы/год | C42: ч-час | E42: =E35*$E28 -> 104.16 | F42: =F35*$E28 -> 104.16 | G42: =G35*$E28 -> 104.16 | H42: =H35*$E28 -> 104.16 | I42: =I35*$E28 -> 104.16 | J42: =J35*$E28 -> 104.16 | K42: =K35*$E28 -> 104.16 | L42: =L35*$E28 -> 104.16 | ... N42: =N35*$E28 -> 104.16
B43: ТО-6: чел-часы/год | C43: ч-час | E43: =E36*$E29 -> 80.08 | F43: =F36*$E29 -> 80.08 | G43: =G36*$E29 -> 80.08 | H43: =H36*$E29 -> 80.08 | I43: =I36*$E29 -> 80.08 | J43: =J36*$E29 -> 80.08 | K43: =K36*$E29 -> 80.08 | L43: =L36*$E29 -> 80.08 | ... N43: =N36*$E29 -> 80.08
...

Sheet Поставщик 3
B1: ДАННЫЕ ПОСТАВЩИКА — ВАРИАНТ 3 (ТО и Ремонты — модель по узлам)
B2: Жёлтое — ввод. Зелёное — авто (снизу вверх). ИТОГО ТОиР = (ЗЧ ТО + ЗЧ капремонтов + сервис) × коэф.калибровки; тянется в «Данные по годам».
B4: Автосамосвал: | E4: ='Ввод данных'!F7 -> SANY SET240S
B5: Валюта затрат ТОиР: | D5: CNY
B6: Показатель | C6: Ед. | E6: год 1 | F6: год 2 | G6: год 3 | H6: год 4 | I6: год 5 | J6: год 6 | K6: год 7 | L6: год 8 | M6: год 9 | N6: год 10
B7: СВОДКА ПО ГОДАМ (зелёное — авто снизу вверх; тянется в расчёт)
B8: Простои на ТО (авто из интервалов) | C8: ч/год | E8: =E37 -> 337.148 | F8: =F37 -> 337.148 | G8: =G37 -> 337.148 | H8: =H37 -> 337.148 | I8: =I37 -> 337.148 | J8: =J37 -> 337.148 | K8: =K37 -> 337.148 | L8: =L37 -> 337.148 | ... N8: =N37 -> 337.148
B9: Простои в ремонтах (справочно) | C9: ч/год | E9: 280 | F9: 570 | G9: 750 | H9: 505 | I9: 930 | J9: 505 | K9: 750 | L9: 505 | M9: 930 | N9: 660
B10: Ежесменный осмотр (20 мин/смену), справочно | C10: ч/год | E10: =('Параметры'!C26-E8-E9)/'Параметры'!C27*20/60 -> 226.19033 | F10: =('Параметры'!C26-F8-F9)/'Параметры'!C27*20/60 -> 218.13478 | G10: =('Параметры'!C26-G8-G9)/'Параметры'!C27*20/60 -> 213.13478 | H10: =('Параметры'!C26-H8-H9)/'Параметры'!C27*20/60 -> 219.94033 | I10: =('Параметры'!C26-I8-I9)/'Параметры'!C27*20/60 -> 208.13478 | J10: =('Параметры'!C26-J8-J9)/'Параметры'!C27*20/60 -> 219.94033 | K10: =('Параметры'!C26-K8-K9)/'Параметры'!C27*20/60 -> 213.13478 | L10: =('Параметры'!C26-L8-L9)/'Параметры'!C27*20/60 -> 219.94033 | M10: =('Параметры'!C26-M8-M9)/'Параметры'!C27*20/60 -> 208.13478 | N10: =('Параметры'!C26-N8-N9)/'Параметры'!C27*20/60 -> 215.63478
B11: КТГ (техготовность, ВВОД) → «Данные по годам» | C11: коэф. | E11: 0.9286 | F11: 0.8958 | G11: 0.8593 | H11: 0.8972 | I11: 0.8436 | J11: 0.8972 | K11: 0.8593 | L11: 0.8972 | M11: 0.8436 | N11: 0.8783
B12: Затраты на ЗЧ ТО (авто из каталога) | C12: тыс.вал/г | E12: =E73 -> 615.85391 | F12: =F73 -> 615.85391 | G12: =G73 -> 615.85391 | H12: =H73 -> 615.85391 | I12: =I73 -> 615.85391 | J12: =J73 -> 615.85391 | K12: =K73 -> 615.85391 | L12: =L73 -> 615.85391 | ... N12: =N73 -> 615.85391
B13: Затраты на ЗЧ капремонтов (авто по ресурсу) | C13: тыс.вал/г | E13: =E96 -> 0 | F13: =F96 -> 151.6104 | G13: =G96 -> 3293.5408 | H13: =H96 -> 894.48203 | I13: =I96 -> 99.85674 | J13: =J96 -> 3353.1664 | K13: =K96 -> 47.96174 | L13: =L96 -> 938.50503 | ... N13: =N96 -> 151.6104
B14: Трудозатраты ТО (авто) | C14: ч-час/г | E14: =E44 -> 1281.392 | F14: =F44 -> 1281.392 | G14: =G44 -> 1281.392 | H14: =H44 -> 1281.392 | I14: =I44 -> 1281.392 | J14: =J44 -> 1281.392 | K14: =K44 -> 1281.392 | L14: =L44 -> 1281.392 | ... N14: =N44 -> 1281.392
B15: Трудозатраты капремонтов (авто) | C15: ч-час/г | E15: =E119 -> 0 | F15: =F119 -> 472 | G15: =G119 -> 1020 | H15: =H119 -> 1038 | I15: =I119 -> 482 | J15: =J119 -> 1020 | K15: =K119 -> 20 | L15: =L119 -> 1490 | ... N15: =N119 -> 472
B16: Сервис (трудозатраты) ТО+капремонты | C16: тыс.вал/г | E16: =(E14+E15)*$E$21/1000 -> 244.74587 | F16: =(F14+F15)*$E$21/1000 -> 334.89787 | G16: =(G14+G15)*$E$21/1000 -> 439.56587 | H16: =(H14+H15)*$E$21/1000 -> 443.00387 | I16: =(I14+I15)*$E$21/1000 -> 336.80787 | J16: =(J14+J15)*$E$21/1000 -> 439.56587 | K16: =(K14+K15)*$E$21/1000 -> 248.56587 | L16: =(L14+L15)*$E$21/1000 -> 529.33587 | ... N16: =(N14+N15)*$E$21/1000 -> 334.89787
B17: Коэффициент калибровки ИТОГО под ТКП | C17: коэф. | E17: 1.3644
B18: ИТОГО ТОиР → «Данные по годам» | C18: тыс.вал/г | E18: =(E12+E13+E16)*$E$17 -> 1174.2023 | F18: =(F12+F13+F16)*$E$17 -> 1504.063 | G18: =(G12+G13+G16)*$E$17 -> 5933.7218 | H18: =(H12+H13+H16)*$E$17 -> 2665.1368 | I18: =(I12+I13+I16)*$E$17 -> 1436.0563 | J18: =(J12+J13+J16)*$E$17 -> 6015.075 | K18: =(K12+K13+K16)*$E$17 -> 1244.8533 | L18: =(L12+L13+L16)*$E$17 -> 2842.9932 | ... N18: =(N12+N13+N16)*$E$17 -> 1504.063
B20: РАСЧЁТ ТО (по интервалам обслуживания), ПО ГОДАМ
B21: Ставка сервиса | C21: вал/ч·час | E21: 191
B22: Наработка по годам | C22: м/час | E22: 7000 | F22: 7000 | G22: 7000 | H22: 7000 | I22: 7000 | J22: 7000 | K22: 7000 | L22: 7000 | M22: 7000 | N22: 7000
B23: Вид ТО | C23: интервал, м/ч | D23: простой/ТО, ч | E23: персонал
B24: ТО-1 | C24: 250 | D24: 2.4 | E24: 3
B25: ТО-2 | C25: 500 | D25: 8.332 | E25: 4
B26: ТО-3 | C26: 1000 | D26: 9.68 | E26: 4
B27: ТО-4 | C27: 2000 | D27: 11.28 | E27: 4
B28: ТО-5 | C28: 5000 | D28: 18.6 | E28: 4
B29: ТО-6 | C29: 10000 | D29: 28.6 | E29: 4
B31: ТО-1: простои, ч/год | C31: ч | E31: =E$22/$C24*$D24 -> 67.2 | F31: =F$22/$C24*$D24 -> 67.2 | G31: =G$22/$C24*$D24 -> 67.2 | H31: =H$22/$C24*$D24 -> 67.2 | I31: =I$22/$C24*$D24 -> 67.2 | J31: =J$22/$C24*$D24 -> 67.2 | K31: =K$22/$C24*$D24 -> 67.2 | L31: =L$22/$C24*$D24 -> 67.2 | ... N31: =N$22/$C24*$D24 -> 67.2
B32: ТО-2: простои, ч/год | C32: ч | E32: =E$22/$C25*$D25 -> 116.648 | F32: =F$22/$C25*$D25 -> 116.648 | G32: =G$22/$C25*$D25 -> 116.648 | H32: =H$22/$C25*$D25 -> 116.648 | I32: =I$22/$C25*$D25 -> 116.648 | J32: =J$22/$C25*$D25 -> 116.648 | K32: =K$22/$C25*$D25 -> 116.648 | L32: =L$22/$C25*$D25 -> 116.648 | ... N32: =N$22/$C25*$D25 -> 116.648
B33: ТО-3: простои, ч/год | C33: ч | E33: =E$22/$C26*$D26 -> 67.76 | F33: =F$22/$C26*$D26 -> 67.76 | G33: =G$22/$C26*$D26 -> 67.76 | H33: =H$22/$C26*$D26 -> 67.76 | I33: =I$22/$C26*$D26 -> 67.76 | J33: =J$22/$C26*$D26 -> 67.76 | K33: =K$22/$C26*$D26 -> 67.76 | L33: =L$22/$C26*$D26 -> 67.76 | ... N33: =N$22/$C26*$D26 -> 67.76
B34: ТО-4: простои, ч/год | C34: ч | E34: =E$22/$C27*$D27 -> 39.48 | F34: =F$22/$C27*$D27 -> 39.48 | G34: =G$22/$C27*$D27 -> 39.48 | H34: =H$22/$C27*$D27 -> 39.48 | I34: =I$22/$C27*$D27 -> 39.48 | J34: =J$22/$C27*$D27 -> 39.48 | K34: =K$22/$C27*$D27 -> 39.48 | L34: =L$22/$C27*$D27 -> 39.48 | ... N34: =N$22/$C27*$D27 -> 39.48
B35: ТО-5: простои, ч/год | C35: ч | E35: =E$22/$C28*$D28 -> 26.04 | F35: =F$22/$C28*$D28 -> 26.04 | G35: =G$22/$C28*$D28 -> 26.04 | H35: =H$22/$C28*$D28 -> 26.04 | I35: =I$22/$C28*$D28 -> 26.04 | J35: =J$22/$C28*$D28 -> 26.04 | K35: =K$22/$C28*$D28 -> 26.04 | L35: =L$22/$C28*$D28 -> 26.04 | ... N35: =N$22/$C28*$D28 -> 26.04
B36: ТО-6: простои, ч/год | C36: ч | E36: =E$22/$C29*$D29 -> 20.02 | F36: =F$22/$C29*$D29 -> 20.02 | G36: =G$22/$C29*$D29 -> 20.02 | H36: =H$22/$C29*$D29 -> 20.02 | I36: =I$22/$C29*$D29 -> 20.02 | J36: =J$22/$C29*$D29 -> 20.02 | K36: =K$22/$C29*$D29 -> 20.02 | L36: =L$22/$C29*$D29 -> 20.02 | ... N36: =N$22/$C29*$D29 -> 20.02
B37: Итого простои ТО | E37: =SUM(E31:E36) -> 337.148 | F37: =SUM(F31:F36) -> 337.148 | G37: =SUM(G31:G36) -> 337.148 | H37: =SUM(H31:H36) -> 337.148 | I37: =SUM(I31:I36) -> 337.148 | J37: =SUM(J31:J36) -> 337.148 | K37: =SUM(K31:K36) -> 337.148 | L37: =SUM(L31:L36) -> 337.148 | ... N37: =SUM(N31:N36) -> 337.148
B38: ТО-1: чел-часы/год | C38: ч-час | E38: =E31*$E24 -> 201.6 | F38: =F31*$E24 -> 201.6 | G38: =G31*$E24 -> 201.6 | H38: =H31*$E24 -> 201.6 | I38: =I31*$E24 -> 201.6 | J38: =J31*$E24 -> 201.6 | K38: =K31*$E24 -> 201.6 | L38: =L31*$E24 -> 201.6 | ... N38: =N31*$E24 -> 201.6
B39: ТО-2: чел-часы/год | C39: ч-час | E39: =E32*$E25 -> 466.592 | F39: =F32*$E25 -> 466.592 | G39: =G32*$E25 -> 466.592 | H39: =H32*$E25 -> 466.592 | I39: =I32*$E25 -> 466.592 | J39: =J32*$E25 -> 466.592 | K39: =K32*$E25 -> 466.592 | L39: =L32*$E25 -> 466.592 | ... N39: =N32*$E25 -> 466.592
B40: ТО-3: чел-часы/год | C40: ч-час | E40: =E33*$E26 -> 271.04 | F40: =F33*$E26 -> 271.04 | G40: =G33*$E26 -> 271.04 | H40: =H33*$E26 -> 271.04 | I40: =I33*$E26 -> 271.04 | J40: =J33*$E26 -> 271.04 | K40: =K33*$E26 -> 271.04 | L40: =L33*$E26 -> 271.04 | ... N40: =N33*$E26 -> 271.04
B41: ТО-4: чел-часы/год | C41: ч-час | E41: =E34*$E27 -> 157.92 | F41: =F34*$E27 -> 157.92 | G41: =G34*$E27 -> 157.92 | H41: =H34*$E27 -> 157.92 | I41: =I34*$E27 -> 157.92 | J41: =J34*$E27 -> 157.92 | K41: =K34*$E27 -> 157.92 | L41: =L34*$E27 -> 157.92 | ... N41: =N34*$E27 -> 157.92
B42: ТО-5: чел-часы/год | C42: ч-час | E42: =E35*$E28 -> 104.16 | F42: =F35*$E28 -> 104.16 | G42: =G35*$E28 -> 104.16 | H42: =H35*$E28 -> 104.16 | I42: =I35*$E28 -> 104.16 | J42: =J35*$E28 -> 104.16 | K42: =K35*$E28 -> 104.16 | L42: =L35*$E28 -> 104.16 | ... N42: =N35*$E28 -> 104.16
B43: ТО-6: чел-часы/год | C43: ч-час | E43: =E36*$E29 -> 80.08 | F43: =F36*$E29 -> 80.08 | G43: =G36*$E29 -> 80.08 | H43: =H36*$E29 -> 80.08 | I43: =I36*$E29 -> 80.08 | J43: =J36*$E29 -> 80.08 | K43: =K36*$E29 -> 80.08 | L43: =L36*$E29 -> 80.08 | ... N43: =N36*$E29 -> 80.08
...

Sheet Поставщик 4
B1: ДАННЫЕ ПОСТАВЩИКА — ВАРИАНТ 4 (ТО и Ремонты — модель по узлам)
B2: Жёлтое — ввод. Зелёное — авто (снизу вверх). ИТОГО ТОиР = (ЗЧ ТО + ЗЧ капремонтов + сервис) × коэф.калибровки; тянется в «Данные по годам».
B4: Автосамосвал: | E4: ='Ввод данных'!G7 -> TZCO TZE240
B5: Валюта затрат ТОиР: | D5: CNY
B6: Показатель | C6: Ед. | E6: год 1 | F6: год 2 | G6: год 3 | H6: год 4 | I6: год 5 | J6: год 6 | K6: год 7 | L6: год 8 | M6: год 9 | N6: год 10
B7: СВОДКА ПО ГОДАМ (зелёное — авто снизу вверх; тянется в расчёт)
B8: Простои на ТО (авто из интервалов) | C8: ч/год | E8: =E37 -> 337.148 | F8: =F37 -> 337.148 | G8: =G37 -> 337.148 | H8: =H37 -> 337.148 | I8: =I37 -> 337.148 | J8: =J37 -> 337.148 | K8: =K37 -> 337.148 | L8: =L37 -> 337.148 | ... N8: =N37 -> 337.148
B9: Простои в ремонтах (справочно) | C9: ч/год | E9: 425 | F9: 690 | G9: 1600 | H9: 690 | I9: 425 | J9: 1800 | K9: 425 | L9: 690 | M9: 425 | N9: 690
B10: Ежесменный осмотр (20 мин/смену), справочно | C10: ч/год | E10: =('Параметры'!C26-E8-E9)/'Параметры'!C27*20/60 -> 222.16256 | F10: =('Параметры'!C26-F8-F9)/'Параметры'!C27*20/60 -> 214.80144 | G10: =('Параметры'!C26-G8-G9)/'Параметры'!C27*20/60 -> 189.52367 | H10: =('Параметры'!C26-H8-H9)/'Параметры'!C27*20/60 -> 214.80144 | I10: =('Параметры'!C26-I8-I9)/'Параметры'!C27*20/60 -> 222.16256 | J10: =('Параметры'!C26-J8-J9)/'Параметры'!C27*20/60 -> 183.96811 | K10: =('Параметры'!C26-K8-K9)/'Параметры'!C27*20/60 -> 222.16256 | L10: =('Параметры'!C26-L8-L9)/'Параметры'!C27*20/60 -> 214.80144 | M10: =('Параметры'!C26-M8-M9)/'Параметры'!C27*20/60 -> 222.16256 | N10: =('Параметры'!C26-N8-N9)/'Параметры'!C27*20/60 -> 214.80144
B11: КТГ (техготовность, ВВОД) → «Данные по годам» | C11: коэф. | E11: 0.8994 | F11: 0.8743 | G11: 0.7653 | H11: 0.8743 | I11: 0.8994 | J11: 0.7396 | K11: 0.8994 | L11: 0.8743 | M11: 0.8994 | N11: 0.8743
B12: Затраты на ЗЧ ТО (авто из каталога) | C12: тыс.вал/г | E12: =E73 -> 615.85391 | F12: =F73 -> 615.85391 | G12: =G73 -> 615.85391 | H12: =H73 -> 615.85391 | I12: =I73 -> 615.85391 | J12: =J73 -> 615.85391 | K12: =K73 -> 615.85391 | L12: =L73 -> 615.85391 | ... N12: =N73 -> 615.85391
B13: Затраты на ЗЧ капремонтов (авто по ресурсу) | C13: тыс.вал/г | E13: =E96 -> 0 | F13: =F96 -> 151.6104 | G13: =G96 -> 3293.5408 | H13: =H96 -> 894.48203 | I13: =I96 -> 99.85674 | J13: =J96 -> 3353.1664 | K13: =K96 -> 47.96174 | L13: =L96 -> 938.50503 | ... N13: =N96 -> 151.6104
B14: Трудозатраты ТО (авто) | C14: ч-час/г | E14: =E44 -> 1281.392 | F14: =F44 -> 1281.392 | G14: =G44 -> 1281.392 | H14: =H44 -> 1281.392 | I14: =I44 -> 1281.392 | J14: =J44 -> 1281.392 | K14: =K44 -> 1281.392 | L14: =L44 -> 1281.392 | ... N14: =N44 -> 1281.392
B15: Трудозатраты капремонтов (авто) | C15: ч-час/г | E15: =E119 -> 0 | F15: =F119 -> 472 | G15: =G119 -> 1020 | H15: =H119 -> 1038 | I15: =I119 -> 482 | J15: =J119 -> 1020 | K15: =K119 -> 20 | L15: =L119 -> 1490 | ... N15: =N119 -> 472
B16: Сервис (трудозатраты) ТО+капремонты | C16: тыс.вал/г | E16: =(E14+E15)*$E$21/1000 -> 244.74587 | F16: =(F14+F15)*$E$21/1000 -> 334.89787 | G16: =(G14+G15)*$E$21/1000 -> 439.56587 | H16: =(H14+H15)*$E$21/1000 -> 443.00387 | I16: =(I14+I15)*$E$21/1000 -> 336.80787 | J16: =(J14+J15)*$E$21/1000 -> 439.56587 | K16: =(K14+K15)*$E$21/1000 -> 248.56587 | L16: =(L14+L15)*$E$21/1000 -> 529.33587 | ... N16: =(N14+N15)*$E$21/1000 -> 334.89787
B17: Коэффициент калибровки ИТОГО под ТКП | C17: коэф. | E17: 2.5162
B18: ИТОГО ТОиР → «Данные по годам» | C18: тыс.вал/г | E18: =(E12+E13+E16)*$E$17 -> 2165.4412 | F18: =(F12+F13+F16)*$E$17 -> 2773.7637 | G18: =(G12+G13+G16)*$E$17 -> 10942.855 | H18: =(H12+H13+H16)*$E$17 -> 4914.9936 | I18: =(I12+I13+I16)*$E$17 -> 2648.3471 | J18: =(J12+J13+J16)*$E$17 -> 11092.885 | K18: =(K12+K13+K16)*$E$17 -> 2295.7344 | L18: =(L12+L13+L16)*$E$17 -> 5242.9929 | ... N18: =(N12+N13+N16)*$E$17 -> 2773.7637
B20: РАСЧЁТ ТО (по интервалам обслуживания), ПО ГОДАМ
B21: Ставка сервиса | C21: вал/ч·час | E21: 191
B22: Наработка по годам | C22: м/час | E22: 7000 | F22: 7000 | G22: 7000 | H22: 7000 | I22: 7000 | J22: 7000 | K22: 7000 | L22: 7000 | M22: 7000 | N22: 7000
B23: Вид ТО | C23: интервал, м/ч | D23: простой/ТО, ч | E23: персонал
B24: ТО-1 | C24: 250 | D24: 2.4 | E24: 3
B25: ТО-2 | C25: 500 | D25: 8.332 | E25: 4
B26: ТО-3 | C26: 1000 | D26: 9.68 | E26: 4
B27: ТО-4 | C27: 2000 | D27: 11.28 | E27: 4
B28: ТО-5 | C28: 5000 | D28: 18.6 | E28: 4
B29: ТО-6 | C29: 10000 | D29: 28.6 | E29: 4
B31: ТО-1: простои, ч/год | C31: ч | E31: =E$22/$C24*$D24 -> 67.2 | F31: =F$22/$C24*$D24 -> 67.2 | G31: =G$22/$C24*$D24 -> 67.2 | H31: =H$22/$C24*$D24 -> 67.2 | I31: =I$22/$C24*$D24 -> 67.2 | J31: =J$22/$C24*$D24 -> 67.2 | K31: =K$22/$C24*$D24 -> 67.2 | L31: =L$22/$C24*$D24 -> 67.2 | ... N31: =N$22/$C24*$D24 -> 67.2
B32: ТО-2: простои, ч/год | C32: ч | E32: =E$22/$C25*$D25 -> 116.648 | F32: =F$22/$C25*$D25 -> 116.648 | G32: =G$22/$C25*$D25 -> 116.648 | H32: =H$22/$C25*$D25 -> 116.648 | I32: =I$22/$C25*$D25 -> 116.648 | J32: =J$22/$C25*$D25 -> 116.648 | K32: =K$22/$C25*$D25 -> 116.648 | L32: =L$22/$C25*$D25 -> 116.648 | ... N32: =N$22/$C25*$D25 -> 116.648
B33: ТО-3: простои, ч/год | C33: ч | E33: =E$22/$C26*$D26 -> 67.76 | F33: =F$22/$C26*$D26 -> 67.76 | G33: =G$22/$C26*$D26 -> 67.76 | H33: =H$22/$C26*$D26 -> 67.76 | I33: =I$22/$C26*$D26 -> 67.76 | J33: =J$22/$C26*$D26 -> 67.76 | K33: =K$22/$C26*$D26 -> 67.76 | L33: =L$22/$C26*$D26 -> 67.76 | ... N33: =N$22/$C26*$D26 -> 67.76
B34: ТО-4: простои, ч/год | C34: ч | E34: =E$22/$C27*$D27 -> 39.48 | F34: =F$22/$C27*$D27 -> 39.48 | G34: =G$22/$C27*$D27 -> 39.48 | H34: =H$22/$C27*$D27 -> 39.48 | I34: =I$22/$C27*$D27 -> 39.48 | J34: =J$22/$C27*$D27 -> 39.48 | K34: =K$22/$C27*$D27 -> 39.48 | L34: =L$22/$C27*$D27 -> 39.48 | ... N34: =N$22/$C27*$D27 -> 39.48
B35: ТО-5: простои, ч/год | C35: ч | E35: =E$22/$C28*$D28 -> 26.04 | F35: =F$22/$C28*$D28 -> 26.04 | G35: =G$22/$C28*$D28 -> 26.04 | H35: =H$22/$C28*$D28 -> 26.04 | I35: =I$22/$C28*$D28 -> 26.04 | J35: =J$22/$C28*$D28 -> 26.04 | K35: =K$22/$C28*$D28 -> 26.04 | L35: =L$22/$C28*$D28 -> 26.04 | ... N35: =N$22/$C28*$D28 -> 26.04
B36: ТО-6: простои, ч/год | C36: ч | E36: =E$22/$C29*$D29 -> 20.02 | F36: =F$22/$C29*$D29 -> 20.02 | G36: =G$22/$C29*$D29 -> 20.02 | H36: =H$22/$C29*$D29 -> 20.02 | I36: =I$22/$C29*$D29 -> 20.02 | J36: =J$22/$C29*$D29 -> 20.02 | K36: =K$22/$C29*$D29 -> 20.02 | L36: =L$22/$C29*$D29 -> 20.02 | ... N36: =N$22/$C29*$D29 -> 20.02
B37: Итого простои ТО | E37: =SUM(E31:E36) -> 337.148 | F37: =SUM(F31:F36) -> 337.148 | G37: =SUM(G31:G36) -> 337.148 | H37: =SUM(H31:H36) -> 337.148 | I37: =SUM(I31:I36) -> 337.148 | J37: =SUM(J31:J36) -> 337.148 | K37: =SUM(K31:K36) -> 337.148 | L37: =SUM(L31:L36) -> 337.148 | ... N37: =SUM(N31:N36) -> 337.148
B38: ТО-1: чел-часы/год | C38: ч-час | E38: =E31*$E24 -> 201.6 | F38: =F31*$E24 -> 201.6 | G38: =G31*$E24 -> 201.6 | H38: =H31*$E24 -> 201.6 | I38: =I31*$E24 -> 201.6 | J38: =J31*$E24 -> 201.6 | K38: =K31*$E24 -> 201.6 | L38: =L31*$E24 -> 201.6 | ... N38: =N31*$E24 -> 201.6
B39: ТО-2: чел-часы/год | C39: ч-час | E39: =E32*$E25 -> 466.592 | F39: =F32*$E25 -> 466.592 | G39: =G32*$E25 -> 466.592 | H39: =H32*$E25 -> 466.592 | I39: =I32*$E25 -> 466.592 | J39: =J32*$E25 -> 466.592 | K39: =K32*$E25 -> 466.592 | L39: =L32*$E25 -> 466.592 | ... N39: =N32*$E25 -> 466.592
B40: ТО-3: чел-часы/год | C40: ч-час | E40: =E33*$E26 -> 271.04 | F40: =F33*$E26 -> 271.04 | G40: =G33*$E26 -> 271.04 | H40: =H33*$E26 -> 271.04 | I40: =I33*$E26 -> 271.04 | J40: =J33*$E26 -> 271.04 | K40: =K33*$E26 -> 271.04 | L40: =L33*$E26 -> 271.04 | ... N40: =N33*$E26 -> 271.04
B41: ТО-4: чел-часы/год | C41: ч-час | E41: =E34*$E27 -> 157.92 | F41: =F34*$E27 -> 157.92 | G41: =G34*$E27 -> 157.92 | H41: =H34*$E27 -> 157.92 | I41: =I34*$E27 -> 157.92 | J41: =J34*$E27 -> 157.92 | K41: =K34*$E27 -> 157.92 | L41: =L34*$E27 -> 157.92 | ... N41: =N34*$E27 -> 157.92
B42: ТО-5: чел-часы/год | C42: ч-час | E42: =E35*$E28 -> 104.16 | F42: =F35*$E28 -> 104.16 | G42: =G35*$E28 -> 104.16 | H42: =H35*$E28 -> 104.16 | I42: =I35*$E28 -> 104.16 | J42: =J35*$E28 -> 104.16 | K42: =K35*$E28 -> 104.16 | L42: =L35*$E28 -> 104.16 | ... N42: =N35*$E28 -> 104.16
B43: ТО-6: чел-часы/год | C43: ч-час | E43: =E36*$E29 -> 80.08 | F43: =F36*$E29 -> 80.08 | G43: =G36*$E29 -> 80.08 | H43: =H36*$E29 -> 80.08 | I43: =I36*$E29 -> 80.08 | J43: =J36*$E29 -> 80.08 | K43: =K36*$E29 -> 80.08 | L43: =L36*$E29 -> 80.08 | ... N43: =N36*$E29 -> 80.08
...

Sheet Поставщик 5
B1: ДАННЫЕ ПОСТАВЩИКА — ВАРИАНТ 5 (ТО и Ремонты — модель по узлам)
B2: Жёлтое — ввод. Зелёное — авто (снизу вверх). ИТОГО ТОиР = (ЗЧ ТО + ЗЧ капремонтов + сервис) × коэф.калибровки; тянется в «Данные по годам».
B4: Автосамосвал: | E4: ='Ввод данных'!H7 -> БелАЗ 7531 (ГПФК)
B5: Валюта затрат ТОиР: | D5: CNY
B6: Показатель | C6: Ед. | E6: год 1 | F6: год 2 | G6: год 3 | H6: год 4 | I6: год 5 | J6: год 6 | K6: год 7 | L6: год 8 | M6: год 9 | N6: год 10
B7: СВОДКА ПО ГОДАМ (зелёное — авто снизу вверх; тянется в расчёт)
B8: Простои на ТО (авто из интервалов) | C8: ч/год | E8: =E37 -> 337.148 | F8: =F37 -> 337.148 | G8: =G37 -> 337.148 | H8: =H37 -> 337.148 | I8: =I37 -> 337.148 | J8: =J37 -> 337.148 | K8: =K37 -> 337.148 | L8: =L37 -> 337.148 | ... N8: =N37 -> 337.148
B9: Простои в ремонтах (справочно) | C9: ч/год | E9: 135 | F9: 341 | G9: 417.667 | H9: 588 | I9: 402 | J9: 680.333 | K9: 549 | L9: 487 | M9: 793 | N9: 842.333
B10: Ежесменный осмотр (20 мин/смену), справочно | C10: ч/год | E10: =('Параметры'!C26-E8-E9)/'Параметры'!C27*20/60 -> 230.21811 | F10: =('Параметры'!C26-F8-F9)/'Параметры'!C27*20/60 -> 224.49589 | G10: =('Параметры'!C26-G8-G9)/'Параметры'!C27*20/60 -> 222.36625 | H10: =('Параметры'!C26-H8-H9)/'Параметры'!C27*20/60 -> 217.63478 | I10: =('Параметры'!C26-I8-I9)/'Параметры'!C27*20/60 -> 222.80144 | J10: =('Параметры'!C26-J8-J9)/'Параметры'!C27*20/60 -> 215.06997 | K10: =('Параметры'!C26-K8-K9)/'Параметры'!C27*20/60 -> 218.71811 | L10: =('Параметры'!C26-L8-L9)/'Параметры'!C27*20/60 -> 220.44033 | M10: =('Параметры'!C26-M8-M9)/'Параметры'!C27*20/60 -> 211.94033 | N10: =('Параметры'!C26-N8-N9)/'Параметры'!C27*20/60 -> 210.56997
B11: КТГ (техготовность, ВВОД) → «Данные по годам» | C11: коэф. | E11: 0.9066 | F11: 0.8842 | G11: 0.863 | H11: 0.8732 | I11: 0.8797 | J11: 0.8448 | K11: 0.8955 | L11: 0.853 | M11: 0.8405 | N11: 0.8595
B12: Затраты на ЗЧ ТО (авто из каталога) | C12: тыс.вал/г | E12: =E73 -> 615.85391 | F12: =F73 -> 615.85391 | G12: =G73 -> 615.85391 | H12: =H73 -> 615.85391 | I12: =I73 -> 615.85391 | J12: =J73 -> 615.85391 | K12: =K73 -> 615.85391 | L12: =L73 -> 615.85391 | ... N12: =N73 -> 615.85391
B13: Затраты на ЗЧ капремонтов (авто по ресурсу) | C13: тыс.вал/г | E13: =E96 -> 0 | F13: =F96 -> 151.6104 | G13: =G96 -> 3293.5408 | H13: =H96 -> 894.48203 | I13: =I96 -> 99.85674 | J13: =J96 -> 3353.1664 | K13: =K96 -> 47.96174 | L13: =L96 -> 938.50503 | ... N13: =N96 -> 151.6104
B14: Трудозатраты ТО (авто) | C14: ч-час/г | E14: =E44 -> 1281.392 | F14: =F44 -> 1281.392 | G14: =G44 -> 1281.392 | H14: =H44 -> 1281.392 | I14: =I44 -> 1281.392 | J14: =J44 -> 1281.392 | K14: =K44 -> 1281.392 | L14: =L44 -> 1281.392 | ... N14: =N44 -> 1281.392
B15: Трудозатраты капремонтов (авто) | C15: ч-час/г | E15: =E119 -> 0 | F15: =F119 -> 472 | G15: =G119 -> 1020 | H15: =H119 -> 1038 | I15: =I119 -> 482 | J15: =J119 -> 1020 | K15: =K119 -> 20 | L15: =L119 -> 1490 | ... N15: =N119 -> 472
B16: Сервис (трудозатраты) ТО+капремонты | C16: тыс.вал/г | E16: =(E14+E15)*$E$21/1000 -> 244.74587 | F16: =(F14+F15)*$E$21/1000 -> 334.89787 | G16: =(G14+G15)*$E$21/1000 -> 439.56587 | H16: =(H14+H15)*$E$21/1000 -> 443.00387 | I16: =(I14+I15)*$E$21/1000 -> 336.80787 | J16: =(J14+J15)*$E$21/1000 -> 439.56587 | K16: =(K14+K15)*$E$21/1000 -> 248.56587 | L16: =(L14+L15)*$E$21/1000 -> 529.33587 | ... N16: =(N14+N15)*$E$21/1000 -> 334.89787
B17: Коэффициент калибровки ИТОГО под ТКП | C17: коэф. | E17: 1.554
B18: ИТОГО ТОиР → «Данные по годам» | C18: тыс.вал/г | E18: =(E12+E13+E16)*$E$17 -> 1337.3721 | F18: =(F12+F13+F16)*$E$17 -> 1713.0708 | G18: =(G12+G13+G16)*$E$17 -> 6758.2847 | H18: =(H12+H13+H16)*$E$17 -> 3035.4901 | I18: =(I12+I13+I16)*$E$17 -> 1635.6138 | J18: =(J12+J13+J16)*$E$17 -> 6850.943 | K18: =(K12+K13+K16)*$E$17 -> 1417.8409 | L18: =(L12+L13+L16)*$E$17 -> 3238.0617 | ... N18: =(N12+N13+N16)*$E$17 -> 1713.0708
B20: РАСЧЁТ ТО (по интервалам обслуживания), ПО ГОДАМ
B21: Ставка сервиса | C21: вал/ч·час | E21: 191
B22: Наработка по годам | C22: м/час | E22: 7000 | F22: 7000 | G22: 7000 | H22: 7000 | I22: 7000 | J22: 7000 | K22: 7000 | L22: 7000 | M22: 7000 | N22: 7000
B23: Вид ТО | C23: интервал, м/ч | D23: простой/ТО, ч | E23: персонал
B24: ТО-1 | C24: 250 | D24: 2.4 | E24: 3
B25: ТО-2 | C25: 500 | D25: 8.332 | E25: 4
B26: ТО-3 | C26: 1000 | D26: 9.68 | E26: 4
B27: ТО-4 | C27: 2000 | D27: 11.28 | E27: 4
B28: ТО-5 | C28: 5000 | D28: 18.6 | E28: 4
B29: ТО-6 | C29: 10000 | D29: 28.6 | E29: 4
B31: ТО-1: простои, ч/год | C31: ч | E31: =E$22/$C24*$D24 -> 67.2 | F31: =F$22/$C24*$D24 -> 67.2 | G31: =G$22/$C24*$D24 -> 67.2 | H31: =H$22/$C24*$D24 -> 67.2 | I31: =I$22/$C24*$D24 -> 67.2 | J31: =J$22/$C24*$D24 -> 67.2 | K31: =K$22/$C24*$D24 -> 67.2 | L31: =L$22/$C24*$D24 -> 67.2 | ... N31: =N$22/$C24*$D24 -> 67.2
B32: ТО-2: простои, ч/год | C32: ч | E32: =E$22/$C25*$D25 -> 116.648 | F32: =F$22/$C25*$D25 -> 116.648 | G32: =G$22/$C25*$D25 -> 116.648 | H32: =H$22/$C25*$D25 -> 116.648 | I32: =I$22/$C25*$D25 -> 116.648 | J32: =J$22/$C25*$D25 -> 116.648 | K32: =K$22/$C25*$D25 -> 116.648 | L32: =L$22/$C25*$D25 -> 116.648 | ... N32: =N$22/$C25*$D25 -> 116.648
B33: ТО-3: простои, ч/год | C33: ч | E33: =E$22/$C26*$D26 -> 67.76 | F33: =F$22/$C26*$D26 -> 67.76 | G33: =G$22/$C26*$D26 -> 67.76 | H33: =H$22/$C26*$D26 -> 67.76 | I33: =I$22/$C26*$D26 -> 67.76 | J33: =J$22/$C26*$D26 -> 67.76 | K33: =K$22/$C26*$D26 -> 67.76 | L33: =L$22/$C26*$D26 -> 67.76 | ... N33: =N$22/$C26*$D26 -> 67.76
B34: ТО-4: простои, ч/год | C34: ч | E34: =E$22/$C27*$D27 -> 39.48 | F34: =F$22/$C27*$D27 -> 39.48 | G34: =G$22/$C27*$D27 -> 39.48 | H34: =H$22/$C27*$D27 -> 39.48 | I34: =I$22/$C27*$D27 -> 39.48 | J34: =J$22/$C27*$D27 -> 39.48 | K34: =K$22/$C27*$D27 -> 39.48 | L34: =L$22/$C27*$D27 -> 39.48 | ... N34: =N$22/$C27*$D27 -> 39.48
B35: ТО-5: простои, ч/год | C35: ч | E35: =E$22/$C28*$D28 -> 26.04 | F35: =F$22/$C28*$D28 -> 26.04 | G35: =G$22/$C28*$D28 -> 26.04 | H35: =H$22/$C28*$D28 -> 26.04 | I35: =I$22/$C28*$D28 -> 26.04 | J35: =J$22/$C28*$D28 -> 26.04 | K35: =K$22/$C28*$D28 -> 26.04 | L35: =L$22/$C28*$D28 -> 26.04 | ... N35: =N$22/$C28*$D28 -> 26.04
B36: ТО-6: простои, ч/год | C36: ч | E36: =E$22/$C29*$D29 -> 20.02 | F36: =F$22/$C29*$D29 -> 20.02 | G36: =G$22/$C29*$D29 -> 20.02 | H36: =H$22/$C29*$D29 -> 20.02 | I36: =I$22/$C29*$D29 -> 20.02 | J36: =J$22/$C29*$D29 -> 20.02 | K36: =K$22/$C29*$D29 -> 20.02 | L36: =L$22/$C29*$D29 -> 20.02 | ... N36: =N$22/$C29*$D29 -> 20.02
B37: Итого простои ТО | E37: =SUM(E31:E36) -> 337.148 | F37: =SUM(F31:F36) -> 337.148 | G37: =SUM(G31:G36) -> 337.148 | H37: =SUM(H31:H36) -> 337.148 | I37: =SUM(I31:I36) -> 337.148 | J37: =SUM(J31:J36) -> 337.148 | K37: =SUM(K31:K36) -> 337.148 | L37: =SUM(L31:L36) -> 337.148 | ... N37: =SUM(N31:N36) -> 337.148
B38: ТО-1: чел-часы/год | C38: ч-час | E38: =E31*$E24 -> 201.6 | F38: =F31*$E24 -> 201.6 | G38: =G31*$E24 -> 201.6 | H38: =H31*$E24 -> 201.6 | I38: =I31*$E24 -> 201.6 | J38: =J31*$E24 -> 201.6 | K38: =K31*$E24 -> 201.6 | L38: =L31*$E24 -> 201.6 | ... N38: =N31*$E24 -> 201.6
B39: ТО-2: чел-часы/год | C39: ч-час | E39: =E32*$E25 -> 466.592 | F39: =F32*$E25 -> 466.592 | G39: =G32*$E25 -> 466.592 | H39: =H32*$E25 -> 466.592 | I39: =I32*$E25 -> 466.592 | J39: =J32*$E25 -> 466.592 | K39: =K32*$E25 -> 466.592 | L39: =L32*$E25 -> 466.592 | ... N39: =N32*$E25 -> 466.592
B40: ТО-3: чел-часы/год | C40: ч-час | E40: =E33*$E26 -> 271.04 | F40: =F33*$E26 -> 271.04 | G40: =G33*$E26 -> 271.04 | H40: =H33*$E26 -> 271.04 | I40: =I33*$E26 -> 271.04 | J40: =J33*$E26 -> 271.04 | K40: =K33*$E26 -> 271.04 | L40: =L33*$E26 -> 271.04 | ... N40: =N33*$E26 -> 271.04
B41: ТО-4: чел-часы/год | C41: ч-час | E41: =E34*$E27 -> 157.92 | F41: =F34*$E27 -> 157.92 | G41: =G34*$E27 -> 157.92 | H41: =H34*$E27 -> 157.92 | I41: =I34*$E27 -> 157.92 | J41: =J34*$E27 -> 157.92 | K41: =K34*$E27 -> 157.92 | L41: =L34*$E27 -> 157.92 | ... N41: =N34*$E27 -> 157.92
B42: ТО-5: чел-часы/год | C42: ч-час | E42: =E35*$E28 -> 104.16 | F42: =F35*$E28 -> 104.16 | G42: =G35*$E28 -> 104.16 | H42: =H35*$E28 -> 104.16 | I42: =I35*$E28 -> 104.16 | J42: =J35*$E28 -> 104.16 | K42: =K35*$E28 -> 104.16 | L42: =L35*$E28 -> 104.16 | ... N42: =N35*$E28 -> 104.16
B43: ТО-6: чел-часы/год | C43: ч-час | E43: =E36*$E29 -> 80.08 | F43: =F36*$E29 -> 80.08 | G43: =G36*$E29 -> 80.08 | H43: =H36*$E29 -> 80.08 | I43: =I36*$E29 -> 80.08 | J43: =J36*$E29 -> 80.08 | K43: =K36*$E29 -> 80.08 | L43: =L36*$E29 -> 80.08 | ... N43: =N36*$E29 -> 80.08
...

Sheet Поставщик 6
B1: ДАННЫЕ ПОСТАВЩИКА — ВАРИАНТ 6 (ТО и Ремонты — модель по узлам)
B2: Жёлтое — ввод. Зелёное — авто (снизу вверх). ИТОГО ТОиР = (ЗЧ ТО + ЗЧ капремонтов + сервис) × коэф.калибровки; тянется в «Данные по годам».
B4: Автосамосвал: | E4: ='Ввод данных'!I7 -> БелАЗ 7531 (БТЛ)
B5: Валюта затрат ТОиР: | D5: CNY
B6: Показатель | C6: Ед. | E6: год 1 | F6: год 2 | G6: год 3 | H6: год 4 | I6: год 5 | J6: год 6 | K6: год 7 | L6: год 8 | M6: год 9 | N6: год 10
B7: СВОДКА ПО ГОДАМ (зелёное — авто снизу вверх; тянется в расчёт)
B8: Простои на ТО (авто из интервалов) | C8: ч/год | E8: =E37 -> 337.148 | F8: =F37 -> 337.148 | G8: =G37 -> 337.148 | H8: =H37 -> 337.148 | I8: =I37 -> 337.148 | J8: =J37 -> 337.148 | K8: =K37 -> 337.148 | L8: =L37 -> 337.148 | ... N8: =N37 -> 337.148
B9: Простои в ремонтах (справочно) | C9: ч/год | E9: 135 | F9: 341 | G9: 417.667 | H9: 588 | I9: 402 | J9: 680.333 | K9: 549 | L9: 487 | M9: 793 | N9: 842.333
B10: Ежесменный осмотр (20 мин/смену), справочно | C10: ч/год | E10: =('Параметры'!C26-E8-E9)/'Параметры'!C27*20/60 -> 230.21811 | F10: =('Параметры'!C26-F8-F9)/'Параметры'!C27*20/60 -> 224.49589 | G10: =('Параметры'!C26-G8-G9)/'Параметры'!C27*20/60 -> 222.36625 | H10: =('Параметры'!C26-H8-H9)/'Параметры'!C27*20/60 -> 217.63478 | I10: =('Параметры'!C26-I8-I9)/'Параметры'!C27*20/60 -> 222.80144 | J10: =('Параметры'!C26-J8-J9)/'Параметры'!C27*20/60 -> 215.06997 | K10: =('Параметры'!C26-K8-K9)/'Параметры'!C27*20/60 -> 218.71811 | L10: =('Параметры'!C26-L8-L9)/'Параметры'!C27*20/60 -> 220.44033 | M10: =('Параметры'!C26-M8-M9)/'Параметры'!C27*20/60 -> 211.94033 | N10: =('Параметры'!C26-N8-N9)/'Параметры'!C27*20/60 -> 210.56997
B11: КТГ (техготовность, ВВОД) → «Данные по годам» | C11: коэф. | E11: 0.9151 | F11: 0.8934 | G11: 0.8846 | H11: 0.8669 | I11: 0.8865 | J11: 0.856 | K11: 0.8373 | L11: 0.8777 | M11: 0.8442 | N11: 0.8383
B12: Затраты на ЗЧ ТО (авто из каталога) | C12: тыс.вал/г | E12: =E73 -> 615.85391 | F12: =F73 -> 615.85391 | G12: =G73 -> 615.85391 | H12: =H73 -> 615.85391 | I12: =I73 -> 615.85391 | J12: =J73 -> 615.85391 | K12: =K73 -> 615.85391 | L12: =L73 -> 615.85391 | ... N12: =N73 -> 615.85391
B13: Затраты на ЗЧ капремонтов (авто по ресурсу) | C13: тыс.вал/г | E13: =E96 -> 0 | F13: =F96 -> 151.6104 | G13: =G96 -> 3293.5408 | H13: =H96 -> 894.48203 | I13: =I96 -> 99.85674 | J13: =J96 -> 3353.1664 | K13: =K96 -> 47.96174 | L13: =L96 -> 938.50503 | ... N13: =N96 -> 151.6104
B14: Трудозатраты ТО (авто) | C14: ч-час/г | E14: =E44 -> 1281.392 | F14: =F44 -> 1281.392 | G14: =G44 -> 1281.392 | H14: =H44 -> 1281.392 | I14: =I44 -> 1281.392 | J14: =J44 -> 1281.392 | K14: =K44 -> 1281.392 | L14: =L44 -> 1281.392 | ... N14: =N44 -> 1281.392
B15: Трудозатраты капремонтов (авто) | C15: ч-час/г | E15: =E119 -> 0 | F15: =F119 -> 472 | G15: =G119 -> 1020 | H15: =H119 -> 1038 | I15: =I119 -> 482 | J15: =J119 -> 1020 | K15: =K119 -> 20 | L15: =L119 -> 1490 | ... N15: =N119 -> 472
B16: Сервис (трудозатраты) ТО+капремонты | C16: тыс.вал/г | E16: =(E14+E15)*$E$21/1000 -> 244.74587 | F16: =(F14+F15)*$E$21/1000 -> 334.89787 | G16: =(G14+G15)*$E$21/1000 -> 439.56587 | H16: =(H14+H15)*$E$21/1000 -> 443.00387 | I16: =(I14+I15)*$E$21/1000 -> 336.80787 | J16: =(J14+J15)*$E$21/1000 -> 439.56587 | K16: =(K14+K15)*$E$21/1000 -> 248.56587 | L16: =(L14+L15)*$E$21/1000 -> 529.33587 | ... N16: =(N14+N15)*$E$21/1000 -> 334.89787
B17: Коэффициент калибровки ИТОГО под ТКП | C17: коэф. | E17: 1.5542
B18: ИТОГО ТОиР → «Данные по годам» | C18: тыс.вал/г | E18: =(E12+E13+E16)*$E$17 -> 1337.5442 | F18: =(F12+F13+F16)*$E$17 -> 1713.2913 | G18: =(G12+G13+G16)*$E$17 -> 6759.1545 | H18: =(H12+H13+H16)*$E$17 -> 3035.8807 | I18: =(I12+I13+I16)*$E$17 -> 1635.8243 | J18: =(J12+J13+J16)*$E$17 -> 6851.8247 | K18: =(K12+K13+K16)*$E$17 -> 1418.0234 | L18: =(L12+L13+L16)*$E$17 -> 3238.4785 | ... N18: =(N12+N13+N16)*$E$17 -> 1713.2913
B20: РАСЧЁТ ТО (по интервалам обслуживания), ПО ГОДАМ
B21: Ставка сервиса | C21: вал/ч·час | E21: 191
B22: Наработка по годам | C22: м/час | E22: 7000 | F22: 7000 | G22: 7000 | H22: 7000 | I22: 7000 | J22: 7000 | K22: 7000 | L22: 7000 | M22: 7000 | N22: 7000
B23: Вид ТО | C23: интервал, м/ч | D23: простой/ТО, ч | E23: персонал
B24: ТО-1 | C24: 250 | D24: 2.4 | E24: 3
B25: ТО-2 | C25: 500 | D25: 8.332 | E25: 4
B26: ТО-3 | C26: 1000 | D26: 9.68 | E26: 4
B27: ТО-4 | C27: 2000 | D27: 11.28 | E27: 4
B28: ТО-5 | C28: 5000 | D28: 18.6 | E28: 4
B29: ТО-6 | C29: 10000 | D29: 28.6 | E29: 4
B31: ТО-1: простои, ч/год | C31: ч | E31: =E$22/$C24*$D24 -> 67.2 | F31: =F$22/$C24*$D24 -> 67.2 | G31: =G$22/$C24*$D24 -> 67.2 | H31: =H$22/$C24*$D24 -> 67.2 | I31: =I$22/$C24*$D24 -> 67.2 | J31: =J$22/$C24*$D24 -> 67.2 | K31: =K$22/$C24*$D24 -> 67.2 | L31: =L$22/$C24*$D24 -> 67.2 | ... N31: =N$22/$C24*$D24 -> 67.2
B32: ТО-2: простои, ч/год | C32: ч | E32: =E$22/$C25*$D25 -> 116.648 | F32: =F$22/$C25*$D25 -> 116.648 | G32: =G$22/$C25*$D25 -> 116.648 | H32: =H$22/$C25*$D25 -> 116.648 | I32: =I$22/$C25*$D25 -> 116.648 | J32: =J$22/$C25*$D25 -> 116.648 | K32: =K$22/$C25*$D25 -> 116.648 | L32: =L$22/$C25*$D25 -> 116.648 | ... N32: =N$22/$C25*$D25 -> 116.648
B33: ТО-3: простои, ч/год | C33: ч | E33: =E$22/$C26*$D26 -> 67.76 | F33: =F$22/$C26*$D26 -> 67.76 | G33: =G$22/$C26*$D26 -> 67.76 | H33: =H$22/$C26*$D26 -> 67.76 | I33: =I$22/$C26*$D26 -> 67.76 | J33: =J$22/$C26*$D26 -> 67.76 | K33: =K$22/$C26*$D26 -> 67.76 | L33: =L$22/$C26*$D26 -> 67.76 | ... N33: =N$22/$C26*$D26 -> 67.76
B34: ТО-4: простои, ч/год | C34: ч | E34: =E$22/$C27*$D27 -> 39.48 | F34: =F$22/$C27*$D27 -> 39.48 | G34: =G$22/$C27*$D27 -> 39.48 | H34: =H$22/$C27*$D27 -> 39.48 | I34: =I$22/$C27*$D27 -> 39.48 | J34: =J$22/$C27*$D27 -> 39.48 | K34: =K$22/$C27*$D27 -> 39.48 | L34: =L$22/$C27*$D27 -> 39.48 | ... N34: =N$22/$C27*$D27 -> 39.48
B35: ТО-5: простои, ч/год | C35: ч | E35: =E$22/$C28*$D28 -> 26.04 | F35: =F$22/$C28*$D28 -> 26.04 | G35: =G$22/$C28*$D28 -> 26.04 | H35: =H$22/$C28*$D28 -> 26.04 | I35: =I$22/$C28*$D28 -> 26.04 | J35: =J$22/$C28*$D28 -> 26.04 | K35: =K$22/$C28*$D28 -> 26.04 | L35: =L$22/$C28*$D28 -> 26.04 | ... N35: =N$22/$C28*$D28 -> 26.04
B36: ТО-6: простои, ч/год | C36: ч | E36: =E$22/$C29*$D29 -> 20.02 | F36: =F$22/$C29*$D29 -> 20.02 | G36: =G$22/$C29*$D29 -> 20.02 | H36: =H$22/$C29*$D29 -> 20.02 | I36: =I$22/$C29*$D29 -> 20.02 | J36: =J$22/$C29*$D29 -> 20.02 | K36: =K$22/$C29*$D29 -> 20.02 | L36: =L$22/$C29*$D29 -> 20.02 | ... N36: =N$22/$C29*$D29 -> 20.02
