Workbook

Sheet Методика
B1: МЕТОДИКА: АННУИТЕТ ЗАТРАТ (РУБ/ТКМ) НА ВЛАДЕНИЕ АВТОСАМОСВАЛАМИ
B2: Пост-налоговый погодовой дисконтированный аннуитет жизненного цикла.
C4: 1. НАЗНАЧЕНИЕ
C5: Экономическое сравнение карьерных автосамосвалов одного класса по удельному аннуитету затрат (руб/ткм грузооборота, а также руб/т перевезённой массы) за полный срок эксплуатации. Метрика корректно сопоставляет самосвалы с разной ценой, грузоподъёмностью и производительностью. Лучший вариант — минимум руб/ткм.
C6: 2. ПРОИЗВОДИТЕЛЬНОСТЬ (транспортный цикл из файла «Производительность»)
C7: Время рейса = (подход + погрузка + разгрузка + прочее) + время движения; время движения = 2 × плечо / скорость × 60 (гружёный + порожний ход). Рейсов/час = 60 / время рейса. Часовая производительность (т/эфф.час) = рейсов/час × грузоподъёмность × КИГ. КИО = КТГ × (1 − простои_смены/(60 × смена)); эффективное время = КФВ × КИО. Годовой объём (тыс.т) = часовая × эффективное время; грузооборот (тыс.ткм) = объём × плечо; пробег = рейсы × 2 × плечо.
C8: 3. ПОГОДОВОЙ ДЕНЕЖНЫЙ ПОТОК (10 лет)
C9: Для каждого года считаются: топливо (грузооборот × г/ткм × цена), ТОиР и сервис (задаются ПО ГОДАМ на листах «Поставщик N» — ТО, текущие и капитальные ремонты; годы капремонтов дают всплеск затрат), шины (пробег × удельный расход × цена), персонал, транспортный налог. Добавляются амортизация (НУ) и налог на прибыль (щит). Операционный поток = база + налог − амортизация. Инвестиции — в год 0, остаточная стоимость — в конце срока.
C10: 4. АННУИТЕТ (ЯДРО)
C11: Потоки дисконтируются и преобразуются в эквивалентный годовой платёж: Аннуитет = NPV затрат / Σ(дисконт-факторов). Инвестиционный аннуитет = (Цена − дисконт. остаточная стоимость) / Σ(дисконт-факторов). Операционный аннуитет — приведённые эксплуатационные затраты после налога. Общий = инвестиционный + операционный. Удельный аннуитет (руб/ткм) = общий аннуитет / средний годовой грузооборот; руб/т = руб/ткм × плечо.
C12: 5. ПОРЯДОК РАБОТЫ
C13: «Параметры» → «Ввод данных» (цена, грузоподъёмность, мощность двигателя, персонал) → листы «Поставщик 1…6»: по каждой машине задаются КТГ, простои и затраты ТОиР по годам — КТГ и ИТОГО ТОиР считаются автоматически. Сводка «Данные по годам» тянет итоги сама → авторасчёт «Производительность», «Денежный поток», «Расчёт аннуитета» → «Дашборд», «Сравнение», «Аналитика», «Чувствительность». Правки — в листах «Поставщик N» и «Ввод данных».
C14: 6. ДОПУЩЕНИЯ
C15: • Самосвалы сравниваются в одном классе и одной задаче; разница в производительности учтена через руб/ткм и руб/т.
... C22: зелёные ячейки — итоговые показатели / лучший вариант

Sheet Дашборд
B1: ИТОГОВЫЙ ДАШБОРД — СРАВНЕНИЕ АВТОСАМОСВАЛОВ
B2: Ключевые показатели и графики. Данные обновляются автоматически.
B4: КЛЮЧЕВЫЕ ПОКАЗАТЕЛИ
B5: Лучший вариант | C5: Мин. аннуитет, руб/ткм | D5: Мин. NPV владения, тыс.руб | E5: Разброс аннуитета, руб/ткм
B6: =INDEX('Ввод данных'!D7:I7,MATCH(MIN('Расчёт аннуитета'!D26:I26),'Расчёт аннуитета'!D26:I26,0)) -> NHL NTE 240 | C6: =MIN('Расчёт аннуитета'!D26:I26) -> 12.046304 | D6: =MIN('Расчёт аннуитета'!D14:I14) -> 784177.62 | E6: =MAX('Расчёт аннуитета'!D26:I26)-MIN('Расчёт аннуитета'!D26:I26) -> 5.290397
B8: РЕЙТИНГ ПО УДЕЛЬНОМУ АННУИТЕТУ (руб/ткм)
B9: Место | C9: Автосамосвал | G9: руб/ткм | I9: руб/т
B10: 1 | C10: =INDEX('Ввод данных'!D7:I7,MATCH(SMALL('Расчёт аннуитета'!D26:I26,1),'Расчёт аннуитета'!D26:I26,0)) -> NHL NTE 240 | G10: =SMALL('Расчёт аннуитета'!D26:I26,1) -> 12.046304 | I10: =INDEX('Расчёт аннуитета'!$D$28:$I$28,MATCH(SMALL('Расчёт аннуитета'!D26:I26,1),'Расчёт аннуитета'!D26:I26,0)) -> 36.615947
B11: 2 | C11: =INDEX('Ввод данных'!D7:I7,MATCH(SMALL('Расчёт аннуитета'!D26:I26,2),'Расчёт аннуитета'!D26:I26,0)) -> SANY SET240S | G11: =SMALL('Расчёт аннуитета'!D26:I26,2) -> 14.02617 | I11: =INDEX('Расчёт аннуитета'!$D$28:$I$28,MATCH(SMALL('Расчёт аннуитета'!D26:I26,2),'Расчёт аннуитета'!D26:I26,0)) -> 42.633947
B12: 3 | C12: =INDEX('Ввод данных'!D7:I7,MATCH(SMALL('Расчёт аннуитета'!D26:I26,3),'Расчёт аннуитета'!D26:I26,0)) -> БелАЗ 7531 (БТЛ) | G12: =SMALL('Расчёт аннуитета'!D26:I26,3) -> 14.09582 | I12: =INDEX('Расчёт аннуитета'!$D$28:$I$28,MATCH(SMALL('Расчёт аннуитета'!D26:I26,3),'Расчёт аннуитета'!D26:I26,0)) -> 42.845655
B13: 4 | C13: =INDEX('Ввод данных'!D7:I7,MATCH(SMALL('Расчёт аннуитета'!D26:I26,4),'Расчёт аннуитета'!D26:I26,0)) -> БелАЗ 7531 (ГПФК) | G13: =SMALL('Расчёт аннуитета'!D26:I26,4) -> 14.372984 | I13: =INDEX('Расчёт аннуитета'!$D$28:$I$28,MATCH(SMALL('Расчёт аннуитета'!D26:I26,4),'Расчёт аннуитета'!D26:I26,0)) -> 43.688123
B14: 5 | C14: =INDEX('Ввод данных'!D7:I7,MATCH(SMALL('Расчёт аннуитета'!D26:I26,5),'Расчёт аннуитета'!D26:I26,0)) -> TZCO TZE240 | G14: =SMALL('Расчёт аннуитета'!D26:I26,5) -> 16.119303 | I14: =INDEX('Расчёт аннуитета'!$D$28:$I$28,MATCH(SMALL('Расчёт аннуитета'!D26:I26,5),'Расчёт аннуитета'!D26:I26,0)) -> 48.996232
B15: 6 | C15: =INDEX('Ввод данных'!D7:I7,MATCH(SMALL('Расчёт аннуитета'!D26:I26,6),'Расчёт аннуитета'!D26:I26,0)) -> Estar ESDE240 (ГПБ К) | G15: =SMALL('Расчёт аннуитета'!D26:I26,6) -> 17.336701 | I15: =INDEX('Расчёт аннуитета'!$D$28:$I$28,MATCH(SMALL('Расчёт аннуитета'!D26:I26,6),'Расчёт аннуитета'!D26:I26,0)) -> 52.696638

Sheet Параметры
B1: ГЛОБАЛЬНЫЕ ПАРАМЕТРЫ МОДЕЛИ
B2: Единые допущения для всех вариантов. Жёлтые ячейки — ввод.
B4: Финансовые допущения
B5: Параметр | C5: Значение | D5: Ед. | E5: Комментарий
B6: Ставка дисконтирования (WACC) | C6: 0.12 | D6: %/год | E6: Стоимость капитала для приведения к текущей стоимости
B7: Налог на прибыль | C7: 0.25 | D7: % | E7: Формирует налоговый щит на затраты и амортизацию
B8: Срок эксплуатации (горизонт) | C8: 10 | D8: лет | E8: Фиксирован = 10 лет в погодовом движке
B9: Срок амортизации (налоговый учёт) | C9: 5.083 | D9: лет | E9: Линейная; 61 мес ≈ 5,08 года
B10: Цена дизельного топлива | C10: 66.019 | D10: тыс.руб/т | E10: СЛ 2025: 1 274 749,9 тыс.руб / 19 308,86 т
B12: Эскалация цен (реальный/номинальный рост)
B13: Параметр | C13: Значение | D13: Ед. | E13: Комментарий
B14: Эскалация цены топлива | C14: 0 | D14: %/год | E14: 0 = данные уже с учётом инфляции
B15: Эскалация ЗЧ/шин/расходников | C15: 0 | D15: %/год | E15: ТОиР задаётся по годам напрямую
B16: Эскалация оплаты труда | C16: 0 | D16: %/год | E16: Рост ФОТ экипажей
B18: Курсы валют
B19: Параметр | C19: Значение | D19: Ед. | E19: Комментарий
B20: Курс юаня (CNY) | C20: 12.7702 | D20: руб | E20: Для оборудования из Китая
B21: Курс доллара (USD) | C21: 94.0485 | D21: руб
B22: Курс евро (EUR) | C22: 100 | D22: руб
B24: Параметры производительности (транспортный цикл)
B25: Параметр | C25: Значение | D25: Ед. | E25: Комментарий
B26: Календарный фонд времени | C26: 8760 | D26: час/год | E26: 24 ч × 365 дн
B27: Длительность смены | C27: 12 | D27: час | E27: Для пересчёта простоев
B28: Расстояние транспортировки (плечо) | C28: 3.0396 | D28: км | E28: Среднее плечо откатки (гружёный ход)
B29: Средняя техническая скорость | C29: 22.46 | D29: км/час | E29: С учётом профиля трассы
B30: КИГ (использование грузоподъёмности) | C30: 0.9837 | D30: коэф. | E30: Доля номинальной грузоподъёмности (факт NTE)
B31: Фикс. время рейса (подход+погр+разгр+прочее) | C31: 8.4 | D31: мин | E31: Подход/погрузка/разгрузка 7,9 + прочие 0,5
B32: Удельный расход топлива | C32: 90 | D32: г/ткм | E32: На тонно-километр грузооборота
B34: Шины
B35: Параметр | C35: Значение | D35: Ед. | E35: Комментарий
B36: Удельный расход шин | C36: 0.075 | D36: шт./тыс.км | E36: Комплект/износ на пробег
B37: Цена шины | C37: 2985.38 | D37: тыс.руб/шт | E37: DDP, без НДС (типоразмер 50/80R57 и аналоги)
B39: Транспортный налог и персонал
B40: Параметр | C40: Значение | D40: Ед. | E40: Комментарий
B41: Ставка транспортного налога | C41: 85 | D41: руб/л.с. | E41: Иркутская область
B43: Расчётные финансовые коэффициенты
B44: Параметр | C44: Значение | D44: Ед. | E44: Комментарий
B45: Коэф. аннуитета Σдиск.факторов (r, N) | C45: =IF('Параметры'!C6=0,'Параметры'!C8,(1-(1+'Параметры'!C6)^-'Параметры'!C8)/'Параметры'!C6) -> 5.650223 | D45: коэф. | E45: Сумма дисконт-факторов за срок службы
B46: Коэф. приведённой амортизации | C46: =(1/'Параметры'!C9)*((1-(1+'Параметры'!C6)^-INT('Параметры'!C9))/'Параметры'!C6+('Параметры'!C9-INT('Параметры'!C9))*(1+'Параметры'!C6)^-(INT('Параметры'!C9)+1)) -> 0.71745555 | D46: коэф. | E46: Приведённая амортизация на 1 руб. цены (налог. щит)
B48: Легенда: | D48: — ввод данных
...

Sheet Ввод данных
B1: ВВОД ИСХОДНЫХ ДАННЫХ ПО АВТОСАМОСВАЛАМ
B2: Сравнение до 6 машин одного класса. Пример: самосвалы класса 220–240 т, карьер «Сухой Лог».
B4: Показатель | C4: Ед. | D4: Самосвал 1 | E4: Самосвал 2 | F4: Самосвал 3 | G4: Самосвал 4 | H4: Самосвал 5 | I4: Самосвал 6 | K4: Пояснение
B6: A. ИДЕНТИФИКАЦИЯ
B7: Наименование / модель | C7: — | D7: NHL NTE 240 | E7: Estar ESDE240 (ГПБ К) | F7: SANY SET240S | G7: TZCO TZE240 | H7: БелАЗ 7531 (ГПФК) | I7: БелАЗ 7531 (БТЛ) | K7: Название варианта
B8: Поставщик | C8: — | D8: Горная Евразия | E8: ГПБ | F8: ИСТК | G8: ИСТК | H8: ГПФК | I8: БТЛ
B9: Двигатель / привод | C9: — | D9: электро (2500 л.с.) | E9: 1864 л.с. | F9: 2843 л.с. | G9: 2500 л.с. | H9: 2535 л.с. | I9: 2535 л.с.
B10: B. СТОИМОСТЬ И ОСТАТОЧНАЯ ЦЕНА
B11: Цена за единицу | C11: тыс.вал. | D11: 20000 | E11: 2800 | F11: 2700 | G11: 2700 | H11: 300000 | I11: 290000 | K11: ⚠ В файле поставщика цена не указана — ОЦЕНКА, уточнить
B12: Валюта цены | C12: — | D12: CNY | E12: USD | F12: USD | G12: USD | H12: RUB | I12: RUB | K12: CNY / USD / EUR / RUB
B13: Доставка, ПНР, шеф-монтаж | C13: тыс.руб | D13: 0 | E13: 0 | F13: 0 | G13: 0 | H13: 0 | I13: 0 | K13: Дополнительно к цене
B14: Остаточная стоимость | C14: % от цены | D14: 0 | E14: 0 | F14: 0 | G14: 0 | H14: 0 | I14: 0 | K14: Реализация в конце срока (0 = не учитывать)
B15: C. ПРОИЗВОДИТЕЛЬНОСТЬ
B16: Грузоподъёмность (в расчёте) | C16: т | D16: 227.8 | E16: 211.392 | F16: 216.362 | G16: 222 | H16: 231 | I16: 231 | K16: × КИГ (лист «Параметры») = фактическая загрузка
B17: D. ПРОЧИЕ ГОДОВЫЕ ЗАТРАТЫ И ПАРАМЕТРЫ
B18: Расходы на персонал (экипаж) | C18: тыс.руб/год | D18: 18475.6 | E18: 18475.6 | F18: 18475.6 | G18: 18475.6 | H18: 18475.6 | I18: 18475.6 | K18: ФОТ+отчисления+прочее на 1 машину
B19: Мощность двигателя (транспортный налог) | C19: л.с. | D19: 2500 | E19: 1864 | F19: 2843 | G19: 2500 | H19: 2535 | I19: 2535 | K19: × ставку налога (руб/л.с.)
B20: ℹ КТГ, простои и затраты на ТОиР (ТО/ТР/капремонты/сервис) задаются ПО ГОДАМ на листах «Поставщик 1…6». Расход топлива (г/ткм), шины и КИГ — общие на листе «Параметры». Сводка — на листе «Данные по годам».

Sheet Поставщик 1
B1: ДАННЫЕ ПОСТАВЩИКА — ВАРИАНТ 1 (ТО и Ремонты ПО ГОДАМ)
B2: Жёлтое — ввод (данные поставщика/расчёта). Зелёное — авто; сводка тянется в «Данные по годам».
B4: Автосамосвал: | E4: ='Ввод данных'!D7 -> NHL NTE 240
B5: Валюта затрат ТОиР: | D5: CNY
B6: Показатель | C6: Ед. | E6: год 1 | F6: год 2 | G6: год 3 | H6: год 4 | I6: год 5 | J6: год 6 | K6: год 7 | L6: год 8 | M6: год 9 | N6: год 10
B7: СВОДКА ПО ГОДАМ (зелёное — авто; тянется в расчёт)
B8: Простои на ТО | C8: ч/год | E8: =E19 -> 173.404 | F8: =F19 -> 202.004 | G8: =G19 -> 173.404 | H8: =H19 -> 202.004 | I8: =I19 -> 173.404 | J8: =J19 -> 202.004 | K8: =K19 -> 202.004 | L8: =L19 -> 173.404 | ... N8: =N19 -> 173.404
B9: Простои в ремонтах | C9: ч/год | E9: =E20 -> 139 | F9: =F20 -> 175 | G9: =G20 -> 289 | H9: =H20 -> 373 | I9: =I20 -> 177 | J9: =J20 -> 253 | K9: =K20 -> 167 | L9: =L20 -> 377 | ... N9: =N20 -> 187
B10: Ежесменный осмотр (20 мин/смену), справочно | C10: ч/год | E10: =('Параметры'!C26-E8-E9)/'Параметры'!C27*20/60 -> 234.65544 | F10: =('Параметры'!C26-F8-F9)/'Параметры'!C27*20/60 -> 232.861 | G10: =('Параметры'!C26-G8-G9)/'Параметры'!C27*20/60 -> 230.48878 | H10: =('Параметры'!C26-H8-H9)/'Параметры'!C27*20/60 -> 227.361 | I10: =('Параметры'!C26-I8-I9)/'Параметры'!C27*20/60 -> 233.59989 | J10: =('Параметры'!C26-J8-J9)/'Параметры'!C27*20/60 -> 230.69433 | K10: =('Параметры'!C26-K8-K9)/'Параметры'!C27*20/60 -> 233.08322 | L10: =('Параметры'!C26-L8-L9)/'Параметры'!C27*20/60 -> 228.04433 | M10: =('Параметры'!C26-M8-M9)/'Параметры'!C27*20/60 -> 229.52767 | N10: =('Параметры'!C26-N8-N9)/'Параметры'!C27*20/60 -> 233.32211
B11: КТГ (техготовность) → «Данные по годам» | C11: коэф. | E11: 0.9376 | F11: 0.9304 | G11: 0.9209 | H11: 0.9084 | I11: 0.9333 | J11: 0.9217 | K11: 0.9313 | L11: 0.9111 | M11: 0.9171 | N11: 0.9322
B12: Затраты на ТО (ЗЧ+смазочные) | C12: тыс.вал/г | E12: =E21 -> 297.274 | F12: =F21 -> 297.274 | G12: =G21 -> 297.274 | H12: =H21 -> 297.274 | I12: =I21 -> 297.274 | J12: =J21 -> 297.274 | K12: =K21 -> 297.274 | L12: =L21 -> 297.274 | ... N12: =N21 -> 297.274
B13: Затраты на текущие ремонты | C13: тыс.вал/г | E13: =E22 -> 0 | F13: =F22 -> 0 | G13: =G22 -> 0 | H13: =H22 -> 0 | I13: =I22 -> 0 | J13: =J22 -> 0 | K13: =K22 -> 0 | L13: =L22 -> 0 | ... N13: =N22 -> 0
B14: Затраты на капитальные/ППР ремонты | C14: тыс.вал/г | E14: =E23 -> 0 | F14: =F23 -> 151.61 | G14: =G23 -> 3293.541 | H14: =H23 -> 1329.651 | I14: =I23 -> 207.444 | J14: =J23 -> 3259.167 | K14: =K23 -> 47.962 | L14: =L23 -> 1481.261 | ... N14: =N23 -> 44.023
B15: Сервис (трудозатраты) — ТО | C15: тыс.вал/г | E15: =E24 -> 126.063 | F15: =F24 -> 147.913 | G15: =G24 -> 126.063 | H15: =H24 -> 147.913 | I15: =I24 -> 126.063 | J15: =J24 -> 147.913 | K15: =K24 -> 147.913 | L15: =L24 -> 126.063 | ... N15: =N24 -> 126.063
B16: Сервис (трудозатраты) — ремонты | C16: тыс.вал/г | E16: =E25 -> 47.368 | F16: =F25 -> 57.3 | G16: =G25 -> 158.53 | H16: =H25 -> 286.118 | I16: =I25 -> 56.536 | J16: =J25 -> 80.22 | K16: =K25 -> 144.014 | L16: =L25 -> 279.624 | ... N16: =N25 -> 74.108
B17: ИТОГО ТОиР → «Данные по годам» | C17: тыс.вал/г | E17: =E12+E13+E14+E15+E16 -> 470.705 | F17: =F12+F13+F14+F15+F16 -> 654.097 | G17: =G12+G13+G14+G15+G16 -> 3875.408 | H17: =H12+H13+H14+H15+H16 -> 2060.956 | I17: =I12+I13+I14+I15+I16 -> 687.317 | J17: =J12+J13+J14+J15+J16 -> 3784.574 | K17: =K12+K13+K14+K15+K16 -> 637.163 | L17: =L12+L13+L14+L15+L16 -> 2184.222 | ... N17: =N12+N13+N14+N15+N16 -> 541.468
B18: ВВОД ДАННЫХ ПОСТАВЩИКА ПО ГОДАМ (жёлтое)
B19: Простои на ТО | C19: ч/год | E19: 173.404 | F19: 202.004 | G19: 173.404 | H19: 202.004 | I19: 173.404 | J19: 202.004 | K19: 202.004 | L19: 173.404 | M19: 202.004 | N19: 173.404
B20: Простои в ремонтах | C20: ч/год | E20: 139 | F20: 175 | G20: 289 | H20: 373 | I20: 177 | J20: 253 | K20: 167 | L20: 377 | M20: 295 | N20: 187
B21: Затраты на ТО (ЗЧ+смазочные) | C21: тыс.вал/г | E21: 297.274 | F21: 297.274 | G21: 297.274 | H21: 297.274 | I21: 297.274 | J21: 297.274 | K21: 297.274 | L21: 297.274 | M21: 297.274 | N21: 297.274
B22: Затраты на текущие ремонты | C22: тыс.вал/г | E22: 0 | F22: 0 | G22: 0 | H22: 0 | I22: 0 | J22: 0 | K22: 0 | L22: 0 | M22: 0 | N22: 0
B23: Затраты на капитальные/ППР ремонты | C23: тыс.вал/г | E23: 0 | F23: 151.61 | G23: 3293.541 | H23: 1329.651 | I23: 207.444 | J23: 3259.167 | K23: 47.962 | L23: 1481.261 | M23: 6533.292 | N23: 44.023
B24: Сервис (трудозатраты) — ТО | C24: тыс.вал/г | E24: 126.063 | F24: 147.913 | G24: 126.063 | H24: 147.913 | I24: 126.063 | J24: 147.913 | K24: 147.913 | L24: 126.063 | M24: 147.913 | N24: 126.063
B25: Сервис (трудозатраты) — ремонты | C25: тыс.вал/г | E25: 47.368 | F25: 57.3 | G25: 158.53 | H25: 286.118 | I25: 56.536 | J25: 80.22 | K25: 144.014 | L25: 279.624 | M25: 81.748 | N25: 74.108
B27: Строки 18–24 — ввод (жёлтое): простои и затраты ТОиР по годам, в валюте (см. «Валюта затрат ТОиР»). Пересчёт в рубли — в «Денежном потоке» по курсу с листа «Параметры». Данные примера — «в расчёте» из 000_БСЛ-2027 (карьер «Сухой Лог»). «Рваный» график капремонтов по годам учитывается дисконтированием.

Sheet Поставщик 2
B1: ДАННЫЕ ПОСТАВЩИКА — ВАРИАНТ 2 (ТО и Ремонты ПО ГОДАМ)
B2: Жёлтое — ввод (данные поставщика/расчёта). Зелёное — авто; сводка тянется в «Данные по годам».
B4: Автосамосвал: | E4: ='Ввод данных'!E7 -> Estar ESDE240 (ГПБ К)
B5: Валюта затрат ТОиР: | D5: USD
B6: Показатель | C6: Ед. | E6: год 1 | F6: год 2 | G6: год 3 | H6: год 4 | I6: год 5 | J6: год 6 | K6: год 7 | L6: год 8 | M6: год 9 | N6: год 10
B7: СВОДКА ПО ГОДАМ (зелёное — авто; тянется в расчёт)
B8: Простои на ТО | C8: ч/год | E8: =E19 -> 153 | F8: =F19 -> 153 | G8: =G19 -> 153 | H8: =H19 -> 153 | I8: =I19 -> 153 | J8: =J19 -> 153 | K8: =K19 -> 153 | L8: =L19 -> 153 | ... N8: =N19 -> 153
B9: Простои в ремонтах | C9: ч/год | E9: =E20 -> 420 | F9: =F20 -> 505 | G9: =G20 -> 905 | H9: =H20 -> 1287 | I9: =I20 -> 455 | J9: =J20 -> 1132 | K9: =K20 -> 485 | L9: =L20 -> 1290 | ... N9: =N20 -> 1155
B10: Ежесменный осмотр (20 мин/смену), справочно | C10: ч/год | E10: =('Параметры'!C26-E8-E9)/'Параметры'!C27*20/60 -> 227.41667 | F10: =('Параметры'!C26-F8-F9)/'Параметры'!C27*20/60 -> 225.05556 | G10: =('Параметры'!C26-G8-G9)/'Параметры'!C27*20/60 -> 213.94444 | H10: =('Параметры'!C26-H8-H9)/'Параметры'!C27*20/60 -> 203.33333 | I10: =('Параметры'!C26-I8-I9)/'Параметры'!C27*20/60 -> 226.44444 | J10: =('Параметры'!C26-J8-J9)/'Параметры'!C27*20/60 -> 207.63889 | K10: =('Параметры'!C26-K8-K9)/'Параметры'!C27*20/60 -> 225.61111 | L10: =('Параметры'!C26-L8-L9)/'Параметры'!C27*20/60 -> 203.25 | M10: =('Параметры'!C26-M8-M9)/'Параметры'!C27*20/60 -> 217.36111 | N10: =('Параметры'!C26-N8-N9)/'Параметры'!C27*20/60 -> 207
B11: КТГ (техготовность) → «Данные по годам» | C11: коэф. | E11: 0.9116 | F11: 0.8956 | G11: 0.8493 | H11: 0.806 | I11: 0.899 | J11: 0.8221 | K11: 0.8886 | L11: 0.8107 | M11: 0.8562 | N11: 0.834
B12: Затраты на ТО (ЗЧ+смазочные) | C12: тыс.вал/г | E12: =E21 -> 154.719 | F12: =F21 -> 154.719 | G12: =G21 -> 154.719 | H12: =H21 -> 154.719 | I12: =I21 -> 154.719 | J12: =J21 -> 154.719 | K12: =K21 -> 154.719 | L12: =L21 -> 154.719 | ... N12: =N21 -> 154.719
B13: Затраты на текущие ремонты | C13: тыс.вал/г | E13: =E22 -> 0 | F13: =F22 -> 0 | G13: =G22 -> 0 | H13: =H22 -> 0 | I13: =I22 -> 0 | J13: =J22 -> 0 | K13: =K22 -> 0 | L13: =L22 -> 0 | ... N13: =N22 -> 0
B14: Затраты на капитальные/ППР ремонты | C14: тыс.вал/г | E14: =E23 -> 4.931 | F14: =F23 -> 88.53 | G14: =G23 -> 701.511 | H14: =H23 -> 2494.29 | I14: =I23 -> 7.014 | J14: =J23 -> 785.11 | K14: =K23 -> 4.931 | L14: =L23 -> 2494.29 | ... N14: =N23 -> 4.931
B15: Сервис (трудозатраты) — ТО | C15: тыс.вал/г | E15: =E24 -> 19.44 | F15: =F24 -> 19.44 | G15: =G24 -> 19.44 | H15: =H24 -> 19.44 | I15: =I24 -> 19.44 | J15: =J24 -> 19.44 | K15: =K24 -> 19.44 | L15: =L24 -> 19.44 | ... N15: =N24 -> 19.44
B16: Сервис (трудозатраты) — ремонты | C16: тыс.вал/г | E16: =E25 -> 1.44 | F16: =F25 -> 14.04 | G16: =G25 -> 52.47 | H16: =H25 -> 82.89 | I16: =I25 -> 3.06 | J16: =J25 -> 65.07 | K16: =K25 -> 1.44 | L16: =L25 -> 82.89 | ... N16: =N25 -> 1.44
B17: ИТОГО ТОиР → «Данные по годам» | C17: тыс.вал/г | E17: =E12+E13+E14+E15+E16 -> 180.53 | F17: =F12+F13+F14+F15+F16 -> 276.729 | G17: =G12+G13+G14+G15+G16 -> 928.14 | H17: =H12+H13+H14+H15+H16 -> 2751.339 | I17: =I12+I13+I14+I15+I16 -> 184.233 | J17: =J12+J13+J14+J15+J16 -> 1024.339 | K17: =K12+K13+K14+K15+K16 -> 180.53 | L17: =L12+L13+L14+L15+L16 -> 2751.339 | ... N17: =N12+N13+N14+N15+N16 -> 180.53
B18: ВВОД ДАННЫХ ПОСТАВЩИКА ПО ГОДАМ (жёлтое)
B19: Простои на ТО | C19: ч/год | E19: 153 | F19: 153 | G19: 153 | H19: 153 | I19: 153 | J19: 153 | K19: 153 | L19: 153 | M19: 153 | N19: 153
B20: Простои в ремонтах | C20: ч/год | E20: 420 | F20: 505 | G20: 905 | H20: 1287 | I20: 455 | J20: 1132 | K20: 485 | L20: 1290 | M20: 782 | N20: 1155
B21: Затраты на ТО (ЗЧ+смазочные) | C21: тыс.вал/г | E21: 154.719 | F21: 154.719 | G21: 154.719 | H21: 154.719 | I21: 154.719 | J21: 154.719 | K21: 154.719 | L21: 154.719 | M21: 154.719 | N21: 154.719
B22: Затраты на текущие ремонты | C22: тыс.вал/г | E22: 0 | F22: 0 | G22: 0 | H22: 0 | I22: 0 | J22: 0 | K22: 0 | L22: 0 | M22: 0 | N22: 0
B23: Затраты на капитальные/ППР ремонты | C23: тыс.вал/г | E23: 4.931 | F23: 88.53 | G23: 701.511 | H23: 2494.29 | I23: 7.014 | J23: 785.11 | K23: 4.931 | L23: 2494.29 | M23: 4.931 | N23: 4.931
B24: Сервис (трудозатраты) — ТО | C24: тыс.вал/г | E24: 19.44 | F24: 19.44 | G24: 19.44 | H24: 19.44 | I24: 19.44 | J24: 19.44 | K24: 19.44 | L24: 19.44 | M24: 19.44 | N24: 19.44
B25: Сервис (трудозатраты) — ремонты | C25: тыс.вал/г | E25: 1.44 | F25: 14.04 | G25: 52.47 | H25: 82.89 | I25: 3.06 | J25: 65.07 | K25: 1.44 | L25: 82.89 | M25: 1.44 | N25: 1.44
B27: Строки 18–24 — ввод (жёлтое): простои и затраты ТОиР по годам, в валюте (см. «Валюта затрат ТОиР»). Пересчёт в рубли — в «Денежном потоке» по курсу с листа «Параметры». Данные примера — «в расчёте» из 000_БСЛ-2027 (карьер «Сухой Лог»). «Рваный» график капремонтов по годам учитывается дисконтированием.

Sheet Поставщик 3
B1: ДАННЫЕ ПОСТАВЩИКА — ВАРИАНТ 3 (ТО и Ремонты ПО ГОДАМ)
B2: Жёлтое — ввод (данные поставщика/расчёта). Зелёное — авто; сводка тянется в «Данные по годам».
B4: Автосамосвал: | E4: ='Ввод данных'!F7 -> SANY SET240S
B5: Валюта затрат ТОиР: | D5: USD
B6: Показатель | C6: Ед. | E6: год 1 | F6: год 2 | G6: год 3 | H6: год 4 | I6: год 5 | J6: год 6 | K6: год 7 | L6: год 8 | M6: год 9 | N6: год 10
B7: СВОДКА ПО ГОДАМ (зелёное — авто; тянется в расчёт)
B8: Простои на ТО | C8: ч/год | E8: =E19 -> 186 | F8: =F19 -> 186 | G8: =G19 -> 186 | H8: =H19 -> 186 | I8: =I19 -> 186 | J8: =J19 -> 186 | K8: =K19 -> 186 | L8: =L19 -> 186 | ... N8: =N19 -> 186
B9: Простои в ремонтах | C9: ч/год | E9: =E20 -> 280 | F9: =F20 -> 570 | G9: =G20 -> 750 | H9: =H20 -> 505 | I9: =I20 -> 930 | J9: =J20 -> 505 | K9: =K20 -> 750 | L9: =L20 -> 505 | ... N9: =N20 -> 660
B10: Ежесменный осмотр (20 мин/смену), справочно | C10: ч/год | E10: =('Параметры'!C26-E8-E9)/'Параметры'!C27*20/60 -> 230.38889 | F10: =('Параметры'!C26-F8-F9)/'Параметры'!C27*20/60 -> 222.33333 | G10: =('Параметры'!C26-G8-G9)/'Параметры'!C27*20/60 -> 217.33333 | H10: =('Параметры'!C26-H8-H9)/'Параметры'!C27*20/60 -> 224.13889 | I10: =('Параметры'!C26-I8-I9)/'Параметры'!C27*20/60 -> 212.33333 | J10: =('Параметры'!C26-J8-J9)/'Параметры'!C27*20/60 -> 224.13889 | K10: =('Параметры'!C26-K8-K9)/'Параметры'!C27*20/60 -> 217.33333 | L10: =('Параметры'!C26-L8-L9)/'Параметры'!C27*20/60 -> 224.13889 | M10: =('Параметры'!C26-M8-M9)/'Параметры'!C27*20/60 -> 212.33333 | N10: =('Параметры'!C26-N8-N9)/'Параметры'!C27*20/60 -> 219.83333
B11: КТГ (техготовность) → «Данные по годам» | C11: коэф. | E11: 0.9357 | F11: 0.9026 | G11: 0.8659 | H11: 0.904 | I11: 0.85 | J11: 0.904 | K11: 0.8659 | L11: 0.904 | M11: 0.85 | N11: 0.885
B12: Затраты на ТО (ЗЧ+смазочные) | C12: тыс.вал/г | E12: =E21 -> 93.681 | F12: =F21 -> 93.681 | G12: =G21 -> 93.681 | H12: =H21 -> 93.681 | I12: =I21 -> 93.681 | J12: =J21 -> 93.681 | K12: =K21 -> 93.681 | L12: =L21 -> 93.681 | ... N12: =N21 -> 93.681
B13: Затраты на текущие ремонты | C13: тыс.вал/г | E13: =E22 -> 17.931 | F13: =F22 -> 17.931 | G13: =G22 -> 17.931 | H13: =H22 -> 17.931 | I13: =I22 -> 17.931 | J13: =J22 -> 17.931 | K13: =K22 -> 17.931 | L13: =L22 -> 17.931 | ... N13: =N22 -> 17.931
B14: Затраты на капитальные/ППР ремонты | C14: тыс.вал/г | E14: =E23 -> 0 | F14: =F23 -> 62.211 | G14: =G23 -> 433.633 | H14: =H23 -> 156.454 | I14: =I23 -> 803.169 | J14: =J23 -> 592.571 | K14: =K23 -> 103.048 | L14: =L23 -> 120.245 | ... N14: =N23 -> 39.493
B15: Сервис (трудозатраты) — ТО | C15: тыс.вал/г | E15: =E24 -> 17.204 | F15: =F24 -> 17.204 | G15: =G24 -> 17.204 | H15: =H24 -> 17.204 | I15: =I24 -> 17.204 | J15: =J24 -> 17.204 | K15: =K24 -> 17.204 | L15: =L24 -> 17.204 | ... N15: =N24 -> 17.204
B16: Сервис (трудозатраты) — ремонты | C16: тыс.вал/г | E16: =E25 -> 6.532 | F16: =F25 -> 20.24 | G16: =G25 -> 35.512 | H16: =H25 -> 19.872 | I16: =I25 -> 41.952 | J16: =J25 -> 19.872 | K16: =K25 -> 35.512 | L16: =L25 -> 19.872 | ... N16: =N25 -> 27.692
B17: ИТОГО ТОиР → «Данные по годам» | C17: тыс.вал/г | E17: =E12+E13+E14+E15+E16 -> 135.348 | F17: =F12+F13+F14+F15+F16 -> 211.267 | G17: =G12+G13+G14+G15+G16 -> 597.961 | H17: =H12+H13+H14+H15+H16 -> 305.142 | I17: =I12+I13+I14+I15+I16 -> 973.937 | J17: =J12+J13+J14+J15+J16 -> 741.259 | K17: =K12+K13+K14+K15+K16 -> 267.376 | L17: =L12+L13+L14+L15+L16 -> 268.933 | ... N17: =N12+N13+N14+N15+N16 -> 196.001
B18: ВВОД ДАННЫХ ПОСТАВЩИКА ПО ГОДАМ (жёлтое)
B19: Простои на ТО | C19: ч/год | E19: 186 | F19: 186 | G19: 186 | H19: 186 | I19: 186 | J19: 186 | K19: 186 | L19: 186 | M19: 186 | N19: 186
B20: Простои в ремонтах | C20: ч/год | E20: 280 | F20: 570 | G20: 750 | H20: 505 | I20: 930 | J20: 505 | K20: 750 | L20: 505 | M20: 930 | N20: 660
B21: Затраты на ТО (ЗЧ+смазочные) | C21: тыс.вал/г | E21: 93.681 | F21: 93.681 | G21: 93.681 | H21: 93.681 | I21: 93.681 | J21: 93.681 | K21: 93.681 | L21: 93.681 | M21: 93.681 | N21: 93.681
B22: Затраты на текущие ремонты | C22: тыс.вал/г | E22: 17.931 | F22: 17.931 | G22: 17.931 | H22: 17.931 | I22: 17.931 | J22: 17.931 | K22: 17.931 | L22: 17.931 | M22: 17.931 | N22: 17.931
B23: Затраты на капитальные/ППР ремонты | C23: тыс.вал/г | E23: 0 | F23: 62.211 | G23: 433.633 | H23: 156.454 | I23: 803.169 | J23: 592.571 | K23: 103.048 | L23: 120.245 | M23: 1178.573 | N23: 39.493
B24: Сервис (трудозатраты) — ТО | C24: тыс.вал/г | E24: 17.204 | F24: 17.204 | G24: 17.204 | H24: 17.204 | I24: 17.204 | J24: 17.204 | K24: 17.204 | L24: 17.204 | M24: 17.204 | N24: 17.204
B25: Сервис (трудозатраты) — ремонты | C25: тыс.вал/г | E25: 6.532 | F25: 20.24 | G25: 35.512 | H25: 19.872 | I25: 41.952 | J25: 19.872 | K25: 35.512 | L25: 19.872 | M25: 41.952 | N25: 27.692
B27: Строки 18–24 — ввод (жёлтое): простои и затраты ТОиР по годам, в валюте (см. «Валюта затрат ТОиР»). Пересчёт в рубли — в «Денежном потоке» по курсу с листа «Параметры». Данные примера — «в расчёте» из 000_БСЛ-2027 (карьер «Сухой Лог»). «Рваный» график капремонтов по годам учитывается дисконтированием.

Sheet Поставщик 4
B1: ДАННЫЕ ПОСТАВЩИКА — ВАРИАНТ 4 (ТО и Ремонты ПО ГОДАМ)
B2: Жёлтое — ввод (данные поставщика/расчёта). Зелёное — авто; сводка тянется в «Данные по годам».
B4: Автосамосвал: | E4: ='Ввод данных'!G7 -> TZCO TZE240
B5: Валюта затрат ТОиР: | D5: USD
B6: Показатель | C6: Ед. | E6: год 1 | F6: год 2 | G6: год 3 | H6: год 4 | I6: год 5 | J6: год 6 | K6: год 7 | L6: год 8 | M6: год 9 | N6: год 10
B7: СВОДКА ПО ГОДАМ (зелёное — авто; тянется в расчёт)
B8: Простои на ТО | C8: ч/год | E8: =E19 -> 196 | F8: =F19 -> 196 | G8: =G19 -> 196 | H8: =H19 -> 196 | I8: =I19 -> 196 | J8: =J19 -> 196 | K8: =K19 -> 196 | L8: =L19 -> 196 | ... N8: =N19 -> 196
B9: Простои в ремонтах | C9: ч/год | E9: =E20 -> 425 | F9: =F20 -> 690 | G9: =G20 -> 1600 | H9: =H20 -> 690 | I9: =I20 -> 425 | J9: =J20 -> 1800 | K9: =K20 -> 425 | L9: =L20 -> 690 | ... N9: =N20 -> 690
B10: Ежесменный осмотр (20 мин/смену), справочно | C10: ч/год | E10: =('Параметры'!C26-E8-E9)/'Параметры'!C27*20/60 -> 226.08333 | F10: =('Параметры'!C26-F8-F9)/'Параметры'!C27*20/60 -> 218.72222 | G10: =('Параметры'!C26-G8-G9)/'Параметры'!C27*20/60 -> 193.44444 | H10: =('Параметры'!C26-H8-H9)/'Параметры'!C27*20/60 -> 218.72222 | I10: =('Параметры'!C26-I8-I9)/'Параметры'!C27*20/60 -> 226.08333 | J10: =('Параметры'!C26-J8-J9)/'Параметры'!C27*20/60 -> 187.88889 | K10: =('Параметры'!C26-K8-K9)/'Параметры'!C27*20/60 -> 226.08333 | L10: =('Параметры'!C26-L8-L9)/'Параметры'!C27*20/60 -> 218.72222 | M10: =('Параметры'!C26-M8-M9)/'Параметры'!C27*20/60 -> 226.08333 | N10: =('Параметры'!C26-N8-N9)/'Параметры'!C27*20/60 -> 218.72222
B11: КТГ (техготовность) → «Данные по годам» | C11: коэф. | E11: 0.9096 | F11: 0.8842 | G11: 0.774 | H11: 0.8842 | I11: 0.9096 | J11: 0.748 | K11: 0.9096 | L11: 0.8842 | M11: 0.9096 | N11: 0.8842
B12: Затраты на ТО (ЗЧ+смазочные) | C12: тыс.вал/г | E12: =E21 -> 217.032 | F12: =F21 -> 217.032 | G12: =G21 -> 217.032 | H12: =H21 -> 217.032 | I12: =I21 -> 217.032 | J12: =J21 -> 217.032 | K12: =K21 -> 217.032 | L12: =L21 -> 217.032 | ... N12: =N21 -> 217.032
B13: Затраты на текущие ремонты | C13: тыс.вал/г | E13: =E22 -> 7.5 | F13: =F22 -> 7.5 | G13: =G22 -> 7.5 | H13: =H22 -> 7.5 | I13: =I22 -> 7.5 | J13: =J22 -> 7.5 | K13: =K22 -> 7.5 | L13: =L22 -> 7.5 | ... N13: =N22 -> 7.5
B14: Затраты на капитальные/ППР ремонты | C14: тыс.вал/г | E14: =E23 -> 22.18 | F14: =F23 -> 117.302 | G14: =G23 -> 1471.522 | H14: =H23 -> 117.302 | I14: =I23 -> 22.18 | J14: =J23 -> 1566.643 | K14: =K23 -> 22.18 | L14: =L23 -> 117.302 | ... N14: =N23 -> 117.302
B15: Сервис (трудозатраты) — ТО | C15: тыс.вал/г | E15: =E24 -> 50.416 | F15: =F24 -> 50.416 | G15: =G24 -> 50.416 | H15: =H24 -> 50.416 | I15: =I24 -> 50.416 | J15: =J24 -> 50.416 | K15: =K24 -> 50.416 | L15: =L24 -> 50.416 | ... N15: =N24 -> 50.416
B16: Сервис (трудозатраты) — ремонты | C16: тыс.вал/г | E16: =E25 -> 2.208 | F16: =F25 -> 237.323 | G16: =G25 -> 134.734 | H16: =H25 -> 237.323 | I16: =I25 -> 2.208 | J16: =J25 -> 369.849 | K16: =K25 -> 2.208 | L16: =L25 -> 237.323 | ... N16: =N25 -> 237.323
B17: ИТОГО ТОиР → «Данные по годам» | C17: тыс.вал/г | E17: =E12+E13+E14+E15+E16 -> 299.336 | F17: =F12+F13+F14+F15+F16 -> 629.573 | G17: =G12+G13+G14+G15+G16 -> 1881.204 | H17: =H12+H13+H14+H15+H16 -> 629.573 | I17: =I12+I13+I14+I15+I16 -> 299.336 | J17: =J12+J13+J14+J15+J16 -> 2211.44 | K17: =K12+K13+K14+K15+K16 -> 299.336 | L17: =L12+L13+L14+L15+L16 -> 629.573 | ... N17: =N12+N13+N14+N15+N16 -> 629.573
B18: ВВОД ДАННЫХ ПОСТАВЩИКА ПО ГОДАМ (жёлтое)
B19: Простои на ТО | C19: ч/год | E19: 196 | F19: 196 | G19: 196 | H19: 196 | I19: 196 | J19: 196 | K19: 196 | L19: 196 | M19: 196 | N19: 196
B20: Простои в ремонтах | C20: ч/год | E20: 425 | F20: 690 | G20: 1600 | H20: 690 | I20: 425 | J20: 1800 | K20: 425 | L20: 690 | M20: 425 | N20: 690
B21: Затраты на ТО (ЗЧ+смазочные) | C21: тыс.вал/г | E21: 217.032 | F21: 217.032 | G21: 217.032 | H21: 217.032 | I21: 217.032 | J21: 217.032 | K21: 217.032 | L21: 217.032 | M21: 217.032 | N21: 217.032
B22: Затраты на текущие ремонты | C22: тыс.вал/г | E22: 7.5 | F22: 7.5 | G22: 7.5 | H22: 7.5 | I22: 7.5 | J22: 7.5 | K22: 7.5 | L22: 7.5 | M22: 7.5 | N22: 7.5
B23: Затраты на капитальные/ППР ремонты | C23: тыс.вал/г | E23: 22.18 | F23: 117.302 | G23: 1471.522 | H23: 117.302 | I23: 22.18 | J23: 1566.643 | K23: 22.18 | L23: 117.302 | M23: 22.18 | N23: 117.302
B24: Сервис (трудозатраты) — ТО | C24: тыс.вал/г | E24: 50.416 | F24: 50.416 | G24: 50.416 | H24: 50.416 | I24: 50.416 | J24: 50.416 | K24: 50.416 | L24: 50.416 | M24: 50.416 | N24: 50.416
B25: Сервис (трудозатраты) — ремонты | C25: тыс.вал/г | E25: 2.208 | F25: 237.323 | G25: 134.734 | H25: 237.323 | I25: 2.208 | J25: 369.849 | K25: 2.208 | L25: 237.323 | M25: 2.208 | N25: 237.323
B27: Строки 18–24 — ввод (жёлтое): простои и затраты ТОиР по годам, в валюте (см. «Валюта затрат ТОиР»). Пересчёт в рубли — в «Денежном потоке» по курсу с листа «Параметры». Данные примера — «в расчёте» из 000_БСЛ-2027 (карьер «Сухой Лог»). «Рваный» график капремонтов по годам учитывается дисконтированием.

Sheet Поставщик 5
B1: ДАННЫЕ ПОСТАВЩИКА — ВАРИАНТ 5 (ТО и Ремонты ПО ГОДАМ)
B2: Жёлтое — ввод (данные поставщика/расчёта). Зелёное — авто; сводка тянется в «Данные по годам».
B4: Автосамосвал: | E4: ='Ввод данных'!H7 -> БелАЗ 7531 (ГПФК)
B5: Валюта затрат ТОиР: | D5: USD
B6: Показатель | C6: Ед. | E6: год 1 | F6: год 2 | G6: год 3 | H6: год 4 | I6: год 5 | J6: год 6 | K6: год 7 | L6: год 8 | M6: год 9 | N6: год 10
B7: СВОДКА ПО ГОДАМ (зелёное — авто; тянется в расчёт)
B8: Простои на ТО | C8: ч/год | E8: =E19 -> 249.395 | F8: =F19 -> 238.375 | G8: =G19 -> 238.375 | H8: =H19 -> 238.375 | I8: =I19 -> 238.375 | J8: =J19 -> 238.375 | K8: =K19 -> 238.375 | L8: =L19 -> 238.375 | ... N8: =N19 -> 238.375
B9: Простои в ремонтах | C9: ч/год | E9: =E20 -> 135 | F9: =F20 -> 341 | G9: =G20 -> 417.667 | H9: =H20 -> 588 | I9: =I20 -> 402 | J9: =J20 -> 680.333 | K9: =K20 -> 549 | L9: =L20 -> 487 | ... N9: =N20 -> 842.333
B10: Ежесменный осмотр (20 мин/смену), справочно | C10: ч/год | E10: =('Параметры'!C26-E8-E9)/'Параметры'!C27*20/60 -> 232.65569 | F10: =('Параметры'!C26-F8-F9)/'Параметры'!C27*20/60 -> 227.23958 | G10: =('Параметры'!C26-G8-G9)/'Параметры'!C27*20/60 -> 225.10994 | H10: =('Параметры'!C26-H8-H9)/'Параметры'!C27*20/60 -> 220.37847 | I10: =('Параметры'!C26-I8-I9)/'Параметры'!C27*20/60 -> 225.54514 | J10: =('Параметры'!C26-J8-J9)/'Параметры'!C27*20/60 -> 217.81367 | K10: =('Параметры'!C26-K8-K9)/'Параметры'!C27*20/60 -> 221.46181 | L10: =('Параметры'!C26-L8-L9)/'Параметры'!C27*20/60 -> 223.18403 | M10: =('Параметры'!C26-M8-M9)/'Параметры'!C27*20/60 -> 214.68403 | N10: =('Параметры'!C26-N8-N9)/'Параметры'!C27*20/60 -> 213.31367
B11: КТГ (техготовность) → «Данные по годам» | C11: коэф. | E11: 0.9083 | F11: 0.8858 | G11: 0.8646 | H11: 0.8748 | I11: 0.8813 | J11: 0.8464 | K11: 0.8971 | L11: 0.8546 | M11: 0.842 | N11: 0.8611
B12: Затраты на ТО (ЗЧ+смазочные) | C12: тыс.вал/г | E12: =E21 -> 62.265 | F12: =F21 -> 51.1 | G12: =G21 -> 51.1 | H12: =H21 -> 51.1 | I12: =I21 -> 51.1 | J12: =J21 -> 51.1 | K12: =K21 -> 51.1 | L12: =L21 -> 51.1 | ... N12: =N21 -> 51.1
B13: Затраты на текущие ремонты | C13: тыс.вал/г | E13: =E22 -> 16.5 | F13: =F22 -> 183.7 | G13: =G22 -> 158.5 | H13: =H22 -> 50.7 | I13: =I22 -> 163.5 | J13: =J22 -> 188.7 | K13: =K22 -> 35.5 | L13: =L22 -> 198.7 | ... N13: =N22 -> 70.7
B14: Затраты на капитальные/ППР ремонты | C14: тыс.вал/г | E14: =E23 -> 0 | F14: =F23 -> 0 | G14: =G23 -> 267.4 | H14: =H23 -> 530 | I14: =I23 -> 327 | J14: =J23 -> 338.2 | K14: =K23 -> 14.2 | L14: =L23 -> 490 | ... N14: =N23 -> 0
B15: Сервис (трудозатраты) — ТО | C15: тыс.вал/г | E15: =E24 -> 60.181 | F15: =F24 -> 59.257 | G15: =G24 -> 59.257 | H15: =H24 -> 59.257 | I15: =I24 -> 59.257 | J15: =J24 -> 59.257 | K15: =K24 -> 59.257 | L15: =L24 -> 59.257 | ... N15: =N24 -> 59.257
B16: Сервис (трудозатраты) — ремонты | C16: тыс.вал/г | E16: =E25 -> 9.101 | F16: =F25 -> 23.544 | G16: =G25 -> 35.811 | H16: =H25 -> 35.949 | I16: =I25 -> 30.766 | J16: =J25 -> 51.362 | K16: =K25 -> 20.438 | L16: =L25 -> 48.137 | ... N16: =N25 -> 50.452
B17: ИТОГО ТОиР → «Данные по годам» | C17: тыс.вал/г | E17: =E12+E13+E14+E15+E16 -> 148.047 | F17: =F12+F13+F14+F15+F16 -> 317.601 | G17: =G12+G13+G14+G15+G16 -> 572.068 | H17: =H12+H13+H14+H15+H16 -> 727.006 | I17: =I12+I13+I14+I15+I16 -> 631.623 | J17: =J12+J13+J14+J15+J16 -> 688.619 | K17: =K12+K13+K14+K15+K16 -> 180.495 | L17: =L12+L13+L14+L15+L16 -> 847.194 | ... N17: =N12+N13+N14+N15+N16 -> 231.509
B18: ВВОД ДАННЫХ ПОСТАВЩИКА ПО ГОДАМ (жёлтое)
B19: Простои на ТО | C19: ч/год | E19: 249.395 | F19: 238.375 | G19: 238.375 | H19: 238.375 | I19: 238.375 | J19: 238.375 | K19: 238.375 | L19: 238.375 | M19: 238.375 | N19: 238.375
B20: Простои в ремонтах | C20: ч/год | E20: 135 | F20: 341 | G20: 417.667 | H20: 588 | I20: 402 | J20: 680.333 | K20: 549 | L20: 487 | M20: 793 | N20: 842.333
B21: Затраты на ТО (ЗЧ+смазочные) | C21: тыс.вал/г | E21: 62.265 | F21: 51.1 | G21: 51.1 | H21: 51.1 | I21: 51.1 | J21: 51.1 | K21: 51.1 | L21: 51.1 | M21: 51.1 | N21: 51.1
B22: Затраты на текущие ремонты | C22: тыс.вал/г | E22: 16.5 | F22: 183.7 | G22: 158.5 | H22: 50.7 | I22: 163.5 | J22: 188.7 | K22: 35.5 | L22: 198.7 | M22: 173.5 | N22: 70.7
B23: Затраты на капитальные/ППР ремонты | C23: тыс.вал/г | E23: 0 | F23: 0 | G23: 267.4 | H23: 530 | I23: 327 | J23: 338.2 | K23: 14.2 | L23: 490 | M23: 620.2 | N23: 0
B24: Сервис (трудозатраты) — ТО | C24: тыс.вал/г | E24: 60.181 | F24: 59.257 | G24: 59.257 | H24: 59.257 | I24: 59.257 | J24: 59.257 | K24: 59.257 | L24: 59.257 | M24: 59.257 | N24: 59.257
B25: Сервис (трудозатраты) — ремонты | C25: тыс.вал/г | E25: 9.101 | F25: 23.544 | G25: 35.811 | H25: 35.949 | I25: 30.766 | J25: 51.362 | K25: 20.438 | L25: 48.137 | M25: 57.693 | N25: 50.452
B27: Строки 18–24 — ввод (жёлтое): простои и затраты ТОиР по годам, в валюте (см. «Валюта затрат ТОиР»). Пересчёт в рубли — в «Денежном потоке» по курсу с листа «Параметры». Данные примера — «в расчёте» из 000_БСЛ-2027 (карьер «Сухой Лог»). «Рваный» график капремонтов по годам учитывается дисконтированием.

Sheet Поставщик 6
B1: ДАННЫЕ ПОСТАВЩИКА — ВАРИАНТ 6 (ТО и Ремонты ПО ГОДАМ)
B2: Жёлтое — ввод (данные поставщика/расчёта). Зелёное — авто; сводка тянется в «Данные по годам».
B4: Автосамосвал: | E4: ='Ввод данных'!I7 -> БелАЗ 7531 (БТЛ)
B5: Валюта затрат ТОиР: | D5: USD
B6: Показатель | C6: Ед. | E6: год 1 | F6: год 2 | G6: год 3 | H6: год 4 | I6: год 5 | J6: год 6 | K6: год 7 | L6: год 8 | M6: год 9 | N6: год 10
B7: СВОДКА ПО ГОДАМ (зелёное — авто; тянется в расчёт)
B8: Простои на ТО | C8: ч/год | E8: =E19 -> 249.395 | F8: =F19 -> 238.375 | G8: =G19 -> 238.375 | H8: =H19 -> 238.375 | I8: =I19 -> 238.375 | J8: =J19 -> 238.375 | K8: =K19 -> 238.375 | L8: =L19 -> 238.375 | ... N8: =N19 -> 238.375
B9: Простои в ремонтах | C9: ч/год | E9: =E20 -> 135 | F9: =F20 -> 341 | G9: =G20 -> 417.667 | H9: =H20 -> 588 | I9: =I20 -> 402 | J9: =J20 -> 680.333 | K9: =K20 -> 549 | L9: =L20 -> 487 | ... N9: =N20 -> 842.333
B10: Ежесменный осмотр (20 мин/смену), справочно | C10: ч/год | E10: =('Параметры'!C26-E8-E9)/'Параметры'!C27*20/60 -> 232.65569 | F10: =('Параметры'!C26-F8-F9)/'Параметры'!C27*20/60 -> 227.23958 | G10: =('Параметры'!C26-G8-G9)/'Параметры'!C27*20/60 -> 225.10994 | H10: =('Параметры'!C26-H8-H9)/'Параметры'!C27*20/60 -> 220.37847 | I10: =('Параметры'!C26-I8-I9)/'Параметры'!C27*20/60 -> 225.54514 | J10: =('Параметры'!C26-J8-J9)/'Параметры'!C27*20/60 -> 217.81367 | K10: =('Параметры'!C26-K8-K9)/'Параметры'!C27*20/60 -> 221.46181 | L10: =('Параметры'!C26-L8-L9)/'Параметры'!C27*20/60 -> 223.18403 | M10: =('Параметры'!C26-M8-M9)/'Параметры'!C27*20/60 -> 214.68403 | N10: =('Параметры'!C26-N8-N9)/'Параметры'!C27*20/60 -> 213.31367
B11: КТГ (техготовность) → «Данные по годам» | C11: коэф. | E11: 0.93 | F11: 0.908 | G11: 0.899 | H11: 0.881 | I11: 0.901 | J11: 0.87 | K11: 0.851 | L11: 0.892 | M11: 0.858 | N11: 0.852
B12: Затраты на ТО (ЗЧ+смазочные) | C12: тыс.вал/г | E12: =E21 -> 49.6 | F12: =F21 -> 41.135 | G12: =G21 -> 41.135 | H12: =H21 -> 41.135 | I12: =I21 -> 41.135 | J12: =J21 -> 41.135 | K12: =K21 -> 41.135 | L12: =L21 -> 41.135 | ... N12: =N21 -> 41.135
B13: Затраты на текущие ремонты | C13: тыс.вал/г | E13: =E22 -> 15.011 | F13: =F22 -> 77.065 | G13: =G22 -> 50.721 | H13: =H22 -> 89.861 | I13: =I22 -> 60.141 | J13: =J22 -> 102.874 | K13: =K22 -> 80.547 | L13: =L22 -> 64.172 | ... N13: =N22 -> 90.366
B14: Затраты на капитальные/ППР ремонты | C14: тыс.вал/г | E14: =E23 -> 0 | F14: =F23 -> 0 | G14: =G23 -> 410.928 | H14: =H23 -> 652.532 | I14: =I23 -> 158.405 | J14: =J23 -> 339.483 | K14: =K23 -> 71.445 | L14: =L23 -> 721.657 | ... N14: =N23 -> 0
B15: Сервис (трудозатраты) — ТО | C15: тыс.вал/г | E15: =E24 -> 48.632 | F15: =F24 -> 46.483 | G15: =G24 -> 46.483 | H15: =H24 -> 46.483 | I15: =I24 -> 46.483 | J15: =J24 -> 46.483 | K15: =K24 -> 46.483 | L15: =L24 -> 46.483 | ... N15: =N24 -> 46.483
B16: Сервис (трудозатраты) — ремонты | C16: тыс.вал/г | E16: =E25 -> 17.55 | F16: =F25 -> 44.33 | G16: =G25 -> 66.17 | H16: =H25 -> 81.51 | I16: =I25 -> 58.5 | J16: =J25 -> 106.99 | K16: =K25 -> 83.85 | L16: =L25 -> 98.28 | ... N16: =N25 -> 157.17
B17: ИТОГО ТОиР → «Данные по годам» | C17: тыс.вал/г | E17: =E12+E13+E14+E15+E16 -> 130.793 | F17: =F12+F13+F14+F15+F16 -> 209.013 | G17: =G12+G13+G14+G15+G16 -> 615.437 | H17: =H12+H13+H14+H15+H16 -> 911.521 | I17: =I12+I13+I14+I15+I16 -> 364.664 | J17: =J12+J13+J14+J15+J16 -> 636.965 | K17: =K12+K13+K14+K15+K16 -> 323.46 | L17: =L12+L13+L14+L15+L16 -> 971.727 | ... N17: =N12+N13+N14+N15+N16 -> 335.154
B18: ВВОД ДАННЫХ ПОСТАВЩИКА ПО ГОДАМ (жёлтое)
B19: Простои на ТО | C19: ч/год | E19: 249.395 | F19: 238.375 | G19: 238.375 | H19: 238.375 | I19: 238.375 | J19: 238.375 | K19: 238.375 | L19: 238.375 | M19: 238.375 | N19: 238.375
B20: Простои в ремонтах | C20: ч/год | E20: 135 | F20: 341 | G20: 417.667 | H20: 588 | I20: 402 | J20: 680.333 | K20: 549 | L20: 487 | M20: 793 | N20: 842.333
B21: Затраты на ТО (ЗЧ+смазочные) | C21: тыс.вал/г | E21: 49.6 | F21: 41.135 | G21: 41.135 | H21: 41.135 | I21: 41.135 | J21: 41.135 | K21: 41.135 | L21: 41.135 | M21: 41.135 | N21: 41.135
B22: Затраты на текущие ремонты | C22: тыс.вал/г | E22: 15.011 | F22: 77.065 | G22: 50.721 | H22: 89.861 | I22: 60.141 | J22: 102.874 | K22: 80.547 | L22: 64.172 | M22: 74.323 | N22: 90.366
B23: Затраты на капитальные/ППР ремонты | C23: тыс.вал/г | E23: 0 | F23: 0 | G23: 410.928 | H23: 652.532 | I23: 158.405 | J23: 339.483 | K23: 71.445 | L23: 721.657 | M23: 497.888 | N23: 0
B24: Сервис (трудозатраты) — ТО | C24: тыс.вал/г | E24: 48.632 | F24: 46.483 | G24: 46.483 | H24: 46.483 | I24: 46.483 | J24: 46.483 | K24: 46.483 | L24: 46.483 | M24: 46.483 | N24: 46.483
B25: Сервис (трудозатраты) — ремонты | C25: тыс.вал/г | E25: 17.55 | F25: 44.33 | G25: 66.17 | H25: 81.51 | I25: 58.5 | J25: 106.99 | K25: 83.85 | L25: 98.28 | M25: 145.47 | N25: 157.17
B27: Строки 18–24 — ввод (жёлтое): простои и затраты ТОиР по годам, в валюте (см. «Валюта затрат ТОиР»). Пересчёт в рубли — в «Денежном потоке» по курсу с листа «Параметры». Данные примера — «в расчёте» из 000_БСЛ-2027 (карьер «Сухой Лог»). «Рваный» график капремонтов по годам учитывается дисконтированием.

Sheet Данные по годам
B1: ПОГОДОВЫЕ ДАННЫЕ ЭКСПЛУАТАЦИИ (СВОДКА)
B2: Автоматически из листов «Поставщик 1…6». Правьте данные там, здесь — только просмотр.
B4: Значения ТЯНУТСЯ из листов «Поставщик 1…6» (КТГ и ИТОГО ТОиР — авто). Чтобы изменить данные по машине — откройте её лист и правьте жёлтые ячейки; сводка и расчёт обновятся сами.
B5: Показатель | C5: Ед. | D5: Валюта | E5: год 1 | F5: год 2 | G5: год 3 | H5: год 4 | I5: год 5 | J5: год 6 | K5: год 7 | L5: год 8 | M5: год 9 | N5: год 10
B6: ="Вариант 1: "&'Ввод данных'!D7 -> Вариант 1: NHL NTE 240
B7: КТГ (техготовность) | C7: коэф. | E7: ='Поставщик 1'!E11 -> 0.9376 | F7: ='Поставщик 1'!F11 -> 0.9304 | G7: ='Поставщик 1'!G11 -> 0.9209 | H7: ='Поставщик 1'!H11 -> 0.9084 | I7: ='Поставщик 1'!I11 -> 0.9333 | J7: ='Поставщик 1'!J11 -> 0.9217 | K7: ='Поставщик 1'!K11 -> 0.9313 | L7: ='Поставщик 1'!L11 -> 0.9111 | ... N7: ='Поставщик 1'!N11 -> 0.9322
B8: Затраты на ТОиР и сервис | C8: тыс.вал/г | D8: ='Поставщик 1'!$D$5 -> CNY | E8: ='Поставщик 1'!E17 -> 470.705 | F8: ='Поставщик 1'!F17 -> 654.097 | G8: ='Поставщик 1'!G17 -> 3875.408 | H8: ='Поставщик 1'!H17 -> 2060.956 | I8: ='Поставщик 1'!I17 -> 687.317 | J8: ='Поставщик 1'!J17 -> 3784.574 | K8: ='Поставщик 1'!K17 -> 637.163 | L8: ='Поставщик 1'!L17 -> 2184.222 | ... N8: ='Поставщик 1'!N17 -> 541.468
B9: ="Вариант 2: "&'Ввод данных'!E7 -> Вариант 2: Estar ESDE240 (ГПБ К)
B10: КТГ (техготовность) | C10: коэф. | E10: ='Поставщик 2'!E11 -> 0.9116 | F10: ='Поставщик 2'!F11 -> 0.8956 | G10: ='Поставщик 2'!G11 -> 0.8493 | H10: ='Поставщик 2'!H11 -> 0.806 | I10: ='Поставщик 2'!I11 -> 0.899 | J10: ='Поставщик 2'!J11 -> 0.8221 | K10: ='Поставщик 2'!K11 -> 0.8886 | L10: ='Поставщик 2'!L11 -> 0.8107 | ... N10: ='Поставщик 2'!N11 -> 0.834
B11: Затраты на ТОиР и сервис | C11: тыс.вал/г | D11: ='Поставщик 2'!$D$5 -> USD | E11: ='Поставщик 2'!E17 -> 180.53 | F11: ='Поставщик 2'!F17 -> 276.729 | G11: ='Поставщик 2'!G17 -> 928.14 | H11: ='Поставщик 2'!H17 -> 2751.339 | I11: ='Поставщик 2'!I17 -> 184.233 | J11: ='Поставщик 2'!J17 -> 1024.339 | K11: ='Поставщик 2'!K17 -> 180.53 | L11: ='Поставщик 2'!L17 -> 2751.339 | ... N11: ='Поставщик 2'!N17 -> 180.53
B12: ="Вариант 3: "&'Ввод данных'!F7 -> Вариант 3: SANY SET240S
B13: КТГ (техготовность) | C13: коэф. | E13: ='Поставщик 3'!E11 -> 0.9357 | F13: ='Поставщик 3'!F11 -> 0.9026 | G13: ='Поставщик 3'!G11 -> 0.8659 | H13: ='Поставщик 3'!H11 -> 0.904 | I13: ='Поставщик 3'!I11 -> 0.85 | J13: ='Поставщик 3'!J11 -> 0.904 | K13: ='Поставщик 3'!K11 -> 0.8659 | L13: ='Поставщик 3'!L11 -> 0.904 | ... N13: ='Поставщик 3'!N11 -> 0.885
B14: Затраты на ТОиР и сервис | C14: тыс.вал/г | D14: ='Поставщик 3'!$D$5 -> USD | E14: ='Поставщик 3'!E17 -> 135.348 | F14: ='Поставщик 3'!F17 -> 211.267 | G14: ='Поставщик 3'!G17 -> 597.961 | H14: ='Поставщик 3'!H17 -> 305.142 | I14: ='Поставщик 3'!I17 -> 973.937 | J14: ='Поставщик 3'!J17 -> 741.259 | K14: ='Поставщик 3'!K17 -> 267.376 | L14: ='Поставщик 3'!L17 -> 268.933 | ... N14: ='Поставщик 3'!N17 -> 196.001
B15: ="Вариант 4: "&'Ввод данных'!G7 -> Вариант 4: TZCO TZE240
B16: КТГ (техготовность) | C16: коэф. | E16: ='Поставщик 4'!E11 -> 0.9096 | F16: ='Поставщик 4'!F11 -> 0.8842 | G16: ='Поставщик 4'!G11 -> 0.774 | H16: ='Поставщик 4'!H11 -> 0.8842 | I16: ='Поставщик 4'!I11 -> 0.9096 | J16: ='Поставщик 4'!J11 -> 0.748 | K16: ='Поставщик 4'!K11 -> 0.9096 | L16: ='Поставщик 4'!L11 -> 0.8842 | ... N16: ='Поставщик 4'!N11 -> 0.8842
B17: Затраты на ТОиР и сервис | C17: тыс.вал/г | D17: ='Поставщик 4'!$D$5 -> USD | E17: ='Поставщик 4'!E17 -> 299.336 | F17: ='Поставщик 4'!F17 -> 629.573 | G17: ='Поставщик 4'!G17 -> 1881.204 | H17: ='Поставщик 4'!H17 -> 629.573 | I17: ='Поставщик 4'!I17 -> 299.336 | J17: ='Поставщик 4'!J17 -> 2211.44 | K17: ='Поставщик 4'!K17 -> 299.336 | L17: ='Поставщик 4'!L17 -> 629.573 | ... N17: ='Поставщик 4'!N17 -> 629.573
B18: ="Вариант 5: "&'Ввод данных'!H7 -> Вариант 5: БелАЗ 7531 (ГПФК)
B19: КТГ (техготовность) | C19: коэф. | E19: ='Поставщик 5'!E11 -> 0.9083 | F19: ='Поставщик 5'!F11 -> 0.8858 | G19: ='Поставщик 5'!G11 -> 0.8646 | H19: ='Поставщик 5'!H11 -> 0.8748 | I19: ='Поставщик 5'!I11 -> 0.8813 | J19: ='Поставщик 5'!J11 -> 0.8464 | K19: ='Поставщик 5'!K11 -> 0.8971 | L19: ='Поставщик 5'!L11 -> 0.8546 | ... N19: ='Поставщик 5'!N11 -> 0.8611
B20: Затраты на ТОиР и сервис | C20: тыс.вал/г | D20: ='Поставщик 5'!$D$5 -> USD | E20: ='Поставщик 5'!E17 -> 148.047 | F20: ='Поставщик 5'!F17 -> 317.601 | G20: ='Поставщик 5'!G17 -> 572.068 | H20: ='Поставщик 5'!H17 -> 727.006 | I20: ='Поставщик 5'!I17 -> 631.623 | J20: ='Поставщик 5'!J17 -> 688.619 | K20: ='Поставщик 5'!K17 -> 180.495 | L20: ='Поставщик 5'!L17 -> 847.194 | ... N20: ='Поставщик 5'!N17 -> 231.509
B21: ="Вариант 6: "&'Ввод данных'!I7 -> Вариант 6: БелАЗ 7531 (БТЛ)
B22: КТГ (техготовность) | C22: коэф. | E22: ='Поставщик 6'!E11 -> 0.93 | F22: ='Поставщик 6'!F11 -> 0.908 | G22: ='Поставщик 6'!G11 -> 0.899 | H22: ='Поставщик 6'!H11 -> 0.881 | I22: ='Поставщик 6'!I11 -> 0.901 | J22: ='Поставщик 6'!J11 -> 0.87 | K22: ='Поставщик 6'!K11 -> 0.851 | L22: ='Поставщик 6'!L11 -> 0.892 | ... N22: ='Поставщик 6'!N11 -> 0.852
B23: Затраты на ТОиР и сервис | C23: тыс.вал/г | D23: ='Поставщик 6'!$D$5 -> USD | E23: ='Поставщик 6'!E17 -> 130.793 | F23: ='Поставщик 6'!F17 -> 209.013 | G23: ='Поставщик 6'!G17 -> 615.437 | H23: ='Поставщик 6'!H17 -> 911.521 | I23: ='Поставщик 6'!I17 -> 364.664 | J23: ='Поставщик 6'!J17 -> 636.965 | K23: ='Поставщик 6'!K17 -> 323.46 | L23: ='Поставщик 6'!L17 -> 971.727 | ... N23: ='Поставщик 6'!N17 -> 335.154

Sheet Производительность
B1: РАСЧЁТ ПРОИЗВОДИТЕЛЬНОСТИ (транспортный цикл)
B2: Часовая производительность (т/эфф.час) — по времени рейса; полная погодовая таблица — с КТГ по годам.
B4: Показатель | C4: Ед. | D4: ='Ввод данных'!D7 -> NHL NTE 240 | E4: ='Ввод данных'!E7 -> Estar ESDE240 (ГПБ К) | F4: ='Ввод данных'!F7 -> SANY SET240S | G4: ='Ввод данных'!G7 -> TZCO TZE240 | H4: ='Ввод данных'!H7 -> БелАЗ 7531 (ГПФК) | I4: ='Ввод данных'!I7 -> БелАЗ 7531 (БТЛ)
B5: Стоимость в рублях | C5: тыс.руб | D5: ='Ввод данных'!D11*IF('Ввод данных'!D12="CNY",'Параметры'!C20,IF('Ввод данных'!D12="USD",'Параметры'!C21,IF('Ввод данных'!D12="EUR",'Параметры'!C22,1)))+'Ввод данных'!D13 -> 255404 | E5: ='Ввод данных'!E11*IF('Ввод данных'!E12="CNY",'Параметры'!C20,IF('Ввод данных'!E12="USD",'Параметры'!C21,IF('Ввод данных'!E12="EUR",'Параметры'!C22,1)))+'Ввод данных'!E13 -> 263335.8 | F5: ='Ввод данных'!F11*IF('Ввод данных'!F12="CNY",'Параметры'!C20,IF('Ввод данных'!F12="USD",'Параметры'!C21,IF('Ввод данных'!F12="EUR",'Параметры'!C22,1)))+'Ввод данных'!F13 -> 253930.95 | G5: ='Ввод данных'!G11*IF('Ввод данных'!G12="CNY",'Параметры'!C20,IF('Ввод данных'!G12="USD",'Параметры'!C21,IF('Ввод данных'!G12="EUR",'Параметры'!C22,1)))+'Ввод данных'!G13 -> 253930.95 | H5: ='Ввод данных'!H11*IF('Ввод данных'!H12="CNY",'Параметры'!C20,IF('Ввод данных'!H12="USD",'Параметры'!C21,IF('Ввод данных'!H12="EUR",'Параметры'!C22,1)))+'Ввод данных'!H13 -> 300000 | I5: ='Ввод данных'!I11*IF('Ввод данных'!I12="CNY",'Параметры'!C20,IF('Ввод данных'!I12="USD",'Параметры'!C21,IF('Ввод данных'!I12="EUR",'Параметры'!C22,1)))+'Ввод данных'!I13 -> 290000
B6: Время движения (гружёный+порожний) | C6: мин | D6: =2*'Параметры'!C28/'Параметры'!C29*60 -> 16.240071 | E6: =2*'Параметры'!C28/'Параметры'!C29*60 -> 16.240071 | F6: =2*'Параметры'!C28/'Параметры'!C29*60 -> 16.240071 | G6: =2*'Параметры'!C28/'Параметры'!C29*60 -> 16.240071 | H6: =2*'Параметры'!C28/'Параметры'!C29*60 -> 16.240071 | I6: =2*'Параметры'!C28/'Параметры'!C29*60 -> 16.240071
B7: Время рейса | C7: мин | D7: ='Параметры'!C31+D6 -> 24.640071 | E7: ='Параметры'!C31+E6 -> 24.640071 | F7: ='Параметры'!C31+F6 -> 24.640071 | G7: ='Параметры'!C31+G6 -> 24.640071 | H7: ='Параметры'!C31+H6 -> 24.640071 | I7: ='Параметры'!C31+I6 -> 24.640071
B8: Рейсов в час | C8: рейс/час | D8: =60/D7 -> 2.4350579 | E8: =60/E7 -> 2.4350579 | F8: =60/F7 -> 2.4350579 | G8: =60/G7 -> 2.4350579 | H8: =60/H7 -> 2.4350579 | I8: =60/I7 -> 2.4350579
B9: Часовая производительность | C9: т/эфф.час | D9: =D8*'Ввод данных'!D16*'Параметры'!C30 -> 545.66448 | E9: =E8*'Ввод данных'!E16*'Параметры'!C30 -> 506.3613 | F9: =F8*'Ввод данных'!F16*'Параметры'!C30 -> 518.26628 | G9: =G8*'Ввод данных'!G16*'Параметры'!C30 -> 531.77135 | H9: =H8*'Ввод данных'!H16*'Параметры'!C30 -> 553.32965 | I9: =I8*'Ввод данных'!I16*'Параметры'!C30 -> 553.32965
B10: КИО (1-й год) | C10: коэф. | D10: ='Данные по годам'!E7*(1-102.38/(60*'Параметры'!C27)) -> 0.80427849 | E10: ='Данные по годам'!E10*(1-102.38/(60*'Параметры'!C27)) -> 0.78197554 | F10: ='Данные по годам'!E13*(1-102.38/(60*'Параметры'!C27)) -> 0.80264866 | G10: ='Данные по годам'!E16*(1-102.38/(60*'Параметры'!C27)) -> 0.78025993 | H10: ='Данные по годам'!E19*(1-102.38/(60*'Параметры'!C27)) -> 0.77914479 | I10: ='Данные по годам'!E22*(1-102.38/(60*'Параметры'!C27)) -> 0.79775917
B12: ПОГОДОВАЯ ПРОИЗВОДИТЕЛЬНОСТЬ (КТГ по годам из «Данные по годам»; часовая производительность — из цикла выше)
B13: Показатель | C13: Ед. | E13: год 1 | F13: год 2 | G13: год 3 | H13: год 4 | I13: год 5 | J13: год 6 | K13: год 7 | L13: год 8 | M13: год 9 | N13: год 10
B14: ="Вариант 1: "&'Ввод данных'!D7 -> Вариант 1: NHL NTE 240
B15: КТГ (по годам) | C15: коэф. | E15: ='Данные по годам'!E7 -> 0.9376 | F15: ='Данные по годам'!F7 -> 0.9304 | G15: ='Данные по годам'!G7 -> 0.9209 | H15: ='Данные по годам'!H7 -> 0.9084 | I15: ='Данные по годам'!I7 -> 0.9333 | J15: ='Данные по годам'!J7 -> 0.9217 | K15: ='Данные по годам'!K7 -> 0.9313 | L15: ='Данные по годам'!L7 -> 0.9111 | ... N15: ='Данные по годам'!N7 -> 0.9322
B16: КИО | C16: коэф. | E16: =E15*(1-102.38/(60*'Параметры'!C27)) -> 0.80427849 | F16: =F15*(1-102.38/(60*'Параметры'!C27)) -> 0.79810229 | G16: =G15*(1-102.38/(60*'Параметры'!C27)) -> 0.78995314 | H16: =H15*(1-102.38/(60*'Параметры'!C27)) -> 0.77923057 | I16: =I15*(1-102.38/(60*'Параметры'!C27)) -> 0.80058993 | J16: =J15*(1-102.38/(60*'Параметры'!C27)) -> 0.79063938 | K16: =K15*(1-102.38/(60*'Параметры'!C27)) -> 0.79887431 | L16: =L15*(1-102.38/(60*'Параметры'!C27)) -> 0.78154664 | M16: =M15*(1-102.38/(60*'Параметры'!C27)) -> 0.78669348 | N16: =N15*(1-102.38/(60*'Параметры'!C27)) -> 0.79964634
B17: Эффективное время | C17: час/год | E17: ='Параметры'!C26*E16 -> 7045.4796 | F17: ='Параметры'!C26*F16 -> 6991.3761 | G17: ='Параметры'!C26*G16 -> 6919.9895 | H17: ='Параметры'!C26*H16 -> 6826.0598 | I17: ='Параметры'!C26*I16 -> 7013.1677 | J17: ='Параметры'!C26*J16 -> 6926.001 | K17: ='Параметры'!C26*K16 -> 6998.139 | L17: ='Параметры'!C26*L16 -> 6846.3486 | M17: ='Параметры'!C26*M16 -> 6891.4348 | N17: ='Параметры'!C26*N16 -> 7004.9019
B18: Объём перевозки | C18: тыс.т | E18: ='Производительность'!D9*E17/1000 -> 3844.4679 | F18: ='Производительность'!D9*F17/1000 -> 3814.9456 | G18: ='Производительность'!D9*G17/1000 -> 3775.9924 | H18: ='Производительность'!D9*H17/1000 -> 3724.7383 | I18: ='Производительность'!D9*I17/1000 -> 3826.8365 | J18: ='Производительность'!D9*J17/1000 -> 3779.2727 | K18: ='Производительность'!D9*K17/1000 -> 3818.6359 | L18: ='Производительность'!D9*L17/1000 -> 3735.8092 | M18: ='Производительность'!D9*M17/1000 -> 3760.4112 | N18: ='Производительность'!D9*N17/1000 -> 3822.3262
B19: Грузооборот | C19: тыс.ткм | E19: =E18*'Параметры'!C28 -> 11685.645 | F19: =F18*'Параметры'!C28 -> 11595.909 | G19: =G18*'Параметры'!C28 -> 11477.507 | H19: =H18*'Параметры'!C28 -> 11321.715 | I19: =I18*'Параметры'!C28 -> 11632.052 | J19: =J18*'Параметры'!C28 -> 11487.477 | K19: =K18*'Параметры'!C28 -> 11607.126 | L19: =L18*'Параметры'!C28 -> 11355.366 | M19: =M18*'Параметры'!C28 -> 11430.146 | N19: =N18*'Параметры'!C28 -> 11618.343
B20: Пробег | C20: тыс.км | E20: ='Производительность'!D8*E17*2*'Параметры'!C28/1000 -> 104.29567 | F20: ='Производительность'!D8*F17*2*'Параметры'!C28/1000 -> 103.49477 | G20: ='Производительность'!D8*G17*2*'Параметры'!C28/1000 -> 102.43802 | H20: ='Производительность'!D8*H17*2*'Параметры'!C28/1000 -> 101.04755 | I20: ='Производительность'!D8*I17*2*'Параметры'!C28/1000 -> 103.81735 | J20: ='Производительность'!D8*J17*2*'Параметры'!C28/1000 -> 102.52701 | K20: ='Производительность'!D8*K17*2*'Параметры'!C28/1000 -> 103.59488 | L20: ='Производительность'!D8*L17*2*'Параметры'!C28/1000 -> 101.34789 | M20: ='Производительность'!D8*M17*2*'Параметры'!C28/1000 -> 102.01532 | N20: ='Производительность'!D8*N17*2*'Параметры'!C28/1000 -> 103.69499
B22: ="Вариант 2: "&'Ввод данных'!E7 -> Вариант 2: Estar ESDE240 (ГПБ К)
B23: КТГ (по годам) | C23: коэф. | E23: ='Данные по годам'!E10 -> 0.9116 | F23: ='Данные по годам'!F10 -> 0.8956 | G23: ='Данные по годам'!G10 -> 0.8493 | H23: ='Данные по годам'!H10 -> 0.806 | I23: ='Данные по годам'!I10 -> 0.899 | J23: ='Данные по годам'!J10 -> 0.8221 | K23: ='Данные по годам'!K10 -> 0.8886 | L23: ='Данные по годам'!L10 -> 0.8107 | ... N23: ='Данные по годам'!N10 -> 0.834
B24: КИО | C24: коэф. | E24: =E23*(1-102.38/(60*'Параметры'!C27)) -> 0.78197554 | F24: =F23*(1-102.38/(60*'Параметры'!C27)) -> 0.76825066 | G24: =G23*(1-102.38/(60*'Параметры'!C27)) -> 0.72853426 | H24: =H23*(1-102.38/(60*'Параметры'!C27)) -> 0.69139128 | I24: =I23*(1-102.38/(60*'Параметры'!C27)) -> 0.77116719 | J24: =J23*(1-102.38/(60*'Параметры'!C27)) -> 0.70520195 | K24: =K23*(1-102.38/(60*'Параметры'!C27)) -> 0.76224602 | L24: =L23*(1-102.38/(60*'Параметры'!C27)) -> 0.69542296 | M24: =M23*(1-102.38/(60*'Параметры'!C27)) -> 0.73445312 | N24: =N23*(1-102.38/(60*'Параметры'!C27)) -> 0.71540983
B25: Эффективное время | C25: час/год | E25: ='Параметры'!C26*E24 -> 6850.1058 | F25: ='Параметры'!C26*F24 -> 6729.8757 | G25: ='Параметры'!C26*G24 -> 6381.9601 | H25: ='Параметры'!C26*H24 -> 6056.5876 | I25: ='Параметры'!C26*I24 -> 6755.4246 | J25: ='Параметры'!C26*J24 -> 6177.5691 | K25: ='Параметры'!C26*K24 -> 6677.2751 | L25: ='Параметры'!C26*L24 -> 6091.9052 | M25: ='Параметры'!C26*M24 -> 6433.8093 | N25: ='Параметры'!C26*N24 -> 6266.9901
B26: Объём перевозки | C26: тыс.т | E26: ='Производительность'!E9*E25/1000 -> 3468.6285 | F26: ='Производительность'!E9*F25/1000 -> 3407.7487 | G26: ='Производительность'!E9*G25/1000 -> 3231.5776 | H26: ='Производительность'!E9*H25/1000 -> 3066.8216 | I26: ='Производительность'!E9*I25/1000 -> 3420.6856 | J26: ='Производительность'!E9*J25/1000 -> 3128.0819 | K26: ='Производительность'!E9*K25/1000 -> 3381.1137 | L26: ='Производительность'!E9*L25/1000 -> 3084.705 | M26: ='Производительность'!E9*M25/1000 -> 3257.8321 | N26: ='Производительность'!E9*N25/1000 -> 3173.3613
B27: Грузооборот | C27: тыс.ткм | E27: =E26*'Параметры'!C28 -> 10543.243 | F27: =F26*'Параметры'!C28 -> 10358.193 | G27: =G26*'Параметры'!C28 -> 9822.7034 | H27: =H26*'Параметры'!C28 -> 9321.9109 | I27: =I26*'Параметры'!C28 -> 10397.516 | J27: =J26*'Параметры'!C28 -> 9508.1178 | K27: =K26*'Параметры'!C28 -> 10277.233 | L27: =L26*'Параметры'!C28 -> 9376.2695 | M27: =M26*'Параметры'!C28 -> 9902.5064 | N27: =N26*'Параметры'!C28 -> 9645.749
B28: Пробег | C28: тыс.км | E28: ='Производительность'!E8*E25*2*'Параметры'!C28/1000 -> 101.40351 | F28: ='Производительность'!E8*F25*2*'Параметры'!C28/1000 -> 99.623723 | G28: ='Производительность'!E8*G25*2*'Параметры'!C28/1000 -> 94.473457 | H28: ='Производительность'!E8*H25*2*'Параметры'!C28/1000 -> 89.656901 | I28: ='Производительность'!E8*I25*2*'Параметры'!C28/1000 -> 100.00193 | J28: ='Производительность'!E8*J25*2*'Параметры'!C28/1000 -> 91.447815 | K28: ='Производительность'!E8*K25*2*'Параметры'!C28/1000 -> 98.845065 | L28: ='Производительность'!E8*L25*2*'Параметры'!C28/1000 -> 90.179715 | M28: ='Производительность'!E8*M25*2*'Параметры'!C28/1000 -> 95.240991 | N28: ='Производительность'!E8*N25*2*'Параметры'!C28/1000 -> 92.771533
B30: ="Вариант 3: "&'Ввод данных'!F7 -> Вариант 3: SANY SET240S
B31: КТГ (по годам) | C31: коэф. | E31: ='Данные по годам'!E13 -> 0.9357 | F31: ='Данные по годам'!F13 -> 0.9026 | G31: ='Данные по годам'!G13 -> 0.8659 | H31: ='Данные по годам'!H13 -> 0.904 | I31: ='Данные по годам'!I13 -> 0.85 | J31: ='Данные по годам'!J13 -> 0.904 | K31: ='Данные по годам'!K13 -> 0.8659 | L31: ='Данные по годам'!L13 -> 0.904 | ... N31: ='Данные по годам'!N13 -> 0.885
B32: КИО | C32: коэф. | E32: =E31*(1-102.38/(60*'Параметры'!C27)) -> 0.80264866 | F32: =F31*(1-102.38/(60*'Параметры'!C27)) -> 0.77425529 | G32: =G31*(1-102.38/(60*'Параметры'!C27)) -> 0.74277383 | H32: =H31*(1-102.38/(60*'Параметры'!C27)) -> 0.77545622 | I32: =I31*(1-102.38/(60*'Параметры'!C27)) -> 0.72913472 | J32: =J31*(1-102.38/(60*'Параметры'!C27)) -> 0.77545622 | K32: =K31*(1-102.38/(60*'Параметры'!C27)) -> 0.74277383 | L32: =L31*(1-102.38/(60*'Параметры'!C27)) -> 0.77545622 | M32: =M31*(1-102.38/(60*'Параметры'!C27)) -> 0.72913472 | N32: =N31*(1-102.38/(60*'Параметры'!C27)) -> 0.75915792
B33: Эффективное время | C33: час/год | E33: ='Параметры'!C26*E32 -> 7031.2022 | F33: ='Параметры'!C26*F32 -> 6782.4764 | G33: ='Параметры'!C26*G32 -> 6506.6988 | H33: ='Параметры'!C26*H32 -> 6792.9965 | I33: ='Параметры'!C26*I32 -> 6387.2202 | J33: ='Параметры'!C26*J32 -> 6792.9965 | K33: ='Параметры'!C26*K32 -> 6506.6988 | L33: ='Параметры'!C26*L32 -> 6792.9965 | M33: ='Параметры'!C26*M32 -> 6387.2202 | N33: ='Параметры'!C26*N32 -> 6650.2234
B34: Объём перевозки | C34: тыс.т | E34: ='Производительность'!F9*E33/1000 -> 3644.035 | F34: ='Производительность'!F9*F33/1000 -> 3515.1288 | G34: ='Производительность'!F9*G33/1000 -> 3372.2025 | H34: ='Производительность'!F9*H33/1000 -> 3520.581 | I34: ='Производительность'!F9*I33/1000 -> 3310.2808 | J34: ='Производительность'!F9*J33/1000 -> 3520.581 | K34: ='Производительность'!F9*K33/1000 -> 3372.2025 | L34: ='Производительность'!F9*L33/1000 -> 3520.581 | M34: ='Производительность'!F9*M33/1000 -> 3310.2808 | N34: ='Производительность'!F9*N33/1000 -> 3446.5865
B35: Грузооборот | C35: тыс.ткм | E35: =E34*'Параметры'!C28 -> 11076.409 | F35: =F34*'Параметры'!C28 -> 10684.585 | G35: =G34*'Параметры'!C28 -> 10250.147 | H35: =H34*'Параметры'!C28 -> 10701.158 | I35: =I34*'Параметры'!C28 -> 10061.93 | J35: =J34*'Параметры'!C28 -> 10701.158 | K35: =K34*'Параметры'!C28 -> 10250.147 | L35: =L34*'Параметры'!C28 -> 10701.158 | M35: =M34*'Параметры'!C28 -> 10061.93 | N35: =N34*'Параметры'!C28 -> 10476.244
B36: Пробег | C36: тыс.км | E36: ='Производительность'!F8*E33*2*'Параметры'!C28/1000 -> 104.08432 | F36: ='Производительность'!F8*F33*2*'Параметры'!C28/1000 -> 100.40238 | G36: ='Производительность'!F8*G33*2*'Параметры'!C28/1000 -> 96.319989 | H36: ='Производительность'!F8*H33*2*'Параметры'!C28/1000 -> 100.55811 | I36: ='Производительность'!F8*I33*2*'Параметры'!C28/1000 -> 94.551323 | J36: ='Производительность'!F8*J33*2*'Параметры'!C28/1000 -> 100.55811 | K36: ='Производительность'!F8*K33*2*'Параметры'!C28/1000 -> 96.319989 | L36: ='Производительность'!F8*L33*2*'Параметры'!C28/1000 -> 100.55811 | M36: ='Производительность'!F8*M33*2*'Параметры'!C28/1000 -> 94.551323 | N36: ='Производительность'!F8*N33*2*'Параметры'!C28/1000 -> 98.444613
B38: ="Вариант 4: "&'Ввод данных'!G7 -> Вариант 4: TZCO TZE240
