Workbook

Sheet Методика
B1: МЕТОДИКА: АННУИТЕТ ЗАТРАТ (РУБ/ПОГ.М) НА ВЛАДЕНИЕ БУРОВЫМИ СТАНКАМИ
B2: Пост-налоговый погодовой дисконтированный аннуитет жизненного цикла.
C4: 1. НАЗНАЧЕНИЕ
C5: Экономическое сравнение буровых станков одного класса по удельному аннуитету затрат (руб/пог.м пробуренной скважины, а также руб/м³ взорванной горной массы) за полный срок эксплуатации. Метрика корректно сопоставляет станки с разной ценой, производительностью и структурой затрат. Лучший вариант — минимум руб/пог.м.
C6: 2. ПРОИЗВОДИТЕЛЬНОСТЬ (методика бурения из файла «W час»)
C7: Теоретическая скорость бурения = (0,1 × мощность вращателя) / (2,73^(0,017 × крепость породы) × диаметр_заряда²); диаметр заряда = диаметр долота × коэффициент разбура. Время цикла скважины = бурение + продувка + наращивание + подъём става + разбор + переезд. Скважин/смену = смена / время цикла. Часовая производительность (п.м/час) = скважин/смену × средняя глубина / смена. КИО = КТГ × (1 − простои_смены/(60 × смена)); эффективное время = КФВ × КИО. Годовой объём бурения (тыс.пог.м) = часовая × эффективное время; объём взрывания (тыс.м³) = бурение × выход м³/пог.м.
C8: 3. ПОГОДОВОЙ ДЕНЕЖНЫЙ ПОТОК (10 лет)
C9: Для каждого года считаются: топливо/энергия (эфф.время × расход × цена), ТОиР и сервис (задаются ПО ГОДАМ на листах «Поставщик N» — ТО, текущие и капитальные ремонты; годы капремонтов дают всплеск затрат), буровой инструмент (долота, штанги), расходники, персонал, транспортный налог. Добавляются амортизация (НУ) и налог на прибыль (щит). Операционный поток = база + налог − амортизация. Инвестиции — в год 0, остаточная стоимость — в конце срока.
C10: 4. АННУИТЕТ (ЯДРО)
C11: Потоки дисконтируются и преобразуются в эквивалентный годовой платёж: Аннуитет = NPV затрат / Σ(дисконт-факторов). Инвестиционный аннуитет = (Цена − дисконт. остаточная стоимость) / Σ(дисконт-факторов). Операционный аннуитет — приведённые эксплуатационные затраты после налога. Общий = инвестиционный + операционный. Удельный аннуитет (руб/пог.м) = общий аннуитет / средний годовой объём бурения (пог.м); руб/м³ = руб/пог.м / выход м³ с 1 пог.м.
C12: 5. ПОРЯДОК РАБОТЫ
C13: «Параметры» → «Ввод данных» (цена, физика бурения: мощность вращателя, диаметр, скорость СПО; персонал) → листы «Поставщик 1…5»: по каждой машине задаются КТГ, простои и затраты ТОиР по годам, расход ДТ, буровой инструмент — КТГ и ИТОГО ТОиР считаются автоматически. Сводка «Данные по годам» тянет итоги сама → авторасчёт «Производительность», «Денежный поток», «Расчёт аннуитета» → «Дашборд», «Сравнение», «Аналитика», «Чувствительность». Правки — в листах «Поставщик N» и «Ввод данных».
C14: 6. ДОПУЩЕНИЯ
C15: • Станки сравниваются в одном классе и одной задаче; разница в производительности учтена через руб/пог.м и руб/м³.
... C22: зелёные ячейки — итоговые показатели / лучший вариант

Sheet Дашборд
B1: ИТОГОВЫЙ ДАШБОРД — СРАВНЕНИЕ БУРОВЫХ СТАНКОВ
B2: Ключевые показатели и графики. Данные обновляются автоматически.
B4: КЛЮЧЕВЫЕ ПОКАЗАТЕЛИ
B5: Лучший вариант | C5: Мин. аннуитет, руб/пог.м | D5: Мин. NPV владения, тыс.руб | E5: Разброс аннуитета, руб/пог.м
B6: =INDEX('Ввод данных'!D7:H7,MATCH(MIN('Расчёт аннуитета'!D30:H30),'Расчёт аннуитета'!D30:H30,0)) -> Sunward SWDRT270SM | C6: =MIN('Расчёт аннуитета'!D30:H30) -> 671.5213 | D6: =MIN('Расчёт аннуитета'!D16:H16) -> 424882.78 | E6: =MAX('Расчёт аннуитета'!D30:H30)-MIN('Расчёт аннуитета'!D30:H30) -> 434.46884
B8: РЕЙТИНГ ПО УДЕЛЬНОМУ АННУИТЕТУ (руб/пог.м)
B9: Место | C9: Буровой станок | G9: руб/пог.м | I9: руб/м³
B10: 1 | C10: =INDEX('Ввод данных'!D7:H7,MATCH(SMALL('Расчёт аннуитета'!D30:H30,1),'Расчёт аннуитета'!D30:H30,0)) -> Sunward SWDRT270SM | G10: =SMALL('Расчёт аннуитета'!D30:H30,1) -> 671.5213 | I10: =INDEX('Расчёт аннуитета'!$D$32:$H$32,MATCH(SMALL('Расчёт аннуитета'!D30:H30,1),'Расчёт аннуитета'!D30:H30,0)) -> 13.575686
B11: 2 | C11: =INDEX('Ввод данных'!D7:H7,MATCH(SMALL('Расчёт аннуитета'!D30:H30,2),'Расчёт аннуитета'!D30:H30,0)) -> Sunward SWDRT250SM | G11: =SMALL('Расчёт аннуитета'!D30:H30,2) -> 700.29852 | I11: =INDEX('Расчёт аннуитета'!$D$32:$H$32,MATCH(SMALL('Расчёт аннуитета'!D30:H30,2),'Расчёт аннуитета'!D30:H30,0)) -> 14.157455
B12: 3 | C12: =INDEX('Ввод данных'!D7:H7,MATCH(SMALL('Расчёт аннуитета'!D30:H30,3),'Расчёт аннуитета'!D30:H30,0)) -> Sunward SWDRT270B | G12: =SMALL('Расчёт аннуитета'!D30:H30,3) -> 792.13068 | I12: =INDEX('Расчёт аннуитета'!$D$32:$H$32,MATCH(SMALL('Расчёт аннуитета'!D30:H30,3),'Расчёт аннуитета'!D30:H30,0)) -> 16.013963
B13: 4 | C13: =INDEX('Ввод данных'!D7:H7,MATCH(SMALL('Расчёт аннуитета'!D30:H30,4),'Расчёт аннуитета'!D30:H30,0)) -> HIFO 75D (аналог DM75) | G13: =SMALL('Расчёт аннуитета'!D30:H30,4) -> 948.27828 | I13: =INDEX('Расчёт аннуитета'!$D$32:$H$32,MATCH(SMALL('Расчёт аннуитета'!D30:H30,4),'Расчёт аннуитета'!D30:H30,0)) -> 19.170692
B14: 5 | C14: =INDEX('Ввод данных'!D7:H7,MATCH(SMALL('Расчёт аннуитета'!D30:H30,5),'Расчёт аннуитета'!D30:H30,0)) -> YANGZI DR75 (аналог Epiroc DM75) | G14: =SMALL('Расчёт аннуитета'!D30:H30,5) -> 1105.9901 | I14: =INDEX('Расчёт аннуитета'!$D$32:$H$32,MATCH(SMALL('Расчёт аннуитета'!D30:H30,5),'Расчёт аннуитета'!D30:H30,0)) -> 22.359045

Sheet Параметры
B1: ГЛОБАЛЬНЫЕ ПАРАМЕТРЫ МОДЕЛИ
B2: Единые допущения для всех вариантов. Жёлтые ячейки — ввод.
B4: Финансовые допущения
B5: Параметр | C5: Значение | D5: Ед. | E5: Комментарий
B6: Ставка дисконтирования (WACC) | C6: 0.12 | D6: %/год | E6: Стоимость капитала для приведения к текущей стоимости
B7: Налог на прибыль | C7: 0.25 | D7: % | E7: Формирует налоговый щит на затраты и амортизацию
B8: Срок эксплуатации (горизонт) | C8: 10 | D8: лет | E8: Фиксирован = 10 лет в погодовом движке
B9: Срок амортизации (налоговый учёт) | C9: 5.083 | D9: лет | E9: Линейная; 61 мес ≈ 5,08 года (как в исходной модели)
B10: Цена дизельного топлива | C10: 66.019 | D10: тыс.руб/т | E10: СЛ 2025: 1 274 749,9 тыс.руб / 19 308,86 т
B11: Цена электроэнергии | C11: 5.133 | D11: руб/кВт·ч | E11: Для электрических станков (СЛ 2025)
B13: Эскалация цен (реальный/номинальный рост)
B14: Параметр | C14: Значение | D14: Ед. | E14: Комментарий
B15: Эскалация цены топлива/энергии | C15: 0 | D15: %/год | E15: 0 = данные уже с учётом инфляции
B16: Эскалация ЗЧ/инструмента/расходников | C16: 0 | D16: %/год | E16: ТОиР задаётся по годам напрямую
B17: Эскалация оплаты труда | C17: 0 | D17: %/год | E17: Рост ФОТ экипажей
B19: Курсы валют
B20: Параметр | C20: Значение | D20: Ед. | E20: Комментарий
B21: Курс юаня (CNY) | C21: 11 | D21: руб | E21: Для оборудования из Китая
B22: Курс доллара (USD) | C22: 80 | D22: руб
B23: Курс евро (EUR) | C23: 90 | D23: руб
B25: Параметры производительности (карьер / буровзрывные работы)
B26: Параметр | C26: Значение | D26: Ед. | E26: Комментарий
B27: Календарный фонд времени | C27: 8760 | D27: час/год | E27: 24 ч × 365 дн
B28: Длительность смены | C28: 12 | D28: час | E28: Для пересчёта простоев и производительности
B29: Предел прочности породы на сжатие | C29: 130 | D29: МПа | E29: Влияет на скорость бурения (крепость f)
B30: Коэффициент разбура | C30: 1.05 | D30: коэф. | E30: Диаметр заряда = диаметр долота × k_разбура
B31: Средняя глубина скважин | C31: 16.16 | D31: м | E31: (гл.руда×доля + гл.вскрыша×доля); из «W час»
B32: КПД скорости подъёма става | C32: 0.8 | D32: коэф. | E32: Фактическая скорость = паспортная × КПД
B33: Время продувки скважины | C33: 2 | D33: мин | E33: Часть цикла бурения одной скважины
B34: Время переезда между скважинами | C34: 2.5 | D34: мин | E34: Часть цикла бурения одной скважины
B35: Выход горной массы с 1 пог.м скважины | C35: 49.465 | D35: м³/пог.м | E35: Для пересчёта руб/пог.м → руб/м³ (сетка БВР)
B37: Расчётные финансовые коэффициенты
B38: Параметр | C38: Значение | D38: Ед. | E38: Комментарий
B39: Коэф. аннуитета Σдиск.факторов (r, N) | C39: =IF('Параметры'!C6=0,'Параметры'!C8,(1-(1+'Параметры'!C6)^-'Параметры'!C8)/'Параметры'!C6) -> 5.650223 | D39: коэф. | E39: Сумма дисконт-факторов за срок службы
B40: Коэф. приведённой амортизации | C40: =(1/'Параметры'!C9)*((1-(1+'Параметры'!C6)^-INT('Параметры'!C9))/'Параметры'!C6+('Параметры'!C9-INT('Параметры'!C9))*(1+'Параметры'!C6)^-(INT('Параметры'!C9)+1)) -> 0.71745555 | D40: коэф. | E40: Приведённая амортизация на 1 руб. цены (налог. щит)
B42: Легенда: | D42: — ввод данных
D43: — расчётные показатели

Sheet Ввод данных
B1: ВВОД ИСХОДНЫХ ДАННЫХ ПО БУРОВЫМ СТАНКАМ
B2: Сравнение до 5 машин одного класса. Пример: станки класса 250–270 мм (дизель), карьер «Сухой Лог».
B4: Показатель | C4: Ед. | D4: Станок 1 | E4: Станок 2 | F4: Станок 3 | G4: Станок 4 | H4: Станок 5 | K4: Пояснение
B6: A. ИДЕНТИФИКАЦИЯ
B7: Наименование / модель | C7: — | D7: YANGZI DR75 (аналог Epiroc DM75) | E7: Sunward SWDRT250SM | F7: Sunward SWDRT270SM | G7: Sunward SWDRT270B | H7: HIFO 75D (аналог DM75) | K7: Название варианта
B8: Поставщик | C8: — | D8: Огунвей | E8: Стройкомпозит-Н | F8: Стройкомпозит-Н | G8: Огунвей | H8: Майнинг Солюшнс
B9: Двигатель / привод | C9: — | D9: Cummins QSK19 | E9: CAT C27 | F9: CAT C27 | G9: CAT C27 | H9: CAT C27
B10: B. СТОИМОСТЬ И ОСТАТОЧНАЯ ЦЕНА
B11: Цена за единицу | C11: тыс.вал. | D11: 1900 | E11: 1400 | F11: 1700 | G11: 1700 | H11: 12000 | K11: ⚠ В файле поставщика цена не указана — ОЦЕНКА, уточнить
B12: Валюта цены | C12: — | D12: USD | E12: USD | F12: USD | G12: USD | H12: CNY | K12: CNY / USD / EUR / RUB
B13: Монтаж, доставка, ПНР | C13: тыс.руб | D13: 0 | E13: 0 | F13: 0 | G13: 0 | H13: 0 | K13: Дополнительно к цене
B14: Остаточная стоимость | C14: % от цены | D14: 0 | E14: 0 | F14: 0 | G14: 0 | H14: 0 | K14: Реализация в конце срока (0 = не учитывать)
B15: C. ПРОИЗВОДИТЕЛЬНОСТЬ (физика бурения — лист «W час»)
B16: Мощность вращателя (в расчёте) | C16: кВт | D16: 136 | E16: 148.3 | F16: 173.4 | G16: 173.4 | H16: 136 | K16: Ключевой драйвер скорости бурения
B17: Диаметр долота (в расчёте) | C17: м | D17: 0.267 | E17: 0.267 | F17: 0.267 | G17: 0.267 | H17: 0.267 | K17: Диаметр заряда = диаметр × k_разбура
B18: Скорость подъёма става | C18: м/мин | D18: 51.5 | E18: 60 | F18: 45 | G18: 45 | H18: 51.5 | K18: Влияет на время СПО
B19: Время наращивания/разбора става | C19: мин | D19: 1.5 | E19: 1.5 | F19: 1.5 | G19: 1.5 | H19: 1.5 | K19: На одну операцию
B20: Кол-во операций свинчивания | C20: ед. | D20: 1 | E20: 1 | F20: 1 | G20: 1 | H20: 1 | K20: Штанг на скважину − 1
B21: D. ПРОЧИЕ ГОДОВЫЕ ЗАТРАТЫ И ПАРАМЕТРЫ
B22: Расходы на персонал (экипаж) | C22: тыс.руб/год | D22: 15710 | E22: 15710 | F22: 15710 | G22: 15710 | H22: 15710 | K22: ФОТ+отчисления+прочее на 1 машину
B23: Мощность двигателя (транспортный налог) | C23: л.с. | D23: 800 | E23: 800 | F23: 800 | G23: 800 | H23: 811.69 | K23: × ставку налога (руб/л.с.)
B24: ℹ КТГ, простои, затраты на ТОиР (ТО/ТР/капремонты/сервис), удельный расход ДТ, буровой инструмент и расходники задаются ПО ГОДАМ на листах «Поставщик 1…5». Сводка — на листе «Данные по годам».

Sheet Поставщик 1
B1: ДАННЫЕ ПОСТАВЩИКА — ВАРИАНТ 1 (ТО и Ремонты — модель по узлам)
B2: Жёлтое — ввод. Зелёное — авто (снизу вверх). ИТОГО ТОиР = (ЗЧ ТО + ЗЧ тек.+кап.ремонтов + сервис) × коэф.калибровки; тянется в «Данные по годам».
B4: Буровой станок: | E4: ='Ввод данных'!D7 -> YANGZI DR75 (аналог Epiroc DM75)
B5: Валюта затрат ТОиР: | D5: EUR
B6: Показатель | C6: Ед. | E6: год 1 | F6: год 2 | G6: год 3 | H6: год 4 | I6: год 5 | J6: год 6 | K6: год 7 | L6: год 8 | M6: год 9 | N6: год 10
B7: СВОДКА ПО ГОДАМ (зелёное — авто снизу вверх; тянется в расчёт)
B8: Простои на ТО (авто из интервалов) | C8: ч/год | E8: =E40 -> 636.37233 | F8: =F40 -> 636.37233 | G8: =G40 -> 636.37233 | H8: =H40 -> 636.37233 | I8: =I40 -> 636.37233 | J8: =J40 -> 636.37233 | K8: =K40 -> 636.37233 | L8: =L40 -> 636.37233 | ... N8: =N40 -> 636.37233
B9: Простои в ремонтах (справочно) | C9: ч/год | E9: 200 | F9: 300 | G9: 200 | H9: 300 | I9: 600 | J9: 300 | K9: 900 | L9: 300 | M9: 200 | N9: 900
B10: Ежесменный осмотр (20 мин/смену), справочно | C10: ч/год | E10: =('Параметры'!C27-E8-E9)/'Параметры'!C28*20/60 -> 220.10077 | F10: =('Параметры'!C27-F8-F9)/'Параметры'!C28*20/60 -> 217.32299 | G10: =('Параметры'!C27-G8-G9)/'Параметры'!C28*20/60 -> 220.10077 | H10: =('Параметры'!C27-H8-H9)/'Параметры'!C28*20/60 -> 217.32299 | I10: =('Параметры'!C27-I8-I9)/'Параметры'!C28*20/60 -> 208.98966 | J10: =('Параметры'!C27-J8-J9)/'Параметры'!C28*20/60 -> 217.32299 | K10: =('Параметры'!C27-K8-K9)/'Параметры'!C28*20/60 -> 200.65632 | L10: =('Параметры'!C27-L8-L9)/'Параметры'!C28*20/60 -> 217.32299 | M10: =('Параметры'!C27-M8-M9)/'Параметры'!C28*20/60 -> 220.10077 | N10: =('Параметры'!C27-N8-N9)/'Параметры'!C28*20/60 -> 200.65632
B11: КТГ (техготовность, ВВОД) → «Данные по годам» | C11: коэф. | E11: 0.9309 | F11: 0.9172 | G11: 0.9309 | H11: 0.9172 | I11: 0.8865 | J11: 0.9172 | K11: 0.8506 | L11: 0.9198 | M11: 0.9283 | N11: 0.8532
B12: Затраты на ЗЧ ТО (авто из каталога) | C12: тыс.вал/г | E12: =E85 -> 136.07379 | F12: =F85 -> 136.07379 | G12: =G85 -> 136.07379 | H12: =H85 -> 136.07379 | I12: =I85 -> 136.07379 | J12: =J85 -> 136.07379 | K12: =K85 -> 136.07379 | L12: =L85 -> 136.07379 | ... N12: =N85 -> 136.07379
B13: Затраты на ЗЧ текущих ремонтов (по ресурсу) | C13: тыс.вал/г | E13: =E105 -> 4.50682 | F13: =F105 -> 60.10984 | G13: =G105 -> 145.1624 | H13: =H105 -> 60.10984 | I13: =I105 -> 144.82518 | J13: =J105 -> 67.22701 | K13: =K105 -> 145.21432 | L13: =L105 -> 60.05792 | ... N13: =N105 -> 105.58931
B14: Затраты на ЗЧ капремонтов (по ресурсу) | C14: тыс.вал/г | E14: =E188 -> 7.38238 | F14: =F188 -> 204.26495 | G14: =G188 -> 438.81584 | H14: =H188 -> 434.86339 | I14: =I188 -> 610.36746 | J14: =J188 -> 366.36175 | K14: =K188 -> 590.25823 | L14: =L188 -> 224.66392 | ... N14: =N188 -> 283.30237
B15: Трудозатраты ТО (авто) | C15: ч-час/г | E15: =E47 -> 636.37233 | F15: =F47 -> 636.37233 | G15: =G47 -> 636.37233 | H15: =H47 -> 636.37233 | I15: =I47 -> 636.37233 | J15: =J47 -> 636.37233 | K15: =K47 -> 636.37233 | L15: =L47 -> 636.37233 | ... N15: =N47 -> 636.37233
B16: Трудозатраты текущих ремонтов (авто) | C16: ч-час/г | E16: =E125 -> 48.4 | F16: =F125 -> 174.3 | G16: =G125 -> 228.3 | H16: =H125 -> 174.3 | I16: =I125 -> 220.4 | J16: =J125 -> 255.8 | K16: =K125 -> 226.3 | L16: =L125 -> 176.3 | ... N16: =N125 -> 365.3
B17: Трудозатраты капремонтов (авто) | C17: ч-час/г | E17: =E251 -> 36.6 | F17: =F251 -> 192.66 | G17: =G251 -> 330.45 | H17: =H251 -> 188.56 | I17: =I251 -> 267.75 | J17: =J251 -> 319.96 | K17: =K251 -> 300.71 | L17: =L251 -> 155.4 | ... N17: =N251 -> 102.4
B18: Сервис (трудозатраты ТО+ТР+КР) | C18: тыс.вал/г | E18: =(E15+E16+E17)*$E$23/1000 -> 41.762927 | F18: =(F15+F16+F17)*$E$23/1000 -> 58.086639 | G18: =(G15+G16+G17)*$E$23/1000 -> 69.190076 | H18: =(H15+H16+H17)*$E$23/1000 -> 57.849275 | I18: =(I15+I16+I17)*$E$23/1000 -> 65.102779 | J18: =(J15+J16+J17)*$E$23/1000 -> 70.174848 | K18: =(K15+K16+K17)*$E$23/1000 -> 67.352529 | L18: =(L15+L16+L17)*$E$23/1000 -> 56.045307 | ... N18: =(N15+N16+N17)*$E$23/1000 -> 63.918853
B19: Коэффициент калибровки ИТОГО под ТКП | C19: коэф. | E19: 0.4664
B20: ИТОГО ТОиР → «Данные по годам» | C20: тыс.вал/г | E20: =(E12+E13+E14+E18)*$E$19 -> 88.488167 | F20: =(F12+F13+F14+F18)*$E$19 -> 213.86083 | G20: =(G12+G13+G14+G18)*$E$19 -> 368.10252 | H20: =(H12+H13+H14+H18)*$E$19 -> 321.30123 | I20: =(I12+I13+I14+I18)*$E$19 -> 446.0506 | J20: =(J12+J13+J14+J18)*$E$19 -> 298.42016 | K20: =(K12+K13+K14+K18)*$E$19 -> 437.90243 | L20: =(L12+L13+L14+L18)*$E$19 -> 222.39861 | ... N20: =(N12+N13+N14+N18)*$E$19 -> 274.65565
B21: Удельный расход ДТ / энергии | C21: кг(кВт)/час | E21: 66.3 | F21: 66.3 | G21: 66.3 | H21: 66.3 | I21: 66.3 | J21: 66.3 | K21: 66.3 | L21: 66.3 | M21: 66.3 | N21: 66.3
B23: Ставка сервиса | C23: вал/ч·час | E23: 57.893718
B24: РАСЧЁТ ТО (по интервалам обслуживания), ПО ГОДАМ
B25: Наработка по годам | C25: м/час | E25: 7000 | F25: 7000 | G25: 7000 | H25: 7000 | I25: 7000 | J25: 7000 | K25: 7000 | L25: 7000 | M25: 7000 | N25: 7000
B26: Вид ТО | C26: интервал, м/ч | D26: простой/ТО, ч | E26: персонал
B27: ТО-1 | C27: 250 | D27: 10.9 | E27: 1
B28: ТО-2 | C28: 500 | D28: 13.5 | E28: 1
B29: ТО-3 | C29: 1000 | D29: 12.43 | E29: 1
B30: ТО-4 | C30: 2000 | D30: 5.67 | E30: 1
B31: ТО-5 | C31: 3000 | D31: 10.06 | E31: 1
B32: ТО-6 | C32: 5000 | D32: 8.46 | E32: 1
B34: ТО-1: простои, ч/год | C34: ч | E34: =E$25/$C27*$D27 -> 305.2 | F34: =F$25/$C27*$D27 -> 305.2 | G34: =G$25/$C27*$D27 -> 305.2 | H34: =H$25/$C27*$D27 -> 305.2 | I34: =I$25/$C27*$D27 -> 305.2 | J34: =J$25/$C27*$D27 -> 305.2 | K34: =K$25/$C27*$D27 -> 305.2 | L34: =L$25/$C27*$D27 -> 305.2 | ... N34: =N$25/$C27*$D27 -> 305.2
B35: ТО-2: простои, ч/год | C35: ч | E35: =E$25/$C28*$D28 -> 189 | F35: =F$25/$C28*$D28 -> 189 | G35: =G$25/$C28*$D28 -> 189 | H35: =H$25/$C28*$D28 -> 189 | I35: =I$25/$C28*$D28 -> 189 | J35: =J$25/$C28*$D28 -> 189 | K35: =K$25/$C28*$D28 -> 189 | L35: =L$25/$C28*$D28 -> 189 | ... N35: =N$25/$C28*$D28 -> 189
B36: ТО-3: простои, ч/год | C36: ч | E36: =E$25/$C29*$D29 -> 87.01 | F36: =F$25/$C29*$D29 -> 87.01 | G36: =G$25/$C29*$D29 -> 87.01 | H36: =H$25/$C29*$D29 -> 87.01 | I36: =I$25/$C29*$D29 -> 87.01 | J36: =J$25/$C29*$D29 -> 87.01 | K36: =K$25/$C29*$D29 -> 87.01 | L36: =L$25/$C29*$D29 -> 87.01 | ... N36: =N$25/$C29*$D29 -> 87.01
B37: ТО-4: простои, ч/год | C37: ч | E37: =E$25/$C30*$D30 -> 19.845 | F37: =F$25/$C30*$D30 -> 19.845 | G37: =G$25/$C30*$D30 -> 19.845 | H37: =H$25/$C30*$D30 -> 19.845 | I37: =I$25/$C30*$D30 -> 19.845 | J37: =J$25/$C30*$D30 -> 19.845 | K37: =K$25/$C30*$D30 -> 19.845 | L37: =L$25/$C30*$D30 -> 19.845 | ... N37: =N$25/$C30*$D30 -> 19.845
B38: ТО-5: простои, ч/год | C38: ч | E38: =E$25/$C31*$D31 -> 23.473333 | F38: =F$25/$C31*$D31 -> 23.473333 | G38: =G$25/$C31*$D31 -> 23.473333 | H38: =H$25/$C31*$D31 -> 23.473333 | I38: =I$25/$C31*$D31 -> 23.473333 | J38: =J$25/$C31*$D31 -> 23.473333 | K38: =K$25/$C31*$D31 -> 23.473333 | L38: =L$25/$C31*$D31 -> 23.473333 | ... N38: =N$25/$C31*$D31 -> 23.473333
B39: ТО-6: простои, ч/год | C39: ч | E39: =E$25/$C32*$D32 -> 11.844 | F39: =F$25/$C32*$D32 -> 11.844 | G39: =G$25/$C32*$D32 -> 11.844 | H39: =H$25/$C32*$D32 -> 11.844 | I39: =I$25/$C32*$D32 -> 11.844 | J39: =J$25/$C32*$D32 -> 11.844 | K39: =K$25/$C32*$D32 -> 11.844 | L39: =L$25/$C32*$D32 -> 11.844 | ... N39: =N$25/$C32*$D32 -> 11.844
B40: Итого простои ТО | E40: =SUM(E34:E39) -> 636.37233 | F40: =SUM(F34:F39) -> 636.37233 | G40: =SUM(G34:G39) -> 636.37233 | H40: =SUM(H34:H39) -> 636.37233 | I40: =SUM(I34:I39) -> 636.37233 | J40: =SUM(J34:J39) -> 636.37233 | K40: =SUM(K34:K39) -> 636.37233 | L40: =SUM(L34:L39) -> 636.37233 | ... N40: =SUM(N34:N39) -> 636.37233
B41: ТО-1: чел-часы/год | C41: ч-час | E41: =E34*$E27 -> 305.2 | F41: =F34*$E27 -> 305.2 | G41: =G34*$E27 -> 305.2 | H41: =H34*$E27 -> 305.2 | I41: =I34*$E27 -> 305.2 | J41: =J34*$E27 -> 305.2 | K41: =K34*$E27 -> 305.2 | L41: =L34*$E27 -> 305.2 | ... N41: =N34*$E27 -> 305.2
B42: ТО-2: чел-часы/год | C42: ч-час | E42: =E35*$E28 -> 189 | F42: =F35*$E28 -> 189 | G42: =G35*$E28 -> 189 | H42: =H35*$E28 -> 189 | I42: =I35*$E28 -> 189 | J42: =J35*$E28 -> 189 | K42: =K35*$E28 -> 189 | L42: =L35*$E28 -> 189 | ... N42: =N35*$E28 -> 189
B43: ТО-3: чел-часы/год | C43: ч-час | E43: =E36*$E29 -> 87.01 | F43: =F36*$E29 -> 87.01 | G43: =G36*$E29 -> 87.01 | H43: =H36*$E29 -> 87.01 | I43: =I36*$E29 -> 87.01 | J43: =J36*$E29 -> 87.01 | K43: =K36*$E29 -> 87.01 | L43: =L36*$E29 -> 87.01 | ... N43: =N36*$E29 -> 87.01
...

Sheet Поставщик 2
B1: ДАННЫЕ ПОСТАВЩИКА — ВАРИАНТ 2 (ТО и Ремонты — модель по узлам)
B2: Жёлтое — ввод. Зелёное — авто (снизу вверх). ИТОГО ТОиР = (ЗЧ ТО + ЗЧ тек.+кап.ремонтов + сервис) × коэф.калибровки; тянется в «Данные по годам».
B4: Буровой станок: | E4: ='Ввод данных'!E7 -> Sunward SWDRT250SM
B5: Валюта затрат ТОиР: | D5: EUR
B6: Показатель | C6: Ед. | E6: год 1 | F6: год 2 | G6: год 3 | H6: год 4 | I6: год 5 | J6: год 6 | K6: год 7 | L6: год 8 | M6: год 9 | N6: год 10
B7: СВОДКА ПО ГОДАМ (зелёное — авто снизу вверх; тянется в расчёт)
B8: Простои на ТО (авто из интервалов) | C8: ч/год | E8: =E40 -> 636.37233 | F8: =F40 -> 636.37233 | G8: =G40 -> 636.37233 | H8: =H40 -> 636.37233 | I8: =I40 -> 636.37233 | J8: =J40 -> 636.37233 | K8: =K40 -> 636.37233 | L8: =L40 -> 636.37233 | ... N8: =N40 -> 636.37233
B9: Простои в ремонтах (справочно) | C9: ч/год | E9: 425.645 | F9: 690.645 | G9: 870.645 | H9: 605.645 | I9: 690.645 | J9: 890.645 | K9: 720.645 | L9: 690.645 | M9: 830.645 | N9: 790.645
B10: Ежесменный осмотр (20 мин/смену), справочно | C10: ч/год | E10: =('Параметры'!C27-E8-E9)/'Параметры'!C28*20/60 -> 213.83285 | F10: =('Параметры'!C27-F8-F9)/'Параметры'!C28*20/60 -> 206.47174 | G10: =('Параметры'!C27-G8-G9)/'Параметры'!C28*20/60 -> 201.47174 | H10: =('Параметры'!C27-H8-H9)/'Параметры'!C28*20/60 -> 208.83285 | I10: =('Параметры'!C27-I8-I9)/'Параметры'!C28*20/60 -> 206.47174 | J10: =('Параметры'!C27-J8-J9)/'Параметры'!C28*20/60 -> 200.91619 | K10: =('Параметры'!C27-K8-K9)/'Параметры'!C28*20/60 -> 205.63841 | L10: =('Параметры'!C27-L8-L9)/'Параметры'!C28*20/60 -> 206.47174 | M10: =('Параметры'!C27-M8-M9)/'Параметры'!C28*20/60 -> 202.58285 | N10: =('Параметры'!C27-N8-N9)/'Параметры'!C28*20/60 -> 203.69396
B11: КТГ (техготовность, ВВОД) → «Данные по годам» | C11: коэф. | E11: 0.8948 | F11: 0.8654 | G11: 0.8454 | H11: 0.8748 | I11: 0.8654 | J11: 0.8432 | K11: 0.8621 | L11: 0.8654 | M11: 0.8498 | N11: 0.8543
B12: Затраты на ЗЧ ТО (авто из каталога) | C12: тыс.вал/г | E12: =E85 -> 136.07379 | F12: =F85 -> 136.07379 | G12: =G85 -> 136.07379 | H12: =H85 -> 136.07379 | I12: =I85 -> 136.07379 | J12: =J85 -> 136.07379 | K12: =K85 -> 136.07379 | L12: =L85 -> 136.07379 | ... N12: =N85 -> 136.07379
B13: Затраты на ЗЧ текущих ремонтов (по ресурсу) | C13: тыс.вал/г | E13: =E105 -> 4.50682 | F13: =F105 -> 60.10984 | G13: =G105 -> 145.1624 | H13: =H105 -> 60.10984 | I13: =I105 -> 144.82518 | J13: =J105 -> 67.22701 | K13: =K105 -> 145.21432 | L13: =L105 -> 60.05792 | ... N13: =N105 -> 105.58931
B14: Затраты на ЗЧ капремонтов (по ресурсу) | C14: тыс.вал/г | E14: =E188 -> 7.38238 | F14: =F188 -> 204.26495 | G14: =G188 -> 438.81584 | H14: =H188 -> 434.86339 | I14: =I188 -> 610.36746 | J14: =J188 -> 366.36175 | K14: =K188 -> 590.25823 | L14: =L188 -> 224.66392 | ... N14: =N188 -> 283.30237
B15: Трудозатраты ТО (авто) | C15: ч-час/г | E15: =E47 -> 636.37233 | F15: =F47 -> 636.37233 | G15: =G47 -> 636.37233 | H15: =H47 -> 636.37233 | I15: =I47 -> 636.37233 | J15: =J47 -> 636.37233 | K15: =K47 -> 636.37233 | L15: =L47 -> 636.37233 | ... N15: =N47 -> 636.37233
B16: Трудозатраты текущих ремонтов (авто) | C16: ч-час/г | E16: =E125 -> 48.4 | F16: =F125 -> 174.3 | G16: =G125 -> 228.3 | H16: =H125 -> 174.3 | I16: =I125 -> 220.4 | J16: =J125 -> 255.8 | K16: =K125 -> 226.3 | L16: =L125 -> 176.3 | ... N16: =N125 -> 365.3
B17: Трудозатраты капремонтов (авто) | C17: ч-час/г | E17: =E251 -> 36.6 | F17: =F251 -> 192.66 | G17: =G251 -> 330.45 | H17: =H251 -> 188.56 | I17: =I251 -> 267.75 | J17: =J251 -> 319.96 | K17: =K251 -> 300.71 | L17: =L251 -> 155.4 | ... N17: =N251 -> 102.4
B18: Сервис (трудозатраты ТО+ТР+КР) | C18: тыс.вал/г | E18: =(E15+E16+E17)*$E$23/1000 -> 41.762927 | F18: =(F15+F16+F17)*$E$23/1000 -> 58.086639 | G18: =(G15+G16+G17)*$E$23/1000 -> 69.190076 | H18: =(H15+H16+H17)*$E$23/1000 -> 57.849275 | I18: =(I15+I16+I17)*$E$23/1000 -> 65.102779 | J18: =(J15+J16+J17)*$E$23/1000 -> 70.174848 | K18: =(K15+K16+K17)*$E$23/1000 -> 67.352529 | L18: =(L15+L16+L17)*$E$23/1000 -> 56.045307 | ... N18: =(N15+N16+N17)*$E$23/1000 -> 63.918853
B19: Коэффициент калибровки ИТОГО под ТКП | C19: коэф. | E19: 0.8225
B20: ИТОГО ТОиР → «Данные по годам» | C20: тыс.вал/г | E20: =(E12+E13+E14+E18)*$E$19 -> 156.04957 | F20: =(F12+F13+F14+F18)*$E$19 -> 377.14522 | G20: =(G12+G13+G14+G18)*$E$19 -> 649.15163 | H20: =(H12+H13+H14+H18)*$E$19 -> 566.6172 | I20: =(I12+I13+I14+I18)*$E$19 -> 786.61367 | J20: =(J12+J13+J14+J18)*$E$19 -> 526.26626 | K20: =(K12+K13+K14+K18)*$E$19 -> 772.24432 | L20: =(L12+L13+L14+L18)*$E$19 -> 392.20167 | ... N20: =(N12+N13+N14+N18)*$E$19 -> 484.35735
B21: Удельный расход ДТ / энергии | C21: кг(кВт)/час | E21: 38.7 | F21: 38.7 | G21: 38.7 | H21: 38.7 | I21: 38.7 | J21: 38.7 | K21: 38.7 | L21: 38.7 | M21: 38.7 | N21: 38.7
B23: Ставка сервиса | C23: вал/ч·час | E23: 57.893718
B24: РАСЧЁТ ТО (по интервалам обслуживания), ПО ГОДАМ
B25: Наработка по годам | C25: м/час | E25: 7000 | F25: 7000 | G25: 7000 | H25: 7000 | I25: 7000 | J25: 7000 | K25: 7000 | L25: 7000 | M25: 7000 | N25: 7000
B26: Вид ТО | C26: интервал, м/ч | D26: простой/ТО, ч | E26: персонал
B27: ТО-1 | C27: 250 | D27: 10.9 | E27: 1
B28: ТО-2 | C28: 500 | D28: 13.5 | E28: 1
B29: ТО-3 | C29: 1000 | D29: 12.43 | E29: 1
B30: ТО-4 | C30: 2000 | D30: 5.67 | E30: 1
B31: ТО-5 | C31: 3000 | D31: 10.06 | E31: 1
B32: ТО-6 | C32: 5000 | D32: 8.46 | E32: 1
B34: ТО-1: простои, ч/год | C34: ч | E34: =E$25/$C27*$D27 -> 305.2 | F34: =F$25/$C27*$D27 -> 305.2 | G34: =G$25/$C27*$D27 -> 305.2 | H34: =H$25/$C27*$D27 -> 305.2 | I34: =I$25/$C27*$D27 -> 305.2 | J34: =J$25/$C27*$D27 -> 305.2 | K34: =K$25/$C27*$D27 -> 305.2 | L34: =L$25/$C27*$D27 -> 305.2 | ... N34: =N$25/$C27*$D27 -> 305.2
B35: ТО-2: простои, ч/год | C35: ч | E35: =E$25/$C28*$D28 -> 189 | F35: =F$25/$C28*$D28 -> 189 | G35: =G$25/$C28*$D28 -> 189 | H35: =H$25/$C28*$D28 -> 189 | I35: =I$25/$C28*$D28 -> 189 | J35: =J$25/$C28*$D28 -> 189 | K35: =K$25/$C28*$D28 -> 189 | L35: =L$25/$C28*$D28 -> 189 | ... N35: =N$25/$C28*$D28 -> 189
B36: ТО-3: простои, ч/год | C36: ч | E36: =E$25/$C29*$D29 -> 87.01 | F36: =F$25/$C29*$D29 -> 87.01 | G36: =G$25/$C29*$D29 -> 87.01 | H36: =H$25/$C29*$D29 -> 87.01 | I36: =I$25/$C29*$D29 -> 87.01 | J36: =J$25/$C29*$D29 -> 87.01 | K36: =K$25/$C29*$D29 -> 87.01 | L36: =L$25/$C29*$D29 -> 87.01 | ... N36: =N$25/$C29*$D29 -> 87.01
B37: ТО-4: простои, ч/год | C37: ч | E37: =E$25/$C30*$D30 -> 19.845 | F37: =F$25/$C30*$D30 -> 19.845 | G37: =G$25/$C30*$D30 -> 19.845 | H37: =H$25/$C30*$D30 -> 19.845 | I37: =I$25/$C30*$D30 -> 19.845 | J37: =J$25/$C30*$D30 -> 19.845 | K37: =K$25/$C30*$D30 -> 19.845 | L37: =L$25/$C30*$D30 -> 19.845 | ... N37: =N$25/$C30*$D30 -> 19.845
B38: ТО-5: простои, ч/год | C38: ч | E38: =E$25/$C31*$D31 -> 23.473333 | F38: =F$25/$C31*$D31 -> 23.473333 | G38: =G$25/$C31*$D31 -> 23.473333 | H38: =H$25/$C31*$D31 -> 23.473333 | I38: =I$25/$C31*$D31 -> 23.473333 | J38: =J$25/$C31*$D31 -> 23.473333 | K38: =K$25/$C31*$D31 -> 23.473333 | L38: =L$25/$C31*$D31 -> 23.473333 | ... N38: =N$25/$C31*$D31 -> 23.473333
B39: ТО-6: простои, ч/год | C39: ч | E39: =E$25/$C32*$D32 -> 11.844 | F39: =F$25/$C32*$D32 -> 11.844 | G39: =G$25/$C32*$D32 -> 11.844 | H39: =H$25/$C32*$D32 -> 11.844 | I39: =I$25/$C32*$D32 -> 11.844 | J39: =J$25/$C32*$D32 -> 11.844 | K39: =K$25/$C32*$D32 -> 11.844 | L39: =L$25/$C32*$D32 -> 11.844 | ... N39: =N$25/$C32*$D32 -> 11.844
B40: Итого простои ТО | E40: =SUM(E34:E39) -> 636.37233 | F40: =SUM(F34:F39) -> 636.37233 | G40: =SUM(G34:G39) -> 636.37233 | H40: =SUM(H34:H39) -> 636.37233 | I40: =SUM(I34:I39) -> 636.37233 | J40: =SUM(J34:J39) -> 636.37233 | K40: =SUM(K34:K39) -> 636.37233 | L40: =SUM(L34:L39) -> 636.37233 | ... N40: =SUM(N34:N39) -> 636.37233
B41: ТО-1: чел-часы/год | C41: ч-час | E41: =E34*$E27 -> 305.2 | F41: =F34*$E27 -> 305.2 | G41: =G34*$E27 -> 305.2 | H41: =H34*$E27 -> 305.2 | I41: =I34*$E27 -> 305.2 | J41: =J34*$E27 -> 305.2 | K41: =K34*$E27 -> 305.2 | L41: =L34*$E27 -> 305.2 | ... N41: =N34*$E27 -> 305.2
B42: ТО-2: чел-часы/год | C42: ч-час | E42: =E35*$E28 -> 189 | F42: =F35*$E28 -> 189 | G42: =G35*$E28 -> 189 | H42: =H35*$E28 -> 189 | I42: =I35*$E28 -> 189 | J42: =J35*$E28 -> 189 | K42: =K35*$E28 -> 189 | L42: =L35*$E28 -> 189 | ... N42: =N35*$E28 -> 189
B43: ТО-3: чел-часы/год | C43: ч-час | E43: =E36*$E29 -> 87.01 | F43: =F36*$E29 -> 87.01 | G43: =G36*$E29 -> 87.01 | H43: =H36*$E29 -> 87.01 | I43: =I36*$E29 -> 87.01 | J43: =J36*$E29 -> 87.01 | K43: =K36*$E29 -> 87.01 | L43: =L36*$E29 -> 87.01 | ... N43: =N36*$E29 -> 87.01
...

Sheet Поставщик 3
B1: ДАННЫЕ ПОСТАВЩИКА — ВАРИАНТ 3 (ТО и Ремонты — модель по узлам)
B2: Жёлтое — ввод. Зелёное — авто (снизу вверх). ИТОГО ТОиР = (ЗЧ ТО + ЗЧ тек.+кап.ремонтов + сервис) × коэф.калибровки; тянется в «Данные по годам».
B4: Буровой станок: | E4: ='Ввод данных'!F7 -> Sunward SWDRT270SM
B5: Валюта затрат ТОиР: | D5: EUR
B6: Показатель | C6: Ед. | E6: год 1 | F6: год 2 | G6: год 3 | H6: год 4 | I6: год 5 | J6: год 6 | K6: год 7 | L6: год 8 | M6: год 9 | N6: год 10
B7: СВОДКА ПО ГОДАМ (зелёное — авто снизу вверх; тянется в расчёт)
B8: Простои на ТО (авто из интервалов) | C8: ч/год | E8: =E40 -> 636.37233 | F8: =F40 -> 636.37233 | G8: =G40 -> 636.37233 | H8: =H40 -> 636.37233 | I8: =I40 -> 636.37233 | J8: =J40 -> 636.37233 | K8: =K40 -> 636.37233 | L8: =L40 -> 636.37233 | ... N8: =N40 -> 636.37233
B9: Простои в ремонтах (справочно) | C9: ч/год | E9: 425.645 | F9: 690.645 | G9: 870.645 | H9: 605.645 | I9: 690.645 | J9: 890.645 | K9: 720.645 | L9: 690.645 | M9: 830.645 | N9: 790.645
B10: Ежесменный осмотр (20 мин/смену), справочно | C10: ч/год | E10: =('Параметры'!C27-E8-E9)/'Параметры'!C28*20/60 -> 213.83285 | F10: =('Параметры'!C27-F8-F9)/'Параметры'!C28*20/60 -> 206.47174 | G10: =('Параметры'!C27-G8-G9)/'Параметры'!C28*20/60 -> 201.47174 | H10: =('Параметры'!C27-H8-H9)/'Параметры'!C28*20/60 -> 208.83285 | I10: =('Параметры'!C27-I8-I9)/'Параметры'!C28*20/60 -> 206.47174 | J10: =('Параметры'!C27-J8-J9)/'Параметры'!C28*20/60 -> 200.91619 | K10: =('Параметры'!C27-K8-K9)/'Параметры'!C28*20/60 -> 205.63841 | L10: =('Параметры'!C27-L8-L9)/'Параметры'!C28*20/60 -> 206.47174 | M10: =('Параметры'!C27-M8-M9)/'Параметры'!C28*20/60 -> 202.58285 | N10: =('Параметры'!C27-N8-N9)/'Параметры'!C28*20/60 -> 203.69396
B11: КТГ (техготовность, ВВОД) → «Данные по годам» | C11: коэф. | E11: 0.8948 | F11: 0.8654 | G11: 0.8454 | H11: 0.8748 | I11: 0.8654 | J11: 0.8432 | K11: 0.8621 | L11: 0.8654 | M11: 0.8498 | N11: 0.8543
B12: Затраты на ЗЧ ТО (авто из каталога) | C12: тыс.вал/г | E12: =E85 -> 136.07379 | F12: =F85 -> 136.07379 | G12: =G85 -> 136.07379 | H12: =H85 -> 136.07379 | I12: =I85 -> 136.07379 | J12: =J85 -> 136.07379 | K12: =K85 -> 136.07379 | L12: =L85 -> 136.07379 | ... N12: =N85 -> 136.07379
B13: Затраты на ЗЧ текущих ремонтов (по ресурсу) | C13: тыс.вал/г | E13: =E105 -> 4.50682 | F13: =F105 -> 60.10984 | G13: =G105 -> 145.1624 | H13: =H105 -> 60.10984 | I13: =I105 -> 144.82518 | J13: =J105 -> 67.22701 | K13: =K105 -> 145.21432 | L13: =L105 -> 60.05792 | ... N13: =N105 -> 105.58931
B14: Затраты на ЗЧ капремонтов (по ресурсу) | C14: тыс.вал/г | E14: =E188 -> 7.38238 | F14: =F188 -> 204.26495 | G14: =G188 -> 438.81584 | H14: =H188 -> 434.86339 | I14: =I188 -> 610.36746 | J14: =J188 -> 366.36175 | K14: =K188 -> 590.25823 | L14: =L188 -> 224.66392 | ... N14: =N188 -> 283.30237
B15: Трудозатраты ТО (авто) | C15: ч-час/г | E15: =E47 -> 636.37233 | F15: =F47 -> 636.37233 | G15: =G47 -> 636.37233 | H15: =H47 -> 636.37233 | I15: =I47 -> 636.37233 | J15: =J47 -> 636.37233 | K15: =K47 -> 636.37233 | L15: =L47 -> 636.37233 | ... N15: =N47 -> 636.37233
B16: Трудозатраты текущих ремонтов (авто) | C16: ч-час/г | E16: =E125 -> 48.4 | F16: =F125 -> 174.3 | G16: =G125 -> 228.3 | H16: =H125 -> 174.3 | I16: =I125 -> 220.4 | J16: =J125 -> 255.8 | K16: =K125 -> 226.3 | L16: =L125 -> 176.3 | ... N16: =N125 -> 365.3
B17: Трудозатраты капремонтов (авто) | C17: ч-час/г | E17: =E251 -> 36.6 | F17: =F251 -> 192.66 | G17: =G251 -> 330.45 | H17: =H251 -> 188.56 | I17: =I251 -> 267.75 | J17: =J251 -> 319.96 | K17: =K251 -> 300.71 | L17: =L251 -> 155.4 | ... N17: =N251 -> 102.4
B18: Сервис (трудозатраты ТО+ТР+КР) | C18: тыс.вал/г | E18: =(E15+E16+E17)*$E$23/1000 -> 41.762927 | F18: =(F15+F16+F17)*$E$23/1000 -> 58.086639 | G18: =(G15+G16+G17)*$E$23/1000 -> 69.190076 | H18: =(H15+H16+H17)*$E$23/1000 -> 57.849275 | I18: =(I15+I16+I17)*$E$23/1000 -> 65.102779 | J18: =(J15+J16+J17)*$E$23/1000 -> 70.174848 | K18: =(K15+K16+K17)*$E$23/1000 -> 67.352529 | L18: =(L15+L16+L17)*$E$23/1000 -> 56.045307 | ... N18: =(N15+N16+N17)*$E$23/1000 -> 63.918853
B19: Коэффициент калибровки ИТОГО под ТКП | C19: коэф. | E19: 0.8225
B20: ИТОГО ТОиР → «Данные по годам» | C20: тыс.вал/г | E20: =(E12+E13+E14+E18)*$E$19 -> 156.04957 | F20: =(F12+F13+F14+F18)*$E$19 -> 377.14522 | G20: =(G12+G13+G14+G18)*$E$19 -> 649.15163 | H20: =(H12+H13+H14+H18)*$E$19 -> 566.6172 | I20: =(I12+I13+I14+I18)*$E$19 -> 786.61367 | J20: =(J12+J13+J14+J18)*$E$19 -> 526.26626 | K20: =(K12+K13+K14+K18)*$E$19 -> 772.24432 | L20: =(L12+L13+L14+L18)*$E$19 -> 392.20167 | ... N20: =(N12+N13+N14+N18)*$E$19 -> 484.35735
B21: Удельный расход ДТ / энергии | C21: кг(кВт)/час | E21: 50.1 | F21: 50.1 | G21: 50.1 | H21: 50.1 | I21: 50.1 | J21: 50.1 | K21: 50.1 | L21: 50.1 | M21: 50.1 | N21: 50.1
B23: Ставка сервиса | C23: вал/ч·час | E23: 57.893718
B24: РАСЧЁТ ТО (по интервалам обслуживания), ПО ГОДАМ
B25: Наработка по годам | C25: м/час | E25: 7000 | F25: 7000 | G25: 7000 | H25: 7000 | I25: 7000 | J25: 7000 | K25: 7000 | L25: 7000 | M25: 7000 | N25: 7000
B26: Вид ТО | C26: интервал, м/ч | D26: простой/ТО, ч | E26: персонал
B27: ТО-1 | C27: 250 | D27: 10.9 | E27: 1
B28: ТО-2 | C28: 500 | D28: 13.5 | E28: 1
B29: ТО-3 | C29: 1000 | D29: 12.43 | E29: 1
B30: ТО-4 | C30: 2000 | D30: 5.67 | E30: 1
B31: ТО-5 | C31: 3000 | D31: 10.06 | E31: 1
B32: ТО-6 | C32: 5000 | D32: 8.46 | E32: 1
B34: ТО-1: простои, ч/год | C34: ч | E34: =E$25/$C27*$D27 -> 305.2 | F34: =F$25/$C27*$D27 -> 305.2 | G34: =G$25/$C27*$D27 -> 305.2 | H34: =H$25/$C27*$D27 -> 305.2 | I34: =I$25/$C27*$D27 -> 305.2 | J34: =J$25/$C27*$D27 -> 305.2 | K34: =K$25/$C27*$D27 -> 305.2 | L34: =L$25/$C27*$D27 -> 305.2 | ... N34: =N$25/$C27*$D27 -> 305.2
B35: ТО-2: простои, ч/год | C35: ч | E35: =E$25/$C28*$D28 -> 189 | F35: =F$25/$C28*$D28 -> 189 | G35: =G$25/$C28*$D28 -> 189 | H35: =H$25/$C28*$D28 -> 189 | I35: =I$25/$C28*$D28 -> 189 | J35: =J$25/$C28*$D28 -> 189 | K35: =K$25/$C28*$D28 -> 189 | L35: =L$25/$C28*$D28 -> 189 | ... N35: =N$25/$C28*$D28 -> 189
B36: ТО-3: простои, ч/год | C36: ч | E36: =E$25/$C29*$D29 -> 87.01 | F36: =F$25/$C29*$D29 -> 87.01 | G36: =G$25/$C29*$D29 -> 87.01 | H36: =H$25/$C29*$D29 -> 87.01 | I36: =I$25/$C29*$D29 -> 87.01 | J36: =J$25/$C29*$D29 -> 87.01 | K36: =K$25/$C29*$D29 -> 87.01 | L36: =L$25/$C29*$D29 -> 87.01 | ... N36: =N$25/$C29*$D29 -> 87.01
B37: ТО-4: простои, ч/год | C37: ч | E37: =E$25/$C30*$D30 -> 19.845 | F37: =F$25/$C30*$D30 -> 19.845 | G37: =G$25/$C30*$D30 -> 19.845 | H37: =H$25/$C30*$D30 -> 19.845 | I37: =I$25/$C30*$D30 -> 19.845 | J37: =J$25/$C30*$D30 -> 19.845 | K37: =K$25/$C30*$D30 -> 19.845 | L37: =L$25/$C30*$D30 -> 19.845 | ... N37: =N$25/$C30*$D30 -> 19.845
B38: ТО-5: простои, ч/год | C38: ч | E38: =E$25/$C31*$D31 -> 23.473333 | F38: =F$25/$C31*$D31 -> 23.473333 | G38: =G$25/$C31*$D31 -> 23.473333 | H38: =H$25/$C31*$D31 -> 23.473333 | I38: =I$25/$C31*$D31 -> 23.473333 | J38: =J$25/$C31*$D31 -> 23.473333 | K38: =K$25/$C31*$D31 -> 23.473333 | L38: =L$25/$C31*$D31 -> 23.473333 | ... N38: =N$25/$C31*$D31 -> 23.473333
B39: ТО-6: простои, ч/год | C39: ч | E39: =E$25/$C32*$D32 -> 11.844 | F39: =F$25/$C32*$D32 -> 11.844 | G39: =G$25/$C32*$D32 -> 11.844 | H39: =H$25/$C32*$D32 -> 11.844 | I39: =I$25/$C32*$D32 -> 11.844 | J39: =J$25/$C32*$D32 -> 11.844 | K39: =K$25/$C32*$D32 -> 11.844 | L39: =L$25/$C32*$D32 -> 11.844 | ... N39: =N$25/$C32*$D32 -> 11.844
B40: Итого простои ТО | E40: =SUM(E34:E39) -> 636.37233 | F40: =SUM(F34:F39) -> 636.37233 | G40: =SUM(G34:G39) -> 636.37233 | H40: =SUM(H34:H39) -> 636.37233 | I40: =SUM(I34:I39) -> 636.37233 | J40: =SUM(J34:J39) -> 636.37233 | K40: =SUM(K34:K39) -> 636.37233 | L40: =SUM(L34:L39) -> 636.37233 | ... N40: =SUM(N34:N39) -> 636.37233
B41: ТО-1: чел-часы/год | C41: ч-час | E41: =E34*$E27 -> 305.2 | F41: =F34*$E27 -> 305.2 | G41: =G34*$E27 -> 305.2 | H41: =H34*$E27 -> 305.2 | I41: =I34*$E27 -> 305.2 | J41: =J34*$E27 -> 305.2 | K41: =K34*$E27 -> 305.2 | L41: =L34*$E27 -> 305.2 | ... N41: =N34*$E27 -> 305.2
B42: ТО-2: чел-часы/год | C42: ч-час | E42: =E35*$E28 -> 189 | F42: =F35*$E28 -> 189 | G42: =G35*$E28 -> 189 | H42: =H35*$E28 -> 189 | I42: =I35*$E28 -> 189 | J42: =J35*$E28 -> 189 | K42: =K35*$E28 -> 189 | L42: =L35*$E28 -> 189 | ... N42: =N35*$E28 -> 189
B43: ТО-3: чел-часы/год | C43: ч-час | E43: =E36*$E29 -> 87.01 | F43: =F36*$E29 -> 87.01 | G43: =G36*$E29 -> 87.01 | H43: =H36*$E29 -> 87.01 | I43: =I36*$E29 -> 87.01 | J43: =J36*$E29 -> 87.01 | K43: =K36*$E29 -> 87.01 | L43: =L36*$E29 -> 87.01 | ... N43: =N36*$E29 -> 87.01
...

Sheet Поставщик 4
B1: ДАННЫЕ ПОСТАВЩИКА — ВАРИАНТ 4 (ТО и Ремонты — модель по узлам)
B2: Жёлтое — ввод. Зелёное — авто (снизу вверх). ИТОГО ТОиР = (ЗЧ ТО + ЗЧ тек.+кап.ремонтов + сервис) × коэф.калибровки; тянется в «Данные по годам».
B4: Буровой станок: | E4: ='Ввод данных'!G7 -> Sunward SWDRT270B
B5: Валюта затрат ТОиР: | D5: EUR
B6: Показатель | C6: Ед. | E6: год 1 | F6: год 2 | G6: год 3 | H6: год 4 | I6: год 5 | J6: год 6 | K6: год 7 | L6: год 8 | M6: год 9 | N6: год 10
B7: СВОДКА ПО ГОДАМ (зелёное — авто снизу вверх; тянется в расчёт)
B8: Простои на ТО (авто из интервалов) | C8: ч/год | E8: =E40 -> 636.37233 | F8: =F40 -> 636.37233 | G8: =G40 -> 636.37233 | H8: =H40 -> 636.37233 | I8: =I40 -> 636.37233 | J8: =J40 -> 636.37233 | K8: =K40 -> 636.37233 | L8: =L40 -> 636.37233 | ... N8: =N40 -> 636.37233
B9: Простои в ремонтах (справочно) | C9: ч/год | E9: 109.67 | F9: 109.67 | G9: 109.67 | H9: 109.67 | I9: 109.67 | J9: 109.67 | K9: 109.67 | L9: 109.67 | M9: 109.67 | N9: 109.67
B10: Ежесменный осмотр (20 мин/смену), справочно | C10: ч/год | E10: =('Параметры'!C27-E8-E9)/'Параметры'!C28*20/60 -> 222.60994 | F10: =('Параметры'!C27-F8-F9)/'Параметры'!C28*20/60 -> 222.60994 | G10: =('Параметры'!C27-G8-G9)/'Параметры'!C28*20/60 -> 222.60994 | H10: =('Параметры'!C27-H8-H9)/'Параметры'!C28*20/60 -> 222.60994 | I10: =('Параметры'!C27-I8-I9)/'Параметры'!C28*20/60 -> 222.60994 | J10: =('Параметры'!C27-J8-J9)/'Параметры'!C28*20/60 -> 222.60994 | K10: =('Параметры'!C27-K8-K9)/'Параметры'!C28*20/60 -> 222.60994 | L10: =('Параметры'!C27-L8-L9)/'Параметры'!C28*20/60 -> 222.60994 | M10: =('Параметры'!C27-M8-M9)/'Параметры'!C28*20/60 -> 222.60994 | N10: =('Параметры'!C27-N8-N9)/'Параметры'!C28*20/60 -> 222.60994
B11: КТГ (техготовность, ВВОД) → «Данные по годам» | C11: коэф. | E11: 0.93 | F11: 0.93 | G11: 0.92 | H11: 0.92 | I11: 0.87 | J11: 0.9 | K11: 0.85 | L11: 0.9 | M11: 0.9 | N11: 0.85
B12: Затраты на ЗЧ ТО (авто из каталога) | C12: тыс.вал/г | E12: =E85 -> 136.07379 | F12: =F85 -> 136.07379 | G12: =G85 -> 136.07379 | H12: =H85 -> 136.07379 | I12: =I85 -> 136.07379 | J12: =J85 -> 136.07379 | K12: =K85 -> 136.07379 | L12: =L85 -> 136.07379 | ... N12: =N85 -> 136.07379
B13: Затраты на ЗЧ текущих ремонтов (по ресурсу) | C13: тыс.вал/г | E13: =E105 -> 4.50682 | F13: =F105 -> 60.10984 | G13: =G105 -> 145.1624 | H13: =H105 -> 60.10984 | I13: =I105 -> 144.82518 | J13: =J105 -> 67.22701 | K13: =K105 -> 145.21432 | L13: =L105 -> 60.05792 | ... N13: =N105 -> 105.58931
B14: Затраты на ЗЧ капремонтов (по ресурсу) | C14: тыс.вал/г | E14: =E188 -> 7.38238 | F14: =F188 -> 204.26495 | G14: =G188 -> 438.81584 | H14: =H188 -> 434.86339 | I14: =I188 -> 610.36746 | J14: =J188 -> 366.36175 | K14: =K188 -> 590.25823 | L14: =L188 -> 224.66392 | ... N14: =N188 -> 283.30237
B15: Трудозатраты ТО (авто) | C15: ч-час/г | E15: =E47 -> 636.37233 | F15: =F47 -> 636.37233 | G15: =G47 -> 636.37233 | H15: =H47 -> 636.37233 | I15: =I47 -> 636.37233 | J15: =J47 -> 636.37233 | K15: =K47 -> 636.37233 | L15: =L47 -> 636.37233 | ... N15: =N47 -> 636.37233
B16: Трудозатраты текущих ремонтов (авто) | C16: ч-час/г | E16: =E125 -> 48.4 | F16: =F125 -> 174.3 | G16: =G125 -> 228.3 | H16: =H125 -> 174.3 | I16: =I125 -> 220.4 | J16: =J125 -> 255.8 | K16: =K125 -> 226.3 | L16: =L125 -> 176.3 | ... N16: =N125 -> 365.3
B17: Трудозатраты капремонтов (авто) | C17: ч-час/г | E17: =E251 -> 36.6 | F17: =F251 -> 192.66 | G17: =G251 -> 330.45 | H17: =H251 -> 188.56 | I17: =I251 -> 267.75 | J17: =J251 -> 319.96 | K17: =K251 -> 300.71 | L17: =L251 -> 155.4 | ... N17: =N251 -> 102.4
B18: Сервис (трудозатраты ТО+ТР+КР) | C18: тыс.вал/г | E18: =(E15+E16+E17)*$E$23/1000 -> 41.762927 | F18: =(F15+F16+F17)*$E$23/1000 -> 58.086639 | G18: =(G15+G16+G17)*$E$23/1000 -> 69.190076 | H18: =(H15+H16+H17)*$E$23/1000 -> 57.849275 | I18: =(I15+I16+I17)*$E$23/1000 -> 65.102779 | J18: =(J15+J16+J17)*$E$23/1000 -> 70.174848 | K18: =(K15+K16+K17)*$E$23/1000 -> 67.352529 | L18: =(L15+L16+L17)*$E$23/1000 -> 56.045307 | ... N18: =(N15+N16+N17)*$E$23/1000 -> 63.918853
B19: Коэффициент калибровки ИТОГО под ТКП | C19: коэф. | E19: 1.0586
B20: ИТОГО ТОиР → «Данные по годам» | C20: тыс.вал/г | E20: =(E12+E13+E14+E18)*$E$19 -> 200.84385 | F20: =(F12+F13+F14+F18)*$E$19 -> 485.40538 | G20: =(G12+G13+G14+G18)*$E$19 -> 835.49169 | H20: =(H12+H13+H14+H18)*$E$19 -> 729.26562 | I20: =(I12+I13+I14+I18)*$E$19 -> 1012.4124 | J20: =(J12+J13+J14+J18)*$E$19 -> 677.33187 | K20: =(K12+K13+K14+K18)*$E$19 -> 993.91834 | L20: =(L12+L13+L14+L18)*$E$19 -> 504.78381 | ... N20: =(N12+N13+N14+N18)*$E$19 -> 623.39294
B21: Удельный расход ДТ / энергии | C21: кг(кВт)/час | E21: 74.8 | F21: 74.8 | G21: 74.8 | H21: 74.8 | I21: 74.8 | J21: 74.8 | K21: 74.8 | L21: 74.8 | M21: 74.8 | N21: 74.8
B23: Ставка сервиса | C23: вал/ч·час | E23: 57.893718
B24: РАСЧЁТ ТО (по интервалам обслуживания), ПО ГОДАМ
B25: Наработка по годам | C25: м/час | E25: 7000 | F25: 7000 | G25: 7000 | H25: 7000 | I25: 7000 | J25: 7000 | K25: 7000 | L25: 7000 | M25: 7000 | N25: 7000
B26: Вид ТО | C26: интервал, м/ч | D26: простой/ТО, ч | E26: персонал
B27: ТО-1 | C27: 250 | D27: 10.9 | E27: 1
B28: ТО-2 | C28: 500 | D28: 13.5 | E28: 1
B29: ТО-3 | C29: 1000 | D29: 12.43 | E29: 1
B30: ТО-4 | C30: 2000 | D30: 5.67 | E30: 1
B31: ТО-5 | C31: 3000 | D31: 10.06 | E31: 1
B32: ТО-6 | C32: 5000 | D32: 8.46 | E32: 1
B34: ТО-1: простои, ч/год | C34: ч | E34: =E$25/$C27*$D27 -> 305.2 | F34: =F$25/$C27*$D27 -> 305.2 | G34: =G$25/$C27*$D27 -> 305.2 | H34: =H$25/$C27*$D27 -> 305.2 | I34: =I$25/$C27*$D27 -> 305.2 | J34: =J$25/$C27*$D27 -> 305.2 | K34: =K$25/$C27*$D27 -> 305.2 | L34: =L$25/$C27*$D27 -> 305.2 | ... N34: =N$25/$C27*$D27 -> 305.2
B35: ТО-2: простои, ч/год | C35: ч | E35: =E$25/$C28*$D28 -> 189 | F35: =F$25/$C28*$D28 -> 189 | G35: =G$25/$C28*$D28 -> 189 | H35: =H$25/$C28*$D28 -> 189 | I35: =I$25/$C28*$D28 -> 189 | J35: =J$25/$C28*$D28 -> 189 | K35: =K$25/$C28*$D28 -> 189 | L35: =L$25/$C28*$D28 -> 189 | ... N35: =N$25/$C28*$D28 -> 189
B36: ТО-3: простои, ч/год | C36: ч | E36: =E$25/$C29*$D29 -> 87.01 | F36: =F$25/$C29*$D29 -> 87.01 | G36: =G$25/$C29*$D29 -> 87.01 | H36: =H$25/$C29*$D29 -> 87.01 | I36: =I$25/$C29*$D29 -> 87.01 | J36: =J$25/$C29*$D29 -> 87.01 | K36: =K$25/$C29*$D29 -> 87.01 | L36: =L$25/$C29*$D29 -> 87.01 | ... N36: =N$25/$C29*$D29 -> 87.01
B37: ТО-4: простои, ч/год | C37: ч | E37: =E$25/$C30*$D30 -> 19.845 | F37: =F$25/$C30*$D30 -> 19.845 | G37: =G$25/$C30*$D30 -> 19.845 | H37: =H$25/$C30*$D30 -> 19.845 | I37: =I$25/$C30*$D30 -> 19.845 | J37: =J$25/$C30*$D30 -> 19.845 | K37: =K$25/$C30*$D30 -> 19.845 | L37: =L$25/$C30*$D30 -> 19.845 | ... N37: =N$25/$C30*$D30 -> 19.845
B38: ТО-5: простои, ч/год | C38: ч | E38: =E$25/$C31*$D31 -> 23.473333 | F38: =F$25/$C31*$D31 -> 23.473333 | G38: =G$25/$C31*$D31 -> 23.473333 | H38: =H$25/$C31*$D31 -> 23.473333 | I38: =I$25/$C31*$D31 -> 23.473333 | J38: =J$25/$C31*$D31 -> 23.473333 | K38: =K$25/$C31*$D31 -> 23.473333 | L38: =L$25/$C31*$D31 -> 23.473333 | ... N38: =N$25/$C31*$D31 -> 23.473333
B39: ТО-6: простои, ч/год | C39: ч | E39: =E$25/$C32*$D32 -> 11.844 | F39: =F$25/$C32*$D32 -> 11.844 | G39: =G$25/$C32*$D32 -> 11.844 | H39: =H$25/$C32*$D32 -> 11.844 | I39: =I$25/$C32*$D32 -> 11.844 | J39: =J$25/$C32*$D32 -> 11.844 | K39: =K$25/$C32*$D32 -> 11.844 | L39: =L$25/$C32*$D32 -> 11.844 | ... N39: =N$25/$C32*$D32 -> 11.844
B40: Итого простои ТО | E40: =SUM(E34:E39) -> 636.37233 | F40: =SUM(F34:F39) -> 636.37233 | G40: =SUM(G34:G39) -> 636.37233 | H40: =SUM(H34:H39) -> 636.37233 | I40: =SUM(I34:I39) -> 636.37233 | J40: =SUM(J34:J39) -> 636.37233 | K40: =SUM(K34:K39) -> 636.37233 | L40: =SUM(L34:L39) -> 636.37233 | ... N40: =SUM(N34:N39) -> 636.37233
B41: ТО-1: чел-часы/год | C41: ч-час | E41: =E34*$E27 -> 305.2 | F41: =F34*$E27 -> 305.2 | G41: =G34*$E27 -> 305.2 | H41: =H34*$E27 -> 305.2 | I41: =I34*$E27 -> 305.2 | J41: =J34*$E27 -> 305.2 | K41: =K34*$E27 -> 305.2 | L41: =L34*$E27 -> 305.2 | ... N41: =N34*$E27 -> 305.2
B42: ТО-2: чел-часы/год | C42: ч-час | E42: =E35*$E28 -> 189 | F42: =F35*$E28 -> 189 | G42: =G35*$E28 -> 189 | H42: =H35*$E28 -> 189 | I42: =I35*$E28 -> 189 | J42: =J35*$E28 -> 189 | K42: =K35*$E28 -> 189 | L42: =L35*$E28 -> 189 | ... N42: =N35*$E28 -> 189
B43: ТО-3: чел-часы/год | C43: ч-час | E43: =E36*$E29 -> 87.01 | F43: =F36*$E29 -> 87.01 | G43: =G36*$E29 -> 87.01 | H43: =H36*$E29 -> 87.01 | I43: =I36*$E29 -> 87.01 | J43: =J36*$E29 -> 87.01 | K43: =K36*$E29 -> 87.01 | L43: =L36*$E29 -> 87.01 | ... N43: =N36*$E29 -> 87.01
...

Sheet Поставщик 5
B1: ДАННЫЕ ПОСТАВЩИКА — ВАРИАНТ 5 (ТО и Ремонты — модель по узлам)
B2: Жёлтое — ввод. Зелёное — авто (снизу вверх). ИТОГО ТОиР = (ЗЧ ТО + ЗЧ тек.+кап.ремонтов + сервис) × коэф.калибровки; тянется в «Данные по годам».
B4: Буровой станок: | E4: ='Ввод данных'!H7 -> HIFO 75D (аналог DM75)
B5: Валюта затрат ТОиР: | D5: EUR
B6: Показатель | C6: Ед. | E6: год 1 | F6: год 2 | G6: год 3 | H6: год 4 | I6: год 5 | J6: год 6 | K6: год 7 | L6: год 8 | M6: год 9 | N6: год 10
B7: СВОДКА ПО ГОДАМ (зелёное — авто снизу вверх; тянется в расчёт)
B8: Простои на ТО (авто из интервалов) | C8: ч/год | E8: =E40 -> 636.37233 | F8: =F40 -> 636.37233 | G8: =G40 -> 636.37233 | H8: =H40 -> 636.37233 | I8: =I40 -> 636.37233 | J8: =J40 -> 636.37233 | K8: =K40 -> 636.37233 | L8: =L40 -> 636.37233 | ... N8: =N40 -> 636.37233
B9: Простои в ремонтах (справочно) | C9: ч/год | E9: 85 | F9: 315.66 | G9: 423.65 | H9: 333.06 | I9: 283.55 | J9: 510.36 | K9: 398.41 | L9: 274.9 | M9: 438.21 | N9: 436.2
B10: Ежесменный осмотр (20 мин/смену), справочно | C10: ч/год | E10: =('Параметры'!C27-E8-E9)/'Параметры'!C28*20/60 -> 223.29521 | F10: =('Параметры'!C27-F8-F9)/'Параметры'!C28*20/60 -> 216.88799 | G10: =('Параметры'!C27-G8-G9)/'Параметры'!C28*20/60 -> 213.88827 | H10: =('Параметры'!C27-H8-H9)/'Параметры'!C28*20/60 -> 216.40466 | I10: =('Параметры'!C27-I8-I9)/'Параметры'!C28*20/60 -> 217.77994 | J10: =('Параметры'!C27-J8-J9)/'Параметры'!C28*20/60 -> 211.47966 | K10: =('Параметры'!C27-K8-K9)/'Параметры'!C28*20/60 -> 214.58938 | L10: =('Параметры'!C27-L8-L9)/'Параметры'!C28*20/60 -> 218.02021 | M10: =('Параметры'!C27-M8-M9)/'Параметры'!C28*20/60 -> 213.48382 | N10: =('Параметры'!C27-N8-N9)/'Параметры'!C28*20/60 -> 213.53966
B11: КТГ (техготовность, ВВОД) → «Данные по годам» | C11: коэф. | E11: 0.8932 | F11: 0.867 | G11: 0.8536 | H11: 0.8651 | I11: 0.8702 | J11: 0.8443 | K11: 0.8584 | L11: 0.8706 | M11: 0.8529 | N11: 0.8527
B12: Затраты на ЗЧ ТО (авто из каталога) | C12: тыс.вал/г | E12: =E85 -> 136.07379 | F12: =F85 -> 136.07379 | G12: =G85 -> 136.07379 | H12: =H85 -> 136.07379 | I12: =I85 -> 136.07379 | J12: =J85 -> 136.07379 | K12: =K85 -> 136.07379 | L12: =L85 -> 136.07379 | ... N12: =N85 -> 136.07379
B13: Затраты на ЗЧ текущих ремонтов (по ресурсу) | C13: тыс.вал/г | E13: =E105 -> 4.50682 | F13: =F105 -> 60.10984 | G13: =G105 -> 145.1624 | H13: =H105 -> 60.10984 | I13: =I105 -> 144.82518 | J13: =J105 -> 67.22701 | K13: =K105 -> 145.21432 | L13: =L105 -> 60.05792 | ... N13: =N105 -> 105.58931
B14: Затраты на ЗЧ капремонтов (по ресурсу) | C14: тыс.вал/г | E14: =E188 -> 7.38238 | F14: =F188 -> 204.26495 | G14: =G188 -> 438.81584 | H14: =H188 -> 434.86339 | I14: =I188 -> 610.36746 | J14: =J188 -> 366.36175 | K14: =K188 -> 590.25823 | L14: =L188 -> 224.66392 | ... N14: =N188 -> 283.30237
B15: Трудозатраты ТО (авто) | C15: ч-час/г | E15: =E47 -> 636.37233 | F15: =F47 -> 636.37233 | G15: =G47 -> 636.37233 | H15: =H47 -> 636.37233 | I15: =I47 -> 636.37233 | J15: =J47 -> 636.37233 | K15: =K47 -> 636.37233 | L15: =L47 -> 636.37233 | ... N15: =N47 -> 636.37233
B16: Трудозатраты текущих ремонтов (авто) | C16: ч-час/г | E16: =E125 -> 48.4 | F16: =F125 -> 174.3 | G16: =G125 -> 228.3 | H16: =H125 -> 174.3 | I16: =I125 -> 220.4 | J16: =J125 -> 255.8 | K16: =K125 -> 226.3 | L16: =L125 -> 176.3 | ... N16: =N125 -> 365.3
B17: Трудозатраты капремонтов (авто) | C17: ч-час/г | E17: =E251 -> 36.6 | F17: =F251 -> 192.66 | G17: =G251 -> 330.45 | H17: =H251 -> 188.56 | I17: =I251 -> 267.75 | J17: =J251 -> 319.96 | K17: =K251 -> 300.71 | L17: =L251 -> 155.4 | ... N17: =N251 -> 102.4
B18: Сервис (трудозатраты ТО+ТР+КР) | C18: тыс.вал/г | E18: =(E15+E16+E17)*$E$23/1000 -> 41.762927 | F18: =(F15+F16+F17)*$E$23/1000 -> 58.086639 | G18: =(G15+G16+G17)*$E$23/1000 -> 69.190076 | H18: =(H15+H16+H17)*$E$23/1000 -> 57.849275 | I18: =(I15+I16+I17)*$E$23/1000 -> 65.102779 | J18: =(J15+J16+J17)*$E$23/1000 -> 70.174848 | K18: =(K15+K16+K17)*$E$23/1000 -> 67.352529 | L18: =(L15+L16+L17)*$E$23/1000 -> 56.045307 | ... N18: =(N15+N16+N17)*$E$23/1000 -> 63.918853
B19: Коэффициент калибровки ИТОГО под ТКП | C19: коэф. | E19: 0.8166
B20: ИТОГО ТОиР → «Данные по годам» | C20: тыс.вал/г | E20: =(E12+E13+E14+E18)*$E$19 -> 154.93018 | F20: =(F12+F13+F14+F18)*$E$19 -> 374.43986 | G20: =(G12+G13+G14+G18)*$E$19 -> 644.4951 | H20: =(H12+H13+H14+H18)*$E$19 -> 562.55271 | I20: =(I12+I13+I14+I18)*$E$19 -> 780.97109 | J20: =(J12+J13+J14+J18)*$E$19 -> 522.49122 | K20: =(K12+K13+K14+K18)*$E$19 -> 766.70482 | L20: =(L12+L13+L14+L18)*$E$19 -> 389.38831 | ... N20: =(N12+N13+N14+N18)*$E$19 -> 480.88294
B21: Удельный расход ДТ / энергии | C21: кг(кВт)/час | E21: 93.5 | F21: 93.5 | G21: 93.5 | H21: 93.5 | I21: 93.5 | J21: 93.5 | K21: 93.5 | L21: 93.5 | M21: 93.5 | N21: 93.5
B23: Ставка сервиса | C23: вал/ч·час | E23: 57.893718
B24: РАСЧЁТ ТО (по интервалам обслуживания), ПО ГОДАМ
B25: Наработка по годам | C25: м/час | E25: 7000 | F25: 7000 | G25: 7000 | H25: 7000 | I25: 7000 | J25: 7000 | K25: 7000 | L25: 7000 | M25: 7000 | N25: 7000
B26: Вид ТО | C26: интервал, м/ч | D26: простой/ТО, ч | E26: персонал
B27: ТО-1 | C27: 250 | D27: 10.9 | E27: 1
B28: ТО-2 | C28: 500 | D28: 13.5 | E28: 1
B29: ТО-3 | C29: 1000 | D29: 12.43 | E29: 1
B30: ТО-4 | C30: 2000 | D30: 5.67 | E30: 1
B31: ТО-5 | C31: 3000 | D31: 10.06 | E31: 1
B32: ТО-6 | C32: 5000 | D32: 8.46 | E32: 1
B34: ТО-1: простои, ч/год | C34: ч | E34: =E$25/$C27*$D27 -> 305.2 | F34: =F$25/$C27*$D27 -> 305.2 | G34: =G$25/$C27*$D27 -> 305.2 | H34: =H$25/$C27*$D27 -> 305.2 | I34: =I$25/$C27*$D27 -> 305.2 | J34: =J$25/$C27*$D27 -> 305.2 | K34: =K$25/$C27*$D27 -> 305.2 | L34: =L$25/$C27*$D27 -> 305.2 | ... N34: =N$25/$C27*$D27 -> 305.2
B35: ТО-2: простои, ч/год | C35: ч | E35: =E$25/$C28*$D28 -> 189 | F35: =F$25/$C28*$D28 -> 189 | G35: =G$25/$C28*$D28 -> 189 | H35: =H$25/$C28*$D28 -> 189 | I35: =I$25/$C28*$D28 -> 189 | J35: =J$25/$C28*$D28 -> 189 | K35: =K$25/$C28*$D28 -> 189 | L35: =L$25/$C28*$D28 -> 189 | ... N35: =N$25/$C28*$D28 -> 189
B36: ТО-3: простои, ч/год | C36: ч | E36: =E$25/$C29*$D29 -> 87.01 | F36: =F$25/$C29*$D29 -> 87.01 | G36: =G$25/$C29*$D29 -> 87.01 | H36: =H$25/$C29*$D29 -> 87.01 | I36: =I$25/$C29*$D29 -> 87.01 | J36: =J$25/$C29*$D29 -> 87.01 | K36: =K$25/$C29*$D29 -> 87.01 | L36: =L$25/$C29*$D29 -> 87.01 | ... N36: =N$25/$C29*$D29 -> 87.01
B37: ТО-4: простои, ч/год | C37: ч | E37: =E$25/$C30*$D30 -> 19.845 | F37: =F$25/$C30*$D30 -> 19.845 | G37: =G$25/$C30*$D30 -> 19.845 | H37: =H$25/$C30*$D30 -> 19.845 | I37: =I$25/$C30*$D30 -> 19.845 | J37: =J$25/$C30*$D30 -> 19.845 | K37: =K$25/$C30*$D30 -> 19.845 | L37: =L$25/$C30*$D30 -> 19.845 | ... N37: =N$25/$C30*$D30 -> 19.845
B38: ТО-5: простои, ч/год | C38: ч | E38: =E$25/$C31*$D31 -> 23.473333 | F38: =F$25/$C31*$D31 -> 23.473333 | G38: =G$25/$C31*$D31 -> 23.473333 | H38: =H$25/$C31*$D31 -> 23.473333 | I38: =I$25/$C31*$D31 -> 23.473333 | J38: =J$25/$C31*$D31 -> 23.473333 | K38: =K$25/$C31*$D31 -> 23.473333 | L38: =L$25/$C31*$D31 -> 23.473333 | ... N38: =N$25/$C31*$D31 -> 23.473333
B39: ТО-6: простои, ч/год | C39: ч | E39: =E$25/$C32*$D32 -> 11.844 | F39: =F$25/$C32*$D32 -> 11.844 | G39: =G$25/$C32*$D32 -> 11.844 | H39: =H$25/$C32*$D32 -> 11.844 | I39: =I$25/$C32*$D32 -> 11.844 | J39: =J$25/$C32*$D32 -> 11.844 | K39: =K$25/$C32*$D32 -> 11.844 | L39: =L$25/$C32*$D32 -> 11.844 | ... N39: =N$25/$C32*$D32 -> 11.844
B40: Итого простои ТО | E40: =SUM(E34:E39) -> 636.37233 | F40: =SUM(F34:F39) -> 636.37233 | G40: =SUM(G34:G39) -> 636.37233 | H40: =SUM(H34:H39) -> 636.37233 | I40: =SUM(I34:I39) -> 636.37233 | J40: =SUM(J34:J39) -> 636.37233 | K40: =SUM(K34:K39) -> 636.37233 | L40: =SUM(L34:L39) -> 636.37233 | ... N40: =SUM(N34:N39) -> 636.37233
B41: ТО-1: чел-часы/год | C41: ч-час | E41: =E34*$E27 -> 305.2 | F41: =F34*$E27 -> 305.2 | G41: =G34*$E27 -> 305.2 | H41: =H34*$E27 -> 305.2 | I41: =I34*$E27 -> 305.2 | J41: =J34*$E27 -> 305.2 | K41: =K34*$E27 -> 305.2 | L41: =L34*$E27 -> 305.2 | ... N41: =N34*$E27 -> 305.2
B42: ТО-2: чел-часы/год | C42: ч-час | E42: =E35*$E28 -> 189 | F42: =F35*$E28 -> 189 | G42: =G35*$E28 -> 189 | H42: =H35*$E28 -> 189 | I42: =I35*$E28 -> 189 | J42: =J35*$E28 -> 189 | K42: =K35*$E28 -> 189 | L42: =L35*$E28 -> 189 | ... N42: =N35*$E28 -> 189
B43: ТО-3: чел-часы/год | C43: ч-час | E43: =E36*$E29 -> 87.01 | F43: =F36*$E29 -> 87.01 | G43: =G36*$E29 -> 87.01 | H43: =H36*$E29 -> 87.01 | I43: =I36*$E29 -> 87.01 | J43: =J36*$E29 -> 87.01 | K43: =K36*$E29 -> 87.01 | L43: =L36*$E29 -> 87.01 | ... N43: =N36*$E29 -> 87.01
...

Sheet Данные по годам
B1: ПОГОДОВЫЕ ДАННЫЕ ЭКСПЛУАТАЦИИ (СВОДКА)
B2: Автоматически из листов «Поставщик 1…5». Правьте данные там, здесь — только просмотр.
B4: Значения ТЯНУТСЯ из листов «Поставщик 1…5» (КТГ и ИТОГО ТОиР — авто). Чтобы изменить данные по машине — откройте её лист и правьте жёлтые ячейки; сводка и расчёт обновятся сами.
B5: Показатель | C5: Ед. | D5: Валюта | E5: год 1 | F5: год 2 | G5: год 3 | H5: год 4 | I5: год 5 | J5: год 6 | K5: год 7 | L5: год 8 | M5: год 9 | N5: год 10
B6: ="Вариант 1: "&'Ввод данных'!D7 -> Вариант 1: YANGZI DR75 (аналог Epiroc DM75)
B7: КТГ (техготовность) | C7: коэф. | E7: ='Поставщик 1'!E11 -> 0.9309 | F7: ='Поставщик 1'!F11 -> 0.9172 | G7: ='Поставщик 1'!G11 -> 0.9309 | H7: ='Поставщик 1'!H11 -> 0.9172 | I7: ='Поставщик 1'!I11 -> 0.8865 | J7: ='Поставщик 1'!J11 -> 0.9172 | K7: ='Поставщик 1'!K11 -> 0.8506 | L7: ='Поставщик 1'!L11 -> 0.9198 | ... N7: ='Поставщик 1'!N11 -> 0.8532
B8: Затраты на ТОиР и сервис | C8: тыс.вал/г | D8: ='Поставщик 1'!$D$5 -> EUR | E8: ='Поставщик 1'!E20 -> 88.488167 | F8: ='Поставщик 1'!F20 -> 213.86083 | G8: ='Поставщик 1'!G20 -> 368.10252 | H8: ='Поставщик 1'!H20 -> 321.30123 | I8: ='Поставщик 1'!I20 -> 446.0506 | J8: ='Поставщик 1'!J20 -> 298.42016 | K8: ='Поставщик 1'!K20 -> 437.90243 | L8: ='Поставщик 1'!L20 -> 222.39861 | ... N8: ='Поставщик 1'!N20 -> 274.65565
B9: Удельный расход ДТ/энергии | C9: кг/час | E9: ='Поставщик 1'!E21 -> 66.3 | F9: ='Поставщик 1'!F21 -> 66.3 | G9: ='Поставщик 1'!G21 -> 66.3 | H9: ='Поставщик 1'!H21 -> 66.3 | I9: ='Поставщик 1'!I21 -> 66.3 | J9: ='Поставщик 1'!J21 -> 66.3 | K9: ='Поставщик 1'!K21 -> 66.3 | L9: ='Поставщик 1'!L21 -> 66.3 | ... N9: ='Поставщик 1'!N21 -> 66.3
B10: ="Вариант 2: "&'Ввод данных'!E7 -> Вариант 2: Sunward SWDRT250SM
B11: КТГ (техготовность) | C11: коэф. | E11: ='Поставщик 2'!E11 -> 0.8948 | F11: ='Поставщик 2'!F11 -> 0.8654 | G11: ='Поставщик 2'!G11 -> 0.8454 | H11: ='Поставщик 2'!H11 -> 0.8748 | I11: ='Поставщик 2'!I11 -> 0.8654 | J11: ='Поставщик 2'!J11 -> 0.8432 | K11: ='Поставщик 2'!K11 -> 0.8621 | L11: ='Поставщик 2'!L11 -> 0.8654 | ... N11: ='Поставщик 2'!N11 -> 0.8543
B12: Затраты на ТОиР и сервис | C12: тыс.вал/г | D12: ='Поставщик 2'!$D$5 -> EUR | E12: ='Поставщик 2'!E20 -> 156.04957 | F12: ='Поставщик 2'!F20 -> 377.14522 | G12: ='Поставщик 2'!G20 -> 649.15163 | H12: ='Поставщик 2'!H20 -> 566.6172 | I12: ='Поставщик 2'!I20 -> 786.61367 | J12: ='Поставщик 2'!J20 -> 526.26626 | K12: ='Поставщик 2'!K20 -> 772.24432 | L12: ='Поставщик 2'!L20 -> 392.20167 | ... N12: ='Поставщик 2'!N20 -> 484.35735
B13: Удельный расход ДТ/энергии | C13: кг/час | E13: ='Поставщик 2'!E21 -> 38.7 | F13: ='Поставщик 2'!F21 -> 38.7 | G13: ='Поставщик 2'!G21 -> 38.7 | H13: ='Поставщик 2'!H21 -> 38.7 | I13: ='Поставщик 2'!I21 -> 38.7 | J13: ='Поставщик 2'!J21 -> 38.7 | K13: ='Поставщик 2'!K21 -> 38.7 | L13: ='Поставщик 2'!L21 -> 38.7 | ... N13: ='Поставщик 2'!N21 -> 38.7
B14: ="Вариант 3: "&'Ввод данных'!F7 -> Вариант 3: Sunward SWDRT270SM
B15: КТГ (техготовность) | C15: коэф. | E15: ='Поставщик 3'!E11 -> 0.8948 | F15: ='Поставщик 3'!F11 -> 0.8654 | G15: ='Поставщик 3'!G11 -> 0.8454 | H15: ='Поставщик 3'!H11 -> 0.8748 | I15: ='Поставщик 3'!I11 -> 0.8654 | J15: ='Поставщик 3'!J11 -> 0.8432 | K15: ='Поставщик 3'!K11 -> 0.8621 | L15: ='Поставщик 3'!L11 -> 0.8654 | ... N15: ='Поставщик 3'!N11 -> 0.8543
B16: Затраты на ТОиР и сервис | C16: тыс.вал/г | D16: ='Поставщик 3'!$D$5 -> EUR | E16: ='Поставщик 3'!E20 -> 156.04957 | F16: ='Поставщик 3'!F20 -> 377.14522 | G16: ='Поставщик 3'!G20 -> 649.15163 | H16: ='Поставщик 3'!H20 -> 566.6172 | I16: ='Поставщик 3'!I20 -> 786.61367 | J16: ='Поставщик 3'!J20 -> 526.26626 | K16: ='Поставщик 3'!K20 -> 772.24432 | L16: ='Поставщик 3'!L20 -> 392.20167 | ... N16: ='Поставщик 3'!N20 -> 484.35735
B17: Удельный расход ДТ/энергии | C17: кг/час | E17: ='Поставщик 3'!E21 -> 50.1 | F17: ='Поставщик 3'!F21 -> 50.1 | G17: ='Поставщик 3'!G21 -> 50.1 | H17: ='Поставщик 3'!H21 -> 50.1 | I17: ='Поставщик 3'!I21 -> 50.1 | J17: ='Поставщик 3'!J21 -> 50.1 | K17: ='Поставщик 3'!K21 -> 50.1 | L17: ='Поставщик 3'!L21 -> 50.1 | ... N17: ='Поставщик 3'!N21 -> 50.1
B18: ="Вариант 4: "&'Ввод данных'!G7 -> Вариант 4: Sunward SWDRT270B
B19: КТГ (техготовность) | C19: коэф. | E19: ='Поставщик 4'!E11 -> 0.93 | F19: ='Поставщик 4'!F11 -> 0.93 | G19: ='Поставщик 4'!G11 -> 0.92 | H19: ='Поставщик 4'!H11 -> 0.92 | I19: ='Поставщик 4'!I11 -> 0.87 | J19: ='Поставщик 4'!J11 -> 0.9 | K19: ='Поставщик 4'!K11 -> 0.85 | L19: ='Поставщик 4'!L11 -> 0.9 | ... N19: ='Поставщик 4'!N11 -> 0.85
B20: Затраты на ТОиР и сервис | C20: тыс.вал/г | D20: ='Поставщик 4'!$D$5 -> EUR | E20: ='Поставщик 4'!E20 -> 200.84385 | F20: ='Поставщик 4'!F20 -> 485.40538 | G20: ='Поставщик 4'!G20 -> 835.49169 | H20: ='Поставщик 4'!H20 -> 729.26562 | I20: ='Поставщик 4'!I20 -> 1012.4124 | J20: ='Поставщик 4'!J20 -> 677.33187 | K20: ='Поставщик 4'!K20 -> 993.91834 | L20: ='Поставщик 4'!L20 -> 504.78381 | ... N20: ='Поставщик 4'!N20 -> 623.39294
B21: Удельный расход ДТ/энергии | C21: кг/час | E21: ='Поставщик 4'!E21 -> 74.8 | F21: ='Поставщик 4'!F21 -> 74.8 | G21: ='Поставщик 4'!G21 -> 74.8 | H21: ='Поставщик 4'!H21 -> 74.8 | I21: ='Поставщик 4'!I21 -> 74.8 | J21: ='Поставщик 4'!J21 -> 74.8 | K21: ='Поставщик 4'!K21 -> 74.8 | L21: ='Поставщик 4'!L21 -> 74.8 | ... N21: ='Поставщик 4'!N21 -> 74.8
B22: ="Вариант 5: "&'Ввод данных'!H7 -> Вариант 5: HIFO 75D (аналог DM75)
B23: КТГ (техготовность) | C23: коэф. | E23: ='Поставщик 5'!E11 -> 0.8932 | F23: ='Поставщик 5'!F11 -> 0.867 | G23: ='Поставщик 5'!G11 -> 0.8536 | H23: ='Поставщик 5'!H11 -> 0.8651 | I23: ='Поставщик 5'!I11 -> 0.8702 | J23: ='Поставщик 5'!J11 -> 0.8443 | K23: ='Поставщик 5'!K11 -> 0.8584 | L23: ='Поставщик 5'!L11 -> 0.8706 | ... N23: ='Поставщик 5'!N11 -> 0.8527
B24: Затраты на ТОиР и сервис | C24: тыс.вал/г | D24: ='Поставщик 5'!$D$5 -> EUR | E24: ='Поставщик 5'!E20 -> 154.93018 | F24: ='Поставщик 5'!F20 -> 374.43986 | G24: ='Поставщик 5'!G20 -> 644.4951 | H24: ='Поставщик 5'!H20 -> 562.55271 | I24: ='Поставщик 5'!I20 -> 780.97109 | J24: ='Поставщик 5'!J20 -> 522.49122 | K24: ='Поставщик 5'!K20 -> 766.70482 | L24: ='Поставщик 5'!L20 -> 389.38831 | ... N24: ='Поставщик 5'!N20 -> 480.88294
B25: Удельный расход ДТ/энергии | C25: кг/час | E25: ='Поставщик 5'!E21 -> 93.5 | F25: ='Поставщик 5'!F21 -> 93.5 | G25: ='Поставщик 5'!G21 -> 93.5 | H25: ='Поставщик 5'!H21 -> 93.5 | I25: ='Поставщик 5'!I21 -> 93.5 | J25: ='Поставщик 5'!J21 -> 93.5 | K25: ='Поставщик 5'!K21 -> 93.5 | L25: ='Поставщик 5'!L21 -> 93.5 | ... N25: ='Поставщик 5'!N21 -> 93.5

