Workbook

Sheet Методика
B1: МЕТОДИКА: АННУИТЕТ ЗАТРАТ (РУБ/М³) НА ВЛАДЕНИЕ ЭКСКАВАТОРАМИ
B2: Пост-налоговый погодовой дисконтированный аннуитет жизненного цикла.
C4: 1. НАЗНАЧЕНИЕ
C5: Экономическое сравнение экскаваторов одного класса по удельному аннуитету затрат (руб/м³ вынутой горной массы) за полный срок эксплуатации. Метрика корректно сопоставляет машины с разной ценой, производительностью и структурой затрат. Лучший вариант — минимум руб/м³.
C6: 2. ПРОИЗВОДИТЕЛЬНОСТЬ
C7: Порода в ковше = ковш × плотность × (наполнение/разрыхление) × потери. Ковшей на самосвал = ОКРУГЛ.ВВЕРХ(грузоподъёмность / порода в ковше). Самосвалов/час = 3600/(ковшей × цикл + постановка а/с). т/ч = грузоподъёмность × самосвалов/час; м³/ч = т/ч / плотность. Годовой объём = м³/ч × эффективное время; эффективное время = КФВ × КТГ × (1 − простои/смена). КТГ снижается с возрастом машины.
C8: 3. ПОГОДОВОЙ ДЕНЕЖНЫЙ ПОТОК (10 лет)
C9: Для каждого года считаются: дизтопливо (эфф.время × кг/ч × цена), ТОиР и сервис (задаются ПО ГОДАМ на листе «Данные по годам» — включают плановое ТО, текущие и капитальные ремонты; годы капремонтов дают всплеск затрат), расходники на ковш, персонал. Добавляются амортизация (НУ) и налог на прибыль (щит). Операционный поток = база + налог − амортизация. Инвестиции — в год 0, остаточная стоимость — в конце срока. КТГ также задаётся по годам.
C10: 4. АННУИТЕТ (ЯДРО)
C11: Потоки дисконтируются и преобразуются в эквивалентный годовой платёж: Аннуитет = NPV затрат / Σ(дисконт-факторов). Инвестиционный аннуитет = (Цена − дисконт. остаточная стоимость) / Σ(дисконт-факторов). Операционный аннуитет — приведённые эксплуатационные затраты после налога. Общий = инвестиционный + операционный. Удельный аннуитет (руб/м³) = общий аннуитет / средний годовой объём; руб/т = руб/м³ / плотность.
C12: 5. ПОРЯДОК РАБОТЫ
C13: «Параметры» → «Ввод данных» (цена, ковш, персонал) → листы «Поставщик 1…6»: по каждой машине встроены модели ТО (интервалы обслуживания → простои, запчасти, сервис) и Ремонтов (простои, текущие и капитальные ремонты, сервис по годам) — КТГ и ИТОГО ТОиР считаются автоматически снизу вверх. Сводка «Данные по годам» тянет итоги сама → авторасчёт «Производительность», «Денежный поток», «Расчёт аннуитета» → «Дашборд», «Сравнение», «Аналитика» (многокритериальная оценка, разложение над лучшим, диапазон риска, ценность готовности), «Чувствительность». Правки — только в листах «Поставщик N».
C14: 6. ДОПУЩЕНИЯ
C15: • Машины сравниваются в одном классе и одной задаче; разница в производительности учтена через руб/м³.
... C22: зелёные ячейки — итоговые показатели / лучший вариант

Sheet Дашборд
B1: ИТОГОВЫЙ ДАШБОРД — СРАВНЕНИЕ ЭКСКАВАТОРОВ
B2: Ключевые показатели и графики. Данные обновляются автоматически.
B4: КЛЮЧЕВЫЕ ПОКАЗАТЕЛИ
B5: Лучший вариант | C5: Мин. аннуитет, руб/м³ | D5: Мин. NPV владения, тыс.руб | E5: Разброс аннуитета, руб/м³
B6: =INDEX('Ввод данных'!D7:J7,MATCH(MIN('Расчёт аннуитета'!D23:J23),'Расчёт аннуитета'!D23:J23,0)) -> XCMG ESTAR ESE2000 (поставщик не указан) | C6: =MIN('Расчёт аннуитета'!D23:J23) -> 31.40079 | D6: =MIN('Расчёт аннуитета'!D13:J13) -> 387032.41 | E6: =MAX('Расчёт аннуитета'!D23:J23)-MIN('Расчёт аннуитета'!D23:J23) -> 115.2246
B8: РЕЙТИНГ ПО УДЕЛЬНОМУ АННУИТЕТУ (руб/м³)
B9: Место | C9: Экскаватор | G9: Аннуитет, руб/м³ | I9: руб/т
B10: 1 | C10: =INDEX('Ввод данных'!D7:J7,MATCH(SMALL('Расчёт аннуитета'!D23:J23,1),'Расчёт аннуитета'!D23:J23,0)) -> XCMG ESTAR ESE2000 (поставщик не указан) | G10: =SMALL('Расчёт аннуитета'!D23:J23,1) -> 31.40079 | I10: =INDEX('Расчёт аннуитета'!$D$25:$J$25,MATCH(SMALL('Расчёт аннуитета'!D23:J23,1),'Расчёт аннуитета'!D23:J23,0)) -> 11.266878
B11: 2 | C11: =INDEX('Ввод данных'!D7:J7,MATCH(SMALL('Расчёт аннуитета'!D23:J23,2),'Расчёт аннуитета'!D23:J23,0)) -> TZCO TZ2000 Дзикай | G11: =SMALL('Расчёт аннуитета'!D23:J23,2) -> 31.591418 | I11: =INDEX('Расчёт аннуитета'!$D$25:$J$25,MATCH(SMALL('Расчёт аннуитета'!D23:J23,2),'Расчёт аннуитета'!D23:J23,0)) -> 11.335277
B12: 3 | C12: =INDEX('Ввод данных'!D7:J7,MATCH(SMALL('Расчёт аннуитета'!D23:J23,3),'Расчёт аннуитета'!D23:J23,0)) -> Sany SY2000 АСТ | G12: =SMALL('Расчёт аннуитета'!D23:J23,3) -> 45.546682 | I12: =INDEX('Расчёт аннуитета'!$D$25:$J$25,MATCH(SMALL('Расчёт аннуитета'!D23:J23,3),'Расчёт аннуитета'!D23:J23,0)) -> 16.342548
B13: 4 | C13: =INDEX('Ввод данных'!D7:J7,MATCH(SMALL('Расчёт аннуитета'!D23:J23,4),'Расчёт аннуитета'!D23:J23,0)) -> Zoomlion ZE2000G Орикс | G13: =SMALL('Расчёт аннуитета'!D23:J23,4) -> 45.840766 | I13: =INDEX('Расчёт аннуитета'!$D$25:$J$25,MATCH(SMALL('Расчёт аннуитета'!D23:J23,4),'Расчёт аннуитета'!D23:J23,0)) -> 16.448068
B14: 5 | C14: =INDEX('Ввод данных'!D7:J7,MATCH(SMALL('Расчёт аннуитета'!D23:J23,5),'Расчёт аннуитета'!D23:J23,0)) -> Komatsu PC2000-11R ИСТК | G14: =SMALL('Расчёт аннуитета'!D23:J23,5) -> 48.691794 | I14: =INDEX('Расчёт аннуитета'!$D$25:$J$25,MATCH(SMALL('Расчёт аннуитета'!D23:J23,5),'Расчёт аннуитета'!D23:J23,0)) -> 17.471042
B15: 6 | C15: =INDEX('Ввод данных'!D7:J7,MATCH(SMALL('Расчёт аннуитета'!D23:J23,6),'Расчёт аннуитета'!D23:J23,0)) -> Komatsu PC2000-8 Mining Solutions | G15: =SMALL('Расчёт аннуитета'!D23:J23,6) -> 67.82058 | I15: =INDEX('Расчёт аннуитета'!$D$25:$J$25,MATCH(SMALL('Расчёт аннуитета'!D23:J23,6),'Расчёт аннуитета'!D23:J23,0)) -> 24.334618
B16: 7 | C16: =INDEX('Ввод данных'!D7:J7,MATCH(SMALL('Расчёт аннуитета'!D23:J23,7),'Расчёт аннуитета'!D23:J23,0)) -> Shantui SE2000LCW | G16: =SMALL('Расчёт аннуитета'!D23:J23,7) -> 146.62539 | I16: =INDEX('Расчёт аннуитета'!$D$25:$J$25,MATCH(SMALL('Расчёт аннуитета'!D23:J23,7),'Расчёт аннуитета'!D23:J23,0)) -> 52.610475

Sheet Параметры
B1: ГЛОБАЛЬНЫЕ ПАРАМЕТРЫ МОДЕЛИ
B2: Единые допущения для всех вариантов. Жёлтые ячейки — ввод.
B4: Финансовые допущения
B5: Параметр | C5: Значение | D5: Ед. | E5: Комментарий
B6: Ставка дисконтирования (WACC) | C6: 0.12 | D6: %/год | E6: Стоимость капитала для приведения к текущей стоимости
B7: Налог на прибыль | C7: 0.25 | D7: % | E7: Формирует налоговый щит на затраты и амортизацию
B8: Срок эксплуатации (горизонт) | C8: 10 | D8: лет | E8: Фиксирован = 10 лет в погодовом движке
B9: Срок амортизации (налоговый учёт) | C9: 5.17 | D9: лет | E9: Линейная; 62 мес ≈ 5,17 года
B10: Цена дизельного топлива | C10: 54.83 | D10: руб/кг | E10: Средняя цена на площадке эксплуатации
B12: Эскалация цен (реальный/номинальный рост)
B13: Параметр | C13: Значение | D13: Ед. | E13: Комментарий
B14: Эскалация цены топлива | C14: 0 | D14: %/год | E14: Рост цены ДТ (0 = данные уже с учётом инфляции)
B15: Эскалация расходников и персонала | C15: 0 | D15: %/год | E15: ТОиР задаётся по годам напрямую (см. «Данные по годам»)
B16: Эскалация оплаты труда | C16: 0 | D16: %/год | E16: Рост ФОТ экипажей
B18: Курсы валют
B19: Параметр | C19: Значение | D19: Ед. | E19: Комментарий
B20: Курс юаня (CNY) | C20: 11.2068 | D20: руб | E20: Для оборудования из Китая
B21: Курс доллара (USD) | C21: 76.1258 | D21: руб
B22: Курс евро (EUR) | C22: 86.8976 | D22: руб
B24: Параметры производительности (карьер)
B25: Параметр | C25: Значение | D25: Ед. | E25: Комментарий
B26: Календарный фонд времени | C26: 8760 | D26: час/год | E26: 24 ч × 365 дн
B27: Плотность породы | C27: 2.787 | D27: т/м³ | E27: В целике; используется и для пересчёта руб/т
B28: Коэффициент разрыхления | C28: 1.5 | D28: коэф.
B29: Коэффициент наполнения ковша | C29: 0.9 | D29: коэф.
B30: Коэффициент потерь при экскавации | C30: 0.9 | D30: коэф.
B31: Грузоподъёмность самосвала | C31: 136 | D31: т | E31: Эталонный самосвал для расчёта
B32: Время постановки самосвала | C32: 32 | D32: сек | E32: Время оборота а/с под погрузку
B33: Длительность смены | C33: 12 | D33: час | E33: Для пересчёта простоев
B35: Расчётные финансовые коэффициенты
B36: Параметр | C36: Значение | D36: Ед. | E36: Комментарий
B37: Коэф. аннуитета Σдиск.факторов (r, N) | C37: =IF('Параметры'!C6=0,'Параметры'!C8,(1-(1+'Параметры'!C6)^-'Параметры'!C8)/'Параметры'!C6) -> 5.650223 | D37: коэф. | E37: Сумма дисконт-факторов за срок службы
B38: Коэф. приведённой амортизации | C38: =(1/'Параметры'!C9)*((1-(1+'Параметры'!C6)^-INT('Параметры'!C9))/'Параметры'!C6+('Параметры'!C9-INT('Параметры'!C9))*(1+'Параметры'!C6)^-(INT('Параметры'!C9)+1)) -> 0.71390783 | D38: коэф. | E38: Приведённая амортизация на 1 руб. цены (налог. щит)
B40: Легенда: | D40: — ввод данных
D41: — расчётные показатели

Sheet Ввод данных
B1: ВВОД ИСХОДНЫХ ДАННЫХ ПО ЭКСКАВАТОРАМ
B2: Сравнение до 6 машин одного класса. Пример: экскаваторы класса 2000 (~12 м³).
B4: Показатель | C4: Ед. | D4: Экскаватор 1 | E4: Экскаватор 2 | F4: Экскаватор 3 | G4: Экскаватор 4 | H4: Экскаватор 5 | I4: Экскаватор 6 | J4: Экскаватор 7 | K4: Пояснение
B6: A. ИДЕНТИФИКАЦИЯ
B7: Наименование / модель | C7: — | D7: Komatsu PC2000-8 Mining Solutions | E7: Komatsu PC2000-11R ИСТК | F7: Zoomlion ZE2000G Орикс | G7: Sany SY2000 АСТ | H7: Shantui SE2000LCW | I7: TZCO TZ2000 Дзикай | J7: XCMG ESTAR ESE2000 (поставщик не указан) | K7: Название варианта
B8: Поставщик | C8: — | D8: Mining Solutions | E8: ИСТК | F8: Орикс | G8: АСТ | H8: Строймпорттехника | I8: Дзикай | J8: —
B9: Двигатель | C9: — | D9: Komatsu SAA12V140E | E9: Komatsu SAA12V140E-7 | F9: Cummins QST30 | G9: Cummins QSK38 | H9: Weichai 12M33 | I9: Weichai 12M33 | J9: 1102 л.с.
B10: B. СТОИМОСТЬ И ОСТАТОЧНАЯ ЦЕНА
B11: Цена за единицу | C11: тыс.вал. | D11: 3800 | E11: 3401.64 | F11: 20129 | G11: 19621.62 | H11: 16742.05 | I11: 15400 | J11: 18000 | K11: В валюте контракта
B12: Валюта цены | C12: — | D12: USD | E12: USD | F12: CNY | G12: CNY | H12: CNY | I12: CNY | J12: CNY | K12: CNY / USD / EUR / RUB
B13: Монтаж, доставка, ПНР | C13: тыс.руб | D13: 0 | E13: 0 | F13: 0 | G13: 0 | H13: 0 | I13: 0 | J13: 0 | K13: Дополнительно к цене
B14: Остаточная стоимость | C14: % от цены | D14: 0 | E14: 0 | F14: 0 | G14: 0 | H14: 0 | I14: 0 | J14: 0 | K14: Стоимость реализации в конце срока (0 = не учитывать)
B15: C. ПРОИЗВОДИТЕЛЬНОСТЬ
B16: Геометрический объём ковша | C16: м³ | D16: 10 | E16: 10 | F16: 10 | G16: 10 | H16: 9.6 | I16: 12 | J16: 12 | K16: Участвует в расчёте производительности
B17: Время цикла экскавации | C17: сек | D17: 37.3 | E17: 37.3 | F17: 37.3 | G17: 37.3 | H17: 37.3 | I17: 37.3 | J17: 26 | K17: Черпание–поворот–разгрузка–поворот
B18: Ежесменные простои | C18: мин/см | D18: 266.1 | E18: 266.1 | F18: 266.1 | G18: 266.1 | H18: 266.1 | I18: 266.1 | J18: 266.1 | K18: ОТМ, ожидание а/с, прочие организационные
B19: D. ПРОЧИЕ ГОДОВЫЕ ЗАТРАТЫ
B20: Расходы на персонал (экипаж) | C20: тыс.руб/год | D20: 10015 | E20: 10015 | F20: 10015 | G20: 10015 | H20: 10015 | I20: 10015 | J20: 10015 | K20: ФОТ с отчислениями на 1 машину
B21: ℹ КТГ, расход ДТ, ТОиР и расходники на ковш задаются ПО ГОДАМ на листе «Данные по годам». Пустой бланк для сбора данных с поставщика — на листе «Шаблон поставщика».

Sheet Поставщик 1
B1: ШАБЛОН ДАННЫХ ПОСТАВЩИКА — ВАРИАНТ 1
B2: Полные модели ТО и Ремонтов ПО ГОДАМ (затраты и трудозатраты — раздельно для ТО / текущих / капитальных ремонтов). Зелёное — авто; сводка тянется в «Данные по годам».
B4: Экскаватор: | E4: ='Ввод данных'!D7 -> Komatsu PC2000-8 Mining Solutions
B5: Валюта затрат ТОиР: | D5: USD
B6: Показатель | C6: Ед. | E6: год 1 | F6: год 2 | G6: год 3 | H6: год 4 | I6: год 5 | J6: год 6 | K6: год 7 | L6: год 8 | M6: год 9 | N6: год 10
B7: СВОДКА ПО ГОДАМ (зелёное — авто из моделей ниже; тянется в расчёт)
B8: Простои на ТО | C8: ч/год | E8: =E37 -> 273.21 | F8: =F37 -> 273.21 | G8: =G37 -> 273.21 | H8: =H37 -> 273.21 | I8: =I37 -> 273.21 | J8: =J37 -> 273.21 | K8: =K37 -> 273.21 | L8: =L37 -> 273.21 | ... N8: =N37 -> 273.21
B9: Простои в текущих + капитальных ремонтах | C9: ч/год | E9: =E80 -> 160.72 | F9: =F80 -> 377.53 | G9: =G80 -> 737.94 | H9: =H80 -> 828.05 | I9: =I80 -> 737.94 | J9: =J80 -> 1169.1 | K9: =K80 -> 1399.63 | L9: =L80 -> 894.37 | ... N9: =N80 -> 1037.94
B10: Ежесменное ТО (20 мин/смену) | C10: ч/год | E10: =('Параметры'!C26-E8-E9)/'Параметры'!C33*20/60 -> 231.27972 | F10: =('Параметры'!C26-F8-F9)/'Параметры'!C33*20/60 -> 225.25722 | G10: =('Параметры'!C26-G8-G9)/'Параметры'!C33*20/60 -> 215.24583 | H10: =('Параметры'!C26-H8-H9)/'Параметры'!C33*20/60 -> 212.74278 | I10: =('Параметры'!C26-I8-I9)/'Параметры'!C33*20/60 -> 215.24583 | J10: =('Параметры'!C26-J8-J9)/'Параметры'!C33*20/60 -> 203.26917 | K10: =('Параметры'!C26-K8-K9)/'Параметры'!C33*20/60 -> 196.86556 | L10: =('Параметры'!C26-L8-L9)/'Параметры'!C33*20/60 -> 210.90056 | M10: =('Параметры'!C26-M8-M9)/'Параметры'!C33*20/60 -> 184.55583 | N10: =('Параметры'!C26-N8-N9)/'Параметры'!C33*20/60 -> 206.9125
B11: КТГ (авто) = (8760 − простои)/8760 | C11: коэф. | E11: =('Параметры'!C26-E8-E9-E10)/'Параметры'!C26 -> 0.92406282 | F11: =('Параметры'!C26-F8-F9-F10)/'Параметры'!C26 -> 0.90000032 | G11: =('Параметры'!C26-G8-G9-G10)/'Параметры'!C26 -> 0.86000048 | H11: =('Параметры'!C26-H8-H9-H10)/'Параметры'!C26 -> 0.84999968 | I11: =('Параметры'!C26-I8-I9-I10)/'Параметры'!C26 -> 0.86000048 | J11: =('Параметры'!C26-J8-J9-J10)/'Параметры'!C26 -> 0.8121485 | K11: =('Параметры'!C26-K8-K9-K10)/'Параметры'!C26 -> 0.78656329 | L11: =('Параметры'!C26-L8-L9-L10)/'Параметры'!C26 -> 0.84263921 | M11: =('Параметры'!C26-M8-M9-M10)/'Параметры'!C26 -> 0.73738061 | N11: =('Параметры'!C26-N8-N9-N10)/'Параметры'!C26 -> 0.82670519
B12: Затраты на ТО (ЗЧ, из каталога) | C12: тыс/год | E12: =E75 -> 107.51972 | F12: =F75 -> 107.51972 | G12: =G75 -> 107.51972 | H12: =H75 -> 107.51972 | I12: =I75 -> 107.51972 | J12: =J75 -> 107.51972 | K12: =K75 -> 107.51972 | L12: =L75 -> 107.51972 | ... N12: =N75 -> 107.51972
B13: Затраты на текущие ремонты (ЗЧ) | C13: тыс/год | E13: =E88*$E$81 -> 1.742 | F13: =F88*$E$81 -> 4.355 | G13: =G88*$E$81 -> 3.484 | H13: =H88*$E$81 -> 2.613 | I13: =I88*$E$81 -> 3.484 | J13: =J88*$E$81 -> 4.355 | K13: =K88*$E$81 -> 2.613 | L13: =L88*$E$81 -> 3.484 | ... N13: =N88*$E$81 -> 3.484
B14: Затраты на капитальные ремонты (ЗЧ, цех) | C14: тыс/год | E14: =E125*$E$81 -> 0 | F14: =F125*$E$81 -> 1347.6074 | G14: =G125*$E$81 -> 1436.0748 | H14: =H125*$E$81 -> 1347.6074 | I14: =I125*$E$81 -> 5.7667 | J14: =J125*$E$81 -> 2734.3671 | K14: =K125*$E$81 -> 49.3151 | L14: =L125*$E$81 -> 2734.3671 | ... N14: =N125*$E$81 -> 1304.059
B15: Трудозатраты на ТО | C15: ч-час/год | E15: =E43 -> 546.42 | F15: =F43 -> 546.42 | G15: =G43 -> 546.42 | H15: =H43 -> 546.42 | I15: =I43 -> 546.42 | J15: =J43 -> 546.42 | K15: =K43 -> 546.42 | L15: =L43 -> 546.42 | ... N15: =N43 -> 546.42
B16: Трудозатраты на текущие ремонты | C16: ч-час/год | E16: =E93*$E$81 -> 0 | F16: =F93*$E$81 -> 0 | G16: =G93*$E$81 -> 0 | H16: =H93*$E$81 -> 0 | I16: =I93*$E$81 -> 0 | J16: =J93*$E$81 -> 0 | K16: =K93*$E$81 -> 0 | L16: =L93*$E$81 -> 0 | ... N16: =N93*$E$81 -> 0
B17: Трудозатраты на капитальные ремонты (цех) | C17: чел-час/год | E17: =E157*$E$81 -> 0 | F17: =F157*$E$81 -> 316 | G17: =G157*$E$81 -> 524 | H17: =H157*$E$81 -> 316 | I17: =I157*$E$81 -> 8 | J17: =J157*$E$81 -> 760 | K17: =K157*$E$81 -> 80 | L17: =L157*$E$81 -> 760 | ... N17: =N157*$E$81 -> 244
B18: Сервис ТО (авто) = трудозатраты ТО × ставка | C18: тыс/год | E18: =E15*$E$77/1000 -> 27.321 | F18: =F15*$E$77/1000 -> 27.321 | G18: =G15*$E$77/1000 -> 27.321 | H18: =H15*$E$77/1000 -> 27.321 | I18: =I15*$E$77/1000 -> 27.321 | J18: =J15*$E$77/1000 -> 27.321 | K18: =K15*$E$77/1000 -> 27.321 | L18: =L15*$E$77/1000 -> 27.321 | ... N18: =N15*$E$77/1000 -> 27.321
B19: Сервис текущих ремонтов (авто) | C19: тыс/год | E19: =E16*$E$77/1000 -> 0 | F19: =F16*$E$77/1000 -> 0 | G19: =G16*$E$77/1000 -> 0 | H19: =H16*$E$77/1000 -> 0 | I19: =I16*$E$77/1000 -> 0 | J19: =J16*$E$77/1000 -> 0 | K19: =K16*$E$77/1000 -> 0 | L19: =L16*$E$77/1000 -> 0 | ... N19: =N16*$E$77/1000 -> 0
B20: Сервис капитальных ремонтов (цех, авто) | C20: тыс/год | E20: =E17*$E$77/1000 -> 0 | F20: =F17*$E$77/1000 -> 15.8 | G20: =G17*$E$77/1000 -> 26.2 | H20: =H17*$E$77/1000 -> 15.8 | I20: =I17*$E$77/1000 -> 0.4 | J20: =J17*$E$77/1000 -> 38 | K20: =K17*$E$77/1000 -> 4 | L20: =L17*$E$77/1000 -> 38 | ... N20: =N17*$E$77/1000 -> 12.2
B21: ИТОГО ТОиР (авто) → «Данные по годам» | C21: тыс/год | E21: =E12+E13+E14+E18+E19+E20 -> 136.58272 | F21: =F12+F13+F14+F18+F19+F20 -> 1502.6031 | G21: =G12+G13+G14+G18+G19+G20 -> 1600.5995 | H21: =H12+H13+H14+H18+H19+H20 -> 1500.8611 | I21: =I12+I13+I14+I18+I19+I20 -> 144.49142 | J21: =J12+J13+J14+J18+J19+J20 -> 2911.5628 | K21: =K12+K13+K14+K18+K19+K20 -> 190.76882 | L21: =L12+L13+L14+L18+L19+L20 -> 2910.6918 | ... N21: =N12+N13+N14+N18+N19+N20 -> 1454.5837
B22: Удельный расход ДТ | C22: кг/час | E22: 88.46 | F22: 88.46 | G22: 88.46 | H22: 88.46 | I22: 88.46 | J22: 88.46 | K22: 88.46 | L22: 88.46 | M22: 88.46 | N22: 88.46
B23: Расходники на ковш | C23: руб/м³ | E23: 0.87 | F23: 0.87 | G23: 0.87 | H23: 0.87 | I23: 0.87 | J23: 0.87 | K23: 0.87 | L23: 0.87 | M23: 0.87 | N23: 0.87
B24: РАСЧЁТ ТО (по интервалам обслуживания), ПО ГОДАМ
B25: Наработка по годам | C25: м/час | E25: 7000 | F25: 7000 | G25: 7000 | H25: 7000 | I25: 7000 | J25: 7000 | K25: 7000 | L25: 7000 | M25: 7000 | N25: 7000
B26: Вид ТО | C26: интервал | D26: длит.простоя | E26: персонал
B27: ТО-1 | C27: 500 | D27: 10.2 | E27: 2
B28: ТО-2 | C28: 1000 | D28: 9.4 | E28: 2
B29: ТО-3 | C29: 2000 | D29: 12.4 | E29: 2
B30: ТО-4 | C30: 4000 | D30: 7.8 | E30: 2
B31: ТО-5 | C31: 5000 | D31: 5.4 | E31: 2
B32: ТО-1: простои, ч/год | C32: #,##0 | E32: =(E$25/$C27)*$D27 -> 142.8 | F32: =(F$25/$C27)*$D27 -> 142.8 | G32: =(G$25/$C27)*$D27 -> 142.8 | H32: =(H$25/$C27)*$D27 -> 142.8 | I32: =(I$25/$C27)*$D27 -> 142.8 | J32: =(J$25/$C27)*$D27 -> 142.8 | K32: =(K$25/$C27)*$D27 -> 142.8 | L32: =(L$25/$C27)*$D27 -> 142.8 | ... N32: =(N$25/$C27)*$D27 -> 142.8
B33: ТО-2: простои, ч/год | C33: #,##0 | E33: =(E$25/$C28)*$D28 -> 65.8 | F33: =(F$25/$C28)*$D28 -> 65.8 | G33: =(G$25/$C28)*$D28 -> 65.8 | H33: =(H$25/$C28)*$D28 -> 65.8 | I33: =(I$25/$C28)*$D28 -> 65.8 | J33: =(J$25/$C28)*$D28 -> 65.8 | K33: =(K$25/$C28)*$D28 -> 65.8 | L33: =(L$25/$C28)*$D28 -> 65.8 | ... N33: =(N$25/$C28)*$D28 -> 65.8
B34: ТО-3: простои, ч/год | C34: #,##0 | E34: =(E$25/$C29)*$D29 -> 43.4 | F34: =(F$25/$C29)*$D29 -> 43.4 | G34: =(G$25/$C29)*$D29 -> 43.4 | H34: =(H$25/$C29)*$D29 -> 43.4 | I34: =(I$25/$C29)*$D29 -> 43.4 | J34: =(J$25/$C29)*$D29 -> 43.4 | K34: =(K$25/$C29)*$D29 -> 43.4 | L34: =(L$25/$C29)*$D29 -> 43.4 | ... N34: =(N$25/$C29)*$D29 -> 43.4
B35: ТО-4: простои, ч/год | C35: #,##0 | E35: =(E$25/$C30)*$D30 -> 13.65 | F35: =(F$25/$C30)*$D30 -> 13.65 | G35: =(G$25/$C30)*$D30 -> 13.65 | H35: =(H$25/$C30)*$D30 -> 13.65 | I35: =(I$25/$C30)*$D30 -> 13.65 | J35: =(J$25/$C30)*$D30 -> 13.65 | K35: =(K$25/$C30)*$D30 -> 13.65 | L35: =(L$25/$C30)*$D30 -> 13.65 | ... N35: =(N$25/$C30)*$D30 -> 13.65
B36: ТО-5: простои, ч/год | C36: #,##0 | E36: =(E$25/$C31)*$D31 -> 7.56 | F36: =(F$25/$C31)*$D31 -> 7.56 | G36: =(G$25/$C31)*$D31 -> 7.56 | H36: =(H$25/$C31)*$D31 -> 7.56 | I36: =(I$25/$C31)*$D31 -> 7.56 | J36: =(J$25/$C31)*$D31 -> 7.56 | K36: =(K$25/$C31)*$D31 -> 7.56 | L36: =(L$25/$C31)*$D31 -> 7.56 | ... N36: =(N$25/$C31)*$D31 -> 7.56
B37: Итого простои ТО, ч/год | C37: ч/год | E37: =SUM(E32:E36) -> 273.21 | F37: =SUM(F32:F36) -> 273.21 | G37: =SUM(G32:G36) -> 273.21 | H37: =SUM(H32:H36) -> 273.21 | I37: =SUM(I32:I36) -> 273.21 | J37: =SUM(J32:J36) -> 273.21 | K37: =SUM(K32:K36) -> 273.21 | L37: =SUM(L32:L36) -> 273.21 | ... N37: =SUM(N32:N36) -> 273.21
B38: ТО-1: ч·часы/год | C38: #,##0 | E38: =E32*$E27 -> 285.6 | F38: =F32*$E27 -> 285.6 | G38: =G32*$E27 -> 285.6 | H38: =H32*$E27 -> 285.6 | I38: =I32*$E27 -> 285.6 | J38: =J32*$E27 -> 285.6 | K38: =K32*$E27 -> 285.6 | L38: =L32*$E27 -> 285.6 | ... N38: =N32*$E27 -> 285.6
B39: ТО-2: ч·часы/год | C39: #,##0 | E39: =E33*$E28 -> 131.6 | F39: =F33*$E28 -> 131.6 | G39: =G33*$E28 -> 131.6 | H39: =H33*$E28 -> 131.6 | I39: =I33*$E28 -> 131.6 | J39: =J33*$E28 -> 131.6 | K39: =K33*$E28 -> 131.6 | L39: =L33*$E28 -> 131.6 | ... N39: =N33*$E28 -> 131.6
B40: ТО-3: ч·часы/год | C40: #,##0 | E40: =E34*$E29 -> 86.8 | F40: =F34*$E29 -> 86.8 | G40: =G34*$E29 -> 86.8 | H40: =H34*$E29 -> 86.8 | I40: =I34*$E29 -> 86.8 | J40: =J34*$E29 -> 86.8 | K40: =K34*$E29 -> 86.8 | L40: =L34*$E29 -> 86.8 | ... N40: =N34*$E29 -> 86.8
B41: ТО-4: ч·часы/год | C41: #,##0 | E41: =E35*$E30 -> 27.3 | F41: =F35*$E30 -> 27.3 | G41: =G35*$E30 -> 27.3 | H41: =H35*$E30 -> 27.3 | I41: =I35*$E30 -> 27.3 | J41: =J35*$E30 -> 27.3 | K41: =K35*$E30 -> 27.3 | L41: =L35*$E30 -> 27.3 | ... N41: =N35*$E30 -> 27.3
...

Sheet Поставщик 2
B1: ШАБЛОН ДАННЫХ ПОСТАВЩИКА — ВАРИАНТ 2
B2: Полные модели ТО и Ремонтов ПО ГОДАМ (затраты и трудозатраты — раздельно для ТО / текущих / капитальных ремонтов). Зелёное — авто; сводка тянется в «Данные по годам».
B4: Экскаватор: | E4: ='Ввод данных'!E7 -> Komatsu PC2000-11R ИСТК
B5: Валюта затрат ТОиР: | D5: USD
B6: Показатель | C6: Ед. | E6: год 1 | F6: год 2 | G6: год 3 | H6: год 4 | I6: год 5 | J6: год 6 | K6: год 7 | L6: год 8 | M6: год 9 | N6: год 10
B7: СВОДКА ПО ГОДАМ (зелёное — авто из моделей ниже; тянется в расчёт)
B8: Простои на ТО | C8: ч/год | E8: =E37 -> 273.21 | F8: =F37 -> 273.21 | G8: =G37 -> 273.21 | H8: =H37 -> 273.21 | I8: =I37 -> 273.21 | J8: =J37 -> 273.21 | K8: =K37 -> 273.21 | L8: =L37 -> 273.21 | ... N8: =N37 -> 273.21
B9: Простои в текущих + капитальных ремонтах | C9: ч/год | E9: =E80 -> 160.72 | F9: =F80 -> 1298.94 | G9: =G80 -> 1057.5 | H9: =H80 -> 1603.44 | I9: =I80 -> 1613.61 | J9: =J80 -> 1169.1 | K9: =K80 -> 1399.63 | L9: =L80 -> 894.37 | ... N9: =N80 -> 1037.94
B10: Ежесменное ТО (20 мин/смену) | C10: ч/год | E10: =('Параметры'!C26-E8-E9)/'Параметры'!C33*20/60 -> 231.27972 | F10: =('Параметры'!C26-F8-F9)/'Параметры'!C33*20/60 -> 199.6625 | G10: =('Параметры'!C26-G8-G9)/'Параметры'!C33*20/60 -> 206.36917 | H10: =('Параметры'!C26-H8-H9)/'Параметры'!C33*20/60 -> 191.20417 | I10: =('Параметры'!C26-I8-I9)/'Параметры'!C33*20/60 -> 190.92167 | J10: =('Параметры'!C26-J8-J9)/'Параметры'!C33*20/60 -> 203.26917 | K10: =('Параметры'!C26-K8-K9)/'Параметры'!C33*20/60 -> 196.86556 | L10: =('Параметры'!C26-L8-L9)/'Параметры'!C33*20/60 -> 210.90056 | M10: =('Параметры'!C26-M8-M9)/'Параметры'!C33*20/60 -> 184.55583 | N10: =('Параметры'!C26-N8-N9)/'Параметры'!C33*20/60 -> 206.9125
B11: КТГ (авто) = (8760 − простои)/8760 | C11: коэф. | E11: =('Параметры'!C26-E8-E9-E10)/'Параметры'!C26 -> 0.92406282 | F11: =('Параметры'!C26-F8-F9-F10)/'Параметры'!C26 -> 0.7977383 | G11: =('Параметры'!C26-G8-G9-G10)/'Параметры'!C26 -> 0.82453434 | H11: =('Параметры'!C26-H8-H9-H10)/'Параметры'!C26 -> 0.76394359 | I11: =('Параметры'!C26-I8-I9-I10)/'Параметры'!C26 -> 0.76281488 | J11: =('Параметры'!C26-J8-J9-J10)/'Параметры'!C26 -> 0.8121485 | K11: =('Параметры'!C26-K8-K9-K10)/'Параметры'!C26 -> 0.78656329 | L11: =('Параметры'!C26-L8-L9-L10)/'Параметры'!C26 -> 0.84263921 | M11: =('Параметры'!C26-M8-M9-M10)/'Параметры'!C26 -> 0.73738061 | N11: =('Параметры'!C26-N8-N9-N10)/'Параметры'!C26 -> 0.82670519
B12: Затраты на ТО (ЗЧ, из каталога) | C12: тыс/год | E12: =E75 -> 107.51972 | F12: =F75 -> 107.51972 | G12: =G75 -> 107.51972 | H12: =H75 -> 107.51972 | I12: =I75 -> 107.51972 | J12: =J75 -> 107.51972 | K12: =K75 -> 107.51972 | L12: =L75 -> 107.51972 | ... N12: =N75 -> 107.51972
B13: Затраты на текущие ремонты (ЗЧ) | C13: тыс/год | E13: =E86*$E$81 -> 0 | F13: =F86*$E$81 -> 0 | G13: =G86*$E$81 -> 0 | H13: =H86*$E$81 -> 0 | I13: =I86*$E$81 -> 0 | J13: =J86*$E$81 -> 0 | K13: =K86*$E$81 -> 0 | L13: =L86*$E$81 -> 0 | ... N13: =N86*$E$81 -> 0
B14: Затраты на капитальные ремонты (ЗЧ, цех) | C14: тыс/год | E14: =E111*$E$81 -> 0 | F14: =F111*$E$81 -> 38.6841 | G14: =G111*$E$81 -> 525.8771 | H14: =H111*$E$81 -> 1317.0265 | I14: =I111*$E$81 -> 110 | J14: =J111*$E$81 -> 564.5612 | K14: =K111*$E$81 -> 38.6841 | L14: =L111*$E$81 -> 1278.3424 | ... N14: =N111*$E$81 -> 0
B15: Трудозатраты на ТО | C15: ч-час/год | E15: =E43 -> 546.42 | F15: =F43 -> 546.42 | G15: =G43 -> 546.42 | H15: =H43 -> 546.42 | I15: =I43 -> 546.42 | J15: =J43 -> 546.42 | K15: =K43 -> 546.42 | L15: =L43 -> 546.42 | ... N15: =N43 -> 546.42
B16: Трудозатраты на текущие ремонты | C16: ч-час/год | E16: =E91*$E$81 -> 0 | F16: =F91*$E$81 -> 0 | G16: =G91*$E$81 -> 0 | H16: =H91*$E$81 -> 0 | I16: =I91*$E$81 -> 0 | J16: =J91*$E$81 -> 0 | K16: =K91*$E$81 -> 0 | L16: =L91*$E$81 -> 0 | ... N16: =N91*$E$81 -> 0
B17: Трудозатраты на капитальные ремонты (цех) | C17: чел-час/год | E17: =E131*$E$81 -> 0 | F17: =F131*$E$81 -> 32 | G17: =G131*$E$81 -> 148 | H17: =H131*$E$81 -> 236 | I17: =I131*$E$81 -> 24 | J17: =J131*$E$81 -> 180 | K17: =K131*$E$81 -> 32 | L17: =L131*$E$81 -> 204 | ... N17: =N131*$E$81 -> 0
B18: Сервис ТО (авто) = трудозатраты ТО × ставка | C18: тыс/год | E18: =E15*$E$77/1000 -> 27.321 | F18: =F15*$E$77/1000 -> 27.321 | G18: =G15*$E$77/1000 -> 27.321 | H18: =H15*$E$77/1000 -> 27.321 | I18: =I15*$E$77/1000 -> 27.321 | J18: =J15*$E$77/1000 -> 27.321 | K18: =K15*$E$77/1000 -> 27.321 | L18: =L15*$E$77/1000 -> 27.321 | ... N18: =N15*$E$77/1000 -> 27.321
B19: Сервис текущих ремонтов (авто) | C19: тыс/год | E19: =E16*$E$77/1000 -> 0 | F19: =F16*$E$77/1000 -> 0 | G19: =G16*$E$77/1000 -> 0 | H19: =H16*$E$77/1000 -> 0 | I19: =I16*$E$77/1000 -> 0 | J19: =J16*$E$77/1000 -> 0 | K19: =K16*$E$77/1000 -> 0 | L19: =L16*$E$77/1000 -> 0 | ... N19: =N16*$E$77/1000 -> 0
B20: Сервис капитальных ремонтов (цех, авто) | C20: тыс/год | E20: =E17*$E$77/1000 -> 0 | F20: =F17*$E$77/1000 -> 1.6 | G20: =G17*$E$77/1000 -> 7.4 | H20: =H17*$E$77/1000 -> 11.8 | I20: =I17*$E$77/1000 -> 1.2 | J20: =J17*$E$77/1000 -> 9 | K20: =K17*$E$77/1000 -> 1.6 | L20: =L17*$E$77/1000 -> 10.2 | ... N20: =N17*$E$77/1000 -> 0
B21: ИТОГО ТОиР (авто) → «Данные по годам» | C21: тыс/год | E21: =E12+E13+E14+E18+E19+E20 -> 134.84072 | F21: =F12+F13+F14+F18+F19+F20 -> 175.12482 | G21: =G12+G13+G14+G18+G19+G20 -> 668.11782 | H21: =H12+H13+H14+H18+H19+H20 -> 1463.6672 | I21: =I12+I13+I14+I18+I19+I20 -> 246.04072 | J21: =J12+J13+J14+J18+J19+J20 -> 708.40192 | K21: =K12+K13+K14+K18+K19+K20 -> 175.12482 | L21: =L12+L13+L14+L18+L19+L20 -> 1423.3831 | ... N21: =N12+N13+N14+N18+N19+N20 -> 134.84072
B22: Удельный расход ДТ | C22: кг/час | E22: 85.81 | F22: 85.81 | G22: 85.81 | H22: 85.81 | I22: 85.81 | J22: 85.81 | K22: 85.81 | L22: 85.81 | M22: 85.81 | N22: 85.81
B23: Расходники на ковш | C23: руб/м³ | E23: 0.87 | F23: 0.87 | G23: 0.87 | H23: 0.87 | I23: 0.87 | J23: 0.87 | K23: 0.87 | L23: 0.87 | M23: 0.87 | N23: 0.87
B24: РАСЧЁТ ТО (по интервалам обслуживания), ПО ГОДАМ
B25: Наработка по годам | C25: м/час | E25: 7000 | F25: 7000 | G25: 7000 | H25: 7000 | I25: 7000 | J25: 7000 | K25: 7000 | L25: 7000 | M25: 7000 | N25: 7000
B26: Вид ТО | C26: интервал | D26: длит.простоя | E26: персонал
B27: ТО-1 | C27: 500 | D27: 10.2 | E27: 2
B28: ТО-2 | C28: 1000 | D28: 9.4 | E28: 2
B29: ТО-3 | C29: 2000 | D29: 12.4 | E29: 2
B30: ТО-4 | C30: 4000 | D30: 7.8 | E30: 2
B31: ТО-5 | C31: 5000 | D31: 5.4 | E31: 2
B32: ТО-1: простои, ч/год | C32: #,##0 | E32: =(E$25/$C27)*$D27 -> 142.8 | F32: =(F$25/$C27)*$D27 -> 142.8 | G32: =(G$25/$C27)*$D27 -> 142.8 | H32: =(H$25/$C27)*$D27 -> 142.8 | I32: =(I$25/$C27)*$D27 -> 142.8 | J32: =(J$25/$C27)*$D27 -> 142.8 | K32: =(K$25/$C27)*$D27 -> 142.8 | L32: =(L$25/$C27)*$D27 -> 142.8 | ... N32: =(N$25/$C27)*$D27 -> 142.8
B33: ТО-2: простои, ч/год | C33: #,##0 | E33: =(E$25/$C28)*$D28 -> 65.8 | F33: =(F$25/$C28)*$D28 -> 65.8 | G33: =(G$25/$C28)*$D28 -> 65.8 | H33: =(H$25/$C28)*$D28 -> 65.8 | I33: =(I$25/$C28)*$D28 -> 65.8 | J33: =(J$25/$C28)*$D28 -> 65.8 | K33: =(K$25/$C28)*$D28 -> 65.8 | L33: =(L$25/$C28)*$D28 -> 65.8 | ... N33: =(N$25/$C28)*$D28 -> 65.8
B34: ТО-3: простои, ч/год | C34: #,##0 | E34: =(E$25/$C29)*$D29 -> 43.4 | F34: =(F$25/$C29)*$D29 -> 43.4 | G34: =(G$25/$C29)*$D29 -> 43.4 | H34: =(H$25/$C29)*$D29 -> 43.4 | I34: =(I$25/$C29)*$D29 -> 43.4 | J34: =(J$25/$C29)*$D29 -> 43.4 | K34: =(K$25/$C29)*$D29 -> 43.4 | L34: =(L$25/$C29)*$D29 -> 43.4 | ... N34: =(N$25/$C29)*$D29 -> 43.4
B35: ТО-4: простои, ч/год | C35: #,##0 | E35: =(E$25/$C30)*$D30 -> 13.65 | F35: =(F$25/$C30)*$D30 -> 13.65 | G35: =(G$25/$C30)*$D30 -> 13.65 | H35: =(H$25/$C30)*$D30 -> 13.65 | I35: =(I$25/$C30)*$D30 -> 13.65 | J35: =(J$25/$C30)*$D30 -> 13.65 | K35: =(K$25/$C30)*$D30 -> 13.65 | L35: =(L$25/$C30)*$D30 -> 13.65 | ... N35: =(N$25/$C30)*$D30 -> 13.65
B36: ТО-5: простои, ч/год | C36: #,##0 | E36: =(E$25/$C31)*$D31 -> 7.56 | F36: =(F$25/$C31)*$D31 -> 7.56 | G36: =(G$25/$C31)*$D31 -> 7.56 | H36: =(H$25/$C31)*$D31 -> 7.56 | I36: =(I$25/$C31)*$D31 -> 7.56 | J36: =(J$25/$C31)*$D31 -> 7.56 | K36: =(K$25/$C31)*$D31 -> 7.56 | L36: =(L$25/$C31)*$D31 -> 7.56 | ... N36: =(N$25/$C31)*$D31 -> 7.56
B37: Итого простои ТО, ч/год | C37: ч/год | E37: =SUM(E32:E36) -> 273.21 | F37: =SUM(F32:F36) -> 273.21 | G37: =SUM(G32:G36) -> 273.21 | H37: =SUM(H32:H36) -> 273.21 | I37: =SUM(I32:I36) -> 273.21 | J37: =SUM(J32:J36) -> 273.21 | K37: =SUM(K32:K36) -> 273.21 | L37: =SUM(L32:L36) -> 273.21 | ... N37: =SUM(N32:N36) -> 273.21
B38: ТО-1: ч·часы/год | C38: #,##0 | E38: =E32*$E27 -> 285.6 | F38: =F32*$E27 -> 285.6 | G38: =G32*$E27 -> 285.6 | H38: =H32*$E27 -> 285.6 | I38: =I32*$E27 -> 285.6 | J38: =J32*$E27 -> 285.6 | K38: =K32*$E27 -> 285.6 | L38: =L32*$E27 -> 285.6 | ... N38: =N32*$E27 -> 285.6
B39: ТО-2: ч·часы/год | C39: #,##0 | E39: =E33*$E28 -> 131.6 | F39: =F33*$E28 -> 131.6 | G39: =G33*$E28 -> 131.6 | H39: =H33*$E28 -> 131.6 | I39: =I33*$E28 -> 131.6 | J39: =J33*$E28 -> 131.6 | K39: =K33*$E28 -> 131.6 | L39: =L33*$E28 -> 131.6 | ... N39: =N33*$E28 -> 131.6
B40: ТО-3: ч·часы/год | C40: #,##0 | E40: =E34*$E29 -> 86.8 | F40: =F34*$E29 -> 86.8 | G40: =G34*$E29 -> 86.8 | H40: =H34*$E29 -> 86.8 | I40: =I34*$E29 -> 86.8 | J40: =J34*$E29 -> 86.8 | K40: =K34*$E29 -> 86.8 | L40: =L34*$E29 -> 86.8 | ... N40: =N34*$E29 -> 86.8
B41: ТО-4: ч·часы/год | C41: #,##0 | E41: =E35*$E30 -> 27.3 | F41: =F35*$E30 -> 27.3 | G41: =G35*$E30 -> 27.3 | H41: =H35*$E30 -> 27.3 | I41: =I35*$E30 -> 27.3 | J41: =J35*$E30 -> 27.3 | K41: =K35*$E30 -> 27.3 | L41: =L35*$E30 -> 27.3 | ... N41: =N35*$E30 -> 27.3
...

Sheet Поставщик 3
B1: ШАБЛОН ДАННЫХ ПОСТАВЩИКА — ВАРИАНТ 3
B2: Полные модели ТО и Ремонтов ПО ГОДАМ (затраты и трудозатраты — раздельно для ТО / текущих / капитальных ремонтов). Зелёное — авто; сводка тянется в «Данные по годам».
B4: Экскаватор: | E4: ='Ввод данных'!F7 -> Zoomlion ZE2000G Орикс
B5: Валюта затрат ТОиР: | D5: USD
B6: Показатель | C6: Ед. | E6: год 1 | F6: год 2 | G6: год 3 | H6: год 4 | I6: год 5 | J6: год 6 | K6: год 7 | L6: год 8 | M6: год 9 | N6: год 10
B7: СВОДКА ПО ГОДАМ (зелёное — авто из моделей ниже; тянется в расчёт)
B8: Простои на ТО | C8: ч/год | E8: =E37 -> 273.21 | F8: =F37 -> 273.21 | G8: =G37 -> 273.21 | H8: =H37 -> 273.21 | I8: =I37 -> 273.21 | J8: =J37 -> 273.21 | K8: =K37 -> 273.21 | L8: =L37 -> 273.21 | ... N8: =N37 -> 273.21
B9: Простои в текущих + капитальных ремонтах | C9: ч/год | E9: =E80 -> 786.13 | F9: =F80 -> 1924.36 | G9: =G80 -> 1682.92 | H9: =H80 -> 2228.84 | I9: =I80 -> 2239.02 | J9: =J80 -> 1794.52 | K9: =K80 -> 2025.05 | L9: =L80 -> 1519.78 | ... N9: =N80 -> 1663.35
B10: Ежесменное ТО (20 мин/смену) | C10: ч/год | E10: =('Параметры'!C26-E8-E9)/'Параметры'!C33*20/60 -> 213.90722 | F10: =('Параметры'!C26-F8-F9)/'Параметры'!C33*20/60 -> 182.28972 | G10: =('Параметры'!C26-G8-G9)/'Параметры'!C33*20/60 -> 188.99639 | H10: =('Параметры'!C26-H8-H9)/'Параметры'!C33*20/60 -> 173.83194 | I10: =('Параметры'!C26-I8-I9)/'Параметры'!C33*20/60 -> 173.54917 | J10: =('Параметры'!C26-J8-J9)/'Параметры'!C33*20/60 -> 185.89639 | K10: =('Параметры'!C26-K8-K9)/'Параметры'!C33*20/60 -> 179.49278 | L10: =('Параметры'!C26-L8-L9)/'Параметры'!C33*20/60 -> 193.52806 | M10: =('Параметры'!C26-M8-M9)/'Параметры'!C33*20/60 -> 167.18333 | N10: =('Параметры'!C26-N8-N9)/'Параметры'!C33*20/60 -> 189.54
B11: КТГ (авто) = (8760 − простои)/8760 | C11: коэф. | E11: =('Параметры'!C26-E8-E9-E10)/'Параметры'!C26 -> 0.85465214 | F11: =('Параметры'!C26-F8-F9-F10)/'Параметры'!C26 -> 0.72832652 | G11: =('Параметры'!C26-G8-G9-G10)/'Параметры'!C26 -> 0.75512256 | H11: =('Параметры'!C26-H8-H9-H10)/'Параметры'!C26 -> 0.69453402 | I11: =('Параметры'!C26-I8-I9-I10)/'Параметры'!C26 -> 0.6934042 | J11: =('Параметры'!C26-J8-J9-J10)/'Параметры'!C26 -> 0.74273671 | K11: =('Параметры'!C26-K8-K9-K10)/'Параметры'!C26 -> 0.71715151 | L11: =('Параметры'!C26-L8-L9-L10)/'Параметры'!C26 -> 0.77322853 | M11: =('Параметры'!C26-M8-M9-M10)/'Параметры'!C26 -> 0.66796994 | N11: =('Параметры'!C26-N8-N9-N10)/'Параметры'!C26 -> 0.75729452
B12: Затраты на ТО (ЗЧ, из каталога) | C12: тыс/год | E12: =E75 -> 107.51972 | F12: =F75 -> 107.51972 | G12: =G75 -> 107.51972 | H12: =H75 -> 107.51972 | I12: =I75 -> 107.51972 | J12: =J75 -> 107.51972 | K12: =K75 -> 107.51972 | L12: =L75 -> 107.51972 | ... N12: =N75 -> 107.51972
B13: Затраты на текущие ремонты (ЗЧ) | C13: тыс/год | E13: =E90*$E$81 -> 29.143 | F13: =F90*$E$81 -> 29.143 | G13: =G90*$E$81 -> 32.4 | H13: =H90*$E$81 -> 29.143 | I13: =I90*$E$81 -> 30.704 | J13: =J90*$E$81 -> 30.839 | K13: =K90*$E$81 -> 30.704 | L13: =L90*$E$81 -> 29.143 | ... N13: =N90*$E$81 -> 29.143
B14: Затраты на капитальные ремонты (ЗЧ, цех) | C14: тыс/год | E14: =E112*$E$81 -> 0 | F14: =F112*$E$81 -> 24.929 | G14: =G112*$E$81 -> 608.818 | H14: =H112*$E$81 -> 89 | I14: =I112*$E$81 -> 608.818 | J14: =J112*$E$81 -> 24.929 | K14: =K112*$E$81 -> 583.889 | L14: =L112*$E$81 -> 113.929 | ... N14: =N112*$E$81 -> 24.929
B15: Трудозатраты на ТО | C15: ч-час/год | E15: =E43 -> 546.42 | F15: =F43 -> 546.42 | G15: =G43 -> 546.42 | H15: =H43 -> 546.42 | I15: =I43 -> 546.42 | J15: =J43 -> 546.42 | K15: =K43 -> 546.42 | L15: =L43 -> 546.42 | ... N15: =N43 -> 546.42
B16: Трудозатраты на текущие ремонты | C16: ч-час/год | E16: =E95*$E$81 -> 80 | F16: =F95*$E$81 -> 80 | G16: =G95*$E$81 -> 80 | H16: =H95*$E$81 -> 80 | I16: =I95*$E$81 -> 80 | J16: =J95*$E$81 -> 80 | K16: =K95*$E$81 -> 80 | L16: =L95*$E$81 -> 80 | ... N16: =N95*$E$81 -> 80
B17: Трудозатраты на капитальные ремонты (цех) | C17: чел-час/год | E17: =E121*$E$81 -> 0 | F17: =F121*$E$81 -> 40 | G17: =G121*$E$81 -> 380 | H17: =H121*$E$81 -> 80 | I17: =I121*$E$81 -> 380 | J17: =J121*$E$81 -> 40 | K17: =K121*$E$81 -> 340 | L17: =L121*$E$81 -> 120 | ... N17: =N121*$E$81 -> 40
B18: Сервис ТО (авто) = трудозатраты ТО × ставка | C18: тыс/год | E18: =E15*$E$77/1000 -> 27.321 | F18: =F15*$E$77/1000 -> 27.321 | G18: =G15*$E$77/1000 -> 27.321 | H18: =H15*$E$77/1000 -> 27.321 | I18: =I15*$E$77/1000 -> 27.321 | J18: =J15*$E$77/1000 -> 27.321 | K18: =K15*$E$77/1000 -> 27.321 | L18: =L15*$E$77/1000 -> 27.321 | ... N18: =N15*$E$77/1000 -> 27.321
B19: Сервис текущих ремонтов (авто) | C19: тыс/год | E19: =E16*$E$77/1000 -> 4 | F19: =F16*$E$77/1000 -> 4 | G19: =G16*$E$77/1000 -> 4 | H19: =H16*$E$77/1000 -> 4 | I19: =I16*$E$77/1000 -> 4 | J19: =J16*$E$77/1000 -> 4 | K19: =K16*$E$77/1000 -> 4 | L19: =L16*$E$77/1000 -> 4 | ... N19: =N16*$E$77/1000 -> 4
B20: Сервис капитальных ремонтов (цех, авто) | C20: тыс/год | E20: =E17*$E$77/1000 -> 0 | F20: =F17*$E$77/1000 -> 2 | G20: =G17*$E$77/1000 -> 19 | H20: =H17*$E$77/1000 -> 4 | I20: =I17*$E$77/1000 -> 19 | J20: =J17*$E$77/1000 -> 2 | K20: =K17*$E$77/1000 -> 17 | L20: =L17*$E$77/1000 -> 6 | ... N20: =N17*$E$77/1000 -> 2
B21: ИТОГО ТОиР (авто) → «Данные по годам» | C21: тыс/год | E21: =E12+E13+E14+E18+E19+E20 -> 167.98372 | F21: =F12+F13+F14+F18+F19+F20 -> 194.91272 | G21: =G12+G13+G14+G18+G19+G20 -> 799.05872 | H21: =H12+H13+H14+H18+H19+H20 -> 260.98372 | I21: =I12+I13+I14+I18+I19+I20 -> 797.36272 | J21: =J12+J13+J14+J18+J19+J20 -> 196.60872 | K21: =K12+K13+K14+K18+K19+K20 -> 770.43372 | L21: =L12+L13+L14+L18+L19+L20 -> 287.91272 | ... N21: =N12+N13+N14+N18+N19+N20 -> 194.91272
B22: Удельный расход ДТ | C22: кг/час | E22: 90.23 | F22: 90.23 | G22: 90.23 | H22: 90.23 | I22: 90.23 | J22: 90.23 | K22: 90.23 | L22: 90.23 | M22: 90.23 | N22: 90.23
B23: Расходники на ковш | C23: руб/м³ | E23: 0.87 | F23: 0.87 | G23: 0.87 | H23: 0.87 | I23: 0.87 | J23: 0.87 | K23: 0.87 | L23: 0.87 | M23: 0.87 | N23: 0.87
B24: РАСЧЁТ ТО (по интервалам обслуживания), ПО ГОДАМ
B25: Наработка по годам | C25: м/час | E25: 7000 | F25: 7000 | G25: 7000 | H25: 7000 | I25: 7000 | J25: 7000 | K25: 7000 | L25: 7000 | M25: 7000 | N25: 7000
B26: Вид ТО | C26: интервал | D26: длит.простоя | E26: персонал
B27: ТО-1 | C27: 500 | D27: 10.2 | E27: 2
B28: ТО-2 | C28: 1000 | D28: 9.4 | E28: 2
B29: ТО-3 | C29: 2000 | D29: 12.4 | E29: 2
B30: ТО-4 | C30: 4000 | D30: 7.8 | E30: 2
B31: ТО-5 | C31: 5000 | D31: 5.4 | E31: 2
B32: ТО-1: простои, ч/год | C32: #,##0 | E32: =(E$25/$C27)*$D27 -> 142.8 | F32: =(F$25/$C27)*$D27 -> 142.8 | G32: =(G$25/$C27)*$D27 -> 142.8 | H32: =(H$25/$C27)*$D27 -> 142.8 | I32: =(I$25/$C27)*$D27 -> 142.8 | J32: =(J$25/$C27)*$D27 -> 142.8 | K32: =(K$25/$C27)*$D27 -> 142.8 | L32: =(L$25/$C27)*$D27 -> 142.8 | ... N32: =(N$25/$C27)*$D27 -> 142.8
B33: ТО-2: простои, ч/год | C33: #,##0 | E33: =(E$25/$C28)*$D28 -> 65.8 | F33: =(F$25/$C28)*$D28 -> 65.8 | G33: =(G$25/$C28)*$D28 -> 65.8 | H33: =(H$25/$C28)*$D28 -> 65.8 | I33: =(I$25/$C28)*$D28 -> 65.8 | J33: =(J$25/$C28)*$D28 -> 65.8 | K33: =(K$25/$C28)*$D28 -> 65.8 | L33: =(L$25/$C28)*$D28 -> 65.8 | ... N33: =(N$25/$C28)*$D28 -> 65.8
B34: ТО-3: простои, ч/год | C34: #,##0 | E34: =(E$25/$C29)*$D29 -> 43.4 | F34: =(F$25/$C29)*$D29 -> 43.4 | G34: =(G$25/$C29)*$D29 -> 43.4 | H34: =(H$25/$C29)*$D29 -> 43.4 | I34: =(I$25/$C29)*$D29 -> 43.4 | J34: =(J$25/$C29)*$D29 -> 43.4 | K34: =(K$25/$C29)*$D29 -> 43.4 | L34: =(L$25/$C29)*$D29 -> 43.4 | ... N34: =(N$25/$C29)*$D29 -> 43.4
B35: ТО-4: простои, ч/год | C35: #,##0 | E35: =(E$25/$C30)*$D30 -> 13.65 | F35: =(F$25/$C30)*$D30 -> 13.65 | G35: =(G$25/$C30)*$D30 -> 13.65 | H35: =(H$25/$C30)*$D30 -> 13.65 | I35: =(I$25/$C30)*$D30 -> 13.65 | J35: =(J$25/$C30)*$D30 -> 13.65 | K35: =(K$25/$C30)*$D30 -> 13.65 | L35: =(L$25/$C30)*$D30 -> 13.65 | ... N35: =(N$25/$C30)*$D30 -> 13.65
B36: ТО-5: простои, ч/год | C36: #,##0 | E36: =(E$25/$C31)*$D31 -> 7.56 | F36: =(F$25/$C31)*$D31 -> 7.56 | G36: =(G$25/$C31)*$D31 -> 7.56 | H36: =(H$25/$C31)*$D31 -> 7.56 | I36: =(I$25/$C31)*$D31 -> 7.56 | J36: =(J$25/$C31)*$D31 -> 7.56 | K36: =(K$25/$C31)*$D31 -> 7.56 | L36: =(L$25/$C31)*$D31 -> 7.56 | ... N36: =(N$25/$C31)*$D31 -> 7.56
B37: Итого простои ТО, ч/год | C37: ч/год | E37: =SUM(E32:E36) -> 273.21 | F37: =SUM(F32:F36) -> 273.21 | G37: =SUM(G32:G36) -> 273.21 | H37: =SUM(H32:H36) -> 273.21 | I37: =SUM(I32:I36) -> 273.21 | J37: =SUM(J32:J36) -> 273.21 | K37: =SUM(K32:K36) -> 273.21 | L37: =SUM(L32:L36) -> 273.21 | ... N37: =SUM(N32:N36) -> 273.21
B38: ТО-1: ч·часы/год | C38: #,##0 | E38: =E32*$E27 -> 285.6 | F38: =F32*$E27 -> 285.6 | G38: =G32*$E27 -> 285.6 | H38: =H32*$E27 -> 285.6 | I38: =I32*$E27 -> 285.6 | J38: =J32*$E27 -> 285.6 | K38: =K32*$E27 -> 285.6 | L38: =L32*$E27 -> 285.6 | ... N38: =N32*$E27 -> 285.6
B39: ТО-2: ч·часы/год | C39: #,##0 | E39: =E33*$E28 -> 131.6 | F39: =F33*$E28 -> 131.6 | G39: =G33*$E28 -> 131.6 | H39: =H33*$E28 -> 131.6 | I39: =I33*$E28 -> 131.6 | J39: =J33*$E28 -> 131.6 | K39: =K33*$E28 -> 131.6 | L39: =L33*$E28 -> 131.6 | ... N39: =N33*$E28 -> 131.6
B40: ТО-3: ч·часы/год | C40: #,##0 | E40: =E34*$E29 -> 86.8 | F40: =F34*$E29 -> 86.8 | G40: =G34*$E29 -> 86.8 | H40: =H34*$E29 -> 86.8 | I40: =I34*$E29 -> 86.8 | J40: =J34*$E29 -> 86.8 | K40: =K34*$E29 -> 86.8 | L40: =L34*$E29 -> 86.8 | ... N40: =N34*$E29 -> 86.8
B41: ТО-4: ч·часы/год | C41: #,##0 | E41: =E35*$E30 -> 27.3 | F41: =F35*$E30 -> 27.3 | G41: =G35*$E30 -> 27.3 | H41: =H35*$E30 -> 27.3 | I41: =I35*$E30 -> 27.3 | J41: =J35*$E30 -> 27.3 | K41: =K35*$E30 -> 27.3 | L41: =L35*$E30 -> 27.3 | ... N41: =N35*$E30 -> 27.3
...

Sheet Поставщик 4
B1: ШАБЛОН ДАННЫХ ПОСТАВЩИКА — ВАРИАНТ 4
B2: Полные модели ТО и Ремонтов ПО ГОДАМ (затраты и трудозатраты — раздельно для ТО / текущих / капитальных ремонтов). Зелёное — авто; сводка тянется в «Данные по годам».
B4: Экскаватор: | E4: ='Ввод данных'!G7 -> Sany SY2000 АСТ
B5: Валюта затрат ТОиР: | D5: USD
B6: Показатель | C6: Ед. | E6: год 1 | F6: год 2 | G6: год 3 | H6: год 4 | I6: год 5 | J6: год 6 | K6: год 7 | L6: год 8 | M6: год 9 | N6: год 10
B7: СВОДКА ПО ГОДАМ (зелёное — авто из моделей ниже; тянется в расчёт)
B8: Простои на ТО | C8: ч/год | E8: =E37 -> 273.21 | F8: =F37 -> 273.21 | G8: =G37 -> 273.21 | H8: =H37 -> 273.21 | I8: =I37 -> 273.21 | J8: =J37 -> 273.21 | K8: =K37 -> 273.21 | L8: =L37 -> 273.21 | ... N8: =N37 -> 273.21
B9: Простои в текущих + капитальных ремонтах | C9: ч/год | E9: =E80 -> 786.13 | F9: =F80 -> 1924.36 | G9: =G80 -> 1682.92 | H9: =H80 -> 2228.84 | I9: =I80 -> 2239.02 | J9: =J80 -> 1794.52 | K9: =K80 -> 2025.05 | L9: =L80 -> 1519.78 | ... N9: =N80 -> 1663.35
B10: Ежесменное ТО (20 мин/смену) | C10: ч/год | E10: =('Параметры'!C26-E8-E9)/'Параметры'!C33*20/60 -> 213.90722 | F10: =('Параметры'!C26-F8-F9)/'Параметры'!C33*20/60 -> 182.28972 | G10: =('Параметры'!C26-G8-G9)/'Параметры'!C33*20/60 -> 188.99639 | H10: =('Параметры'!C26-H8-H9)/'Параметры'!C33*20/60 -> 173.83194 | I10: =('Параметры'!C26-I8-I9)/'Параметры'!C33*20/60 -> 173.54917 | J10: =('Параметры'!C26-J8-J9)/'Параметры'!C33*20/60 -> 185.89639 | K10: =('Параметры'!C26-K8-K9)/'Параметры'!C33*20/60 -> 179.49278 | L10: =('Параметры'!C26-L8-L9)/'Параметры'!C33*20/60 -> 193.52806 | M10: =('Параметры'!C26-M8-M9)/'Параметры'!C33*20/60 -> 167.18333 | N10: =('Параметры'!C26-N8-N9)/'Параметры'!C33*20/60 -> 189.54
B11: КТГ (авто) = (8760 − простои)/8760 | C11: коэф. | E11: =('Параметры'!C26-E8-E9-E10)/'Параметры'!C26 -> 0.85465214 | F11: =('Параметры'!C26-F8-F9-F10)/'Параметры'!C26 -> 0.72832652 | G11: =('Параметры'!C26-G8-G9-G10)/'Параметры'!C26 -> 0.75512256 | H11: =('Параметры'!C26-H8-H9-H10)/'Параметры'!C26 -> 0.69453402 | I11: =('Параметры'!C26-I8-I9-I10)/'Параметры'!C26 -> 0.6934042 | J11: =('Параметры'!C26-J8-J9-J10)/'Параметры'!C26 -> 0.74273671 | K11: =('Параметры'!C26-K8-K9-K10)/'Параметры'!C26 -> 0.71715151 | L11: =('Параметры'!C26-L8-L9-L10)/'Параметры'!C26 -> 0.77322853 | M11: =('Параметры'!C26-M8-M9-M10)/'Параметры'!C26 -> 0.66796994 | N11: =('Параметры'!C26-N8-N9-N10)/'Параметры'!C26 -> 0.75729452
B12: Затраты на ТО (ЗЧ, из каталога) | C12: тыс/год | E12: =E75 -> 107.51972 | F12: =F75 -> 107.51972 | G12: =G75 -> 107.51972 | H12: =H75 -> 107.51972 | I12: =I75 -> 107.51972 | J12: =J75 -> 107.51972 | K12: =K75 -> 107.51972 | L12: =L75 -> 107.51972 | ... N12: =N75 -> 107.51972
B13: Затраты на текущие ремонты (ЗЧ) | C13: тыс/год | E13: =E90*$E$81 -> 29.143 | F13: =F90*$E$81 -> 29.143 | G13: =G90*$E$81 -> 32.4 | H13: =H90*$E$81 -> 29.143 | I13: =I90*$E$81 -> 30.704 | J13: =J90*$E$81 -> 30.839 | K13: =K90*$E$81 -> 30.704 | L13: =L90*$E$81 -> 29.143 | ... N13: =N90*$E$81 -> 29.143
B14: Затраты на капитальные ремонты (ЗЧ, цех) | C14: тыс/год | E14: =E112*$E$81 -> 0 | F14: =F112*$E$81 -> 24.929 | G14: =G112*$E$81 -> 608.818 | H14: =H112*$E$81 -> 89 | I14: =I112*$E$81 -> 608.818 | J14: =J112*$E$81 -> 24.929 | K14: =K112*$E$81 -> 583.889 | L14: =L112*$E$81 -> 113.929 | ... N14: =N112*$E$81 -> 24.929
B15: Трудозатраты на ТО | C15: ч-час/год | E15: =E43 -> 546.42 | F15: =F43 -> 546.42 | G15: =G43 -> 546.42 | H15: =H43 -> 546.42 | I15: =I43 -> 546.42 | J15: =J43 -> 546.42 | K15: =K43 -> 546.42 | L15: =L43 -> 546.42 | ... N15: =N43 -> 546.42
B16: Трудозатраты на текущие ремонты | C16: ч-час/год | E16: =E95*$E$81 -> 80 | F16: =F95*$E$81 -> 80 | G16: =G95*$E$81 -> 80 | H16: =H95*$E$81 -> 80 | I16: =I95*$E$81 -> 80 | J16: =J95*$E$81 -> 80 | K16: =K95*$E$81 -> 80 | L16: =L95*$E$81 -> 80 | ... N16: =N95*$E$81 -> 80
B17: Трудозатраты на капитальные ремонты (цех) | C17: чел-час/год | E17: =E121*$E$81 -> 0 | F17: =F121*$E$81 -> 40 | G17: =G121*$E$81 -> 380 | H17: =H121*$E$81 -> 80 | I17: =I121*$E$81 -> 380 | J17: =J121*$E$81 -> 40 | K17: =K121*$E$81 -> 340 | L17: =L121*$E$81 -> 120 | ... N17: =N121*$E$81 -> 40
B18: Сервис ТО (авто) = трудозатраты ТО × ставка | C18: тыс/год | E18: =E15*$E$77/1000 -> 27.321 | F18: =F15*$E$77/1000 -> 27.321 | G18: =G15*$E$77/1000 -> 27.321 | H18: =H15*$E$77/1000 -> 27.321 | I18: =I15*$E$77/1000 -> 27.321 | J18: =J15*$E$77/1000 -> 27.321 | K18: =K15*$E$77/1000 -> 27.321 | L18: =L15*$E$77/1000 -> 27.321 | ... N18: =N15*$E$77/1000 -> 27.321
B19: Сервис текущих ремонтов (авто) | C19: тыс/год | E19: =E16*$E$77/1000 -> 4 | F19: =F16*$E$77/1000 -> 4 | G19: =G16*$E$77/1000 -> 4 | H19: =H16*$E$77/1000 -> 4 | I19: =I16*$E$77/1000 -> 4 | J19: =J16*$E$77/1000 -> 4 | K19: =K16*$E$77/1000 -> 4 | L19: =L16*$E$77/1000 -> 4 | ... N19: =N16*$E$77/1000 -> 4
B20: Сервис капитальных ремонтов (цех, авто) | C20: тыс/год | E20: =E17*$E$77/1000 -> 0 | F20: =F17*$E$77/1000 -> 2 | G20: =G17*$E$77/1000 -> 19 | H20: =H17*$E$77/1000 -> 4 | I20: =I17*$E$77/1000 -> 19 | J20: =J17*$E$77/1000 -> 2 | K20: =K17*$E$77/1000 -> 17 | L20: =L17*$E$77/1000 -> 6 | ... N20: =N17*$E$77/1000 -> 2
B21: ИТОГО ТОиР (авто) → «Данные по годам» | C21: тыс/год | E21: =E12+E13+E14+E18+E19+E20 -> 167.98372 | F21: =F12+F13+F14+F18+F19+F20 -> 194.91272 | G21: =G12+G13+G14+G18+G19+G20 -> 799.05872 | H21: =H12+H13+H14+H18+H19+H20 -> 260.98372 | I21: =I12+I13+I14+I18+I19+I20 -> 797.36272 | J21: =J12+J13+J14+J18+J19+J20 -> 196.60872 | K21: =K12+K13+K14+K18+K19+K20 -> 770.43372 | L21: =L12+L13+L14+L18+L19+L20 -> 287.91272 | ... N21: =N12+N13+N14+N18+N19+N20 -> 194.91272
B22: Удельный расход ДТ | C22: кг/час | E22: 92.04 | F22: 92.04 | G22: 92.04 | H22: 92.04 | I22: 92.04 | J22: 92.04 | K22: 92.04 | L22: 92.04 | M22: 92.04 | N22: 92.04
B23: Расходники на ковш | C23: руб/м³ | E23: 0.87 | F23: 0.87 | G23: 0.87 | H23: 0.87 | I23: 0.87 | J23: 0.87 | K23: 0.87 | L23: 0.87 | M23: 0.87 | N23: 0.87
B24: РАСЧЁТ ТО (по интервалам обслуживания), ПО ГОДАМ
B25: Наработка по годам | C25: м/час | E25: 7000 | F25: 7000 | G25: 7000 | H25: 7000 | I25: 7000 | J25: 7000 | K25: 7000 | L25: 7000 | M25: 7000 | N25: 7000
B26: Вид ТО | C26: интервал | D26: длит.простоя | E26: персонал
B27: ТО-1 | C27: 500 | D27: 10.2 | E27: 2
B28: ТО-2 | C28: 1000 | D28: 9.4 | E28: 2
B29: ТО-3 | C29: 2000 | D29: 12.4 | E29: 2
B30: ТО-4 | C30: 4000 | D30: 7.8 | E30: 2
B31: ТО-5 | C31: 5000 | D31: 5.4 | E31: 2
B32: ТО-1: простои, ч/год | C32: #,##0 | E32: =(E$25/$C27)*$D27 -> 142.8 | F32: =(F$25/$C27)*$D27 -> 142.8 | G32: =(G$25/$C27)*$D27 -> 142.8 | H32: =(H$25/$C27)*$D27 -> 142.8 | I32: =(I$25/$C27)*$D27 -> 142.8 | J32: =(J$25/$C27)*$D27 -> 142.8 | K32: =(K$25/$C27)*$D27 -> 142.8 | L32: =(L$25/$C27)*$D27 -> 142.8 | ... N32: =(N$25/$C27)*$D27 -> 142.8
B33: ТО-2: простои, ч/год | C33: #,##0 | E33: =(E$25/$C28)*$D28 -> 65.8 | F33: =(F$25/$C28)*$D28 -> 65.8 | G33: =(G$25/$C28)*$D28 -> 65.8 | H33: =(H$25/$C28)*$D28 -> 65.8 | I33: =(I$25/$C28)*$D28 -> 65.8 | J33: =(J$25/$C28)*$D28 -> 65.8 | K33: =(K$25/$C28)*$D28 -> 65.8 | L33: =(L$25/$C28)*$D28 -> 65.8 | ... N33: =(N$25/$C28)*$D28 -> 65.8
B34: ТО-3: простои, ч/год | C34: #,##0 | E34: =(E$25/$C29)*$D29 -> 43.4 | F34: =(F$25/$C29)*$D29 -> 43.4 | G34: =(G$25/$C29)*$D29 -> 43.4 | H34: =(H$25/$C29)*$D29 -> 43.4 | I34: =(I$25/$C29)*$D29 -> 43.4 | J34: =(J$25/$C29)*$D29 -> 43.4 | K34: =(K$25/$C29)*$D29 -> 43.4 | L34: =(L$25/$C29)*$D29 -> 43.4 | ... N34: =(N$25/$C29)*$D29 -> 43.4
B35: ТО-4: простои, ч/год | C35: #,##0 | E35: =(E$25/$C30)*$D30 -> 13.65 | F35: =(F$25/$C30)*$D30 -> 13.65 | G35: =(G$25/$C30)*$D30 -> 13.65 | H35: =(H$25/$C30)*$D30 -> 13.65 | I35: =(I$25/$C30)*$D30 -> 13.65 | J35: =(J$25/$C30)*$D30 -> 13.65 | K35: =(K$25/$C30)*$D30 -> 13.65 | L35: =(L$25/$C30)*$D30 -> 13.65 | ... N35: =(N$25/$C30)*$D30 -> 13.65
B36: ТО-5: простои, ч/год | C36: #,##0 | E36: =(E$25/$C31)*$D31 -> 7.56 | F36: =(F$25/$C31)*$D31 -> 7.56 | G36: =(G$25/$C31)*$D31 -> 7.56 | H36: =(H$25/$C31)*$D31 -> 7.56 | I36: =(I$25/$C31)*$D31 -> 7.56 | J36: =(J$25/$C31)*$D31 -> 7.56 | K36: =(K$25/$C31)*$D31 -> 7.56 | L36: =(L$25/$C31)*$D31 -> 7.56 | ... N36: =(N$25/$C31)*$D31 -> 7.56
B37: Итого простои ТО, ч/год | C37: ч/год | E37: =SUM(E32:E36) -> 273.21 | F37: =SUM(F32:F36) -> 273.21 | G37: =SUM(G32:G36) -> 273.21 | H37: =SUM(H32:H36) -> 273.21 | I37: =SUM(I32:I36) -> 273.21 | J37: =SUM(J32:J36) -> 273.21 | K37: =SUM(K32:K36) -> 273.21 | L37: =SUM(L32:L36) -> 273.21 | ... N37: =SUM(N32:N36) -> 273.21
B38: ТО-1: ч·часы/год | C38: #,##0 | E38: =E32*$E27 -> 285.6 | F38: =F32*$E27 -> 285.6 | G38: =G32*$E27 -> 285.6 | H38: =H32*$E27 -> 285.6 | I38: =I32*$E27 -> 285.6 | J38: =J32*$E27 -> 285.6 | K38: =K32*$E27 -> 285.6 | L38: =L32*$E27 -> 285.6 | ... N38: =N32*$E27 -> 285.6
B39: ТО-2: ч·часы/год | C39: #,##0 | E39: =E33*$E28 -> 131.6 | F39: =F33*$E28 -> 131.6 | G39: =G33*$E28 -> 131.6 | H39: =H33*$E28 -> 131.6 | I39: =I33*$E28 -> 131.6 | J39: =J33*$E28 -> 131.6 | K39: =K33*$E28 -> 131.6 | L39: =L33*$E28 -> 131.6 | ... N39: =N33*$E28 -> 131.6
B40: ТО-3: ч·часы/год | C40: #,##0 | E40: =E34*$E29 -> 86.8 | F40: =F34*$E29 -> 86.8 | G40: =G34*$E29 -> 86.8 | H40: =H34*$E29 -> 86.8 | I40: =I34*$E29 -> 86.8 | J40: =J34*$E29 -> 86.8 | K40: =K34*$E29 -> 86.8 | L40: =L34*$E29 -> 86.8 | ... N40: =N34*$E29 -> 86.8
B41: ТО-4: ч·часы/год | C41: #,##0 | E41: =E35*$E30 -> 27.3 | F41: =F35*$E30 -> 27.3 | G41: =G35*$E30 -> 27.3 | H41: =H35*$E30 -> 27.3 | I41: =I35*$E30 -> 27.3 | J41: =J35*$E30 -> 27.3 | K41: =K35*$E30 -> 27.3 | L41: =L35*$E30 -> 27.3 | ... N41: =N35*$E30 -> 27.3
...

Sheet Поставщик 5
B1: ШАБЛОН ДАННЫХ ПОСТАВЩИКА — ВАРИАНТ 5
B2: Полные модели ТО и Ремонтов ПО ГОДАМ (затраты и трудозатраты — раздельно для ТО / текущих / капитальных ремонтов). Зелёное — авто; сводка тянется в «Данные по годам».
B4: Экскаватор: | E4: ='Ввод данных'!H7 -> Shantui SE2000LCW
B5: Валюта затрат ТОиР: | D5: USD
B6: Показатель | C6: Ед. | E6: год 1 | F6: год 2 | G6: год 3 | H6: год 4 | I6: год 5 | J6: год 6 | K6: год 7 | L6: год 8 | M6: год 9 | N6: год 10
B7: СВОДКА ПО ГОДАМ (зелёное — авто из моделей ниже; тянется в расчёт)
B8: Простои на ТО | C8: ч/год | E8: =E37 -> 273.21 | F8: =F37 -> 273.21 | G8: =G37 -> 273.21 | H8: =H37 -> 273.21 | I8: =I37 -> 273.21 | J8: =J37 -> 273.21 | K8: =K37 -> 273.21 | L8: =L37 -> 273.21 | ... N8: =N37 -> 273.21
B9: Простои в текущих + капитальных ремонтах | C9: ч/год | E9: =E80 -> 786.13 | F9: =F80 -> 1924.36 | G9: =G80 -> 1682.92 | H9: =H80 -> 2228.84 | I9: =I80 -> 2239.02 | J9: =J80 -> 1794.52 | K9: =K80 -> 2025.05 | L9: =L80 -> 1519.78 | ... N9: =N80 -> 1663.35
B10: Ежесменное ТО (20 мин/смену) | C10: ч/год | E10: =('Параметры'!C26-E8-E9)/'Параметры'!C33*20/60 -> 213.90722 | F10: =('Параметры'!C26-F8-F9)/'Параметры'!C33*20/60 -> 182.28972 | G10: =('Параметры'!C26-G8-G9)/'Параметры'!C33*20/60 -> 188.99639 | H10: =('Параметры'!C26-H8-H9)/'Параметры'!C33*20/60 -> 173.83194 | I10: =('Параметры'!C26-I8-I9)/'Параметры'!C33*20/60 -> 173.54917 | J10: =('Параметры'!C26-J8-J9)/'Параметры'!C33*20/60 -> 185.89639 | K10: =('Параметры'!C26-K8-K9)/'Параметры'!C33*20/60 -> 179.49278 | L10: =('Параметры'!C26-L8-L9)/'Параметры'!C33*20/60 -> 193.52806 | M10: =('Параметры'!C26-M8-M9)/'Параметры'!C33*20/60 -> 167.18333 | N10: =('Параметры'!C26-N8-N9)/'Параметры'!C33*20/60 -> 189.54
B11: КТГ (авто) = (8760 − простои)/8760 | C11: коэф. | E11: =('Параметры'!C26-E8-E9-E10)/'Параметры'!C26 -> 0.85465214 | F11: =('Параметры'!C26-F8-F9-F10)/'Параметры'!C26 -> 0.72832652 | G11: =('Параметры'!C26-G8-G9-G10)/'Параметры'!C26 -> 0.75512256 | H11: =('Параметры'!C26-H8-H9-H10)/'Параметры'!C26 -> 0.69453402 | I11: =('Параметры'!C26-I8-I9-I10)/'Параметры'!C26 -> 0.6934042 | J11: =('Параметры'!C26-J8-J9-J10)/'Параметры'!C26 -> 0.74273671 | K11: =('Параметры'!C26-K8-K9-K10)/'Параметры'!C26 -> 0.71715151 | L11: =('Параметры'!C26-L8-L9-L10)/'Параметры'!C26 -> 0.77322853 | M11: =('Параметры'!C26-M8-M9-M10)/'Параметры'!C26 -> 0.66796994 | N11: =('Параметры'!C26-N8-N9-N10)/'Параметры'!C26 -> 0.75729452
B12: Затраты на ТО (ЗЧ, из каталога) | C12: тыс/год | E12: =E75 -> 107.51972 | F12: =F75 -> 107.51972 | G12: =G75 -> 107.51972 | H12: =H75 -> 107.51972 | I12: =I75 -> 107.51972 | J12: =J75 -> 107.51972 | K12: =K75 -> 107.51972 | L12: =L75 -> 107.51972 | ... N12: =N75 -> 107.51972
B13: Затраты на текущие ремонты (ЗЧ) | C13: тыс/год | E13: =E86*$E$81 -> 0 | F13: =F86*$E$81 -> 0 | G13: =G86*$E$81 -> 0 | H13: =H86*$E$81 -> 0 | I13: =I86*$E$81 -> 0 | J13: =J86*$E$81 -> 0 | K13: =K86*$E$81 -> 0 | L13: =L86*$E$81 -> 0 | ... N13: =N86*$E$81 -> 0
B14: Затраты на капитальные ремонты (ЗЧ, цех) | C14: тыс/год | E14: =E126*$E$81 -> 43.4832 | F14: =F126*$E$81 -> 1092.9194 | G14: =G126*$E$81 -> 7491.5263 | H14: =H126*$E$81 -> 3128.3212 | I14: =I126*$E$81 -> 2381.5915 | J14: =J126*$E$81 -> 8584.4457 | K14: =K126*$E$81 -> 3128.3212 | L14: =L126*$E$81 -> 7491.5263 | ... N14: =N126*$E$81 -> 43.4832
B15: Трудозатраты на ТО | C15: ч-час/год | E15: =E43 -> 546.42 | F15: =F43 -> 546.42 | G15: =G43 -> 546.42 | H15: =H43 -> 546.42 | I15: =I43 -> 546.42 | J15: =J43 -> 546.42 | K15: =K43 -> 546.42 | L15: =L43 -> 546.42 | ... N15: =N43 -> 546.42
B16: Трудозатраты на текущие ремонты | C16: ч-час/год | E16: =E91*$E$81 -> 0 | F16: =F91*$E$81 -> 0 | G16: =G91*$E$81 -> 0 | H16: =H91*$E$81 -> 0 | I16: =I91*$E$81 -> 0 | J16: =J91*$E$81 -> 0 | K16: =K91*$E$81 -> 0 | L16: =L91*$E$81 -> 0 | ... N16: =N91*$E$81 -> 0
B17: Трудозатраты на капитальные ремонты (цех) | C17: чел-час/год | E17: =E136*$E$81 -> 0 | F17: =F136*$E$81 -> 12 | G17: =G136*$E$81 -> 148 | H17: =H136*$E$81 -> 12 | I17: =I136*$E$81 -> 14 | J17: =J136*$E$81 -> 160 | K17: =K136*$E$81 -> 12 | L17: =L136*$E$81 -> 148 | ... N17: =N136*$E$81 -> 0
B18: Сервис ТО (авто) = трудозатраты ТО × ставка | C18: тыс/год | E18: =E15*$E$77/1000 -> 27.321 | F18: =F15*$E$77/1000 -> 27.321 | G18: =G15*$E$77/1000 -> 27.321 | H18: =H15*$E$77/1000 -> 27.321 | I18: =I15*$E$77/1000 -> 27.321 | J18: =J15*$E$77/1000 -> 27.321 | K18: =K15*$E$77/1000 -> 27.321 | L18: =L15*$E$77/1000 -> 27.321 | ... N18: =N15*$E$77/1000 -> 27.321
B19: Сервис текущих ремонтов (авто) | C19: тыс/год | E19: =E16*$E$77/1000 -> 0 | F19: =F16*$E$77/1000 -> 0 | G19: =G16*$E$77/1000 -> 0 | H19: =H16*$E$77/1000 -> 0 | I19: =I16*$E$77/1000 -> 0 | J19: =J16*$E$77/1000 -> 0 | K19: =K16*$E$77/1000 -> 0 | L19: =L16*$E$77/1000 -> 0 | ... N19: =N16*$E$77/1000 -> 0
B20: Сервис капитальных ремонтов (цех, авто) | C20: тыс/год | E20: =E17*$E$77/1000 -> 0 | F20: =F17*$E$77/1000 -> 0.6 | G20: =G17*$E$77/1000 -> 7.4 | H20: =H17*$E$77/1000 -> 0.6 | I20: =I17*$E$77/1000 -> 0.7 | J20: =J17*$E$77/1000 -> 8 | K20: =K17*$E$77/1000 -> 0.6 | L20: =L17*$E$77/1000 -> 7.4 | ... N20: =N17*$E$77/1000 -> 0
B21: ИТОГО ТОиР (авто) → «Данные по годам» | C21: тыс/год | E21: =E12+E13+E14+E18+E19+E20 -> 178.32392 | F21: =F12+F13+F14+F18+F19+F20 -> 1228.3601 | G21: =G12+G13+G14+G18+G19+G20 -> 7633.767 | H21: =H12+H13+H14+H18+H19+H20 -> 3263.7619 | I21: =I12+I13+I14+I18+I19+I20 -> 2517.1322 | J21: =J12+J13+J14+J18+J19+J20 -> 8727.2864 | K21: =K12+K13+K14+K18+K19+K20 -> 3263.7619 | L21: =L12+L13+L14+L18+L19+L20 -> 7633.767 | ... N21: =N12+N13+N14+N18+N19+N20 -> 178.32392
B22: Удельный расход ДТ | C22: кг/час | E22: 102 | F22: 102 | G22: 102 | H22: 102 | I22: 102 | J22: 102 | K22: 102 | L22: 102 | M22: 102 | N22: 102
B23: Расходники на ковш | C23: руб/м³ | E23: 0.87 | F23: 0.87 | G23: 0.87 | H23: 0.87 | I23: 0.87 | J23: 0.87 | K23: 0.87 | L23: 0.87 | M23: 0.87 | N23: 0.87
B24: РАСЧЁТ ТО (по интервалам обслуживания), ПО ГОДАМ
B25: Наработка по годам | C25: м/час | E25: 7000 | F25: 7000 | G25: 7000 | H25: 7000 | I25: 7000 | J25: 7000 | K25: 7000 | L25: 7000 | M25: 7000 | N25: 7000
B26: Вид ТО | C26: интервал | D26: длит.простоя | E26: персонал
B27: ТО-1 | C27: 500 | D27: 10.2 | E27: 2
B28: ТО-2 | C28: 1000 | D28: 9.4 | E28: 2
B29: ТО-3 | C29: 2000 | D29: 12.4 | E29: 2
B30: ТО-4 | C30: 4000 | D30: 7.8 | E30: 2
B31: ТО-5 | C31: 5000 | D31: 5.4 | E31: 2
B32: ТО-1: простои, ч/год | C32: #,##0 | E32: =(E$25/$C27)*$D27 -> 142.8 | F32: =(F$25/$C27)*$D27 -> 142.8 | G32: =(G$25/$C27)*$D27 -> 142.8 | H32: =(H$25/$C27)*$D27 -> 142.8 | I32: =(I$25/$C27)*$D27 -> 142.8 | J32: =(J$25/$C27)*$D27 -> 142.8 | K32: =(K$25/$C27)*$D27 -> 142.8 | L32: =(L$25/$C27)*$D27 -> 142.8 | ... N32: =(N$25/$C27)*$D27 -> 142.8
B33: ТО-2: простои, ч/год | C33: #,##0 | E33: =(E$25/$C28)*$D28 -> 65.8 | F33: =(F$25/$C28)*$D28 -> 65.8 | G33: =(G$25/$C28)*$D28 -> 65.8 | H33: =(H$25/$C28)*$D28 -> 65.8 | I33: =(I$25/$C28)*$D28 -> 65.8 | J33: =(J$25/$C28)*$D28 -> 65.8 | K33: =(K$25/$C28)*$D28 -> 65.8 | L33: =(L$25/$C28)*$D28 -> 65.8 | ... N33: =(N$25/$C28)*$D28 -> 65.8
B34: ТО-3: простои, ч/год | C34: #,##0 | E34: =(E$25/$C29)*$D29 -> 43.4 | F34: =(F$25/$C29)*$D29 -> 43.4 | G34: =(G$25/$C29)*$D29 -> 43.4 | H34: =(H$25/$C29)*$D29 -> 43.4 | I34: =(I$25/$C29)*$D29 -> 43.4 | J34: =(J$25/$C29)*$D29 -> 43.4 | K34: =(K$25/$C29)*$D29 -> 43.4 | L34: =(L$25/$C29)*$D29 -> 43.4 | ... N34: =(N$25/$C29)*$D29 -> 43.4
B35: ТО-4: простои, ч/год | C35: #,##0 | E35: =(E$25/$C30)*$D30 -> 13.65 | F35: =(F$25/$C30)*$D30 -> 13.65 | G35: =(G$25/$C30)*$D30 -> 13.65 | H35: =(H$25/$C30)*$D30 -> 13.65 | I35: =(I$25/$C30)*$D30 -> 13.65 | J35: =(J$25/$C30)*$D30 -> 13.65 | K35: =(K$25/$C30)*$D30 -> 13.65 | L35: =(L$25/$C30)*$D30 -> 13.65 | ... N35: =(N$25/$C30)*$D30 -> 13.65
B36: ТО-5: простои, ч/год | C36: #,##0 | E36: =(E$25/$C31)*$D31 -> 7.56 | F36: =(F$25/$C31)*$D31 -> 7.56 | G36: =(G$25/$C31)*$D31 -> 7.56 | H36: =(H$25/$C31)*$D31 -> 7.56 | I36: =(I$25/$C31)*$D31 -> 7.56 | J36: =(J$25/$C31)*$D31 -> 7.56 | K36: =(K$25/$C31)*$D31 -> 7.56 | L36: =(L$25/$C31)*$D31 -> 7.56 | ... N36: =(N$25/$C31)*$D31 -> 7.56
B37: Итого простои ТО, ч/год | C37: ч/год | E37: =SUM(E32:E36) -> 273.21 | F37: =SUM(F32:F36) -> 273.21 | G37: =SUM(G32:G36) -> 273.21 | H37: =SUM(H32:H36) -> 273.21 | I37: =SUM(I32:I36) -> 273.21 | J37: =SUM(J32:J36) -> 273.21 | K37: =SUM(K32:K36) -> 273.21 | L37: =SUM(L32:L36) -> 273.21 | ... N37: =SUM(N32:N36) -> 273.21
B38: ТО-1: ч·часы/год | C38: #,##0 | E38: =E32*$E27 -> 285.6 | F38: =F32*$E27 -> 285.6 | G38: =G32*$E27 -> 285.6 | H38: =H32*$E27 -> 285.6 | I38: =I32*$E27 -> 285.6 | J38: =J32*$E27 -> 285.6 | K38: =K32*$E27 -> 285.6 | L38: =L32*$E27 -> 285.6 | ... N38: =N32*$E27 -> 285.6
B39: ТО-2: ч·часы/год | C39: #,##0 | E39: =E33*$E28 -> 131.6 | F39: =F33*$E28 -> 131.6 | G39: =G33*$E28 -> 131.6 | H39: =H33*$E28 -> 131.6 | I39: =I33*$E28 -> 131.6 | J39: =J33*$E28 -> 131.6 | K39: =K33*$E28 -> 131.6 | L39: =L33*$E28 -> 131.6 | ... N39: =N33*$E28 -> 131.6
B40: ТО-3: ч·часы/год | C40: #,##0 | E40: =E34*$E29 -> 86.8 | F40: =F34*$E29 -> 86.8 | G40: =G34*$E29 -> 86.8 | H40: =H34*$E29 -> 86.8 | I40: =I34*$E29 -> 86.8 | J40: =J34*$E29 -> 86.8 | K40: =K34*$E29 -> 86.8 | L40: =L34*$E29 -> 86.8 | ... N40: =N34*$E29 -> 86.8
B41: ТО-4: ч·часы/год | C41: #,##0 | E41: =E35*$E30 -> 27.3 | F41: =F35*$E30 -> 27.3 | G41: =G35*$E30 -> 27.3 | H41: =H35*$E30 -> 27.3 | I41: =I35*$E30 -> 27.3 | J41: =J35*$E30 -> 27.3 | K41: =K35*$E30 -> 27.3 | L41: =L35*$E30 -> 27.3 | ... N41: =N35*$E30 -> 27.3
...

Sheet Поставщик 6
B1: ШАБЛОН ДАННЫХ ПОСТАВЩИКА — ВАРИАНТ 6
B2: Полные модели ТО и Ремонтов ПО ГОДАМ (затраты и трудозатраты — раздельно для ТО / текущих / капитальных ремонтов). Зелёное — авто; сводка тянется в «Данные по годам».
B4: Экскаватор: | E4: ='Ввод данных'!I7 -> TZCO TZ2000 Дзикай
B5: Валюта затрат ТОиР: | D5: USD
B6: Показатель | C6: Ед. | E6: год 1 | F6: год 2 | G6: год 3 | H6: год 4 | I6: год 5 | J6: год 6 | K6: год 7 | L6: год 8 | M6: год 9 | N6: год 10
B7: СВОДКА ПО ГОДАМ (зелёное — авто из моделей ниже; тянется в расчёт)
B8: Простои на ТО | C8: ч/год | E8: =E37 -> 273.21 | F8: =F37 -> 273.21 | G8: =G37 -> 273.21 | H8: =H37 -> 273.21 | I8: =I37 -> 273.21 | J8: =J37 -> 273.21 | K8: =K37 -> 273.21 | L8: =L37 -> 273.21 | ... N8: =N37 -> 273.21
B9: Простои в текущих + капитальных ремонтах | C9: ч/год | E9: =E80 -> 786.13 | F9: =F80 -> 1924.36 | G9: =G80 -> 1682.92 | H9: =H80 -> 2228.84 | I9: =I80 -> 2239.02 | J9: =J80 -> 1794.52 | K9: =K80 -> 2025.05 | L9: =L80 -> 1519.78 | ... N9: =N80 -> 1663.35
