Workbook

Sheet Данные_Буровой станок
B2: ячейки к заполнению поставщиком
B3: Буровой станок | C3: SWDRT270Е | Q3: Примечания
A4: 1 | B4: Период | C4: Ед. изм. | D4: 0 | E4: =D4+1 -> 1 | F4: =E4+1 -> 2 | G4: =F4+1 -> 3 | H4: =G4+1 -> 4 | I4: =H4+1 -> 5 | J4: =I4+1 -> 6 | K4: =J4+1 -> 7 | L4: =K4+1 -> 8 | ... P4: =O4+1 -> 12 | Q4: Учесть срок эксплуатации (в данном примере это 12 лет)
A5: =A4+1 -> 2 | B5: Диаметр долота | C5: мм | D5: 270
A6: =A5+1 -> 3 | B6: КТГ при нормативной эксплуатации | C6: коэф. | E6: 0.93 | F6: 0.93 | G6: 0.92 | H6: 0.92 | I6: 0.87 | J6: 0.9 | K6: 0.85 | L6: 0.9 | M6: 0.9 | N6: 0.85 | O6: 0.89 | P6: 0.89 | Q6: расчетный
A7: =A6+1 -> 4 | B7: простои на ТО | C7: часов | E7: =ТО!G7 -> 206 | F7: =ТО!H7 -> 238 | G7: =ТО!I7 -> 214 | H7: =ТО!J7 -> 238 | I7: =ТО!K7 -> 206 | J7: =ТО!L7 -> 258 | K7: =ТО!M7 -> 230 | L7: =ТО!N7 -> 214 | ... P7: =ТО!R7 -> 258
A8: =A7+1 -> 5 | B8: простои в ремонтах | C8: часов | E8: =Ремонты!F8 -> 102.66667 | F8: =Ремонты!G8 -> 102.66667 | G8: =Ремонты!H8 -> 102.66667 | H8: =Ремонты!I8 -> 102.66667 | I8: =Ремонты!J8 -> 102.66667 | J8: =Ремонты!K8 -> 102.66667 | K8: =Ремонты!L8 -> 102.66667 | L8: =Ремонты!M8 -> 102.66667 | ... P8: =Ремонты!Q8 -> 102.66667
B9: ежесменный осмотр (20 мин/смену) | C9: часов | E9: =(8760-E7-E8)/12*20/60 -> 234.75926 | F9: =(8760-F7-F8)/12*20/60 -> 233.87037 | G9: =(8760-G7-G8)/12*20/60 -> 234.53704 | H9: =(8760-H7-H8)/12*20/60 -> 233.87037 | I9: =(8760-I7-I8)/12*20/60 -> 234.75926 | J9: =(8760-J7-J8)/12*20/60 -> 233.31481 | K9: =(8760-K7-K8)/12*20/60 -> 234.09259 | L9: =(8760-L7-L8)/12*20/60 -> 234.53704 | ... P9: =(8760-P7-P8)/12*20/60 -> 233.31481
A10: =A8+1 -> 6 | B10: Модель ДВС | D10: Электродвигатель
A11: =A10+1 -> 7 | B11: Мощность двигателя | C11: кВт | D11: 630
A12: =A11+1 -> 8 | B12: Длина штанги | C12: м | D12: 10
A13: =A12+1 -> 9 | B13: Глубина бурения в первый заход | C13: м | D13: 10
A14: =A13+1 -> 10 | B14: Скорость подъема бур.снаряда, м/мин | C14: м/мин | D14: 30
B15: Скорость спуска бур.снаряда, м/мин | C15: м/мин | D15: 45
B16: Для вращательного бурения
A17: =A14+1 -> 11 | B17: Мощность привода вращателя, кВт | C17: кВт / л.с. | D17: 120
A18: =A17+1 -> 12 | B18: Крутящий момент вращателя | C18: Нм | D18: 13800
A19: =A18+1 -> 13 | B19: Частота вращения | C19: об/мин | D19: 0-150
B20: Для пневмоударного бурения
A21: =A19+1 -> 14 | B21: Производительность компрессора | C21: м3/мин | D21: 51
A22: =A21+1 -> 15 | B22: Давление компрессора | C22: бар | D22: 8
A23: =A22+1 -> 16 | B23: Рекомендуемый буровой инструмент
A24: =A23+1 -> 17 | B24: Паспортное потребление воздуха / давление | C24: м3/мин | D24: /
A25: =A24+1 -> 18 | B25: Число ударов пневмоударника | C25: уд/мин | D25: Режим шарошечного долота, без удара
A26: =A25+1 -> 19 | B26: Энергия единичного удара | C26: Дж | D26: /
A28: =A26+1 -> 20 | B28: Затраты на ТО и ремонты | C28: тыс./год | E28: =SUM(E29:E33) -> 248.86817 | F28: =SUM(F29:F33) -> 888.31767 | G28: =SUM(G29:G33) -> 785.48442 | H28: =SUM(H29:H33) -> 703.84767 | I28: =SUM(I29:I33) -> 690.00817 | J28: =SUM(J29:J33) -> 985.19492 | K28: =SUM(K29:K33) -> 698.61817 | L28: =SUM(L29:L33) -> 701.83767 | ... P28: =SUM(P29:P33) -> 981.06992
A29: =A28+1 -> 21 | B29: ТО | E29: =ТО!G9/1000 -> 34.3365 | F29: =ТО!H9/1000 -> 39.006 | G29: =ТО!I9/1000 -> 34.37775 | H29: =ТО!J9/1000 -> 39.006 | I29: =ТО!K9/1000 -> 34.3365 | J29: =ТО!L9/1000 -> 42.08325 | K29: =ТО!M9/1000 -> 34.3365 | L29: =ТО!N9/1000 -> 39.006 | ... P29: =ТО!R9/1000 -> 42.08325
A30: =A29+1 -> 22 | B30: текущие ремонты | E30: =Ремонты!F33/1000 -> 2.5 | F30: =Ремонты!G33/1000 -> 2.5 | G30: =Ремонты!H33/1000 -> 2.5 | H30: =Ремонты!I33/1000 -> 2.5 | I30: =Ремонты!J33/1000 -> 2.5 | J30: =Ремонты!K33/1000 -> 2.5 | K30: =Ремонты!L33/1000 -> 2.5 | L30: =Ремонты!M33/1000 -> 2.5 | ... P30: =Ремонты!Q33/1000 -> 2.5
A31: =A30+1 -> 23 | B31: планово-предупредительные (капитальные) ремонты | E31: =Ремонты!F39/1000 -> 71.845 | F31: =Ремонты!G39/1000 -> 704.385 | G31: =Ремонты!H39/1000 -> 607.86 | H31: =Ремонты!I39/1000 -> 519.915 | I31: =Ремонты!J39/1000 -> 512.985 | J31: =Ремонты!K39/1000 -> 796.785 | K31: =Ремонты!L39/1000 -> 519.915 | L31: =Ремонты!M39/1000 -> 519.585 | ... P31: =Ремонты!Q39/1000 -> 792.66
A32: =A31+1 -> 24 | B32: сервис (трудозатраты) - ТО | E32: =ТО!G10/1000 -> 14.42 | F32: =ТО!H10/1000 -> 16.66 | G32: =ТО!I10/1000 -> 14.98 | H32: =ТО!J10/1000 -> 16.66 | I32: =ТО!K10/1000 -> 14.42 | J32: =ТО!L10/1000 -> 18.06 | K32: =ТО!M10/1000 -> 16.1 | L32: =ТО!N10/1000 -> 14.98 | ... P32: =ТО!R10/1000 -> 18.06
A33: =A32+1 -> 25 | B33: сервис (трудозатраты) - ремонты | E33: =Ремонты!F12/1000 -> 125.76667 | F33: =Ремонты!G12/1000 -> 125.76667 | G33: =Ремонты!H12/1000 -> 125.76667 | H33: =Ремонты!I12/1000 -> 125.76667 | I33: =Ремонты!J12/1000 -> 125.76667 | J33: =Ремонты!K12/1000 -> 125.76667 | K33: =Ремонты!L12/1000 -> 125.76667 | L33: =Ремонты!M12/1000 -> 125.76667 | ... P33: =Ремонты!Q12/1000 -> 125.76667
A35: =A33+1 -> 26 | B35: Рекомендуемый буровой инструмент | Q35: Здесь перечень приведен в качестве примера
A36: =A35+1 -> 27 | B36: Для вращательного бурения
A37: =A36+1 -> 28 | B37: долота
A38: =A37+1 -> 29 | B38: удельный расход | C38: 3000 | E38: =200000/$C$38*$C$39 -> 388740 | F38: =200000/$C$38*$C$39 -> 388740 | G38: =200000/$C$38*$C$39 -> 388740 | H38: =200000/$C$38*$C$39 -> 388740 | I38: =200000/$C$38*$C$39 -> 388740 | J38: =200000/$C$38*$C$39 -> 388740 | K38: =200000/$C$38*$C$39 -> 388740 | L38: =200000/$C$38*$C$39 -> 388740 | ... P38: =200000/$C$38*$C$39 -> 388740
A39: =A38+1 -> 30 | B39: цена за ед. | C39: 5831.1
A40: =A39+1 -> 31 | B40: Штанги буровые
A41: =A40+1 -> 32 | B41: удельный расход | C41: 50000 | E41: =200000/$C$41*$C$42 -> 18361.2 | F41: =200000/$C$41*$C$42 -> 18361.2 | G41: =200000/$C$41*$C$42 -> 18361.2 | H41: =200000/$C$41*$C$42 -> 18361.2 | I41: =200000/$C$41*$C$42 -> 18361.2 | J41: =200000/$C$41*$C$42 -> 18361.2 | K41: =200000/$C$41*$C$42 -> 18361.2 | L41: =200000/$C$41*$C$42 -> 18361.2 | ... P41: =200000/$C$41*$C$42 -> 18361.2
A42: =A41+1 -> 33 | B42: цена за ед. | C42: 4590.3
A43: =A42+1 -> 34 | B43: Cтабилизатор штанги
...

Sheet ТО
B2: ячейки к заполнению поставщиком
B4: Год службы (год) | C4: Ед. изм. | G4: =E4+1 -> 1 | H4: =G4+1 -> 2 | I4: =H4+1 -> 3 | J4: =I4+1 -> 4 | K4: =J4+1 -> 5 | L4: =K4+1 -> 6 | M4: =L4+1 -> 7 | N4: =M4+1 -> 8 | O4: =N4+1 -> 9 | ... R4: =Q4+1 -> 12
B5: Наработка на начало года | C5: м/час | G5: 0 | H5: =G6+1 -> 7001 | I5: =H6+1 -> 14001 | J5: =I6+1 -> 21001 | K5: =J6+1 -> 28001 | L5: =K6+1 -> 35001 | M5: =L6+1 -> 42001 | N5: =M6+1 -> 49001 | O5: =N6+1 -> 56001 | ... R5: =Q6+1 -> 77001
B6: Наработка на конец года | C6: м/час | F6: 7000 | G6: =F6 -> 7000 | H6: =G6+$F6 -> 14000 | I6: =H6+$F6 -> 21000 | J6: =I6+$F6 -> 28000 | K6: =J6+$F6 -> 35000 | L6: =K6+$F6 -> 42000 | M6: =L6+$F6 -> 49000 | N6: =M6+$F6 -> 56000 | O6: =N6+$F6 -> 63000 | ... R6: =Q6+$F6 -> 84000
B7: длительность простоев на ТО | C7: часов | G7: =G13 -> 206 | H7: =H13 -> 238 | I7: =I13 -> 214 | J7: =J13 -> 238 | K7: =K13 -> 206 | L7: =L13 -> 258 | M7: =M13 -> 230 | N7: =N13 -> 214 | ... R7: =R13 -> 258
B8: Затраты на ТО | C8: долларов/год | G8: =SUM(G9:G10) -> 48756.5 | H8: =SUM(H9:H10) -> 55666 | I8: =SUM(I9:I10) -> 49357.75 | J8: =SUM(J9:J10) -> 55666 | K8: =SUM(K9:K10) -> 48756.5 | L8: =SUM(L9:L10) -> 60143.25 | M8: =SUM(M9:M10) -> 50436.5 | N8: =SUM(N9:N10) -> 53986 | ... R8: =SUM(R9:R10) -> 60143.25
B9: ТО, включая масла и смазки | C9: долларов/год | G9: =G22 -> 34336.5 | H9: =H22 -> 39006 | I9: =I22 -> 34377.75 | J9: =J22 -> 39006 | K9: =K22 -> 34336.5 | L9: =L22 -> 42083.25 | M9: =M22 -> 34336.5 | N9: =N22 -> 39006 | ... R9: =R22 -> 42083.25
B10: сервис (трудозатраты) на ТО | C10: долларов/год | F10: 35 | G10: =SUMPRODUCT(G14:G19,$F$14:$F$19)*$F10 -> 14420 | H10: =SUMPRODUCT(H14:H19,$F$14:$F$19)*$F10 -> 16660 | I10: =SUMPRODUCT(I14:I19,$F$14:$F$19)*$F10 -> 14980 | J10: =SUMPRODUCT(J14:J19,$F$14:$F$19)*$F10 -> 16660 | K10: =SUMPRODUCT(K14:K19,$F$14:$F$19)*$F10 -> 14420 | L10: =SUMPRODUCT(L14:L19,$F$14:$F$19)*$F10 -> 18060 | M10: =SUMPRODUCT(M14:M19,$F$14:$F$19)*$F10 -> 16100 | N10: =SUMPRODUCT(N14:N19,$F$14:$F$19)*$F10 -> 14980 | ... R10: =SUMPRODUCT(R14:R19,$F$14:$F$19)*$F10 -> 18060
B12: Простои оборудования на ТО | C12: Интервал ТО | D12: Длительность простоя на одном ТО, час | E12: Кол-во ТО в год | F12: Занято человек | G12: Простоев в год, час | H12: Простоев в год, час | I12: Простоев в год, час | J12: Простоев в год, час | K12: Простоев в год, час | L12: Простоев в год, час | M12: Простоев в год, час | N12: Простоев в год, час | O12: Простоев в год, час | P12: Простоев в год, час | Q12: Простоев в год, час | R12: Простоев в год, час
B13: всего простоев на ТО, часов | G13: =SUM(G14:G19) -> 206 | H13: =SUM(H14:H19) -> 238 | I13: =SUM(I14:I19) -> 214 | J13: =SUM(J14:J19) -> 238 | K13: =SUM(K14:K19) -> 206 | L13: =SUM(L14:L19) -> 258 | M13: =SUM(M14:M19) -> 230 | N13: =SUM(N14:N19) -> 214 | ... R13: =SUM(R14:R19) -> 258
B14: ТО-1 | C14: 250 | D14: 4 | E14: =$F$6/C14 -> 28 | F14: 2 | G14: =$E14*$D14 -> 112 | H14: =$E14*$D14 -> 112 | I14: =$E14*$D14 -> 112 | J14: =$E14*$D14 -> 112 | K14: =$E14*$D14 -> 112 | L14: =$E14*$D14 -> 112 | M14: =$E14*$D14 -> 112 | N14: =$E14*$D14 -> 112 | ... R14: =$E14*$D14 -> 112 | T14: формулы для примера, можно менять под необходимые параметры
B15: ТО-2 | C15: 1000 | D15: 6 | E15: =$F$6/C15 -> 7 | F15: 2 | G15: =$E15*$D15 -> 42 | H15: =$E15*$D15 -> 42 | I15: =$E15*$D15 -> 42 | J15: =$E15*$D15 -> 42 | K15: =$E15*$D15 -> 42 | L15: =$E15*$D15 -> 42 | M15: =$E15*$D15 -> 42 | N15: =$E15*$D15 -> 42 | ... R15: =$E15*$D15 -> 42 | T15: формулы для примера, можно менять под необходимые параметры
B16: ТО-3 | C16: 2000 | D16: 8 | E16: =ROUNDDOWN($F$6/C16,0) -> 3 | F16: 2 | G16: =$E16*$D16 -> 24 | H16: =$E16*$D16+D16 -> 32 | I16: =$E16*$D16 -> 24 | J16: =$E16*$D16+D16 -> 32 | K16: =$E16*$D16 -> 24 | L16: =$E16*$D16+D16 -> 32 | M16: =$E16*$D16 -> 24 | N16: =$E16*$D16+D16 -> 32 | O16: =$E16*$D16 -> 24 | P16: =$E16*$D16+D16 -> 32 | Q16: =$E16*$D16 -> 24 | R16: =$E16*$D16+D16 -> 32 | T16: формулы для примера, можно менять под необходимые параметры
B17: ТО-4 | C17: 3000 | D17: 8 | E17: =ROUNDDOWN($F$6/C17,0) -> 2 | F17: 2 | G17: =$E17*$D17 -> 16 | H17: =$E17*$D17 -> 16 | I17: =$E17*$D17+D17 -> 24 | J17: =$E17*$D17 -> 16 | K17: =$E17*$D17 -> 16 | L17: =$E17*$D17+D17 -> 24 | M17: =$E17*$D17 -> 16 | N17: =$E17*$D17 -> 16 | O17: =$E17*$D17+D17 -> 24 | P17: =$E17*$D17 -> 16 | Q17: =$E17*$D17 -> 16 | R17: =$E17*$D17+D17 -> 24 | T17: формулы для примера, можно менять под необходимые параметры
B18: ТО-5 | C18: 6000 | D18: 12 | E18: =ROUNDDOWN($F$6/C18,0) -> 1 | F18: 2 | G18: =$E18*$D18 -> 12 | H18: =$E18*$D18 -> 12 | I18: =$E18*$D18 -> 12 | J18: =$E18*$D18 -> 12 | K18: =$E18*$D18 -> 12 | L18: =$E18*$D18+D18 -> 24 | M18: =$E18*$D18 -> 12 | N18: =$E18*$D18 -> 12 | O18: =$E18*$D18 -> 12 | P18: =$E18*$D18 -> 12 | Q18: =$E18*$D18 -> 12 | R18: =$E18*$D18+D18 -> 24 | T18: формулы для примера, можно менять под необходимые параметры
B19: ТО-6 | C19: 12000 | D19: 24 | F19: 2 | G19: 0 | H19: =$D19 -> 24 | I19: 0 | J19: =D19 -> 24 | K19: 0 | L19: =$D19 -> 24 | M19: =D19 -> 24 | N19: 0 | O19: =$D19 -> 24 | P19: 0 | Q19: =D19 -> 24 | R19: =$D19 -> 24 | T19: формулы для примера, можно менять под необходимые параметры
B21: Затраты на ТО | C21: Каталожный номер | D21: стоимость за ед., $ | E21: Кол-во | F21: Кол-во ТО в год | G21: $ | H21: $ | I21: $ | J21: $ | K21: $ | L21: $ | M21: $ | N21: $ | O21: $ | P21: $ | Q21: $ | R21: $
B22: ТО | G22: =SUM(G23:G58) -> 34336.5 | H22: =SUM(H23:H58) -> 39006 | I22: =SUM(I23:I58) -> 34377.75 | J22: =SUM(J23:J58) -> 39006 | K22: =SUM(K23:K58) -> 34336.5 | L22: =SUM(L23:L58) -> 42083.25 | M22: =SUM(M23:M58) -> 34336.5 | N22: =SUM(N23:N58) -> 39006 | ... R22: =SUM(R23:R58) -> 42083.25
B23: ТО-1 | E23: =VLOOKUP($B23,$B$14:$C$19,2,FALSE) -> 250 | F23: =VLOOKUP($B23,$B$14:$E$19,4,FALSE) -> 28
B24: фильтр | D24: 0 | E24: 0 | G24: =IF(G$14=0,0,G$14/$D$14*$E24*$D24) -> 0 | H24: =IF(H$14=0,0,H$14/$D$14*$E24*$D24) -> 0 | I24: =IF(I$14=0,0,I$14/$D$14*$E24*$D24) -> 0 | J24: =IF(J$14=0,0,J$14/$D$14*$E24*$D24) -> 0 | K24: =IF(K$14=0,0,K$14/$D$14*$E24*$D24) -> 0 | L24: =IF(L$14=0,0,L$14/$D$14*$E24*$D24) -> 0 | M24: =IF(M$14=0,0,M$14/$D$14*$E24*$D24) -> 0 | N24: =IF(N$14=0,0,N$14/$D$14*$E24*$D24) -> 0 | ... R24: =IF(R$14=0,0,R$14/$D$14*$E24*$D24) -> 0
B25: фильтр | D25: 0 | E25: 0 | G25: =IF(G$14=0,0,G$14/$D$14*$E25*$D25) -> 0 | H25: =IF(H$14=0,0,H$14/$D$14*$E25*$D25) -> 0 | I25: =IF(I$14=0,0,I$14/$D$14*$E25*$D25) -> 0 | J25: =IF(J$14=0,0,J$14/$D$14*$E25*$D25) -> 0 | K25: =IF(K$14=0,0,K$14/$D$14*$E25*$D25) -> 0 | L25: =IF(L$14=0,0,L$14/$D$14*$E25*$D25) -> 0 | M25: =IF(M$14=0,0,M$14/$D$14*$E25*$D25) -> 0 | N25: =IF(N$14=0,0,N$14/$D$14*$E25*$D25) -> 0 | ... R25: =IF(R$14=0,0,R$14/$D$14*$E25*$D25) -> 0
B26: масло | D26: 0 | E26: 0 | G26: =IF(G$14=0,0,G$14/$D$14*$E26*$D26) -> 0 | H26: =IF(H$14=0,0,H$14/$D$14*$E26*$D26) -> 0 | I26: =IF(I$14=0,0,I$14/$D$14*$E26*$D26) -> 0 | J26: =IF(J$14=0,0,J$14/$D$14*$E26*$D26) -> 0 | K26: =IF(K$14=0,0,K$14/$D$14*$E26*$D26) -> 0 | L26: =IF(L$14=0,0,L$14/$D$14*$E26*$D26) -> 0 | M26: =IF(M$14=0,0,M$14/$D$14*$E26*$D26) -> 0 | N26: =IF(N$14=0,0,N$14/$D$14*$E26*$D26) -> 0 | ... R26: =IF(R$14=0,0,R$14/$D$14*$E26*$D26) -> 0
B27: масло | D27: 0 | E27: 0 | G27: =IF(G$14=0,0,G$14/$D$14*$E27*$D27) -> 0 | H27: =IF(H$14=0,0,H$14/$D$14*$E27*$D27) -> 0 | I27: =IF(I$14=0,0,I$14/$D$14*$E27*$D27) -> 0 | J27: =IF(J$14=0,0,J$14/$D$14*$E27*$D27) -> 0 | K27: =IF(K$14=0,0,K$14/$D$14*$E27*$D27) -> 0 | L27: =IF(L$14=0,0,L$14/$D$14*$E27*$D27) -> 0 | M27: =IF(M$14=0,0,M$14/$D$14*$E27*$D27) -> 0 | N27: =IF(N$14=0,0,N$14/$D$14*$E27*$D27) -> 0 | ... R27: =IF(R$14=0,0,R$14/$D$14*$E27*$D27) -> 0
B28: смазка | D28: 82.5 | E28: 2 | G28: =IF(G$14=0,0,G$14/$D$14*$E28*$D28) -> 4620 | H28: =IF(H$14=0,0,H$14/$D$14*$E28*$D28) -> 4620 | I28: =IF(I$14=0,0,I$14/$D$14*$E28*$D28) -> 4620 | J28: =IF(J$14=0,0,J$14/$D$14*$E28*$D28) -> 4620 | K28: =IF(K$14=0,0,K$14/$D$14*$E28*$D28) -> 4620 | L28: =IF(L$14=0,0,L$14/$D$14*$E28*$D28) -> 4620 | M28: =IF(M$14=0,0,M$14/$D$14*$E28*$D28) -> 4620 | N28: =IF(N$14=0,0,N$14/$D$14*$E28*$D28) -> 4620 | ... R28: =IF(R$14=0,0,R$14/$D$14*$E28*$D28) -> 4620
B29: смазка | D29: 0 | E29: 0 | G29: =IF(G$14=0,0,G$14/$D$14*$E29*$D29) -> 0 | H29: =IF(H$14=0,0,H$14/$D$14*$E29*$D29) -> 0 | I29: =IF(I$14=0,0,I$14/$D$14*$E29*$D29) -> 0 | J29: =IF(J$14=0,0,J$14/$D$14*$E29*$D29) -> 0 | K29: =IF(K$14=0,0,K$14/$D$14*$E29*$D29) -> 0 | L29: =IF(L$14=0,0,L$14/$D$14*$E29*$D29) -> 0 | M29: =IF(M$14=0,0,M$14/$D$14*$E29*$D29) -> 0 | N29: =IF(N$14=0,0,N$14/$D$14*$E29*$D29) -> 0 | ... R29: =IF(R$14=0,0,R$14/$D$14*$E29*$D29) -> 0
B30: ТО-2 | E30: =VLOOKUP($B30,$B$14:$C$19,2,FALSE) -> 1000 | F30: =VLOOKUP($B30,$B$14:$E$19,4,FALSE) -> 7
B31: фильтр | D31: 0 | E31: 0 | G31: =IF(G$15=0,0,G$15/$D$15*$E31*$D31) -> 0 | H31: =IF(H$15=0,0,H$15/$D$15*$E31*$D31) -> 0 | I31: =IF(I$15=0,0,I$15/$D$15*$E31*$D31) -> 0 | J31: =IF(J$15=0,0,J$15/$D$15*$E31*$D31) -> 0 | K31: =IF(K$15=0,0,K$15/$D$15*$E31*$D31) -> 0 | L31: =IF(L$15=0,0,L$15/$D$15*$E31*$D31) -> 0 | M31: =IF(M$15=0,0,M$15/$D$15*$E31*$D31) -> 0 | N31: =IF(N$15=0,0,N$15/$D$15*$E31*$D31) -> 0 | ... R31: =IF(R$15=0,0,R$15/$D$15*$E31*$D31) -> 0
B32: фильтр | D32: 0 | E32: 0 | G32: =IF(G$15=0,0,G$15/$D$15*$E32*$D32) -> 0 | H32: =IF(H$15=0,0,H$15/$D$15*$E32*$D32) -> 0 | I32: =IF(I$15=0,0,I$15/$D$15*$E32*$D32) -> 0 | J32: =IF(J$15=0,0,J$15/$D$15*$E32*$D32) -> 0 | K32: =IF(K$15=0,0,K$15/$D$15*$E32*$D32) -> 0 | L32: =IF(L$15=0,0,L$15/$D$15*$E32*$D32) -> 0 | M32: =IF(M$15=0,0,M$15/$D$15*$E32*$D32) -> 0 | N32: =IF(N$15=0,0,N$15/$D$15*$E32*$D32) -> 0 | ... R32: =IF(R$15=0,0,R$15/$D$15*$E32*$D32) -> 0
B33: масло | D33: 0 | E33: 0 | G33: =IF(G$15=0,0,G$15/$D$15*$E33*$D33) -> 0 | H33: =IF(H$15=0,0,H$15/$D$15*$E33*$D33) -> 0 | I33: =IF(I$15=0,0,I$15/$D$15*$E33*$D33) -> 0 | J33: =IF(J$15=0,0,J$15/$D$15*$E33*$D33) -> 0 | K33: =IF(K$15=0,0,K$15/$D$15*$E33*$D33) -> 0 | L33: =IF(L$15=0,0,L$15/$D$15*$E33*$D33) -> 0 | M33: =IF(M$15=0,0,M$15/$D$15*$E33*$D33) -> 0 | N33: =IF(N$15=0,0,N$15/$D$15*$E33*$D33) -> 0 | ... R33: =IF(R$15=0,0,R$15/$D$15*$E33*$D33) -> 0
B34: масло | D34: 326.7 | E34: 5 | G34: =IF(G$15=0,0,G$15/$D$15*$E34*$D34) -> 11434.5 | H34: =IF(H$15=0,0,H$15/$D$15*$E34*$D34) -> 11434.5 | I34: =IF(I$15=0,0,I$15/$D$15*$E34*$D34) -> 11434.5 | J34: =IF(J$15=0,0,J$15/$D$15*$E34*$D34) -> 11434.5 | K34: =IF(K$15=0,0,K$15/$D$15*$E34*$D34) -> 11434.5 | L34: =IF(L$15=0,0,L$15/$D$15*$E34*$D34) -> 11434.5 | M34: =IF(M$15=0,0,M$15/$D$15*$E34*$D34) -> 11434.5 | N34: =IF(N$15=0,0,N$15/$D$15*$E34*$D34) -> 11434.5 | ... R34: =IF(R$15=0,0,R$15/$D$15*$E34*$D34) -> 11434.5
B35: смазка | D35: 82.5 | E35: 2 | G35: =IF(G$15=0,0,G$15/$D$15*$E35*$D35) -> 1155 | H35: =IF(H$15=0,0,H$15/$D$15*$E35*$D35) -> 1155 | I35: =IF(I$15=0,0,I$15/$D$15*$E35*$D35) -> 1155 | J35: =IF(J$15=0,0,J$15/$D$15*$E35*$D35) -> 1155 | K35: =IF(K$15=0,0,K$15/$D$15*$E35*$D35) -> 1155 | L35: =IF(L$15=0,0,L$15/$D$15*$E35*$D35) -> 1155 | M35: =IF(M$15=0,0,M$15/$D$15*$E35*$D35) -> 1155 | N35: =IF(N$15=0,0,N$15/$D$15*$E35*$D35) -> 1155 | ... R35: =IF(R$15=0,0,R$15/$D$15*$E35*$D35) -> 1155
B36: смазка | D36: 0 | E36: 0 | G36: =IF(G$15=0,0,G$15/$D$15*$E36*$D36) -> 0 | H36: =IF(H$15=0,0,H$15/$D$15*$E36*$D36) -> 0 | I36: =IF(I$15=0,0,I$15/$D$15*$E36*$D36) -> 0 | J36: =IF(J$15=0,0,J$15/$D$15*$E36*$D36) -> 0 | K36: =IF(K$15=0,0,K$15/$D$15*$E36*$D36) -> 0 | L36: =IF(L$15=0,0,L$15/$D$15*$E36*$D36) -> 0 | M36: =IF(M$15=0,0,M$15/$D$15*$E36*$D36) -> 0 | N36: =IF(N$15=0,0,N$15/$D$15*$E36*$D36) -> 0 | ... R36: =IF(R$15=0,0,R$15/$D$15*$E36*$D36) -> 0
B37: ТО-3 | E37: =VLOOKUP($B37,$B$14:$C$19,2,FALSE) -> 2000 | F37: =VLOOKUP($B37,$B$14:$E$19,4,FALSE) -> 3
B38: фильтр | D38: 0 | E38: 0 | G38: =IF(G$16=0,0,G$16/$D$16*$E38*$D38) -> 0 | H38: =IF(H$16=0,0,H$16/$D$16*$E38*$D38) -> 0 | I38: =IF(I$16=0,0,I$16/$D$16*$E38*$D38) -> 0 | J38: =IF(J$16=0,0,J$16/$D$16*$E38*$D38) -> 0 | K38: =IF(K$16=0,0,K$16/$D$16*$E38*$D38) -> 0 | L38: =IF(L$16=0,0,L$16/$D$16*$E38*$D38) -> 0 | M38: =IF(M$16=0,0,M$16/$D$16*$E38*$D38) -> 0 | N38: =IF(N$16=0,0,N$16/$D$16*$E38*$D38) -> 0 | ... R38: =IF(R$16=0,0,R$16/$D$16*$E38*$D38) -> 0
B39: фильтр | D39: 0 | E39: 0 | G39: =IF(G$16=0,0,G$16/$D$16*$E39*$D39) -> 0 | H39: =IF(H$16=0,0,H$16/$D$16*$E39*$D39) -> 0 | I39: =IF(I$16=0,0,I$16/$D$16*$E39*$D39) -> 0 | J39: =IF(J$16=0,0,J$16/$D$16*$E39*$D39) -> 0 | K39: =IF(K$16=0,0,K$16/$D$16*$E39*$D39) -> 0 | L39: =IF(L$16=0,0,L$16/$D$16*$E39*$D39) -> 0 | M39: =IF(M$16=0,0,M$16/$D$16*$E39*$D39) -> 0 | N39: =IF(N$16=0,0,N$16/$D$16*$E39*$D39) -> 0 | ... R39: =IF(R$16=0,0,R$16/$D$16*$E39*$D39) -> 0
B40: масло | D40: 0 | E40: 0 | G40: =IF(G$16=0,0,G$16/$D$16*$E40*$D40) -> 0 | H40: =IF(H$16=0,0,H$16/$D$16*$E40*$D40) -> 0 | I40: =IF(I$16=0,0,I$16/$D$16*$E40*$D40) -> 0 | J40: =IF(J$16=0,0,J$16/$D$16*$E40*$D40) -> 0 | K40: =IF(K$16=0,0,K$16/$D$16*$E40*$D40) -> 0 | L40: =IF(L$16=0,0,L$16/$D$16*$E40*$D40) -> 0 | M40: =IF(M$16=0,0,M$16/$D$16*$E40*$D40) -> 0 | N40: =IF(N$16=0,0,N$16/$D$16*$E40*$D40) -> 0 | ... R40: =IF(R$16=0,0,R$16/$D$16*$E40*$D40) -> 0
B41: масло | D41: 326.7 | E41: 5 | G41: =IF(G$16=0,0,G$16/$D$16*$E41*$D41) -> 4900.5 | H41: =IF(H$16=0,0,H$16/$D$16*$E41*$D41) -> 6534 | I41: =IF(I$16=0,0,I$16/$D$16*$E41*$D41) -> 4900.5 | J41: =IF(J$16=0,0,J$16/$D$16*$E41*$D41) -> 6534 | K41: =IF(K$16=0,0,K$16/$D$16*$E41*$D41) -> 4900.5 | L41: =IF(L$16=0,0,L$16/$D$16*$E41*$D41) -> 6534 | M41: =IF(M$16=0,0,M$16/$D$16*$E41*$D41) -> 4900.5 | N41: =IF(N$16=0,0,N$16/$D$16*$E41*$D41) -> 6534 | ... R41: =IF(R$16=0,0,R$16/$D$16*$E41*$D41) -> 6534
B42: смазка | D42: 82.5 | E42: 2 | G42: =IF(G$16=0,0,G$16/$D$16*$E42*$D42) -> 495 | H42: =IF(H$16=0,0,H$16/$D$16*$E42*$D42) -> 660 | I42: =IF(I$16=0,0,I$16/$D$16*$E42*$D42) -> 495 | J42: =IF(J$16=0,0,J$16/$D$16*$E42*$D42) -> 660 | K42: =IF(K$16=0,0,K$16/$D$16*$E42*$D42) -> 495 | L42: =IF(L$16=0,0,L$16/$D$16*$E42*$D42) -> 660 | M42: =IF(M$16=0,0,M$16/$D$16*$E42*$D42) -> 495 | N42: =IF(N$16=0,0,N$16/$D$16*$E42*$D42) -> 660 | ... R42: =IF(R$16=0,0,R$16/$D$16*$E42*$D42) -> 660
B43: смазка | D43: 574.2 | E43: 5 | G43: =IF(G$16=0,0,G$16/$D$16*$E43*$D43) -> 8613 | H43: =IF(H$16=0,0,H$16/$D$16*$E43*$D43) -> 11484 | I43: =IF(I$16=0,0,I$16/$D$16*$E43*$D43) -> 8613 | J43: =IF(J$16=0,0,J$16/$D$16*$E43*$D43) -> 11484 | K43: =IF(K$16=0,0,K$16/$D$16*$E43*$D43) -> 8613 | L43: =IF(L$16=0,0,L$16/$D$16*$E43*$D43) -> 11484 | M43: =IF(M$16=0,0,M$16/$D$16*$E43*$D43) -> 8613 | N43: =IF(N$16=0,0,N$16/$D$16*$E43*$D43) -> 11484 | ... R43: =IF(R$16=0,0,R$16/$D$16*$E43*$D43) -> 11484
B44: ТО-4 | E44: =VLOOKUP($B44,$B$14:$C$19,2,FALSE) -> 3000 | F44: =VLOOKUP($B44,$B$14:$E$19,4,FALSE) -> 2
...

Sheet Ремонты
B2: ячейки к заполнению поставщиком
B3: Расчетный КТГ | F3: ='Данные_Буровой станок'!E6 -> 0.93 | G3: ='Данные_Буровой станок'!F6 -> 0.93 | H3: ='Данные_Буровой станок'!G6 -> 0.92 | I3: ='Данные_Буровой станок'!H6 -> 0.92 | J3: ='Данные_Буровой станок'!I6 -> 0.87 | K3: ='Данные_Буровой станок'!J6 -> 0.9 | L3: ='Данные_Буровой станок'!K6 -> 0.85 | M3: ='Данные_Буровой станок'!L6 -> 0.9 | ... Q3: ='Данные_Буровой станок'!P6 -> 0.89
B4: Год службы (год) | C4: Ед.изм. | F4: 1 | G4: =F4+1 -> 2 | H4: =G4+1 -> 3 | I4: =H4+1 -> 4 | J4: =I4+1 -> 5 | K4: =J4+1 -> 6 | L4: =K4+1 -> 7 | M4: =L4+1 -> 8 | N4: =M4+1 -> 9 | ... Q4: =P4+1 -> 12
B5: Наработка на начало года | C5: м/час | F5: 0 | G5: =F6+1 -> 7001 | H5: =G6+1 -> 14001 | I5: =H6+1 -> 21001 | J5: =I6+1 -> 28001 | K5: =J6+1 -> 35001 | L5: =K6+1 -> 42001 | M5: =L6+1 -> 49001 | N5: =M6+1 -> 56001 | ... Q5: =P6+1 -> 77001
B6: Наработка на конец года | C6: м/час | E6: =[2]维护!F6 -> 7000 | F6: =E6 -> 7000 | G6: =F6+$E6 -> 14000 | H6: =G6+$E6 -> 21000 | I6: =H6+$E6 -> 28000 | J6: =I6+$E6 -> 35000 | K6: =J6+$E6 -> 42000 | L6: =K6+$E6 -> 49000 | M6: =L6+$E6 -> 56000 | N6: =M6+$E6 -> 63000 | ... Q6: =P6+$E6 -> 84000
B8: Простои в ремонтах | C8: часов | F8: =F16 -> 102.66667 | G8: =G16 -> 102.66667 | H8: =H16 -> 102.66667 | I8: =I16 -> 102.66667 | J8: =J16 -> 102.66667 | K8: =K16 -> 102.66667 | L8: =L16 -> 102.66667 | M8: =M16 -> 102.66667 | ... Q8: =Q16 -> 102.66667
B9: Затраты на ТО и ремонты | C9: $/год | F9: =SUM(F10:F12) -> 200111.67 | G9: =SUM(G10:G12) -> 832651.67 | H9: =SUM(H10:H12) -> 736126.67 | I9: =SUM(I10:I12) -> 648181.67 | J9: =SUM(J10:J12) -> 641251.67 | K9: =SUM(K10:K12) -> 925051.67 | L9: =SUM(L10:L12) -> 648181.67 | M9: =SUM(M10:M12) -> 647851.67 | ... Q9: =SUM(Q10:Q12) -> 920926.67
B10: текущие ремонты | C10: $/год | F10: =F33 -> 2500 | G10: =G33 -> 2500 | H10: =H33 -> 2500 | I10: =I33 -> 2500 | J10: =J33 -> 2500 | K10: =K33 -> 2500 | L10: =L33 -> 2500 | M10: =M33 -> 2500 | ... Q10: =Q33 -> 2500
B11: планово-предупредительные (капитальные) ремонты | C11: $/год | F11: =F39 -> 71845 | G11: =G39 -> 704385 | H11: =H39 -> 607860 | I11: =I39 -> 519915 | J11: =J39 -> 512985 | K11: =K39 -> 796785 | L11: =L39 -> 519915 | M11: =M39 -> 519585 | ... Q11: =Q39 -> 792660
B12: сервис (трудозатраты) | C12: $/год | F12: =SUMPRODUCT(F$25:F$29,$D25:$D29) -> 125766.67 | G12: =SUMPRODUCT(G$25:G$29,$D25:$D29) -> 125766.67 | H12: =SUMPRODUCT(H$25:H$29,$D25:$D29) -> 125766.67 | I12: =SUMPRODUCT(I$25:I$29,$D25:$D29) -> 125766.67 | J12: =SUMPRODUCT(J$25:J$29,$D25:$D29) -> 125766.67 | K12: =SUMPRODUCT(K$25:K$29,$D25:$D29) -> 125766.67 | L12: =SUMPRODUCT(L$25:L$29,$D25:$D29) -> 125766.67 | M12: =SUMPRODUCT(M$25:M$29,$D25:$D29) -> 125766.67 | ... Q12: =SUMPRODUCT(Q$25:Q$29,$D25:$D29) -> 125766.67
B14: Простои в ремонте (час)
B15: Вид ремонта | C15: Ед.изм. | F15: часов | G15: часов | H15: часов | I15: часов | J15: часов | K15: часов | L15: часов | M15: часов | N15: часов | O15: часов | P15: часов | Q15: часов
B16: Всего простоев | F16: =SUM(F17:F21) -> 102.66667 | G16: =SUM(G17:G21) -> 102.66667 | H16: =SUM(H17:H21) -> 102.66667 | I16: =SUM(I17:I21) -> 102.66667 | J16: =SUM(J17:J21) -> 102.66667 | K16: =SUM(K17:K21) -> 102.66667 | L16: =SUM(L17:L21) -> 102.66667 | M16: =SUM(M17:M21) -> 102.66667 | ... Q16: =SUM(Q17:Q21) -> 102.66667
B17: Замена электрических компонентов | C17: часов | F17: =7000/1000*4 -> 28 | G17: =7000/1000*4 -> 28 | H17: =7000/1000*4 -> 28 | I17: =7000/1000*4 -> 28 | J17: =7000/1000*4 -> 28 | K17: =7000/1000*4 -> 28 | L17: =7000/1000*4 -> 28 | M17: =7000/1000*4 -> 28 | ... Q17: =7000/1000*4 -> 28
B18: Регулировка или замена изнашиваемых деталей рабочего оборудования | C18: часов | F18: =7000/1000*4 -> 28 | G18: =7000/1000*4 -> 28 | H18: =7000/1000*4 -> 28 | I18: =7000/1000*4 -> 28 | J18: =7000/1000*4 -> 28 | K18: =7000/1000*4 -> 28 | L18: =7000/1000*4 -> 28 | M18: =7000/1000*4 -> 28 | ... Q18: =7000/1000*4 -> 28
B19: Ремонт и техническое обслуживание системы двигателя | C19: часов | F19: 0 | G19: 0 | H19: 0 | I19: 0 | J19: 0 | K19: 0 | L19: 0 | M19: 0 | N19: 0 | O19: 0 | P19: 0 | Q19: 0
B20: Ремонт и техническое обслуживание гидравлической системы | C20: часов | F20: =7000/1500*4 -> 18.666667 | G20: =7000/1500*4 -> 18.666667 | H20: =7000/1500*4 -> 18.666667 | I20: =7000/1500*4 -> 18.666667 | J20: =7000/1500*4 -> 18.666667 | K20: =7000/1500*4 -> 18.666667 | L20: =7000/1500*4 -> 18.666667 | M20: =7000/1500*4 -> 18.666667 | ... Q20: =7000/1500*4 -> 18.666667
B21: Ремонт и техническое обслуживание ходовой части | C21: часов | F21: =7000/1500*6 -> 28 | G21: =7000/1500*6 -> 28 | H21: =7000/1500*6 -> 28 | I21: =7000/1500*6 -> 28 | J21: =7000/1500*6 -> 28 | K21: =7000/1500*6 -> 28 | L21: =7000/1500*6 -> 28 | M21: =7000/1500*6 -> 28 | ... Q21: =7000/1500*6 -> 28
B23: Трудозатраты на ремонты (ч/час) | D23: =ТО!F10 -> 35
B24: Вид ремонта | C24: Ед.изм. | D24: Стоимость чел.часа | F24: ч/часов | G24: ч/часов | H24: ч/часов | I24: ч/часов | J24: ч/часов | K24: ч/часов | L24: ч/часов | M24: ч/часов | N24: ч/часов | O24: ч/часов | P24: ч/часов | Q24: ч/часов
B25: =B17 -> Замена электрических компонентов | C25: ч/часов | D25: =$D$23 -> 35 | F25: =$D$25*F17 -> 980 | G25: =$D$25*G17 -> 980 | H25: =$D$25*H17 -> 980 | I25: =$D$25*I17 -> 980 | J25: =$D$25*J17 -> 980 | K25: =$D$25*K17 -> 980 | L25: =$D$25*L17 -> 980 | M25: =$D$25*M17 -> 980 | ... Q25: =$D$25*Q17 -> 980
B26: =B18 -> Регулировка или замена изнашиваемых деталей рабочего оборудования | C26: ч/часов | D26: =$D$23 -> 35 | F26: =$D$26*F18 -> 980 | G26: =$D$26*G18 -> 980 | H26: =$D$26*H18 -> 980 | I26: =$D$26*I18 -> 980 | J26: =$D$26*J18 -> 980 | K26: =$D$26*K18 -> 980 | L26: =$D$26*L18 -> 980 | M26: =$D$26*M18 -> 980 | ... Q26: =$D$26*Q18 -> 980
B27: =B19 -> Ремонт и техническое обслуживание системы двигателя | C27: ч/часов | D27: =$D$23 -> 35 | F27: =$D$27*F19 -> 0 | G27: =$D$27*G19 -> 0 | H27: =$D$27*H19 -> 0 | I27: =$D$27*I19 -> 0 | J27: =$D$27*J19 -> 0 | K27: =$D$27*K19 -> 0 | L27: =$D$27*L19 -> 0 | M27: =$D$27*M19 -> 0 | ... Q27: =$D$27*Q19 -> 0
B28: =B20 -> Ремонт и техническое обслуживание гидравлической системы | C28: ч/часов | D28: =$D$23 -> 35 | F28: =$D$28*F20 -> 653.33333 | G28: =$D$28*G20 -> 653.33333 | H28: =$D$28*H20 -> 653.33333 | I28: =$D$28*I20 -> 653.33333 | J28: =$D$28*J20 -> 653.33333 | K28: =$D$28*K20 -> 653.33333 | L28: =$D$28*L20 -> 653.33333 | M28: =$D$28*M20 -> 653.33333 | ... Q28: =$D$28*Q20 -> 653.33333
B29: =B21 -> Ремонт и техническое обслуживание ходовой части | C29: ч/часов | D29: =$D$23 -> 35 | F29: =$D$29*F21 -> 980 | G29: =$D$29*G21 -> 980 | H29: =$D$29*H21 -> 980 | I29: =$D$29*I21 -> 980 | J29: =$D$29*J21 -> 980 | K29: =$D$29*K21 -> 980 | L29: =$D$29*L21 -> 980 | M29: =$D$29*M21 -> 980 | ... Q29: =$D$29*Q21 -> 980
B31: Затраты на ремонты ($)
B32: Детализация затрат | C32: Стоимость за ед., $ | D32: Ресурс до замены / ремонта, м/ч | E32: Кол-во МТР | F32: $ | G32: $ | H32: $ | I32: $ | J32: $ | K32: $ | L32: $ | M32: $ | N32: $ | O32: $ | P32: $ | Q32: $
B33: Текущие ремонты (если планируются) | F33: =SUM(F34:F38) -> 2500 | G33: =SUM(G34:G38) -> 2500 | H33: =SUM(H34:H38) -> 2500 | I33: =SUM(I34:I38) -> 2500 | J33: =SUM(J34:J38) -> 2500 | K33: =SUM(K34:K38) -> 2500 | L33: =SUM(L34:L38) -> 2500 | M33: =SUM(M34:M38) -> 2500 | ... Q33: =SUM(Q34:Q38) -> 2500
B34: текущий ремонт (ходовая часть) | C34: 500 | D34: 2000 | E34: 2 | F34: =$E34*$C34 -> 1000 | G34: =$E34*$C34 -> 1000 | H34: =$E34*$C34 -> 1000 | I34: =$E34*$C34 -> 1000 | J34: =$E34*$C34 -> 1000 | K34: =$E34*$C34 -> 1000 | L34: =$E34*$C34 -> 1000 | M34: =$E34*$C34 -> 1000 | ... Q34: =$E34*$C34 -> 1000
B35: текущий ремонт (рабочее оборудование) | C35: 500 | D35: 1000 | E35: 1 | F35: =$E35*$C35 -> 500 | G35: =$E35*$C35 -> 500 | H35: =$E35*$C35 -> 500 | I35: =$E35*$C35 -> 500 | J35: =$E35*$C35 -> 500 | K35: =$E35*$C35 -> 500 | L35: =$E35*$C35 -> 500 | M35: =$E35*$C35 -> 500 | ... Q35: =$E35*$C35 -> 500
B36: другое (электрические компоненты) | C36: 500 | D36: 2000 | E36: 1 | F36: =$E36*$C36 -> 500 | G36: =$E36*$C36 -> 500 | H36: =$E36*$C36 -> 500 | I36: =$E36*$C36 -> 500 | J36: =$E36*$C36 -> 500 | K36: =$E36*$C36 -> 500 | L36: =$E36*$C36 -> 500 | M36: =$E36*$C36 -> 500 | ... Q36: =$E36*$C36 -> 500
B37: другое (силовая система) | C37: 500 | D37: 2000 | E37: 0 | F37: =$E37*$C37 -> 0 | G37: =$E37*$C37 -> 0 | H37: =$E37*$C37 -> 0 | I37: =$E37*$C37 -> 0 | J37: =$E37*$C37 -> 0 | K37: =$E37*$C37 -> 0 | L37: =$E37*$C37 -> 0 | M37: =$E37*$C37 -> 0 | ... Q37: =$E37*$C37 -> 0
B38: другое (система воздушного компрессора) | C38: 500 | D38: 2000 | E38: 1 | F38: =$E38*$C38 -> 500 | G38: =$E38*$C38 -> 500 | H38: =$E38*$C38 -> 500 | I38: =$E38*$C38 -> 500 | J38: =$E38*$C38 -> 500 | K38: =$E38*$C38 -> 500 | L38: =$E38*$C38 -> 500 | M38: =$E38*$C38 -> 500 | ... Q38: =$E38*$C38 -> 500
B39: планово-предупредительные (капитальные) ремонты | F39: =SUM(F40:F77) -> 71845 | G39: =SUM(G40:G77) -> 704385 | H39: =SUM(H40:H77) -> 607860 | I39: =SUM(I40:I77) -> 519915 | J39: =SUM(J40:J77) -> 512985 | K39: =SUM(K40:K77) -> 796785 | L39: =SUM(L40:L77) -> 519915 | M39: =SUM(M40:M77) -> 519585 | ... Q39: =SUM(Q40:Q77) -> 792660
B40: ДВС
B41: турбокомпрессор | C41: 12375 | D41: 12000 | E41: 1 | F41: 0 | G41: =C41*E41 -> 12375 | H41: 0 | I41: =C41*E41 -> 12375 | J41: 0 | K41: =C41*E41 -> 12375 | L41: =C41*E41 -> 12375 | M41: 0 | N41: =C41*E41 -> 12375 | O41: 0 | P41: =C41*E41 -> 12375 | Q41: =C41*E41 -> 12375
B42: инжекторы | C42: 3795 | D42: 10000 | E42: 1 | F42: 0 | G42: =C42*E42 -> 3795 | H42: =C42*E42 -> 3795 | I42: 0 | J42: =C42*E42 -> 3795 | K42: =C42*E42 -> 3795 | L42: 0 | M42: =C42*E42 -> 3795 | N42: =C42*E42 -> 3795 | O42: =C42*E42 -> 3795 | P42: 0 | Q42: =C42*E42 -> 3795
B43: стартер | C43: 2475 | D43: 8000 | E43: 1 | F43: 0 | G43: =C43*E43 -> 2475 | H43: =C43*E43 -> 2475 | I43: =C43*E43 -> 2475 | J43: =C43*E43 -> 2475 | K43: =C43*E43 -> 2475 | L43: =C43*E43 -> 2475 | M43: =C43*E43 -> 2475 | N43: 0 | O43: =C43*E43 -> 2475 | P43: =C43*E43 -> 2475 | Q43: =C43*E43 -> 2475
B44: генератор | C44: 4125 | D44: 8000 | E44: 1 | F44: 0 | G44: =C44*E44 -> 4125 | H44: =C44*E44 -> 4125 | I44: =C44*E44 -> 4125 | J44: =C44*E44 -> 4125 | K44: =C44*E44 -> 4125 | L44: =C44*E44 -> 4125 | M44: =C44*E44 -> 4125 | N44: 0 | O44: =C44*E44 -> 4125 | P44: =C44*E44 -> 4125 | Q44: =C44*E44 -> 4125
B45: другое (радиатор) | C45: 6600 | D45: 10000 | E45: 1 | F45: 0 | G45: =C45*E45 -> 6600 | H45: =C45*E45 -> 6600 | I45: 0 | J45: =C45*E45 -> 6600 | K45: =C45*E45 -> 6600 | L45: 0 | M45: =C45*E45 -> 6600 | N45: =C45*E45 -> 6600 | O45: =C45*E45 -> 6600 | P45: 0 | Q45: =C45*E45 -> 6600
...
