Workbook

Sheet Данные -Карьерный самосвал
B2: ячейки к заполнению поставщиком | P2: в действующих ценах
B3: Карьерный автосамосвал | C3: Марка, модель | D3: 7531N | O3: Примечания
A4: 1 | B4: Период | C4: Ед. изм. | D4: 0 | E4: =D4+1 -> 1 | F4: =E4+1 -> 2 | G4: =F4+1 -> 3 | H4: =G4+1 -> 4 | I4: =H4+1 -> 5 | J4: =I4+1 -> 6 | K4: =J4+1 -> 7 | L4: =K4+1 -> 8 | ... N4: =M4+1 -> 10
A5: =A4+1 -> 2 | B5: Габариты машины
A6: =A5+1 -> 3 | B6: Эксплуатационная ширина (по зеркалам) | C6: мм | E6: 8400 | F6: 8400 | G6: 8400 | H6: 8400 | I6: 8400 | J6: 8400 | K6: 8400 | L6: 8400 | M6: 8400 | N6: 8400
A7: =A6+1 -> 4 | B7: Высота по переднему козырьку | C7: мм | E7: 6720 | F7: 6720 | G7: 6720 | H7: 6720 | I7: 6720 | J7: 6720 | K7: 6720 | L7: 6720 | M7: 6720 | N7: 6720
A8: =A7+1 -> 5 | B8: Габаритная длина | C8: мм | E8: 13390 | F8: 13390 | G8: 13390 | H8: 13390 | I8: 13390 | J8: 13390 | K8: 13390 | L8: 13390 | M8: 13390 | N8: 13390
A9: =A8+1 -> 6 | B9: Грузоподъемность | C9: тн | E9: 240 | F9: 240 | G9: 240 | H9: 240 | I9: 240 | J9: 240 | K9: 240 | L9: 240 | M9: 240 | N9: 240
A10: =A9+1 -> 7 | B10: Геометрические параметры кузова (конфигурация, размеры) | C10: м³ | E10: 141 | F10: 141 | G10: 141 | H10: 141 | I10: 141 | J10: 141 | K10: 141 | L10: 141 | M10: 141 | N10: 141 | O10: не более 2000 кг/куб.м
A11: =A10+1 -> 8 | B11: Мощность двигателя | C11: л.с. | E11: 2535 | F11: 2535 | G11: 2535 | H11: 2535 | I11: 2535 | J11: 2535 | K11: 2535 | L11: 2535 | M11: 2535 | N11: 2535
A12: =A11+1 -> 9 | B12: КТГ (сервисный) | E12: =(8760-E13-E14-E15)/8760 -> 0.93078341 | F12: =(8760-F13-F14-F15)/8760 -> 0.90792065 | G12: =(8760-G13-G14-G15)/8760 -> 0.89941186 | H12: =(8760-H13-H14-H15)/8760 -> 0.88050754 | I12: =(8760-I13-I14-I15)/8760 -> 0.90115061 | J12: =(8760-J13-J14-J15)/8760 -> 0.87025999 | K12: =(8760-K13-K14-K15-300)/8760 -> 0.85058935 | L12: =(8760-L13-L14-L15)/8760 -> 0.89171695 | M12: =(8760-M13-M14-M15)/8760 -> 0.85775576 | N12: =(8760-N13-N14-N15)/8760 -> 0.85228054 | O12: при применении оборотных агрегатов
A13: =A12+1 -> 10 | B13: простои на ТО | C13: час | E13: =ТО!F7 -> 238.3755 | F13: =ТО!G7 -> 238.3755 | G13: =ТО!H7 -> 238.3755 | H13: =ТО!I7 -> 238.3755 | I13: =ТО!J7 -> 238.3755 | J13: =ТО!K7 -> 238.3755 | K13: =ТО!L7 -> 238.3755 | L13: =ТО!M7 -> 238.3755 | ... N13: =ТО!O7 -> 238.3755
A14: =A13+1 -> 11 | B14: простои в ремонтах | C14: час | E14: ='Ремонты '!F9 -> 135 | F14: ='Ремонты '!G9 -> 341 | G14: ='Ремонты '!H9 -> 417.66667 | H14: ='Ремонты '!I9 -> 588 | I14: ='Ремонты '!J9 -> 402 | J14: ='Ремонты '!K9 -> 680.33333 | K14: ='Ремонты '!L9 -> 549 | L14: ='Ремонты '!M9 -> 487 | ... N14: ='Ремонты '!O9 -> 842.33333
A15: =A14+1 -> 12 | B15: ежесменный осмотр (20 минут в смену силами водителя) | C15: час | E15: =(8760-E13-E14)/12*20/60 -> 232.96179 | F15: =(8760-F13-F14)/12*20/60 -> 227.23957 | G15: =(8760-G13-G14)/12*20/60 -> 225.10994 | H15: =(8760-H13-H14)/12*20/60 -> 220.37846 | I15: =(8760-I13-I14)/12*20/60 -> 225.54512 | J15: =(8760-J13-J14)/12*20/60 -> 217.81364 | K15: =(8760-K13-K14)/12*20/60 -> 221.46179 | L15: =(8760-L13-L14)/12*20/60 -> 223.18401 | ... N15: =(8760-N13-N14)/12*20/60 -> 213.31364
A16: =A15+1 -> 13 | B16: Время подъема кузова с грузом | C16: сек | E16: 22 | F16: 22 | G16: 22 | H16: 22 | I16: 22 | J16: 22 | K16: 22 | L16: 22 | M16: 22 | N16: 22
A17: =A16+1 -> 14 | B17: Время опускания кузова | C17: сек | E17: 33 | F17: 33 | G17: 33 | H17: 33 | I17: 33 | J17: 33 | K17: 33 | L17: 33 | M17: 33 | N17: 33
A18: =A17+1 -> 15 | B18: ТО, ТР, ПР, сервис (включая смазочных), моточас работы | C18: тыс.долл/год | E18: =SUM(E19:E23) -> 128.6444 | F18: =SUM(F19:F23) -> 209.01238 | G18: =SUM(G19:G23) -> 615.43665 | H18: =SUM(H19:H23) -> 911.52059 | I18: =SUM(I19:I23) -> 364.66374 | J18: =SUM(J19:J23) -> 636.96468 | K18: =SUM(K19:K23) -> 323.46018 | L18: =SUM(L19:L23) -> 971.72701 | ... N18: =SUM(N19:N23) -> 335.15355
A19: =A18+1 -> 16 | B19: ТО, включая смазочные | C19: тыс.дол./год | E19: =ТО!F9/1000 -> 49.599956 | F19: =ТО!G9/1000 -> 41.134557 | G19: =ТО!H9/1000 -> 41.134557 | H19: =ТО!I9/1000 -> 41.134557 | I19: =ТО!J9/1000 -> 41.134557 | J19: =ТО!K9/1000 -> 41.134557 | K19: =ТО!L9/1000 -> 41.134557 | L19: =ТО!M9/1000 -> 41.134557 | ... N19: =ТО!O9/1000 -> 41.134557
A20: =A19+1 -> 17 | B20: текущие ремонты | C20: тыс.дол./год | E20: ='Ремонты '!F11/1000 -> 15.01122 | F20: ='Ремонты '!G11/1000 -> 77.0646 | G20: ='Ремонты '!H11/1000 -> 50.72067 | H20: ='Ремонты '!I11/1000 -> 89.861 | I20: ='Ремонты '!J11/1000 -> 60.14095 | J20: ='Ремонты '!K11/1000 -> 102.8737 | K20: ='Ремонты '!L11/1000 -> 80.5474 | L20: ='Ремонты '!M11/1000 -> 64.17223 | ... N20: ='Ремонты '!O11/1000 -> 90.365775
A21: =A20+1 -> 18 | B21: планово-предупредительные (капитальные) ремонты | C21: тыс.дол./год | E21: ='Ремонты '!F12/1000 -> 0 | F21: ='Ремонты '!G12/1000 -> 0 | G21: ='Ремонты '!H12/1000 -> 410.9282 | H21: ='Ремонты '!I12/1000 -> 652.53181 | I21: ='Ремонты '!J12/1000 -> 158.40501 | J21: ='Ремонты '!K12/1000 -> 339.4832 | K21: ='Ремонты '!L12/1000 -> 71.444999 | L21: ='Ремонты '!M12/1000 -> 721.657 | ... N21: ='Ремонты '!O12/1000 -> 0
A22: =A21+1 -> 19 | B22: сервис (трудозатраты) - ТО | C22: тыс.дол./год | E22: =ТО!F10/1000 -> 46.483222 | F22: =ТО!G10/1000 -> 46.483222 | G22: =ТО!H10/1000 -> 46.483222 | H22: =ТО!I10/1000 -> 46.483222 | I22: =ТО!J10/1000 -> 46.483222 | J22: =ТО!K10/1000 -> 46.483222 | K22: =ТО!L10/1000 -> 46.483222 | L22: =ТО!M10/1000 -> 46.483222 | ... N22: =ТО!O10/1000 -> 46.483222
A23: =A22+1 -> 20 | B23: сервис (трудозатраты) - ремонты | C23: тыс.дол./год | E23: ='Ремонты '!F13/1000 -> 17.55 | F23: ='Ремонты '!G13/1000 -> 44.33 | G23: ='Ремонты '!H13/1000 -> 66.17 | H23: ='Ремонты '!I13/1000 -> 81.51 | I23: ='Ремонты '!J13/1000 -> 58.5 | J23: ='Ремонты '!K13/1000 -> 106.99 | K23: ='Ремонты '!L13/1000 -> 83.85 | L23: ='Ремонты '!M13/1000 -> 98.28 | ... N23: ='Ремонты '!O13/1000 -> 157.17
A24: =A23+1 -> 21 | B24: Шины
A25: =A24+1 -> 22 | B25: типоразмер | D25: 46/90R57 | E25: 46/90R57
A26: =A25+1 -> 23 | B26: Цена за единицу | D26: $ | E26: нет данных | O26: поставка без шин
A27: =A26+1 -> 24 | B27: Топливо
A28: =A27+1 -> 25 | B28: Расход - легкие условия | C28: л/час | E28: 90,3-135,4
A29: =A28+1 -> 26 | B29: Расход - средние условия | C29: л/час | E29: 135,4-180,6
A30: =A29+1 -> 27 | B30: Расход - тяжелые условия | C30: л/час | E30: 180,6-225,7
A31: =A30+1 -> 28 | B31: Сроки поставки | C31: мес
B33: ТО | D33: долл в час простоя ТО | E33: =E22/E13*1000 -> 195 | F33: =F22/F13*1000 -> 195 | G33: =G22/G13*1000 -> 195 | H33: =H22/H13*1000 -> 195 | I33: =I22/I13*1000 -> 195 | J33: =J22/J13*1000 -> 195 | K33: =K22/K13*1000 -> 195 | L33: =L22/L13*1000 -> 195 | ... N33: =N22/N13*1000 -> 195
D34: численность на ТО | E34: =E33/ТО!$E$10 -> 3 | F34: =F33/ТО!$E$10 -> 3 | G34: =G33/ТО!$E$10 -> 3 | H34: =H33/ТО!$E$10 -> 3 | I34: =I33/ТО!$E$10 -> 3 | J34: =J33/ТО!$E$10 -> 3 | K34: =K33/ТО!$E$10 -> 3 | L34: =L33/ТО!$E$10 -> 3 | ... N34: =N33/ТО!$E$10 -> 3 | O34: человека
D35: долл в час простоя сервис | E35: =E23/E14*1000 -> 130 | F35: =F23/F14*1000 -> 130 | G35: =G23/G14*1000 -> 158.42777 | H35: =H23/H14*1000 -> 138.62245 | I35: =I23/I14*1000 -> 145.52239 | J35: =J23/J14*1000 -> 157.26115 | K35: =K23/K14*1000 -> 152.73224 | L35: =L23/L14*1000 -> 201.80698 | ... N35: =N23/N14*1000 -> 186.58884
D36: численность на ремонт | E36: =E35/#REF! -> #REF! | F36: =F35/#REF! -> #REF! | G36: =G35/#REF! -> #REF! | H36: =H35/#REF! -> #REF! | I36: =I35/#REF! -> #REF! | J36: =J35/#REF! -> #REF! | K36: =K35/#REF! -> #REF! | L36: =L35/#REF! -> #REF! | ... N36: =N35/#REF! -> #REF!
C39: стоимость ч/час ТО | D39: =ТО!E10 -> 65 | E39: с транспортными?
C40: стоимость ч/час ремонт | D40: =#REF! -> #REF!
B42: * все стоимости указаны без НДС
B43: ** эксплуатации машин на плече не более 5 км
B44: *** без учета шин и топлива

Sheet ТО
A2: ячейки к заполнению поставщиком | B2: ='Данные -Карьерный самосвал'!C3 -> Марка, модель | C2: ='Данные -Карьерный самосвал'!D3 -> 7531N
A3: Расчетный КТГ | F3: ='Данные -Карьерный самосвал'!E12 -> 0.93078341 | G3: ='Данные -Карьерный самосвал'!F12 -> 0.90792065 | H3: ='Данные -Карьерный самосвал'!G12 -> 0.89941186 | I3: ='Данные -Карьерный самосвал'!H12 -> 0.88050754 | J3: ='Данные -Карьерный самосвал'!I12 -> 0.90115061 | K3: ='Данные -Карьерный самосвал'!J12 -> 0.87025999 | L3: ='Данные -Карьерный самосвал'!K12 -> 0.85058935 | M3: ='Данные -Карьерный самосвал'!L12 -> 0.89171695 | ... O3: ='Данные -Карьерный самосвал'!N12 -> 0.85228054
A4: Год службы (год) | B4: Ед. изм. | F4: =D4+1 -> 1 | G4: =F4+1 -> 2 | H4: =G4+1 -> 3 | I4: =H4+1 -> 4 | J4: =I4+1 -> 5 | K4: =J4+1 -> 6 | L4: =K4+1 -> 7 | M4: =L4+1 -> 8 | N4: =M4+1 -> 9 | O4: =N4+1 -> 10
A5: Наработка на начало года | B5: м/час | F5: 0 | G5: =F6+1 -> 7001 | H5: =G6+1 -> 14001 | I5: =H6+1 -> 21001 | J5: =I6+1 -> 28001 | K5: =J6+1 -> 35001 | L5: =K6+1 -> 42001 | M5: =L6+1 -> 49001 | N5: =M6+1 -> 56001 | O5: =N6+1 -> 63001
A6: Наработка на конец года | B6: м/час | E6: 7000 | F6: =E6 -> 7000 | G6: =F6+$E6 -> 14000 | H6: =G6+$E6 -> 21000 | I6: =H6+$E6 -> 28000 | J6: =I6+$E6 -> 35000 | K6: =J6+$E6 -> 42000 | L6: =K6+$E6 -> 49000 | M6: =L6+$E6 -> 56000 | N6: =M6+$E6 -> 63000 | O6: =N6+$E6 -> 70000
A7: длительность простоев на ТО | B7: часов | F7: =F13 -> 238.3755 | G7: =G13 -> 238.3755 | H7: =H13 -> 238.3755 | I7: =I13 -> 238.3755 | J7: =J13 -> 238.3755 | K7: =K13 -> 238.3755 | L7: =L13 -> 238.3755 | M7: =M13 -> 238.3755 | ... O7: =O13 -> 238.3755
A8: Затраты на ТО | B8: долларов/год | F8: =SUM(F9:F10) -> 96083.178 | G8: =SUM(G9:G10) -> 87617.78 | H8: =SUM(H9:H10) -> 87617.78 | I8: =SUM(I9:I10) -> 87617.78 | J8: =SUM(J9:J10) -> 87617.78 | K8: =SUM(K9:K10) -> 87617.78 | L8: =SUM(L9:L10) -> 87617.78 | M8: =SUM(M9:M10) -> 87617.78 | ... O8: =SUM(O9:O10) -> 87617.78
A9: ТО, включая масла и смазки | B9: долларов/год | F9: =F24 -> 49599.956 | G9: =G24 -> 41134.557 | H9: =H24 -> 41134.557 | I9: =I24 -> 41134.557 | J9: =J24 -> 41134.557 | K9: =K24 -> 41134.557 | L9: =L24 -> 41134.557 | M9: =M24 -> 41134.557 | ... O9: =O24 -> 41134.557
A10: сервис (трудозатраты) на ТО | B10: долларов/год | E10: 65 | F10: =SUMPRODUCT(F15:F21,$E$15:$E$21)*$E10 -> 46483.222 | G10: =SUMPRODUCT(G15:G21,$E$15:$E$21)*$E10 -> 46483.222 | H10: =SUMPRODUCT(H15:H21,$E$15:$E$21)*$E10 -> 46483.222 | I10: =SUMPRODUCT(I15:I21,$E$15:$E$21)*$E10 -> 46483.222 | J10: =SUMPRODUCT(J15:J21,$E$15:$E$21)*$E10 -> 46483.222 | K10: =SUMPRODUCT(K15:K21,$E$15:$E$21)*$E10 -> 46483.222 | L10: =SUMPRODUCT(L15:L21,$E$15:$E$21)*$E10 -> 46483.222 | M10: =SUMPRODUCT(M15:M21,$E$15:$E$21)*$E10 -> 46483.222 | ... O10: =SUMPRODUCT(O15:O21,$E$15:$E$21)*$E10 -> 46483.222
A12: Простои оборудования на ТО | B12: Интервал ТО | C12: Длительность простоя на одном ТО, час | D12: Кол-во ТО в год | E12: Занято человек | F12: Простоев в год, час | G12: Простоев в год, час | H12: Простоев в год, час | I12: Простоев в год, час | J12: Простоев в год, час | K12: Простоев в год, час | L12: Простоев в год, час | M12: Простоев в год, час | N12: Простоев в год, час | O12: Простоев в год, час
A13: всего простоев на ТО, часов | F13: =SUM(F15:F21) -> 238.3755 | G13: =SUM(G15:G21) -> 238.3755 | H13: =SUM(H15:H21) -> 238.3755 | I13: =SUM(I15:I21) -> 238.3755 | J13: =SUM(J15:J21) -> 238.3755 | K13: =SUM(K15:K21) -> 238.3755 | L13: =SUM(L15:L21) -> 238.3755 | M13: =SUM(M15:M21) -> 238.3755 | ... O13: =SUM(O15:O21) -> 238.3755 | Q13: простой | R13: Н/ч
A14: ТО-100 (один раз после обкатки) | B14: 100 | C14: =Q14 -> 11.02 | D14: 1 | E14: 3 | F14: =$D14*$C14 -> 11.02 | Q14: =ROUND(R14/3,2) -> 11.02 | R14: 33.05
A15: ТО-1 | B15: 250 | C15: =Q15 -> 0.47 | D15: 14 | E15: 3 | F15: =$D15*$C15 -> 6.58 | G15: =$D15*$C15 -> 6.58 | H15: =$D15*$C15 -> 6.58 | I15: =$D15*$C15 -> 6.58 | J15: =$D15*$C15 -> 6.58 | K15: =$D15*$C15 -> 6.58 | L15: =$D15*$C15 -> 6.58 | M15: =$D15*$C15 -> 6.58 | ... O15: =$D15*$C15 -> 6.58 | Q15: =ROUND(R15/3,2) -> 0.47 | R15: 1.4
A16: ТО-2 | B16: 500 | C16: =Q16 -> 10.9 | D16: 7 | E16: 3 | F16: =$D16*$C16 -> 76.3 | G16: =$D16*$C16 -> 76.3 | H16: =$D16*$C16 -> 76.3 | I16: =$D16*$C16 -> 76.3 | J16: =$D16*$C16 -> 76.3 | K16: =$D16*$C16 -> 76.3 | L16: =$D16*$C16 -> 76.3 | M16: =$D16*$C16 -> 76.3 | ... O16: =$D16*$C16 -> 76.3 | Q16: =ROUND(R16/3,2) -> 10.9 | R16: 32.7
A17: ТО-3 | B17: 1000 | C17: =Q17 -> 18.08 | D17: 7 | E17: 3 | F17: =$D17*$C17 -> 126.56 | G17: =$D17*$C17 -> 126.56 | H17: =$D17*$C17 -> 126.56 | I17: =$D17*$C17 -> 126.56 | J17: =$D17*$C17 -> 126.56 | K17: =$D17*$C17 -> 126.56 | L17: =$D17*$C17 -> 126.56 | M17: =$D17*$C17 -> 126.56 | ... O17: =$D17*$C17 -> 126.56 | Q17: =ROUND(R17/3,2) -> 18.08 | R17: 54.25
A18: ТО-каждые 2500 м/ч | B18: 2500 | C18: =Q18 -> 1.47 | D18: 2.8 | E18: 3 | F18: =$D18*$C18 -> 4.116 | G18: =$D18*$C18 -> 4.116 | H18: =$D18*$C18 -> 4.116 | I18: =$D18*$C18 -> 4.116 | J18: =$D18*$C18 -> 4.116 | K18: =$D18*$C18 -> 4.116 | L18: =$D18*$C18 -> 4.116 | M18: =$D18*$C18 -> 4.116 | ... O18: =$D18*$C18 -> 4.116 | Q18: =ROUND(R18/3,2) -> 1.47 | R18: 4.4
A19: ТО-каждые 4000 м/ч | B19: 4000 | C19: =Q19 -> 2.33 | D19: 1.75 | E19: 3 | F19: =$D19*$C19 -> 4.0775 | G19: =$D19*$C19 -> 4.0775 | H19: =$D19*$C19 -> 4.0775 | I19: =$D19*$C19 -> 4.0775 | J19: =$D19*$C19 -> 4.0775 | K19: =$D19*$C19 -> 4.0775 | L19: =$D19*$C19 -> 4.0775 | M19: =$D19*$C19 -> 4.0775 | ... O19: =$D19*$C19 -> 4.0775 | Q19: =ROUND(R19/3,2) -> 2.33 | R19: 7
A20: ТО-каждые 5000 м/ч | B20: 5000 | C20: =Q20 -> 2.43 | D20: 1.4 | E20: 3 | F20: =$D20*$C20 -> 3.402 | G20: =$D20*$C20 -> 3.402 | H20: =$D20*$C20 -> 3.402 | I20: =$D20*$C20 -> 3.402 | J20: =$D20*$C20 -> 3.402 | K20: =$D20*$C20 -> 3.402 | L20: =$D20*$C20 -> 3.402 | M20: =$D20*$C20 -> 3.402 | ... O20: =$D20*$C20 -> 3.402 | Q20: =ROUND(R20/3,2) -> 2.43 | R20: 7.3
A21: СО | B21: 3500 | C21: =Q21 -> 8.67 | D21: 2 | E21: 3 | F21: =$D21*$C21 -> 17.34 | G21: =$D21*$C21 -> 17.34 | H21: =$D21*$C21 -> 17.34 | I21: =$D21*$C21 -> 17.34 | J21: =$D21*$C21 -> 17.34 | K21: =$D21*$C21 -> 17.34 | L21: =$D21*$C21 -> 17.34 | M21: =$D21*$C21 -> 17.34 | ... O21: =$D21*$C21 -> 17.34 | Q21: =ROUND(R21/3,2) -> 8.67 | R21: 26
A23: Затраты на ТО | B23: Каталожный номер | C23: стоимость за ед., $ | D23: Кол-во | E23: Кол-во ТО в год | F23: $ | G23: $ | H23: $ | I23: $ | J23: $ | K23: $ | L23: $ | M23: $ | N23: $ | O23: $
A24: ТО | F24: =SUM(F25:F66) -> 49599.956 | G24: =SUM(G25:G66) -> 41134.557 | H24: =SUM(H25:H66) -> 41134.557 | I24: =SUM(I25:I66) -> 41134.557 | J24: =SUM(J25:J66) -> 41134.557 | K24: =SUM(K25:K66) -> 41134.557 | L24: =SUM(L25:L66) -> 41134.557 | M24: =SUM(M25:M66) -> 41134.557 | ... O24: =SUM(O25:O66) -> 41134.557
A25: ТО-100 | D25: 100 | E25: 1
A26: Масло моторное | B26: BELAZG-ProfiMining15W-40 | C26: =VLOOKUP(B26,'[1]Прайс-лист'!$C$5:$J$45,8,FALSE) -> 3.43 | D26: 380 | F26: =IF(F$14=0,0,F$14/$C$14*$D26*$C26) -> 1303.4
A27: Заменить центробежный масляный фильтр ДВС | B27: 1005008511 | C27: =VLOOKUP(B27,'[1]Прайс-лист'!$C$5:$J$45,8,FALSE) -> 5.6785235 | D27: 2 | F27: =IF(F$14=0,0,F$14/$C$14*$D27*$C27) -> 11.357047
A28: Заменить фильтр масляный полнопоточный ДВС | B28: 1013032300 | C28: =VLOOKUP(B28,'[1]Прайс-лист'!$C$5:$J$45,8,FALSE) -> 160.35279 | D28: 5 | F28: =IF(F$14=0,0,F$14/$C$14*$D28*$C28) -> 801.76394
A29: Заменить фильтр топливный грубой очистки ДВС | B29: 1008088044(1000104480) | C29: =VLOOKUP(B29,'[1]Прайс-лист'!$C$5:$J$45,8,FALSE) -> 202.41122 | D29: 1 | F29: =IF(F$14=0,0,F$14/$C$14*$D29*$C29) -> 202.41122
A30: Заменить фильтр топливный тонкой очистки ДВС | B30: 1008088046(1000104483) | C30: =VLOOKUP(B30,'[1]Прайс-лист'!$C$5:$J$45,8,FALSE) -> 147.49115 | D30: 3 | F30: =IF(F$14=0,0,F$14/$C$14*$D30*$C30) -> 442.47346
A31: Заменить масло в РМК | B31: BELAZ G-Profi TRANS Plus 680 | C31: =VLOOKUP(B31,'[1]Прайс-лист'!$C$5:$J$45,8,FALSE) -> 15.036 | D31: 210 | F31: =IF(F$14=0,0,F$14/$C$14*$D31*$C31) -> 3157.56
A32: добавить смазку в манжеты картера редуктора РМК (100 г в каждую масленку) | B32: BELAZ G-Profi Grease MP EP 2 / CLS | C32: =VLOOKUP(B32,'[1]Прайс-лист'!$C$5:$J$45,8,FALSE) -> 11.046 | D32: 0.6 | F32: =IF(F$14=0,0,F$14/$C$14*$D32*$C32) -> 6.6276
A33: Произвести замену масла объединенной гидравлической системы | B33: BELAZG-ProfiHydraulicHVLP46/32 | C33: =VLOOKUP(B33,'[1]Прайс-лист'!$C$5:$J$45,8,FALSE) -> 3.08 | D33: 790 | F33: =IF(F$14=0,0,F$14/$C$14*$D33*$C33) -> 2433.2
A34: Заменить фильтрующий элемент гидробака | B34: EE500600/М5409МК | C34: =VLOOKUP(B34,'[1]Прайс-лист'!$C$5:$J$45,8,FALSE) -> 86.669333 | D34: 1 | F34: =IF(F$14=0,0,F$14/$C$14*$D34*$C34) -> 86.669333
A35: Заменить фильтрующий элемент напорной линии насоса | B35: EE502300 (М5402МК) | C35: =VLOOKUP(B35,'[1]Прайс-лист'!$C$5:$J$45,8,FALSE) -> 19.936 | D35: 1 | F35: =IF(F$14=0,0,F$14/$C$14*$D35*$C35) -> 19.936
A36: ТО-1 | D36: =VLOOKUP($A36,$A$15:$B$21,2,FALSE) -> 250 | E36: =VLOOKUP($A36,$A$15:$D$21,4,) -> 14
F37: =IF(F$15=0,0,F$15/$C$15*$D37*$C37) -> 0 | G37: =IF(G$15=0,0,G$15/$C$15*$D37*$C37) -> 0 | H37: =IF(H$15=0,0,H$15/$C$15*$D37*$C37) -> 0 | I37: =IF(I$15=0,0,I$15/$C$15*$D37*$C37) -> 0 | J37: =IF(J$15=0,0,J$15/$C$15*$D37*$C37) -> 0 | K37: =IF(K$15=0,0,K$15/$C$15*$D37*$C37) -> 0 | L37: =IF(L$15=0,0,L$15/$C$15*$D37*$C37) -> 0 | M37: =IF(M$15=0,0,M$15/$C$15*$D37*$C37) -> 0 | ... O37: =IF(O$15=0,0,O$15/$C$15*$D37*$C37) -> 0
A38: ТО-2 | D38: =VLOOKUP($A38,$A$15:$B$21,2,FALSE) -> 500 | E38: =VLOOKUP($A38,$A$15:$D$21,4,FALSE) -> 7
A39: Масло моторное | B39: BELAZG-ProfiMining15W-40 | C39: =VLOOKUP(B39,'[1]Прайс-лист'!$C$5:$J$45,8,FALSE) -> 3.43 | D39: 380 | F39: =IF(F$16=0,0,F$16/$C$16*$D39*$C39) -> 9123.8 | G39: =IF(G$16=0,0,G$16/$C$16*$D39*$C39) -> 9123.8 | H39: =IF(H$16=0,0,H$16/$C$16*$D39*$C39) -> 9123.8 | I39: =IF(I$16=0,0,I$16/$C$16*$D39*$C39) -> 9123.8 | J39: =IF(J$16=0,0,J$16/$C$16*$D39*$C39) -> 9123.8 | K39: =IF(K$16=0,0,K$16/$C$16*$D39*$C39) -> 9123.8 | L39: =IF(L$16=0,0,L$16/$C$16*$D39*$C39) -> 9123.8 | M39: =IF(M$16=0,0,M$16/$C$16*$D39*$C39) -> 9123.8 | ... O39: =IF(O$16=0,0,O$16/$C$16*$D39*$C39) -> 9123.8
A40: Заменить центробежный масляный фильтр ДВС | B40: 1005008511 | C40: =VLOOKUP(B40,'[1]Прайс-лист'!$C$5:$J$45,8,FALSE) -> 5.6785235 | D40: 2 | F40: =IF(F$16=0,0,F$16/$C$16*$D40*$C40) -> 79.499329 | G40: =IF(G$16=0,0,G$16/$C$16*$D40*$C40) -> 79.499329 | H40: =IF(H$16=0,0,H$16/$C$16*$D40*$C40) -> 79.499329 | I40: =IF(I$16=0,0,I$16/$C$16*$D40*$C40) -> 79.499329 | J40: =IF(J$16=0,0,J$16/$C$16*$D40*$C40) -> 79.499329 | K40: =IF(K$16=0,0,K$16/$C$16*$D40*$C40) -> 79.499329 | L40: =IF(L$16=0,0,L$16/$C$16*$D40*$C40) -> 79.499329 | M40: =IF(M$16=0,0,M$16/$C$16*$D40*$C40) -> 79.499329 | ... O40: =IF(O$16=0,0,O$16/$C$16*$D40*$C40) -> 79.499329
A41: Заменить фильтр масляный полнопоточный ДВС | B41: 1013032300 | C41: =VLOOKUP(B41,'[1]Прайс-лист'!$C$5:$J$45,8,FALSE) -> 160.35279 | D41: 5 | F41: =IF(F$16=0,0,F$16/$C$16*$D41*$C41) -> 5612.3476 | G41: =IF(G$16=0,0,G$16/$C$16*$D41*$C41) -> 5612.3476 | H41: =IF(H$16=0,0,H$16/$C$16*$D41*$C41) -> 5612.3476 | I41: =IF(I$16=0,0,I$16/$C$16*$D41*$C41) -> 5612.3476 | J41: =IF(J$16=0,0,J$16/$C$16*$D41*$C41) -> 5612.3476 | K41: =IF(K$16=0,0,K$16/$C$16*$D41*$C41) -> 5612.3476 | L41: =IF(L$16=0,0,L$16/$C$16*$D41*$C41) -> 5612.3476 | M41: =IF(M$16=0,0,M$16/$C$16*$D41*$C41) -> 5612.3476 | ... O41: =IF(O$16=0,0,O$16/$C$16*$D41*$C41) -> 5612.3476
A42: Заменить фильтр топливный грубой очистки ДВС | B42: 1008088044(1000104480) | C42: =VLOOKUP(B42,'[1]Прайс-лист'!$C$5:$J$45,8,FALSE) -> 202.41122 | D42: 1 | F42: =IF(F$16=0,0,F$16/$C$16*$D42*$C42) -> 1416.8785 | G42: =IF(G$16=0,0,G$16/$C$16*$D42*$C42) -> 1416.8785 | H42: =IF(H$16=0,0,H$16/$C$16*$D42*$C42) -> 1416.8785 | I42: =IF(I$16=0,0,I$16/$C$16*$D42*$C42) -> 1416.8785 | J42: =IF(J$16=0,0,J$16/$C$16*$D42*$C42) -> 1416.8785 | K42: =IF(K$16=0,0,K$16/$C$16*$D42*$C42) -> 1416.8785 | L42: =IF(L$16=0,0,L$16/$C$16*$D42*$C42) -> 1416.8785 | M42: =IF(M$16=0,0,M$16/$C$16*$D42*$C42) -> 1416.8785 | ... O42: =IF(O$16=0,0,O$16/$C$16*$D42*$C42) -> 1416.8785
A43: Заменить фильтр топливный тонкой очистки ДВС | B43: 1008088046(1000104483) | C43: =VLOOKUP(B43,'[1]Прайс-лист'!$C$5:$J$45,8,FALSE) -> 147.49115 | D43: 3 | F43: =IF(F$16=0,0,F$16/$C$16*$D43*$C43) -> 3097.3142 | G43: =IF(G$16=0,0,G$16/$C$16*$D43*$C43) -> 3097.3142 | H43: =IF(H$16=0,0,H$16/$C$16*$D43*$C43) -> 3097.3142 | I43: =IF(I$16=0,0,I$16/$C$16*$D43*$C43) -> 3097.3142 | J43: =IF(J$16=0,0,J$16/$C$16*$D43*$C43) -> 3097.3142 | K43: =IF(K$16=0,0,K$16/$C$16*$D43*$C43) -> 3097.3142 | L43: =IF(L$16=0,0,L$16/$C$16*$D43*$C43) -> 3097.3142 | M43: =IF(M$16=0,0,M$16/$C$16*$D43*$C43) -> 3097.3142 | ... O43: =IF(O$16=0,0,O$16/$C$16*$D43*$C43) -> 3097.3142
...

Sheet Ремонты 
B3: ячейки к заполнению поставщиком | C3: ='Данные -Карьерный самосвал'!C3 -> Марка, модель | D3: ='Данные -Карьерный самосвал'!D3 -> 7531N
B4: Расчетный КТГ | F4: ='Данные -Карьерный самосвал'!E12 -> 0.93078341 | G4: ='Данные -Карьерный самосвал'!F12 -> 0.90792065 | H4: ='Данные -Карьерный самосвал'!G12 -> 0.89941186 | I4: ='Данные -Карьерный самосвал'!H12 -> 0.88050754 | J4: ='Данные -Карьерный самосвал'!I12 -> 0.90115061 | K4: ='Данные -Карьерный самосвал'!J12 -> 0.87025999 | L4: ='Данные -Карьерный самосвал'!K12 -> 0.85058935 | M4: ='Данные -Карьерный самосвал'!L12 -> 0.89171695 | ... O4: ='Данные -Карьерный самосвал'!N12 -> 0.85228054
B5: Год службы (год) | C5: Ед.изм. | F5: 1 год | G5: 2 год | H5: 3 год | I5: 4 год | J5: 5 год | K5: 6 год | L5: 7 год | M5: 8 год | N5: 9 год | O5: 10 год
B6: Наработка на начало года | C6: м/час | F6: 0 | G6: =F7+1 -> 7001 | H6: =G7+1 -> 14001 | I6: =H7+1 -> 21001 | J6: =I7+1 -> 28001 | K6: =J7+1 -> 35001 | L6: =K7+1 -> 42001 | M6: =L7+1 -> 49001 | N6: =M7+1 -> 56001 | O6: =N7+1 -> 63001
B7: Наработка на конец года | C7: м/час | F7: 7000 | G7: =F7+F7 -> 14000 | H7: =F7+G7 -> 21000 | I7: =H7+F7 -> 28000 | J7: =I7+$F$7 -> 35000 | K7: =J7+$F$7 -> 42000 | L7: =K7+$F$7 -> 49000 | M7: =L7+$F$7 -> 56000 | N7: =M7+$F$7 -> 63000 | O7: =N7+$F$7 -> 70000
B9: Простои в ремонтах | C9: часов | F9: =F17 -> 135 | G9: =G17 -> 341 | H9: =H17 -> 417.66667 | I9: =I17 -> 588 | J9: =J17 -> 402 | K9: =K17 -> 680.33333 | L9: =L17 -> 549 | M9: =M17 -> 487 | ... O9: =O17 -> 842.33333
B10: Затраты на ТО и ремонты | C10: $/год | F10: =SUM(F11:F13) -> 32561.22 | G10: =SUM(G11:G13) -> 121394.6 | H10: =SUM(H11:H13) -> 527818.87 | I10: =SUM(I11:I13) -> 823902.81 | J10: =SUM(J11:J13) -> 277045.96 | K10: =SUM(K11:K13) -> 549346.9 | L10: =SUM(L11:L13) -> 235842.4 | M10: =SUM(M11:M13) -> 884109.23 | ... O10: =SUM(O11:O13) -> 247535.77
B11: текущие ремонты | C11: $/год | F11: =F57 -> 15011.22 | G11: =G57 -> 77064.6 | H11: =H57 -> 50720.67 | I11: =I57 -> 89861 | J11: =J57 -> 60140.95 | K11: =K57 -> 102873.7 | L11: =L57 -> 80547.4 | M11: =M57 -> 64172.23 | ... O11: =O57 -> 90365.775
B12: планово-предупредительные (капитальные) ремонты | C12: $/год | F12: =F62 -> 0 | G12: =G62 -> 0 | H12: =H62 -> 410928.2 | I12: =I62 -> 652531.81 | J12: =J62 -> 158405.01 | K12: =K62 -> 339483.2 | L12: =L62 -> 71444.999 | M12: =M62 -> 721657 | ... O12: =O62 -> 0
B13: сервис (трудозатраты) | C13: $/год | F13: =SUMPRODUCT($E31:$E53,F$31:F$53) -> 17550 | G13: =SUMPRODUCT($E31:$E53,G$31:G$53) -> 44330 | H13: =SUMPRODUCT($E31:$E53,H$31:H$53) -> 66170 | I13: =SUMPRODUCT($E31:$E53,I$31:I$53) -> 81510 | J13: =SUMPRODUCT($E31:$E53,J$31:J$53) -> 58500 | K13: =SUMPRODUCT($E31:$E53,K$31:K$53) -> 106990 | L13: =SUMPRODUCT($E31:$E53,L$31:L$53) -> 83850 | M13: =SUMPRODUCT($E31:$E53,M$31:M$53) -> 98280 | ... O13: =SUMPRODUCT($E31:$E53,O$31:O$53) -> 157170
B15: Простои в ремонте (час)
B16: Вид ремонта | C16: Ед.изм. | F16: =F5 -> 1 год | G16: =G5 -> 2 год | H16: =H5 -> 3 год | I16: =I5 -> 4 год | J16: =J5 -> 5 год | K16: =K5 -> 6 год | L16: =L5 -> 7 год | M16: =M5 -> 8 год | ... O16: =O5 -> 10 год
B17: Всего простоев | F17: =SUM(F18:F26) -> 135 | G17: =SUM(G18:G26) -> 341 | H17: =SUM(H18:H26) -> 417.66667 | I17: =SUM(I18:I26) -> 588 | J17: =SUM(J18:J26) -> 402 | K17: =SUM(K18:K26) -> 680.33333 | L17: =SUM(L18:L26) -> 549 | M17: =SUM(M18:M26) -> 487 | ... O17: =SUM(O18:O26) -> 842.33333
B18: Аварийные ремонты | C18: часов | F18: =F31/2 -> 45 | G18: =G31/2 -> 72 | H18: =H31/2 -> 90 | I18: =I31/3 -> 90 | J18: =J31/3 -> 120 | K18: =K31/3 -> 150 | L18: =L31/3 -> 216 | M18: =M31/3 -> 270 | N18: =N31/3 -> 300 | O18: =O31/3 -> 733.33333
B19: ТР ДВС (10000 м/ч) | C19: часов | F19: =F32/2 -> 0 | G19: =G32/2 -> 19 | H19: =H32/2 -> 19 | I19: =I32/2 -> 0 | J19: =J32/2 -> 19 | K19: =K32/2 -> 19 | L19: =L32/2 -> 0 | M19: =M32/2 -> 19 | ... O19: =O32/2 -> 19
B20: БЕЛАЗ 7531N ТР-1 (6000 м/ч) | C20: часов | F20: =F33/2 -> 90 | G20: =G33/2 -> 90 | H20: =H33/2 -> 90 | I20: =I33/2 -> 90 | J20: =J33/2 -> 90 | K20: =K33/2 -> 180 | L20: =L33/2 -> 90 | M20: =M33/2 -> 90 | ... O20: =O33/2 -> 90
B21: БЕЛАЗ 7531N ТР-2 (12 000 м/ч) | C21: часов | F21: =F34/2 -> 0 | G21: =G34/2 -> 160 | H21: =H34/2 -> 0 | I21: =I34/2 -> 160 | J21: =J34/2 -> 0 | K21: =K34/2 -> 160 | L21: =L34/2 -> 160 | M21: =M34/2 -> 0 | ... O21: =O34/2 -> 0
B22: Двигатель кап.ремонт (25 000 м/ч) | C22: часов | E22: 1 | F22: =F35/2 -> 0 | G22: =G35/2 -> 0 | H22: =H35/2 -> 0 | I22: =I35/2 -> 140 | J22: =J35/2 -> 0 | K22: =K35/2 -> 0 | L22: =L35/2 -> 0 | M22: =M35/2 -> 0 | ... O22: =O35/2 -> 0
B23: Двигатель кап.ремонт (замена) | C23: часов | E23: 1 | F23: =F36/2 -> 0 | G23: =G36/2 -> 0 | H23: =H36/2 -> 0 | I23: =I38/2 -> 0 | J23: =J38/2 -> 12 | K23: =K38/2 -> 0 | L23: =L38/2 -> 12 | M23: =M38/2 -> 0 | N23: =N38/2 -> 12 | O23: =O38/2 -> 0
B24: Тяговый генератор | E24: 1 | F24: =F46/2 -> 0 | G24: =G46/2 -> 0 | H24: =H46/2 -> 0 | I24: =I46/2 -> 6 | J24: =J46/2 -> 0 | K24: =K46/2 -> 0 | L24: =L46/2 -> 0 | M24: =M46/2 -> 6 | ... O24: =O46/2 -> 0
B25: Тяговый мотор | C25: часов | E25: 2 | F25: =F47/2 -> 0 | G25: =G47/2 -> 0 | H25: =H47/2 -> 12 | I25: =I47/2 -> 0 | J25: =J47/2 -> 0 | K25: =K47/2 -> 12 | L25: =L47/2 -> 0 | M25: =M47/2 -> 0 | ... O25: =O47/2 -> 0
B26: Прочие ПР (КР) | C26: часов | F26: =(F41+F42+F44+F45+F48+F49+F50+F51+F52+F53+F43+F40+F39+F38+F37)/2 -> 0 | G26: =(G41+G42+G44+G45+G46+G47+G48+G49+G50+G51+G52+G53+G43+G40+G39+G38+G37)/2 -> 0 | H26: =(H41+H42+H44+H45+H46+H47+H48+H49+H50+H51+H52+H53+H43+H40+H39+H38+H37)/3 -> 206.66667 | I26: =(I41+I42+I44+I45+I46+I47+I48+I49+I50+I51+I52+I53+I43+I40+I39+I38+I37)/2 -> 102 | J26: =(J41+J42+J44+J45+J46+J47+J48+J49+J50+J51+J52+J53+J43+J40+J39+J38+J37)/2 -> 161 | K26: =(K41+K42+K44+K45+K46+K47+K48+K49+K50+K51+K52+K53+K43+K40+K39+K38+K37)/3 -> 159.33333 | L26: =(L41+L42+L44+L45+L46+L47+L48+L49+L50+L51+L52+L53+L43+L40+L39+L38+L37)/2 -> 71 | M26: =(M41+M42+M44+M45+M46+M47+M48+M49+M50+M51+M52+M53+M43+M40+M39+M38+M37)/2 -> 102 | N26: =(N41+N42+N44+N45+N46+N47+N48+N49+N50+N51+N52+N53+N43+N40+N39+N38+N37)/4 -> 200 | O26: =(O41+O42+O44+O45+O46+O47+O48+O49+O50+O51+O52+O53+O43+O40+O39+O38+O37)/2 -> 0
B28: Трудозатраты на ремонты (ч/час) | E28: =ТО!E10 -> 65
B29: Вид ремонта | C29: Ед.изм. | D29: Ресурс до замены / ремонта, м/ч | E29: Стоимость ч/часа | F29: =F16 -> 1 год | G29: =G16 -> 2 год | H29: =H16 -> 3 год | I29: =I16 -> 4 год | J29: =J16 -> 5 год | K29: =K16 -> 6 год | L29: =L16 -> 7 год | M29: =M16 -> 8 год | ... O29: =O16 -> 10 год
B30: Всего ч/часов* | C30: ч/часов | F30: =SUM(F31:F53) -> 270 | G30: =SUM(G31:G53) -> 682 | H30: =SUM(H31:H53) -> 1018 | I30: =SUM(I31:I53) -> 1254 | J30: =SUM(J31:J53) -> 900 | K30: =SUM(K31:K53) -> 1646 | L30: =SUM(L31:L53) -> 1290 | M30: =SUM(M31:M53) -> 1512 | ... O30: =SUM(O31:O53) -> 2418
B31: Аварийные ремонты | E31: =$E$28 -> 65 | F31: 90 | G31: 144 | H31: 180 | I31: 270 | J31: 360 | K31: 450 | L31: 648 | M31: 810 | N31: 900 | O31: 2200
B32: ТР ДВС (10000 м/ч) | C32: 38 | D32: =VLOOKUP(B32,$B$58:$D$86,3,FALSE) -> 10000 | E32: =$E$28 -> 65 | F32: 0 | G32: 38 | H32: 38 | I32: 0 | J32: 38 | K32: 38 | L32: 0 | M32: 38 | N32: 38 | O32: 38
B33: БЕЛАЗ 7531N ТР-1 (6000 м/ч) | C33: 180 | D33: =VLOOKUP(B33,$B$58:$D$86,3,FALSE) -> 6000 | E33: =$E$28 -> 65 | F33: 180 | G33: 180 | H33: 180 | I33: 180 | J33: 180 | K33: 360 | L33: 180 | M33: 180 | N33: 180 | O33: 180
B34: БЕЛАЗ 7531N ТР-2 (12 000 м/ч) | C34: 320 | D34: =VLOOKUP(B34,$B$58:$D$86,3,FALSE) -> 12000 | E34: =$E$28 -> 65 | F34: 0 | G34: 320 | H34: 0 | I34: 320 | J34: 0 | K34: 320 | L34: 320 | M34: 0 | N34: 320 | O34: 0
B35: Двигатель кап.ремонт (25 000 м/ч) | C35: 280 | D35: =VLOOKUP(B35,$B$58:$D$86,3,FALSE) -> 25000 | E35: =$E$28 -> 65 | F35: 0 | G35: 0 | H35: 0 | I35: 280 | J35: 0 | K35: 0 | L35: 0 | N35: 0 | O35: 0
B36: Двигатель кап.ремонт (замена) | C36: 280 | D36: =VLOOKUP(B36,$B$58:$D$86,3,FALSE) -> 50000 | E36: =$E$28 -> 65 | F36: 0 | G36: 0 | H36: 0 | I36: 0 | J36: 0 | K36: 0 | L36: 0 | M36: 280 | N36: 0 | O36: 0
B37: РМК | C37: =96*2 -> 192 | D37: =VLOOKUP(B37,$B$58:$D$86,3,FALSE) -> 20000 | E37: =$E$28 -> 65 | F37: 0 | G37: 0 | H37: 192 | I37: 0 | J37: 0 | K37: 192 | L37: 0 | M37: 0 | N37: 192 | O37: 0
B38: п.цилиндр. подвески | C38: 24 | D38: =VLOOKUP(B38,$B$58:$D$86,3,FALSE) -> 15000 | E38: =$E$28 -> 65 | F38: 0 | G38: 0 | H38: 24 | I38: 0 | J38: 24 | K38: 0 | L38: 24 | M38: 0 | N38: 24 | O38: 0
B39: з.цилиндр. подвески | C39: 22 | D39: =VLOOKUP(B39,$B$58:$D$86,3,FALSE) -> 15000 | E39: =$E$28 -> 65 | F39: 0 | G39: 0 | H39: 22 | I39: 0 | J39: 22 | K39: 0 | L39: 22 | M39: 0 | N39: 22 | O39: 0
B40: Передняя ось | C40: 120 | D40: =VLOOKUP(B40,$B$58:$D$86,3,FALSE) -> 30000 | E40: =$E$28 -> 65 | F40: 0 | G40: 0 | H40: 0 | I40: 0 | J40: 120 | K40: 0 | L40: 0 | M40: 0 | N40: 120 | O40: 0
B41: Рулевое управление | C41: 32 | D41: =VLOOKUP(B41,$B$58:$D$86,3,FALSE) -> 20000 | E41: =$E$28 -> 65 | F41: 0 | G41: 0 | H41: 32 | I41: 0 | J41: 0 | K41: 32 | L41: 0 | M41: 0 | N41: 32 | O41: 0
B42: ЦОМ | C42: =19*2 -> 38 | D42: =VLOOKUP(B42,$B$58:$D$86,3,FALSE) -> 20000 | E42: =$E$28 -> 65 | F42: 0 | G42: 0 | H42: 38 | I42: 0 | J42: 0 | K42: 38 | L42: 0 | M42: 0 | N42: 38 | O42: 0
B43: Кулак поворотный со ступицей | C43: =78*2 -> 156 | D43: =VLOOKUP(B43,$B$58:$D$86,3,FALSE) -> 20000 | E43: =$E$28 -> 65 | F43: 0 | G43: 0 | H43: 156 | I43: 0 | J43: 0 | K43: 156 | L43: 0 | M43: 0 | N43: 156 | O43: 0
B44: Корпус тормоза | C44: =8*12 -> 96 | D44: =VLOOKUP(B44,$B$58:$D$86,3,FALSE) -> 15000 | E44: =$E$28 -> 65 | F44: 0 | G44: 0 | H44: 96 | I44: 0 | J44: 96 | K44: 0 | L44: 96 | M44: 0 | N44: 96 | O44: 0
B45: Радиатор | C45: 18 | D45: =VLOOKUP(B45,$B$58:$D$86,3,FALSE) -> 20000 | E45: =$E$28 -> 65 | F45: 0 | G45: 0 | H45: 18 | I45: 0 | J45: 0 | K45: 18 | L45: 0 | M45: 0 | N45: 18 | O45: 0
...
