Workbook
Name __1_2003: #REF!
Name _1_2003: #REF!
Name _1Excel_BuiltIn_Print_Area_1_1: #REF!
Name _500_LD: #REF!
Name _ALT_: [1]EGATの実績!#REF!
Name _ID_: [1]EGATの実績!#REF!
Name _IDX_MK_OUTPUT_RAWDATA: '[2]FC_RawData (2)'!#REF!
Name _IDX_SQL_RAWDATA: [1]EGATの実績!#REF!
Name _INT_: [1]EGATの実績!#REF!
Name _LNS_MK_OUTPUT_RAWDATA: '[2]FC_RawData (2)'!#REF!
Name _LNS_SQL_RAWDATA: [1]EGATの実績!#REF!
Name _NID_: [1]EGATの実績!#REF!
Name _PWD_: [1]EGATの実績!#REF!
Name _REC_MK_OUTPUT_RAWDATA: '[2]FC_RawData (2)'!#REF!
Name _REC_SQL_RAWDATA: [1]EGATの実績!#REF!
Name _S201: #REF!
Name _S202: #REF!
Name _S203: #REF!
Name _S204: #REF!
Name _S205: #REF!
Name _S206: #REF!
Name _S301: #REF!
Name _S302: #REF!
Name _S303: #REF!
Name _S304: #REF!
Name _S305: #REF!
Name _S306: #REF!
Name _S307: #REF!
Name _S308: #REF!
Name _S309: #REF!
Name _S310: #REF!
Name _S311: #REF!
Name _S312: #REF!
Name _SDAY_: [1]EGATの実績!#REF!
Name _SID_: [1]EGATの実績!#REF!
Name _SMIN_: [1]EGATの実績!#REF!
Name a: #REF!
Name A_BeforeOutput: #REF!
Name AAA: #N/A
Name aadfasdfasdf: #REF!
Name ADEJAD: #REF!
Name adfha: #REF!
Name ADJADGJ: #REF!
Name afag: #REF!
Name AGAH: #REF!
Name AHDH: #REF!
Name ahmed: '[5]Ahmed prices'!$A$1:$C$7002
Name APLlist: [6]APLpriceOLD!$E$5:$E$2563
Name APRIL: [7]EQIPHR97!#REF!
Name asdfghashj: #REF!
Name asf: #REF!
Name ASH: #REF!
Name ASHAD: #REF!
Name AUG: [7]EQIPHR97!#REF!
Name AUGUST: [7]EQIPHR97!#REF!
Name Base_Capital: #REF!
Name Beg_Bal: #REF!
Name Centreline_クエリ1: #REF!
Name COOLANT: '[8]MARC Input & Summary'!$J$17
Name COPYRANGEP1: #REF!

Sheet Данные_Экскаватор
B2: ячейки к заполнению поставщиком
B3: Экскаватор | C3: Марка, модель | O3: Примечания
A4: 1 | B4: Период (год) | C4: Ед. изм. | D4: 0 | E4: =D4+1 -> 1 | F4: =E4+1 -> 2 | G4: =F4+1 -> 3 | H4: =G4+1 -> 4 | I4: =H4+1 -> 5 | J4: =I4+1 -> 6 | K4: =J4+1 -> 7 | L4: =K4+1 -> 8 | ... N4: =M4+1 -> 10
A5: =A4+1 -> 2 | B5: Геометрическая емкость ковша экскаватора | C5: м3 | D5: 9.5
A6: =A5+1 -> 3 | B6: Емкость ковша с шапкой | C6: м3 | D6: 12 | O6: ISO 7451 Heaped 1:1
A7: =A6+1 -> 4 | B7: КТГ при нормативной эксплуатации | E7: =(8760-E8-E9-E10)/8760 -> 0.94292237 | F7: =(8760-F8-F9-F10)/8760 -> 0.93315576 | G7: =(8760-G8-G9-G10)/8760 -> 0.90651953 | H7: =(8760-H8-H9-H10)/8760 -> 0.89564307 | I7: =(8760-I8-I9-I10)/8760 -> 0.94381025 | J7: =(8760-J8-J9-J10)/8760 -> 0.87167047 | K7: =(8760-K8-K9-K10)/8760 -> 0.89564307 | L7: =(8760-L8-L9-L10)/8760 -> 0.90651953 | ... N7: =(8760-N8-N9-N10)/8760 -> 0.92827245 | O7: Расчетный
A8: =A7+1 -> 5 | B8: простои на ТО | C8: час | E8: =ТО!G7 -> 124 | F8: =ТО!H7 -> 116 | G8: =ТО!I7 -> 116 | H8: =ТО!J7 -> 116 | I8: =ТО!K7 -> 116 | J8: =ТО!L7 -> 116 | K8: =ТО!M7 -> 116 | L8: =ТО!N7 -> 116 | ... N8: =ТО!P7 -> 116
A9: =A8+1 -> 6 | B9: простои в ремонтах | C9: час | E9: =Ремонты!F8 -> 140 | F9: =Ремонты!G8 -> 236 | G9: =Ремонты!H8 -> 476 | H9: =Ремонты!I8 -> 574 | I9: =Ремонты!J8 -> 140 | J9: =Ремонты!K8 -> 790 | K9: =Ремонты!L8 -> 574 | L9: =Ремонты!M8 -> 476 | ... N9: =Ремонты!O8 -> 280
A10: =A9+1 -> 7 | B10: ежесменный осмотр (20 минут в смену) | C10: час | E10: =(8760-E8-E9)/12*20/60 -> 236 | F10: =(8760-F8-F9)/12*20/60 -> 233.55556 | G10: =(8760-G8-G9)/12*20/60 -> 226.88889 | H10: =(8760-H8-H9)/12*20/60 -> 224.16667 | I10: =(8760-I8-I9)/12*20/60 -> 236.22222 | J10: =(8760-J8-J9)/12*20/60 -> 218.16667 | K10: =(8760-K8-K9)/12*20/60 -> 224.16667 | L10: =(8760-L8-L9)/12*20/60 -> 226.88889 | ... N10: =(8760-N8-N9)/12*20/60 -> 232.33333
A11: =A10+1 -> 8 | B11: Время цикла | C11: сек | D11: См.вкладку время цикла
A12: =A11+1 -> 9 | B12: Мощность двигателя | C12: л.с. | D12: 1000
A13: =A12+1 -> 10 | B13: Затраты на ТО и ремонты | C13: тыс.дол./год | E13: =SUM(E14:E18) -> 91.61822 | F13: =SUM(F14:F18) -> 185.75814 | G13: =SUM(G14:G18) -> 403.56284 | H13: =SUM(H14:H18) -> 747.64068 | I13: =SUM(I14:I18) -> 87.40084 | J13: =SUM(J14:J18) -> 1814.7169 | K13: =SUM(K14:K18) -> 747.64068 | L13: =SUM(L14:L18) -> 403.56284 | ... N13: =SUM(N14:N18) -> 93.00084
A14: =A13+1 -> 11 | B14: ТО, включая смазочные | C14: тыс.дол./год | E14: =ТО!G9/1000 -> 75.61822 | F14: =ТО!H9/1000 -> 72.04084 | G14: =ТО!I9/1000 -> 72.04084 | H14: =ТО!J9/1000 -> 72.04084 | I14: =ТО!K9/1000 -> 72.04084 | J14: =ТО!L9/1000 -> 72.04084 | K14: =ТО!M9/1000 -> 72.04084 | L14: =ТО!N9/1000 -> 72.04084 | ... N14: =ТО!P9/1000 -> 72.04084
A15: =A14+1 -> 12 | B15: текущие ремонты | C15: тыс.дол./год | E15: =Ремонты!F10/1000 -> 0 | F15: =Ремонты!G10/1000 -> 0 | G15: =Ремонты!H10/1000 -> 0 | H15: =Ремонты!I10/1000 -> 0 | I15: =Ремонты!J10/1000 -> 0 | J15: =Ремонты!K10/1000 -> 0 | K15: =Ремонты!L10/1000 -> 0 | L15: =Ремонты!M10/1000 -> 0 | ... N15: =Ремонты!O10/1000 -> 0
A16: =A15+1 -> 13 | B16: планово-предупредительные (капитальные) ремонты | C16: тыс.дол./год | E16: =Ремонты!F11/1000 -> 0 | F16: =Ремонты!G11/1000 -> 90.3573 | G16: =Ремонты!H11/1000 -> 299.882 | H16: =Ремонты!I11/1000 -> 628.23984 | I16: =Ремонты!J11/1000 -> 0 | J16: =Ремонты!K11/1000 -> 1639.8361 | K16: =Ремонты!L11/1000 -> 628.23984 | L16: =Ремонты!M11/1000 -> 299.882 | ... N16: =Ремонты!O11/1000 -> 0
A17: =A16+1 -> 14 | B17: сервис (трудозатраты) - ТО | C17: тыс.дол./год | E17: =ТО!G10/1000 -> 10.4 | F17: =ТО!H10/1000 -> 9.76 | G17: =ТО!I10/1000 -> 9.76 | H17: =ТО!J10/1000 -> 9.76 | I17: =ТО!K10/1000 -> 9.76 | J17: =ТО!L10/1000 -> 9.76 | K17: =ТО!M10/1000 -> 9.76 | L17: =ТО!N10/1000 -> 9.76 | ... N17: =ТО!P10/1000 -> 9.76
A18: =A17+1 -> 15 | B18: сервис (трудозатраты) - ремонты | C18: тыс.дол./год | E18: =Ремонты!F12/1000 -> 5.6 | F18: =Ремонты!G12/1000 -> 13.6 | G18: =Ремонты!H12/1000 -> 21.88 | H18: =Ремонты!I12/1000 -> 37.6 | I18: =Ремонты!J12/1000 -> 5.6 | J18: =Ремонты!K12/1000 -> 93.08 | K18: =Ремонты!L12/1000 -> 37.6 | L18: =Ремонты!M12/1000 -> 21.88 | ... N18: =Ремонты!O12/1000 -> 11.2
A19: =A18+1 -> 16 | B19: Расходные материалы: | O19: Здесь перечень приведен в качестве примера
A20: =A19+1 -> 17 | B20: канаты | O20: Указать нужные данные (здесь приведены - в качестве примера)
A21: =A20+1 -> 18 | B21: удельный расход | O21: Указать нужные данные (здесь приведены - в качестве примера)
A22: =A21+1 -> 19 | B22: цена за ед. | O22: Указать нужные данные (здесь приведены - в качестве примера)
A23: =A22+1 -> 20 | B23: кабели | O23: Указать нужные данные (здесь приведены - в качестве примера)
A24: =A23+1 -> 21 | B24: удельный расход | O24: Указать нужные данные (здесь приведены - в качестве примера)
A25: =A24+1 -> 22 | B25: цена за ед. | O25: Указать нужные данные (здесь приведены - в качестве примера)
A26: =A25+1 -> 23 | B26: зубья ковша | O26: Указать нужные данные (здесь приведены - в качестве примера)
A27: =A26+1 -> 24 | B27: удельный расход | O27: Указать нужные данные (здесь приведены - в качестве примера)
A28: =A27+1 -> 25 | B28: цена за ед. | O28: Указать нужные данные (здесь приведены - в качестве примера)
A29: =A28+1 -> 26 | B29: режущие кромки | O29: Указать нужные данные (здесь приведены - в качестве примера)
A30: =A29+1 -> 27 | B30: удельный расход | O30: Указать нужные данные (здесь приведены - в качестве примера)
... A34: =A33+1 -> 31 | B34: цена за ед. | O34: Указать нужные данные (здесь приведены - в качестве примера)
A35: =A34+1 -> 32 | B35: Электроэнергия / дизтопливо
A36: =A35+1 -> 33 | B36: удельный расход | C36: указать ед.изм. | D36: См.ниже
A37: =A36+1 -> 34 | B37: Сроки поставки | C37: мес

Sheet ТО
B2: ячейки к заполнению поставщиком
B3: Расчетный КТГ | G3: =Данные_Экскаватор!E7 -> 0.94292237 | H3: =Данные_Экскаватор!F7 -> 0.93315576 | I3: =Данные_Экскаватор!G7 -> 0.90651953 | J3: =Данные_Экскаватор!H7 -> 0.89564307 | K3: =Данные_Экскаватор!I7 -> 0.94381025 | L3: =Данные_Экскаватор!J7 -> 0.87167047 | M3: =Данные_Экскаватор!K7 -> 0.89564307 | N3: =Данные_Экскаватор!L7 -> 0.90651953 | ... P3: =Данные_Экскаватор!N7 -> 0.92827245
B4: Год службы (год) | C4: Ед. изм. | G4: =E4+1 -> 1 | H4: =G4+1 -> 2 | I4: =H4+1 -> 3 | J4: =I4+1 -> 4 | K4: =J4+1 -> 5 | L4: =K4+1 -> 6 | M4: =L4+1 -> 7 | N4: =M4+1 -> 8 | O4: =N4+1 -> 9 | P4: =O4+1 -> 10
B5: Наработка на начало года | C5: м/час | G5: 0 | H5: =G6+1 -> 7001 | I5: =H6+1 -> 14001 | J5: =I6+1 -> 21001 | K5: =J6+1 -> 28001 | L5: =K6+1 -> 35001 | M5: =L6+1 -> 42001 | N5: =M6+1 -> 49001 | O5: =N6+1 -> 56001 | P5: =O6+1 -> 63001
B6: Наработка на конец года | C6: м/час | F6: 7000 | G6: =F6 -> 7000 | H6: =G6+$F6 -> 14000 | I6: =H6+$F6 -> 21000 | J6: =I6+$F6 -> 28000 | K6: =J6+$F6 -> 35000 | L6: =K6+$F6 -> 42000 | M6: =L6+$F6 -> 49000 | N6: =M6+$F6 -> 56000 | O6: =N6+$F6 -> 63000 | P6: =O6+$F6 -> 70000
B7: длительность простоев на ТО | C7: часов | G7: =G13 -> 124 | H7: =H13 -> 116 | I7: =I13 -> 116 | J7: =J13 -> 116 | K7: =K13 -> 116 | L7: =L13 -> 116 | M7: =M13 -> 116 | N7: =N13 -> 116 | ... P7: =P13 -> 116
B8: Затраты на ТО | C8: долларов/год | G8: =SUM(G9:G10) -> 86018.22 | H8: =SUM(H9:H10) -> 81800.84 | I8: =SUM(I9:I10) -> 81800.84 | J8: =SUM(J9:J10) -> 81800.84 | K8: =SUM(K9:K10) -> 81800.84 | L8: =SUM(L9:L10) -> 81800.84 | M8: =SUM(M9:M10) -> 81800.84 | N8: =SUM(N9:N10) -> 81800.84 | ... P8: =SUM(P9:P10) -> 81800.84
B9: ТО, включая масла и смазки | C9: долларов/год | G9: =G22 -> 75618.22 | H9: =H22 -> 72040.84 | I9: =I22 -> 72040.84 | J9: =J22 -> 72040.84 | K9: =K22 -> 72040.84 | L9: =L22 -> 72040.84 | M9: =M22 -> 72040.84 | N9: =N22 -> 72040.84 | ... P9: =P22 -> 72040.84
B10: сервис (трудозатраты) на ТО | C10: долларов/год | F10: 40 | G10: =SUMPRODUCT(G14:G19,$F$14:$F$19)*$F10 -> 10400 | H10: =SUMPRODUCT(H14:H19,$F$14:$F$19)*$F10 -> 9760 | I10: =SUMPRODUCT(I14:I19,$F$14:$F$19)*$F10 -> 9760 | J10: =SUMPRODUCT(J14:J19,$F$14:$F$19)*$F10 -> 9760 | K10: =SUMPRODUCT(K14:K19,$F$14:$F$19)*$F10 -> 9760 | L10: =SUMPRODUCT(L14:L19,$F$14:$F$19)*$F10 -> 9760 | M10: =SUMPRODUCT(M14:M19,$F$14:$F$19)*$F10 -> 9760 | N10: =SUMPRODUCT(N14:N19,$F$14:$F$19)*$F10 -> 9760 | ... P10: =SUMPRODUCT(P14:P19,$F$14:$F$19)*$F10 -> 9760
B12: Простои оборудования на ТО | C12: Интервал ТО | D12: Длительность простоя на одном ТО, час | E12: Кол-во ТО в год | F12: Занято человек | G12: Простоев в год, час | H12: Простоев в год, час | I12: Простоев в год, час | J12: Простоев в год, час | K12: Простоев в год, час | L12: Простоев в год, час | M12: Простоев в год, час | N12: Простоев в год, час | O12: Простоев в год, час | P12: Простоев в год, час
B13: всего простоев на ТО, часов | G13: =SUM(G14:G19) -> 124 | H13: =SUM(H14:H19) -> 116 | I13: =SUM(I14:I19) -> 116 | J13: =SUM(J14:J19) -> 116 | K13: =SUM(K14:K19) -> 116 | L13: =SUM(L14:L19) -> 116 | M13: =SUM(M14:M19) -> 116 | N13: =SUM(N14:N19) -> 116 | ... P13: =SUM(P14:P19) -> 116
B14: ТО-0 | C14: 50 | D14: 8 | E14: 1 | F14: 2 | G14: =$E14*$D14 -> 8 | R14: формулы для примера, можно менять под необходимые параметры
B15: ТО-1 | C15: 250 | D15: 3 | E15: =$F$6/C15/2 -> 14 | F15: 2 | G15: =$E15*$D15 -> 42 | H15: =$E15*$D15 -> 42 | I15: =$E15*$D15 -> 42 | J15: =$E15*$D15 -> 42 | K15: =$E15*$D15 -> 42 | L15: =$E15*$D15 -> 42 | M15: =$E15*$D15 -> 42 | N15: =$E15*$D15 -> 42 | ... P15: =$E15*$D15 -> 42 | R15: формулы для примера, можно менять под необходимые параметры
B16: ТО-2 | C16: 500 | D16: 4 | E16: =$F$6/C16/2 -> 7 | F16: 2 | G16: =$E16*$D16 -> 28 | H16: =$E16*$D16 -> 28 | I16: =$E16*$D16 -> 28 | J16: =$E16*$D16 -> 28 | K16: =$E16*$D16 -> 28 | L16: =$E16*$D16 -> 28 | M16: =$E16*$D16 -> 28 | N16: =$E16*$D16 -> 28 | ... P16: =$E16*$D16 -> 28 | R16: формулы для примера, можно менять под необходимые параметры
B17: ТО-3 | C17: 1000 | D17: 5 | E17: 4 | F17: 2 | G17: =$E17*$D17 -> 20 | H17: =$E17*$D17 -> 20 | I17: =$E17*$D17 -> 20 | J17: =$E17*$D17 -> 20 | K17: =$E17*$D17 -> 20 | L17: =$E17*$D17 -> 20 | M17: =$E17*$D17 -> 20 | N17: =$E17*$D17 -> 20 | ... P17: =$E17*$D17 -> 20 | R17: формулы для примера, можно менять под необходимые параметры
B18: ТО-4 | C18: 2000 | D18: 7 | E18: 2 | F18: 2 | G18: =$E18*$D18 -> 14 | H18: =$E18*$D18 -> 14 | I18: =$E18*$D18 -> 14 | J18: =$E18*$D18 -> 14 | K18: =$E18*$D18 -> 14 | L18: =$E18*$D18 -> 14 | M18: =$E18*$D18 -> 14 | N18: =$E18*$D18 -> 14 | ... P18: =$E18*$D18 -> 14 | R18: формулы для примера, можно менять под необходимые параметры
B19: ТО-5 | C19: 4000 | D19: 12 | E19: 1 | F19: 3 | G19: =$E19*$D19 -> 12 | H19: =$D19 -> 12 | I19: =$E19*$D19 -> 12 | J19: =$D19 -> 12 | K19: =$E19*$D19 -> 12 | L19: =$D19 -> 12 | M19: =$D19 -> 12 | N19: =$E19*$D19 -> 12 | O19: =$D19 -> 12 | P19: =$E19*$D19 -> 12 | R19: формулы для примера, можно менять под необходимые параметры
B21: Затраты на ТО | C21: Каталожный номер | D21: стоимость за ед., $ | E21: Кол-во | F21: Кол-во ТО в год | G21: $ | H21: $ | I21: $ | J21: $ | K21: $ | L21: $ | M21: $ | N21: $ | O21: $ | P21: $
B22: ТО | G22: =SUM(G23:G81) -> 75618.22 | H22: =SUM(H23:H81) -> 72040.84 | I22: =SUM(I23:I81) -> 72040.84 | J22: =SUM(J23:J81) -> 72040.84 | K22: =SUM(K23:K81) -> 72040.84 | L22: =SUM(L23:L81) -> 72040.84 | M22: =SUM(M23:M81) -> 72040.84 | N22: =SUM(N23:N81) -> 72040.84 | ... P22: =SUM(P23:P81) -> 72040.84
B23: ТО-0 | E23: =VLOOKUP($B23,$B$14:$C$19,2,FALSE) -> 50 | F23: =VLOOKUP($B23,$B$14:$E$19,4,FALSE) -> 1
B24: фильтр | C24: шт. | D24: 49.42 | E24: 4 | G24: =IF(G$14=0,0,G$14/$D$14*$E24*$D24) -> 197.68 | H24: =IF(H$14=0,0,H$14/$D$14*$E24*$D24) -> 0 | I24: =IF(I$14=0,0,I$14/$D$14*$E24*$D24) -> 0 | J24: =IF(J$14=0,0,J$14/$D$14*$E24*$D24) -> 0 | K24: =IF(K$14=0,0,K$14/$D$14*$E24*$D24) -> 0 | L24: =IF(L$14=0,0,L$14/$D$14*$E24*$D24) -> 0 | M24: =IF(M$14=0,0,M$14/$D$14*$E24*$D24) -> 0 | N24: =IF(N$14=0,0,N$14/$D$14*$E24*$D24) -> 0 | ... P24: =IF(P$14=0,0,P$14/$D$14*$E24*$D24) -> 0
B25: фильтр | C25: шт. | D25: 119.36 | E25: 4 | G25: =IF(G$14=0,0,G$14/$D$14*$E25*$D25) -> 477.44 | H25: =IF(H$14=0,0,H$14/$D$14*$E25*$D25) -> 0 | I25: =IF(I$14=0,0,I$14/$D$14*$E25*$D25) -> 0 | J25: =IF(J$14=0,0,J$14/$D$14*$E25*$D25) -> 0 | K25: =IF(K$14=0,0,K$14/$D$14*$E25*$D25) -> 0 | L25: =IF(L$14=0,0,L$14/$D$14*$E25*$D25) -> 0 | M25: =IF(M$14=0,0,M$14/$D$14*$E25*$D25) -> 0 | N25: =IF(N$14=0,0,N$14/$D$14*$E25*$D25) -> 0 | ... P25: =IF(P$14=0,0,P$14/$D$14*$E25*$D25) -> 0
B26: фильтр | C26: шт. | D26: 128.92 | E26: 1 | G26: =IF(G$14=0,0,G$14/$D$14*$E26*$D26) -> 128.92 | H26: =IF(H$14=0,0,H$14/$D$14*$E26*$D26) -> 0 | I26: =IF(I$14=0,0,I$14/$D$14*$E26*$D26) -> 0 | J26: =IF(J$14=0,0,J$14/$D$14*$E26*$D26) -> 0 | K26: =IF(K$14=0,0,K$14/$D$14*$E26*$D26) -> 0 | L26: =IF(L$14=0,0,L$14/$D$14*$E26*$D26) -> 0 | M26: =IF(M$14=0,0,M$14/$D$14*$E26*$D26) -> 0 | N26: =IF(N$14=0,0,N$14/$D$14*$E26*$D26) -> 0 | ... P26: =IF(P$14=0,0,P$14/$D$14*$E26*$D26) -> 0
B27: фильтр | C27: шт. | D27: 172.25 | E27: 2 | G27: =IF(G$14=0,0,G$14/$D$14*$E27*$D27) -> 344.5 | H27: =IF(H$14=0,0,H$14/$D$14*$E27*$D27) -> 0 | I27: =IF(I$14=0,0,I$14/$D$14*$E27*$D27) -> 0 | J27: =IF(J$14=0,0,J$14/$D$14*$E27*$D27) -> 0 | K27: =IF(K$14=0,0,K$14/$D$14*$E27*$D27) -> 0 | L27: =IF(L$14=0,0,L$14/$D$14*$E27*$D27) -> 0 | M27: =IF(M$14=0,0,M$14/$D$14*$E27*$D27) -> 0 | N27: =IF(N$14=0,0,N$14/$D$14*$E27*$D27) -> 0 | ... P27: =IF(P$14=0,0,P$14/$D$14*$E27*$D27) -> 0
B28: масло | C28: л. | D28: 3.98 | E28: 158 | G28: =IF(G$14=0,0,G$14/$D$14*$E28*$D28) -> 628.84 | H28: =IF(H$14=0,0,H$14/$D$14*$E28*$D28) -> 0 | I28: =IF(I$14=0,0,I$14/$D$14*$E28*$D28) -> 0 | J28: =IF(J$14=0,0,J$14/$D$14*$E28*$D28) -> 0 | K28: =IF(K$14=0,0,K$14/$D$14*$E28*$D28) -> 0 | L28: =IF(L$14=0,0,L$14/$D$14*$E28*$D28) -> 0 | M28: =IF(M$14=0,0,M$14/$D$14*$E28*$D28) -> 0 | N28: =IF(N$14=0,0,N$14/$D$14*$E28*$D28) -> 0 | ... P28: =IF(P$14=0,0,P$14/$D$14*$E28*$D28) -> 0
B29: масло | C29: л. | D29: 3.6 | E29: 200 | G29: =IF(G$14=0,0,G$14/$D$14*$E29*$D29) -> 720 | H29: =IF(H$14=0,0,H$14/$D$14*$E29*$D29) -> 0 | I29: =IF(I$14=0,0,I$14/$D$14*$E29*$D29) -> 0 | J29: =IF(J$14=0,0,J$14/$D$14*$E29*$D29) -> 0 | K29: =IF(K$14=0,0,K$14/$D$14*$E29*$D29) -> 0 | L29: =IF(L$14=0,0,L$14/$D$14*$E29*$D29) -> 0 | M29: =IF(M$14=0,0,M$14/$D$14*$E29*$D29) -> 0 | N29: =IF(N$14=0,0,N$14/$D$14*$E29*$D29) -> 0 | ... P29: =IF(P$14=0,0,P$14/$D$14*$E29*$D29) -> 0
B30: смазка | C30: кг. | D30: 6 | E30: 180 | G30: =IF(G$14=0,0,G$14/$D$14*$E30*$D30) -> 1080 | H30: =IF(H$14=0,0,H$14/$D$14*$E30*$D30) -> 0 | I30: =IF(I$14=0,0,I$14/$D$14*$E30*$D30) -> 0 | J30: =IF(J$14=0,0,J$14/$D$14*$E30*$D30) -> 0 | K30: =IF(K$14=0,0,K$14/$D$14*$E30*$D30) -> 0 | L30: =IF(L$14=0,0,L$14/$D$14*$E30*$D30) -> 0 | M30: =IF(M$14=0,0,M$14/$D$14*$E30*$D30) -> 0 | N30: =IF(N$14=0,0,N$14/$D$14*$E30*$D30) -> 0 | ... P30: =IF(P$14=0,0,P$14/$D$14*$E30*$D30) -> 0
B31: ТО-1 | E31: =VLOOKUP($B31,$B$14:$C$19,2,FALSE) -> 250 | F31: =VLOOKUP($B31,$B$14:$E$19,4,FALSE) -> 14
B32: фильтр | C32: шт. | D32: 49.42 | E32: 4 | G32: =IF(G$15=0,0,G$15/$D$15*$E32*$D32) -> 2767.52 | H32: =IF(H$15=0,0,H$15/$D$15*$E32*$D32) -> 2767.52 | I32: =IF(I$15=0,0,I$15/$D$15*$E32*$D32) -> 2767.52 | J32: =IF(J$15=0,0,J$15/$D$15*$E32*$D32) -> 2767.52 | K32: =IF(K$15=0,0,K$15/$D$15*$E32*$D32) -> 2767.52 | L32: =IF(L$15=0,0,L$15/$D$15*$E32*$D32) -> 2767.52 | M32: =IF(M$15=0,0,M$15/$D$15*$E32*$D32) -> 2767.52 | N32: =IF(N$15=0,0,N$15/$D$15*$E32*$D32) -> 2767.52 | ... P32: =IF(P$15=0,0,P$15/$D$15*$E32*$D32) -> 2767.52
B33: масло | C33: л. | D33: 3.98 | E33: 132 | G33: =IF(G$15=0,0,G$15/$D$15*$E33*$D33) -> 7355.04 | H33: =IF(H$15=0,0,H$15/$D$15*$E33*$D33) -> 7355.04 | I33: =IF(I$15=0,0,I$15/$D$15*$E33*$D33) -> 7355.04 | J33: =IF(J$15=0,0,J$15/$D$15*$E33*$D33) -> 7355.04 | K33: =IF(K$15=0,0,K$15/$D$15*$E33*$D33) -> 7355.04 | L33: =IF(L$15=0,0,L$15/$D$15*$E33*$D33) -> 7355.04 | M33: =IF(M$15=0,0,M$15/$D$15*$E33*$D33) -> 7355.04 | N33: =IF(N$15=0,0,N$15/$D$15*$E33*$D33) -> 7355.04 | ... P33: =IF(P$15=0,0,P$15/$D$15*$E33*$D33) -> 7355.04
B34: смазка | C34: кг. | D34: 6 | E34: 180 | G34: =IF(G$16=0,0,G$16/$D$16*$E34*$D34) -> 7560 | H34: =IF(H$16=0,0,H$16/$D$16*$E34*$D34) -> 7560 | I34: =IF(I$16=0,0,I$16/$D$16*$E34*$D34) -> 7560 | J34: =IF(J$16=0,0,J$16/$D$16*$E34*$D34) -> 7560 | K34: =IF(K$16=0,0,K$16/$D$16*$E34*$D34) -> 7560 | L34: =IF(L$16=0,0,L$16/$D$16*$E34*$D34) -> 7560 | M34: =IF(M$16=0,0,M$16/$D$16*$E34*$D34) -> 7560 | N34: =IF(N$16=0,0,N$16/$D$16*$E34*$D34) -> 7560 | ... P34: =IF(P$16=0,0,P$16/$D$16*$E34*$D34) -> 7560
B35: ТО-2 | E35: =VLOOKUP($B35,$B$14:$C$19,2,FALSE) -> 500 | F35: =VLOOKUP($B35,$B$14:$E$19,4,FALSE) -> 7
B36: фильтр | C36: шт. | D36: 49.42 | E36: 4 | G36: =IF(G$16=0,0,G$16/$D$16*$E36*$D36) -> 1383.76 | H36: =IF(H$16=0,0,H$16/$D$16*$E36*$D36) -> 1383.76 | I36: =IF(I$16=0,0,I$16/$D$16*$E36*$D36) -> 1383.76 | J36: =IF(J$16=0,0,J$16/$D$16*$E36*$D36) -> 1383.76 | K36: =IF(K$16=0,0,K$16/$D$16*$E36*$D36) -> 1383.76 | L36: =IF(L$16=0,0,L$16/$D$16*$E36*$D36) -> 1383.76 | M36: =IF(M$16=0,0,M$16/$D$16*$E36*$D36) -> 1383.76 | N36: =IF(N$16=0,0,N$16/$D$16*$E36*$D36) -> 1383.76 | ... P36: =IF(P$16=0,0,P$16/$D$16*$E36*$D36) -> 1383.76
B37: фильтр | C37: шт. | D37: 64.88 | E37: 1 | G37: =IF(G$16=0,0,G$16/$D$16*$E37*$D37) -> 454.16 | H37: =IF(H$16=0,0,H$16/$D$16*$E37*$D37) -> 454.16 | I37: =IF(I$16=0,0,I$16/$D$16*$E37*$D37) -> 454.16 | J37: =IF(J$16=0,0,J$16/$D$16*$E37*$D37) -> 454.16 | K37: =IF(K$16=0,0,K$16/$D$16*$E37*$D37) -> 454.16 | L37: =IF(L$16=0,0,L$16/$D$16*$E37*$D37) -> 454.16 | M37: =IF(M$16=0,0,M$16/$D$16*$E37*$D37) -> 454.16 | N37: =IF(N$16=0,0,N$16/$D$16*$E37*$D37) -> 454.16 | ... P37: =IF(P$16=0,0,P$16/$D$16*$E37*$D37) -> 454.16
B38: фильтр | C38: шт. | D38: 349.37 | E38: 1 | G38: =IF(G$16=0,0,G$16/$D$16*$E38*$D38) -> 2445.59 | H38: =IF(H$16=0,0,H$16/$D$16*$E38*$D38) -> 2445.59 | I38: =IF(I$16=0,0,I$16/$D$16*$E38*$D38) -> 2445.59 | J38: =IF(J$16=0,0,J$16/$D$16*$E38*$D38) -> 2445.59 | K38: =IF(K$16=0,0,K$16/$D$16*$E38*$D38) -> 2445.59 | L38: =IF(L$16=0,0,L$16/$D$16*$E38*$D38) -> 2445.59 | M38: =IF(M$16=0,0,M$16/$D$16*$E38*$D38) -> 2445.59 | N38: =IF(N$16=0,0,N$16/$D$16*$E38*$D38) -> 2445.59 | ... P38: =IF(P$16=0,0,P$16/$D$16*$E38*$D38) -> 2445.59
B39: фильтр | C39: шт. | D39: 28.57 | E39: 1 | G39: =IF(G$16=0,0,G$16/$D$16*$E39*$D39) -> 199.99 | H39: =IF(H$16=0,0,H$16/$D$16*$E39*$D39) -> 199.99 | I39: =IF(I$16=0,0,I$16/$D$16*$E39*$D39) -> 199.99 | J39: =IF(J$16=0,0,J$16/$D$16*$E39*$D39) -> 199.99 | K39: =IF(K$16=0,0,K$16/$D$16*$E39*$D39) -> 199.99 | L39: =IF(L$16=0,0,L$16/$D$16*$E39*$D39) -> 199.99 | M39: =IF(M$16=0,0,M$16/$D$16*$E39*$D39) -> 199.99 | N39: =IF(N$16=0,0,N$16/$D$16*$E39*$D39) -> 199.99 | ... P39: =IF(P$16=0,0,P$16/$D$16*$E39*$D39) -> 199.99
B40: фильтр | C40: шт. | D40: 57.56 | E40: 1 | G40: =IF(G$16=0,0,G$16/$D$16*$E40*$D40) -> 402.92 | H40: =IF(H$16=0,0,H$16/$D$16*$E40*$D40) -> 402.92 | I40: =IF(I$16=0,0,I$16/$D$16*$E40*$D40) -> 402.92 | J40: =IF(J$16=0,0,J$16/$D$16*$E40*$D40) -> 402.92 | K40: =IF(K$16=0,0,K$16/$D$16*$E40*$D40) -> 402.92 | L40: =IF(L$16=0,0,L$16/$D$16*$E40*$D40) -> 402.92 | M40: =IF(M$16=0,0,M$16/$D$16*$E40*$D40) -> 402.92 | N40: =IF(N$16=0,0,N$16/$D$16*$E40*$D40) -> 402.92 | ... P40: =IF(P$16=0,0,P$16/$D$16*$E40*$D40) -> 402.92
B41: фильтр | C41: шт. | D41: 128.92 | E41: 1 | G41: =IF(G$16=0,0,G$16/$D$16*$E41*$D41) -> 902.44 | H41: =IF(H$16=0,0,H$16/$D$16*$E41*$D41) -> 902.44 | I41: =IF(I$16=0,0,I$16/$D$16*$E41*$D41) -> 902.44 | J41: =IF(J$16=0,0,J$16/$D$16*$E41*$D41) -> 902.44 | K41: =IF(K$16=0,0,K$16/$D$16*$E41*$D41) -> 902.44 | L41: =IF(L$16=0,0,L$16/$D$16*$E41*$D41) -> 902.44 | M41: =IF(M$16=0,0,M$16/$D$16*$E41*$D41) -> 902.44 | N41: =IF(N$16=0,0,N$16/$D$16*$E41*$D41) -> 902.44 | ... P41: =IF(P$16=0,0,P$16/$D$16*$E41*$D41) -> 902.44
B42: фильтр | C42: шт. | D42: 263.82 | E42: 1 | G42: =IF(G$16=0,0,G$16/$D$16*$E42*$D42) -> 1846.74 | H42: =IF(H$16=0,0,H$16/$D$16*$E42*$D42) -> 1846.74 | I42: =IF(I$16=0,0,I$16/$D$16*$E42*$D42) -> 1846.74 | J42: =IF(J$16=0,0,J$16/$D$16*$E42*$D42) -> 1846.74 | K42: =IF(K$16=0,0,K$16/$D$16*$E42*$D42) -> 1846.74 | L42: =IF(L$16=0,0,L$16/$D$16*$E42*$D42) -> 1846.74 | M42: =IF(M$16=0,0,M$16/$D$16*$E42*$D42) -> 1846.74 | N42: =IF(N$16=0,0,N$16/$D$16*$E42*$D42) -> 1846.74 | ... P42: =IF(P$16=0,0,P$16/$D$16*$E42*$D42) -> 1846.74
B43: фильтр | C43: шт. | D43: 96.92 | E43: 1 | G43: =IF(G$16=0,0,G$16/$D$16*$E43*$D43) -> 678.44 | H43: =IF(H$16=0,0,H$16/$D$16*$E43*$D43) -> 678.44 | I43: =IF(I$16=0,0,I$16/$D$16*$E43*$D43) -> 678.44 | J43: =IF(J$16=0,0,J$16/$D$16*$E43*$D43) -> 678.44 | K43: =IF(K$16=0,0,K$16/$D$16*$E43*$D43) -> 678.44 | L43: =IF(L$16=0,0,L$16/$D$16*$E43*$D43) -> 678.44 | M43: =IF(M$16=0,0,M$16/$D$16*$E43*$D43) -> 678.44 | N43: =IF(N$16=0,0,N$16/$D$16*$E43*$D43) -> 678.44 | ... P43: =IF(P$16=0,0,P$16/$D$16*$E43*$D43) -> 678.44
...

Sheet Ремонты
B2: ячейки к заполнению поставщиком
B3: Расчетный КТГ | F3: =Данные_Экскаватор!E7 -> 0.94292237 | G3: =Данные_Экскаватор!F7 -> 0.93315576 | H3: =Данные_Экскаватор!G7 -> 0.90651953 | I3: =Данные_Экскаватор!H7 -> 0.89564307 | J3: =Данные_Экскаватор!I7 -> 0.94381025 | K3: =Данные_Экскаватор!J7 -> 0.87167047 | L3: =Данные_Экскаватор!K7 -> 0.89564307 | M3: =Данные_Экскаватор!L7 -> 0.90651953 | ... O3: =Данные_Экскаватор!N7 -> 0.92827245
B4: Год службы (год) | C4: Ед.изм. | F4: 1 | G4: =F4+1 -> 2 | H4: =G4+1 -> 3 | I4: =H4+1 -> 4 | J4: =I4+1 -> 5 | K4: =J4+1 -> 6 | L4: =K4+1 -> 7 | M4: =L4+1 -> 8 | N4: =M4+1 -> 9 | O4: =N4+1 -> 10
B5: Наработка на начало года | C5: м/час | F5: 0 | G5: =F6+1 -> 7001 | H5: =G6+1 -> 14001 | I5: =H6+1 -> 21001 | J5: =I6+1 -> 28001 | K5: =J6+1 -> 35001 | L5: =K6+1 -> 42001 | M5: =L6+1 -> 49001 | N5: =M6+1 -> 56001 | O5: =N6+1 -> 63001
B6: Наработка на конец года | C6: м/час | E6: =ТО!F6 -> 7000 | F6: =E6 -> 7000 | G6: =F6+$E6 -> 14000 | H6: =G6+$E6 -> 21000 | I6: =H6+$E6 -> 28000 | J6: =I6+$E6 -> 35000 | K6: =J6+$E6 -> 42000 | L6: =K6+$E6 -> 49000 | M6: =L6+$E6 -> 56000 | N6: =M6+$E6 -> 63000 | O6: =N6+$E6 -> 70000
B8: Простои в ремонтах | C8: часов | F8: =F16 -> 140 | G8: =G16 -> 236 | H8: =H16 -> 476 | I8: =I16 -> 574 | J8: =J16 -> 140 | K8: =K16 -> 790 | L8: =L16 -> 574 | M8: =M16 -> 476 | ... O8: =O16 -> 280
B9: Затраты на ТО и ремонты | C9: $/год | F9: =SUM(F10:F12) -> 5600 | G9: =SUM(G10:G12) -> 103957.3 | H9: =SUM(H10:H12) -> 321762 | I9: =SUM(I10:I12) -> 665839.84 | J9: =SUM(J10:J12) -> 5600 | K9: =SUM(K10:K12) -> 1732916.1 | L9: =SUM(L10:L12) -> 665839.84 | M9: =SUM(M10:M12) -> 321762 | ... O9: =SUM(O10:O12) -> 11200
B10: текущие ремонты | C10: $/год | F10: =F34 -> 0 | G10: =G34 -> 0 | H10: =H34 -> 0 | I10: =I34 -> 0 | J10: =J34 -> 0 | K10: =K34 -> 0 | L10: =L34 -> 0 | M10: =M34 -> 0 | ... O10: =O34 -> 0
B11: планово-предупредительные (капитальные) ремонты | C11: $/год | F11: =F40 -> 0 | G11: =G40 -> 90357.3 | H11: =H40 -> 299882 | I11: =I40 -> 628239.84 | J11: =J40 -> 0 | K11: =K40 -> 1639836.1 | L11: =L40 -> 628239.84 | M11: =M40 -> 299882 | ... O11: =O40 -> 0
B12: сервис (трудозатраты) | C12: $/год | F12: =SUMPRODUCT($D26:$D30,F$26:F$30) -> 5600 | G12: =SUMPRODUCT($D26:$D30,G$26:G$30) -> 13600 | H12: =SUMPRODUCT($D26:$D30,H$26:H$30) -> 21880 | I12: =SUMPRODUCT($D26:$D30,I$26:I$30) -> 37600 | J12: =SUMPRODUCT($D26:$D30,J$26:J$30) -> 5600 | K12: =SUMPRODUCT($D26:$D30,K$26:K$30) -> 93080 | L12: =SUMPRODUCT($D26:$D30,L$26:L$30) -> 37600 | M12: =SUMPRODUCT($D26:$D30,M$26:M$30) -> 21880 | ... O12: =SUMPRODUCT($D26:$D30,O$26:O$30) -> 11200
B14: Простои в ремонте (час)
B15: Вид ремонта | C15: Ед.изм. | F15: =F4 -> 1 | G15: =G4 -> 2 | H15: =H4 -> 3 | I15: =I4 -> 4 | J15: =J4 -> 5 | K15: =K4 -> 6 | L15: =L4 -> 7 | M15: =M4 -> 8 | ... O15: =O4 -> 10
B16: Всего простоев | F16: =SUM(F17:F21) -> 140 | G16: =SUM(G17:G21) -> 236 | H16: =SUM(H17:H21) -> 476 | I16: =SUM(I17:I21) -> 574 | J16: =SUM(J17:J21) -> 140 | K16: =SUM(K17:K21) -> 790 | L16: =SUM(L17:L21) -> 574 | M16: =SUM(M17:M21) -> 476 | ... O16: =SUM(O17:O21) -> 280
B17: ППР 12000 | C17: часов | G17: 96 | I17: 72 | K17: 72 | L17: 72 | N17: 72
B18: ППР 18000 | C18: часов | H18: 336 | K18: 336 | M18: 336
B19: ППР 24000 | C19: часов | I19: 432 | L19: 432
B20: ППР 36000 | C20: часов | K20: 312
B21: Непредвиденне простои | C21: часов | F21: 140 | G21: 140 | H21: 140 | I21: 70 | J21: 140 | K21: 70 | L21: 70 | M21: 140 | N21: 200 | O21: 280
B23: Трудозатраты на ремонты (ч/час) | D23: =ТО!F10 -> 40
B24: Вид ремонта | C24: Ед.изм. | D24: Стоимость ч/часа | F24: =F15 -> 1 | G24: =G15 -> 2 | H24: =H15 -> 3 | I24: =I15 -> 4 | J24: =J15 -> 5 | K24: =K15 -> 6 | L24: =L15 -> 7 | M24: =M15 -> 8 | ... O24: =O15 -> 10
B25: Всего ч/часов | C25: ч/часов | F25: =SUM(F26:F30) -> 140 | G25: =SUM(G26:G30) -> 340 | H25: =SUM(H26:H30) -> 547 | I25: =SUM(I26:I30) -> 940 | J25: =SUM(J26:J30) -> 140 | K25: =SUM(K26:K30) -> 2327 | L25: =SUM(L26:L30) -> 940 | M25: =SUM(M26:M30) -> 547 | ... O25: =SUM(O26:O30) -> 280
B26: ППР 12000 | C26: ч/часов | D26: =$D$23 -> 40 | G26: 200 | I26: 200 | K26: 200 | L26: 200 | N26: 200
B27: ППР 18000 | C27: ч/часов | D27: =$D$23 -> 40 | H27: 407 | K27: 407 | M27: 407
B28: ППР 24000 | C28: ч/часов | D28: =$D$23 -> 40 | I28: 670 | L28: 670
B29: ППР 36000 | C29: ч/часов | D29: =$D$23 -> 40 | K29: 1650
B30: Непредвиденные простои | C30: ч/часов | D30: =$D$23 -> 40 | F30: 140 | G30: 140 | H30: 140 | I30: 70 | J30: 140 | K30: 70 | L30: 70 | M30: 140 | N30: 200 | O30: 280
B32: Затраты на ремонты ($)
B33: Детализация затрат | C33: Стоимость за ед., $ | D33: Ресурс до замены / ремонта, м/ч | E33: Кол-во МТР | F33: $ | G33: $ | H33: $ | I33: $ | J33: $ | K33: $ | L33: $ | M33: $ | N33: $ | O33: $
B34: Текущие ремонты (если планируются) | F34: =SUM(F35:F39) -> 0 | G34: =SUM(G35:G39) -> 0 | H34: =SUM(H35:H39) -> 0 | I34: =SUM(I35:I39) -> 0 | J34: =SUM(J35:J39) -> 0 | K34: =SUM(K35:K39) -> 0 | L34: =SUM(L35:L39) -> 0 | M34: =SUM(M35:M39) -> 0 | ... O34: =SUM(O35:O39) -> 0
B35: текущий ремонт (ходовая часть) | F35: =$E35*$C35 -> 0 | G35: =$E35*$C35 -> 0 | H35: =$E35*$C35 -> 0 | I35: =$E35*$C35 -> 0 | J35: =$E35*$C35 -> 0 | K35: =$E35*$C35 -> 0 | L35: =$E35*$C35 -> 0 | M35: =$E35*$C35 -> 0 | ... O35: =$E35*$C35 -> 0
B36: текущий ремонт (рабочее оборудование) | F36: =$E36*$C36 -> 0 | G36: =$E36*$C36 -> 0 | H36: =$E36*$C36 -> 0 | I36: =$E36*$C36 -> 0 | J36: =$E36*$C36 -> 0 | K36: =$E36*$C36 -> 0 | L36: =$E36*$C36 -> 0 | M36: =$E36*$C36 -> 0 | ... O36: =$E36*$C36 -> 0
B37: другое | F37: =$E37*$C37 -> 0 | G37: =$E37*$C37 -> 0 | H37: =$E37*$C37 -> 0 | I37: =$E37*$C37 -> 0 | J37: =$E37*$C37 -> 0 | K37: =$E37*$C37 -> 0 | L37: =$E37*$C37 -> 0 | M37: =$E37*$C37 -> 0 | ... O37: =$E37*$C37 -> 0
B38: другое | F38: =$E38*$C38 -> 0 | G38: =$E38*$C38 -> 0 | H38: =$E38*$C38 -> 0 | I38: =$E38*$C38 -> 0 | J38: =$E38*$C38 -> 0 | K38: =$E38*$C38 -> 0 | L38: =$E38*$C38 -> 0 | M38: =$E38*$C38 -> 0 | ... O38: =$E38*$C38 -> 0
B39: другое | F39: =$E39*$C39 -> 0 | G39: =$E39*$C39 -> 0 | H39: =$E39*$C39 -> 0 | I39: =$E39*$C39 -> 0 | J39: =$E39*$C39 -> 0 | K39: =$E39*$C39 -> 0 | L39: =$E39*$C39 -> 0 | M39: =$E39*$C39 -> 0 | ... O39: =$E39*$C39 -> 0
B40: планово-предупредительные (капитальные) ремонты | F40: =SUM(F41:F72) -> 0 | G40: =SUM(G41:G72) -> 90357.3 | H40: =SUM(H41:H72) -> 299882 | I40: =SUM(I41:I72) -> 628239.84 | J40: =SUM(J41:J72) -> 0 | K40: =SUM(K41:K72) -> 1639836.1 | L40: =SUM(L41:L72) -> 628239.84 | M40: =SUM(M41:M72) -> 299882 | ... O40: =SUM(O41:O72) -> 0
B41: ППР 12000
B42: Система смазки | C42: 13827.3 | D42: 12000 | E42: 1 | G42: =$C42*$E42 -> 13827.3 | I42: =$C42*$E42 -> 13827.3 | K42: =$C42*$E42 -> 13827.3 | L42: =$C42*$E42 -> 13827.3 | N42: =$C42*$E42 -> 13827.3
B43: Пальцы-втулки в районе ковша | C43: 58770 | D43: 12000 | E43: 1 | G43: =$C43*$E43 -> 58770 | I43: =$C43*$E43 -> 58770 | K43: =$C43*$E43 -> 58770 | L43: =$C43*$E43 -> 58770 | N43: =$C43*$E43 -> 58770
B44: АКБ | C44: 1400 | D44: 12000 | E44: 4 | G44: =$C44*$E44 -> 5600 | I44: =$C44*$E44 -> 5600 | K44: =$C44*$E44 -> 5600 | L44: =$C44*$E44 -> 5600 | N44: =$C44*$E44 -> 5600
B45: Джойстики управления | C45: 6080 | D45: 12000 | E45: 2 | G45: =$C45*$E45 -> 12160 | I45: =$C45*$E45 -> 12160 | K45: =$C45*$E45 -> 12160 | L45: =$C45*$E45 -> 12160 | N45: =$C45*$E45 -> 12160
...

Sheet Время цикла
