Workbook

Sheet Данные-самосвал NHL NTE240
B2: ячейки к заполнению поставщиком
B3: Карьерный автосамосвал | C3: Марка, модель | Y3: Примечания
A4: 1 | B4: Период | C4: Ед. изм. | D4: 0 | E4: =D4+1 -> 1 | F4: =E4+1 -> 2 | G4: =F4+1 -> 3 | H4: =G4+1 -> 4 | I4: =H4+1 -> 5 | J4: =I4+1 -> 6 | K4: =J4+1 -> 7 | L4: =K4+1 -> 8 | ... P4: =O4+1 -> 12 | Q4: 13 | R4: 14 | S4: 15 | T4: 16 | U4: 17 | V4: 18 | W4: 19 | X4: 20 | Y4: Учесть срок эксплуатации (в данном примере это 20 лет)
A5: =A4+1 -> 2 | B5: Габариты машины
A6: =A5+1 -> 3 | B6: Эксплуатационная ширина (по зеркалам) | C6: мм | D6: 8500 | E6: =D6 -> 8500 | F6: =E6 -> 8500 | G6: =F6 -> 8500 | H6: =G6 -> 8500 | I6: =H6 -> 8500 | J6: =I6 -> 8500 | K6: =J6 -> 8500 | L6: =K6 -> 8500 | ... X6: =W6 -> 8500 | Y6: Ширина по зеркалам
A7: =A6+1 -> 4 | B7: Высота по переднему козырьку | C7: мм | D7: 7300 | E7: =D7 -> 7300 | F7: =E7 -> 7300 | G7: =F7 -> 7300 | H7: =G7 -> 7300 | I7: =H7 -> 7300 | J7: =I7 -> 7300 | K7: =J7 -> 7300 | L7: =K7 -> 7300 | ... X7: =W7 -> 7300 | Y7: Высота по козырьку кузова
A8: =A7+1 -> 5 | B8: Габаритная длина | C8: мм | D8: 15600 | E8: =D8 -> 15600 | F8: =E8 -> 15600 | G8: =F8 -> 15600 | H8: =G8 -> 15600 | I8: =H8 -> 15600 | J8: =I8 -> 15600 | K8: =J8 -> 15600 | L8: =K8 -> 15600 | ... X8: =W8 -> 15600 | Y8: Длина с учетом переднего бампера с лестницей
A9: =A8+1 -> 6 | B9: Грузоподъемность | C9: тн | D9: 236 | E9: 236 | F9: 236 | G9: 236 | H9: 236 | I9: 236 | J9: 236 | K9: 236 | L9: 236 | M9: 236 | N9: 236 | O9: 236 | P9: 236 | Q9: 236 | R9: 236 | S9: 236 | T9: 236 | U9: 236 | V9: 236 | W9: 236 | X9: 236 | Y9: Номинальная грузоподъёмность
A10: =A9+1 -> 7 | B10: Геометрические параметры кузова (конфигурация, размеры) | C10: м³ | D10: 140 | E10: =D10 -> 140 | F10: =E10 -> 140 | G10: =F10 -> 140 | H10: =G10 -> 140 | I10: =H10 -> 140 | J10: =I10 -> 140 | K10: =J10 -> 140 | L10: =K10 -> 140 | ... X10: =W10 -> 140 | Y10: Стандартный кузов, SAE 2:1
A11: =A10+1 -> 8 | B11: Мощность двигателя | C11: л.с. | D11: 2500 | E11: 2500 | F11: 2500 | G11: 2500 | H11: 2500 | I11: 2500 | J11: 2500 | K11: 2500 | L11: 2500 | M11: 2500 | N11: 2500 | O11: 2500 | P11: 2500 | Q11: 2500 | R11: 2500 | S11: 2500 | T11: 2500 | U11: 2500 | V11: 2500 | W11: 2500 | X11: 2500 | Y11: Указана максимальная мощность двигателя
A12: =A11+1 -> 9 | B12: КТГ | E12: =(8760-E13-E14-E15)/8760 -> 0.93755029 | F12: =(8760-F13-F14-F15)/8760 -> 0.93038071 | G12: =(8760-G13-G14-G15)/8760 -> 0.92090265 | H12: =(8760-H13-H14-H15)/8760 -> 0.90840582 | I12: =(8760-I13-I14-I15)/8760 -> 0.93333289 | J12: =(8760-J13-J14-J15)/8760 -> 0.92172393 | K12: =(8760-K13-K14-K15)/8760 -> 0.93126858 | L12: =(8760-L13-L14-L15)/8760 -> 0.91113604 | ... X12: =(8760-X13-X14-X15)/8760 -> 0.92201249
A13: =A12+1 -> 10 | B13: простои на ТО | C13: час | E13: =ТО!G7 -> 173.404 | F13: =ТО!H7 -> 202.004 | G13: =ТО!I7 -> 173.404 | H13: =ТО!J7 -> 202.004 | I13: =ТО!K7 -> 173.404 | J13: =ТО!L7 -> 202.004 | K13: =ТО!M7 -> 202.004 | L13: =ТО!N7 -> 173.404 | ... X13: =ТО!Z7 -> 197.404
A14: =A13+1 -> 11 | B14: простои в ремонтах | C14: час | E14: =Ремонты!G8 -> 139 | F14: =Ремонты!H8 -> 175 | G14: =Ремонты!I8 -> 289 | H14: =Ремонты!J8 -> 373 | I14: =Ремонты!K8 -> 177 | J14: =Ремонты!L8 -> 253 | K14: =Ремонты!M8 -> 167 | L14: =Ремонты!N8 -> 377 | ... X14: =Ремонты!Z8 -> 255
A15: =A14+1 -> 12 | B15: ежесменный осмотр (20 минут в смену) | C15: час | E15: =(8760-E13-E14)/12*20/60 -> 234.65544 | F15: =(8760-F13-F14)/12*20/60 -> 232.861 | G15: =(8760-G13-G14)/12*20/60 -> 230.48878 | H15: =(8760-H13-H14)/12*20/60 -> 227.361 | I15: =(8760-I13-I14)/12*20/60 -> 233.59989 | J15: =(8760-J13-J14)/12*20/60 -> 230.69433 | K15: =(8760-K13-K14)/12*20/60 -> 233.08322 | L15: =(8760-L13-L14)/12*20/60 -> 228.04433 | ... X15: =(8760-X13-X14)/12*20/60 -> 230.76656
A16: =A15+1 -> 13 | B16: Время подъема кузова с грузом | C16: сек | D16: 22 | E16: =D16 -> 22 | F16: =E16 -> 22 | G16: =F16 -> 22 | H16: =G16 -> 22 | I16: =H16 -> 22 | J16: =I16 -> 22 | K16: =J16 -> 22 | L16: =K16 -> 22 | ... X16: =W16 -> 22
A17: =A16+1 -> 14 | B17: Время опускания кузова | C17: сек | D17: 15 | E17: =D17 -> 15 | F17: =E17 -> 15 | G17: =F17 -> 15 | H17: =G17 -> 15 | I17: =H17 -> 15 | J17: =I17 -> 15 | K17: =J17 -> 15 | L17: =K17 -> 15 | ... X17: =W17 -> 15
A18: =A17+1 -> 15 | B18: ТО, ТР, ПР, сервис (кроме/включая смазочных), моточас работы | C18: тыс.Юаней/год | E18: =SUM(E19:E22) -> 448.2533 | F18: =SUM(F19:F22) -> 631.6461 | G18: =SUM(G19:G22) -> 3852.9561 | H18: =SUM(H19:H22) -> 2038.5043 | I18: =SUM(I19:I22) -> 664.86544 | J18: =SUM(J19:J22) -> 3762.1227 | K18: =SUM(K19:K22) -> 614.71144 | L18: =SUM(L19:L22) -> 2161.7703 | ... X18: =SUM(X19:X22) -> 724.56957
A19: =A18+1 -> 16 | B19: ТО, включая смазочные | C19: тыс.Юаней/год | E19: =ТО!G9/1000 -> 274.82224 | F19: =ТО!H9/1000 -> 274.82224 | G19: =ТО!I9/1000 -> 274.82224 | H19: =ТО!J9/1000 -> 274.82224 | I19: =ТО!K9/1000 -> 274.82224 | J19: =ТО!L9/1000 -> 274.82224 | K19: =ТО!M9/1000 -> 274.82224 | L19: =ТО!N9/1000 -> 274.82224 | ... X19: =ТО!Z9/1000 -> 274.82224 | Y19: Стоимость ТО без учета смазочных материалов
A20: =A19+1 -> 17 | B20: планово-предупредительные (капитальные) ремонты | C20: тыс.Юаней/год | E20: =Ремонты!G10/1000 -> 0 | F20: =Ремонты!H10/1000 -> 151.6104 | G20: =Ремонты!I10/1000 -> 3293.5408 | H20: =Ремонты!J10/1000 -> 1329.6506 | I20: =Ремонты!K10/1000 -> 207.44414 | J20: =Ремонты!L10/1000 -> 3259.167 | K20: =Ремонты!M10/1000 -> 47.96174 | L20: =Ремонты!N10/1000 -> 1481.261 | ... X20: =Ремонты!Z10/1000 -> 237.35227
A21: =A20+1 -> 18 | B21: сервис (трудозатраты) - ТО | C21: тыс.Юаней/год | E21: =ТО!G10/1000 -> 126.06306 | F21: =ТО!H10/1000 -> 147.91346 | G21: =ТО!I10/1000 -> 126.06306 | H21: =ТО!J10/1000 -> 147.91346 | I21: =ТО!K10/1000 -> 126.06306 | J21: =ТО!L10/1000 -> 147.91346 | K21: =ТО!M10/1000 -> 147.91346 | L21: =ТО!N10/1000 -> 126.06306 | ... X21: =ТО!Z10/1000 -> 144.39906
A22: =A21+1 -> 19 | B22: сервис (трудозатраты) - ремонты | C22: тыс.Юаней/год | E22: =Ремонты!G11/1000 -> 47.368 | F22: =Ремонты!H11/1000 -> 57.3 | G22: =Ремонты!I11/1000 -> 158.53 | H22: =Ремонты!J11/1000 -> 286.118 | I22: =Ремонты!K11/1000 -> 56.536 | J22: =Ремонты!L11/1000 -> 80.22 | K22: =Ремонты!M11/1000 -> 144.014 | L22: =Ремонты!N11/1000 -> 279.624 | ... X22: =Ремонты!Z11/1000 -> 67.996 | Y22: На 1 час эксплуатации оборудования
A23: =A22+1 -> 20 | B23: Шины
A24: =A23+1 -> 21 | B24: типоразмер | D24: 50/80R57 | E24: 50/80R57 | F24: 50/80R57 | G24: 50/80R57 | H24: 50/80R57 | I24: 50/80R57 | J24: 50/80R57 | K24: 50/80R57 | L24: 50/80R57 | M24: 50/80R57 | N24: 50/80R57 | O24: 50/80R57 | P24: 50/80R57 | Q24: 50/80R57 | R24: 50/80R57 | S24: 50/80R57 | T24: 50/80R57 | U24: 50/80R57 | V24: 50/80R57 | W24: 50/80R57 | X24: 50/80R57 | Y24: Модель резины по выбору завода изготовителя (обычно это MAXAM)
A25: =A24+1 -> 22 | B25: Цена за единицу | D25: 0 | E25: =D25 -> 0 | F25: =E25 -> 0 | G25: =F25 -> 0 | H25: =G25 -> 0 | I25: =H25 -> 0 | J25: =I25 -> 0 | K25: =J25 -> 0 | L25: =K25 -> 0 | ... X25: =W25 -> 0 | Y25: Точная цена у Покупателя, такие шины Покупатель приобретает самостоятельно.
A26: =A25+1 -> 23 | B26: Топливо | Y26: Средний расход топлива в час при обычном режиме работы
A27: =A26+1 -> 24 | B27: Расход - легкие условия | C27: л/час | D27: 140 | E27: =D27 -> 140 | F27: =E27 -> 140 | G27: =F27 -> 140 | H27: =G27 -> 140 | I27: =H27 -> 140 | J27: =I27 -> 140 | K27: =J27 -> 140 | L27: =K27 -> 140 | ... X27: =W27 -> 140 | Y27: Средний расход - легкие условия
A28: =A27+1 -> 25 | B28: Расход - средние условия | C28: л/час | D28: 165 | E28: =D28 -> 165 | F28: =E28 -> 165 | G28: =F28 -> 165 | H28: =G28 -> 165 | I28: =H28 -> 165 | J28: =I28 -> 165 | K28: =J28 -> 165 | L28: =K28 -> 165 | ... X28: =W28 -> 165 | Y28: Средний расход - средние условия
A29: =A28+1 -> 26 | B29: Расход - тяжелые условия | C29: л/час | D29: 190 | E29: =D29 -> 190 | F29: =E29 -> 190 | G29: =F29 -> 190 | H29: =G29 -> 190 | I29: =H29 -> 190 | J29: =I29 -> 190 | K29: =J29 -> 190 | L29: =K29 -> 190 | ... X29: =W29 -> 190 | Y29: Средний расход - тяжелые условия
A30: =A29+1 -> 27 | B30: Сроки поставки | C30: мес | D30: От 6 до 14 | E30: =D30 -> От 6 до 14 | F30: =E30 -> От 6 до 14 | G30: =F30 -> От 6 до 14 | H30: =G30 -> От 6 до 14 | I30: =H30 -> От 6 до 14 | J30: =I30 -> От 6 до 14 | K30: =J30 -> От 6 до 14 | L30: =K30 -> От 6 до 14 | ... X30: =W30 -> От 6 до 14 | Y30: Сроки поставки зависят от количества самосвалов в партии и даты заказа.

Sheet ТО
B2: ячейки к заполнению поставщиком
B3: Расчетный КТГ | G3: ='Данные-самосвал NHL NTE240'!E12 -> 0.93755029 | H3: ='Данные-самосвал NHL NTE240'!F12 -> 0.93038071 | I3: ='Данные-самосвал NHL NTE240'!G12 -> 0.92090265 | J3: ='Данные-самосвал NHL NTE240'!H12 -> 0.90840582 | K3: ='Данные-самосвал NHL NTE240'!I12 -> 0.93333289 | L3: ='Данные-самосвал NHL NTE240'!J12 -> 0.92172393 | M3: ='Данные-самосвал NHL NTE240'!K12 -> 0.93126858 | N3: ='Данные-самосвал NHL NTE240'!L12 -> 0.91113604 | ... Z3: ='Данные-самосвал NHL NTE240'!X12 -> 0.92201249
B4: Год службы (год) | C4: Ед. изм. | G4: =E4+1 -> 1 | H4: =G4+1 -> 2 | I4: =H4+1 -> 3 | J4: =I4+1 -> 4 | K4: =J4+1 -> 5 | L4: =K4+1 -> 6 | M4: =L4+1 -> 7 | N4: =M4+1 -> 8 | O4: =N4+1 -> 9 | ... R4: =Q4+1 -> 12 | S4: 13 | T4: 14 | U4: 15 | V4: 16 | W4: 17 | X4: 18 | Y4: 19 | Z4: 20
B5: Наработка на начало года | C5: м/час | G5: 0 | H5: =G6+1 -> 7001 | I5: =H6+1 -> 14001 | J5: =I6+1 -> 21001 | K5: =J6+1 -> 28001 | L5: =K6+1 -> 35001 | M5: =L6+1 -> 42001 | N5: =M6+1 -> 49001 | O5: =N6+1 -> 56001 | ... Z5: =Y6+1 -> 133001
B6: Наработка на конец года | C6: м/час | F6: 7000 | G6: =F6 -> 7000 | H6: =G6+$F6 -> 14000 | I6: =H6+$F6 -> 21000 | J6: =I6+$F6 -> 28000 | K6: =J6+$F6 -> 35000 | L6: =K6+$F6 -> 42000 | M6: =L6+$F6 -> 49000 | N6: =M6+$F6 -> 56000 | O6: =N6+$F6 -> 63000 | ... R6: =Q6+$F6 -> 84000 | S6: 91000 | T6: 98000 | U6: 105000 | V6: 112000 | W6: 119000 | X6: 126000 | Y6: 133000 | Z6: 140000
B7: длительность простоев на ТО | C7: часов | G7: =G13 -> 173.404 | H7: =H13 -> 202.004 | I7: =I13 -> 173.404 | J7: =J13 -> 202.004 | K7: =K13 -> 173.404 | L7: =L13 -> 202.004 | M7: =M13 -> 202.004 | N7: =N13 -> 173.404 | ... Z7: =Z13 -> 197.404
B8: Затраты на ТО | C8: Юаней в /год | G8: =SUM(G9:G10) -> 400885.3 | H8: =SUM(H9:H10) -> 422735.7 | I8: =SUM(I9:I10) -> 400885.3 | J8: =SUM(J9:J10) -> 422735.7 | K8: =SUM(K9:K10) -> 400885.3 | L8: =SUM(L9:L10) -> 422735.7 | M8: =SUM(M9:M10) -> 422735.7 | N8: =SUM(N9:N10) -> 400885.3 | ... Z8: =SUM(Z9:Z10) -> 419221.3
B9: ТО, включая масла и смазки | C9: Юаней в /год | G9: =G22 -> 274822.24 | H9: =H22 -> 274822.24 | I9: =I22 -> 274822.24 | J9: =J22 -> 274822.24 | K9: =K22 -> 274822.24 | L9: =L22 -> 274822.24 | M9: =M22 -> 274822.24 | N9: =N22 -> 274822.24 | ... Z9: =Z22 -> 274822.24
B10: сервис (трудозатраты) на ТО | C10: Юаней в /год | F10: 191 | G10: =SUMPRODUCT(G14:G19,$F$14:$F$19)*$F10 -> 126063.06 | H10: =SUMPRODUCT(H14:H19,$F$14:$F$19)*$F10 -> 147913.46 | I10: =SUMPRODUCT(I14:I19,$F$14:$F$19)*$F10 -> 126063.06 | J10: =SUMPRODUCT(J14:J19,$F$14:$F$19)*$F10 -> 147913.46 | K10: =SUMPRODUCT(K14:K19,$F$14:$F$19)*$F10 -> 126063.06 | L10: =SUMPRODUCT(L14:L19,$F$14:$F$19)*$F10 -> 147913.46 | M10: =SUMPRODUCT(M14:M19,$F$14:$F$19)*$F10 -> 147913.46 | N10: =SUMPRODUCT(N14:N19,$F$14:$F$19)*$F10 -> 126063.06 | ... Z10: =SUMPRODUCT(Z14:Z19,$F$14:$F$19)*$F10 -> 144399.06
B12: Простои оборудования на ТО | C12: Интервал ТО | D12: Длительность простоя на одном ТО, час | E12: Кол-во ТО в год | F12: Занято человек | G12: Простоев в год, час | H12: Простоев в год, час | I12: Простоев в год, час | J12: Простоев в год, час | K12: Простоев в год, час | L12: Простоев в год, час | M12: Простоев в год, час | N12: Простоев в год, час | O12: Простоев в год, час | P12: Простоев в год, час | Q12: Простоев в год, час | R12: Простоев в год, час | S12: Простоев в год, час | T12: Простоев в год, час | U12: Простоев в год, час | V12: Простоев в год, час | W12: Простоев в год, час | X12: Простоев в год, час | Y12: Простоев в год, час | Z12: Простоев в год, час
B13: всего простоев на ТО, часов | G13: =SUM(G14:G19) -> 173.404 | H13: =SUM(H14:H19) -> 202.004 | I13: =SUM(I14:I19) -> 173.404 | J13: =SUM(J14:J19) -> 202.004 | K13: =SUM(K14:K19) -> 173.404 | L13: =SUM(L14:L19) -> 202.004 | M13: =SUM(M14:M19) -> 202.004 | N13: =SUM(N14:N19) -> 173.404 | ... Z13: =SUM(Z14:Z19) -> 197.404
B14: ТО-1 | C14: 250 | D14: =6/2.5 -> 2.4 | E14: 14 | F14: 3 | G14: =$E14*$D14 -> 33.6 | H14: =$E14*$D14 -> 33.6 | I14: =$E14*$D14 -> 33.6 | J14: =$E14*$D14 -> 33.6 | K14: =$E14*$D14 -> 33.6 | L14: =$E14*$D14 -> 33.6 | M14: =$E14*$D14 -> 33.6 | N14: =$E14*$D14 -> 33.6 | ... Z14: =$E14*$D14 -> 33.6
B15: ТО-2 | C15: 500 | D15: =20.83/2.5 -> 8.332 | E15: 7 | F15: 4 | G15: =$E15*$D15 -> 58.324 | H15: =$E15*$D15 -> 58.324 | I15: =$E15*$D15 -> 58.324 | J15: =$E15*$D15 -> 58.324 | K15: =$E15*$D15 -> 58.324 | L15: =$E15*$D15 -> 58.324 | M15: =$E15*$D15 -> 58.324 | N15: =$E15*$D15 -> 58.324 | ... Z15: =$E15*$D15 -> 58.324
B16: ТО-3 | C16: 1000 | D16: =24.2/2.5 -> 9.68 | E16: 3 | F16: 4 | G16: =$E16*$D16 -> 29.04 | H16: =$E16*$D16 -> 29.04 | I16: =$E16*$D16 -> 29.04 | J16: =$E16*$D16 -> 29.04 | K16: =$E16*$D16 -> 29.04 | L16: =$E16*$D16 -> 29.04 | M16: =$E16*$D16 -> 29.04 | N16: =$E16*$D16 -> 29.04 | ... Z16: =$E16*$D16 -> 29.04
B17: ТО-4 | C17: 2000 | D17: =28.2/2.5 -> 11.28 | E17: 3 | F17: 4 | G17: =$E17*$D17 -> 33.84 | H17: =$E17*$D17 -> 33.84 | I17: =$E17*$D17 -> 33.84 | J17: =$E17*$D17 -> 33.84 | K17: =$E17*$D17 -> 33.84 | L17: =$E17*$D17 -> 33.84 | M17: =$E17*$D17 -> 33.84 | N17: =$E17*$D17 -> 33.84 | ... Z17: =$E17*$D17 -> 33.84
B18: ТО-5 | C18: 5000 | D18: =46.5/2.5 -> 18.6 | E18: 1 | F18: 4 | G18: =$E18*$D18 -> 18.6 | H18: =$E18*$D18 -> 18.6 | I18: =$E18*$D18 -> 18.6 | J18: =$E18*$D18 -> 18.6 | K18: =$E18*$D18 -> 18.6 | L18: =$E18*$D18 -> 18.6 | M18: =$E18*$D18 -> 18.6 | N18: =$E18*$D18 -> 18.6 | ... Z18: =$E18*$D18 -> 18.6
B19: ТО-6 | C19: 10000 | D19: =71.5/2.5 -> 28.6 | F19: 4 | H19: =$D19 -> 28.6 | J19: =$D19 -> 28.6 | L19: =$D19 -> 28.6 | M19: =$D19 -> 28.6 | O19: =$D19 -> 28.6 | Q19: =$D19 -> 28.6 | R19: =$D19 -> 28.6 | T19: 24 | U19: 24 | W19: 24 | X19: 24 | Z19: 24
B21: Затраты на ТО | C21: Каталожный номер | D21: стоимость за ед., ¥ | E21: Кол-во | F21: Кол-во ТО в год | G21: ¥ | H21: =G21 -> ¥ | I21: =H21 -> ¥ | J21: =I21 -> ¥ | K21: =J21 -> ¥ | L21: =K21 -> ¥ | M21: =L21 -> ¥ | N21: =M21 -> ¥ | O21: =N21 -> ¥ | ... Z21: =Y21 -> ¥
B22: ТО | G22: =SUM(G23:G52) -> 274822.24 | H22: =SUM(H23:H52) -> 274822.24 | I22: =SUM(I23:I52) -> 274822.24 | J22: =SUM(J23:J52) -> 274822.24 | K22: =SUM(K23:K52) -> 274822.24 | L22: =SUM(L23:L52) -> 274822.24 | M22: =SUM(M23:M52) -> 274822.24 | N22: =SUM(N23:N52) -> 274822.24 | ... Z22: =SUM(Z23:Z52) -> 274822.24
B23: ТО-1 | E23: =VLOOKUP($B23,$B$14:$C$19,2,FALSE) -> 250 | F23: =VLOOKUP($B23,$B$14:$E$19,4,FALSE) -> 14
B24: фильтр | C24: 4323856 | D24: 446.41 | E24: 1 | G24: =IF(G$14=0,0,G$14/$D$14*$E24*$D24) -> 6249.74 | H24: =IF(H$14=0,0,H$14/$D$14*$E24*$D24) -> 6249.74 | I24: =IF(I$14=0,0,I$14/$D$14*$E24*$D24) -> 6249.74 | J24: =IF(J$14=0,0,J$14/$D$14*$E24*$D24) -> 6249.74 | K24: =IF(K$14=0,0,K$14/$D$14*$E24*$D24) -> 6249.74 | L24: =IF(L$14=0,0,L$14/$D$14*$E24*$D24) -> 6249.74 | M24: =IF(M$14=0,0,M$14/$D$14*$E24*$D24) -> 6249.74 | N24: =IF(N$14=0,0,N$14/$D$14*$E24*$D24) -> 6249.74 | ... Z24: =IF(Z$14=0,0,Z$14/$D$14*$E24*$D24) -> 6249.74
B25: фильтр | C25: 5375337 | D25: 1131.08 | E25: 4 | G25: =IF(G$14=0,0,G$14/$D$14*$E25*$D25) -> 63340.48 | H25: =IF(H$14=0,0,H$14/$D$14*$E25*$D25) -> 63340.48 | I25: =IF(I$14=0,0,I$14/$D$14*$E25*$D25) -> 63340.48 | J25: =IF(J$14=0,0,J$14/$D$14*$E25*$D25) -> 63340.48 | K25: =IF(K$14=0,0,K$14/$D$14*$E25*$D25) -> 63340.48 | L25: =IF(L$14=0,0,L$14/$D$14*$E25*$D25) -> 63340.48 | M25: =IF(M$14=0,0,M$14/$D$14*$E25*$D25) -> 63340.48 | N25: =IF(N$14=0,0,N$14/$D$14*$E25*$D25) -> 63340.48 | ... Z25: =IF(Z$14=0,0,Z$14/$D$14*$E25*$D25) -> 63340.48
B26: фильтр | C26: 2881458 | D26: 1711.91 | E26: 3 | G26: =IF(G$14=0,0,G$14/$D$14*$E26*$D26) -> 71900.22 | H26: =IF(H$14=0,0,H$14/$D$14*$E26*$D26) -> 71900.22 | I26: =IF(I$14=0,0,I$14/$D$14*$E26*$D26) -> 71900.22 | J26: =IF(J$14=0,0,J$14/$D$14*$E26*$D26) -> 71900.22 | K26: =IF(K$14=0,0,K$14/$D$14*$E26*$D26) -> 71900.22 | L26: =IF(L$14=0,0,L$14/$D$14*$E26*$D26) -> 71900.22 | M26: =IF(M$14=0,0,M$14/$D$14*$E26*$D26) -> 71900.22 | N26: =IF(N$14=0,0,N$14/$D$14*$E26*$D26) -> 71900.22 | ... Z26: =IF(Z$14=0,0,Z$14/$D$14*$E26*$D26) -> 71900.22
B27: масло 15W-40 | C27: 0 | D27: 0 | E27: 280 | G27: =IF(G$14=0,0,G$14/$D$14*$E27*$D27) -> 0 | H27: =IF(H$14=0,0,H$14/$D$14*$E27*$D27) -> 0 | I27: =IF(I$14=0,0,I$14/$D$14*$E27*$D27) -> 0 | J27: =IF(J$14=0,0,J$14/$D$14*$E27*$D27) -> 0 | K27: =IF(K$14=0,0,K$14/$D$14*$E27*$D27) -> 0 | L27: =IF(L$14=0,0,L$14/$D$14*$E27*$D27) -> 0 | M27: =IF(M$14=0,0,M$14/$D$14*$E27*$D27) -> 0 | N27: =IF(N$14=0,0,N$14/$D$14*$E27*$D27) -> 0 | ... Z27: =IF(Z$14=0,0,Z$14/$D$14*$E27*$D27) -> 0
B28: смазка 1-100 HD | C28: 0 | D28: 0 | E28: 50 | G28: =IF(G$14=0,0,G$14/$D$14*$E28*$D28) -> 0 | H28: =IF(H$14=0,0,H$14/$D$14*$E28*$D28) -> 0 | I28: =IF(I$14=0,0,I$14/$D$14*$E28*$D28) -> 0 | J28: =IF(J$14=0,0,J$14/$D$14*$E28*$D28) -> 0 | K28: =IF(K$14=0,0,K$14/$D$14*$E28*$D28) -> 0 | L28: =IF(L$14=0,0,L$14/$D$14*$E28*$D28) -> 0 | M28: =IF(M$14=0,0,M$14/$D$14*$E28*$D28) -> 0 | N28: =IF(N$14=0,0,N$14/$D$14*$E28*$D28) -> 0 | ... Z28: =IF(Z$14=0,0,Z$14/$D$14*$E28*$D28) -> 0
B29: антифриз HD Long Life | C29: 0 | D29: 0 | E29: 40 | G29: =IF(G$14=0,0,G$14/$D$14*$E29*$D29) -> 0 | H29: =IF(H$14=0,0,H$14/$D$14*$E29*$D29) -> 0 | I29: =IF(I$14=0,0,I$14/$D$14*$E29*$D29) -> 0 | J29: =IF(J$14=0,0,J$14/$D$14*$E29*$D29) -> 0 | K29: =IF(K$14=0,0,K$14/$D$14*$E29*$D29) -> 0 | L29: =IF(L$14=0,0,L$14/$D$14*$E29*$D29) -> 0 | M29: =IF(M$14=0,0,M$14/$D$14*$E29*$D29) -> 0 | N29: =IF(N$14=0,0,N$14/$D$14*$E29*$D29) -> 0 | ... Z29: =IF(Z$14=0,0,Z$14/$D$14*$E29*$D29) -> 0
B30: ТО-2 | E30: =VLOOKUP($B30,$B$14:$C$19,2,FALSE) -> 500 | F30: =VLOOKUP($B30,$B$14:$E$19,4,FALSE) -> 7
B31: фильтр | C31: 916254 / 20059910 | D31: 1146.86 | E31: 3 | G31: =IF(G$15=0,0,G$15/$D$15*$E31*$D31) -> 24084.06 | H31: =IF(H$15=0,0,H$15/$D$15*$E31*$D31) -> 24084.06 | I31: =IF(I$15=0,0,I$15/$D$15*$E31*$D31) -> 24084.06 | J31: =IF(J$15=0,0,J$15/$D$15*$E31*$D31) -> 24084.06 | K31: =IF(K$15=0,0,K$15/$D$15*$E31*$D31) -> 24084.06 | L31: =IF(L$15=0,0,L$15/$D$15*$E31*$D31) -> 24084.06 | M31: =IF(M$15=0,0,M$15/$D$15*$E31*$D31) -> 24084.06 | N31: =IF(N$15=0,0,N$15/$D$15*$E31*$D31) -> 24084.06 | ... Z31: =IF(Z$15=0,0,Z$15/$D$15*$E31*$D31) -> 24084.06
B32: фильтр | C32: 20070596 | D32: 5185.61 | E32: 1 | G32: =IF(G$15=0,0,G$15/$D$15*$E32*$D32) -> 36299.27 | H32: =IF(H$15=0,0,H$15/$D$15*$E32*$D32) -> 36299.27 | I32: =IF(I$15=0,0,I$15/$D$15*$E32*$D32) -> 36299.27 | J32: =IF(J$15=0,0,J$15/$D$15*$E32*$D32) -> 36299.27 | K32: =IF(K$15=0,0,K$15/$D$15*$E32*$D32) -> 36299.27 | L32: =IF(L$15=0,0,L$15/$D$15*$E32*$D32) -> 36299.27 | M32: =IF(M$15=0,0,M$15/$D$15*$E32*$D32) -> 36299.27 | N32: =IF(N$15=0,0,N$15/$D$15*$E32*$D32) -> 36299.27 | ... Z32: =IF(Z$15=0,0,Z$15/$D$15*$E32*$D32) -> 36299.27
B33: фильтр | C33: 4328043 | D33: 2381.38 | E33: 1 | G33: =IF(G$15=0,0,G$15/$D$15*$E33*$D33) -> 16669.66 | H33: =IF(H$15=0,0,H$15/$D$15*$E33*$D33) -> 16669.66 | I33: =IF(I$15=0,0,I$15/$D$15*$E33*$D33) -> 16669.66 | J33: =IF(J$15=0,0,J$15/$D$15*$E33*$D33) -> 16669.66 | K33: =IF(K$15=0,0,K$15/$D$15*$E33*$D33) -> 16669.66 | L33: =IF(L$15=0,0,L$15/$D$15*$E33*$D33) -> 16669.66 | M33: =IF(M$15=0,0,M$15/$D$15*$E33*$D33) -> 16669.66 | N33: =IF(N$15=0,0,N$15/$D$15*$E33*$D33) -> 16669.66 | ... Z33: =IF(Z$15=0,0,Z$15/$D$15*$E33*$D33) -> 16669.66
B34: фильтр | C34: 3100308 | D34: 133.17 | E34: 2 | G34: =IF(G$15=0,0,G$15/$D$15*$E34*$D34) -> 1864.38 | H34: =IF(H$15=0,0,H$15/$D$15*$E34*$D34) -> 1864.38 | I34: =IF(I$15=0,0,I$15/$D$15*$E34*$D34) -> 1864.38 | J34: =IF(J$15=0,0,J$15/$D$15*$E34*$D34) -> 1864.38 | K34: =IF(K$15=0,0,K$15/$D$15*$E34*$D34) -> 1864.38 | L34: =IF(L$15=0,0,L$15/$D$15*$E34*$D34) -> 1864.38 | M34: =IF(M$15=0,0,M$15/$D$15*$E34*$D34) -> 1864.38 | N34: =IF(N$15=0,0,N$15/$D$15*$E34*$D34) -> 1864.38 | ... Z34: =IF(Z$15=0,0,Z$15/$D$15*$E34*$D34) -> 1864.38
B35: ТО-3 | E35: =VLOOKUP($B35,$B$14:$C$19,2,FALSE) -> 1000 | F35: =VLOOKUP($B35,$B$14:$E$19,4,FALSE) -> 3
B36: фильтр | C36: UR24465 | D36: 810 | E36: 2 | G36: =IF(G$16=0,0,G$16/$D$16*$E36*$D36) -> 4860 | H36: =IF(H$16=0,0,H$16/$D$16*$E36*$D36) -> 4860 | I36: =IF(I$16=0,0,I$16/$D$16*$E36*$D36) -> 4860 | J36: =IF(J$16=0,0,J$16/$D$16*$E36*$D36) -> 4860 | K36: =IF(K$16=0,0,K$16/$D$16*$E36*$D36) -> 4860 | L36: =IF(L$16=0,0,L$16/$D$16*$E36*$D36) -> 4860 | M36: =IF(M$16=0,0,M$16/$D$16*$E36*$D36) -> 4860 | N36: =IF(N$16=0,0,N$16/$D$16*$E36*$D36) -> 4860 | ... Z36: =IF(Z$16=0,0,Z$16/$D$16*$E36*$D36) -> 4860
B37: фильтр | C37: 20042559 | D37: 814.95 | E37: 4 | G37: =IF(G$16=0,0,G$16/$D$16*$E37*$D37) -> 9779.4 | H37: =IF(H$16=0,0,H$16/$D$16*$E37*$D37) -> 9779.4 | I37: =IF(I$16=0,0,I$16/$D$16*$E37*$D37) -> 9779.4 | J37: =IF(J$16=0,0,J$16/$D$16*$E37*$D37) -> 9779.4 | K37: =IF(K$16=0,0,K$16/$D$16*$E37*$D37) -> 9779.4 | L37: =IF(L$16=0,0,L$16/$D$16*$E37*$D37) -> 9779.4 | M37: =IF(M$16=0,0,M$16/$D$16*$E37*$D37) -> 9779.4 | N37: =IF(N$16=0,0,N$16/$D$16*$E37*$D37) -> 9779.4 | ... Z37: =IF(Z$16=0,0,Z$16/$D$16*$E37*$D37) -> 9779.4
B38: фильтр | C38: 20042560 | D38: 1895.1 | E38: 4 | G38: =IF(G$16=0,0,G$16/$D$16*$E38*$D38) -> 22741.2 | H38: =IF(H$16=0,0,H$16/$D$16*$E38*$D38) -> 22741.2 | I38: =IF(I$16=0,0,I$16/$D$16*$E38*$D38) -> 22741.2 | J38: =IF(J$16=0,0,J$16/$D$16*$E38*$D38) -> 22741.2 | K38: =IF(K$16=0,0,K$16/$D$16*$E38*$D38) -> 22741.2 | L38: =IF(L$16=0,0,L$16/$D$16*$E38*$D38) -> 22741.2 | M38: =IF(M$16=0,0,M$16/$D$16*$E38*$D38) -> 22741.2 | N38: =IF(N$16=0,0,N$16/$D$16*$E38*$D38) -> 22741.2 | ... Z38: =IF(Z$16=0,0,Z$16/$D$16*$E38*$D38) -> 22741.2
B39: фильтр | C39: 20039876 | D39: 3242.88 | E39: 1 | G39: =IF(G$16=0,0,G$16/$D$16*$E39*$D39) -> 9728.64 | H39: =IF(H$16=0,0,H$16/$D$16*$E39*$D39) -> 9728.64 | I39: =IF(I$16=0,0,I$16/$D$16*$E39*$D39) -> 9728.64 | J39: =IF(J$16=0,0,J$16/$D$16*$E39*$D39) -> 9728.64 | K39: =IF(K$16=0,0,K$16/$D$16*$E39*$D39) -> 9728.64 | L39: =IF(L$16=0,0,L$16/$D$16*$E39*$D39) -> 9728.64 | M39: =IF(M$16=0,0,M$16/$D$16*$E39*$D39) -> 9728.64 | N39: =IF(N$16=0,0,N$16/$D$16*$E39*$D39) -> 9728.64 | ... Z39: =IF(Z$16=0,0,Z$16/$D$16*$E39*$D39) -> 9728.64
B40: фильтр | C40: 20046992 | D40: 64.4 | E40: 1 | G40: =IF(G$16=0,0,G$16/$D$16*$E40*$D40) -> 193.2 | H40: =IF(H$16=0,0,H$16/$D$16*$E40*$D40) -> 193.2 | I40: =IF(I$16=0,0,I$16/$D$16*$E40*$D40) -> 193.2 | J40: =IF(J$16=0,0,J$16/$D$16*$E40*$D40) -> 193.2 | K40: =IF(K$16=0,0,K$16/$D$16*$E40*$D40) -> 193.2 | L40: =IF(L$16=0,0,L$16/$D$16*$E40*$D40) -> 193.2 | M40: =IF(M$16=0,0,M$16/$D$16*$E40*$D40) -> 193.2 | N40: =IF(N$16=0,0,N$16/$D$16*$E40*$D40) -> 193.2 | ... Z40: =IF(Z$16=0,0,Z$16/$D$16*$E40*$D40) -> 193.2
B41: фильтр | C41: 20046634 | D41: 452.98 | E41: 1 | G41: =IF(G$16=0,0,G$16/$D$16*$E41*$D41) -> 1358.94 | H41: =IF(H$16=0,0,H$16/$D$16*$E41*$D41) -> 1358.94 | I41: =IF(I$16=0,0,I$16/$D$16*$E41*$D41) -> 1358.94 | J41: =IF(J$16=0,0,J$16/$D$16*$E41*$D41) -> 1358.94 | K41: =IF(K$16=0,0,K$16/$D$16*$E41*$D41) -> 1358.94 | L41: =IF(L$16=0,0,L$16/$D$16*$E41*$D41) -> 1358.94 | M41: =IF(M$16=0,0,M$16/$D$16*$E41*$D41) -> 1358.94 | N41: =IF(N$16=0,0,N$16/$D$16*$E41*$D41) -> 1358.94 | ... Z41: =IF(Z$16=0,0,Z$16/$D$16*$E41*$D41) -> 1358.94
B42: фильтр | C42: UR24465 | D42: 810 | E42: 2
B43: ТО-4 | E43: =VLOOKUP($B43,$B$14:$C$19,2,FALSE) -> 2000 | F43: =VLOOKUP($B43,$B$14:$E$19,4,FALSE) -> 3
...

Sheet Ремонты
B2: ячейки к заполнению поставщиком
B3: Расчетный КТГ | G3: ='Данные-самосвал NHL NTE240'!E12 -> 0.93755029 | H3: ='Данные-самосвал NHL NTE240'!F12 -> 0.93038071 | I3: ='Данные-самосвал NHL NTE240'!G12 -> 0.92090265 | J3: ='Данные-самосвал NHL NTE240'!H12 -> 0.90840582 | K3: ='Данные-самосвал NHL NTE240'!I12 -> 0.93333289 | L3: ='Данные-самосвал NHL NTE240'!J12 -> 0.92172393 | M3: ='Данные-самосвал NHL NTE240'!K12 -> 0.93126858 | N3: ='Данные-самосвал NHL NTE240'!L12 -> 0.91113604 | ... Z3: ='Данные-самосвал NHL NTE240'!X12 -> 0.92201249
B4: Год службы (год) | D4: Ед.изм. | G4: 1 | H4: =G4+1 -> 2 | I4: =H4+1 -> 3 | J4: =I4+1 -> 4 | K4: =J4+1 -> 5 | L4: =K4+1 -> 6 | M4: =L4+1 -> 7 | N4: =M4+1 -> 8 | O4: =N4+1 -> 9 | ... Z4: =Y4+1 -> 20
B5: Наработка на начало года | D5: м/час | G5: 0 | H5: =G6+1 -> 7001 | I5: =H6+1 -> 14001 | J5: =I6+1 -> 21001 | K5: =J6+1 -> 28001 | L5: =K6+1 -> 35001 | M5: =L6+1 -> 42001 | N5: =M6+1 -> 49001 | O5: =N6+1 -> 56001 | ... R5: =Q6+1 -> 77001 | S5: 84001 | T5: 91001 | U5: 98001 | V5: 105001 | W5: 112001 | X5: 119001 | Y5: 126001 | Z5: 133001
B6: Наработка на конец года | D6: м/час | F6: =ТО!F6 -> 7000 | G6: =F6 -> 7000 | H6: =G6+$F6 -> 14000 | I6: =H6+$F6 -> 21000 | J6: =I6+$F6 -> 28000 | K6: =J6+$F6 -> 35000 | L6: =K6+$F6 -> 42000 | M6: =L6+$F6 -> 49000 | N6: =M6+$F6 -> 56000 | O6: =N6+$F6 -> 63000 | ... R6: =Q6+$F6 -> 84000 | S6: 91000 | T6: 98000 | U6: 105000 | V6: 112000 | W6: 119000 | X6: 126000 | Y6: 133000 | Z6: 140000
B8: Простои в ремонтах | D8: часов | G8: =G14 -> 139 | H8: =H14 -> 175 | I8: =I14 -> 289 | J8: =J14 -> 373 | K8: =K14 -> 177 | L8: =L14 -> 253 | M8: =M14 -> 167 | N8: =N14 -> 377 | ... Z8: =Z14 -> 255
B9: Затраты на ремонты | D9: ¥ / год | G9: =SUM(G10:G11) -> 47368 | H9: =SUM(H10:H11) -> 208910.4 | I9: =SUM(I10:I11) -> 3452070.8 | J9: =SUM(J10:J11) -> 1615768.6 | K9: =SUM(K10:K11) -> 263980.14 | L9: =SUM(L10:L11) -> 3339387 | M9: =SUM(M10:M11) -> 191975.74 | N9: =SUM(N10:N11) -> 1760885 | ... Z9: =SUM(Z10:Z11) -> 305348.27
B10: Планово-предупредительные (капитальные) ремонты | D10: ¥ / год | G10: =G61 -> 0 | H10: =H61 -> 151610.4 | I10: =I61 -> 3293540.8 | J10: =J61 -> 1329650.6 | K10: =K61 -> 207444.14 | L10: =L61 -> 3259167 | M10: =M61 -> 47961.74 | N10: =N61 -> 1481261 | ... Z10: =Z61 -> 237352.27
B11: Сервис (трудозатраты) | D11: ¥ / год | G11: =G38*E36 -> 47368 | H11: =H38*E36 -> 57300 | I11: =I38*E36 -> 158530 | J11: =J38*E36 -> 286118 | K11: =K38*E36 -> 56536 | L11: =L38*E36 -> 80220 | M11: =M38*E36 -> 144014 | N11: =N38*E36 -> 279624 | O11: =O38*E36 -> 81748 | P11: =P38*E36 -> 74108 | Q11: =Q38*E36 -> 345328 | R11: =R38*E36 -> 90152 | S11: =S38*E36 -> 67232 | T11: =T38*E36 -> 51188 | U11: =U38*E36 -> 382764 | V11: =V38*E36 -> 82130 | W11: =W38*E36 -> 44312 | X11: =X38*E36 -> 300634 | Y11: =Y38*E36 -> 144014 | Z11: =Z38*E36 -> 67996
B12: Простои в ремонте (час)
B13: Вид ремонта | D13: Ед.изм. | G13: =G4 -> 1 | H13: =H4 -> 2 | I13: =I4 -> 3 | J13: =J4 -> 4 | K13: =K4 -> 5 | L13: =L4 -> 6 | M13: =M4 -> 7 | N13: =N4 -> 8 | ... R13: =R4 -> 12 | S13: 13 | T13: 14 | U13: 15 | V13: 16 | W13: 17 | X13: 18 | Y13: 19 | Z13: 20
B14: Всего простоев | D14: часов | G14: =SUM(G15:G34) -> 139 | H14: =SUM(H15:H34) -> 175 | I14: =SUM(I15:I34) -> 289 | J14: =SUM(J15:J34) -> 373 | K14: =SUM(K15:K34) -> 177 | L14: =SUM(L15:L34) -> 253 | M14: =SUM(M15:M34) -> 167 | N14: =SUM(N15:N34) -> 377 | ... Z14: =SUM(Z15:Z34) -> 255
A15: 1 | B15: Двигатель | D15: часов | E15: 20000 | F15: 1 | G15: 30 | H15: 50 | I15: 60 | J15: 30 | K15: 50 | L15: 60 | M15: 30 | N15: 50 | O15: 60 | P15: 30 | Q15: 50 | R15: 60 | S15: 30 | T15: 50 | U15: 60 | V15: 30 | W15: 50 | X15: 60 | Y15: 30 | Z15: 50
A16: 2 | B16: Турбокомпрессор | D16: часов | E16: 14000 | F16: 4 | G16: 0 | H16: 10 | I16: 0 | J16: 0 | K16: 0 | L16: 10 | M16: 0 | N16: 0 | O16: 0 | P16: 10 | Q16: 0 | R16: 10 | S16: 0 | T16: 10 | U16: 0 | V16: 10 | W16: 0 | X16: 0 | Y16: 0 | Z16: 12
A17: 3 | B17: Блок инжектора | D17: часов | E17: 20000 | F17: 16 | G17: 0 | H17: 0 | I17: 12 | J17: 0 | K17: 0 | L17: 12 | M17: 0 | N17: 0 | O17: 12 | P17: 0 | Q17: 0 | R17: 12 | S17: 0 | T17: 0 | U17: 12 | V17: 0 | W17: 0 | X17: 12 | Y17: 0 | Z17: 0
A18: 4 | B18: Глушитель | D18: часов | E18: 20000 | F18: 1 | G18: 0 | H18: 0 | I18: 2 | J18: 0 | K18: 0 | L18: 2 | M18: 0 | N18: 0 | O18: 2 | P18: 0 | Q18: 0 | R18: 2 | S18: 0 | T18: 0 | U18: 2 | V18: 0 | W18: 0 | X18: 2 | Y18: 0 | Z18: 0
A19: 5 | B19: Главный Генератор | D19: часов | E19: 25000 | F19: 1 | G19: 0 | H19: 0 | I19: 0 | J19: 65 | K19: 0 | L19: 0 | M19: 0 | N19: =J19 -> 65 | O19: 0 | P19: 0 | Q19: =N19 -> 65 | R19: 0 | S19: 0 | T19: 0 | U19: =Q19 -> 65 | V19: 0 | W19: 0 | X19: =U19 -> 65 | Y19: 0 | Z19: 0
A20: 6 | B20: РМК | D20: часов | E20: 25000 | F20: 2 | G20: 0 | H20: 0 | I20: 0 | J20: 12 | K20: 0 | L20: 0 | M20: 0 | N20: =J20 -> 12 | O20: 0 | P20: 0 | Q20: =N20 -> 12 | R20: 0 | S20: 0 | T20: 0 | U20: =Q20 -> 12 | V20: 0 | W20: 0 | X20: =U20 -> 12 | Y20: 0 | Z20: 0
A21: 7 | B21: Ретардер | D21: часов | E21: 25000 | F21: 1 | G21: 0 | H21: 0 | I21: 0 | J21: 4 | K21: 0 | L21: 0 | M21: 0 | N21: =J21 -> 4 | O21: 0 | P21: 0 | Q21: =N21 -> 4 | R21: 0 | S21: 0 | T21: 0 | U21: =Q21 -> 4 | V21: 0 | W21: 0 | X21: =U21 -> 4 | Y21: 0 | Z21: 0
A22: 8 | B22: Регулировка клапанов ГРМ ДВС при ТО6 (10000 м\час) | C22: ТО6-10000 | D22: часов | E22: 20000 | F22: 0 | G22: 0 | H22: 8 | I22: 8 | J22: 0 | K22: 8 | L22: 0 | M22: 8 | N22: 8 | O22: 8 | P22: 0 | Q22: 8 | R22: 8 | S22: 8 | T22: 0 | U22: 8 | V22: 8 | W22: 0 | X22: 8 | Y22: 8 | Z22: 8
A23: 9 | B23: Подвеска (передняя и задняя) | D23: часов | E23: 15000 | F23: 4 | G23: 0 | H23: 0 | I23: 24 | J23: 0 | K23: 0 | L23: 4 | M23: 0 | N23: 0 | O23: 24 | P23: 0 | Q23: 0 | R23: 4 | S23: 0 | T23: 0 | U23: 24 | V23: 0 | W23: 0 | X23: 4 | Y23: 0 | Z23: 0
A24: 10 | B24: Гидроцилиндры цом | D24: часов | E24: 25000 | F24: 2 | G24: 0 | H24: 0 | I24: 0 | J24: 30 | K24: 0 | L24: 0 | M24: 0 | N24: 30 | O24: 0 | P24: 0 | Q24: 0 | R24: 30 | S24: 0 | T24: 0 | U24: 0 | V24: 30 | W24: 0 | X24: 0 | Y24: 0 | Z24: 30
A25: 11 | B25: Гидроцилиндры рул | D25: часов | E25: 20000 | F25: 2 | G25: 0 | H25: 0 | I25: 6 | J25: 0 | K25: 0 | L25: 6 | M25: 0 | N25: 0 | O25: 6 | P25: 0 | Q25: 0 | R25: 6 | S25: 0 | T25: 0 | U25: 6 | V25: 0 | W25: 0 | X25: 6 | Y25: 0 | Z25: 0
A26: 12 | B26: Насос гидравлический | D26: часов | E26: 20000 | F26: 2 | G26: 0 | H26: 0 | I26: 4 | J26: 0 | K26: 0 | L26: 4 | M26: 0 | N26: 0 | O26: 4 | P26: 0 | Q26: 0 | R26: 4 | S26: 0 | T26: 0 | U26: 4 | V26: 0 | W26: 0 | X26: 4 | Y26: 0 | Z26: 0
A27: 13 | B27: Насос рулевой | D27: часов | E27: 20000 | F27: 1 | G27: 0 | H27: 0 | I27: 4 | J27: 0 | K27: 0 | L27: 4 | M27: 0 | N27: 0 | O27: 4 | P27: 0 | Q27: 0 | R27: 4 | S27: 0 | T27: 0 | U27: 4 | V27: 0 | W27: 0 | X27: 4 | Y27: 0 | Z27: 0
A28: 14 | B28: Радиатор | D28: часов | E28: 30000 | F28: 1 | G28: 0 | H28: 0 | I28: 0 | J28: 0 | K28: 6 | L28: 0 | M28: 0 | N28: 0 | O28: 6 | P28: 0 | Q28: 0 | R28: 0 | S28: 6 | T28: 0 | U28: 0 | V28: 0 | W28: 6 | X28: 0 | Y28: 0 | Z28: 0
A29: 15 | B29: Радиатор гидравличекий | D29: часов | E29: 20000 | F29: 1 | G29: 0 | H29: 0 | I29: 5 | J29: 0 | K29: 0 | L29: 5 | M29: 0 | N29: 0 | O29: 5 | P29: 0 | Q29: 0 | R29: 5 | S29: 0 | T29: 0 | U29: 5 | V29: 0 | W29: 0 | X29: 5 | Y29: 0 | Z29: 0
A30: 16 | B30: Вентилятор | D30: часов | E30: 20000 | F30: 1 | G30: 0 | H30: 0 | I30: 6 | J30: 0 | K30: 0 | L30: 6 | M30: 0 | N30: 0 | O30: 6 | P30: 0 | Q30: 0 | R30: 6 | S30: 0 | T30: 0 | U30: 6 | V30: 0 | W30: 0 | X30: 6 | Y30: 0 | Z30: 0
A31: 17 | B31: Водяной насос охлаждения | D31: часов | E31: 20000 | F31: 1 | G31: 0 | H31: 0 | I31: 4 | J31: 0 | K31: 0 | L31: 4 | M31: 0 | N31: 0 | O31: 4 | P31: 0 | Q31: 0 | R31: 4 | S31: 0 | T31: 0 | U31: 4 | V31: 0 | W31: 0 | X31: 4 | Y31: 0 | Z31: 0
A32: 18 | B32: Насос ЦСС | D32: часов | E32: 15000 | F32: 1 | G32: 0 | H32: 0 | I32: 0 | J32: 3 | K32: 0 | L32: 0 | M32: 3 | N32: 0 | O32: 0 | P32: 3 | Q32: 0 | R32: 0 | S32: 3 | T32: 0 | U32: 0 | V32: 3 | W32: 0 | X32: 0 | Y32: 3 | Z32: 0
A33: 19 | B33: Подшипники передней оси | D33: часов | E33: 25000 | F33: 4 | G33: 0 | H33: 0 | I33: 0 | J33: 3 | K33: 0 | L33: 0 | M33: 3 | N33: 0 | O33: 0 | P33: 3 | Q33: 0 | R33: 0 | S33: 3 | T33: 0 | U33: 0 | V33: 3 | W33: 0 | X33: 0 | Y33: 3 | Z33: 0
A34: 20 | B34: Ходовая часть + прочие работы | D34: часов | E34: 14000 | F34: 2 | G34: 109 | H34: 107 | I34: 154 | J34: 226 | K34: 113 | L34: 136 | M34: 123 | N34: 208 | O34: 154 | P34: 141 | Q34: 178 | R34: 174 | S34: 123 | T34: 99 | U34: 251 | V34: 163 | W34: 89 | X34: 215 | Y34: 123 | Z34: 155
B36: Трудозатраты на ремонты (ч/час) | E36: =ТО!F10 -> 191
B37: Вид ремонта | D37: Ед.изм. | E37: Стоимость ч/часа | G37: =G13 -> 1 | H37: =H13 -> 2 | I37: =I13 -> 3 | J37: =J13 -> 4 | K37: =K13 -> 5 | L37: =L13 -> 6 | M37: =M13 -> 7 | N37: =N13 -> 8 | ... R37: =R13 -> 12 | S37: 13 | T37: 14 | U37: 15 | V37: 16 | W37: 17 | X37: 18 | Y37: 19 | Z37: 20
B38: Всего ч/часов | D38: ч/часов | G38: =SUM(G39:G58) -> 248 | H38: =SUM(H39:H58) -> 300 | I38: =SUM(I39:I58) -> 830 | J38: =SUM(J39:J58) -> 1498 | K38: =SUM(K39:K58) -> 296 | L38: =SUM(L39:L58) -> 420 | M38: =SUM(M39:M58) -> 754 | N38: =SUM(N39:N58) -> 1464 | ... Z38: =SUM(Z39:Z58) -> 356
A39: 1 | B39: Двигатель | D39: ч/часов | E39: =E36 -> 191 | G39: 30 | H39: 50 | I39: 450 | J39: 30 | K39: 30 | L39: 50 | M39: 450 | N39: 30 | O39: 30 | P39: 50 | Q39: 450 | R39: 30 | S39: 30 | T39: 50 | U39: 450 | V39: 30 | W39: 30 | X39: 50 | Y39: 450 | Z39: 30
A40: 2 | B40: Турбокомпрессор | D40: ч/часов | E40: 191 | G40: 0 | H40: 20 | I40: 0 | J40: 0 | K40: 0 | L40: 20 | M40: 0 | N40: 0 | O40: 0 | P40: 20 | Q40: 0 | R40: 0 | S40: 0 | T40: 20 | U40: 0 | V40: 0 | W40: 0 | X40: 20 | Y40: 0 | Z40: 0
A41: 3 | B41: Блок инжектора | D41: ч/часов | E41: 191 | G41: 0 | H41: 0 | I41: 6 | J41: 0 | K41: 0 | L41: 0 | M41: 6 | N41: 0 | O41: 0 | P41: 0 | Q41: 6 | R41: 0 | S41: 0 | T41: 0 | U41: 6 | V41: 0 | W41: 0 | X41: 0 | Y41: 6 | Z41: 0
A42: 4 | B42: Глушитель | D42: ч/часов | E42: 191 | G42: 0 | H42: 0 | I42: 4 | J42: 0 | K42: 0 | L42: 4 | M42: 0 | N42: 0 | O42: 4 | P42: 0 | Q42: 0 | R42: 4 | S42: 0 | T42: 0 | U42: 4 | V42: 0 | W42: 0 | X42: 4 | Y42: 0 | Z42: 0
A43: 5 | B43: Главный Генератор | D43: ч/часов | E43: 191 | G43: 0 | H43: 0 | I43: 0 | J43: 200 | K43: 0 | L43: 0 | M43: 0 | N43: =J43 -> 200 | O43: 0 | P43: 0 | Q43: =N43 -> 200 | R43: 0 | S43: 0 | T43: 0 | U43: =Q43 -> 200 | V43: 0 | W43: 0 | X43: =U43 -> 200 | Y43: 0 | Z43: 0
...
